Workbook

Sheet Category Summary
A1: Chase 1168 — DWG Capital Group 2025 Activity
A2: Category Summary | Jan 2025 – Dec 2025
A4: Entity | B4: DWG Capital Group
A5: Account | B5: Business Checking — Chase 1168
A6: Period | B6: Jan 2025 – Dec 2025
A8: TOTALS
A9: Total Inflows | B9: =SUMIFS('Transaction Overview'!$D$2:$D$1850,'Transaction Overview'!$D$2:$D$1850,">0") -> 2173385.3
A10: Total Outflows | B10: =SUMIFS('Transaction Overview'!$D$2:$D$1850,'Transaction Overview'!$D$2:$D$1850,"<0") -> -2192318.1
A11: Net Change | B11: =B9+B10 -> -18932.79
A14: Category | B14: Inflows | C14: Outflows | D14: Net
A15: Deal-Specific
A16: Deal Specific: Moab | B16: =SUMIFS('Transaction Overview'!$D$2:$D$1850,'Transaction Overview'!$I$2:$I$1850,$A16,'Transaction Overview'!$D$2:$D$1850,">0") -> 0 | C16: =SUMIFS('Transaction Overview'!$D$2:$D$1850,'Transaction Overview'!$I$2:$I$1850,$A16,'Transaction Overview'!$D$2:$D$1850,"<0") -> -40000 | D16: =B16+C16 -> -40000
A17: Deal Specific: Moab (Reimbursement) | B17: =SUMIFS('Transaction Overview'!$D$2:$D$1850,'Transaction Overview'!$I$2:$I$1850,$A17,'Transaction Overview'!$D$2:$D$1850,">0") -> 40000 | C17: =SUMIFS('Transaction Overview'!$D$2:$D$1850,'Transaction Overview'!$I$2:$I$1850,$A17,'Transaction Overview'!$D$2:$D$1850,"<0") -> 0 | D17: =B17+C17 -> 40000
A18: Deal Specific: TBD | B18: =SUMIFS('Transaction Overview'!$D$2:$D$1850,'Transaction Overview'!$I$2:$I$1850,$A18,'Transaction Overview'!$D$2:$D$1850,">0") -> 0 | C18: =SUMIFS('Transaction Overview'!$D$2:$D$1850,'Transaction Overview'!$I$2:$I$1850,$A18,'Transaction Overview'!$D$2:$D$1850,"<0") -> -15000 | D18: =B18+C18 -> -15000
A19: Subtotal — Deal-Specific | B19: =SUMIFS('Transaction Overview'!$D$2:$D$1850,'Transaction Overview'!$J$2:$J$1850,"Deal-Specific",'Transaction Overview'!$D$2:$D$1850,">0") -> 40000 | C19: =SUMIFS('Transaction Overview'!$D$2:$D$1850,'Transaction Overview'!$J$2:$J$1850,"Deal-Specific",'Transaction Overview'!$D$2:$D$1850,"<0") -> -55000 | D19: =B19+C19 -> -15000
A21: Commissions — Incoming
A22: Incoming Commission: Aspen | B22: =SUMIFS('Transaction Overview'!$D$2:$D$1850,'Transaction Overview'!$I$2:$I$1850,$A22,'Transaction Overview'!$D$2:$D$1850,">0") -> 87850 | C22: =SUMIFS('Transaction Overview'!$D$2:$D$1850,'Transaction Overview'!$I$2:$I$1850,$A22,'Transaction Overview'!$D$2:$D$1850,"<0") -> 0 | D22: =B22+C22 -> 87850
A23: Incoming Commission: Charlmont | B23: =SUMIFS('Transaction Overview'!$D$2:$D$1850,'Transaction Overview'!$I$2:$I$1850,$A23,'Transaction Overview'!$D$2:$D$1850,">0") -> 235000 | C23: =SUMIFS('Transaction Overview'!$D$2:$D$1850,'Transaction Overview'!$I$2:$I$1850,$A23,'Transaction Overview'!$D$2:$D$1850,"<0") -> -25000 | D23: =B23+C23 -> 210000
A24: Incoming Commission: 115 Penn | B24: =SUMIFS('Transaction Overview'!$D$2:$D$1850,'Transaction Overview'!$I$2:$I$1850,$A24,'Transaction Overview'!$D$2:$D$1850,">0") -> 42500 | C24: =SUMIFS('Transaction Overview'!$D$2:$D$1850,'Transaction Overview'!$I$2:$I$1850,$A24,'Transaction Overview'!$D$2:$D$1850,"<0") -> 0 | D24: =B24+C24 -> 42500
A25: Incoming Commission: 2055 Laguna Canyon | B25: =SUMIFS('Transaction Overview'!$D$2:$D$1850,'Transaction Overview'!$I$2:$I$1850,$A25,'Transaction Overview'!$D$2:$D$1850,">0") -> 40000 | C25: =SUMIFS('Transaction Overview'!$D$2:$D$1850,'Transaction Overview'!$I$2:$I$1850,$A25,'Transaction Overview'!$D$2:$D$1850,"<0") -> 0 | D25: =B25+C25 -> 40000
A26: Incoming Commission: 20635 N 29th Pl, Phoenix AZ (Deer Valley) | B26: =SUMIFS('Transaction Overview'!$D$2:$D$1850,'Transaction Overview'!$I$2:$I$1850,$A26,'Transaction Overview'!$D$2:$D$1850,">0") -> 69000 | C26: =SUMIFS('Transaction Overview'!$D$2:$D$1850,'Transaction Overview'!$I$2:$I$1850,$A26,'Transaction Overview'!$D$2:$D$1850,"<0") -> 0 | D26: =B26+C26 -> 69000
A27: Incoming Commission: 315 York | B27: =SUMIFS('Transaction Overview'!$D$2:$D$1850,'Transaction Overview'!$I$2:$I$1850,$A27,'Transaction Overview'!$D$2:$D$1850,">0") -> 40350 | C27: =SUMIFS('Transaction Overview'!$D$2:$D$1850,'Transaction Overview'!$I$2:$I$1850,$A27,'Transaction Overview'!$D$2:$D$1850,"<0") -> 0 | D27: =B27+C27 -> 40350
A28: Incoming Commission: 3811 E Bankhead | B28: =SUMIFS('Transaction Overview'!$D$2:$D$1850,'Transaction Overview'!$I$2:$I$1850,$A28,'Transaction Overview'!$D$2:$D$1850,">0") -> 85700 | C28: =SUMIFS('Transaction Overview'!$D$2:$D$1850,'Transaction Overview'!$I$2:$I$1850,$A28,'Transaction Overview'!$D$2:$D$1850,"<0") -> 0 | D28: =B28+C28 -> 85700
A29: Incoming Commission: Edge Builder | B29: =SUMIFS('Transaction Overview'!$D$2:$D$1850,'Transaction Overview'!$I$2:$I$1850,$A29,'Transaction Overview'!$D$2:$D$1850,">0") -> 61037 | C29: =SUMIFS('Transaction Overview'!$D$2:$D$1850,'Transaction Overview'!$I$2:$I$1850,$A29,'Transaction Overview'!$D$2:$D$1850,"<0") -> 0 | D29: =B29+C29 -> 61037
A30: Subtotal — Commissions — Incoming | B30: =SUMIFS('Transaction Overview'!$D$2:$D$1850,'Transaction Overview'!$J$2:$J$1850,"Commissions — Incoming",'Transaction Overview'!$D$2:$D$1850,">0") -> 661437 | C30: =SUMIFS('Transaction Overview'!$D$2:$D$1850,'Transaction Overview'!$J$2:$J$1850,"Commissions — Incoming",'Transaction Overview'!$D$2:$D$1850,"<0") -> -25000 | D30: =B30+C30 -> 636437
A32: Commissions — Outgoing
A33: Commission Paid: Brian Bowis (Charlmont) | B33: =SUMIFS('Transaction Overview'!$D$2:$D$1850,'Transaction Overview'!$I$2:$I$1850,$A33,'Transaction Overview'!$D$2:$D$1850,">0") -> 0 | C33: =SUMIFS('Transaction Overview'!$D$2:$D$1850,'Transaction Overview'!$I$2:$I$1850,$A33,'Transaction Overview'!$D$2:$D$1850,"<0") -> -102500 | D33: =B33+C33 -> -102500
A34: Subtotal — Commissions — Outgoing | B34: =SUMIFS('Transaction Overview'!$D$2:$D$1850,'Transaction Overview'!$J$2:$J$1850,"Commissions — Outgoing",'Transaction Overview'!$D$2:$D$1850,">0") -> 0 | C34: =SUMIFS('Transaction Overview'!$D$2:$D$1850,'Transaction Overview'!$J$2:$J$1850,"Commissions — Outgoing",'Transaction Overview'!$D$2:$D$1850,"<0") -> -102500 | D34: =B34+C34 -> -102500
A36: MAG Pass-Through
A37: Due to Andrew – MAG Pass-Through 30% | B37: =SUMIFS('Transaction Overview'!$D$2:$D$1850,'Transaction Overview'!$I$2:$I$1850,$A37,'Transaction Overview'!$D$2:$D$1850,">0") -> 0 | C37: =SUMIFS('Transaction Overview'!$D$2:$D$1850,'Transaction Overview'!$I$2:$I$1850,$A37,'Transaction Overview'!$D$2:$D$1850,"<0") -> -114028.02 | D37: =B37+C37 -> -114028.02
A38: Due to Andrew – MAG Pass-Through 30% | B38: =SUMIFS('Transaction Overview'!$D$2:$D$1850,'Transaction Overview'!$I$2:$I$1850,$A38,'Transaction Overview'!$D$2:$D$1850,">0") -> 0 | C38: =SUMIFS('Transaction Overview'!$D$2:$D$1850,'Transaction Overview'!$I$2:$I$1850,$A38,'Transaction Overview'!$D$2:$D$1850,"<0") -> -83437 | D38: =B38+C38 -> -83437
A39: Due to Dax – MAG Pass-Through 70% | B39: =SUMIFS('Transaction Overview'!$D$2:$D$1850,'Transaction Overview'!$I$2:$I$1850,$A39,'Transaction Overview'!$D$2:$D$1850,">0") -> 0 | C39: =SUMIFS('Transaction Overview'!$D$2:$D$1850,'Transaction Overview'!$I$2:$I$1850,$A39,'Transaction Overview'!$D$2:$D$1850,"<0") -> -454752.37 | D39: =B39+C39 -> -454752.37
A40: MAG - Admeer Advisory Transfer | B40: =SUMIFS('Transaction Overview'!$D$2:$D$1850,'Transaction Overview'!$I$2:$I$1850,$A40,'Transaction Overview'!$D$2:$D$1850,">0") -> 0 | C40: =SUMIFS('Transaction Overview'!$D$2:$D$1850,'Transaction Overview'!$I$2:$I$1850,$A40,'Transaction Overview'!$D$2:$D$1850,"<0") -> -10000 | D40: =B40+C40 -> -10000
A41: MAG Capital Partners Pass-Through Wire – 70/30 Split | B41: =SUMIFS('Transaction Overview'!$D$2:$D$1850,'Transaction Overview'!$I$2:$I$1850,$A41,'Transaction Overview'!$D$2:$D$1850,">0") -> 365125 | C41: =SUMIFS('Transaction Overview'!$D$2:$D$1850,'Transaction Overview'!$I$2:$I$1850,$A41,'Transaction Overview'!$D$2:$D$1850,"<0") -> 0 | D41: =B41+C41 -> 365125
A42: Subtotal — MAG Pass-Through | B42: =SUMIFS('Transaction Overview'!$D$2:$D$1850,'Transaction Overview'!$J$2:$J$1850,"MAG Pass-Through",'Transaction Overview'!$D$2:$D$1850,">0") -> 365125 | C42: =SUMIFS('Transaction Overview'!$D$2:$D$1850,'Transaction Overview'!$J$2:$J$1850,"MAG Pass-Through",'Transaction Overview'!$D$2:$D$1850,"<0") -> -662217.39 | D42: =B42+C42 -> -297092.39
A44: Poseidon Asset Group
A45: Poseidon Asset Group (Incoming) | B45: =SUMIFS('Transaction Overview'!$D$2:$D$1850,'Transaction Overview'!$I$2:$I$1850,$A45,'Transaction Overview'!$D$2:$D$1850,">0") -> 423000 | C45: =SUMIFS('Transaction Overview'!$D$2:$D$1850,'Transaction Overview'!$I$2:$I$1850,$A45,'Transaction Overview'!$D$2:$D$1850,"<0") -> 0 | D45: =B45+C45 -> 423000
A46: Transfer From Poseidon Asset Group | B46: =SUMIFS('Transaction Overview'!$D$2:$D$1850,'Transaction Overview'!$I$2:$I$1850,$A46,'Transaction Overview'!$D$2:$D$1850,">0") -> 255000 | C46: =SUMIFS('Transaction Overview'!$D$2:$D$1850,'Transaction Overview'!$I$2:$I$1850,$A46,'Transaction Overview'!$D$2:$D$1850,"<0") -> 0 | D46: =B46+C46 -> 255000
A47: Transfer to Poseidon | B47: =SUMIFS('Transaction Overview'!$D$2:$D$1850,'Transaction Overview'!$I$2:$I$1850,$A47,'Transaction Overview'!$D$2:$D$1850,">0") -> 0 | C47: =SUMIFS('Transaction Overview'!$D$2:$D$1850,'Transaction Overview'!$I$2:$I$1850,$A47,'Transaction Overview'!$D$2:$D$1850,"<0") -> -5000 | D47: =B47+C47 -> -5000
A48: Subtotal — Poseidon Asset Group | B48: =SUMIFS('Transaction Overview'!$D$2:$D$1850,'Transaction Overview'!$J$2:$J$1850,"Poseidon Asset Group",'Transaction Overview'!$D$2:$D$1850,">0") -> 678000 | C48: =SUMIFS('Transaction Overview'!$D$2:$D$1850,'Transaction Overview'!$J$2:$J$1850,"Poseidon Asset Group",'Transaction Overview'!$D$2:$D$1850,"<0") -> -5000 | D48: =B48+C48 -> 673000
...

Sheet Monthly Breakdown
A1: Chase 1168 — DWG Capital Group 2025 Activity
A2: Monthly Breakdown | Jan 2025 – Dec 2025
A4: Category | B4: =DATE(2025,1,1) -> 45658 | C4: =DATE(2025,2,1) -> 45689 | D4: =DATE(2025,3,1) -> 45717 | E4: =DATE(2025,4,1) -> 45748 | F4: =DATE(2025,5,1) -> 45778 | G4: =DATE(2025,6,1) -> 45809 | H4: =DATE(2025,7,1) -> 45839 | I4: =DATE(2025,8,1) -> 45870 | J4: =DATE(2025,9,1) -> 45901 | K4: =DATE(2025,10,1) -> 45931 | L4: =DATE(2025,11,1) -> 45962 | M4: =DATE(2025,12,1) -> 45992 | N4: Total
A5: Deal-Specific
A6: Deal Specific: Moab | B6: =SUMIFS('Transaction Overview'!$D$2:$D$1850,'Transaction Overview'!$I$2:$I$1850,$A6,'Transaction Overview'!$H$2:$H$1850,B$4) -> 0 | C6: =SUMIFS('Transaction Overview'!$D$2:$D$1850,'Transaction Overview'!$I$2:$I$1850,$A6,'Transaction Overview'!$H$2:$H$1850,C$4) -> 0 | D6: =SUMIFS('Transaction Overview'!$D$2:$D$1850,'Transaction Overview'!$I$2:$I$1850,$A6,'Transaction Overview'!$H$2:$H$1850,D$4) -> 0 | E6: =SUMIFS('Transaction Overview'!$D$2:$D$1850,'Transaction Overview'!$I$2:$I$1850,$A6,'Transaction Overview'!$H$2:$H$1850,E$4) -> 0 | F6: =SUMIFS('Transaction Overview'!$D$2:$D$1850,'Transaction Overview'!$I$2:$I$1850,$A6,'Transaction Overview'!$H$2:$H$1850,F$4) -> 0 | G6: =SUMIFS('Transaction Overview'!$D$2:$D$1850,'Transaction Overview'!$I$2:$I$1850,$A6,'Transaction Overview'!$H$2:$H$1850,G$4) -> 0 | H6: =SUMIFS('Transaction Overview'!$D$2:$D$1850,'Transaction Overview'!$I$2:$I$1850,$A6,'Transaction Overview'!$H$2:$H$1850,H$4) -> 0 | I6: =SUMIFS('Transaction Overview'!$D$2:$D$1850,'Transaction Overview'!$I$2:$I$1850,$A6,'Transaction Overview'!$H$2:$H$1850,I$4) -> 0 | ... M6: =SUMIFS('Transaction Overview'!$D$2:$D$1850,'Transaction Overview'!$I$2:$I$1850,$A6,'Transaction Overview'!$H$2:$H$1850,M$4) -> 0 | N6: =SUM(B6:M6) -> -40000
A7: Deal Specific: Moab (Reimbursement) | B7: =SUMIFS('Transaction Overview'!$D$2:$D$1850,'Transaction Overview'!$I$2:$I$1850,$A7,'Transaction Overview'!$H$2:$H$1850,B$4) -> 0 | C7: =SUMIFS('Transaction Overview'!$D$2:$D$1850,'Transaction Overview'!$I$2:$I$1850,$A7,'Transaction Overview'!$H$2:$H$1850,C$4) -> 0 | D7: =SUMIFS('Transaction Overview'!$D$2:$D$1850,'Transaction Overview'!$I$2:$I$1850,$A7,'Transaction Overview'!$H$2:$H$1850,D$4) -> 0 | E7: =SUMIFS('Transaction Overview'!$D$2:$D$1850,'Transaction Overview'!$I$2:$I$1850,$A7,'Transaction Overview'!$H$2:$H$1850,E$4) -> 0 | F7: =SUMIFS('Transaction Overview'!$D$2:$D$1850,'Transaction Overview'!$I$2:$I$1850,$A7,'Transaction Overview'!$H$2:$H$1850,F$4) -> 0 | G7: =SUMIFS('Transaction Overview'!$D$2:$D$1850,'Transaction Overview'!$I$2:$I$1850,$A7,'Transaction Overview'!$H$2:$H$1850,G$4) -> 0 | H7: =SUMIFS('Transaction Overview'!$D$2:$D$1850,'Transaction Overview'!$I$2:$I$1850,$A7,'Transaction Overview'!$H$2:$H$1850,H$4) -> 0 | I7: =SUMIFS('Transaction Overview'!$D$2:$D$1850,'Transaction Overview'!$I$2:$I$1850,$A7,'Transaction Overview'!$H$2:$H$1850,I$4) -> 0 | ... M7: =SUMIFS('Transaction Overview'!$D$2:$D$1850,'Transaction Overview'!$I$2:$I$1850,$A7,'Transaction Overview'!$H$2:$H$1850,M$4) -> 0 | N7: =SUM(B7:M7) -> 40000
A8: Deal Specific: TBD | B8: =SUMIFS('Transaction Overview'!$D$2:$D$1850,'Transaction Overview'!$I$2:$I$1850,$A8,'Transaction Overview'!$H$2:$H$1850,B$4) -> 0 | C8: =SUMIFS('Transaction Overview'!$D$2:$D$1850,'Transaction Overview'!$I$2:$I$1850,$A8,'Transaction Overview'!$H$2:$H$1850,C$4) -> 0 | D8: =SUMIFS('Transaction Overview'!$D$2:$D$1850,'Transaction Overview'!$I$2:$I$1850,$A8,'Transaction Overview'!$H$2:$H$1850,D$4) -> -15000 | E8: =SUMIFS('Transaction Overview'!$D$2:$D$1850,'Transaction Overview'!$I$2:$I$1850,$A8,'Transaction Overview'!$H$2:$H$1850,E$4) -> 0 | F8: =SUMIFS('Transaction Overview'!$D$2:$D$1850,'Transaction Overview'!$I$2:$I$1850,$A8,'Transaction Overview'!$H$2:$H$1850,F$4) -> 0 | G8: =SUMIFS('Transaction Overview'!$D$2:$D$1850,'Transaction Overview'!$I$2:$I$1850,$A8,'Transaction Overview'!$H$2:$H$1850,G$4) -> 0 | H8: =SUMIFS('Transaction Overview'!$D$2:$D$1850,'Transaction Overview'!$I$2:$I$1850,$A8,'Transaction Overview'!$H$2:$H$1850,H$4) -> 0 | I8: =SUMIFS('Transaction Overview'!$D$2:$D$1850,'Transaction Overview'!$I$2:$I$1850,$A8,'Transaction Overview'!$H$2:$H$1850,I$4) -> 0 | ... M8: =SUMIFS('Transaction Overview'!$D$2:$D$1850,'Transaction Overview'!$I$2:$I$1850,$A8,'Transaction Overview'!$H$2:$H$1850,M$4) -> 0 | N8: =SUM(B8:M8) -> -15000
A9: Commissions — Incoming
A10: Incoming Commission: Aspen | B10: =SUMIFS('Transaction Overview'!$D$2:$D$1850,'Transaction Overview'!$I$2:$I$1850,$A10,'Transaction Overview'!$H$2:$H$1850,B$4) -> 0 | C10: =SUMIFS('Transaction Overview'!$D$2:$D$1850,'Transaction Overview'!$I$2:$I$1850,$A10,'Transaction Overview'!$H$2:$H$1850,C$4) -> 0 | D10: =SUMIFS('Transaction Overview'!$D$2:$D$1850,'Transaction Overview'!$I$2:$I$1850,$A10,'Transaction Overview'!$H$2:$H$1850,D$4) -> 0 | E10: =SUMIFS('Transaction Overview'!$D$2:$D$1850,'Transaction Overview'!$I$2:$I$1850,$A10,'Transaction Overview'!$H$2:$H$1850,E$4) -> 0 | F10: =SUMIFS('Transaction Overview'!$D$2:$D$1850,'Transaction Overview'!$I$2:$I$1850,$A10,'Transaction Overview'!$H$2:$H$1850,F$4) -> 0 | G10: =SUMIFS('Transaction Overview'!$D$2:$D$1850,'Transaction Overview'!$I$2:$I$1850,$A10,'Transaction Overview'!$H$2:$H$1850,G$4) -> 87850 | H10: =SUMIFS('Transaction Overview'!$D$2:$D$1850,'Transaction Overview'!$I$2:$I$1850,$A10,'Transaction Overview'!$H$2:$H$1850,H$4) -> 0 | I10: =SUMIFS('Transaction Overview'!$D$2:$D$1850,'Transaction Overview'!$I$2:$I$1850,$A10,'Transaction Overview'!$H$2:$H$1850,I$4) -> 0 | ... M10: =SUMIFS('Transaction Overview'!$D$2:$D$1850,'Transaction Overview'!$I$2:$I$1850,$A10,'Transaction Overview'!$H$2:$H$1850,M$4) -> 0 | N10: =SUM(B10:M10) -> 87850
A11: Incoming Commission: Charlmont | B11: =SUMIFS('Transaction Overview'!$D$2:$D$1850,'Transaction Overview'!$I$2:$I$1850,$A11,'Transaction Overview'!$H$2:$H$1850,B$4) -> 0 | C11: =SUMIFS('Transaction Overview'!$D$2:$D$1850,'Transaction Overview'!$I$2:$I$1850,$A11,'Transaction Overview'!$H$2:$H$1850,C$4) -> 0 | D11: =SUMIFS('Transaction Overview'!$D$2:$D$1850,'Transaction Overview'!$I$2:$I$1850,$A11,'Transaction Overview'!$H$2:$H$1850,D$4) -> 0 | E11: =SUMIFS('Transaction Overview'!$D$2:$D$1850,'Transaction Overview'!$I$2:$I$1850,$A11,'Transaction Overview'!$H$2:$H$1850,E$4) -> 0 | F11: =SUMIFS('Transaction Overview'!$D$2:$D$1850,'Transaction Overview'!$I$2:$I$1850,$A11,'Transaction Overview'!$H$2:$H$1850,F$4) -> 0 | G11: =SUMIFS('Transaction Overview'!$D$2:$D$1850,'Transaction Overview'!$I$2:$I$1850,$A11,'Transaction Overview'!$H$2:$H$1850,G$4) -> 0 | H11: =SUMIFS('Transaction Overview'!$D$2:$D$1850,'Transaction Overview'!$I$2:$I$1850,$A11,'Transaction Overview'!$H$2:$H$1850,H$4) -> 0 | I11: =SUMIFS('Transaction Overview'!$D$2:$D$1850,'Transaction Overview'!$I$2:$I$1850,$A11,'Transaction Overview'!$H$2:$H$1850,I$4) -> 0 | ... M11: =SUMIFS('Transaction Overview'!$D$2:$D$1850,'Transaction Overview'!$I$2:$I$1850,$A11,'Transaction Overview'!$H$2:$H$1850,M$4) -> 235000 | N11: =SUM(B11:M11) -> 210000
A12: Incoming Commission: 115 Penn | B12: =SUMIFS('Transaction Overview'!$D$2:$D$1850,'Transaction Overview'!$I$2:$I$1850,$A12,'Transaction Overview'!$H$2:$H$1850,B$4) -> 0 | C12: =SUMIFS('Transaction Overview'!$D$2:$D$1850,'Transaction Overview'!$I$2:$I$1850,$A12,'Transaction Overview'!$H$2:$H$1850,C$4) -> 0 | D12: =SUMIFS('Transaction Overview'!$D$2:$D$1850,'Transaction Overview'!$I$2:$I$1850,$A12,'Transaction Overview'!$H$2:$H$1850,D$4) -> 0 | E12: =SUMIFS('Transaction Overview'!$D$2:$D$1850,'Transaction Overview'!$I$2:$I$1850,$A12,'Transaction Overview'!$H$2:$H$1850,E$4) -> 0 | F12: =SUMIFS('Transaction Overview'!$D$2:$D$1850,'Transaction Overview'!$I$2:$I$1850,$A12,'Transaction Overview'!$H$2:$H$1850,F$4) -> 0 | G12: =SUMIFS('Transaction Overview'!$D$2:$D$1850,'Transaction Overview'!$I$2:$I$1850,$A12,'Transaction Overview'!$H$2:$H$1850,G$4) -> 0 | H12: =SUMIFS('Transaction Overview'!$D$2:$D$1850,'Transaction Overview'!$I$2:$I$1850,$A12,'Transaction Overview'!$H$2:$H$1850,H$4) -> 0 | I12: =SUMIFS('Transaction Overview'!$D$2:$D$1850,'Transaction Overview'!$I$2:$I$1850,$A12,'Transaction Overview'!$H$2:$H$1850,I$4) -> 0 | ... M12: =SUMIFS('Transaction Overview'!$D$2:$D$1850,'Transaction Overview'!$I$2:$I$1850,$A12,'Transaction Overview'!$H$2:$H$1850,M$4) -> 0 | N12: =SUM(B12:M12) -> 42500
A13: Incoming Commission: 2055 Laguna Canyon | B13: =SUMIFS('Transaction Overview'!$D$2:$D$1850,'Transaction Overview'!$I$2:$I$1850,$A13,'Transaction Overview'!$H$2:$H$1850,B$4) -> 0 | C13: =SUMIFS('Transaction Overview'!$D$2:$D$1850,'Transaction Overview'!$I$2:$I$1850,$A13,'Transaction Overview'!$H$2:$H$1850,C$4) -> 0 | D13: =SUMIFS('Transaction Overview'!$D$2:$D$1850,'Transaction Overview'!$I$2:$I$1850,$A13,'Transaction Overview'!$H$2:$H$1850,D$4) -> 0 | E13: =SUMIFS('Transaction Overview'!$D$2:$D$1850,'Transaction Overview'!$I$2:$I$1850,$A13,'Transaction Overview'!$H$2:$H$1850,E$4) -> 0 | F13: =SUMIFS('Transaction Overview'!$D$2:$D$1850,'Transaction Overview'!$I$2:$I$1850,$A13,'Transaction Overview'!$H$2:$H$1850,F$4) -> 0 | G13: =SUMIFS('Transaction Overview'!$D$2:$D$1850,'Transaction Overview'!$I$2:$I$1850,$A13,'Transaction Overview'!$H$2:$H$1850,G$4) -> 0 | H13: =SUMIFS('Transaction Overview'!$D$2:$D$1850,'Transaction Overview'!$I$2:$I$1850,$A13,'Transaction Overview'!$H$2:$H$1850,H$4) -> 0 | I13: =SUMIFS('Transaction Overview'!$D$2:$D$1850,'Transaction Overview'!$I$2:$I$1850,$A13,'Transaction Overview'!$H$2:$H$1850,I$4) -> 0 | ... M13: =SUMIFS('Transaction Overview'!$D$2:$D$1850,'Transaction Overview'!$I$2:$I$1850,$A13,'Transaction Overview'!$H$2:$H$1850,M$4) -> 0 | N13: =SUM(B13:M13) -> 40000
A14: Incoming Commission: 20635 N 29th Pl, Phoenix AZ (Deer Valley) | B14: =SUMIFS('Transaction Overview'!$D$2:$D$1850,'Transaction Overview'!$I$2:$I$1850,$A14,'Transaction Overview'!$H$2:$H$1850,B$4) -> 0 | C14: =SUMIFS('Transaction Overview'!$D$2:$D$1850,'Transaction Overview'!$I$2:$I$1850,$A14,'Transaction Overview'!$H$2:$H$1850,C$4) -> 0 | D14: =SUMIFS('Transaction Overview'!$D$2:$D$1850,'Transaction Overview'!$I$2:$I$1850,$A14,'Transaction Overview'!$H$2:$H$1850,D$4) -> 0 | E14: =SUMIFS('Transaction Overview'!$D$2:$D$1850,'Transaction Overview'!$I$2:$I$1850,$A14,'Transaction Overview'!$H$2:$H$1850,E$4) -> 0 | F14: =SUMIFS('Transaction Overview'!$D$2:$D$1850,'Transaction Overview'!$I$2:$I$1850,$A14,'Transaction Overview'!$H$2:$H$1850,F$4) -> 0 | G14: =SUMIFS('Transaction Overview'!$D$2:$D$1850,'Transaction Overview'!$I$2:$I$1850,$A14,'Transaction Overview'!$H$2:$H$1850,G$4) -> 0 | H14: =SUMIFS('Transaction Overview'!$D$2:$D$1850,'Transaction Overview'!$I$2:$I$1850,$A14,'Transaction Overview'!$H$2:$H$1850,H$4) -> 0 | I14: =SUMIFS('Transaction Overview'!$D$2:$D$1850,'Transaction Overview'!$I$2:$I$1850,$A14,'Transaction Overview'!$H$2:$H$1850,I$4) -> 0 | ... M14: =SUMIFS('Transaction Overview'!$D$2:$D$1850,'Transaction Overview'!$I$2:$I$1850,$A14,'Transaction Overview'!$H$2:$H$1850,M$4) -> 0 | N14: =SUM(B14:M14) -> 69000
A15: Incoming Commission: 315 York | B15: =SUMIFS('Transaction Overview'!$D$2:$D$1850,'Transaction Overview'!$I$2:$I$1850,$A15,'Transaction Overview'!$H$2:$H$1850,B$4) -> 0 | C15: =SUMIFS('Transaction Overview'!$D$2:$D$1850,'Transaction Overview'!$I$2:$I$1850,$A15,'Transaction Overview'!$H$2:$H$1850,C$4) -> 0 | D15: =SUMIFS('Transaction Overview'!$D$2:$D$1850,'Transaction Overview'!$I$2:$I$1850,$A15,'Transaction Overview'!$H$2:$H$1850,D$4) -> 40350 | E15: =SUMIFS('Transaction Overview'!$D$2:$D$1850,'Transaction Overview'!$I$2:$I$1850,$A15,'Transaction Overview'!$H$2:$H$1850,E$4) -> 0 | F15: =SUMIFS('Transaction Overview'!$D$2:$D$1850,'Transaction Overview'!$I$2:$I$1850,$A15,'Transaction Overview'!$H$2:$H$1850,F$4) -> 0 | G15: =SUMIFS('Transaction Overview'!$D$2:$D$1850,'Transaction Overview'!$I$2:$I$1850,$A15,'Transaction Overview'!$H$2:$H$1850,G$4) -> 0 | H15: =SUMIFS('Transaction Overview'!$D$2:$D$1850,'Transaction Overview'!$I$2:$I$1850,$A15,'Transaction Overview'!$H$2:$H$1850,H$4) -> 0 | I15: =SUMIFS('Transaction Overview'!$D$2:$D$1850,'Transaction Overview'!$I$2:$I$1850,$A15,'Transaction Overview'!$H$2:$H$1850,I$4) -> 0 | ... M15: =SUMIFS('Transaction Overview'!$D$2:$D$1850,'Transaction Overview'!$I$2:$I$1850,$A15,'Transaction Overview'!$H$2:$H$1850,M$4) -> 0 | N15: =SUM(B15:M15) -> 40350
A16: Incoming Commission: 3811 E Bankhead | B16: =SUMIFS('Transaction Overview'!$D$2:$D$1850,'Transaction Overview'!$I$2:$I$1850,$A16,'Transaction Overview'!$H$2:$H$1850,B$4) -> 0 | C16: =SUMIFS('Transaction Overview'!$D$2:$D$1850,'Transaction Overview'!$I$2:$I$1850,$A16,'Transaction Overview'!$H$2:$H$1850,C$4) -> 85700 | D16: =SUMIFS('Transaction Overview'!$D$2:$D$1850,'Transaction Overview'!$I$2:$I$1850,$A16,'Transaction Overview'!$H$2:$H$1850,D$4) -> 0 | E16: =SUMIFS('Transaction Overview'!$D$2:$D$1850,'Transaction Overview'!$I$2:$I$1850,$A16,'Transaction Overview'!$H$2:$H$1850,E$4) -> 0 | F16: =SUMIFS('Transaction Overview'!$D$2:$D$1850,'Transaction Overview'!$I$2:$I$1850,$A16,'Transaction Overview'!$H$2:$H$1850,F$4) -> 0 | G16: =SUMIFS('Transaction Overview'!$D$2:$D$1850,'Transaction Overview'!$I$2:$I$1850,$A16,'Transaction Overview'!$H$2:$H$1850,G$4) -> 0 | H16: =SUMIFS('Transaction Overview'!$D$2:$D$1850,'Transaction Overview'!$I$2:$I$1850,$A16,'Transaction Overview'!$H$2:$H$1850,H$4) -> 0 | I16: =SUMIFS('Transaction Overview'!$D$2:$D$1850,'Transaction Overview'!$I$2:$I$1850,$A16,'Transaction Overview'!$H$2:$H$1850,I$4) -> 0 | ... M16: =SUMIFS('Transaction Overview'!$D$2:$D$1850,'Transaction Overview'!$I$2:$I$1850,$A16,'Transaction Overview'!$H$2:$H$1850,M$4) -> 0 | N16: =SUM(B16:M16) -> 85700
A17: Incoming Commission: Edge Builder | B17: =SUMIFS('Transaction Overview'!$D$2:$D$1850,'Transaction Overview'!$I$2:$I$1850,$A17,'Transaction Overview'!$H$2:$H$1850,B$4) -> 61037 | C17: =SUMIFS('Transaction Overview'!$D$2:$D$1850,'Transaction Overview'!$I$2:$I$1850,$A17,'Transaction Overview'!$H$2:$H$1850,C$4) -> 0 | D17: =SUMIFS('Transaction Overview'!$D$2:$D$1850,'Transaction Overview'!$I$2:$I$1850,$A17,'Transaction Overview'!$H$2:$H$1850,D$4) -> 0 | E17: =SUMIFS('Transaction Overview'!$D$2:$D$1850,'Transaction Overview'!$I$2:$I$1850,$A17,'Transaction Overview'!$H$2:$H$1850,E$4) -> 0 | F17: =SUMIFS('Transaction Overview'!$D$2:$D$1850,'Transaction Overview'!$I$2:$I$1850,$A17,'Transaction Overview'!$H$2:$H$1850,F$4) -> 0 | G17: =SUMIFS('Transaction Overview'!$D$2:$D$1850,'Transaction Overview'!$I$2:$I$1850,$A17,'Transaction Overview'!$H$2:$H$1850,G$4) -> 0 | H17: =SUMIFS('Transaction Overview'!$D$2:$D$1850,'Transaction Overview'!$I$2:$I$1850,$A17,'Transaction Overview'!$H$2:$H$1850,H$4) -> 0 | I17: =SUMIFS('Transaction Overview'!$D$2:$D$1850,'Transaction Overview'!$I$2:$I$1850,$A17,'Transaction Overview'!$H$2:$H$1850,I$4) -> 0 | ... M17: =SUMIFS('Transaction Overview'!$D$2:$D$1850,'Transaction Overview'!$I$2:$I$1850,$A17,'Transaction Overview'!$H$2:$H$1850,M$4) -> 0 | N17: =SUM(B17:M17) -> 61037
A18: Commissions — Outgoing
A19: Commission Paid: Brian Bowis (Charlmont) | B19: =SUMIFS('Transaction Overview'!$D$2:$D$1850,'Transaction Overview'!$I$2:$I$1850,$A19,'Transaction Overview'!$H$2:$H$1850,B$4) -> 0 | C19: =SUMIFS('Transaction Overview'!$D$2:$D$1850,'Transaction Overview'!$I$2:$I$1850,$A19,'Transaction Overview'!$H$2:$H$1850,C$4) -> 0 | D19: =SUMIFS('Transaction Overview'!$D$2:$D$1850,'Transaction Overview'!$I$2:$I$1850,$A19,'Transaction Overview'!$H$2:$H$1850,D$4) -> 0 | E19: =SUMIFS('Transaction Overview'!$D$2:$D$1850,'Transaction Overview'!$I$2:$I$1850,$A19,'Transaction Overview'!$H$2:$H$1850,E$4) -> 0 | F19: =SUMIFS('Transaction Overview'!$D$2:$D$1850,'Transaction Overview'!$I$2:$I$1850,$A19,'Transaction Overview'!$H$2:$H$1850,F$4) -> 0 | G19: =SUMIFS('Transaction Overview'!$D$2:$D$1850,'Transaction Overview'!$I$2:$I$1850,$A19,'Transaction Overview'!$H$2:$H$1850,G$4) -> 0 | H19: =SUMIFS('Transaction Overview'!$D$2:$D$1850,'Transaction Overview'!$I$2:$I$1850,$A19,'Transaction Overview'!$H$2:$H$1850,H$4) -> 0 | I19: =SUMIFS('Transaction Overview'!$D$2:$D$1850,'Transaction Overview'!$I$2:$I$1850,$A19,'Transaction Overview'!$H$2:$H$1850,I$4) -> 0 | ... M19: =SUMIFS('Transaction Overview'!$D$2:$D$1850,'Transaction Overview'!$I$2:$I$1850,$A19,'Transaction Overview'!$H$2:$H$1850,M$4) -> -102500 | N19: =SUM(B19:M19) -> -102500
A20: MAG Pass-Through
A21: Due to Andrew – MAG Pass-Through 30% | B21: =SUMIFS('Transaction Overview'!$D$2:$D$1850,'Transaction Overview'!$I$2:$I$1850,$A21,'Transaction Overview'!$H$2:$H$1850,B$4) -> 0 | C21: =SUMIFS('Transaction Overview'!$D$2:$D$1850,'Transaction Overview'!$I$2:$I$1850,$A21,'Transaction Overview'!$H$2:$H$1850,C$4) -> -114028.02 | D21: =SUMIFS('Transaction Overview'!$D$2:$D$1850,'Transaction Overview'!$I$2:$I$1850,$A21,'Transaction Overview'!$H$2:$H$1850,D$4) -> 0 | E21: =SUMIFS('Transaction Overview'!$D$2:$D$1850,'Transaction Overview'!$I$2:$I$1850,$A21,'Transaction Overview'!$H$2:$H$1850,E$4) -> 0 | F21: =SUMIFS('Transaction Overview'!$D$2:$D$1850,'Transaction Overview'!$I$2:$I$1850,$A21,'Transaction Overview'!$H$2:$H$1850,F$4) -> 0 | G21: =SUMIFS('Transaction Overview'!$D$2:$D$1850,'Transaction Overview'!$I$2:$I$1850,$A21,'Transaction Overview'!$H$2:$H$1850,G$4) -> 0 | H21: =SUMIFS('Transaction Overview'!$D$2:$D$1850,'Transaction Overview'!$I$2:$I$1850,$A21,'Transaction Overview'!$H$2:$H$1850,H$4) -> 0 | I21: =SUMIFS('Transaction Overview'!$D$2:$D$1850,'Transaction Overview'!$I$2:$I$1850,$A21,'Transaction Overview'!$H$2:$H$1850,I$4) -> 0 | ... M21: =SUMIFS('Transaction Overview'!$D$2:$D$1850,'Transaction Overview'!$I$2:$I$1850,$A21,'Transaction Overview'!$H$2:$H$1850,M$4) -> 0 | N21: =SUM(B21:M21) -> -114028.02
A22: Due to Andrew – MAG Pass-Through 30% | B22: =SUMIFS('Transaction Overview'!$D$2:$D$1850,'Transaction Overview'!$I$2:$I$1850,$A22,'Transaction Overview'!$H$2:$H$1850,B$4) -> 0 | C22: =SUMIFS('Transaction Overview'!$D$2:$D$1850,'Transaction Overview'!$I$2:$I$1850,$A22,'Transaction Overview'!$H$2:$H$1850,C$4) -> -15300 | D22: =SUMIFS('Transaction Overview'!$D$2:$D$1850,'Transaction Overview'!$I$2:$I$1850,$A22,'Transaction Overview'!$H$2:$H$1850,D$4) -> 0 | E22: =SUMIFS('Transaction Overview'!$D$2:$D$1850,'Transaction Overview'!$I$2:$I$1850,$A22,'Transaction Overview'!$H$2:$H$1850,E$4) -> 0 | F22: =SUMIFS('Transaction Overview'!$D$2:$D$1850,'Transaction Overview'!$I$2:$I$1850,$A22,'Transaction Overview'!$H$2:$H$1850,F$4) -> 0 | G22: =SUMIFS('Transaction Overview'!$D$2:$D$1850,'Transaction Overview'!$I$2:$I$1850,$A22,'Transaction Overview'!$H$2:$H$1850,G$4) -> 0 | H22: =SUMIFS('Transaction Overview'!$D$2:$D$1850,'Transaction Overview'!$I$2:$I$1850,$A22,'Transaction Overview'!$H$2:$H$1850,H$4) -> 0 | I22: =SUMIFS('Transaction Overview'!$D$2:$D$1850,'Transaction Overview'!$I$2:$I$1850,$A22,'Transaction Overview'!$H$2:$H$1850,I$4) -> -25500 | ... M22: =SUMIFS('Transaction Overview'!$D$2:$D$1850,'Transaction Overview'!$I$2:$I$1850,$A22,'Transaction Overview'!$H$2:$H$1850,M$4) -> 0 | N22: =SUM(B22:M22) -> -83437
A23: Due to Dax – MAG Pass-Through 70% | B23: =SUMIFS('Transaction Overview'!$D$2:$D$1850,'Transaction Overview'!$I$2:$I$1850,$A23,'Transaction Overview'!$H$2:$H$1850,B$4) -> 0 | C23: =SUMIFS('Transaction Overview'!$D$2:$D$1850,'Transaction Overview'!$I$2:$I$1850,$A23,'Transaction Overview'!$H$2:$H$1850,C$4) -> -295765.37 | D23: =SUMIFS('Transaction Overview'!$D$2:$D$1850,'Transaction Overview'!$I$2:$I$1850,$A23,'Transaction Overview'!$H$2:$H$1850,D$4) -> 0 | E23: =SUMIFS('Transaction Overview'!$D$2:$D$1850,'Transaction Overview'!$I$2:$I$1850,$A23,'Transaction Overview'!$H$2:$H$1850,E$4) -> 0 | F23: =SUMIFS('Transaction Overview'!$D$2:$D$1850,'Transaction Overview'!$I$2:$I$1850,$A23,'Transaction Overview'!$H$2:$H$1850,F$4) -> 0 | G23: =SUMIFS('Transaction Overview'!$D$2:$D$1850,'Transaction Overview'!$I$2:$I$1850,$A23,'Transaction Overview'!$H$2:$H$1850,G$4) -> 0 | H23: =SUMIFS('Transaction Overview'!$D$2:$D$1850,'Transaction Overview'!$I$2:$I$1850,$A23,'Transaction Overview'!$H$2:$H$1850,H$4) -> 0 | I23: =SUMIFS('Transaction Overview'!$D$2:$D$1850,'Transaction Overview'!$I$2:$I$1850,$A23,'Transaction Overview'!$H$2:$H$1850,I$4) -> -59500 | ... M23: =SUMIFS('Transaction Overview'!$D$2:$D$1850,'Transaction Overview'!$I$2:$I$1850,$A23,'Transaction Overview'!$H$2:$H$1850,M$4) -> 0 | N23: =SUM(B23:M23) -> -454752.37
A24: MAG - Admeer Advisory Transfer | B24: =SUMIFS('Transaction Overview'!$D$2:$D$1850,'Transaction Overview'!$I$2:$I$1850,$A24,'Transaction Overview'!$H$2:$H$1850,B$4) -> 0 | C24: =SUMIFS('Transaction Overview'!$D$2:$D$1850,'Transaction Overview'!$I$2:$I$1850,$A24,'Transaction Overview'!$H$2:$H$1850,C$4) -> 0 | D24: =SUMIFS('Transaction Overview'!$D$2:$D$1850,'Transaction Overview'!$I$2:$I$1850,$A24,'Transaction Overview'!$H$2:$H$1850,D$4) -> 0 | E24: =SUMIFS('Transaction Overview'!$D$2:$D$1850,'Transaction Overview'!$I$2:$I$1850,$A24,'Transaction Overview'!$H$2:$H$1850,E$4) -> 0 | F24: =SUMIFS('Transaction Overview'!$D$2:$D$1850,'Transaction Overview'!$I$2:$I$1850,$A24,'Transaction Overview'!$H$2:$H$1850,F$4) -> 0 | G24: =SUMIFS('Transaction Overview'!$D$2:$D$1850,'Transaction Overview'!$I$2:$I$1850,$A24,'Transaction Overview'!$H$2:$H$1850,G$4) -> 0 | H24: =SUMIFS('Transaction Overview'!$D$2:$D$1850,'Transaction Overview'!$I$2:$I$1850,$A24,'Transaction Overview'!$H$2:$H$1850,H$4) -> 0 | I24: =SUMIFS('Transaction Overview'!$D$2:$D$1850,'Transaction Overview'!$I$2:$I$1850,$A24,'Transaction Overview'!$H$2:$H$1850,I$4) -> 0 | ... M24: =SUMIFS('Transaction Overview'!$D$2:$D$1850,'Transaction Overview'!$I$2:$I$1850,$A24,'Transaction Overview'!$H$2:$H$1850,M$4) -> -10000 | N24: =SUM(B24:M24) -> -10000
A25: MAG Capital Partners Pass-Through Wire – 70/30 Split | B25: =SUMIFS('Transaction Overview'!$D$2:$D$1850,'Transaction Overview'!$I$2:$I$1850,$A25,'Transaction Overview'!$H$2:$H$1850,B$4) -> 0 | C25: =SUMIFS('Transaction Overview'!$D$2:$D$1850,'Transaction Overview'!$I$2:$I$1850,$A25,'Transaction Overview'!$H$2:$H$1850,C$4) -> 50000 | D25: =SUMIFS('Transaction Overview'!$D$2:$D$1850,'Transaction Overview'!$I$2:$I$1850,$A25,'Transaction Overview'!$H$2:$H$1850,D$4) -> 0 | E25: =SUMIFS('Transaction Overview'!$D$2:$D$1850,'Transaction Overview'!$I$2:$I$1850,$A25,'Transaction Overview'!$H$2:$H$1850,E$4) -> 0 | F25: =SUMIFS('Transaction Overview'!$D$2:$D$1850,'Transaction Overview'!$I$2:$I$1850,$A25,'Transaction Overview'!$H$2:$H$1850,F$4) -> 0 | G25: =SUMIFS('Transaction Overview'!$D$2:$D$1850,'Transaction Overview'!$I$2:$I$1850,$A25,'Transaction Overview'!$H$2:$H$1850,G$4) -> 0 | H25: =SUMIFS('Transaction Overview'!$D$2:$D$1850,'Transaction Overview'!$I$2:$I$1850,$A25,'Transaction Overview'!$H$2:$H$1850,H$4) -> 170000 | I25: =SUMIFS('Transaction Overview'!$D$2:$D$1850,'Transaction Overview'!$I$2:$I$1850,$A25,'Transaction Overview'!$H$2:$H$1850,I$4) -> 0 | ... M25: =SUMIFS('Transaction Overview'!$D$2:$D$1850,'Transaction Overview'!$I$2:$I$1850,$A25,'Transaction Overview'!$H$2:$H$1850,M$4) -> 0 | N25: =SUM(B25:M25) -> 365125
A26: Poseidon Asset Group
A27: Poseidon Asset Group (Incoming) | B27: =SUMIFS('Transaction Overview'!$D$2:$D$1850,'Transaction Overview'!$I$2:$I$1850,$A27,'Transaction Overview'!$H$2:$H$1850,B$4) -> 0 | C27: =SUMIFS('Transaction Overview'!$D$2:$D$1850,'Transaction Overview'!$I$2:$I$1850,$A27,'Transaction Overview'!$H$2:$H$1850,C$4) -> 0 | D27: =SUMIFS('Transaction Overview'!$D$2:$D$1850,'Transaction Overview'!$I$2:$I$1850,$A27,'Transaction Overview'!$H$2:$H$1850,D$4) -> 0 | E27: =SUMIFS('Transaction Overview'!$D$2:$D$1850,'Transaction Overview'!$I$2:$I$1850,$A27,'Transaction Overview'!$H$2:$H$1850,E$4) -> 0 | F27: =SUMIFS('Transaction Overview'!$D$2:$D$1850,'Transaction Overview'!$I$2:$I$1850,$A27,'Transaction Overview'!$H$2:$H$1850,F$4) -> 0 | G27: =SUMIFS('Transaction Overview'!$D$2:$D$1850,'Transaction Overview'!$I$2:$I$1850,$A27,'Transaction Overview'!$H$2:$H$1850,G$4) -> 63000 | H27: =SUMIFS('Transaction Overview'!$D$2:$D$1850,'Transaction Overview'!$I$2:$I$1850,$A27,'Transaction Overview'!$H$2:$H$1850,H$4) -> 80000 | I27: =SUMIFS('Transaction Overview'!$D$2:$D$1850,'Transaction Overview'!$I$2:$I$1850,$A27,'Transaction Overview'!$H$2:$H$1850,I$4) -> 30000 | ... M27: =SUMIFS('Transaction Overview'!$D$2:$D$1850,'Transaction Overview'!$I$2:$I$1850,$A27,'Transaction Overview'!$H$2:$H$1850,M$4) -> 50000 | N27: =SUM(B27:M27) -> 423000
A28: Transfer From Poseidon Asset Group | B28: =SUMIFS('Transaction Overview'!$D$2:$D$1850,'Transaction Overview'!$I$2:$I$1850,$A28,'Transaction Overview'!$H$2:$H$1850,B$4) -> 30000 | C28: =SUMIFS('Transaction Overview'!$D$2:$D$1850,'Transaction Overview'!$I$2:$I$1850,$A28,'Transaction Overview'!$H$2:$H$1850,C$4) -> 50000 | D28: =SUMIFS('Transaction Overview'!$D$2:$D$1850,'Transaction Overview'!$I$2:$I$1850,$A28,'Transaction Overview'!$H$2:$H$1850,D$4) -> 105000 | E28: =SUMIFS('Transaction Overview'!$D$2:$D$1850,'Transaction Overview'!$I$2:$I$1850,$A28,'Transaction Overview'!$H$2:$H$1850,E$4) -> 30000 | F28: =SUMIFS('Transaction Overview'!$D$2:$D$1850,'Transaction Overview'!$I$2:$I$1850,$A28,'Transaction Overview'!$H$2:$H$1850,F$4) -> 40000 | G28: =SUMIFS('Transaction Overview'!$D$2:$D$1850,'Transaction Overview'!$I$2:$I$1850,$A28,'Transaction Overview'!$H$2:$H$1850,G$4) -> 0 | H28: =SUMIFS('Transaction Overview'!$D$2:$D$1850,'Transaction Overview'!$I$2:$I$1850,$A28,'Transaction Overview'!$H$2:$H$1850,H$4) -> 0 | I28: =SUMIFS('Transaction Overview'!$D$2:$D$1850,'Transaction Overview'!$I$2:$I$1850,$A28,'Transaction Overview'!$H$2:$H$1850,I$4) -> 0 | ... M28: =SUMIFS('Transaction Overview'!$D$2:$D$1850,'Transaction Overview'!$I$2:$I$1850,$A28,'Transaction Overview'!$H$2:$H$1850,M$4) -> 0 | N28: =SUM(B28:M28) -> 255000
A29: Transfer to Poseidon | B29: =SUMIFS('Transaction Overview'!$D$2:$D$1850,'Transaction Overview'!$I$2:$I$1850,$A29,'Transaction Overview'!$H$2:$H$1850,B$4) -> 0 | C29: =SUMIFS('Transaction Overview'!$D$2:$D$1850,'Transaction Overview'!$I$2:$I$1850,$A29,'Transaction Overview'!$H$2:$H$1850,C$4) -> 0 | D29: =SUMIFS('Transaction Overview'!$D$2:$D$1850,'Transaction Overview'!$I$2:$I$1850,$A29,'Transaction Overview'!$H$2:$H$1850,D$4) -> 0 | E29: =SUMIFS('Transaction Overview'!$D$2:$D$1850,'Transaction Overview'!$I$2:$I$1850,$A29,'Transaction Overview'!$H$2:$H$1850,E$4) -> 0 | F29: =SUMIFS('Transaction Overview'!$D$2:$D$1850,'Transaction Overview'!$I$2:$I$1850,$A29,'Transaction Overview'!$H$2:$H$1850,F$4) -> 0 | G29: =SUMIFS('Transaction Overview'!$D$2:$D$1850,'Transaction Overview'!$I$2:$I$1850,$A29,'Transaction Overview'!$H$2:$H$1850,G$4) -> 0 | H29: =SUMIFS('Transaction Overview'!$D$2:$D$1850,'Transaction Overview'!$I$2:$I$1850,$A29,'Transaction Overview'!$H$2:$H$1850,H$4) -> 0 | I29: =SUMIFS('Transaction Overview'!$D$2:$D$1850,'Transaction Overview'!$I$2:$I$1850,$A29,'Transaction Overview'!$H$2:$H$1850,I$4) -> 0 | ... M29: =SUMIFS('Transaction Overview'!$D$2:$D$1850,'Transaction Overview'!$I$2:$I$1850,$A29,'Transaction Overview'!$H$2:$H$1850,M$4) -> 0 | N29: =SUM(B29:M29) -> -5000
A30: Intercompany & Savings Transfers
A31: DWG Capital Partners - Outgoing | B31: =SUMIFS('Transaction Overview'!$D$2:$D$1850,'Transaction Overview'!$I$2:$I$1850,$A31,'Transaction Overview'!$H$2:$H$1850,B$4) -> 0 | C31: =SUMIFS('Transaction Overview'!$D$2:$D$1850,'Transaction Overview'!$I$2:$I$1850,$A31,'Transaction Overview'!$H$2:$H$1850,C$4) -> 0 | D31: =SUMIFS('Transaction Overview'!$D$2:$D$1850,'Transaction Overview'!$I$2:$I$1850,$A31,'Transaction Overview'!$H$2:$H$1850,D$4) -> 0 | E31: =SUMIFS('Transaction Overview'!$D$2:$D$1850,'Transaction Overview'!$I$2:$I$1850,$A31,'Transaction Overview'!$H$2:$H$1850,E$4) -> 0 | F31: =SUMIFS('Transaction Overview'!$D$2:$D$1850,'Transaction Overview'!$I$2:$I$1850,$A31,'Transaction Overview'!$H$2:$H$1850,F$4) -> 0 | G31: =SUMIFS('Transaction Overview'!$D$2:$D$1850,'Transaction Overview'!$I$2:$I$1850,$A31,'Transaction Overview'!$H$2:$H$1850,G$4) -> -2000 | H31: =SUMIFS('Transaction Overview'!$D$2:$D$1850,'Transaction Overview'!$I$2:$I$1850,$A31,'Transaction Overview'!$H$2:$H$1850,H$4) -> 0 | I31: =SUMIFS('Transaction Overview'!$D$2:$D$1850,'Transaction Overview'!$I$2:$I$1850,$A31,'Transaction Overview'!$H$2:$H$1850,I$4) -> 0 | ... M31: =SUMIFS('Transaction Overview'!$D$2:$D$1850,'Transaction Overview'!$I$2:$I$1850,$A31,'Transaction Overview'!$H$2:$H$1850,M$4) -> -1000 | N31: =SUM(B31:M31) -> -90500
A32: Internal Transfer | B32: =SUMIFS('Transaction Overview'!$D$2:$D$1850,'Transaction Overview'!$I$2:$I$1850,$A32,'Transaction Overview'!$H$2:$H$1850,B$4) -> 0 | C32: =SUMIFS('Transaction Overview'!$D$2:$D$1850,'Transaction Overview'!$I$2:$I$1850,$A32,'Transaction Overview'!$H$2:$H$1850,C$4) -> 0 | D32: =SUMIFS('Transaction Overview'!$D$2:$D$1850,'Transaction Overview'!$I$2:$I$1850,$A32,'Transaction Overview'!$H$2:$H$1850,D$4) -> 0 | E32: =SUMIFS('Transaction Overview'!$D$2:$D$1850,'Transaction Overview'!$I$2:$I$1850,$A32,'Transaction Overview'!$H$2:$H$1850,E$4) -> 0 | F32: =SUMIFS('Transaction Overview'!$D$2:$D$1850,'Transaction Overview'!$I$2:$I$1850,$A32,'Transaction Overview'!$H$2:$H$1850,F$4) -> 0 | G32: =SUMIFS('Transaction Overview'!$D$2:$D$1850,'Transaction Overview'!$I$2:$I$1850,$A32,'Transaction Overview'!$H$2:$H$1850,G$4) -> 20000 | H32: =SUMIFS('Transaction Overview'!$D$2:$D$1850,'Transaction Overview'!$I$2:$I$1850,$A32,'Transaction Overview'!$H$2:$H$1850,H$4) -> 0 | I32: =SUMIFS('Transaction Overview'!$D$2:$D$1850,'Transaction Overview'!$I$2:$I$1850,$A32,'Transaction Overview'!$H$2:$H$1850,I$4) -> 0 | ... M32: =SUMIFS('Transaction Overview'!$D$2:$D$1850,'Transaction Overview'!$I$2:$I$1850,$A32,'Transaction Overview'!$H$2:$H$1850,M$4) -> 0 | N32: =SUM(B32:M32) -> 20000
A33: Transfer From Butler Weldments | B33: =SUMIFS('Transaction Overview'!$D$2:$D$1850,'Transaction Overview'!$I$2:$I$1850,$A33,'Transaction Overview'!$H$2:$H$1850,B$4) -> 0 | C33: =SUMIFS('Transaction Overview'!$D$2:$D$1850,'Transaction Overview'!$I$2:$I$1850,$A33,'Transaction Overview'!$H$2:$H$1850,C$4) -> 0 | D33: =SUMIFS('Transaction Overview'!$D$2:$D$1850,'Transaction Overview'!$I$2:$I$1850,$A33,'Transaction Overview'!$H$2:$H$1850,D$4) -> 1500 | E33: =SUMIFS('Transaction Overview'!$D$2:$D$1850,'Transaction Overview'!$I$2:$I$1850,$A33,'Transaction Overview'!$H$2:$H$1850,E$4) -> 0 | F33: =SUMIFS('Transaction Overview'!$D$2:$D$1850,'Transaction Overview'!$I$2:$I$1850,$A33,'Transaction Overview'!$H$2:$H$1850,F$4) -> 0 | G33: =SUMIFS('Transaction Overview'!$D$2:$D$1850,'Transaction Overview'!$I$2:$I$1850,$A33,'Transaction Overview'!$H$2:$H$1850,G$4) -> 0 | H33: =SUMIFS('Transaction Overview'!$D$2:$D$1850,'Transaction Overview'!$I$2:$I$1850,$A33,'Transaction Overview'!$H$2:$H$1850,H$4) -> 0 | I33: =SUMIFS('Transaction Overview'!$D$2:$D$1850,'Transaction Overview'!$I$2:$I$1850,$A33,'Transaction Overview'!$H$2:$H$1850,I$4) -> 0 | ... M33: =SUMIFS('Transaction Overview'!$D$2:$D$1850,'Transaction Overview'!$I$2:$I$1850,$A33,'Transaction Overview'!$H$2:$H$1850,M$4) -> 0 | N33: =SUM(B33:M33) -> 1500
A34: Transfer From DWG Capital Partners | B34: =SUMIFS('Transaction Overview'!$D$2:$D$1850,'Transaction Overview'!$I$2:$I$1850,$A34,'Transaction Overview'!$H$2:$H$1850,B$4) -> 0 | C34: =SUMIFS('Transaction Overview'!$D$2:$D$1850,'Transaction Overview'!$I$2:$I$1850,$A34,'Transaction Overview'!$H$2:$H$1850,C$4) -> 5000 | D34: =SUMIFS('Transaction Overview'!$D$2:$D$1850,'Transaction Overview'!$I$2:$I$1850,$A34,'Transaction Overview'!$H$2:$H$1850,D$4) -> 0 | E34: =SUMIFS('Transaction Overview'!$D$2:$D$1850,'Transaction Overview'!$I$2:$I$1850,$A34,'Transaction Overview'!$H$2:$H$1850,E$4) -> 0 | F34: =SUMIFS('Transaction Overview'!$D$2:$D$1850,'Transaction Overview'!$I$2:$I$1850,$A34,'Transaction Overview'!$H$2:$H$1850,F$4) -> 0 | G34: =SUMIFS('Transaction Overview'!$D$2:$D$1850,'Transaction Overview'!$I$2:$I$1850,$A34,'Transaction Overview'!$H$2:$H$1850,G$4) -> 0 | H34: =SUMIFS('Transaction Overview'!$D$2:$D$1850,'Transaction Overview'!$I$2:$I$1850,$A34,'Transaction Overview'!$H$2:$H$1850,H$4) -> 0 | I34: =SUMIFS('Transaction Overview'!$D$2:$D$1850,'Transaction Overview'!$I$2:$I$1850,$A34,'Transaction Overview'!$H$2:$H$1850,I$4) -> 0 | ... M34: =SUMIFS('Transaction Overview'!$D$2:$D$1850,'Transaction Overview'!$I$2:$I$1850,$A34,'Transaction Overview'!$H$2:$H$1850,M$4) -> 0 | N34: =SUM(B34:M34) -> 5000
A35: Transfer to Breese Marketing | B35: =SUMIFS('Transaction Overview'!$D$2:$D$1850,'Transaction Overview'!$I$2:$I$1850,$A35,'Transaction Overview'!$H$2:$H$1850,B$4) -> 0 | C35: =SUMIFS('Transaction Overview'!$D$2:$D$1850,'Transaction Overview'!$I$2:$I$1850,$A35,'Transaction Overview'!$H$2:$H$1850,C$4) -> 0 | D35: =SUMIFS('Transaction Overview'!$D$2:$D$1850,'Transaction Overview'!$I$2:$I$1850,$A35,'Transaction Overview'!$H$2:$H$1850,D$4) -> 0 | E35: =SUMIFS('Transaction Overview'!$D$2:$D$1850,'Transaction Overview'!$I$2:$I$1850,$A35,'Transaction Overview'!$H$2:$H$1850,E$4) -> 0 | F35: =SUMIFS('Transaction Overview'!$D$2:$D$1850,'Transaction Overview'!$I$2:$I$1850,$A35,'Transaction Overview'!$H$2:$H$1850,F$4) -> 0 | G35: =SUMIFS('Transaction Overview'!$D$2:$D$1850,'Transaction Overview'!$I$2:$I$1850,$A35,'Transaction Overview'!$H$2:$H$1850,G$4) -> -500 | H35: =SUMIFS('Transaction Overview'!$D$2:$D$1850,'Transaction Overview'!$I$2:$I$1850,$A35,'Transaction Overview'!$H$2:$H$1850,H$4) -> 0 | I35: =SUMIFS('Transaction Overview'!$D$2:$D$1850,'Transaction Overview'!$I$2:$I$1850,$A35,'Transaction Overview'!$H$2:$H$1850,I$4) -> 0 | ... M35: =SUMIFS('Transaction Overview'!$D$2:$D$1850,'Transaction Overview'!$I$2:$I$1850,$A35,'Transaction Overview'!$H$2:$H$1850,M$4) -> 0 | N35: =SUM(B35:M35) -> -500
A36: Transfer to DWG Capital Group_Costar | B36: =SUMIFS('Transaction Overview'!$D$2:$D$1850,'Transaction Overview'!$I$2:$I$1850,$A36,'Transaction Overview'!$H$2:$H$1850,B$4) -> 0 | C36: =SUMIFS('Transaction Overview'!$D$2:$D$1850,'Transaction Overview'!$I$2:$I$1850,$A36,'Transaction Overview'!$H$2:$H$1850,C$4) -> 0 | D36: =SUMIFS('Transaction Overview'!$D$2:$D$1850,'Transaction Overview'!$I$2:$I$1850,$A36,'Transaction Overview'!$H$2:$H$1850,D$4) -> 0 | E36: =SUMIFS('Transaction Overview'!$D$2:$D$1850,'Transaction Overview'!$I$2:$I$1850,$A36,'Transaction Overview'!$H$2:$H$1850,E$4) -> 0 | F36: =SUMIFS('Transaction Overview'!$D$2:$D$1850,'Transaction Overview'!$I$2:$I$1850,$A36,'Transaction Overview'!$H$2:$H$1850,F$4) -> -5000 | G36: =SUMIFS('Transaction Overview'!$D$2:$D$1850,'Transaction Overview'!$I$2:$I$1850,$A36,'Transaction Overview'!$H$2:$H$1850,G$4) -> 0 | H36: =SUMIFS('Transaction Overview'!$D$2:$D$1850,'Transaction Overview'!$I$2:$I$1850,$A36,'Transaction Overview'!$H$2:$H$1850,H$4) -> 0 | I36: =SUMIFS('Transaction Overview'!$D$2:$D$1850,'Transaction Overview'!$I$2:$I$1850,$A36,'Transaction Overview'!$H$2:$H$1850,I$4) -> -1000 | ... M36: =SUMIFS('Transaction Overview'!$D$2:$D$1850,'Transaction Overview'!$I$2:$I$1850,$A36,'Transaction Overview'!$H$2:$H$1850,M$4) -> 0 | N36: =SUM(B36:M36) -> -9000
A37: Transfer to DWG Savings | B37: =SUMIFS('Transaction Overview'!$D$2:$D$1850,'Transaction Overview'!$I$2:$I$1850,$A37,'Transaction Overview'!$H$2:$H$1850,B$4) -> -1000 | C37: =SUMIFS('Transaction Overview'!$D$2:$D$1850,'Transaction Overview'!$I$2:$I$1850,$A37,'Transaction Overview'!$H$2:$H$1850,C$4) -> -1000 | D37: =SUMIFS('Transaction Overview'!$D$2:$D$1850,'Transaction Overview'!$I$2:$I$1850,$A37,'Transaction Overview'!$H$2:$H$1850,D$4) -> -1000 | E37: =SUMIFS('Transaction Overview'!$D$2:$D$1850,'Transaction Overview'!$I$2:$I$1850,$A37,'Transaction Overview'!$H$2:$H$1850,E$4) -> 0 | F37: =SUMIFS('Transaction Overview'!$D$2:$D$1850,'Transaction Overview'!$I$2:$I$1850,$A37,'Transaction Overview'!$H$2:$H$1850,F$4) -> -1800 | G37: =SUMIFS('Transaction Overview'!$D$2:$D$1850,'Transaction Overview'!$I$2:$I$1850,$A37,'Transaction Overview'!$H$2:$H$1850,G$4) -> -1500 | H37: =SUMIFS('Transaction Overview'!$D$2:$D$1850,'Transaction Overview'!$I$2:$I$1850,$A37,'Transaction Overview'!$H$2:$H$1850,H$4) -> -2000 | I37: =SUMIFS('Transaction Overview'!$D$2:$D$1850,'Transaction Overview'!$I$2:$I$1850,$A37,'Transaction Overview'!$H$2:$H$1850,I$4) -> -2000 | ... M37: =SUMIFS('Transaction Overview'!$D$2:$D$1850,'Transaction Overview'!$I$2:$I$1850,$A37,'Transaction Overview'!$H$2:$H$1850,M$4) -> 0 | N37: =SUM(B37:M37) -> -15300
A38: Transfer to DWG Capital Partners | B38: =SUMIFS('Transaction Overview'!$D$2:$D$1850,'Transaction Overview'!$I$2:$I$1850,$A38,'Transaction Overview'!$H$2:$H$1850,B$4) -> 0 | C38: =SUMIFS('Transaction Overview'!$D$2:$D$1850,'Transaction Overview'!$I$2:$I$1850,$A38,'Transaction Overview'!$H$2:$H$1850,C$4) -> 0 | D38: =SUMIFS('Transaction Overview'!$D$2:$D$1850,'Transaction Overview'!$I$2:$I$1850,$A38,'Transaction Overview'!$H$2:$H$1850,D$4) -> 0 | E38: =SUMIFS('Transaction Overview'!$D$2:$D$1850,'Transaction Overview'!$I$2:$I$1850,$A38,'Transaction Overview'!$H$2:$H$1850,E$4) -> 0 | F38: =SUMIFS('Transaction Overview'!$D$2:$D$1850,'Transaction Overview'!$I$2:$I$1850,$A38,'Transaction Overview'!$H$2:$H$1850,F$4) -> -1000 | G38: =SUMIFS('Transaction Overview'!$D$2:$D$1850,'Transaction Overview'!$I$2:$I$1850,$A38,'Transaction Overview'!$H$2:$H$1850,G$4) -> 0 | H38: =SUMIFS('Transaction Overview'!$D$2:$D$1850,'Transaction Overview'!$I$2:$I$1850,$A38,'Transaction Overview'!$H$2:$H$1850,H$4) -> 0 | I38: =SUMIFS('Transaction Overview'!$D$2:$D$1850,'Transaction Overview'!$I$2:$I$1850,$A38,'Transaction Overview'!$H$2:$H$1850,I$4) -> 0 | ... M38: =SUMIFS('Transaction Overview'!$D$2:$D$1850,'Transaction Overview'!$I$2:$I$1850,$A38,'Transaction Overview'!$H$2:$H$1850,M$4) -> 0 | N38: =SUM(B38:M38) -> -1000
A39: Transfer to DWG Holdings | B39: =SUMIFS('Transaction Overview'!$D$2:$D$1850,'Transaction Overview'!$I$2:$I$1850,$A39,'Transaction Overview'!$H$2:$H$1850,B$4) -> 0 | C39: =SUMIFS('Transaction Overview'!$D$2:$D$1850,'Transaction Overview'!$I$2:$I$1850,$A39,'Transaction Overview'!$H$2:$H$1850,C$4) -> -100 | D39: =SUMIFS('Transaction Overview'!$D$2:$D$1850,'Transaction Overview'!$I$2:$I$1850,$A39,'Transaction Overview'!$H$2:$H$1850,D$4) -> 0 | E39: =SUMIFS('Transaction Overview'!$D$2:$D$1850,'Transaction Overview'!$I$2:$I$1850,$A39,'Transaction Overview'!$H$2:$H$1850,E$4) -> 0 | F39: =SUMIFS('Transaction Overview'!$D$2:$D$1850,'Transaction Overview'!$I$2:$I$1850,$A39,'Transaction Overview'!$H$2:$H$1850,F$4) -> 0 | G39: =SUMIFS('Transaction Overview'!$D$2:$D$1850,'Transaction Overview'!$I$2:$I$1850,$A39,'Transaction Overview'!$H$2:$H$1850,G$4) -> 0 | H39: =SUMIFS('Transaction Overview'!$D$2:$D$1850,'Transaction Overview'!$I$2:$I$1850,$A39,'Transaction Overview'!$H$2:$H$1850,H$4) -> 0 | I39: =SUMIFS('Transaction Overview'!$D$2:$D$1850,'Transaction Overview'!$I$2:$I$1850,$A39,'Transaction Overview'!$H$2:$H$1850,I$4) -> 0 | ... M39: =SUMIFS('Transaction Overview'!$D$2:$D$1850,'Transaction Overview'!$I$2:$I$1850,$A39,'Transaction Overview'!$H$2:$H$1850,M$4) -> 0 | N39: =SUM(B39:M39) -> -100
A40: Transfer to DWGCG_Costar | B40: =SUMIFS('Transaction Overview'!$D$2:$D$1850,'Transaction Overview'!$I$2:$I$1850,$A40,'Transaction Overview'!$H$2:$H$1850,B$4) -> -902.89 | C40: =SUMIFS('Transaction Overview'!$D$2:$D$1850,'Transaction Overview'!$I$2:$I$1850,$A40,'Transaction Overview'!$H$2:$H$1850,C$4) -> -3000 | D40: =SUMIFS('Transaction Overview'!$D$2:$D$1850,'Transaction Overview'!$I$2:$I$1850,$A40,'Transaction Overview'!$H$2:$H$1850,D$4) -> 0 | E40: =SUMIFS('Transaction Overview'!$D$2:$D$1850,'Transaction Overview'!$I$2:$I$1850,$A40,'Transaction Overview'!$H$2:$H$1850,E$4) -> 0 | F40: =SUMIFS('Transaction Overview'!$D$2:$D$1850,'Transaction Overview'!$I$2:$I$1850,$A40,'Transaction Overview'!$H$2:$H$1850,F$4) -> 0 | G40: =SUMIFS('Transaction Overview'!$D$2:$D$1850,'Transaction Overview'!$I$2:$I$1850,$A40,'Transaction Overview'!$H$2:$H$1850,G$4) -> 0 | H40: =SUMIFS('Transaction Overview'!$D$2:$D$1850,'Transaction Overview'!$I$2:$I$1850,$A40,'Transaction Overview'!$H$2:$H$1850,H$4) -> 0 | I40: =SUMIFS('Transaction Overview'!$D$2:$D$1850,'Transaction Overview'!$I$2:$I$1850,$A40,'Transaction Overview'!$H$2:$H$1850,I$4) -> 0 | ... M40: =SUMIFS('Transaction Overview'!$D$2:$D$1850,'Transaction Overview'!$I$2:$I$1850,$A40,'Transaction Overview'!$H$2:$H$1850,M$4) -> 0 | N40: =SUM(B40:M40) -> -3902.89
A41: Transfer to Ecomm_PosPrtnrs | B41: =SUMIFS('Transaction Overview'!$D$2:$D$1850,'Transaction Overview'!$I$2:$I$1850,$A41,'Transaction Overview'!$H$2:$H$1850,B$4) -> 10000 | C41: =SUMIFS('Transaction Overview'!$D$2:$D$1850,'Transaction Overview'!$I$2:$I$1850,$A41,'Transaction Overview'!$H$2:$H$1850,C$4) -> 0 | D41: =SUMIFS('Transaction Overview'!$D$2:$D$1850,'Transaction Overview'!$I$2:$I$1850,$A41,'Transaction Overview'!$H$2:$H$1850,D$4) -> 0 | E41: =SUMIFS('Transaction Overview'!$D$2:$D$1850,'Transaction Overview'!$I$2:$I$1850,$A41,'Transaction Overview'!$H$2:$H$1850,E$4) -> 0 | F41: =SUMIFS('Transaction Overview'!$D$2:$D$1850,'Transaction Overview'!$I$2:$I$1850,$A41,'Transaction Overview'!$H$2:$H$1850,F$4) -> 0 | G41: =SUMIFS('Transaction Overview'!$D$2:$D$1850,'Transaction Overview'!$I$2:$I$1850,$A41,'Transaction Overview'!$H$2:$H$1850,G$4) -> 0 | H41: =SUMIFS('Transaction Overview'!$D$2:$D$1850,'Transaction Overview'!$I$2:$I$1850,$A41,'Transaction Overview'!$H$2:$H$1850,H$4) -> 0 | I41: =SUMIFS('Transaction Overview'!$D$2:$D$1850,'Transaction Overview'!$I$2:$I$1850,$A41,'Transaction Overview'!$H$2:$H$1850,I$4) -> 0 | ... M41: =SUMIFS('Transaction Overview'!$D$2:$D$1850,'Transaction Overview'!$I$2:$I$1850,$A41,'Transaction Overview'!$H$2:$H$1850,M$4) -> 0 | N41: =SUM(B41:M41) -> 10000
...

Sheet Transfer In
A1: Chase 1168 — DWG Capital Group 2025 Activity
A2: Intercompany Transfers — In | Jan 2025 – Dec 2025
A4: SUMMARY
A5: Total | C5: =SUMIFS('Transaction Overview'!$D$2:$D$1850,'Transaction Overview'!$J$2:$J$1850,"Intercompany & Savings Transfers",'Transaction Overview'!$D$2:$D$1850,">0") -> 36500
A6: # Transactions | C6: =COUNTIFS('Transaction Overview'!$J$2:$J$1850,"Intercompany & Savings Transfers",'Transaction Overview'!$D$2:$D$1850,">0") -> 4

Sheet Transfer Out
A1: Chase 1168 — DWG Capital Group 2025 Activity
A2: Intercompany Transfers — Out | Jan 2025 – Dec 2025
A4: SUMMARY
A5: Total | C5: =SUMIFS('Transaction Overview'!$D$2:$D$1850,'Transaction Overview'!$J$2:$J$1850,"Intercompany & Savings Transfers",'Transaction Overview'!$D$2:$D$1850,"<0") -> -123202.89
A6: # Transactions | C6: =COUNTIFS('Transaction Overview'!$J$2:$J$1850,"Intercompany & Savings Transfers",'Transaction Overview'!$D$2:$D$1850,"<0") -> 33

Sheet Wire In
A1: Chase 1168 — DWG Capital Group 2025 Activity
A2: Wire Transfers — In | Jan 2025 – Dec 2025
A4: SUMMARY
A5: Total | C5: =SUMIFS('Transaction Overview'!$D$2:$D$1850,'Transaction Overview'!$J$2:$J$1850,"Intercompany & Savings Transfers",'Transaction Overview'!$D$2:$D$1850,">0") -> 36500
A6: # Transactions | C6: =COUNTIFS('Transaction Overview'!$J$2:$J$1850,"Intercompany & Savings Transfers",'Transaction Overview'!$D$2:$D$1850,">0") -> 4

Sheet Wire Out
A1: Chase 1168 — DWG Capital Group 2025 Activity
A2: Wire Transfers — Out | Jan 2025 – Dec 2025
A4: SUMMARY
A5: Total | C5: =SUMIFS('Transaction Overview'!$D$2:$D$1850,'Transaction Overview'!$J$2:$J$1850,"Intercompany & Savings Transfers",'Transaction Overview'!$D$2:$D$1850,"<0") -> -123202.89
A6: # Transactions | C6: =COUNTIFS('Transaction Overview'!$J$2:$J$1850,"Intercompany & Savings Transfers",'Transaction Overview'!$D$2:$D$1850,"<0") -> 33

Sheet Commission
A1: Chase 1168 — DWG Capital Group 2025 Activity
A2: Commissions Statement | Jan 2025 – Dec 2025
A4: SUMMARY
A5: Total | C5: =SUMIFS('Transaction Overview'!$D$2:$D$1850,'Transaction Overview'!$J$2:$J$1850,"Commissions — Incoming",'Transaction Overview'!$D$2:$D$1850,">0") -> 661437
A6: # Transactions | C6: =COUNTIFS('Transaction Overview'!$J$2:$J$1850,"Commissions — Incoming",'Transaction Overview'!$D$2:$D$1850,">0") -> 10

Sheet Transaction Overview
A1: Details | B1: Posting Date | C1: Description | D1: Amount | E1: Type | F1: Balance | G1: Category | H1: Month | I1: Combined Category | J1: Group
A2: =Chase1168_2025!A2 -> DEBIT | B2: =Chase1168_2025!B2 -> 46022 | C2: =Chase1168_2025!C2 -> ONLINE FX INTERNATIONAL WIRE FEE | D2: =Chase1168_2025!D2 -> -5 | E2: =Chase1168_2025!E2 -> FEE_TRANSACTION | F2: =Chase1168_2025!F2 -> 30206.23 | G2: =Chase1168_2025!G2 -> Andres Alarcon Payroll | H2: =IF($B2="","",DATE(YEAR($B2),MONTH($B2),1)) -> 45992 | I2: =IF($G2="","Uncategorized — Review",IFERROR(INDEX(Mapping!$B:$B,MATCH($G2,Mapping!$A:$A,0)),"Uncategorized — Review")) -> Andres Alarcon Payroll | J2: =IF($G2="","Uncategorized — Review",IFERROR(INDEX(Mapping!$C:$C,MATCH($G2,Mapping!$A:$A,0)),"Uncategorized — Review")) -> Payroll & Contractors
A3: =Chase1168_2025!A3 -> DEBIT | B3: =Chase1168_2025!B3 -> 46022 | C3: =Chase1168_2025!C3 -> ONLINE INTERNATIONAL WIRE TRANSFER A/C: FOREIGN CUR BUS ACCT BK 1 COLUMBUS NEWARK DE 197132107 US ORG: 00000000283681168 DWG CAPITAL GROUP BEN:/00714849981 MARIA FERNANDA ALARCON PIEDRAHITA REF: TAXID1017222855/TEL573207819186/SAV/SALARY/PAYROLL PAYMENTS/OCMT/COP26 49416,78/EXCH/3532.5557/CNTR/156111 34/INT/ANDRES_52763ATHOTMAIL.C TRN: 6879000365RE 12/31 | D3: =Chase1168_2025!D3 -> -750 | E3: =Chase1168_2025!E3 -> WIRE_OUTGOING | F3: =Chase1168_2025!F3 -> 30211.23 | G3: =Chase1168_2025!G3 -> Andres Alarcon Payroll | H3: =IF($B3="","",DATE(YEAR($B3),MONTH($B3),1)) -> 45992 | I3: =IF($G3="","Uncategorized — Review",IFERROR(INDEX(Mapping!$B:$B,MATCH($G3,Mapping!$A:$A,0)),"Uncategorized — Review")) -> Andres Alarcon Payroll | J3: =IF($G3="","Uncategorized — Review",IFERROR(INDEX(Mapping!$C:$C,MATCH($G3,Mapping!$A:$A,0)),"Uncategorized — Review")) -> Payroll & Contractors
A4: =Chase1168_2025!A4 -> DEBIT | B4: =Chase1168_2025!B4 -> 46022 | C4: =Chase1168_2025!C4 -> ORIG CO NAME:GEICO ORIG ID:3530075853 DESC DATE:251230 CO ENTRY DESCR:PREM COLL SEC:PPD TRACE#:021000020954890 EED:251231 IND ID: IND NAME:ANGELA TRN: 3650954890TC | D4: =Chase1168_2025!D4 -> -619.87 | E4: =Chase1168_2025!E4 -> ACH_DEBIT | F4: =Chase1168_2025!F4 -> 30961.23 | G4: =Chase1168_2025!G4 -> Personal - Car Insurance | H4: =IF($B4="","",DATE(YEAR($B4),MONTH($B4),1)) -> 45992 | I4: =IF($G4="","Uncategorized — Review",IFERROR(INDEX(Mapping!$B:$B,MATCH($G4,Mapping!$A:$A,0)),"Uncategorized — Review")) -> Personal - Car & Auto | J4: =IF($G4="","Uncategorized — Review",IFERROR(INDEX(Mapping!$C:$C,MATCH($G4,Mapping!$A:$A,0)),"Uncategorized — Review")) -> Personal — Owner
A5: =Chase1168_2025!A5 -> DEBIT | B5: =Chase1168_2025!B5 -> 46021 | C5: =Chase1168_2025!C5 -> ORIG CO NAME:SBA EIDL LOAN ORIG ID:7300000118 DESC DATE:251229 CO ENTRY DESCR:PAYMENT SEC:CCD TRACE#:041036049540812 EED:251230 IND ID:0000 IND NAME:JOHN DUNNING 1871308204 ACH TRANSACTION TRN: 3649540812TC | D5: =Chase1168_2025!D5 -> -2524 | E5: =Chase1168_2025!E5 -> ACH_DEBIT | F5: =Chase1168_2025!F5 -> 31581.1 | G5: =Chase1168_2025!G5 -> SBC EIDL Loan | H5: =IF($B5="","",DATE(YEAR($B5),MONTH($B5),1)) -> 45992 | I5: =IF($G5="","Uncategorized — Review",IFERROR(INDEX(Mapping!$B:$B,MATCH($G5,Mapping!$A:$A,0)),"Uncategorized — Review")) -> SBC EIDL Loan | J5: =IF($G5="","Uncategorized — Review",IFERROR(INDEX(Mapping!$C:$C,MATCH($G5,Mapping!$A:$A,0)),"Uncategorized — Review")) -> Credit Card & Loan Payments
A6: =Chase1168_2025!A6 -> DEBIT | B6: =Chase1168_2025!B6 -> 46020 | C6: =Chase1168_2025!C6 -> ORIG CO NAME:TXU ENERGY ORIG ID:1001020329 DESC DATE: CO ENTRY DESCR:TXUE_ACH SEC:WEB TRACE#:021000025255110 EED:251229 IND ID:900062431557 IND NAME:DWG CAPITAL GROUP 17333702810000000000000000000003592 4192821 DIRECT DEBITING TRN: 3635255110TC | D6: =Chase1168_2025!D6 -> -510.09 | E6: =Chase1168_2025!E6 -> ACH_DEBIT | F6: =Chase1168_2025!F6 -> 34105.1 | G6: =Chase1168_2025!G6 -> Texas - House Utilities | H6: =IF($B6="","",DATE(YEAR($B6),MONTH($B6),1)) -> 45992 | I6: =IF($G6="","Uncategorized — Review",IFERROR(INDEX(Mapping!$B:$B,MATCH($G6,Mapping!$A:$A,0)),"Uncategorized — Review")) -> Texas - House Utilities | J6: =IF($G6="","Uncategorized — Review",IFERROR(INDEX(Mapping!$C:$C,MATCH($G6,Mapping!$A:$A,0)),"Uncategorized — Review")) -> Personal — Owner
A7: =Chase1168_2025!A7 -> DEBIT | B7: =Chase1168_2025!B7 -> 46020 | C7: =Chase1168_2025!C7 -> Basic Online Payroll Payment 11200477377 to ########4122 | D7: =Chase1168_2025!D7 -> -1750 | E7: =Chase1168_2025!E7 -> BASIC_PAYROLL | F7: =Chase1168_2025!F7 -> 34615.19 | G7: =Chase1168_2025!G7 -> Mike Paytonjian - Payroll | H7: =IF($B7="","",DATE(YEAR($B7),MONTH($B7),1)) -> 45992 | I7: =IF($G7="","Uncategorized — Review",IFERROR(INDEX(Mapping!$B:$B,MATCH($G7,Mapping!$A:$A,0)),"Uncategorized — Review")) -> Mike Paytonjian - Payroll | J7: =IF($G7="","Uncategorized — Review",IFERROR(INDEX(Mapping!$C:$C,MATCH($G7,Mapping!$A:$A,0)),"Uncategorized — Review")) -> Payroll & Contractors
A8: =Chase1168_2025!A8 -> DEBIT | B8: =Chase1168_2025!B8 -> 46020 | C8: =Chase1168_2025!C8 -> ORIG CO NAME:BANNER LIFE ORIG ID:1521236145 DESC DATE:251228 CO ENTRY DESCR:PREM DEBITSEC:PPD TRACE#:091000014535049 EED:251229 IND ID: IND NAME:ANGELA L DUNNING TRN: 3634535049TC | D8: =Chase1168_2025!D8 -> -12.5 | E8: =Chase1168_2025!E8 -> ACH_DEBIT | F8: =Chase1168_2025!F8 -> 36365.19 | G8: =Chase1168_2025!G8 -> Personal - Life Insurance | H8: =IF($B8="","",DATE(YEAR($B8),MONTH($B8),1)) -> 45992 | I8: =IF($G8="","Uncategorized — Review",IFERROR(INDEX(Mapping!$B:$B,MATCH($G8,Mapping!$A:$A,0)),"Uncategorized — Review")) -> Personal - Life Insurance | J8: =IF($G8="","Uncategorized — Review",IFERROR(INDEX(Mapping!$C:$C,MATCH($G8,Mapping!$A:$A,0)),"Uncategorized — Review")) -> Personal — Owner
A9: =Chase1168_2025!A9 -> DEBIT | B9: =Chase1168_2025!B9 -> 46020 | C9: =Chase1168_2025!C9 -> ORIG CO NAME:BANNER LIFE ORIG ID:1521236145 DESC DATE:251228 CO ENTRY DESCR:PREM DEBITSEC:PPD TRACE#:091000014535050 EED:251229 IND ID: IND NAME:JOHN DUNNING TRN: 3634535050TC | D9: =Chase1168_2025!D9 -> -22.92 | E9: =Chase1168_2025!E9 -> ACH_DEBIT | F9: =Chase1168_2025!F9 -> 36377.69 | G9: =Chase1168_2025!G9 -> Personal - Life Insurance | H9: =IF($B9="","",DATE(YEAR($B9),MONTH($B9),1)) -> 45992 | I9: =IF($G9="","Uncategorized — Review",IFERROR(INDEX(Mapping!$B:$B,MATCH($G9,Mapping!$A:$A,0)),"Uncategorized — Review")) -> Personal - Life Insurance | J9: =IF($G9="","Uncategorized — Review",IFERROR(INDEX(Mapping!$C:$C,MATCH($G9,Mapping!$A:$A,0)),"Uncategorized — Review")) -> Personal — Owner
