Workbook

Sheet Transaction Summary
A1: American Express — Business Platinum Card
A2: Statement Summary | Jan 1, 2025 – Dec 31, 2025
A4: Prepared For | B4: John Dunning
A5: Account | B5: XXXX-XXXXXX-02000
A6: Statement Period | B6: Jan 2025 – Dec 2025
A8: TOTALS
A9: Charges | B9: =SUMIFS('Raw Data'!$F$8:$F$2052,'Raw Data'!$F$8:$F$2052,">0") -> 347202.33
A10: Credits & Payments | B10: =SUMIFS('Raw Data'!$F$8:$F$2052,'Raw Data'!$F$8:$F$2052,"<0") -> -354496.62
A11: Net Balance | B11: =B9+B10 -> -7294.29
A13: ACTIVITY BY CARD
A14: Card Member | B14: Payments & Credits | C14: Charges | D14: Total
A15: JOHN DUNNING | B15: =SUMIFS('Raw Data'!$F$8:$F$2052,'Raw Data'!$D$8:$D$2052,$A15,'Raw Data'!$F$8:$F$2052,"<0") -> -351061.92 | C15: =SUMIFS('Raw Data'!$F$8:$F$2052,'Raw Data'!$D$8:$D$2052,$A15,'Raw Data'!$F$8:$F$2052,">0") -> 308718.72 | D15: =B15+C15 -> -42343.2
A16: ANGELA LISA DUNNING | B16: =SUMIFS('Raw Data'!$F$8:$F$2052,'Raw Data'!$D$8:$D$2052,$A16,'Raw Data'!$F$8:$F$2052,"<0") -> -3434.7 | C16: =SUMIFS('Raw Data'!$F$8:$F$2052,'Raw Data'!$D$8:$D$2052,$A16,'Raw Data'!$F$8:$F$2052,">0") -> 38483.61 | D16: =B16+C16 -> 35048.91
A17: AVA YEMNA PEREZ | B17: =SUMIFS('Raw Data'!$F$8:$F$2052,'Raw Data'!$D$8:$D$2052,$A17,'Raw Data'!$F$8:$F$2052,"<0") -> 0 | C17: =SUMIFS('Raw Data'!$F$8:$F$2052,'Raw Data'!$D$8:$D$2052,$A17,'Raw Data'!$F$8:$F$2052,">0") -> 0 | D17: =B17+C17 -> 0
A18: Total | B18: =SUMIFS('Raw Data'!$F$8:$F$2052,'Raw Data'!$F$8:$F$2052,"<0") -> -354496.62 | C18: =SUMIFS('Raw Data'!$F$8:$F$2052,'Raw Data'!$F$8:$F$2052,">0") -> 347202.33 | D18: =B18+C18 -> -7294.29
A20: SPEND BY CATEGORY
A21: Category | B21: Amount | C21: % of Charges
A22: DWG / Operating
A23: DWG Listing Platform | B23: =SUMIF('Raw Data'!$I$8:$I$2052,$A23,'Raw Data'!$F$8:$F$2052) -> 21635 | C23: =B23/$B$9 -> 0.06231237
A24: Sponsor Cloud | B24: =SUMIF('Raw Data'!$I$8:$I$2052,$A24,'Raw Data'!$F$8:$F$2052) -> 8690.84 | C24: =B24/$B$9 -> 0.025031053
A25: Software & Subscriptions | B25: =SUMIF('Raw Data'!$I$8:$I$2052,$A25,'Raw Data'!$F$8:$F$2052) -> 9932.65 | C25: =B25/$B$9 -> 0.028607671
A26: AI Subscriptions | B26: =SUMIF('Raw Data'!$I$8:$I$2052,$A26,'Raw Data'!$F$8:$F$2052) -> 790.29 | C26: =B26/$B$9 -> 0.0022761656
A27: Go Daddy | B27: =SUMIF('Raw Data'!$I$8:$I$2052,$A27,'Raw Data'!$F$8:$F$2052) -> 8972.87 | C27: =B27/$B$9 -> 0.025843346
A28: DWG Operations | B28: =SUMIF('Raw Data'!$I$8:$I$2052,$A28,'Raw Data'!$F$8:$F$2052) -> 7689.66 | C28: =B28/$B$9 -> 0.02214749
A29: DWG Conference | B29: =SUMIF('Raw Data'!$I$8:$I$2052,$A29,'Raw Data'!$F$8:$F$2052) -> 6935 | C29: =B29/$B$9 -> 0.019973944
A30: DWG Marketing | B30: =SUMIF('Raw Data'!$I$8:$I$2052,$A30,'Raw Data'!$F$8:$F$2052) -> 3107 | C30: =B30/$B$9 -> 0.0089486727
A31: DWG Electronics | B31: =SUMIF('Raw Data'!$I$8:$I$2052,$A31,'Raw Data'!$F$8:$F$2052) -> 2691.84 | C31: =B31/$B$9 -> 0.0077529434
A32: DWG Development | B32: =SUMIF('Raw Data'!$I$8:$I$2052,$A32,'Raw Data'!$F$8:$F$2052) -> 194.85 | C32: =B32/$B$9 -> 0.00056120015
A33: DWG Swag | B33: =SUMIF('Raw Data'!$I$8:$I$2052,$A33,'Raw Data'!$F$8:$F$2052) -> 183.18 | C33: =B33/$B$9 -> 0.00052758863
A34: DWG-RE Platform (Redirected) | B34: =SUMIF('Raw Data'!$I$8:$I$2052,$A34,'Raw Data'!$F$8:$F$2052) -> 584 | C34: =B34/$B$9 -> 0.0016820164
... A36: RENEWAL MEMBERSHIP FEE | B36: =SUMIF('Raw Data'!$I$8:$I$2052,$A36,'Raw Data'!$F$8:$F$2052) -> 695 | C36: =B36/$B$9 -> 0.0020017147
A37: Subtotal — Operating | B37: =SUM(B23:B36) -> 74751.18 | C37: =B37/$B$9 -> 0.21529573
A39: Deal-Specific
A40: Deal Specific: Moab | B40: =SUMIF('Raw Data'!$I$8:$I$2052,$A40,'Raw Data'!$F$8:$F$2052) -> 72 | C40: =B40/$B$9 -> 0.00020737188
A41: Deal Specific - 260 S Hibbert | B41: =SUMIF('Raw Data'!$I$8:$I$2052,$A41,'Raw Data'!$F$8:$F$2052) -> 32 | C41: =B41/$B$9 -> 9.216528e-05
A42: Subtotal — Deal-Specific | B42: =SUM(B40:B41) -> 104 | C42: =B42/$B$9 -> 0.00029953716
A44: Legal / Professional / Other
A45: The Brandon Law Firm | B45: =SUMIF('Raw Data'!$I$8:$I$2052,$A45,'Raw Data'!$F$8:$F$2052) -> 4377.5 | C45: =B45/$B$9 -> 0.012607922
A46: Donation | B46: =SUMIF('Raw Data'!$I$8:$I$2052,$A46,'Raw Data'!$F$8:$F$2052) -> 330 | C46: =B46/$B$9 -> 0.00095045445
A47: Interest Charge on Pay Over Time Purchases | B47: =SUMIF('Raw Data'!$I$8:$I$2052,$A47,'Raw Data'!$F$8:$F$2052) -> 694.13 | C47: =B47/$B$9 -> 0.0019992089
...

Sheet Monthly Breakdown
A1: American Express — Business Platinum Card
A2: Monthly Breakdown | Jan 1, 2025 – Dec 31, 2025
A4: Period | B4: Jan 2025 – Dec 2025
A6: =DATE(2025,1,1) -> 45658
A7: Category | B7: Amount | C7: % of Month Charges
A8: DWG Listing Platform | B8: =SUMIFS('Raw Data'!$F$8:$F$2052,'Raw Data'!$I$8:$I$2052,$A8,'Raw Data'!$K$8:$K$2052,MONTH($A$6)) -> 2260 | C8: =IFERROR(B8/$B$25,0) -> 0.091975129
A9: Team Travel (Angela) | B9: =SUMIFS('Raw Data'!$F$8:$F$2052,'Raw Data'!$I$8:$I$2052,$A9,'Raw Data'!$K$8:$K$2052,MONTH($A$6)) -> 2226.75 | C9: =IFERROR(B9/$B$25,0) -> 0.090621955
A10: 2024/2025 Canada Family Trip | B10: =SUMIFS('Raw Data'!$F$8:$F$2052,'Raw Data'!$I$8:$I$2052,$A10,'Raw Data'!$K$8:$K$2052,MONTH($A$6)) -> 2139.02 | C10: =IFERROR(B10/$B$25,0) -> 0.087051611
A11: Personal - Food | B11: =SUMIFS('Raw Data'!$F$8:$F$2052,'Raw Data'!$I$8:$I$2052,$A11,'Raw Data'!$K$8:$K$2052,MONTH($A$6)) -> 977.84 | C11: =IFERROR(B11/$B$25,0) -> 0.039795115
A12: Software & Subscriptions | B12: =SUMIFS('Raw Data'!$F$8:$F$2052,'Raw Data'!$I$8:$I$2052,$A12,'Raw Data'!$K$8:$K$2052,MONTH($A$6)) -> 969.1 | C12: =IFERROR(B12/$B$25,0) -> 0.039439424
A13: Personal - Health | B13: =SUMIFS('Raw Data'!$F$8:$F$2052,'Raw Data'!$I$8:$I$2052,$A13,'Raw Data'!$K$8:$K$2052,MONTH($A$6)) -> 868.51 | C13: =IFERROR(B13/$B$25,0) -> 0.035345717
A14: Amazon | B14: =SUMIFS('Raw Data'!$F$8:$F$2052,'Raw Data'!$I$8:$I$2052,$A14,'Raw Data'!$K$8:$K$2052,MONTH($A$6)) -> 617.5 | C14: =IFERROR(B14/$B$25,0) -> 0.025130373
A15: Palm Springs Renewal | B15: =SUMIFS('Raw Data'!$F$8:$F$2052,'Raw Data'!$I$8:$I$2052,$A15,'Raw Data'!$K$8:$K$2052,MONTH($A$6)) -> 599 | C15: =IFERROR(B15/$B$25,0) -> 0.024377479
A16: Personal - Entertainment | B16: =SUMIFS('Raw Data'!$F$8:$F$2052,'Raw Data'!$I$8:$I$2052,$A16,'Raw Data'!$K$8:$K$2052,MONTH($A$6)) -> 474.85 | C16: =IFERROR(B16/$B$25,0) -> 0.019324951
A17: Go Daddy | B17: =SUMIFS('Raw Data'!$F$8:$F$2052,'Raw Data'!$I$8:$I$2052,$A17,'Raw Data'!$K$8:$K$2052,MONTH($A$6)) -> 412.37 | C17: =IFERROR(B17/$B$25,0) -> 0.016782205
A18: Donation | B18: =SUMIFS('Raw Data'!$F$8:$F$2052,'Raw Data'!$I$8:$I$2052,$A18,'Raw Data'!$K$8:$K$2052,MONTH($A$6)) -> 330 | C18: =IFERROR(B18/$B$25,0) -> 0.013429997
A19: Personal - House | B19: =SUMIFS('Raw Data'!$F$8:$F$2052,'Raw Data'!$I$8:$I$2052,$A19,'Raw Data'!$K$8:$K$2052,MONTH($A$6)) -> 269.84 | C19: =IFERROR(B19/$B$25,0) -> 0.010981668
... A24: Online AMEX Payment | B24: =SUMIFS('Raw Data'!$F$8:$F$2052,'Raw Data'!$I$8:$I$2052,$A24,'Raw Data'!$K$8:$K$2052,MONTH($A$6)) -> -27459.41 | C24: =IFERROR(B24/$B$25,0) -> -1.1175145
A25: Total Charges | B25: =SUMIFS('Raw Data'!$F$8:$F$2052,'Raw Data'!$K$8:$K$2052,MONTH($A$6),'Raw Data'!$F$8:$F$2052,">0") -> 24571.86
A26: Credits & Payments | B26: =SUMIFS('Raw Data'!$F$8:$F$2052,'Raw Data'!$K$8:$K$2052,MONTH($A$6),'Raw Data'!$F$8:$F$2052,"<0") -> -39722.02
A27: Net | B27: =B25+B26 -> -15150.16
A29: =DATE(2025,2,1) -> 45689
A30: Category | B30: Amount | C30: % of Month Charges
A31: Sponsor Cloud | B31: =SUMIFS('Raw Data'!$F$8:$F$2052,'Raw Data'!$I$8:$I$2052,$A31,'Raw Data'!$K$8:$K$2052,MONTH($A$29)) -> 7200 | C31: =IFERROR(B31/$B$49,0) -> 0.1933135
A32: Personal - Car | B32: =SUMIFS('Raw Data'!$F$8:$F$2052,'Raw Data'!$I$8:$I$2052,$A32,'Raw Data'!$K$8:$K$2052,MONTH($A$29)) -> 5057.91 | C32: =IFERROR(B32/$B$49,0) -> 0.13580032
A33: Personal - Food | B33: =SUMIFS('Raw Data'!$F$8:$F$2052,'Raw Data'!$I$8:$I$2052,$A33,'Raw Data'!$K$8:$K$2052,MONTH($A$29)) -> 3560.74 | C33: =IFERROR(B33/$B$49,0) -> 0.095602655
A34: Team Travel (Angela) | B34: =SUMIFS('Raw Data'!$F$8:$F$2052,'Raw Data'!$I$8:$I$2052,$A34,'Raw Data'!$K$8:$K$2052,MONTH($A$29)) -> 2386.31 | C34: =IFERROR(B34/$B$49,0) -> 0.064070269
A35: DWG Listing Platform | B35: =SUMIFS('Raw Data'!$F$8:$F$2052,'Raw Data'!$I$8:$I$2052,$A35,'Raw Data'!$K$8:$K$2052,MONTH($A$29)) -> 2260 | C35: =IFERROR(B35/$B$49,0) -> 0.06067896
A36: Personal - Health | B36: =SUMIFS('Raw Data'!$F$8:$F$2052,'Raw Data'!$I$8:$I$2052,$A36,'Raw Data'!$K$8:$K$2052,MONTH($A$29)) -> 1405.22 | C36: =IFERROR(B36/$B$49,0) -> 0.037728889
A37: DWG Operations | B37: =SUMIFS('Raw Data'!$F$8:$F$2052,'Raw Data'!$I$8:$I$2052,$A37,'Raw Data'!$K$8:$K$2052,MONTH($A$29)) -> 1251.43 | C37: =IFERROR(B37/$B$49,0) -> 0.033599766
A38: DWG Marketing | B38: =SUMIFS('Raw Data'!$F$8:$F$2052,'Raw Data'!$I$8:$I$2052,$A38,'Raw Data'!$K$8:$K$2052,MONTH($A$29)) -> 1172 | C38: =IFERROR(B38/$B$49,0) -> 0.031467142
A39: The Brandon Law Firm | B39: =SUMIFS('Raw Data'!$F$8:$F$2052,'Raw Data'!$I$8:$I$2052,$A39,'Raw Data'!$K$8:$K$2052,MONTH($A$29)) -> 1030 | C39: =IFERROR(B39/$B$49,0) -> 0.02765457
A40: Software & Subscriptions | B40: =SUMIFS('Raw Data'!$F$8:$F$2052,'Raw Data'!$I$8:$I$2052,$A40,'Raw Data'!$K$8:$K$2052,MONTH($A$29)) -> 793.1 | C40: =IFERROR(B40/$B$49,0) -> 0.021294019
A41: Go Daddy | B41: =SUMIFS('Raw Data'!$F$8:$F$2052,'Raw Data'!$I$8:$I$2052,$A41,'Raw Data'!$K$8:$K$2052,MONTH($A$29)) -> 435.74 | C41: =IFERROR(B41/$B$49,0) -> 0.011699226
A42: Personal - House | B42: =SUMIFS('Raw Data'!$F$8:$F$2052,'Raw Data'!$I$8:$I$2052,$A42,'Raw Data'!$K$8:$K$2052,MONTH($A$29)) -> 343.96 | C42: =IFERROR(B42/$B$49,0) -> 0.0092350155
... A48: Online AMEX Payment | B48: =SUMIFS('Raw Data'!$F$8:$F$2052,'Raw Data'!$I$8:$I$2052,$A48,'Raw Data'!$K$8:$K$2052,MONTH($A$29)) -> -48648.58 | C48: =IFERROR(B48/$B$49,0) -> -1.3061705
A49: Total Charges | B49: =SUMIFS('Raw Data'!$F$8:$F$2052,'Raw Data'!$K$8:$K$2052,MONTH($A$29),'Raw Data'!$F$8:$F$2052,">0") -> 37245.2
A50: Credits & Payments | B50: =SUMIFS('Raw Data'!$F$8:$F$2052,'Raw Data'!$K$8:$K$2052,MONTH($A$29),'Raw Data'!$F$8:$F$2052,"<0") -> -58256.28
A51: Net | B51: =B49+B50 -> -21011.08
A53: =DATE(2025,3,1) -> 45717
...

Sheet Transaction Details
A1: American Express — Business Platinum Card
A2: Transaction Detail | Jan 1, 2025 – Dec 31, 2025
A4: Date | B4: Merchant | C4: Category | D4: Amount
A5: ='Raw Data'!A8 -> 12/31/2025 | B5: ='Raw Data'!C8 -> A&R NOTARY PLUS Los Angeles CA | C5: ='Raw Data'!I8 -> Deal Specific: Moab | D5: ='Raw Data'!F8 -> 72
A6: ='Raw Data'!A9 -> 12/31/2025 | B6: ='Raw Data'!C9 -> BUDGET RENT A CAR RICHMOND CA | C6: ='Raw Data'!I9 -> Family Trip | D6: ='Raw Data'!F9 -> 2160.6
A7: ='Raw Data'!A10 -> 12/31/2025 | B7: ='Raw Data'!C10 -> SPONSORCLOUD (SYNPROSALT LAKE CITY UT | C7: ='Raw Data'!I10 -> Sponsor Cloud | D7: ='Raw Data'!F10 -> 180.14
A8: ='Raw Data'!A11 -> 12/29/2025 | B8: ='Raw Data'!C11 -> DNH*GODADDY#39806828Tempe AZ | C8: ='Raw Data'!I11 -> Go Daddy | D8: ='Raw Data'!F11 -> 22.98
A9: ='Raw Data'!A12 -> 12/29/2025 | B9: ='Raw Data'!C12 -> OPENAI *CHATGPT SUBSSAN FRANCISCO CA | C9: ='Raw Data'!I12 -> AI Subscriptions | D9: ='Raw Data'!F12 -> 20
A10: ='Raw Data'!A13 -> 12/28/2025 | B10: ='Raw Data'!C13 -> ONLINE PAYMENT - THANK YOU | C10: ='Raw Data'!I13 -> Online AMEX Payment | D10: ='Raw Data'!F13 -> -29571.15
A11: ='Raw Data'!A14 -> 12/27/2025 | B11: ='Raw Data'!C14 -> DNH*GODADDY#39792539Tempe AZ | C11: ='Raw Data'!I14 -> Go Daddy | D11: ='Raw Data'!F14 -> 11.99
A12: ='Raw Data'!A15 -> 12/27/2025 | B12: ='Raw Data'!C15 -> SPLICE.COM NEW YORK NY | C12: ='Raw Data'!I15 -> Software & Subscriptions | D12: ='Raw Data'!F15 -> 39.99
A13: ='Raw Data'!A16 -> 12/25/2025 | B13: ='Raw Data'!C16 -> DNH*GODADDY#39778629Tempe AZ | C13: ='Raw Data'!I16 -> Go Daddy | D13: ='Raw Data'!F16 -> 15.98
A14: ='Raw Data'!A17 -> 12/23/2025 | B14: ='Raw Data'!C17 -> DNH*GODADDY#39769602Tempe AZ | C14: ='Raw Data'!I17 -> Go Daddy | D14: ='Raw Data'!F17 -> 40.97
A15: ='Raw Data'!A18 -> 12/20/2025 | B15: ='Raw Data'!C18 -> CAMPAIGNER SVC 888-845-4544 CA | C15: ='Raw Data'!I18 -> DWG-RE Platform (Redirected) | D15: ='Raw Data'!F18 -> 584
A16: ='Raw Data'!A19 -> 12/20/2025 | B16: ='Raw Data'!C19 -> DNH*GODADDY#39749794Tempe AZ | C16: ='Raw Data'!I19 -> Go Daddy | D16: ='Raw Data'!F19 -> 17.97
... A2049: ='Raw Data'!A2052 -> 01/01/2025 | B2049: ='Raw Data'!C2052 -> WICKANINNISH INN LTDTOFINO CA | C2049: ='Raw Data'!I2052 -> 2024/2025 Canada Family Trip | D2049: ='Raw Data'!F2052 -> 951.4

Sheet Raw Data
A1: Transaction Details | B1: Business Platinum Card® / Jan 01, 2025 to Dec 31, 2025
A2: Prepared for
A3: JOHN DUNNING
A4: Account Number
A5: XXXX-XXXXXX-02000
A7: Date | B7: Receipt | C7: Description | D7: Card Member | E7: Account # | F7: Amount | G7: Extended Details | H7: Appears On Your Statement As | I7: Category | K7: Month #
A8: 12/31/2025 | C8: A&R NOTARY PLUS Los Angeles CA | D8: JOHN DUNNING | E8: -02000 | F8: 72 | G8: NoLBczBdb3W squareup.com/receipts A&R NOTARY PLUS Los Angeles CA squareup.com/receipts | H8: A&R NOTARY PLUS Los Angeles CA | I8: Deal Specific: Moab | K8: =IF($A8="","",IF(ISNUMBER($A8),MONTH($A8),MONTH(DATEVALUE($A8)))) -> 12
A9: 12/31/2025 | C9: BUDGET RENT A CAR RICHMOND CA | D9: JOHN DUNNING | E9: -02000 | F9: 2160.6 | G9: R/A# 964532601 1-800-621-2844 BUDGET RENT A CAR RICHMOND CA Foreign Spend Amount: 2956.78 CANADIAN DOLLAR Commission Amount: Currency Exchange Rate: null | H9: BUDGET RENT A CAR RICHMOND CA | I9: Family Trip | K9: =IF($A9="","",IF(ISNUMBER($A9),MONTH($A9),MONTH(DATEVALUE($A9)))) -> 12
A10: 12/31/2025 | C10: SPONSORCLOUD (SYNPROSALT LAKE CITY UT | D10: JOHN DUNNING | E10: -02000 | F10: 180.14 | G10: CH_3SKZJQB7 +13854834872 SPONSORCLOUD (SYNPRO) SALT LAKE CITY UT +13854834872 | H10: SPONSORCLOUD (SYNPROSALT LAKE CITY UT | I10: Sponsor Cloud | K10: =IF($A10="","",IF(ISNUMBER($A10),MONTH($A10),MONTH(DATEVALUE($A10)))) -> 12
A11: 12/29/2025 | C11: DNH*GODADDY#39806828Tempe AZ | D11: JOHN DUNNING | E11: -02000 | F11: 22.98 | G11: 3980682814 4805058855 Microsoft 365 Online Business Essentials Email - Archiving - Renewal DNH*GODADDY#3980682814 Tempe AZ Microsoft 365 Online Business Essentials Email - Archiving - Renewal 4805058855 | H11: DNH*GODADDY#39806828Tempe AZ | I11: Go Daddy | K11: =IF($A11="","",IF(ISNUMBER($A11),MONTH($A11),MONTH(DATEVALUE($A11)))) -> 12
A12: 12/29/2025 | C12: OPENAI *CHATGPT SUBSSAN FRANCISCO CA | D12: JOHN DUNNING | E12: -02000 | F12: 20 | G12: CH_3SJMPNC6 +14158799686 OPENAI *CHATGPT SUBSCR SAN FRANCISCO CA +14158799686 | H12: OPENAI *CHATGPT SUBSSAN FRANCISCO CA | I12: AI Subscriptions | K12: =IF($A12="","",IF(ISNUMBER($A12),MONTH($A12),MONTH(DATEVALUE($A12)))) -> 12
A13: 12/28/2025 | C13: ONLINE PAYMENT - THANK YOU | D13: JOHN DUNNING | E13: -02000 | F13: -29571.15 | G13: ONLINE PAYMENT - THANK YOU | H13: ONLINE PAYMENT - THANK YOU | I13: Online AMEX Payment | K13: =IF($A13="","",IF(ISNUMBER($A13),MONTH($A13),MONTH(DATEVALUE($A13)))) -> 12
A14: 12/27/2025 | C14: DNH*GODADDY#39792539Tempe AZ | D14: JOHN DUNNING | E14: -02000 | F14: 11.99 | G14: 3979253910 4805058855 Hosting - Web - Economy - Linux cPanel - DNH*GODADDY#3979253910 Tempe AZ Hosting - Web - Economy - Linux cPanel - 4805058855 | H14: DNH*GODADDY#39792539Tempe AZ | I14: Go Daddy | K14: =IF($A14="","",IF(ISNUMBER($A14),MONTH($A14),MONTH(DATEVALUE($A14)))) -> 12
A15: 12/27/2025 | C15: SPLICE.COM NEW YORK NY | D15: JOHN DUNNING | E15: -02000 | F15: 39.99 | G15: CH_3SIYBXCF 3235775423 SPLICE.COM NEW YORK NY 3235775423 | H15: SPLICE.COM NEW YORK NY | I15: Software & Subscriptions | K15: =IF($A15="","",IF(ISNUMBER($A15),MONTH($A15),MONTH(DATEVALUE($A15)))) -> 12
A16: 12/25/2025 | C16: DNH*GODADDY#39778629Tempe AZ | D16: JOHN DUNNING | E16: -02000 | F16: 15.98 | G16: 3977862936 4805058855 Email Plus - Renewal - monthly Email - Archiving - Renewal DNH*GODADDY#3977862936 Tempe AZ Email Plus - Renewal - monthly Email - Archiving - Renewal 4805058855 | H16: DNH*GODADDY#39778629Tempe AZ | I16: Go Daddy | K16: =IF($A16="","",IF(ISNUMBER($A16),MONTH($A16),MONTH(DATEVALUE($A16)))) -> 12
A17: 12/23/2025 | C17: DNH*GODADDY#39769602Tempe AZ | D17: JOHN DUNNING | E17: -02000 | F17: 40.97 | G17: 3976960263 4805058855 Business Enterprise - Renewal - 1 month Email - Archiving - Renewal Microsoft 365 Email Backup - Renewal DNH*GODADDY#3976960263 Tempe AZ Business Enterprise - Renewal - 1 month Email - Archiving - Renewal Microsoft 365 Email Backup - Renewal 4805058855 | H17: DNH*GODADDY#39769602Tempe AZ | I17: Go Daddy | K17: =IF($A17="","",IF(ISNUMBER($A17),MONTH($A17),MONTH(DATEVALUE($A17)))) -> 12
A18: 12/20/2025 | C18: CAMPAIGNER SVC 888-845-4544 CA | D18: JOHN DUNNING | E18: -02000 | F18: 584 | G18: 34200007 EMAIL MARKET CAMPAIGNER SVC 888-845-4544 CA EMAIL MARKET | H18: CAMPAIGNER SVC 888-845-4544 CA | I18: DWG-RE Platform (Redirected) | K18: =IF($A18="","",IF(ISNUMBER($A18),MONTH($A18),MONTH(DATEVALUE($A18)))) -> 12
A19: 12/20/2025 | C19: DNH*GODADDY#39749794Tempe AZ | D19: JOHN DUNNING | E19: -02000 | F19: 17.97 | G19: 3974979472 4805058855 Microsoft 365 Email Essentials - Renewal Email - Archiving - Renewal Microsoft 365 Email Backup - Renewal DNH*GODADDY#3974979472 Tempe AZ Microsoft 365 Email Essentials - Renewal Email - Archiving - Renewal Microsoft 365 Email Backup - Renewal 4805058855 | H19: DNH*GODADDY#39749794Tempe AZ | I19: Go Daddy | K19: =IF($A19="","",IF(ISNUMBER($A19),MONTH($A19),MONTH(DATEVALUE($A19)))) -> 12
... A108: 11/30/2025 | C108: LA FIESTA FOODS INC.Los Angeles CA | D108: JOHN DUNNING | E108: -02000 | F108: 74.35 | G108: 5GDNzGPjewG squareup.com/receipts LA FIESTA FOODS INC. DBA THE TAMALE FI Los Angeles CA squareup.com/receipts | H108: LA FIESTA FOODS INC.Los Angeles CA | I108: Personal - Food | K108: =IF($A108="","",IF(ISNUMBER($A108),MONTH($A108),MONTH(DATEVALUE($A108)))) -> 11
A109: 11/30/2025 | B109: * | C109: PICKLED BY SHRED LLCLos Angeles CA | D109: JOHN DUNNING | E109: -02000 | F109: 58 | G109: LtAkhbwJuJj squareup.com/receipts PICKLED BY SHRED LLC Los Angeles CA squareup.com/receipts | H109: PICKLED BY SHRED LLCLos Angeles CA | I109: Personal - Food | K109: =IF($A109="","",IF(ISNUMBER($A109),MONTH($A109),MONTH(DATEVALUE($A109)))) -> 11
A110: 11/30/2025 | C110: PY *FATBURGER 65 000MARINA DEL RE CA | D110: JOHN DUNNING | E110: -02000 | F110: 54.37 | G110: 99999995334 3107490925 PY *FATBURGER 65 000007086 MARINA DEL RE CA 3107490925 | H110: PY *FATBURGER 65 000MARINA DEL RE CA | I110: Personal - Food | K110: =IF($A110="","",IF(ISNUMBER($A110),MONTH($A110),MONTH(DATEVALUE($A110)))) -> 11
A111: 11/30/2025 | C111: SPONSORCLOUD (SYNPROSALT LAKE CITY UT | D111: JOHN DUNNING | E111: -02000 | F111: 180.14 | G111: CH_3SZKXLB7 +13854834872 SPONSORCLOUD (SYNPRO) SALT LAKE CITY UT +13854834872 | H111: SPONSORCLOUD (SYNPROSALT LAKE CITY UT | I111: Sponsor Cloud | K111: =IF($A111="","",IF(ISNUMBER($A111),MONTH($A111),MONTH(DATEVALUE($A111)))) -> 11
A112: 11/30/2025 | C112: TST* BEETHOVEN 00200LOS ANGELES CA | D112: JOHN DUNNING | E112: -02000 | F112: 283.23 | G112: 00200094029 RESTAURANT TST* BEETHOVEN 00200094 LOS ANGELES CA RESTAURANT | H112: TST* BEETHOVEN 00200LOS ANGELES CA | I112: Personal - Food | K112: =IF($A112="","",IF(ISNUMBER($A112),MONTH($A112),MONTH(DATEVALUE($A112)))) -> 11
A113: 11/30/2025 | C113: UNION 76 10194728 LOS ANGELES CA | D113: JOHN DUNNING | E113: -02000 | F113: 6.69 | G113: 11813046054 UNION 76 UNION 76 10194728 LOS ANGELES CA UNION 76 | H113: UNION 76 10194728 LOS ANGELES CA | I113: Personal - Car | K113: =IF($A113="","",IF(ISNUMBER($A113),MONTH($A113),MONTH(DATEVALUE($A113)))) -> 11
A114: 11/29/2025 | C114: CASABLANCA RESTAURANVENICE CA | D114: JOHN DUNNING | E114: -02000 | F114: 147.86 | G114: 31099535334 RESTAURANT CASABLANCA RESTAURANT 00-08045339838 VENICE CA RESTAURANT | H114: CASABLANCA RESTAURANVENICE CA | I114: Personal - Food | K114: =IF($A114="","",IF(ISNUMBER($A114),MONTH($A114),MONTH(DATEVALUE($A114)))) -> 11
A115: 11/29/2025 | C115: DNH*GODADDY#39582504Tempe AZ | D115: JOHN DUNNING | E115: -02000 | F115: 22.98 | G115: 3958250499 4805058855 Microsoft 365 Online Business Essentials Email - Archiving - Renewal DNH*GODADDY#3958250499 Tempe AZ Microsoft 365 Online Business Essentials Email - Archiving - Renewal 4805058855 | H115: DNH*GODADDY#39582504Tempe AZ | I115: Go Daddy | K115: =IF($A115="","",IF(ISNUMBER($A115),MONTH($A115),MONTH(DATEVALUE($A115)))) -> 11
A116: 11/29/2025 | C116: JACKS SURF BOARDS SANTA MONICA CA | D116: JOHN DUNNING | E116: -02000 | F116: 614.29 | G116: 3104506569 JACKS SURF BOARDS SANTA MONICA CA 3104506569 | H116: JACKS SURF BOARDS SANTA MONICA CA | I116: Personal - Entertainment | K116: =IF($A116="","",IF(ISNUMBER($A116),MONTH($A116),MONTH(DATEVALUE($A116)))) -> 11
A117: 11/29/2025 | C117: LARRYS SHAVER SHOPPESANTA MONICA CA | D117: JOHN DUNNING | E117: -02000 | F117: 99.62 | G117: 73011395334 RNAWPAR@GMAIL.COM LARRYS SHAVER SHOPPE 965797900664226 SANTA MONICA CA RNAWPAR@GMAIL.COM | H117: LARRYS SHAVER SHOPPESANTA MONICA CA | I117: Personal - Entertainment | K117: =IF($A117="","",IF(ISNUMBER($A117),MONTH($A117),MONTH(DATEVALUE($A117)))) -> 11
A118: 11/29/2025 | C118: OPENAI *CHATGPT SUBSSAN FRANCISCO CA | D118: JOHN DUNNING | E118: -02000 | F118: 20 | G118: CH_3SYUZBC6 +14158799686 OPENAI *CHATGPT SUBSCR SAN FRANCISCO CA +14158799686 | H118: OPENAI *CHATGPT SUBSSAN FRANCISCO CA | I118: AI Subscriptions | K118: =IF($A118="","",IF(ISNUMBER($A118),MONTH($A118),MONTH(DATEVALUE($A118)))) -> 11
A119: 11/29/2025 | C119: STARBUCKS STORE 0566SANTA MONICA CA | D119: JOHN DUNNING | E119: -02000 | F119: 8.3 | G119: 11D0075BB69 FAST FOOD RESTAURANT STARBUCKS STORE 0566 SANTA MONICA CA FAST FOOD RESTAURANT | H119: STARBUCKS STORE 0566SANTA MONICA CA | I119: Personal - Food | K119: =IF($A119="","",IF(ISNUMBER($A119),MONTH($A119),MONTH(DATEVALUE($A119)))) -> 11
A120: 11/28/2025 | C120: ANACAPA SURF N SPORTOXNARD CA | D120: JOHN DUNNING | E120: -02000 | F120: 87.4 | G120: 44900014 805-382-1602 ANACAPA SURF N SPORT OXNARD CA Description : SPORTING GOODS/APPA Price : 0.00 805-382-1602 | H120: ANACAPA SURF N SPORTOXNARD CA | I120: Personal - Entertainment | K120: =IF($A120="","",IF(ISNUMBER($A120),MONTH($A120),MONTH(DATEVALUE($A120)))) -> 11
A121: 11/28/2025 | C121: ANACAPA SURF N SPORTOXNARD CA | D121: JOHN DUNNING | E121: -02000 | F121: 318.96 | G121: 44900013 805-382-1602 ANACAPA SURF N SPORT OXNARD CA Description : SPORTING GOODS/APPA Price : 0.00 805-382-1602 | H121: ANACAPA SURF N SPORTOXNARD CA | I121: Personal - Entertainment | K121: =IF($A121="","",IF(ISNUMBER($A121),MONTH($A121),MONTH(DATEVALUE($A121)))) -> 11
... A148: 11/16/2025 | C148: SOCIALPILOT LEWES DE | D148: JOHN DUNNING | E148: -02000 | F148: 50 | G148: CH_2SUATN04 +14154506060 SOCIALPILOT LEWES DE +14154506060 | H148: SOCIALPILOT LEWES DE | I148: Software & Subscriptions | K148: =IF($A148="","",IF(ISNUMBER($A148),MONTH($A148),MONTH(DATEVALUE($A148)))) -> 11
A149: 11/16/2025 | B149: * | C149: THE ODYSSEY THEATRE Los Angeles CA | D149: JOHN DUNNING | E149: -02000 | F149: 7 | G149: ZcMQjWOp7Un squareup.com/receipts THE ODYSSEY THEATRE ENSEMBLE Los Angeles CA squareup.com/receipts | H149: THE ODYSSEY THEATRE Los Angeles CA | I149: Personal - Entertainment | K149: =IF($A149="","",IF(ISNUMBER($A149),MONTH($A149),MONTH(DATEVALUE($A149)))) -> 11
A150: 11/15/2025 | C150: 800.COM, LLC 800-800-4321 FL | D150: JOHN DUNNING | E150: -02000 | F150: 69.62 | G150: 21105175320 ESTABLISHES 800.COM, LLC 800-800-4321 FL ESTABLISHES | H150: 800.COM, LLC 800-800-4321 FL | I150: Software & Subscriptions | K150: =IF($A150="","",IF(ISNUMBER($A150),MONTH($A150),MONTH(DATEVALUE($A150)))) -> 11
A151: 11/15/2025 | C151: CVS PHARMACY LOS ANGELES CA | D151: JOHN DUNNING | E151: -02000 | F151: 31.26 | G151: 10052191 8007467287 PHARMACIES CVS PHARMACY LOS ANGELES CA PHARMACIES 8007467287 | H151: CVS PHARMACY LOS ANGELES CA | I151: Personal - Health | K151: =IF($A151="","",IF(ISNUMBER($A151),MONTH($A151),MONTH(DATEVALUE($A151)))) -> 11
A152: 11/15/2025 | C152: RESTORE.COM AUSTIN TX | D152: JOHN DUNNING | E152: -02000 | F152: 199 | G152: CH_3STFJAA8 +15125374087 RESTORE.COM AUSTIN TX +15125374087 | H152: RESTORE.COM AUSTIN TX | I152: Personal - Health | K152: =IF($A152="","",IF(ISNUMBER($A152),MONTH($A152),MONTH(DATEVALUE($A152)))) -> 11
A153: 11/15/2025 | C153: TST* TAVERNA AT THE LOS ANGELES CA | D153: JOHN DUNNING | E153: -02000 | F153: 88.94 | G153: 21105175320 RESTAURANT TST* TAVERNA AT THE MAR V 00207350 LOS ANGELES CA RESTAURANT | H153: TST* TAVERNA AT THE LOS ANGELES CA | I153: Personal - Food | K153: =IF($A153="","",IF(ISNUMBER($A153),MONTH($A153),MONTH(DATEVALUE($A153)))) -> 11
A154: 11/14/2025 | C154: RESTORE.COM AUSTIN TX | D154: JOHN DUNNING | E154: -02000 | F154: 206 | G154: CH_3STYNYA8 +15125374087 RESTORE.COM AUSTIN TX +15125374087 | H154: RESTORE.COM AUSTIN TX | I154: Personal - Health | K154: =IF($A154="","",IF(ISNUMBER($A154),MONTH($A154),MONTH(DATEVALUE($A154)))) -> 11
A155: 11/14/2025 | C155: TST* BLUEYS KITCHEN LOS ANGELES CA | D155: JOHN DUNNING | E155: -02000 | F155: 96.64 | G155: 21105175319 RESTAURANT TST* BLUEYS KITCHEN MAR V 00098618 LOS ANGELES CA RESTAURANT | H155: TST* BLUEYS KITCHEN LOS ANGELES CA | I155: Personal - Food | K155: =IF($A155="","",IF(ISNUMBER($A155),MONTH($A155),MONTH(DATEVALUE($A155)))) -> 11
...
