Workbook

Sheet Transaction Summary
A1: American Express - The Plum Card
A2: The Plum Card® | Statement Summary
A4: Account Holder | B4: John B Dunning
A5: Account | B5: XXXX-XXXXXX-27008
A6: Statement Period (Full Year) | B6: Jan 2025 - Dec 2025
A8: TOTALS
A9: Charges | B9: ='Transaction Details'!D427 -> 218574.69
A10: Credits & Payments | B10: ='Transaction Details'!D428 -> -182795.92
A11: Net Balance | B11: =B9+B10 -> 35778.77
A13: SPEND BY CATEGORY
A14: Category | B14: Amount | C14: % of Charges
A15: DWGCP / DWG Operating
A16: DWG-RE Listing Platform (Redirected) | B16: =SUMIFS('Transaction Details'!D:D,'Transaction Details'!C:C,A16) -> 4000 | C16: =IFERROR(B16/$B$9,0) -> 0.018300381
A17: DWG Investor Meeting (San Francisco) | B17: =SUMIFS('Transaction Details'!D:D,'Transaction Details'!C:C,A17) -> 3235.05 | C17: =IFERROR(B17/$B$9,0) -> 0.014800662
A18: DWG Marketing | B18: =SUMIFS('Transaction Details'!D:D,'Transaction Details'!C:C,A18) -> 2133.93 | C18: =IFERROR(B18/$B$9,0) -> 0.0097629328
A19: DWG Canceled Software | B19: =SUMIFS('Transaction Details'!D:D,'Transaction Details'!C:C,A19) -> 1358 | C19: =IFERROR(B19/$B$9,0) -> 0.0062129792
A20: Software & Subscriptions | B20: =SUMIFS('Transaction Details'!D:D,'Transaction Details'!C:C,A20) -> 471.89 | C20: =IFERROR(B20/$B$9,0) -> 0.0021589416
A21: Go Daddy | B21: =SUMIFS('Transaction Details'!D:D,'Transaction Details'!C:C,A21) -> 778.98 | C21: =IFERROR(B21/$B$9,0) -> 0.0035639076
A22: Wordpress | B22: =SUMIFS('Transaction Details'!D:D,'Transaction Details'!C:C,A22) -> 621 | C22: =IFERROR(B22/$B$9,0) -> 0.0028411341
A23: Costar Billing | B23: =SUMIFS('Transaction Details'!D:D,'Transaction Details'!C:C,A23) -> 9247.18 | C23: =IFERROR(B23/$B$9,0) -> 0.042306728
A24: Fund Launch | B24: =SUMIFS('Transaction Details'!D:D,'Transaction Details'!C:C,A24) -> 883 | C24: =IFERROR(B24/$B$9,0) -> 0.004039809
A25: Team Travel (Judd) | B25: =SUMIFS('Transaction Details'!D:D,'Transaction Details'!C:C,A25) -> 1813.46 | C25: =IFERROR(B25/$B$9,0) -> 0.008296752
A26: Team Lunch | B26: =SUMIFS('Transaction Details'!D:D,'Transaction Details'!C:C,A26) -> 184.45 | C26: =IFERROR(B26/$B$9,0) -> 0.0008438763
A27: Employee Bonus | B27: =SUMIFS('Transaction Details'!D:D,'Transaction Details'!C:C,A27) -> 6657.5 | C27: =IFERROR(B27/$B$9,0) -> 0.030458696
... A29: Renewal Membership Fee | B29: =SUMIFS('Transaction Details'!D:D,'Transaction Details'!C:C,A29) -> 250 | C29: =IFERROR(B29/$B$9,0) -> 0.0011437738
A30: Subtotal — Operating | B30: =SUM(B16:B29) -> 34030.46
A32: Deal-Specific
A33: Deal Specific: 260 S Hibbert - Taxes | B33: =SUMIFS('Transaction Details'!D:D,'Transaction Details'!C:C,A33) -> 23243.89 | C33: =IFERROR(B33/$B$9,0) -> 0.10634301
A34: Deal Specific: 260 S Hibbert - Insurance | B34: =SUMIFS('Transaction Details'!D:D,'Transaction Details'!C:C,A34) -> 8287.62 | C34: =IFERROR(B34/$B$9,0) -> 0.03791665
A35: Deal Specific: 260 S Hibbert - Utilities | B35: =SUMIFS('Transaction Details'!D:D,'Transaction Details'!C:C,A35) -> 67.5 | C35: =IFERROR(B35/$B$9,0) -> 0.00030881892
A36: Deal Specific - 260 S Hibbert - Marketing | B36: =SUMIFS('Transaction Details'!D:D,'Transaction Details'!C:C,A36) -> 1055.92 | C36: =IFERROR(B36/$B$9,0) -> 0.0048309345
A37: Deal Specific: Stryten Energy | B37: =SUMIFS('Transaction Details'!D:D,'Transaction Details'!C:C,A37) -> 399.67 | C37: =IFERROR(B37/$B$9,0) -> 0.0018285283
A38: Deal Specific - Bankhead Marketing | B38: =SUMIFS('Transaction Details'!D:D,'Transaction Details'!C:C,A38) -> 1323.03 | C38: =IFERROR(B38/$B$9,0) -> 0.0060529881
A39: Moab Appraisal | B39: =SUMIFS('Transaction Details'!D:D,'Transaction Details'!C:C,A39) -> 2175 | C39: =IFERROR(B39/$B$9,0) -> 0.0099508319
A40: Subtotal — Deal-Specific | B40: =SUM(B33:B39) -> 36552.63
A42: Legal / Professional / Other
A43: Jeff Farjado - Unconfirmed | B43: =SUMIFS('Transaction Details'!D:D,'Transaction Details'!C:C,A43) -> 17778.8 | C43: =IFERROR(B43/$B$9,0) -> 0.081339701
A44: The Brandon Law Firm | B44: =SUMIFS('Transaction Details'!D:D,'Transaction Details'!C:C,A44) -> 507.35 | C44: =IFERROR(B44/$B$9,0) -> 0.0023211745
A45: Adameer | B45: =SUMIFS('Transaction Details'!D:D,'Transaction Details'!C:C,A45) -> 4116.3 | C45: =IFERROR(B45/$B$9,0) -> 0.018832464
A46: Bridge Loan (Cash Reimbursement) - $11,300 total loss | B46: =SUMIFS('Transaction Details'!D:D,'Transaction Details'!C:C,A46) -> 11300 | C46: =IFERROR(B46/$B$9,0) -> 0.051698575
...

Sheet Monthly Breakdown
A1: DWG CAPITAL PARTNERS
A2: The Plum Card® | Monthly Breakdown
A4: Period | B4: Jan 2025 - Dec 2025
A6: =DATE(2025,1,1) -> 45658
A7: Category | B7: Amount | C7: % of Month Charges
A8: Online AMEX Payment | B8: =SUMIFS('Transaction Details'!D:D,'Transaction Details'!C:C,A8,'Transaction Details'!A:A,">="&DATE(2025,1,1),'Transaction Details'!A:A,"<"&DATE(2025,2,1)) -> -3951.39 | C8: =IFERROR(B8/$B$18,0) -> -1.1988695
A9: Deal Specific - Bankhead Marketing | B9: =SUMIFS('Transaction Details'!D:D,'Transaction Details'!C:C,A9,'Transaction Details'!A:A,">="&DATE(2025,1,1),'Transaction Details'!A:A,"<"&DATE(2025,2,1)) -> 1323.03 | C9: =IFERROR(B9/$B$18,0) -> 0.40141326
A10: Donation | B10: =SUMIFS('Transaction Details'!D:D,'Transaction Details'!C:C,A10,'Transaction Details'!A:A,">="&DATE(2025,1,1),'Transaction Details'!A:A,"<"&DATE(2025,2,1)) -> 818 | C10: =IFERROR(B10/$B$18,0) -> 0.24818488
A11: Personal - Food | B11: =SUMIFS('Transaction Details'!D:D,'Transaction Details'!C:C,A11,'Transaction Details'!A:A,">="&DATE(2025,1,1),'Transaction Details'!A:A,"<"&DATE(2025,2,1)) -> 582 | C11: =IFERROR(B11/$B$18,0) -> 0.17658142
A12: DWG Canceled Software | B12: =SUMIFS('Transaction Details'!D:D,'Transaction Details'!C:C,A12,'Transaction Details'!A:A,">="&DATE(2025,1,1),'Transaction Details'!A:A,"<"&DATE(2025,2,1)) -> 219 | C12: =IFERROR(B12/$B$18,0) -> 0.066445586
A13: Team Travel (Judd) | B13: =SUMIFS('Transaction Details'!D:D,'Transaction Details'!C:C,A13,'Transaction Details'!A:A,">="&DATE(2025,1,1),'Transaction Details'!A:A,"<"&DATE(2025,2,1)) -> 152.54 | C13: =IFERROR(B13/$B$18,0) -> 0.046281323
A14: Go Daddy | B14: =SUMIFS('Transaction Details'!D:D,'Transaction Details'!C:C,A14,'Transaction Details'!A:A,">="&DATE(2025,1,1),'Transaction Details'!A:A,"<"&DATE(2025,2,1)) -> 104.7 | C14: =IFERROR(B14/$B$18,0) -> 0.031766451
A15: Software & Subscriptions | B15: =SUMIFS('Transaction Details'!D:D,'Transaction Details'!C:C,A15,'Transaction Details'!A:A,">="&DATE(2025,1,1),'Transaction Details'!A:A,"<"&DATE(2025,2,1)) -> 37.6 | C15: =IFERROR(B15/$B$18,0) -> 0.011408009
A16: Personal - Car | B16: =SUMIFS('Transaction Details'!D:D,'Transaction Details'!C:C,A16,'Transaction Details'!A:A,">="&DATE(2025,1,1),'Transaction Details'!A:A,"<"&DATE(2025,2,1)) -> 34.07 | C16: =IFERROR(B16/$B$18,0) -> 0.010336991
A17: Personal - Family | B17: =SUMIFS('Transaction Details'!D:D,'Transaction Details'!C:C,A17,'Transaction Details'!A:A,">="&DATE(2025,1,1),'Transaction Details'!A:A,"<"&DATE(2025,2,1)) -> 24.99 | C17: =IFERROR(B17/$B$18,0) -> 0.0075820785
A18: Total Charges | B18: =SUMIFS('Transaction Details'!D:D,'Transaction Details'!A:A,">="&DATE(2025,1,1),'Transaction Details'!A:A,"<"&DATE(2025,2,1),'Transaction Details'!D:D,">0") -> 3295.93
A19: Credits & Payments | B19: =SUMIFS('Transaction Details'!D:D,'Transaction Details'!A:A,">="&DATE(2025,1,1),'Transaction Details'!A:A,"<"&DATE(2025,2,1),'Transaction Details'!D:D,"<0") -> -3951.39
A20: Net | B20: =B18+B19 -> -655.46
A22: =DATE(2025,2,1) -> 45689
A23: Category | B23: Amount | C23: % of Month Charges
A24: Online AMEX Payment | B24: =SUMIFS('Transaction Details'!D:D,'Transaction Details'!C:C,A24,'Transaction Details'!A:A,">="&DATE(2025,2,1),'Transaction Details'!A:A,"<"&DATE(2025,3,1)) -> -14054.21 | C24: =IFERROR(B24/$B$35,0) -> -1.2865066
A25: Costar Billing | B25: =SUMIFS('Transaction Details'!D:D,'Transaction Details'!C:C,A25,'Transaction Details'!A:A,">="&DATE(2025,2,1),'Transaction Details'!A:A,"<"&DATE(2025,3,1)) -> 9247.18 | C25: =IFERROR(B25/$B$35,0) -> 0.84647649
A26: The Brandon Law Firm | B26: =SUMIFS('Transaction Details'!D:D,'Transaction Details'!C:C,A26,'Transaction Details'!A:A,">="&DATE(2025,2,1),'Transaction Details'!A:A,"<"&DATE(2025,3,1)) -> 507.35 | C26: =IFERROR(B26/$B$35,0) -> 0.04644225
A27: Personal - Food | B27: =SUMIFS('Transaction Details'!D:D,'Transaction Details'!C:C,A27,'Transaction Details'!A:A,">="&DATE(2025,2,1),'Transaction Details'!A:A,"<"&DATE(2025,3,1)) -> 486.73 | C27: =IFERROR(B27/$B$35,0) -> 0.044554718
A28: DWG Canceled Software | B28: =SUMIFS('Transaction Details'!D:D,'Transaction Details'!C:C,A28,'Transaction Details'!A:A,">="&DATE(2025,2,1),'Transaction Details'!A:A,"<"&DATE(2025,3,1)) -> 219 | C28: =IFERROR(B28/$B$35,0) -> 0.020047014
A29: Go Daddy | B29: =SUMIFS('Transaction Details'!D:D,'Transaction Details'!C:C,A29,'Transaction Details'!A:A,">="&DATE(2025,2,1),'Transaction Details'!A:A,"<"&DATE(2025,3,1)) -> 132.86 | C29: =IFERROR(B29/$B$35,0) -> 0.012161855
A30: Personal - Health | B30: =SUMIFS('Transaction Details'!D:D,'Transaction Details'!C:C,A30,'Transaction Details'!A:A,">="&DATE(2025,2,1),'Transaction Details'!A:A,"<"&DATE(2025,3,1)) -> 114.91 | C30: =IFERROR(B30/$B$35,0) -> 0.010518733
A31: Personal - Entertainment | B31: =SUMIFS('Transaction Details'!D:D,'Transaction Details'!C:C,A31,'Transaction Details'!A:A,">="&DATE(2025,2,1),'Transaction Details'!A:A,"<"&DATE(2025,3,1)) -> 109.71 | C31: =IFERROR(B31/$B$35,0) -> 0.01004273
A32: Software & Subscriptions | B32: =SUMIFS('Transaction Details'!D:D,'Transaction Details'!C:C,A32,'Transaction Details'!A:A,">="&DATE(2025,2,1),'Transaction Details'!A:A,"<"&DATE(2025,3,1)) -> 42.59 | C32: =IFERROR(B32/$B$35,0) -> 0.0038986408
A33: Team Travel (Judd) | B33: =SUMIFS('Transaction Details'!D:D,'Transaction Details'!C:C,A33,'Transaction Details'!A:A,">="&DATE(2025,2,1),'Transaction Details'!A:A,"<"&DATE(2025,3,1)) -> 39 | C33: =IFERROR(B33/$B$35,0) -> 0.0035700163
A34: Personal - Family | B34: =SUMIFS('Transaction Details'!D:D,'Transaction Details'!C:C,A34,'Transaction Details'!A:A,">="&DATE(2025,2,1),'Transaction Details'!A:A,"<"&DATE(2025,3,1)) -> 24.99 | C34: =IFERROR(B34/$B$35,0) -> 0.0022875566
A35: Total Charges | B35: =SUMIFS('Transaction Details'!D:D,'Transaction Details'!A:A,">="&DATE(2025,2,1),'Transaction Details'!A:A,"<"&DATE(2025,3,1),'Transaction Details'!D:D,">0") -> 10924.32
A36: Credits & Payments | B36: =SUMIFS('Transaction Details'!D:D,'Transaction Details'!A:A,">="&DATE(2025,2,1),'Transaction Details'!A:A,"<"&DATE(2025,3,1),'Transaction Details'!D:D,"<0") -> -14054.21
A37: Net | B37: =B35+B36 -> -3129.89
A39: =DATE(2025,3,1) -> 45717
A40: Category | B40: Amount | C40: % of Month Charges
A41: Online AMEX Payment | B41: =SUMIFS('Transaction Details'!D:D,'Transaction Details'!C:C,A41,'Transaction Details'!A:A,">="&DATE(2025,3,1),'Transaction Details'!A:A,"<"&DATE(2025,4,1)) -> -18892.34 | C41: =IFERROR(B41/$B$50,0) -> -0.66358507
A42: Judd/Angela Italy Trip | B42: =SUMIFS('Transaction Details'!D:D,'Transaction Details'!C:C,A42,'Transaction Details'!A:A,">="&DATE(2025,3,1),'Transaction Details'!A:A,"<"&DATE(2025,4,1)) -> 18579.8 | C42: =IFERROR(B42/$B$50,0) -> 0.65260724
A43: DWG Canceled Software | B43: =SUMIFS('Transaction Details'!D:D,'Transaction Details'!C:C,A43,'Transaction Details'!A:A,">="&DATE(2025,3,1),'Transaction Details'!A:A,"<"&DATE(2025,4,1)) -> 219 | C43: =IFERROR(B43/$B$50,0) -> 0.007692278
A44: Personal - Food | B44: =SUMIFS('Transaction Details'!D:D,'Transaction Details'!C:C,A44,'Transaction Details'!A:A,">="&DATE(2025,3,1),'Transaction Details'!A:A,"<"&DATE(2025,4,1)) -> 177.71 | C44: =IFERROR(B44/$B$50,0) -> 0.006241985
...

Sheet Transaction Details
A1: DWG CAPITAL PARTNERS
A2: The Plum Card® | Transaction Detail
A4: Account Holder | B4: John B Dunning
A5: Account | B5: XXXX-XXXXXX-27008
A6: Statement Period | B6: Jan 1, 2025 – Dec 31, 2025
A7: Entity | B7: DWG Capital Partners
A9: Date | B9: Merchant | C9: Category | D9: Amount | E9: B/P | F9: Reimb. | G9: Notes
A10: 46022 | B10: ETERNAL ABUNDANCE | C10: Family Trip | D10: 53.09 | E10: P | F10: Yes
A11: 46022 | B11: ICONS SPORTS BAR & GRICHMOND | C11: Family Trip | D11: 91.62 | E11: P | F11: Yes
A12: 46022 | B12: STARBUCKS US | C12: Family Trip | D12: 3.84 | E12: P | F12: Yes
A13: 46022 | B13: STARBUCKS US | C13: Family Trip | D13: 33.6 | E13: P | F13: Yes
A14: 46022 | B14: UNITED AIRLINES | C14: Family Trip | D14: 38.36 | E14: P | F14: Yes
A15: 46021 | B15: BANANA REPUBLIC 6734VANCOUVER | C15: Family Trip | D15: 128.98 | E15: P | F15: Yes
A16: 46021 | B16: MOLTAQA MOROCCAN RESVANCOUVER | C16: Family Trip | D16: 219.81 | E16: P | F16: Yes
A17: 46021 | B17: MUJI ROBSON STREET 4VANCOUVER | C17: Family Trip | D17: 97.45 | E17: P | F17: Yes
A18: 46021 | B18: PUERTO MEXICO | C18: Family Trip | D18: 12.06 | E18: P | F18: Yes
A19: 46021 | B19: SAVE ON FOODS #999 | C19: Family Trip | D19: 3.17 | E19: P | F19: Yes
A20: 46021 | B20: STEVE MADDEN (SM16 VVANCOUVER | C20: Family Trip | D20: 202.67 | E20: P | F20: Yes
A21: 46021 | B21: THE NAAM RESTAURANT VANCOUVER | C21: Family Trip | D21: 208.09 | E21: P | F21: Yes
... A56: 46009 | B56: WOK N ROLL RESTAURANDELTA | C56: Family Trip | D56: 4.74 | E56: P | F56: Yes
A57: 46007 | B57: LEV INC | C57: DWG-RE Listing Platform (Redirected) | D57: 2000 | E57: B
A58: 46005 | B58: SETHAN HILL | C58: Employee Bonus | D58: 1657.5 | E58: B
A59: 45999 | B59: PUBLICGOODS.COM | C59: Personal - House | D59: 79 | E59: P | F59: Yes
A60: 45996 | B60: AMERICAN AIRLINES | C60: Team Travel (Judd) | D60: 36.14 | E60: B
A61: 45996 | B61: AMERICAN AIRLINES | C61: Team Travel (Judd) | D61: 418.18 | E61: B
A62: 45996 | B62: CUSTOMER SERVICE PAYMENT - THANK YOU | C62: Online AMEX Payment | D62: -4281.72
A63: 45996 | B63: EXPEDIA 733192261296EXPEDIA.COM | C63: Team Travel (Judd) | D63: 125.59 | E63: B
A64: 45996 | B64: MCTO TAX PAYMENT | C64: Deal Specific: 260 S Hibbert - Taxes | D64: 20243.89 | E64: B
A65: 45996 | B65: PAYMENTUS CORPORATIO800-420-1663 | C65: Utilities | D65: 455.49 | E65: B
A66: 45995 | B66: GOOGLE *HURDLR MILEA G.CO/HELPPAY# | C66: Software & Subscriptions | D66: 10.81 | E66: B
A67: 45995 | B67: ONLINE PAYMENT - THANK YOU | C67: Online AMEX Payment | D67: -16724.33
A68: 45995 | B68: UNITED AIRLINES | C68: Team Travel (Judd) | D68: 49.44 | E68: B
A69: 45995 | B69: UNITED AIRLINES | C69: Team Travel (Judd) | D69: 468.49 | E69: B
A70: 45994 | B70: FS *WICKANINNISH INNTOFINO | C70: Family Trip | D70: 4281.72 | E70: P | F70: Yes
A71: 45994 | B71: MOBILE PAYMENT - THANK YOU | C71: Online AMEX Payment | D71: -10000
A72: 45994 | B72: PROPERTYRATE APPRAISORANGE | C72: Moab Appraisal | D72: 250 | E72: B
A73: 45994 | B73: PROPERTYRATE APPRAISORANGE | C73: Moab Appraisal | D73: 250 | E73: B
A74: 45992 | B74: PAYPAL *WALMART COM 8009256278 | C74: Personal - House | D74: -0.01 | E74: P | F74: Yes
A75: 45991 | B75: PAYPAL *APPLE.COM/BI8002752273 | C75: Software & Subscriptions | D75: 8.99 | E75: B
A76: 45990 | B76: PAYPAL *APPLE.COM/BI8002752273 | C76: Software & Subscriptions | D76: 18.99 | E76: B
...

Sheet Raw Data
A1: Transaction Details | B1: The Plum Card® / Jan 01, 2025 to Dec 31, 2025
A2: Prepared for
A3: JOHN B DUNNING
A4: Account Number
A5: XXXX-XXXXXX-27008
A7: Date | B7: Description | C7: Card Member | D7: Account # | E7: Amount | F7: Extended Details | G7: Appears On Your Statement As | H7: Category
A8: 12/31/2025 | B8: ETERNAL ABUNDANCE VANCOUVER CA | C8: JOHN B DUNNING | D8: -27008 | E8: 53.09 | F8: OXOYI5 squareup.com/receipts ETERNAL ABUNDANCE VANCOUVER CA squareup.com/receiptsForeign Spend Amount: 72.60 CANADIAN DOLLAR Commission Amount: Currency Exchange Rate: null | G8: ETERNAL ABUNDANCE VANCOUVER CA | H8: Family Trip
A9: 12/31/2025 | B9: ICONS SPORTS BAR & GRICHMOND CA | C9: JOHN B DUNNING | D9: -27008 | E9: 91.62 | F9: 4379 RESTAURANT ICONS SPORTS BAR & G RICHMOND CA RESTAURANTForeign Spend Amount: 125.38 CANADIAN DOLLAR Commission Amount: Currency Exchange Rate: null | G9: ICONS SPORTS BAR & GRICHMOND CA | H9: Family Trip
A10: 12/31/2025 | B10: STARBUCKS US RICHMOND CA | C10: JOHN B DUNNING | D10: -27008 | E10: 3.84 | F10: 481210 FAST FOOD RESTAURANT STARBUCKS US RICHMOND CA FAST FOOD RESTAURANTForeign Spend Amount: 5.25 CANADIAN DOLLAR Commission Amount: Currency Exchange Rate: null | G10: STARBUCKS US RICHMOND CA | H10: Family Trip
A11: 12/31/2025 | B11: STARBUCKS US RICHMOND CA | C11: JOHN B DUNNING | D11: -27008 | E11: 33.6 | F11: 481204 FAST FOOD RESTAURANT STARBUCKS US RICHMOND CA FAST FOOD RESTAURANTForeign Spend Amount: 45.98 CANADIAN DOLLAR Commission Amount: Currency Exchange Rate: null | G11: STARBUCKS US RICHMOND CA | H11: Family Trip
A12: 12/31/2025 | B12: UNITED AIRLINES VANCOUVER CA | C12: JOHN B DUNNING | D12: -27008 | E12: 38.36 | F12: 00183460 WWW.UNITED.COM EXCESS BAGGAGE UNITED AIRLINES VANCOUVER CA Carrier : UNITED AIRLINES Passenger Name : DUNNING /SPORTING EQUIP Ticket Number : 01643581108562 Departure Day : 12/31 Additional Info : EXCESS BAGGAGE From : VANCOUVER INTERNAT To : LOS ANGELES INTERNForeign Spend Amount: 52.50 CANADIAN DOLLAR Commission Amount: Currency Exchange Rate: null | G12: UNITED AIRLINES VANCOUVER CA | H12: Family Trip
A13: 12/30/2025 | B13: BANANA REPUBLIC 6734VANCOUVER CA | C13: JOHN B DUNNING | D13: -27008 | E13: 128.98 | F13: 06734659044 FAMILY CLOTHING BANANA REPUBLIC 6734 VANCOUVER CA FAMILY CLOTHINGForeign Spend Amount: 176.39 CANADIAN DOLLAR Commission Amount: Currency Exchange Rate: null | G13: BANANA REPUBLIC 6734VANCOUVER CA | H13: Family Trip
A14: 12/30/2025 | B14: MOLTAQA MOROCCAN RESVANCOUVER CA | C14: JOHN B DUNNING | D14: -27008 | E14: 219.81 | F14: 01858251 604-696-4055 MOLTAQA MOROCCAN RESTAUR 001 VANCOUVER CA 604-696-4055Foreign Spend Amount: 300.61 CANADIAN DOLLAR Commission Amount: Currency Exchange Rate: null | G14: MOLTAQA MOROCCAN RESVANCOUVER CA | H14: Family Trip
A15: 12/30/2025 | B15: MUJI ROBSON STREET 4VANCOUVER CA | C15: JOHN B DUNNING | D15: -27008 | E15: 97.45 | F15: 11106582536 DEPARTMENT STORE MUJI ROBSON STREET 409756081 VANCOUVER CA DEPARTMENT STOREForeign Spend Amount: 133.27 CANADIAN DOLLAR Commission Amount: Currency Exchange Rate: null | G15: MUJI ROBSON STREET 4VANCOUVER CA | H15: Family Trip
A16: 12/30/2025 | B16: PUERTO MEXICO VANCOUVER CA | C16: JOHN B DUNNING | D16: -27008 | E16: 12.06 | F16: OXHHYK squareup.com/receipts PUERTO MEXICO VANCOUVER CA squareup.com/receiptsForeign Spend Amount: 16.47 CANADIAN DOLLAR Commission Amount: Currency Exchange Rate: null | G16: PUERTO MEXICO VANCOUVER CA | H16: Family Trip
A17: 12/30/2025 | B17: SAVE ON FOODS #999 NORTH VANCOUVER CA | C17: JOHN B DUNNING | D17: -27008 | E17: 3.17 | F17: 18002429229 SAVE ON FOODS #999 NORTH VANCOUVER CA 18002429229Foreign Spend Amount: 4.34 CANADIAN DOLLAR Commission Amount: Currency Exchange Rate: null | G17: SAVE ON FOODS #999 NORTH VANCOUVER CA | H17: Family Trip
A18: 12/30/2025 | B18: STEVE MADDEN (SM16 VVANCOUVER CA | C18: JOHN B DUNNING | D18: -27008 | E18: 202.67 | F18: 8 SHOE STORE STEVE MADDEN (SM16 VANCOUVER VANCOUVER CA Description : 12303598 Price : 0.00 SHOE STOREForeign Spend Amount: 277.17 CANADIAN DOLLAR Commission Amount: Currency Exchange Rate: null | G18: STEVE MADDEN (SM16 VVANCOUVER CA | H18: Family Trip
A19: 12/30/2025 | B19: THE NAAM RESTAURANT VANCOUVER CA | C19: JOHN B DUNNING | D19: -27008 | E19: 208.09 | F19: 21105185365 RESTAURANT THE NAAM RESTAURANT VANCOUVER CA RESTAURANTForeign Spend Amount: 284.59 CANADIAN DOLLAR Commission Amount: Currency Exchange Rate: null | G19: THE NAAM RESTAURANT VANCOUVER CA | H19: Family Trip
... A423: 01/01/2025 | B423: AplPay WIFIONBOARD AVANCOUVER CA | C423: JOHN B DUNNING | D423: -27008 | E423: 11.34 | F423: 409214217SS INFLIGHTWIFI AplPay WIFIONBOARD AIR CANA VANCOUVER CA INFLIGHTWIFIForeign Spend Amount: 16.28 CANADIAN DOLLAR Commission Amount: Currency Exchange Rate: null | G423: AplPay WIFIONBOARD AVANCOUVER CA | H423: Team Travel (Judd)
