Workbook

Sheet Category Summary
A1: Chase — DWG 2025 Activity
A2: Category Summary | Jan 2025 – Dec 2025
A4: Entity | B4: DWG Capital Partners
A5: Account | B5: Business Checking — Chase
A6: Period | B6: Jan 2025 – Dec 2025
A8: TOTALS
A9: Total Inflows | B9: =SUMIFS('Transaction Overview'!$D$2:$D$389,'Transaction Overview'!$D$2:$D$389,">0") -> 1476904.6
A10: Total Outflows | B10: =SUMIFS('Transaction Overview'!$D$2:$D$389,'Transaction Overview'!$D$2:$D$389,"<0") -> -1475219.5
A11: Net Change | B11: =B9+B10 -> 1685.14
A14: Category | B14: Inflows | C14: Outflows | D14: Net
A15: Deal-Specific
A16: Deal Specific | B16: =SUMIFS('Transaction Overview'!$D$2:$D$389,'Transaction Overview'!$I$2:$I$389,$A16,'Transaction Overview'!$D$2:$D$389,">0") -> 326500 | C16: =SUMIFS('Transaction Overview'!$D$2:$D$389,'Transaction Overview'!$I$2:$I$389,$A16,'Transaction Overview'!$D$2:$D$389,"<0") -> -365714.14 | D16: =B16+C16 -> -39214.14
A17: Subtotal — Deal-Specific | B17: =SUMIFS('Transaction Overview'!$D$2:$D$389,'Transaction Overview'!$J$2:$J$389,"Deal-Specific",'Transaction Overview'!$D$2:$D$389,">0") -> 326500 | C17: =SUMIFS('Transaction Overview'!$D$2:$D$389,'Transaction Overview'!$J$2:$J$389,"Deal-Specific",'Transaction Overview'!$D$2:$D$389,"<0") -> -365714.14 | D17: =B17+C17 -> -39214.14
A19: Intercompany & Savings Transfers
A20: Transfer from AIMP | B20: =SUMIFS('Transaction Overview'!$D$2:$D$389,'Transaction Overview'!$I$2:$I$389,$A20,'Transaction Overview'!$D$2:$D$389,">0") -> 500000 | C20: =SUMIFS('Transaction Overview'!$D$2:$D$389,'Transaction Overview'!$I$2:$I$389,$A20,'Transaction Overview'!$D$2:$D$389,"<0") -> 0 | D20: =B20+C20 -> 500000
A21: Transfer from AirBagit | B21: =SUMIFS('Transaction Overview'!$D$2:$D$389,'Transaction Overview'!$I$2:$I$389,$A21,'Transaction Overview'!$D$2:$D$389,">0") -> 46000 | C21: =SUMIFS('Transaction Overview'!$D$2:$D$389,'Transaction Overview'!$I$2:$I$389,$A21,'Transaction Overview'!$D$2:$D$389,"<0") -> 0 | D21: =B21+C21 -> 46000
A22: Transfer from DWG Capital Group | B22: =SUMIFS('Transaction Overview'!$D$2:$D$389,'Transaction Overview'!$I$2:$I$389,$A22,'Transaction Overview'!$D$2:$D$389,">0") -> 97500 | C22: =SUMIFS('Transaction Overview'!$D$2:$D$389,'Transaction Overview'!$I$2:$I$389,$A22,'Transaction Overview'!$D$2:$D$389,"<0") -> 0 | D22: =B22+C22 -> 97500
A23: Transfer from Ecomm_PosPrtnrs_BC | B23: =SUMIFS('Transaction Overview'!$D$2:$D$389,'Transaction Overview'!$I$2:$I$389,$A23,'Transaction Overview'!$D$2:$D$389,">0") -> 10000 | C23: =SUMIFS('Transaction Overview'!$D$2:$D$389,'Transaction Overview'!$I$2:$I$389,$A23,'Transaction Overview'!$D$2:$D$389,"<0") -> 0 | D23: =B23+C23 -> 10000
A24: Transfer from JAL Southbend | B24: =SUMIFS('Transaction Overview'!$D$2:$D$389,'Transaction Overview'!$I$2:$I$389,$A24,'Transaction Overview'!$D$2:$D$389,">0") -> 23349 | C24: =SUMIFS('Transaction Overview'!$D$2:$D$389,'Transaction Overview'!$I$2:$I$389,$A24,'Transaction Overview'!$D$2:$D$389,"<0") -> 0 | D24: =B24+C24 -> 23349
A25: Transfer from Poseidon Asset Group | B25: =SUMIFS('Transaction Overview'!$D$2:$D$389,'Transaction Overview'!$I$2:$I$389,$A25,'Transaction Overview'!$D$2:$D$389,">0") -> 201500 | C25: =SUMIFS('Transaction Overview'!$D$2:$D$389,'Transaction Overview'!$I$2:$I$389,$A25,'Transaction Overview'!$D$2:$D$389,"<0") -> 0 | D25: =B25+C25 -> 201500
A26: Transfer from Stryten Energy | B26: =SUMIFS('Transaction Overview'!$D$2:$D$389,'Transaction Overview'!$I$2:$I$389,$A26,'Transaction Overview'!$D$2:$D$389,">0") -> 270000 | C26: =SUMIFS('Transaction Overview'!$D$2:$D$389,'Transaction Overview'!$I$2:$I$389,$A26,'Transaction Overview'!$D$2:$D$389,"<0") -> 0 | D26: =B26+C26 -> 270000
A27: Transfer to AIMP | B27: =SUMIFS('Transaction Overview'!$D$2:$D$389,'Transaction Overview'!$I$2:$I$389,$A27,'Transaction Overview'!$D$2:$D$389,">0") -> 0 | C27: =SUMIFS('Transaction Overview'!$D$2:$D$389,'Transaction Overview'!$I$2:$I$389,$A27,'Transaction Overview'!$D$2:$D$389,"<0") -> -500000 | D27: =B27+C27 -> -500000
A28: Transfer to AirBagit | B28: =SUMIFS('Transaction Overview'!$D$2:$D$389,'Transaction Overview'!$I$2:$I$389,$A28,'Transaction Overview'!$D$2:$D$389,">0") -> 0 | C28: =SUMIFS('Transaction Overview'!$D$2:$D$389,'Transaction Overview'!$I$2:$I$389,$A28,'Transaction Overview'!$D$2:$D$389,"<0") -> -7500 | D28: =B28+C28 -> -7500
A29: Transfer to Poseidon Asset Group | B29: =SUMIFS('Transaction Overview'!$D$2:$D$389,'Transaction Overview'!$I$2:$I$389,$A29,'Transaction Overview'!$D$2:$D$389,">0") -> 0 | C29: =SUMIFS('Transaction Overview'!$D$2:$D$389,'Transaction Overview'!$I$2:$I$389,$A29,'Transaction Overview'!$D$2:$D$389,"<0") -> -383350 | D29: =B29+C29 -> -383350
A30: Subtotal — Intercompany & Savings Transfers | B30: =SUMIFS('Transaction Overview'!$D$2:$D$389,'Transaction Overview'!$J$2:$J$389,"Intercompany & Savings Transfers",'Transaction Overview'!$D$2:$D$389,">0") -> 1148349 | C30: =SUMIFS('Transaction Overview'!$D$2:$D$389,'Transaction Overview'!$J$2:$J$389,"Intercompany & Savings Transfers",'Transaction Overview'!$D$2:$D$389,"<0") -> -890850 | D30: =B30+C30 -> 257499
A32: Payroll & Contractors
A33: Max Rodriguez - Payroll | B33: =SUMIFS('Transaction Overview'!$D$2:$D$389,'Transaction Overview'!$I$2:$I$389,$A33,'Transaction Overview'!$D$2:$D$389,">0") -> 0 | C33: =SUMIFS('Transaction Overview'!$D$2:$D$389,'Transaction Overview'!$I$2:$I$389,$A33,'Transaction Overview'!$D$2:$D$389,"<0") -> -5000 | D33: =B33+C33 -> -5000
A34: Meg Maran - Payroll | B34: =SUMIFS('Transaction Overview'!$D$2:$D$389,'Transaction Overview'!$I$2:$I$389,$A34,'Transaction Overview'!$D$2:$D$389,">0") -> 0 | C34: =SUMIFS('Transaction Overview'!$D$2:$D$389,'Transaction Overview'!$I$2:$I$389,$A34,'Transaction Overview'!$D$2:$D$389,"<0") -> -80000 | D34: =B34+C34 -> -80000
A35: Mike Paytonjian - Payroll | B35: =SUMIFS('Transaction Overview'!$D$2:$D$389,'Transaction Overview'!$I$2:$I$389,$A35,'Transaction Overview'!$D$2:$D$389,">0") -> 0 | C35: =SUMIFS('Transaction Overview'!$D$2:$D$389,'Transaction Overview'!$I$2:$I$389,$A35,'Transaction Overview'!$D$2:$D$389,"<0") -> -2671.34 | D35: =B35+C35 -> -2671.34
A36: Ryan Billings - Payroll | B36: =SUMIFS('Transaction Overview'!$D$2:$D$389,'Transaction Overview'!$I$2:$I$389,$A36,'Transaction Overview'!$D$2:$D$389,">0") -> 0 | C36: =SUMIFS('Transaction Overview'!$D$2:$D$389,'Transaction Overview'!$I$2:$I$389,$A36,'Transaction Overview'!$D$2:$D$389,"<0") -> -55000 | D36: =B36+C36 -> -55000
A37: Sandy - PR Payment | B37: =SUMIFS('Transaction Overview'!$D$2:$D$389,'Transaction Overview'!$I$2:$I$389,$A37,'Transaction Overview'!$D$2:$D$389,">0") -> 0 | C37: =SUMIFS('Transaction Overview'!$D$2:$D$389,'Transaction Overview'!$I$2:$I$389,$A37,'Transaction Overview'!$D$2:$D$389,"<0") -> -300 | D37: =B37+C37 -> -300
A38: Subtotal — Payroll & Contractors | B38: =SUMIFS('Transaction Overview'!$D$2:$D$389,'Transaction Overview'!$J$2:$J$389,"Payroll & Contractors",'Transaction Overview'!$D$2:$D$389,">0") -> 0 | C38: =SUMIFS('Transaction Overview'!$D$2:$D$389,'Transaction Overview'!$J$2:$J$389,"Payroll & Contractors",'Transaction Overview'!$D$2:$D$389,"<0") -> -142971.34 | D38: =B38+C38 -> -142971.34
A40: P2P Payments (Zelle/Venmo/PayPal)
A41: Zelle - Joseph Whitner | B41: =SUMIFS('Transaction Overview'!$D$2:$D$389,'Transaction Overview'!$I$2:$I$389,$A41,'Transaction Overview'!$D$2:$D$389,">0") -> 2000 | C41: =SUMIFS('Transaction Overview'!$D$2:$D$389,'Transaction Overview'!$I$2:$I$389,$A41,'Transaction Overview'!$D$2:$D$389,"<0") -> 0 | D41: =B41+C41 -> 2000
A42: Subtotal — P2P Payments (Zelle/Venmo/PayPal) | B42: =SUMIFS('Transaction Overview'!$D$2:$D$389,'Transaction Overview'!$J$2:$J$389,"P2P Payments (Zelle/Venmo/PayPal)",'Transaction Overview'!$D$2:$D$389,">0") -> 2000 | C42: =SUMIFS('Transaction Overview'!$D$2:$D$389,'Transaction Overview'!$J$2:$J$389,"P2P Payments (Zelle/Venmo/PayPal)",'Transaction Overview'!$D$2:$D$389,"<0") -> 0 | D42: =B42+C42 -> 2000
A44: Credit Card & Loan Payments
A45: AMEX Credit Card Payment | B45: =SUMIFS('Transaction Overview'!$D$2:$D$389,'Transaction Overview'!$I$2:$I$389,$A45,'Transaction Overview'!$D$2:$D$389,">0") -> 0 | C45: =SUMIFS('Transaction Overview'!$D$2:$D$389,'Transaction Overview'!$I$2:$I$389,$A45,'Transaction Overview'!$D$2:$D$389,"<0") -> -39948.91 | D45: =B45+C45 -> -39948.91
A46: Subtotal — Credit Card & Loan Payments | B46: =SUMIFS('Transaction Overview'!$D$2:$D$389,'Transaction Overview'!$J$2:$J$389,"Credit Card & Loan Payments",'Transaction Overview'!$D$2:$D$389,">0") -> 0 | C46: =SUMIFS('Transaction Overview'!$D$2:$D$389,'Transaction Overview'!$J$2:$J$389,"Credit Card & Loan Payments",'Transaction Overview'!$D$2:$D$389,"<0") -> -39948.91 | D46: =B46+C46 -> -39948.91
A48: DWG Operating
A49: AI Subscription | B49: =SUMIFS('Transaction Overview'!$D$2:$D$389,'Transaction Overview'!$I$2:$I$389,$A49,'Transaction Overview'!$D$2:$D$389,">0") -> 0 | C49: =SUMIFS('Transaction Overview'!$D$2:$D$389,'Transaction Overview'!$I$2:$I$389,$A49,'Transaction Overview'!$D$2:$D$389,"<0") -> -60 | D49: =B49+C49 -> -60
...

Sheet Monthly Breakdown
A1: Chase — DWG 2025 Activity
A2: Monthly Breakdown | Jan 2025 – Dec 2025
A4: Group | B4: =DATE(2025,1,1) -> 45658 | C4: =DATE(2025,2,1) -> 45689 | D4: =DATE(2025,3,1) -> 45717 | E4: =DATE(2025,4,1) -> 45748 | F4: =DATE(2025,5,1) -> 45778 | G4: =DATE(2025,6,1) -> 45809 | H4: =DATE(2025,7,1) -> 45839 | I4: =DATE(2025,8,1) -> 45870 | J4: =DATE(2025,9,1) -> 45901 | K4: =DATE(2025,10,1) -> 45931 | L4: =DATE(2025,11,1) -> 45962 | M4: =DATE(2025,12,1) -> 45992 | N4: Total
A5: Deal-Specific | B5: =SUMIFS('Transaction Overview'!$D$2:$D$389,'Transaction Overview'!$J$2:$J$389,$A5,'Transaction Overview'!$H$2:$H$389,B$4) -> 0 | C5: =SUMIFS('Transaction Overview'!$D$2:$D$389,'Transaction Overview'!$J$2:$J$389,$A5,'Transaction Overview'!$H$2:$H$389,C$4) -> 0 | D5: =SUMIFS('Transaction Overview'!$D$2:$D$389,'Transaction Overview'!$J$2:$J$389,$A5,'Transaction Overview'!$H$2:$H$389,D$4) -> 0 | E5: =SUMIFS('Transaction Overview'!$D$2:$D$389,'Transaction Overview'!$J$2:$J$389,$A5,'Transaction Overview'!$H$2:$H$389,E$4) -> 0 | F5: =SUMIFS('Transaction Overview'!$D$2:$D$389,'Transaction Overview'!$J$2:$J$389,$A5,'Transaction Overview'!$H$2:$H$389,F$4) -> 0 | G5: =SUMIFS('Transaction Overview'!$D$2:$D$389,'Transaction Overview'!$J$2:$J$389,$A5,'Transaction Overview'!$H$2:$H$389,G$4) -> 0 | H5: =SUMIFS('Transaction Overview'!$D$2:$D$389,'Transaction Overview'!$J$2:$J$389,$A5,'Transaction Overview'!$H$2:$H$389,H$4) -> 0 | I5: =SUMIFS('Transaction Overview'!$D$2:$D$389,'Transaction Overview'!$J$2:$J$389,$A5,'Transaction Overview'!$H$2:$H$389,I$4) -> -3500 | ... M5: =SUMIFS('Transaction Overview'!$D$2:$D$389,'Transaction Overview'!$J$2:$J$389,$A5,'Transaction Overview'!$H$2:$H$389,M$4) -> 89642.93 | N5: =SUM(B5:M5) -> -39214.14
A6: Intercompany & Savings Transfers | B6: =SUMIFS('Transaction Overview'!$D$2:$D$389,'Transaction Overview'!$J$2:$J$389,$A6,'Transaction Overview'!$H$2:$H$389,B$4) -> 0 | C6: =SUMIFS('Transaction Overview'!$D$2:$D$389,'Transaction Overview'!$J$2:$J$389,$A6,'Transaction Overview'!$H$2:$H$389,C$4) -> 0 | D6: =SUMIFS('Transaction Overview'!$D$2:$D$389,'Transaction Overview'!$J$2:$J$389,$A6,'Transaction Overview'!$H$2:$H$389,D$4) -> 0 | E6: =SUMIFS('Transaction Overview'!$D$2:$D$389,'Transaction Overview'!$J$2:$J$389,$A6,'Transaction Overview'!$H$2:$H$389,E$4) -> 0 | F6: =SUMIFS('Transaction Overview'!$D$2:$D$389,'Transaction Overview'!$J$2:$J$389,$A6,'Transaction Overview'!$H$2:$H$389,F$4) -> 47000 | G6: =SUMIFS('Transaction Overview'!$D$2:$D$389,'Transaction Overview'!$J$2:$J$389,$A6,'Transaction Overview'!$H$2:$H$389,G$4) -> 32000 | H6: =SUMIFS('Transaction Overview'!$D$2:$D$389,'Transaction Overview'!$J$2:$J$389,$A6,'Transaction Overview'!$H$2:$H$389,H$4) -> 65000 | I6: =SUMIFS('Transaction Overview'!$D$2:$D$389,'Transaction Overview'!$J$2:$J$389,$A6,'Transaction Overview'!$H$2:$H$389,I$4) -> 18500 | ... M6: =SUMIFS('Transaction Overview'!$D$2:$D$389,'Transaction Overview'!$J$2:$J$389,$A6,'Transaction Overview'!$H$2:$H$389,M$4) -> -62501 | N6: =SUM(B6:M6) -> 257499
A7: Payroll & Contractors | B7: =SUMIFS('Transaction Overview'!$D$2:$D$389,'Transaction Overview'!$J$2:$J$389,$A7,'Transaction Overview'!$H$2:$H$389,B$4) -> 0 | C7: =SUMIFS('Transaction Overview'!$D$2:$D$389,'Transaction Overview'!$J$2:$J$389,$A7,'Transaction Overview'!$H$2:$H$389,C$4) -> 0 | D7: =SUMIFS('Transaction Overview'!$D$2:$D$389,'Transaction Overview'!$J$2:$J$389,$A7,'Transaction Overview'!$H$2:$H$389,D$4) -> 0 | E7: =SUMIFS('Transaction Overview'!$D$2:$D$389,'Transaction Overview'!$J$2:$J$389,$A7,'Transaction Overview'!$H$2:$H$389,E$4) -> 0 | F7: =SUMIFS('Transaction Overview'!$D$2:$D$389,'Transaction Overview'!$J$2:$J$389,$A7,'Transaction Overview'!$H$2:$H$389,F$4) -> -20000 | G7: =SUMIFS('Transaction Overview'!$D$2:$D$389,'Transaction Overview'!$J$2:$J$389,$A7,'Transaction Overview'!$H$2:$H$389,G$4) -> -22671.34 | H7: =SUMIFS('Transaction Overview'!$D$2:$D$389,'Transaction Overview'!$J$2:$J$389,$A7,'Transaction Overview'!$H$2:$H$389,H$4) -> -30000 | I7: =SUMIFS('Transaction Overview'!$D$2:$D$389,'Transaction Overview'!$J$2:$J$389,$A7,'Transaction Overview'!$H$2:$H$389,I$4) -> -20000 | ... M7: =SUMIFS('Transaction Overview'!$D$2:$D$389,'Transaction Overview'!$J$2:$J$389,$A7,'Transaction Overview'!$H$2:$H$389,M$4) -> -10300 | N7: =SUM(B7:M7) -> -142971.34
A8: P2P Payments (Zelle/Venmo/PayPal) | B8: =SUMIFS('Transaction Overview'!$D$2:$D$389,'Transaction Overview'!$J$2:$J$389,$A8,'Transaction Overview'!$H$2:$H$389,B$4) -> 0 | C8: =SUMIFS('Transaction Overview'!$D$2:$D$389,'Transaction Overview'!$J$2:$J$389,$A8,'Transaction Overview'!$H$2:$H$389,C$4) -> 0 | D8: =SUMIFS('Transaction Overview'!$D$2:$D$389,'Transaction Overview'!$J$2:$J$389,$A8,'Transaction Overview'!$H$2:$H$389,D$4) -> 0 | E8: =SUMIFS('Transaction Overview'!$D$2:$D$389,'Transaction Overview'!$J$2:$J$389,$A8,'Transaction Overview'!$H$2:$H$389,E$4) -> 0 | F8: =SUMIFS('Transaction Overview'!$D$2:$D$389,'Transaction Overview'!$J$2:$J$389,$A8,'Transaction Overview'!$H$2:$H$389,F$4) -> 0 | G8: =SUMIFS('Transaction Overview'!$D$2:$D$389,'Transaction Overview'!$J$2:$J$389,$A8,'Transaction Overview'!$H$2:$H$389,G$4) -> 0 | H8: =SUMIFS('Transaction Overview'!$D$2:$D$389,'Transaction Overview'!$J$2:$J$389,$A8,'Transaction Overview'!$H$2:$H$389,H$4) -> 0 | I8: =SUMIFS('Transaction Overview'!$D$2:$D$389,'Transaction Overview'!$J$2:$J$389,$A8,'Transaction Overview'!$H$2:$H$389,I$4) -> 2000 | ... M8: =SUMIFS('Transaction Overview'!$D$2:$D$389,'Transaction Overview'!$J$2:$J$389,$A8,'Transaction Overview'!$H$2:$H$389,M$4) -> 0 | N8: =SUM(B8:M8) -> 2000
A9: Credit Card & Loan Payments | B9: =SUMIFS('Transaction Overview'!$D$2:$D$389,'Transaction Overview'!$J$2:$J$389,$A9,'Transaction Overview'!$H$2:$H$389,B$4) -> 0 | C9: =SUMIFS('Transaction Overview'!$D$2:$D$389,'Transaction Overview'!$J$2:$J$389,$A9,'Transaction Overview'!$H$2:$H$389,C$4) -> 0 | D9: =SUMIFS('Transaction Overview'!$D$2:$D$389,'Transaction Overview'!$J$2:$J$389,$A9,'Transaction Overview'!$H$2:$H$389,D$4) -> 0 | E9: =SUMIFS('Transaction Overview'!$D$2:$D$389,'Transaction Overview'!$J$2:$J$389,$A9,'Transaction Overview'!$H$2:$H$389,E$4) -> 0 | F9: =SUMIFS('Transaction Overview'!$D$2:$D$389,'Transaction Overview'!$J$2:$J$389,$A9,'Transaction Overview'!$H$2:$H$389,F$4) -> -35152.11 | G9: =SUMIFS('Transaction Overview'!$D$2:$D$389,'Transaction Overview'!$J$2:$J$389,$A9,'Transaction Overview'!$H$2:$H$389,G$4) -> -180.24 | H9: =SUMIFS('Transaction Overview'!$D$2:$D$389,'Transaction Overview'!$J$2:$J$389,$A9,'Transaction Overview'!$H$2:$H$389,H$4) -> 0 | I9: =SUMIFS('Transaction Overview'!$D$2:$D$389,'Transaction Overview'!$J$2:$J$389,$A9,'Transaction Overview'!$H$2:$H$389,I$4) -> 0 | ... M9: =SUMIFS('Transaction Overview'!$D$2:$D$389,'Transaction Overview'!$J$2:$J$389,$A9,'Transaction Overview'!$H$2:$H$389,M$4) -> 0 | N9: =SUM(B9:M9) -> -39948.91
A10: DWG Operating | B10: =SUMIFS('Transaction Overview'!$D$2:$D$389,'Transaction Overview'!$J$2:$J$389,$A10,'Transaction Overview'!$H$2:$H$389,B$4) -> 0 | C10: =SUMIFS('Transaction Overview'!$D$2:$D$389,'Transaction Overview'!$J$2:$J$389,$A10,'Transaction Overview'!$H$2:$H$389,C$4) -> 0 | D10: =SUMIFS('Transaction Overview'!$D$2:$D$389,'Transaction Overview'!$J$2:$J$389,$A10,'Transaction Overview'!$H$2:$H$389,D$4) -> 0 | E10: =SUMIFS('Transaction Overview'!$D$2:$D$389,'Transaction Overview'!$J$2:$J$389,$A10,'Transaction Overview'!$H$2:$H$389,E$4) -> 0 | F10: =SUMIFS('Transaction Overview'!$D$2:$D$389,'Transaction Overview'!$J$2:$J$389,$A10,'Transaction Overview'!$H$2:$H$389,F$4) -> -972.28 | G10: =SUMIFS('Transaction Overview'!$D$2:$D$389,'Transaction Overview'!$J$2:$J$389,$A10,'Transaction Overview'!$H$2:$H$389,G$4) -> -982.28 | H10: =SUMIFS('Transaction Overview'!$D$2:$D$389,'Transaction Overview'!$J$2:$J$389,$A10,'Transaction Overview'!$H$2:$H$389,H$4) -> -771.15 | I10: =SUMIFS('Transaction Overview'!$D$2:$D$389,'Transaction Overview'!$J$2:$J$389,$A10,'Transaction Overview'!$H$2:$H$389,I$4) -> -1130.82 | ... M10: =SUMIFS('Transaction Overview'!$D$2:$D$389,'Transaction Overview'!$J$2:$J$389,$A10,'Transaction Overview'!$H$2:$H$389,M$4) -> -2374.03 | N10: =SUM(B10:M10) -> -8007.21
A11: Personal — Owner | B11: =SUMIFS('Transaction Overview'!$D$2:$D$389,'Transaction Overview'!$J$2:$J$389,$A11,'Transaction Overview'!$H$2:$H$389,B$4) -> 0 | C11: =SUMIFS('Transaction Overview'!$D$2:$D$389,'Transaction Overview'!$J$2:$J$389,$A11,'Transaction Overview'!$H$2:$H$389,C$4) -> 0 | D11: =SUMIFS('Transaction Overview'!$D$2:$D$389,'Transaction Overview'!$J$2:$J$389,$A11,'Transaction Overview'!$H$2:$H$389,D$4) -> 0 | E11: =SUMIFS('Transaction Overview'!$D$2:$D$389,'Transaction Overview'!$J$2:$J$389,$A11,'Transaction Overview'!$H$2:$H$389,E$4) -> 0 | F11: =SUMIFS('Transaction Overview'!$D$2:$D$389,'Transaction Overview'!$J$2:$J$389,$A11,'Transaction Overview'!$H$2:$H$389,F$4) -> -2181.06 | G11: =SUMIFS('Transaction Overview'!$D$2:$D$389,'Transaction Overview'!$J$2:$J$389,$A11,'Transaction Overview'!$H$2:$H$389,G$4) -> -6157.42 | H11: =SUMIFS('Transaction Overview'!$D$2:$D$389,'Transaction Overview'!$J$2:$J$389,$A11,'Transaction Overview'!$H$2:$H$389,H$4) -> -2594.71 | I11: =SUMIFS('Transaction Overview'!$D$2:$D$389,'Transaction Overview'!$J$2:$J$389,$A11,'Transaction Overview'!$H$2:$H$389,I$4) -> -2035.68 | ... M11: =SUMIFS('Transaction Overview'!$D$2:$D$389,'Transaction Overview'!$J$2:$J$389,$A11,'Transaction Overview'!$H$2:$H$389,M$4) -> -965.58 | N11: =SUM(B11:M11) -> -17549.27
A12: Uncategorized — Review | B12: =SUMIFS('Transaction Overview'!$D$2:$D$389,'Transaction Overview'!$J$2:$J$389,$A12,'Transaction Overview'!$H$2:$H$389,B$4) -> 0 | C12: =SUMIFS('Transaction Overview'!$D$2:$D$389,'Transaction Overview'!$J$2:$J$389,$A12,'Transaction Overview'!$H$2:$H$389,C$4) -> 0 | D12: =SUMIFS('Transaction Overview'!$D$2:$D$389,'Transaction Overview'!$J$2:$J$389,$A12,'Transaction Overview'!$H$2:$H$389,D$4) -> 0 | E12: =SUMIFS('Transaction Overview'!$D$2:$D$389,'Transaction Overview'!$J$2:$J$389,$A12,'Transaction Overview'!$H$2:$H$389,E$4) -> 0 | F12: =SUMIFS('Transaction Overview'!$D$2:$D$389,'Transaction Overview'!$J$2:$J$389,$A12,'Transaction Overview'!$H$2:$H$389,F$4) -> 0 | G12: =SUMIFS('Transaction Overview'!$D$2:$D$389,'Transaction Overview'!$J$2:$J$389,$A12,'Transaction Overview'!$H$2:$H$389,G$4) -> 0 | H12: =SUMIFS('Transaction Overview'!$D$2:$D$389,'Transaction Overview'!$J$2:$J$389,$A12,'Transaction Overview'!$H$2:$H$389,H$4) -> -10122.99 | I12: =SUMIFS('Transaction Overview'!$D$2:$D$389,'Transaction Overview'!$J$2:$J$389,$A12,'Transaction Overview'!$H$2:$H$389,I$4) -> 0 | ... M12: =SUMIFS('Transaction Overview'!$D$2:$D$389,'Transaction Overview'!$J$2:$J$389,$A12,'Transaction Overview'!$H$2:$H$389,M$4) -> 0 | N12: =SUM(B12:M12) -> -10122.99

Sheet Transfer In
A1: Chase — DWG 2025 Activity
A2: Intercompany Transfers — In | Jan 2025 – Dec 2025
A4: SUMMARY
A5: Total | C5: =SUMIFS('Transaction Overview'!$D$2:$D$389,'Transaction Overview'!$J$2:$J$389,"Intercompany & Savings Transfers",'Transaction Overview'!$D$2:$D$389,">0") -> 1148349
A6: # Transactions | C6: =COUNTIFS('Transaction Overview'!$J$2:$J$389,"Intercompany & Savings Transfers",'Transaction Overview'!$D$2:$D$389,">0") -> 32

Sheet Transfer Out
A1: Chase — DWG 2025 Activity
A2: Intercompany Transfers — Out | Jan 2025 – Dec 2025
A4: SUMMARY
A5: Total | C5: =SUMIFS('Transaction Overview'!$D$2:$D$389,'Transaction Overview'!$J$2:$J$389,"Intercompany & Savings Transfers",'Transaction Overview'!$D$2:$D$389,"<0") -> -890850
A6: # Transactions | C6: =COUNTIFS('Transaction Overview'!$J$2:$J$389,"Intercompany & Savings Transfers",'Transaction Overview'!$D$2:$D$389,"<0") -> 7

Sheet Commission
A1: Chase — DWG 2025 Activity
A2: Commissions Statement | Jan 2025 – Dec 2025
A4: SUMMARY
A5: Total | C5: =SUMIFS('Transaction Overview'!$D$2:$D$389,'Transaction Overview'!$J$2:$J$389,"Payroll & Contractors",'Transaction Overview'!$D$2:$D$389,"<0") -> -142971.34
A6: # Transactions | C6: =COUNTIFS('Transaction Overview'!$J$2:$J$389,"Payroll & Contractors",'Transaction Overview'!$D$2:$D$389,"<0") -> 29

Sheet Transaction Overview
A1: Details | B1: Posting Date | C1: Description | D1: Amount | E1: Type | F1: Balance | G1: Category | H1: Month | I1: Combined Category | J1: Group
A2: =2025_DWG_Activity!A2 -> DEBIT | B2: =2025_DWG_Activity!B2 -> 46022 | C2: =2025_DWG_Activity!C2 -> Online Transfer to CHK ...9335 transaction#: 27532478452 12/31 | D2: =2025_DWG_Activity!D2 -> -23350 | E2: =2025_DWG_Activity!E2 -> ACCT_XFER | F2: =2025_DWG_Activity!F2 -> 13515.83 | G2: =2025_DWG_Activity!G2 -> Transfer to Poseidon Asset Group | H2: =IF($B2="","",DATE(YEAR($B2),MONTH($B2),1)) -> 45992 | I2: =IF($G2="","Uncategorized — Review",IFERROR(INDEX(Mapping!$B:$B,MATCH($G2,Mapping!$A:$A,0)),"Uncategorized — Review")) -> Transfer to Poseidon Asset Group | J2: =IF($G2="","Uncategorized — Review",IFERROR(INDEX(Mapping!$C:$C,MATCH($G2,Mapping!$A:$A,0)),"Uncategorized — Review")) -> Intercompany & Savings Transfers
A3: =2025_DWG_Activity!A3 -> DEBIT | B3: =2025_DWG_Activity!B3 -> 46022 | C3: =2025_DWG_Activity!C3 -> ELEMENTOR.COM ELEMENTOR.COM DE 12/30 | D3: =2025_DWG_Activity!D3 -> -99 | E3: =2025_DWG_Activity!E3 -> DEBIT_CARD | F3: =2025_DWG_Activity!F3 -> 36865.83 | G3: =2025_DWG_Activity!G3 -> DWG Marketing | H3: =IF($B3="","",DATE(YEAR($B3),MONTH($B3),1)) -> 45992 | I3: =IF($G3="","Uncategorized — Review",IFERROR(INDEX(Mapping!$B:$B,MATCH($G3,Mapping!$A:$A,0)),"Uncategorized — Review")) -> DWG Marketing | J3: =IF($G3="","Uncategorized — Review",IFERROR(INDEX(Mapping!$C:$C,MATCH($G3,Mapping!$A:$A,0)),"Uncategorized — Review")) -> DWG Operating
A4: =2025_DWG_Activity!A4 -> DEBIT | B4: =2025_DWG_Activity!B4 -> 46022 | C4: =2025_DWG_Activity!C4 -> PP*APPLE.COM/BILL 800-275-2273 CA 12/30 | D4: =2025_DWG_Activity!D4 -> -8.99 | E4: =2025_DWG_Activity!E4 -> DEBIT_CARD | F4: =2025_DWG_Activity!F4 -> 36964.83 | G4: =2025_DWG_Activity!G4 -> Personal - Subscriptions | H4: =IF($B4="","",DATE(YEAR($B4),MONTH($B4),1)) -> 45992 | I4: =IF($G4="","Uncategorized — Review",IFERROR(INDEX(Mapping!$B:$B,MATCH($G4,Mapping!$A:$A,0)),"Uncategorized — Review")) -> Personal - Subscriptions | J4: =IF($G4="","Uncategorized — Review",IFERROR(INDEX(Mapping!$C:$C,MATCH($G4,Mapping!$A:$A,0)),"Uncategorized — Review")) -> Personal — Owner
A5: =2025_DWG_Activity!A5 -> DEBIT | B5: =2025_DWG_Activity!B5 -> 46022 | C5: =2025_DWG_Activity!C5 -> PAYPAL *LINKEDIN 402-935-7733 CA 12/30 | D5: =2025_DWG_Activity!D5 -> -508 | E5: =2025_DWG_Activity!E5 -> DEBIT_CARD | F5: =2025_DWG_Activity!F5 -> 36973.82 | G5: =2025_DWG_Activity!G5 -> DWG HR | H5: =IF($B5="","",DATE(YEAR($B5),MONTH($B5),1)) -> 45992 | I5: =IF($G5="","Uncategorized — Review",IFERROR(INDEX(Mapping!$B:$B,MATCH($G5,Mapping!$A:$A,0)),"Uncategorized — Review")) -> DWG HR | J5: =IF($G5="","Uncategorized — Review",IFERROR(INDEX(Mapping!$C:$C,MATCH($G5,Mapping!$A:$A,0)),"Uncategorized — Review")) -> DWG Operating
A6: =2025_DWG_Activity!A6 -> CREDIT | B6: =2025_DWG_Activity!B6 -> 46022 | C6: =2025_DWG_Activity!C6 -> Online Transfer from CHK ...9769 transaction#: 27532436614 | D6: =2025_DWG_Activity!D6 -> 23349 | E6: =2025_DWG_Activity!E6 -> ACCT_XFER | F6: =2025_DWG_Activity!F6 -> 37481.82 | G6: =2025_DWG_Activity!G6 -> Transfer from JAL Southbend | H6: =IF($B6="","",DATE(YEAR($B6),MONTH($B6),1)) -> 45992 | I6: =IF($G6="","Uncategorized — Review",IFERROR(INDEX(Mapping!$B:$B,MATCH($G6,Mapping!$A:$A,0)),"Uncategorized — Review")) -> Transfer from JAL Southbend | J6: =IF($G6="","Uncategorized — Review",IFERROR(INDEX(Mapping!$C:$C,MATCH($G6,Mapping!$A:$A,0)),"Uncategorized — Review")) -> Intercompany & Savings Transfers
A7: =2025_DWG_Activity!A7 -> DEBIT | B7: =2025_DWG_Activity!B7 -> 46021 | C7: =2025_DWG_Activity!C7 -> Online Transfer to CHK ...1283 transaction#: 27515609629 12/30 | D7: =2025_DWG_Activity!D7 -> -235000 | E7: =2025_DWG_Activity!E7 -> ACCT_XFER | F7: =2025_DWG_Activity!F7 -> 14132.82 | G7: =2025_DWG_Activity!G7 -> Deal Specific | H7: =IF($B7="","",DATE(YEAR($B7),MONTH($B7),1)) -> 45992 | I7: =IF($G7="","Uncategorized — Review",IFERROR(INDEX(Mapping!$B:$B,MATCH($G7,Mapping!$A:$A,0)),"Uncategorized — Review")) -> Deal Specific | J7: =IF($G7="","Uncategorized — Review",IFERROR(INDEX(Mapping!$C:$C,MATCH($G7,Mapping!$A:$A,0)),"Uncategorized — Review")) -> Deal-Specific
A8: =2025_DWG_Activity!A8 -> DEBIT | B8: =2025_DWG_Activity!B8 -> 46021 | C8: =2025_DWG_Activity!C8 -> BREVITAS 415-993-8886 CA 12/30 | D8: =2025_DWG_Activity!D8 -> -187 | E8: =2025_DWG_Activity!E8 -> DEBIT_CARD | F8: =2025_DWG_Activity!F8 -> 249132.82 | G8: =2025_DWG_Activity!G8 -> DWG Listing Platform | H8: =IF($B8="","",DATE(YEAR($B8),MONTH($B8),1)) -> 45992 | I8: =IF($G8="","Uncategorized — Review",IFERROR(INDEX(Mapping!$B:$B,MATCH($G8,Mapping!$A:$A,0)),"Uncategorized — Review")) -> DWG Listing Platform | J8: =IF($G8="","Uncategorized — Review",IFERROR(INDEX(Mapping!$C:$C,MATCH($G8,Mapping!$A:$A,0)),"Uncategorized — Review")) -> DWG Operating
A9: =2025_DWG_Activity!A9 -> DEBIT | B9: =2025_DWG_Activity!B9 -> 46021 | C9: =2025_DWG_Activity!C9 -> Basic Online Payroll Payment 11199342689 to ########6812 | D9: =2025_DWG_Activity!D9 -> -5000 | E9: =2025_DWG_Activity!E9 -> BASIC_PAYROLL | F9: =2025_DWG_Activity!F9 -> 249319.82 | G9: =2025_DWG_Activity!G9 -> Meg Maran - Payroll | H9: =IF($B9="","",DATE(YEAR($B9),MONTH($B9),1)) -> 45992 | I9: =IF($G9="","Uncategorized — Review",IFERROR(INDEX(Mapping!$B:$B,MATCH($G9,Mapping!$A:$A,0)),"Uncategorized — Review")) -> Meg Maran - Payroll | J9: =IF($G9="","Uncategorized — Review",IFERROR(INDEX(Mapping!$C:$C,MATCH($G9,Mapping!$A:$A,0)),"Uncategorized — Review")) -> Payroll & Contractors
A10: =2025_DWG_Activity!A10 -> DEBIT | B10: =2025_DWG_Activity!B10 -> 46020 | C10: =2025_DWG_Activity!C10 -> PP*APPLE.COM/BILL 800-275-2273 CA 12/27 | D10: =2025_DWG_Activity!D10 -> -18.99 | E10: =2025_DWG_Activity!E10 -> DEBIT_CARD | F10: =2025_DWG_Activity!F10 -> 254319.82 | G10: =2025_DWG_Activity!G10 -> Personal - Subscriptions | H10: =IF($B10="","",DATE(YEAR($B10),MONTH($B10),1)) -> 45992 | I10: =IF($G10="","Uncategorized — Review",IFERROR(INDEX(Mapping!$B:$B,MATCH($G10,Mapping!$A:$A,0)),"Uncategorized — Review")) -> Personal - Subscriptions | J10: =IF($G10="","Uncategorized — Review",IFERROR(INDEX(Mapping!$C:$C,MATCH($G10,Mapping!$A:$A,0)),"Uncategorized — Review")) -> Personal — Owner
A11: =2025_DWG_Activity!A11 -> DEBIT | B11: =2025_DWG_Activity!B11 -> 46020 | C11: =2025_DWG_Activity!C11 -> PP*APPLE.COM/BILL 800-275-2273 CA 12/27 | D11: =2025_DWG_Activity!D11 -> -18.49 | E11: =2025_DWG_Activity!E11 -> DEBIT_CARD | F11: =2025_DWG_Activity!F11 -> 254338.81 | G11: =2025_DWG_Activity!G11 -> Personal - Subscriptions | H11: =IF($B11="","",DATE(YEAR($B11),MONTH($B11),1)) -> 45992 | I11: =IF($G11="","Uncategorized — Review",IFERROR(INDEX(Mapping!$B:$B,MATCH($G11,Mapping!$A:$A,0)),"Uncategorized — Review")) -> Personal - Subscriptions | J11: =IF($G11="","Uncategorized — Review",IFERROR(INDEX(Mapping!$C:$C,MATCH($G11,Mapping!$A:$A,0)),"Uncategorized — Review")) -> Personal — Owner
A12: =2025_DWG_Activity!A12 -> DEBIT | B12: =2025_DWG_Activity!B12 -> 46020 | C12: =2025_DWG_Activity!C12 -> PP*APPLE.COM/BILL 800-275-2273 CA 12/26 | D12: =2025_DWG_Activity!D12 -> -9.99 | E12: =2025_DWG_Activity!E12 -> DEBIT_CARD | F12: =2025_DWG_Activity!F12 -> 254357.3 | G12: =2025_DWG_Activity!G12 -> Personal - Subscriptions | H12: =IF($B12="","",DATE(YEAR($B12),MONTH($B12),1)) -> 45992 | I12: =IF($G12="","Uncategorized — Review",IFERROR(INDEX(Mapping!$B:$B,MATCH($G12,Mapping!$A:$A,0)),"Uncategorized — Review")) -> Personal - Subscriptions | J12: =IF($G12="","Uncategorized — Review",IFERROR(INDEX(Mapping!$C:$C,MATCH($G12,Mapping!$A:$A,0)),"Uncategorized — Review")) -> Personal — Owner
A13: =2025_DWG_Activity!A13 -> DEBIT | B13: =2025_DWG_Activity!B13 -> 46020 | C13: =2025_DWG_Activity!C13 -> PP*APPLE.COM/BILL 800-275-2273 CA 12/26 | D13: =2025_DWG_Activity!D13 -> -100 | E13: =2025_DWG_Activity!E13 -> DEBIT_CARD | F13: =2025_DWG_Activity!F13 -> 254367.29 | G13: =2025_DWG_Activity!G13 -> Personal - Subscriptions | H13: =IF($B13="","",DATE(YEAR($B13),MONTH($B13),1)) -> 45992 | I13: =IF($G13="","Uncategorized — Review",IFERROR(INDEX(Mapping!$B:$B,MATCH($G13,Mapping!$A:$A,0)),"Uncategorized — Review")) -> Personal - Subscriptions | J13: =IF($G13="","Uncategorized — Review",IFERROR(INDEX(Mapping!$C:$C,MATCH($G13,Mapping!$A:$A,0)),"Uncategorized — Review")) -> Personal — Owner
... A389: =2025_DWG_Activity!A389 -> DEBIT | B389: =2025_DWG_Activity!B389 -> 45779 | C389: =2025_DWG_Activity!C389 -> LAX AIRP CROWNS LAX T4 LOS ANGELES CA 04/30 | D389: =2025_DWG_Activity!D389 -> -29.38 | E389: =2025_DWG_Activity!E389 -> DEBIT_CARD | F389: =2025_DWG_Activity!F389 -> 11801.31 | G389: =2025_DWG_Activity!G389 -> Personal - Food | H389: =IF($B389="","",DATE(YEAR($B389),MONTH($B389),1)) -> 45778 | I389: =IF($G389="","Uncategorized — Review",IFERROR(INDEX(Mapping!$B:$B,MATCH($G389,Mapping!$A:$A,0)),"Uncategorized — Review")) -> Personal - Food | J389: =IF($G389="","Uncategorized — Review",IFERROR(INDEX(Mapping!$C:$C,MATCH($G389,Mapping!$A:$A,0)),"Uncategorized — Review")) -> Personal — Owner

Sheet Mapping
A1: Raw Category | B1: Combined Category | C1: Group
A2: AI Subscription | B2: AI Subscription | C2: DWG Operating
A3: AMEX Credit Card Payment | B3: AMEX Credit Card Payment | C3: Credit Card & Loan Payments
A4: ATM Withdrawal | B4: ATM Withdrawal | C4: Uncategorized — Review
A5: Amazon | B5: Amazon | C5: Personal — Owner
A6: Bank Fees | B6: Bank Fees | C6: DWG Operating
A7: DWG Capital Partners | B7: DWG Capital Partners | C7: DWG Operating
A8: DWG HR | B8: DWG HR | C8: DWG Operating
A9: DWG Listing Platform | B9: DWG Listing Platform | C9: DWG Operating
A10: DWG Marketing | B10: DWG Marketing | C10: DWG Operating
A11: Deal Specific | B11: Deal Specific | C11: Deal-Specific
A12: Go Daddy | B12: Go Daddy | C12: DWG Operating
... A42: Zelle - Joseph Whitner | B42: Zelle - Joseph Whitner | C42: P2P Payments (Zelle/Venmo/PayPal)

Sheet 2025_DWG_Activity
A1: Details | B1: Posting Date | C1: Description | D1: Amount | E1: Type | F1: Balance | G1: Categories
A2: DEBIT | B2: 46022 | C2: Online Transfer to CHK ...9335 transaction#: 27532478452 12/31 | D2: -23350 | E2: ACCT_XFER | F2: 13515.83 | G2: Transfer to Poseidon Asset Group
A3: DEBIT | B3: 46022 | C3: ELEMENTOR.COM ELEMENTOR.COM DE 12/30 | D3: -99 | E3: DEBIT_CARD | F3: 36865.83 | G3: DWG Marketing
A4: DEBIT | B4: 46022 | C4: PP*APPLE.COM/BILL 800-275-2273 CA 12/30 | D4: -8.99 | E4: DEBIT_CARD | F4: 36964.83 | G4: Personal - Subscriptions
A5: DEBIT | B5: 46022 | C5: PAYPAL *LINKEDIN 402-935-7733 CA 12/30 | D5: -508 | E5: DEBIT_CARD | F5: 36973.82 | G5: DWG HR
A6: CREDIT | B6: 46022 | C6: Online Transfer from CHK ...9769 transaction#: 27532436614 | D6: 23349 | E6: ACCT_XFER | F6: 37481.82 | G6: Transfer from JAL Southbend
A7: DEBIT | B7: 46021 | C7: Online Transfer to CHK ...1283 transaction#: 27515609629 12/30 | D7: -235000 | E7: ACCT_XFER | F7: 14132.82 | G7: Deal Specific
A8: DEBIT | B8: 46021 | C8: BREVITAS 415-993-8886 CA 12/30 | D8: -187 | E8: DEBIT_CARD | F8: 249132.82 | G8: DWG Listing Platform
A9: DEBIT | B9: 46021 | C9: Basic Online Payroll Payment 11199342689 to ########6812 | D9: -5000 | E9: BASIC_PAYROLL | F9: 249319.82 | G9: Meg Maran - Payroll
A10: DEBIT | B10: 46020 | C10: PP*APPLE.COM/BILL 800-275-2273 CA 12/27 | D10: -18.99 | E10: DEBIT_CARD | F10: 254319.82 | G10: Personal - Subscriptions
A11: DEBIT | B11: 46020 | C11: PP*APPLE.COM/BILL 800-275-2273 CA 12/27 | D11: -18.49 | E11: DEBIT_CARD | F11: 254338.81 | G11: Personal - Subscriptions
A12: DEBIT | B12: 46020 | C12: PP*APPLE.COM/BILL 800-275-2273 CA 12/26 | D12: -9.99 | E12: DEBIT_CARD | F12: 254357.3 | G12: Personal - Subscriptions
A13: DEBIT | B13: 46020 | C13: PP*APPLE.COM/BILL 800-275-2273 CA 12/26 | D13: -100 | E13: DEBIT_CARD | F13: 254367.29 | G13: Personal - Subscriptions
... A199: DEBIT | B199: 45859 | C199: ONLINE DOMESTIC WIRE FEE | D199: -25 | E199: FEE_TRANSACTION | F199: 35798.49 | G199: Bank Fees
A200: DEBIT | B200: 45859 | C200: ONLINE DOMESTIC WIRE TRANSFER VIA: WASH FEDL SVGS SEA/325070980 A/C: DWG CAPITAL PARTNERS LLC SEATTLE WA 98101 US IMAD: 0721MMQFMP2L024886 TRN: 3638425202ES 07/21 | D200: -10000 | E200: WIRE_OUTGOING | F200: 35823.49
A201: CREDIT | B201: 45859 | C201: Online Transfer from CHK ...9335 transaction#: 25563251227 | D201: 10000 | E201: ACCT_XFER | F201: 45823.49 | G201: Transfer from Poseidon Asset Group
A202: DEBIT | B202: 45856 | C202: DNH*GODADDY#38209789 https://www.g AZ 07/17 | D202: -19.97 | E202: DEBIT_CARD | F202: 35823.49 | G202: Go Daddy
A203: DEBIT | B203: 45856 | C203: DNH*GODADDY#38209789 https://www.g AZ 07/17 | D203: -13.98 | E203: DEBIT_CARD | F203: 35843.46 | G203: Go Daddy
A204: CREDIT | B204: 45855 | C204: ORIG CO NAME:#QRR Melio ORIG ID:1460820571 DESC DATE: CO ENTRY DESCR:ACCTVERIFYSEC:PPD TRACE#:021214898583365 EED:250717 IND ID: IND NAME:John Dunning TRN: 1988583365TC | D204: 0.01 | E204: ACH_CREDIT | F204: 35857.44 | G204: Verification
A205: DEBIT | B205: 45854 | C205: DNH*GODADDY#38184470 https://www.g AZ 07/15 | D205: -8.99 | E205: DEBIT_CARD | F205: 35857.43 | G205: Go Daddy
A206: DEBIT | B206: 45853 | C206: TST*BLUEYS KITCHEN MAR Los Angeles CA 07/14 | D206: -118.92 | E206: DEBIT_CARD | F206: 35866.42 | G206: Personal - Food
A207: DEBIT | B207: 45853 | C207: CITY OF SANTA MONICA SANTA MONICA CA 07/14 | D207: -1.25 | E207: DEBIT_CARD | F207: 35985.34 | G207: Personal - Car
A208: DEBIT | B208: 45853 | C208: DNH*GODADDY#38170993 https://www.g AZ 07/14 | D208: -73.15 | E208: DEBIT_CARD | F208: 35986.59 | G208: Go Daddy
A209: DEBIT | B209: 45853 | C209: LA CABANA - VENICE VENICE CA 07/13 | D209: -228.76 | E209: DEBIT_CARD | F209: 36059.74 | G209: Personal - Food
A210: DEBIT | B210: 45852 | C210: Basic Online Payroll Payment 11180106136 to ######7939 | D210: -10000 | E210: BASIC_PAYROLL | F210: 36288.5 | G210: Ryan Billings - Payroll
A211: DEBIT | B211: 45852 | C211: Basic Online Payroll Payment 11180108817 to ########6812 | D211: -5000 | E211: BASIC_PAYROLL | F211: 46288.5 | G211: Meg Maran - Payroll
A212: DEBIT | B212: 45852 | C212: CHEVRON 0092316 FIREBAUGH CA 07/13 | D212: -35.19 | E212: DEBIT_CARD | F212: 51288.5 | G212: DWG Capital Partners
... A389: DEBIT | B389: 45779 | C389: LAX AIRP CROWNS LAX T4 LOS ANGELES CA 04/30 | D389: -29.38 | E389: DEBIT_CARD | F389: 11801.31 | G389: Personal - Food
