Workbook

Sheet Category Summary
A1: Chase 9335 — 2025 Activity
A2: Category Summary | Jan 2025 – Dec 2025
A4: Entity | B4: Poseidon Asset Group
A5: Account | B5: Personal Checking — Chase 9335
A6: Period | B6: Jan 2025 – Dec 2025
A8: TOTALS
A9: Total Inflows | B9: =SUMIFS('Transaction Overview'!$D$2:$D$790,'Transaction Overview'!$D$2:$D$790,">0") -> 2665832.7
A10: Total Outflows | B10: =SUMIFS('Transaction Overview'!$D$2:$D$790,'Transaction Overview'!$D$2:$D$790,"<0") -> -2704637.9
A11: Net Change | B11: =B9+B10 -> -38805.16
A14: Category | B14: Inflows | C14: Outflows | D14: Net
A15: Deal-Specific
A16: Deal Specific: Austin Iron | B16: =SUMIFS('Transaction Overview'!$D$2:$D$790,'Transaction Overview'!$G$2:$G$790,$A16,'Transaction Overview'!$D$2:$D$790,">0") -> 4200 | C16: =SUMIFS('Transaction Overview'!$D$2:$D$790,'Transaction Overview'!$G$2:$G$790,$A16,'Transaction Overview'!$D$2:$D$790,"<0") -> 0 | D16: =B16+C16 -> 4200
A17: Deal Specific: Cloverdale | B17: =SUMIFS('Transaction Overview'!$D$2:$D$790,'Transaction Overview'!$G$2:$G$790,$A17,'Transaction Overview'!$D$2:$D$790,">0") -> 0 | C17: =SUMIFS('Transaction Overview'!$D$2:$D$790,'Transaction Overview'!$G$2:$G$790,$A17,'Transaction Overview'!$D$2:$D$790,"<0") -> -155000 | D17: =B17+C17 -> -155000
A18: Deal Specific: Hibbert | B18: =SUMIFS('Transaction Overview'!$D$2:$D$790,'Transaction Overview'!$G$2:$G$790,$A18,'Transaction Overview'!$D$2:$D$790,">0") -> 0 | C18: =SUMIFS('Transaction Overview'!$D$2:$D$790,'Transaction Overview'!$G$2:$G$790,$A18,'Transaction Overview'!$D$2:$D$790,"<0") -> -46528.05 | D18: =B18+C18 -> -46528.05
A19: Deal Specific: JAL Breese | B19: =SUMIFS('Transaction Overview'!$D$2:$D$790,'Transaction Overview'!$G$2:$G$790,$A19,'Transaction Overview'!$D$2:$D$790,">0") -> 0 | C19: =SUMIFS('Transaction Overview'!$D$2:$D$790,'Transaction Overview'!$G$2:$G$790,$A19,'Transaction Overview'!$D$2:$D$790,"<0") -> -50000 | D19: =B19+C19 -> -50000
A20: Deal Specific: Merit-Lancaster | B20: =SUMIFS('Transaction Overview'!$D$2:$D$790,'Transaction Overview'!$G$2:$G$790,$A20,'Transaction Overview'!$D$2:$D$790,">0") -> 5687.14 | C20: =SUMIFS('Transaction Overview'!$D$2:$D$790,'Transaction Overview'!$G$2:$G$790,$A20,'Transaction Overview'!$D$2:$D$790,"<0") -> 0 | D20: =B20+C20 -> 5687.14
A21: Deal Specific: Moab | B21: =SUMIFS('Transaction Overview'!$D$2:$D$790,'Transaction Overview'!$G$2:$G$790,$A21,'Transaction Overview'!$D$2:$D$790,">0") -> 626675 | C21: =SUMIFS('Transaction Overview'!$D$2:$D$790,'Transaction Overview'!$G$2:$G$790,$A21,'Transaction Overview'!$D$2:$D$790,"<0") -> -620000 | D21: =B21+C21 -> 6675
A22: Deal Specific: MRM | B22: =SUMIFS('Transaction Overview'!$D$2:$D$790,'Transaction Overview'!$G$2:$G$790,$A22,'Transaction Overview'!$D$2:$D$790,">0") -> 2847.44 | C22: =SUMIFS('Transaction Overview'!$D$2:$D$790,'Transaction Overview'!$G$2:$G$790,$A22,'Transaction Overview'!$D$2:$D$790,"<0") -> 0 | D22: =B22+C22 -> 2847.44
A23: Deal Specific: Rabourn Road | B23: =SUMIFS('Transaction Overview'!$D$2:$D$790,'Transaction Overview'!$G$2:$G$790,$A23,'Transaction Overview'!$D$2:$D$790,">0") -> 1166.65 | C23: =SUMIFS('Transaction Overview'!$D$2:$D$790,'Transaction Overview'!$G$2:$G$790,$A23,'Transaction Overview'!$D$2:$D$790,"<0") -> 0 | D23: =B23+C23 -> 1166.65
A24: Deal Specific: T&T Machine | B24: =SUMIFS('Transaction Overview'!$D$2:$D$790,'Transaction Overview'!$G$2:$G$790,$A24,'Transaction Overview'!$D$2:$D$790,">0") -> 4315.42 | C24: =SUMIFS('Transaction Overview'!$D$2:$D$790,'Transaction Overview'!$G$2:$G$790,$A24,'Transaction Overview'!$D$2:$D$790,"<0") -> 0 | D24: =B24+C24 -> 4315.42
A25: Subtotal — Deal-Specific | B25: =SUMIFS('Transaction Overview'!$D$2:$D$790,'Transaction Overview'!$J$2:$J$790,"Deal-Specific",'Transaction Overview'!$D$2:$D$790,">0") -> 644891.65 | C25: =SUMIFS('Transaction Overview'!$D$2:$D$790,'Transaction Overview'!$J$2:$J$790,"Deal-Specific",'Transaction Overview'!$D$2:$D$790,"<0") -> -871528.05 | D25: =B25+C25 -> -226636.4
A27: Commissions — Incoming
A28: Incoming Commission: Breese | B28: =SUMIFS('Transaction Overview'!$D$2:$D$790,'Transaction Overview'!$G$2:$G$790,$A28,'Transaction Overview'!$D$2:$D$790,">0") -> 269473.73 | C28: =SUMIFS('Transaction Overview'!$D$2:$D$790,'Transaction Overview'!$G$2:$G$790,$A28,'Transaction Overview'!$D$2:$D$790,"<0") -> 0 | D28: =B28+C28 -> 269473.73
A29: Incoming Commission: Butler Weldments | B29: =SUMIFS('Transaction Overview'!$D$2:$D$790,'Transaction Overview'!$G$2:$G$790,$A29,'Transaction Overview'!$D$2:$D$790,">0") -> 164150.5 | C29: =SUMIFS('Transaction Overview'!$D$2:$D$790,'Transaction Overview'!$G$2:$G$790,$A29,'Transaction Overview'!$D$2:$D$790,"<0") -> 0 | D29: =B29+C29 -> 164150.5
A30: Incoming Commission: Edge Builder | B30: =SUMIFS('Transaction Overview'!$D$2:$D$790,'Transaction Overview'!$G$2:$G$790,$A30,'Transaction Overview'!$D$2:$D$790,">0") -> 148250 | C30: =SUMIFS('Transaction Overview'!$D$2:$D$790,'Transaction Overview'!$G$2:$G$790,$A30,'Transaction Overview'!$D$2:$D$790,"<0") -> 0 | D30: =B30+C30 -> 148250
A31: Incoming Commission: Kalkaska Screw | B31: =SUMIFS('Transaction Overview'!$D$2:$D$790,'Transaction Overview'!$G$2:$G$790,$A31,'Transaction Overview'!$D$2:$D$790,">0") -> 133875 | C31: =SUMIFS('Transaction Overview'!$D$2:$D$790,'Transaction Overview'!$G$2:$G$790,$A31,'Transaction Overview'!$D$2:$D$790,"<0") -> 0 | D31: =B31+C31 -> 133875
A32: Incoming Commission: Stryten Energy | B32: =SUMIFS('Transaction Overview'!$D$2:$D$790,'Transaction Overview'!$G$2:$G$790,$A32,'Transaction Overview'!$D$2:$D$790,">0") -> 318189.39 | C32: =SUMIFS('Transaction Overview'!$D$2:$D$790,'Transaction Overview'!$G$2:$G$790,$A32,'Transaction Overview'!$D$2:$D$790,"<0") -> 0 | D32: =B32+C32 -> 318189.39
A33: Subtotal — Commissions — Incoming | B33: =SUMIFS('Transaction Overview'!$D$2:$D$790,'Transaction Overview'!$J$2:$J$790,"Commissions — Incoming",'Transaction Overview'!$D$2:$D$790,">0") -> 1033938.6 | C33: =SUMIFS('Transaction Overview'!$D$2:$D$790,'Transaction Overview'!$J$2:$J$790,"Commissions — Incoming",'Transaction Overview'!$D$2:$D$790,"<0") -> 0 | D33: =B33+C33 -> 1033938.6
A35: Commissions — Outgoing
A36: Wire Out — Edge Builder Commission Payments | B36: =SUMIFS('Transaction Overview'!$D$2:$D$790,'Transaction Overview'!$G$2:$G$790,$A36,'Transaction Overview'!$D$2:$D$790,">0") -> 0 | C36: =SUMIFS('Transaction Overview'!$D$2:$D$790,'Transaction Overview'!$G$2:$G$790,$A36,'Transaction Overview'!$D$2:$D$790,"<0") -> -23830 | D36: =B36+C36 -> -23830
A37: Wire Out — Stryten Commission Payments | B37: =SUMIFS('Transaction Overview'!$D$2:$D$790,'Transaction Overview'!$G$2:$G$790,$A37,'Transaction Overview'!$D$2:$D$790,">0") -> 0 | C37: =SUMIFS('Transaction Overview'!$D$2:$D$790,'Transaction Overview'!$G$2:$G$790,$A37,'Transaction Overview'!$D$2:$D$790,"<0") -> -47820 | D37: =B37+C37 -> -47820
A38: Subtotal — Commissions — Outgoing | B38: =SUMIFS('Transaction Overview'!$D$2:$D$790,'Transaction Overview'!$J$2:$J$790,"Commissions — Outgoing",'Transaction Overview'!$D$2:$D$790,">0") -> 0 | C38: =SUMIFS('Transaction Overview'!$D$2:$D$790,'Transaction Overview'!$J$2:$J$790,"Commissions — Outgoing",'Transaction Overview'!$D$2:$D$790,"<0") -> -71650 | D38: =B38+C38 -> -71650
A40: MAG Pass-Through
A41: Due to Andrew – MAG Pass-Through 30% | B41: =SUMIFS('Transaction Overview'!$D$2:$D$790,'Transaction Overview'!$G$2:$G$790,$A41,'Transaction Overview'!$D$2:$D$790,">0") -> 0 | C41: =SUMIFS('Transaction Overview'!$D$2:$D$790,'Transaction Overview'!$G$2:$G$790,$A41,'Transaction Overview'!$D$2:$D$790,"<0") -> -21000 | D41: =B41+C41 -> -21000
A42: Due to Dax – MAG Pass-Through 70% | B42: =SUMIFS('Transaction Overview'!$D$2:$D$790,'Transaction Overview'!$G$2:$G$790,$A42,'Transaction Overview'!$D$2:$D$790,">0") -> 0 | C42: =SUMIFS('Transaction Overview'!$D$2:$D$790,'Transaction Overview'!$G$2:$G$790,$A42,'Transaction Overview'!$D$2:$D$790,"<0") -> -39000 | D42: =B42+C42 -> -39000
A43: MAG - Admeer Advisory Reimbursement | B43: =SUMIFS('Transaction Overview'!$D$2:$D$790,'Transaction Overview'!$G$2:$G$790,$A43,'Transaction Overview'!$D$2:$D$790,">0") -> 35000 | C43: =SUMIFS('Transaction Overview'!$D$2:$D$790,'Transaction Overview'!$G$2:$G$790,$A43,'Transaction Overview'!$D$2:$D$790,"<0") -> 0 | D43: =B43+C43 -> 35000
A44: MAG - Admeer Advisory Transfer | B44: =SUMIFS('Transaction Overview'!$D$2:$D$790,'Transaction Overview'!$G$2:$G$790,$A44,'Transaction Overview'!$D$2:$D$790,">0") -> 0 | C44: =SUMIFS('Transaction Overview'!$D$2:$D$790,'Transaction Overview'!$G$2:$G$790,$A44,'Transaction Overview'!$D$2:$D$790,"<0") -> -42450 | D44: =B44+C44 -> -42450
A45: MAG Capital Partners Pass-Through Wire – 70/30 Split | B45: =SUMIFS('Transaction Overview'!$D$2:$D$790,'Transaction Overview'!$G$2:$G$790,$A45,'Transaction Overview'!$D$2:$D$790,">0") -> 75000 | C45: =SUMIFS('Transaction Overview'!$D$2:$D$790,'Transaction Overview'!$G$2:$G$790,$A45,'Transaction Overview'!$D$2:$D$790,"<0") -> 0 | D45: =B45+C45 -> 75000
A46: MAG Marketing Reimbursement | B46: =SUMIFS('Transaction Overview'!$D$2:$D$790,'Transaction Overview'!$G$2:$G$790,$A46,'Transaction Overview'!$D$2:$D$790,">0") -> 15000 | C46: =SUMIFS('Transaction Overview'!$D$2:$D$790,'Transaction Overview'!$G$2:$G$790,$A46,'Transaction Overview'!$D$2:$D$790,"<0") -> 0 | D46: =B46+C46 -> 15000
A47: Subtotal — MAG Pass-Through | B47: =SUMIFS('Transaction Overview'!$D$2:$D$790,'Transaction Overview'!$J$2:$J$790,"MAG Pass-Through",'Transaction Overview'!$D$2:$D$790,">0") -> 125000 | C47: =SUMIFS('Transaction Overview'!$D$2:$D$790,'Transaction Overview'!$J$2:$J$790,"MAG Pass-Through",'Transaction Overview'!$D$2:$D$790,"<0") -> -102450 | D47: =B47+C47 -> 22550
...

Sheet Commission
A1: Chase 9335 — 2025 Activity
A2: Commissions Statement | Jan 2025 – Dec 2025
A4: SUMMARY
A5: Commissions Earned (net) | C5: =SUMIFS('Transaction Overview'!$D$2:$D$790,'Transaction Overview'!$J$2:$J$790,"Commissions — Incoming") -> 1033938.6
A6: Commissions Paid Out | C6: =SUMIFS('Transaction Overview'!$D$2:$D$790,'Transaction Overview'!$J$2:$J$790,"Commissions — Outgoing") -> -71650
A7: Net Commission Kept | C7: =C5+C6 -> 962288.62

Sheet Monthly Breakdown
A1: Chase 9335 — 2025 Activity
A2: Monthly Breakdown | Net by Category | Jan 2025 – Dec 2025
A4: Category | B4: =DATE(2025,1,1) -> 45658 | C4: =DATE(2025,2,1) -> 45689 | D4: =DATE(2025,3,1) -> 45717 | E4: =DATE(2025,4,1) -> 45748 | F4: =DATE(2025,5,1) -> 45778 | G4: =DATE(2025,6,1) -> 45809 | H4: =DATE(2025,7,1) -> 45839 | I4: =DATE(2025,8,1) -> 45870 | J4: =DATE(2025,9,1) -> 45901 | K4: =DATE(2025,10,1) -> 45931 | L4: =DATE(2025,11,1) -> 45962 | M4: =DATE(2025,12,1) -> 45992 | N4: Total
A5: Deal-Specific
A6: Deal Specific: Austin Iron | B6: =SUMIFS('Transaction Overview'!$D$2:$D$790,'Transaction Overview'!$I$2:$I$790,$A6,'Transaction Overview'!$H$2:$H$790,B$4) -> 350 | C6: =SUMIFS('Transaction Overview'!$D$2:$D$790,'Transaction Overview'!$I$2:$I$790,$A6,'Transaction Overview'!$H$2:$H$790,C$4) -> 350 | D6: =SUMIFS('Transaction Overview'!$D$2:$D$790,'Transaction Overview'!$I$2:$I$790,$A6,'Transaction Overview'!$H$2:$H$790,D$4) -> 350 | E6: =SUMIFS('Transaction Overview'!$D$2:$D$790,'Transaction Overview'!$I$2:$I$790,$A6,'Transaction Overview'!$H$2:$H$790,E$4) -> 350 | F6: =SUMIFS('Transaction Overview'!$D$2:$D$790,'Transaction Overview'!$I$2:$I$790,$A6,'Transaction Overview'!$H$2:$H$790,F$4) -> 350 | G6: =SUMIFS('Transaction Overview'!$D$2:$D$790,'Transaction Overview'!$I$2:$I$790,$A6,'Transaction Overview'!$H$2:$H$790,G$4) -> 350 | H6: =SUMIFS('Transaction Overview'!$D$2:$D$790,'Transaction Overview'!$I$2:$I$790,$A6,'Transaction Overview'!$H$2:$H$790,H$4) -> 350 | I6: =SUMIFS('Transaction Overview'!$D$2:$D$790,'Transaction Overview'!$I$2:$I$790,$A6,'Transaction Overview'!$H$2:$H$790,I$4) -> 350 | ... M6: =SUMIFS('Transaction Overview'!$D$2:$D$790,'Transaction Overview'!$I$2:$I$790,$A6,'Transaction Overview'!$H$2:$H$790,M$4) -> 350 | N6: =SUM(B6:M6) -> 4200
A7: Deal Specific: Cloverdale | B7: =SUMIFS('Transaction Overview'!$D$2:$D$790,'Transaction Overview'!$I$2:$I$790,$A7,'Transaction Overview'!$H$2:$H$790,B$4) -> 0 | C7: =SUMIFS('Transaction Overview'!$D$2:$D$790,'Transaction Overview'!$I$2:$I$790,$A7,'Transaction Overview'!$H$2:$H$790,C$4) -> 0 | D7: =SUMIFS('Transaction Overview'!$D$2:$D$790,'Transaction Overview'!$I$2:$I$790,$A7,'Transaction Overview'!$H$2:$H$790,D$4) -> 0 | E7: =SUMIFS('Transaction Overview'!$D$2:$D$790,'Transaction Overview'!$I$2:$I$790,$A7,'Transaction Overview'!$H$2:$H$790,E$4) -> 0 | F7: =SUMIFS('Transaction Overview'!$D$2:$D$790,'Transaction Overview'!$I$2:$I$790,$A7,'Transaction Overview'!$H$2:$H$790,F$4) -> 0 | G7: =SUMIFS('Transaction Overview'!$D$2:$D$790,'Transaction Overview'!$I$2:$I$790,$A7,'Transaction Overview'!$H$2:$H$790,G$4) -> 0 | H7: =SUMIFS('Transaction Overview'!$D$2:$D$790,'Transaction Overview'!$I$2:$I$790,$A7,'Transaction Overview'!$H$2:$H$790,H$4) -> 0 | I7: =SUMIFS('Transaction Overview'!$D$2:$D$790,'Transaction Overview'!$I$2:$I$790,$A7,'Transaction Overview'!$H$2:$H$790,I$4) -> 0 | ... M7: =SUMIFS('Transaction Overview'!$D$2:$D$790,'Transaction Overview'!$I$2:$I$790,$A7,'Transaction Overview'!$H$2:$H$790,M$4) -> -155000 | N7: =SUM(B7:M7) -> -155000
A8: Deal Specific: Hibbert | B8: =SUMIFS('Transaction Overview'!$D$2:$D$790,'Transaction Overview'!$I$2:$I$790,$A8,'Transaction Overview'!$H$2:$H$790,B$4) -> 0 | C8: =SUMIFS('Transaction Overview'!$D$2:$D$790,'Transaction Overview'!$I$2:$I$790,$A8,'Transaction Overview'!$H$2:$H$790,C$4) -> 0 | D8: =SUMIFS('Transaction Overview'!$D$2:$D$790,'Transaction Overview'!$I$2:$I$790,$A8,'Transaction Overview'!$H$2:$H$790,D$4) -> 0 | E8: =SUMIFS('Transaction Overview'!$D$2:$D$790,'Transaction Overview'!$I$2:$I$790,$A8,'Transaction Overview'!$H$2:$H$790,E$4) -> 0 | F8: =SUMIFS('Transaction Overview'!$D$2:$D$790,'Transaction Overview'!$I$2:$I$790,$A8,'Transaction Overview'!$H$2:$H$790,F$4) -> 0 | G8: =SUMIFS('Transaction Overview'!$D$2:$D$790,'Transaction Overview'!$I$2:$I$790,$A8,'Transaction Overview'!$H$2:$H$790,G$4) -> 0 | H8: =SUMIFS('Transaction Overview'!$D$2:$D$790,'Transaction Overview'!$I$2:$I$790,$A8,'Transaction Overview'!$H$2:$H$790,H$4) -> 0 | I8: =SUMIFS('Transaction Overview'!$D$2:$D$790,'Transaction Overview'!$I$2:$I$790,$A8,'Transaction Overview'!$H$2:$H$790,I$4) -> 0 | ... M8: =SUMIFS('Transaction Overview'!$D$2:$D$790,'Transaction Overview'!$I$2:$I$790,$A8,'Transaction Overview'!$H$2:$H$790,M$4) -> 0 | N8: =SUM(B8:M8) -> -46528.05
A9: Deal Specific: JAL Breese | B9: =SUMIFS('Transaction Overview'!$D$2:$D$790,'Transaction Overview'!$I$2:$I$790,$A9,'Transaction Overview'!$H$2:$H$790,B$4) -> 0 | C9: =SUMIFS('Transaction Overview'!$D$2:$D$790,'Transaction Overview'!$I$2:$I$790,$A9,'Transaction Overview'!$H$2:$H$790,C$4) -> 0 | D9: =SUMIFS('Transaction Overview'!$D$2:$D$790,'Transaction Overview'!$I$2:$I$790,$A9,'Transaction Overview'!$H$2:$H$790,D$4) -> 0 | E9: =SUMIFS('Transaction Overview'!$D$2:$D$790,'Transaction Overview'!$I$2:$I$790,$A9,'Transaction Overview'!$H$2:$H$790,E$4) -> -50000 | F9: =SUMIFS('Transaction Overview'!$D$2:$D$790,'Transaction Overview'!$I$2:$I$790,$A9,'Transaction Overview'!$H$2:$H$790,F$4) -> 0 | G9: =SUMIFS('Transaction Overview'!$D$2:$D$790,'Transaction Overview'!$I$2:$I$790,$A9,'Transaction Overview'!$H$2:$H$790,G$4) -> 0 | H9: =SUMIFS('Transaction Overview'!$D$2:$D$790,'Transaction Overview'!$I$2:$I$790,$A9,'Transaction Overview'!$H$2:$H$790,H$4) -> 0 | I9: =SUMIFS('Transaction Overview'!$D$2:$D$790,'Transaction Overview'!$I$2:$I$790,$A9,'Transaction Overview'!$H$2:$H$790,I$4) -> 0 | ... M9: =SUMIFS('Transaction Overview'!$D$2:$D$790,'Transaction Overview'!$I$2:$I$790,$A9,'Transaction Overview'!$H$2:$H$790,M$4) -> 0 | N9: =SUM(B9:M9) -> -50000
A10: Deal Specific: Merit-Lancaster | B10: =SUMIFS('Transaction Overview'!$D$2:$D$790,'Transaction Overview'!$I$2:$I$790,$A10,'Transaction Overview'!$H$2:$H$790,B$4) -> 461.52 | C10: =SUMIFS('Transaction Overview'!$D$2:$D$790,'Transaction Overview'!$I$2:$I$790,$A10,'Transaction Overview'!$H$2:$H$790,C$4) -> 461.52 | D10: =SUMIFS('Transaction Overview'!$D$2:$D$790,'Transaction Overview'!$I$2:$I$790,$A10,'Transaction Overview'!$H$2:$H$790,D$4) -> 476.41 | E10: =SUMIFS('Transaction Overview'!$D$2:$D$790,'Transaction Overview'!$I$2:$I$790,$A10,'Transaction Overview'!$H$2:$H$790,E$4) -> 476.41 | F10: =SUMIFS('Transaction Overview'!$D$2:$D$790,'Transaction Overview'!$I$2:$I$790,$A10,'Transaction Overview'!$H$2:$H$790,F$4) -> 476.41 | G10: =SUMIFS('Transaction Overview'!$D$2:$D$790,'Transaction Overview'!$I$2:$I$790,$A10,'Transaction Overview'!$H$2:$H$790,G$4) -> 476.41 | H10: =SUMIFS('Transaction Overview'!$D$2:$D$790,'Transaction Overview'!$I$2:$I$790,$A10,'Transaction Overview'!$H$2:$H$790,H$4) -> 476.41 | I10: =SUMIFS('Transaction Overview'!$D$2:$D$790,'Transaction Overview'!$I$2:$I$790,$A10,'Transaction Overview'!$H$2:$H$790,I$4) -> 476.41 | ... M10: =SUMIFS('Transaction Overview'!$D$2:$D$790,'Transaction Overview'!$I$2:$I$790,$A10,'Transaction Overview'!$H$2:$H$790,M$4) -> 476.41 | N10: =SUM(B10:M10) -> 5687.14
A11: Deal Specific: Moab | B11: =SUMIFS('Transaction Overview'!$D$2:$D$790,'Transaction Overview'!$I$2:$I$790,$A11,'Transaction Overview'!$H$2:$H$790,B$4) -> 0 | C11: =SUMIFS('Transaction Overview'!$D$2:$D$790,'Transaction Overview'!$I$2:$I$790,$A11,'Transaction Overview'!$H$2:$H$790,C$4) -> 0 | D11: =SUMIFS('Transaction Overview'!$D$2:$D$790,'Transaction Overview'!$I$2:$I$790,$A11,'Transaction Overview'!$H$2:$H$790,D$4) -> 0 | E11: =SUMIFS('Transaction Overview'!$D$2:$D$790,'Transaction Overview'!$I$2:$I$790,$A11,'Transaction Overview'!$H$2:$H$790,E$4) -> 0 | F11: =SUMIFS('Transaction Overview'!$D$2:$D$790,'Transaction Overview'!$I$2:$I$790,$A11,'Transaction Overview'!$H$2:$H$790,F$4) -> 0 | G11: =SUMIFS('Transaction Overview'!$D$2:$D$790,'Transaction Overview'!$I$2:$I$790,$A11,'Transaction Overview'!$H$2:$H$790,G$4) -> 0 | H11: =SUMIFS('Transaction Overview'!$D$2:$D$790,'Transaction Overview'!$I$2:$I$790,$A11,'Transaction Overview'!$H$2:$H$790,H$4) -> 0 | I11: =SUMIFS('Transaction Overview'!$D$2:$D$790,'Transaction Overview'!$I$2:$I$790,$A11,'Transaction Overview'!$H$2:$H$790,I$4) -> 0 | ... M11: =SUMIFS('Transaction Overview'!$D$2:$D$790,'Transaction Overview'!$I$2:$I$790,$A11,'Transaction Overview'!$H$2:$H$790,M$4) -> 5000 | N11: =SUM(B11:M11) -> 6675
A12: Deal Specific: MRM | B12: =SUMIFS('Transaction Overview'!$D$2:$D$790,'Transaction Overview'!$I$2:$I$790,$A12,'Transaction Overview'!$H$2:$H$790,B$4) -> 236.37 | C12: =SUMIFS('Transaction Overview'!$D$2:$D$790,'Transaction Overview'!$I$2:$I$790,$A12,'Transaction Overview'!$H$2:$H$790,C$4) -> 236.37 | D12: =SUMIFS('Transaction Overview'!$D$2:$D$790,'Transaction Overview'!$I$2:$I$790,$A12,'Transaction Overview'!$H$2:$H$790,D$4) -> 236.37 | E12: =SUMIFS('Transaction Overview'!$D$2:$D$790,'Transaction Overview'!$I$2:$I$790,$A12,'Transaction Overview'!$H$2:$H$790,E$4) -> 236.37 | F12: =SUMIFS('Transaction Overview'!$D$2:$D$790,'Transaction Overview'!$I$2:$I$790,$A12,'Transaction Overview'!$H$2:$H$790,F$4) -> 236.37 | G12: =SUMIFS('Transaction Overview'!$D$2:$D$790,'Transaction Overview'!$I$2:$I$790,$A12,'Transaction Overview'!$H$2:$H$790,G$4) -> 236.37 | H12: =SUMIFS('Transaction Overview'!$D$2:$D$790,'Transaction Overview'!$I$2:$I$790,$A12,'Transaction Overview'!$H$2:$H$790,H$4) -> 236.37 | I12: =SUMIFS('Transaction Overview'!$D$2:$D$790,'Transaction Overview'!$I$2:$I$790,$A12,'Transaction Overview'!$H$2:$H$790,I$4) -> 236.37 | ... M12: =SUMIFS('Transaction Overview'!$D$2:$D$790,'Transaction Overview'!$I$2:$I$790,$A12,'Transaction Overview'!$H$2:$H$790,M$4) -> 241.87 | N12: =SUM(B12:M12) -> 2847.44
A13: Deal Specific: Rabourn Road | B13: =SUMIFS('Transaction Overview'!$D$2:$D$790,'Transaction Overview'!$I$2:$I$790,$A13,'Transaction Overview'!$H$2:$H$790,B$4) -> 0 | C13: =SUMIFS('Transaction Overview'!$D$2:$D$790,'Transaction Overview'!$I$2:$I$790,$A13,'Transaction Overview'!$H$2:$H$790,C$4) -> 0 | D13: =SUMIFS('Transaction Overview'!$D$2:$D$790,'Transaction Overview'!$I$2:$I$790,$A13,'Transaction Overview'!$H$2:$H$790,D$4) -> 0 | E13: =SUMIFS('Transaction Overview'!$D$2:$D$790,'Transaction Overview'!$I$2:$I$790,$A13,'Transaction Overview'!$H$2:$H$790,E$4) -> 0 | F13: =SUMIFS('Transaction Overview'!$D$2:$D$790,'Transaction Overview'!$I$2:$I$790,$A13,'Transaction Overview'!$H$2:$H$790,F$4) -> 0 | G13: =SUMIFS('Transaction Overview'!$D$2:$D$790,'Transaction Overview'!$I$2:$I$790,$A13,'Transaction Overview'!$H$2:$H$790,G$4) -> 0 | H13: =SUMIFS('Transaction Overview'!$D$2:$D$790,'Transaction Overview'!$I$2:$I$790,$A13,'Transaction Overview'!$H$2:$H$790,H$4) -> 0 | I13: =SUMIFS('Transaction Overview'!$D$2:$D$790,'Transaction Overview'!$I$2:$I$790,$A13,'Transaction Overview'!$H$2:$H$790,I$4) -> 233.33 | ... M13: =SUMIFS('Transaction Overview'!$D$2:$D$790,'Transaction Overview'!$I$2:$I$790,$A13,'Transaction Overview'!$H$2:$H$790,M$4) -> 233.33 | N13: =SUM(B13:M13) -> 1166.65
A14: Deal Specific: T&T Machine | B14: =SUMIFS('Transaction Overview'!$D$2:$D$790,'Transaction Overview'!$I$2:$I$790,$A14,'Transaction Overview'!$H$2:$H$790,B$4) -> 345.24 | C14: =SUMIFS('Transaction Overview'!$D$2:$D$790,'Transaction Overview'!$I$2:$I$790,$A14,'Transaction Overview'!$H$2:$H$790,C$4) -> 356.38 | D14: =SUMIFS('Transaction Overview'!$D$2:$D$790,'Transaction Overview'!$I$2:$I$790,$A14,'Transaction Overview'!$H$2:$H$790,D$4) -> 356.38 | E14: =SUMIFS('Transaction Overview'!$D$2:$D$790,'Transaction Overview'!$I$2:$I$790,$A14,'Transaction Overview'!$H$2:$H$790,E$4) -> 356.38 | F14: =SUMIFS('Transaction Overview'!$D$2:$D$790,'Transaction Overview'!$I$2:$I$790,$A14,'Transaction Overview'!$H$2:$H$790,F$4) -> 356.38 | G14: =SUMIFS('Transaction Overview'!$D$2:$D$790,'Transaction Overview'!$I$2:$I$790,$A14,'Transaction Overview'!$H$2:$H$790,G$4) -> 356.38 | H14: =SUMIFS('Transaction Overview'!$D$2:$D$790,'Transaction Overview'!$I$2:$I$790,$A14,'Transaction Overview'!$H$2:$H$790,H$4) -> 356.38 | I14: =SUMIFS('Transaction Overview'!$D$2:$D$790,'Transaction Overview'!$I$2:$I$790,$A14,'Transaction Overview'!$H$2:$H$790,I$4) -> 356.38 | ... M14: =SUMIFS('Transaction Overview'!$D$2:$D$790,'Transaction Overview'!$I$2:$I$790,$A14,'Transaction Overview'!$H$2:$H$790,M$4) -> 356.38 | N14: =SUM(B14:M14) -> 4315.42
A15: Subtotal — Deal-Specific | B15: =SUMIFS('Transaction Overview'!$D$2:$D$790,'Transaction Overview'!$J$2:$J$790,"Deal-Specific",'Transaction Overview'!$H$2:$H$790,B$4) -> 1393.13 | C15: =SUMIFS('Transaction Overview'!$D$2:$D$790,'Transaction Overview'!$J$2:$J$790,"Deal-Specific",'Transaction Overview'!$H$2:$H$790,C$4) -> 1404.27 | D15: =SUMIFS('Transaction Overview'!$D$2:$D$790,'Transaction Overview'!$J$2:$J$790,"Deal-Specific",'Transaction Overview'!$H$2:$H$790,D$4) -> 1419.16 | E15: =SUMIFS('Transaction Overview'!$D$2:$D$790,'Transaction Overview'!$J$2:$J$790,"Deal-Specific",'Transaction Overview'!$H$2:$H$790,E$4) -> -48580.84 | F15: =SUMIFS('Transaction Overview'!$D$2:$D$790,'Transaction Overview'!$J$2:$J$790,"Deal-Specific",'Transaction Overview'!$H$2:$H$790,F$4) -> 1419.16 | G15: =SUMIFS('Transaction Overview'!$D$2:$D$790,'Transaction Overview'!$J$2:$J$790,"Deal-Specific",'Transaction Overview'!$H$2:$H$790,G$4) -> 1419.16 | H15: =SUMIFS('Transaction Overview'!$D$2:$D$790,'Transaction Overview'!$J$2:$J$790,"Deal-Specific",'Transaction Overview'!$H$2:$H$790,H$4) -> 1419.16 | I15: =SUMIFS('Transaction Overview'!$D$2:$D$790,'Transaction Overview'!$J$2:$J$790,"Deal-Specific",'Transaction Overview'!$H$2:$H$790,I$4) -> 1652.49 | ... M15: =SUMIFS('Transaction Overview'!$D$2:$D$790,'Transaction Overview'!$J$2:$J$790,"Deal-Specific",'Transaction Overview'!$H$2:$H$790,M$4) -> -148342.01 | N15: =SUM(B15:M15) -> -226636.4
A17: Commissions — Incoming
A18: Incoming Commission: Breese | B18: =SUMIFS('Transaction Overview'!$D$2:$D$790,'Transaction Overview'!$I$2:$I$790,$A18,'Transaction Overview'!$H$2:$H$790,B$4) -> 0 | C18: =SUMIFS('Transaction Overview'!$D$2:$D$790,'Transaction Overview'!$I$2:$I$790,$A18,'Transaction Overview'!$H$2:$H$790,C$4) -> 0 | D18: =SUMIFS('Transaction Overview'!$D$2:$D$790,'Transaction Overview'!$I$2:$I$790,$A18,'Transaction Overview'!$H$2:$H$790,D$4) -> 0 | E18: =SUMIFS('Transaction Overview'!$D$2:$D$790,'Transaction Overview'!$I$2:$I$790,$A18,'Transaction Overview'!$H$2:$H$790,E$4) -> 0 | F18: =SUMIFS('Transaction Overview'!$D$2:$D$790,'Transaction Overview'!$I$2:$I$790,$A18,'Transaction Overview'!$H$2:$H$790,F$4) -> 0 | G18: =SUMIFS('Transaction Overview'!$D$2:$D$790,'Transaction Overview'!$I$2:$I$790,$A18,'Transaction Overview'!$H$2:$H$790,G$4) -> 0 | H18: =SUMIFS('Transaction Overview'!$D$2:$D$790,'Transaction Overview'!$I$2:$I$790,$A18,'Transaction Overview'!$H$2:$H$790,H$4) -> 269473.73 | I18: =SUMIFS('Transaction Overview'!$D$2:$D$790,'Transaction Overview'!$I$2:$I$790,$A18,'Transaction Overview'!$H$2:$H$790,I$4) -> 0 | ... M18: =SUMIFS('Transaction Overview'!$D$2:$D$790,'Transaction Overview'!$I$2:$I$790,$A18,'Transaction Overview'!$H$2:$H$790,M$4) -> 0 | N18: =SUM(B18:M18) -> 269473.73
A19: Incoming Commission: Butler Weldments | B19: =SUMIFS('Transaction Overview'!$D$2:$D$790,'Transaction Overview'!$I$2:$I$790,$A19,'Transaction Overview'!$H$2:$H$790,B$4) -> 0 | C19: =SUMIFS('Transaction Overview'!$D$2:$D$790,'Transaction Overview'!$I$2:$I$790,$A19,'Transaction Overview'!$H$2:$H$790,C$4) -> 0 | D19: =SUMIFS('Transaction Overview'!$D$2:$D$790,'Transaction Overview'!$I$2:$I$790,$A19,'Transaction Overview'!$H$2:$H$790,D$4) -> 164150.5 | E19: =SUMIFS('Transaction Overview'!$D$2:$D$790,'Transaction Overview'!$I$2:$I$790,$A19,'Transaction Overview'!$H$2:$H$790,E$4) -> 0 | F19: =SUMIFS('Transaction Overview'!$D$2:$D$790,'Transaction Overview'!$I$2:$I$790,$A19,'Transaction Overview'!$H$2:$H$790,F$4) -> 0 | G19: =SUMIFS('Transaction Overview'!$D$2:$D$790,'Transaction Overview'!$I$2:$I$790,$A19,'Transaction Overview'!$H$2:$H$790,G$4) -> 0 | H19: =SUMIFS('Transaction Overview'!$D$2:$D$790,'Transaction Overview'!$I$2:$I$790,$A19,'Transaction Overview'!$H$2:$H$790,H$4) -> 0 | I19: =SUMIFS('Transaction Overview'!$D$2:$D$790,'Transaction Overview'!$I$2:$I$790,$A19,'Transaction Overview'!$H$2:$H$790,I$4) -> 0 | ... M19: =SUMIFS('Transaction Overview'!$D$2:$D$790,'Transaction Overview'!$I$2:$I$790,$A19,'Transaction Overview'!$H$2:$H$790,M$4) -> 0 | N19: =SUM(B19:M19) -> 164150.5
A20: Incoming Commission: Edge Builder | B20: =SUMIFS('Transaction Overview'!$D$2:$D$790,'Transaction Overview'!$I$2:$I$790,$A20,'Transaction Overview'!$H$2:$H$790,B$4) -> 148250 | C20: =SUMIFS('Transaction Overview'!$D$2:$D$790,'Transaction Overview'!$I$2:$I$790,$A20,'Transaction Overview'!$H$2:$H$790,C$4) -> 0 | D20: =SUMIFS('Transaction Overview'!$D$2:$D$790,'Transaction Overview'!$I$2:$I$790,$A20,'Transaction Overview'!$H$2:$H$790,D$4) -> 0 | E20: =SUMIFS('Transaction Overview'!$D$2:$D$790,'Transaction Overview'!$I$2:$I$790,$A20,'Transaction Overview'!$H$2:$H$790,E$4) -> 0 | F20: =SUMIFS('Transaction Overview'!$D$2:$D$790,'Transaction Overview'!$I$2:$I$790,$A20,'Transaction Overview'!$H$2:$H$790,F$4) -> 0 | G20: =SUMIFS('Transaction Overview'!$D$2:$D$790,'Transaction Overview'!$I$2:$I$790,$A20,'Transaction Overview'!$H$2:$H$790,G$4) -> 0 | H20: =SUMIFS('Transaction Overview'!$D$2:$D$790,'Transaction Overview'!$I$2:$I$790,$A20,'Transaction Overview'!$H$2:$H$790,H$4) -> 0 | I20: =SUMIFS('Transaction Overview'!$D$2:$D$790,'Transaction Overview'!$I$2:$I$790,$A20,'Transaction Overview'!$H$2:$H$790,I$4) -> 0 | ... M20: =SUMIFS('Transaction Overview'!$D$2:$D$790,'Transaction Overview'!$I$2:$I$790,$A20,'Transaction Overview'!$H$2:$H$790,M$4) -> 0 | N20: =SUM(B20:M20) -> 148250
A21: Incoming Commission: Kalkaska Screw | B21: =SUMIFS('Transaction Overview'!$D$2:$D$790,'Transaction Overview'!$I$2:$I$790,$A21,'Transaction Overview'!$H$2:$H$790,B$4) -> 0 | C21: =SUMIFS('Transaction Overview'!$D$2:$D$790,'Transaction Overview'!$I$2:$I$790,$A21,'Transaction Overview'!$H$2:$H$790,C$4) -> 0 | D21: =SUMIFS('Transaction Overview'!$D$2:$D$790,'Transaction Overview'!$I$2:$I$790,$A21,'Transaction Overview'!$H$2:$H$790,D$4) -> 0 | E21: =SUMIFS('Transaction Overview'!$D$2:$D$790,'Transaction Overview'!$I$2:$I$790,$A21,'Transaction Overview'!$H$2:$H$790,E$4) -> 133875 | F21: =SUMIFS('Transaction Overview'!$D$2:$D$790,'Transaction Overview'!$I$2:$I$790,$A21,'Transaction Overview'!$H$2:$H$790,F$4) -> 0 | G21: =SUMIFS('Transaction Overview'!$D$2:$D$790,'Transaction Overview'!$I$2:$I$790,$A21,'Transaction Overview'!$H$2:$H$790,G$4) -> 0 | H21: =SUMIFS('Transaction Overview'!$D$2:$D$790,'Transaction Overview'!$I$2:$I$790,$A21,'Transaction Overview'!$H$2:$H$790,H$4) -> 0 | I21: =SUMIFS('Transaction Overview'!$D$2:$D$790,'Transaction Overview'!$I$2:$I$790,$A21,'Transaction Overview'!$H$2:$H$790,I$4) -> 0 | ... M21: =SUMIFS('Transaction Overview'!$D$2:$D$790,'Transaction Overview'!$I$2:$I$790,$A21,'Transaction Overview'!$H$2:$H$790,M$4) -> 0 | N21: =SUM(B21:M21) -> 133875
A22: Incoming Commission: Stryten Energy | B22: =SUMIFS('Transaction Overview'!$D$2:$D$790,'Transaction Overview'!$I$2:$I$790,$A22,'Transaction Overview'!$H$2:$H$790,B$4) -> 0 | C22: =SUMIFS('Transaction Overview'!$D$2:$D$790,'Transaction Overview'!$I$2:$I$790,$A22,'Transaction Overview'!$H$2:$H$790,C$4) -> 0 | D22: =SUMIFS('Transaction Overview'!$D$2:$D$790,'Transaction Overview'!$I$2:$I$790,$A22,'Transaction Overview'!$H$2:$H$790,D$4) -> 0 | E22: =SUMIFS('Transaction Overview'!$D$2:$D$790,'Transaction Overview'!$I$2:$I$790,$A22,'Transaction Overview'!$H$2:$H$790,E$4) -> 0 | F22: =SUMIFS('Transaction Overview'!$D$2:$D$790,'Transaction Overview'!$I$2:$I$790,$A22,'Transaction Overview'!$H$2:$H$790,F$4) -> 0 | G22: =SUMIFS('Transaction Overview'!$D$2:$D$790,'Transaction Overview'!$I$2:$I$790,$A22,'Transaction Overview'!$H$2:$H$790,G$4) -> 0 | H22: =SUMIFS('Transaction Overview'!$D$2:$D$790,'Transaction Overview'!$I$2:$I$790,$A22,'Transaction Overview'!$H$2:$H$790,H$4) -> 0 | I22: =SUMIFS('Transaction Overview'!$D$2:$D$790,'Transaction Overview'!$I$2:$I$790,$A22,'Transaction Overview'!$H$2:$H$790,I$4) -> 0 | ... M22: =SUMIFS('Transaction Overview'!$D$2:$D$790,'Transaction Overview'!$I$2:$I$790,$A22,'Transaction Overview'!$H$2:$H$790,M$4) -> 318189.39 | N22: =SUM(B22:M22) -> 318189.39
A23: Subtotal — Commissions — Incoming | B23: =SUMIFS('Transaction Overview'!$D$2:$D$790,'Transaction Overview'!$J$2:$J$790,"Commissions — Incoming",'Transaction Overview'!$H$2:$H$790,B$4) -> 148250 | C23: =SUMIFS('Transaction Overview'!$D$2:$D$790,'Transaction Overview'!$J$2:$J$790,"Commissions — Incoming",'Transaction Overview'!$H$2:$H$790,C$4) -> 0 | D23: =SUMIFS('Transaction Overview'!$D$2:$D$790,'Transaction Overview'!$J$2:$J$790,"Commissions — Incoming",'Transaction Overview'!$H$2:$H$790,D$4) -> 164150.5 | E23: =SUMIFS('Transaction Overview'!$D$2:$D$790,'Transaction Overview'!$J$2:$J$790,"Commissions — Incoming",'Transaction Overview'!$H$2:$H$790,E$4) -> 133875 | F23: =SUMIFS('Transaction Overview'!$D$2:$D$790,'Transaction Overview'!$J$2:$J$790,"Commissions — Incoming",'Transaction Overview'!$H$2:$H$790,F$4) -> 0 | G23: =SUMIFS('Transaction Overview'!$D$2:$D$790,'Transaction Overview'!$J$2:$J$790,"Commissions — Incoming",'Transaction Overview'!$H$2:$H$790,G$4) -> 0 | H23: =SUMIFS('Transaction Overview'!$D$2:$D$790,'Transaction Overview'!$J$2:$J$790,"Commissions — Incoming",'Transaction Overview'!$H$2:$H$790,H$4) -> 269473.73 | I23: =SUMIFS('Transaction Overview'!$D$2:$D$790,'Transaction Overview'!$J$2:$J$790,"Commissions — Incoming",'Transaction Overview'!$H$2:$H$790,I$4) -> 0 | ... M23: =SUMIFS('Transaction Overview'!$D$2:$D$790,'Transaction Overview'!$J$2:$J$790,"Commissions — Incoming",'Transaction Overview'!$H$2:$H$790,M$4) -> 318189.39 | N23: =SUM(B23:M23) -> 1033938.6
A25: Commissions — Outgoing
A26: Wire Out — Edge Builder Commission Payments | B26: =SUMIFS('Transaction Overview'!$D$2:$D$790,'Transaction Overview'!$I$2:$I$790,$A26,'Transaction Overview'!$H$2:$H$790,B$4) -> -23830 | C26: =SUMIFS('Transaction Overview'!$D$2:$D$790,'Transaction Overview'!$I$2:$I$790,$A26,'Transaction Overview'!$H$2:$H$790,C$4) -> 0 | D26: =SUMIFS('Transaction Overview'!$D$2:$D$790,'Transaction Overview'!$I$2:$I$790,$A26,'Transaction Overview'!$H$2:$H$790,D$4) -> 0 | E26: =SUMIFS('Transaction Overview'!$D$2:$D$790,'Transaction Overview'!$I$2:$I$790,$A26,'Transaction Overview'!$H$2:$H$790,E$4) -> 0 | F26: =SUMIFS('Transaction Overview'!$D$2:$D$790,'Transaction Overview'!$I$2:$I$790,$A26,'Transaction Overview'!$H$2:$H$790,F$4) -> 0 | G26: =SUMIFS('Transaction Overview'!$D$2:$D$790,'Transaction Overview'!$I$2:$I$790,$A26,'Transaction Overview'!$H$2:$H$790,G$4) -> 0 | H26: =SUMIFS('Transaction Overview'!$D$2:$D$790,'Transaction Overview'!$I$2:$I$790,$A26,'Transaction Overview'!$H$2:$H$790,H$4) -> 0 | I26: =SUMIFS('Transaction Overview'!$D$2:$D$790,'Transaction Overview'!$I$2:$I$790,$A26,'Transaction Overview'!$H$2:$H$790,I$4) -> 0 | ... M26: =SUMIFS('Transaction Overview'!$D$2:$D$790,'Transaction Overview'!$I$2:$I$790,$A26,'Transaction Overview'!$H$2:$H$790,M$4) -> 0 | N26: =SUM(B26:M26) -> -23830
A27: Wire Out — Stryten Commission Payments | B27: =SUMIFS('Transaction Overview'!$D$2:$D$790,'Transaction Overview'!$I$2:$I$790,$A27,'Transaction Overview'!$H$2:$H$790,B$4) -> 0 | C27: =SUMIFS('Transaction Overview'!$D$2:$D$790,'Transaction Overview'!$I$2:$I$790,$A27,'Transaction Overview'!$H$2:$H$790,C$4) -> 0 | D27: =SUMIFS('Transaction Overview'!$D$2:$D$790,'Transaction Overview'!$I$2:$I$790,$A27,'Transaction Overview'!$H$2:$H$790,D$4) -> 0 | E27: =SUMIFS('Transaction Overview'!$D$2:$D$790,'Transaction Overview'!$I$2:$I$790,$A27,'Transaction Overview'!$H$2:$H$790,E$4) -> 0 | F27: =SUMIFS('Transaction Overview'!$D$2:$D$790,'Transaction Overview'!$I$2:$I$790,$A27,'Transaction Overview'!$H$2:$H$790,F$4) -> 0 | G27: =SUMIFS('Transaction Overview'!$D$2:$D$790,'Transaction Overview'!$I$2:$I$790,$A27,'Transaction Overview'!$H$2:$H$790,G$4) -> 0 | H27: =SUMIFS('Transaction Overview'!$D$2:$D$790,'Transaction Overview'!$I$2:$I$790,$A27,'Transaction Overview'!$H$2:$H$790,H$4) -> 0 | I27: =SUMIFS('Transaction Overview'!$D$2:$D$790,'Transaction Overview'!$I$2:$I$790,$A27,'Transaction Overview'!$H$2:$H$790,I$4) -> 0 | ... M27: =SUMIFS('Transaction Overview'!$D$2:$D$790,'Transaction Overview'!$I$2:$I$790,$A27,'Transaction Overview'!$H$2:$H$790,M$4) -> -47820 | N27: =SUM(B27:M27) -> -47820
A28: Subtotal — Commissions — Outgoing | B28: =SUMIFS('Transaction Overview'!$D$2:$D$790,'Transaction Overview'!$J$2:$J$790,"Commissions — Outgoing",'Transaction Overview'!$H$2:$H$790,B$4) -> -23830 | C28: =SUMIFS('Transaction Overview'!$D$2:$D$790,'Transaction Overview'!$J$2:$J$790,"Commissions — Outgoing",'Transaction Overview'!$H$2:$H$790,C$4) -> 0 | D28: =SUMIFS('Transaction Overview'!$D$2:$D$790,'Transaction Overview'!$J$2:$J$790,"Commissions — Outgoing",'Transaction Overview'!$H$2:$H$790,D$4) -> 0 | E28: =SUMIFS('Transaction Overview'!$D$2:$D$790,'Transaction Overview'!$J$2:$J$790,"Commissions — Outgoing",'Transaction Overview'!$H$2:$H$790,E$4) -> 0 | F28: =SUMIFS('Transaction Overview'!$D$2:$D$790,'Transaction Overview'!$J$2:$J$790,"Commissions — Outgoing",'Transaction Overview'!$H$2:$H$790,F$4) -> 0 | G28: =SUMIFS('Transaction Overview'!$D$2:$D$790,'Transaction Overview'!$J$2:$J$790,"Commissions — Outgoing",'Transaction Overview'!$H$2:$H$790,G$4) -> 0 | H28: =SUMIFS('Transaction Overview'!$D$2:$D$790,'Transaction Overview'!$J$2:$J$790,"Commissions — Outgoing",'Transaction Overview'!$H$2:$H$790,H$4) -> 0 | I28: =SUMIFS('Transaction Overview'!$D$2:$D$790,'Transaction Overview'!$J$2:$J$790,"Commissions — Outgoing",'Transaction Overview'!$H$2:$H$790,I$4) -> 0 | ... M28: =SUMIFS('Transaction Overview'!$D$2:$D$790,'Transaction Overview'!$J$2:$J$790,"Commissions — Outgoing",'Transaction Overview'!$H$2:$H$790,M$4) -> -47820 | N28: =SUM(B28:M28) -> -71650
A30: MAG Pass-Through
A31: Due to Andrew – MAG Pass-Through 30% | B31: =SUMIFS('Transaction Overview'!$D$2:$D$790,'Transaction Overview'!$I$2:$I$790,$A31,'Transaction Overview'!$H$2:$H$790,B$4) -> 0 | C31: =SUMIFS('Transaction Overview'!$D$2:$D$790,'Transaction Overview'!$I$2:$I$790,$A31,'Transaction Overview'!$H$2:$H$790,C$4) -> 0 | D31: =SUMIFS('Transaction Overview'!$D$2:$D$790,'Transaction Overview'!$I$2:$I$790,$A31,'Transaction Overview'!$H$2:$H$790,D$4) -> 0 | E31: =SUMIFS('Transaction Overview'!$D$2:$D$790,'Transaction Overview'!$I$2:$I$790,$A31,'Transaction Overview'!$H$2:$H$790,E$4) -> 0 | F31: =SUMIFS('Transaction Overview'!$D$2:$D$790,'Transaction Overview'!$I$2:$I$790,$A31,'Transaction Overview'!$H$2:$H$790,F$4) -> 0 | G31: =SUMIFS('Transaction Overview'!$D$2:$D$790,'Transaction Overview'!$I$2:$I$790,$A31,'Transaction Overview'!$H$2:$H$790,G$4) -> 0 | H31: =SUMIFS('Transaction Overview'!$D$2:$D$790,'Transaction Overview'!$I$2:$I$790,$A31,'Transaction Overview'!$H$2:$H$790,H$4) -> 0 | I31: =SUMIFS('Transaction Overview'!$D$2:$D$790,'Transaction Overview'!$I$2:$I$790,$A31,'Transaction Overview'!$H$2:$H$790,I$4) -> 0 | ... M31: =SUMIFS('Transaction Overview'!$D$2:$D$790,'Transaction Overview'!$I$2:$I$790,$A31,'Transaction Overview'!$H$2:$H$790,M$4) -> -21000 | N31: =SUM(B31:M31) -> -21000
A32: Due to Dax – MAG Pass-Through 70% | B32: =SUMIFS('Transaction Overview'!$D$2:$D$790,'Transaction Overview'!$I$2:$I$790,$A32,'Transaction Overview'!$H$2:$H$790,B$4) -> 0 | C32: =SUMIFS('Transaction Overview'!$D$2:$D$790,'Transaction Overview'!$I$2:$I$790,$A32,'Transaction Overview'!$H$2:$H$790,C$4) -> 0 | D32: =SUMIFS('Transaction Overview'!$D$2:$D$790,'Transaction Overview'!$I$2:$I$790,$A32,'Transaction Overview'!$H$2:$H$790,D$4) -> 0 | E32: =SUMIFS('Transaction Overview'!$D$2:$D$790,'Transaction Overview'!$I$2:$I$790,$A32,'Transaction Overview'!$H$2:$H$790,E$4) -> 0 | F32: =SUMIFS('Transaction Overview'!$D$2:$D$790,'Transaction Overview'!$I$2:$I$790,$A32,'Transaction Overview'!$H$2:$H$790,F$4) -> 0 | G32: =SUMIFS('Transaction Overview'!$D$2:$D$790,'Transaction Overview'!$I$2:$I$790,$A32,'Transaction Overview'!$H$2:$H$790,G$4) -> 0 | H32: =SUMIFS('Transaction Overview'!$D$2:$D$790,'Transaction Overview'!$I$2:$I$790,$A32,'Transaction Overview'!$H$2:$H$790,H$4) -> 0 | I32: =SUMIFS('Transaction Overview'!$D$2:$D$790,'Transaction Overview'!$I$2:$I$790,$A32,'Transaction Overview'!$H$2:$H$790,I$4) -> 0 | ... M32: =SUMIFS('Transaction Overview'!$D$2:$D$790,'Transaction Overview'!$I$2:$I$790,$A32,'Transaction Overview'!$H$2:$H$790,M$4) -> -39000 | N32: =SUM(B32:M32) -> -39000
A33: MAG - Admeer Advisory Reimbursement | B33: =SUMIFS('Transaction Overview'!$D$2:$D$790,'Transaction Overview'!$I$2:$I$790,$A33,'Transaction Overview'!$H$2:$H$790,B$4) -> 15000 | C33: =SUMIFS('Transaction Overview'!$D$2:$D$790,'Transaction Overview'!$I$2:$I$790,$A33,'Transaction Overview'!$H$2:$H$790,C$4) -> 20000 | D33: =SUMIFS('Transaction Overview'!$D$2:$D$790,'Transaction Overview'!$I$2:$I$790,$A33,'Transaction Overview'!$H$2:$H$790,D$4) -> 0 | E33: =SUMIFS('Transaction Overview'!$D$2:$D$790,'Transaction Overview'!$I$2:$I$790,$A33,'Transaction Overview'!$H$2:$H$790,E$4) -> 0 | F33: =SUMIFS('Transaction Overview'!$D$2:$D$790,'Transaction Overview'!$I$2:$I$790,$A33,'Transaction Overview'!$H$2:$H$790,F$4) -> 0 | G33: =SUMIFS('Transaction Overview'!$D$2:$D$790,'Transaction Overview'!$I$2:$I$790,$A33,'Transaction Overview'!$H$2:$H$790,G$4) -> 0 | H33: =SUMIFS('Transaction Overview'!$D$2:$D$790,'Transaction Overview'!$I$2:$I$790,$A33,'Transaction Overview'!$H$2:$H$790,H$4) -> 0 | I33: =SUMIFS('Transaction Overview'!$D$2:$D$790,'Transaction Overview'!$I$2:$I$790,$A33,'Transaction Overview'!$H$2:$H$790,I$4) -> 0 | ... M33: =SUMIFS('Transaction Overview'!$D$2:$D$790,'Transaction Overview'!$I$2:$I$790,$A33,'Transaction Overview'!$H$2:$H$790,M$4) -> 0 | N33: =SUM(B33:M33) -> 35000
A34: MAG - Admeer Advisory Transfer | B34: =SUMIFS('Transaction Overview'!$D$2:$D$790,'Transaction Overview'!$I$2:$I$790,$A34,'Transaction Overview'!$H$2:$H$790,B$4) -> -9950 | C34: =SUMIFS('Transaction Overview'!$D$2:$D$790,'Transaction Overview'!$I$2:$I$790,$A34,'Transaction Overview'!$H$2:$H$790,C$4) -> -15000 | D34: =SUMIFS('Transaction Overview'!$D$2:$D$790,'Transaction Overview'!$I$2:$I$790,$A34,'Transaction Overview'!$H$2:$H$790,D$4) -> 0 | E34: =SUMIFS('Transaction Overview'!$D$2:$D$790,'Transaction Overview'!$I$2:$I$790,$A34,'Transaction Overview'!$H$2:$H$790,E$4) -> 0 | F34: =SUMIFS('Transaction Overview'!$D$2:$D$790,'Transaction Overview'!$I$2:$I$790,$A34,'Transaction Overview'!$H$2:$H$790,F$4) -> -2500 | G34: =SUMIFS('Transaction Overview'!$D$2:$D$790,'Transaction Overview'!$I$2:$I$790,$A34,'Transaction Overview'!$H$2:$H$790,G$4) -> -5000 | H34: =SUMIFS('Transaction Overview'!$D$2:$D$790,'Transaction Overview'!$I$2:$I$790,$A34,'Transaction Overview'!$H$2:$H$790,H$4) -> 0 | I34: =SUMIFS('Transaction Overview'!$D$2:$D$790,'Transaction Overview'!$I$2:$I$790,$A34,'Transaction Overview'!$H$2:$H$790,I$4) -> 0 | ... M34: =SUMIFS('Transaction Overview'!$D$2:$D$790,'Transaction Overview'!$I$2:$I$790,$A34,'Transaction Overview'!$H$2:$H$790,M$4) -> 0 | N34: =SUM(B34:M34) -> -42450
A35: MAG Capital Partners Pass-Through Wire – 70/30 Split | B35: =SUMIFS('Transaction Overview'!$D$2:$D$790,'Transaction Overview'!$I$2:$I$790,$A35,'Transaction Overview'!$H$2:$H$790,B$4) -> 0 | C35: =SUMIFS('Transaction Overview'!$D$2:$D$790,'Transaction Overview'!$I$2:$I$790,$A35,'Transaction Overview'!$H$2:$H$790,C$4) -> 0 | D35: =SUMIFS('Transaction Overview'!$D$2:$D$790,'Transaction Overview'!$I$2:$I$790,$A35,'Transaction Overview'!$H$2:$H$790,D$4) -> 0 | E35: =SUMIFS('Transaction Overview'!$D$2:$D$790,'Transaction Overview'!$I$2:$I$790,$A35,'Transaction Overview'!$H$2:$H$790,E$4) -> 0 | F35: =SUMIFS('Transaction Overview'!$D$2:$D$790,'Transaction Overview'!$I$2:$I$790,$A35,'Transaction Overview'!$H$2:$H$790,F$4) -> 0 | G35: =SUMIFS('Transaction Overview'!$D$2:$D$790,'Transaction Overview'!$I$2:$I$790,$A35,'Transaction Overview'!$H$2:$H$790,G$4) -> 0 | H35: =SUMIFS('Transaction Overview'!$D$2:$D$790,'Transaction Overview'!$I$2:$I$790,$A35,'Transaction Overview'!$H$2:$H$790,H$4) -> 0 | I35: =SUMIFS('Transaction Overview'!$D$2:$D$790,'Transaction Overview'!$I$2:$I$790,$A35,'Transaction Overview'!$H$2:$H$790,I$4) -> 0 | ... M35: =SUMIFS('Transaction Overview'!$D$2:$D$790,'Transaction Overview'!$I$2:$I$790,$A35,'Transaction Overview'!$H$2:$H$790,M$4) -> 75000 | N35: =SUM(B35:M35) -> 75000
A36: MAG Marketing Reimbursement | B36: =SUMIFS('Transaction Overview'!$D$2:$D$790,'Transaction Overview'!$I$2:$I$790,$A36,'Transaction Overview'!$H$2:$H$790,B$4) -> 0 | C36: =SUMIFS('Transaction Overview'!$D$2:$D$790,'Transaction Overview'!$I$2:$I$790,$A36,'Transaction Overview'!$H$2:$H$790,C$4) -> 0 | D36: =SUMIFS('Transaction Overview'!$D$2:$D$790,'Transaction Overview'!$I$2:$I$790,$A36,'Transaction Overview'!$H$2:$H$790,D$4) -> 0 | E36: =SUMIFS('Transaction Overview'!$D$2:$D$790,'Transaction Overview'!$I$2:$I$790,$A36,'Transaction Overview'!$H$2:$H$790,E$4) -> 0 | F36: =SUMIFS('Transaction Overview'!$D$2:$D$790,'Transaction Overview'!$I$2:$I$790,$A36,'Transaction Overview'!$H$2:$H$790,F$4) -> 0 | G36: =SUMIFS('Transaction Overview'!$D$2:$D$790,'Transaction Overview'!$I$2:$I$790,$A36,'Transaction Overview'!$H$2:$H$790,G$4) -> 0 | H36: =SUMIFS('Transaction Overview'!$D$2:$D$790,'Transaction Overview'!$I$2:$I$790,$A36,'Transaction Overview'!$H$2:$H$790,H$4) -> 0 | I36: =SUMIFS('Transaction Overview'!$D$2:$D$790,'Transaction Overview'!$I$2:$I$790,$A36,'Transaction Overview'!$H$2:$H$790,I$4) -> 0 | ... M36: =SUMIFS('Transaction Overview'!$D$2:$D$790,'Transaction Overview'!$I$2:$I$790,$A36,'Transaction Overview'!$H$2:$H$790,M$4) -> 0 | N36: =SUM(B36:M36) -> 15000
A37: Subtotal — MAG Pass-Through | B37: =SUMIFS('Transaction Overview'!$D$2:$D$790,'Transaction Overview'!$J$2:$J$790,"MAG Pass-Through",'Transaction Overview'!$H$2:$H$790,B$4) -> 5050 | C37: =SUMIFS('Transaction Overview'!$D$2:$D$790,'Transaction Overview'!$J$2:$J$790,"MAG Pass-Through",'Transaction Overview'!$H$2:$H$790,C$4) -> 5000 | D37: =SUMIFS('Transaction Overview'!$D$2:$D$790,'Transaction Overview'!$J$2:$J$790,"MAG Pass-Through",'Transaction Overview'!$H$2:$H$790,D$4) -> 0 | E37: =SUMIFS('Transaction Overview'!$D$2:$D$790,'Transaction Overview'!$J$2:$J$790,"MAG Pass-Through",'Transaction Overview'!$H$2:$H$790,E$4) -> 0 | F37: =SUMIFS('Transaction Overview'!$D$2:$D$790,'Transaction Overview'!$J$2:$J$790,"MAG Pass-Through",'Transaction Overview'!$H$2:$H$790,F$4) -> -2500 | G37: =SUMIFS('Transaction Overview'!$D$2:$D$790,'Transaction Overview'!$J$2:$J$790,"MAG Pass-Through",'Transaction Overview'!$H$2:$H$790,G$4) -> -5000 | H37: =SUMIFS('Transaction Overview'!$D$2:$D$790,'Transaction Overview'!$J$2:$J$790,"MAG Pass-Through",'Transaction Overview'!$H$2:$H$790,H$4) -> 0 | I37: =SUMIFS('Transaction Overview'!$D$2:$D$790,'Transaction Overview'!$J$2:$J$790,"MAG Pass-Through",'Transaction Overview'!$H$2:$H$790,I$4) -> 0 | ... M37: =SUMIFS('Transaction Overview'!$D$2:$D$790,'Transaction Overview'!$J$2:$J$790,"MAG Pass-Through",'Transaction Overview'!$H$2:$H$790,M$4) -> 15000 | N37: =SUM(B37:M37) -> 22550
A39: Wire Transfers — Incoming
A40: Incoming Crystal Asset Management Wire | B40: =SUMIFS('Transaction Overview'!$D$2:$D$790,'Transaction Overview'!$I$2:$I$790,$A40,'Transaction Overview'!$H$2:$H$790,B$4) -> 0 | C40: =SUMIFS('Transaction Overview'!$D$2:$D$790,'Transaction Overview'!$I$2:$I$790,$A40,'Transaction Overview'!$H$2:$H$790,C$4) -> 0 | D40: =SUMIFS('Transaction Overview'!$D$2:$D$790,'Transaction Overview'!$I$2:$I$790,$A40,'Transaction Overview'!$H$2:$H$790,D$4) -> 0 | E40: =SUMIFS('Transaction Overview'!$D$2:$D$790,'Transaction Overview'!$I$2:$I$790,$A40,'Transaction Overview'!$H$2:$H$790,E$4) -> 0 | F40: =SUMIFS('Transaction Overview'!$D$2:$D$790,'Transaction Overview'!$I$2:$I$790,$A40,'Transaction Overview'!$H$2:$H$790,F$4) -> 0 | G40: =SUMIFS('Transaction Overview'!$D$2:$D$790,'Transaction Overview'!$I$2:$I$790,$A40,'Transaction Overview'!$H$2:$H$790,G$4) -> 100000 | H40: =SUMIFS('Transaction Overview'!$D$2:$D$790,'Transaction Overview'!$I$2:$I$790,$A40,'Transaction Overview'!$H$2:$H$790,H$4) -> 0 | I40: =SUMIFS('Transaction Overview'!$D$2:$D$790,'Transaction Overview'!$I$2:$I$790,$A40,'Transaction Overview'!$H$2:$H$790,I$4) -> 0 | ... M40: =SUMIFS('Transaction Overview'!$D$2:$D$790,'Transaction Overview'!$I$2:$I$790,$A40,'Transaction Overview'!$H$2:$H$790,M$4) -> 0 | N40: =SUM(B40:M40) -> 100000
A41: Incoming wire from JC Whitner | B41: =SUMIFS('Transaction Overview'!$D$2:$D$790,'Transaction Overview'!$I$2:$I$790,$A41,'Transaction Overview'!$H$2:$H$790,B$4) -> 0 | C41: =SUMIFS('Transaction Overview'!$D$2:$D$790,'Transaction Overview'!$I$2:$I$790,$A41,'Transaction Overview'!$H$2:$H$790,C$4) -> 0 | D41: =SUMIFS('Transaction Overview'!$D$2:$D$790,'Transaction Overview'!$I$2:$I$790,$A41,'Transaction Overview'!$H$2:$H$790,D$4) -> 0 | E41: =SUMIFS('Transaction Overview'!$D$2:$D$790,'Transaction Overview'!$I$2:$I$790,$A41,'Transaction Overview'!$H$2:$H$790,E$4) -> 0 | F41: =SUMIFS('Transaction Overview'!$D$2:$D$790,'Transaction Overview'!$I$2:$I$790,$A41,'Transaction Overview'!$H$2:$H$790,F$4) -> 0 | G41: =SUMIFS('Transaction Overview'!$D$2:$D$790,'Transaction Overview'!$I$2:$I$790,$A41,'Transaction Overview'!$H$2:$H$790,G$4) -> 0 | H41: =SUMIFS('Transaction Overview'!$D$2:$D$790,'Transaction Overview'!$I$2:$I$790,$A41,'Transaction Overview'!$H$2:$H$790,H$4) -> 0 | I41: =SUMIFS('Transaction Overview'!$D$2:$D$790,'Transaction Overview'!$I$2:$I$790,$A41,'Transaction Overview'!$H$2:$H$790,I$4) -> 20000 | ... M41: =SUMIFS('Transaction Overview'!$D$2:$D$790,'Transaction Overview'!$I$2:$I$790,$A41,'Transaction Overview'!$H$2:$H$790,M$4) -> 0 | N41: =SUM(B41:M41) -> 20000
A42: Subtotal — Wire Transfers — Incoming | B42: =SUMIFS('Transaction Overview'!$D$2:$D$790,'Transaction Overview'!$J$2:$J$790,"Wire Transfers — Incoming",'Transaction Overview'!$H$2:$H$790,B$4) -> 0 | C42: =SUMIFS('Transaction Overview'!$D$2:$D$790,'Transaction Overview'!$J$2:$J$790,"Wire Transfers — Incoming",'Transaction Overview'!$H$2:$H$790,C$4) -> 0 | D42: =SUMIFS('Transaction Overview'!$D$2:$D$790,'Transaction Overview'!$J$2:$J$790,"Wire Transfers — Incoming",'Transaction Overview'!$H$2:$H$790,D$4) -> 0 | E42: =SUMIFS('Transaction Overview'!$D$2:$D$790,'Transaction Overview'!$J$2:$J$790,"Wire Transfers — Incoming",'Transaction Overview'!$H$2:$H$790,E$4) -> 0 | F42: =SUMIFS('Transaction Overview'!$D$2:$D$790,'Transaction Overview'!$J$2:$J$790,"Wire Transfers — Incoming",'Transaction Overview'!$H$2:$H$790,F$4) -> 0 | G42: =SUMIFS('Transaction Overview'!$D$2:$D$790,'Transaction Overview'!$J$2:$J$790,"Wire Transfers — Incoming",'Transaction Overview'!$H$2:$H$790,G$4) -> 100000 | H42: =SUMIFS('Transaction Overview'!$D$2:$D$790,'Transaction Overview'!$J$2:$J$790,"Wire Transfers — Incoming",'Transaction Overview'!$H$2:$H$790,H$4) -> 0 | I42: =SUMIFS('Transaction Overview'!$D$2:$D$790,'Transaction Overview'!$J$2:$J$790,"Wire Transfers — Incoming",'Transaction Overview'!$H$2:$H$790,I$4) -> 20000 | ... M42: =SUMIFS('Transaction Overview'!$D$2:$D$790,'Transaction Overview'!$J$2:$J$790,"Wire Transfers — Incoming",'Transaction Overview'!$H$2:$H$790,M$4) -> 0 | N42: =SUM(B42:M42) -> 120000
A44: Wire Transfers — Outgoing
A45: Outgoing Crystal Asset Management Wire | B45: =SUMIFS('Transaction Overview'!$D$2:$D$790,'Transaction Overview'!$I$2:$I$790,$A45,'Transaction Overview'!$H$2:$H$790,B$4) -> 0 | C45: =SUMIFS('Transaction Overview'!$D$2:$D$790,'Transaction Overview'!$I$2:$I$790,$A45,'Transaction Overview'!$H$2:$H$790,C$4) -> 0 | D45: =SUMIFS('Transaction Overview'!$D$2:$D$790,'Transaction Overview'!$I$2:$I$790,$A45,'Transaction Overview'!$H$2:$H$790,D$4) -> 0 | E45: =SUMIFS('Transaction Overview'!$D$2:$D$790,'Transaction Overview'!$I$2:$I$790,$A45,'Transaction Overview'!$H$2:$H$790,E$4) -> 0 | F45: =SUMIFS('Transaction Overview'!$D$2:$D$790,'Transaction Overview'!$I$2:$I$790,$A45,'Transaction Overview'!$H$2:$H$790,F$4) -> 0 | G45: =SUMIFS('Transaction Overview'!$D$2:$D$790,'Transaction Overview'!$I$2:$I$790,$A45,'Transaction Overview'!$H$2:$H$790,G$4) -> -100000 | H45: =SUMIFS('Transaction Overview'!$D$2:$D$790,'Transaction Overview'!$I$2:$I$790,$A45,'Transaction Overview'!$H$2:$H$790,H$4) -> 0 | I45: =SUMIFS('Transaction Overview'!$D$2:$D$790,'Transaction Overview'!$I$2:$I$790,$A45,'Transaction Overview'!$H$2:$H$790,I$4) -> 0 | ... M45: =SUMIFS('Transaction Overview'!$D$2:$D$790,'Transaction Overview'!$I$2:$I$790,$A45,'Transaction Overview'!$H$2:$H$790,M$4) -> 0 | N45: =SUM(B45:M45) -> -100000
A46: Outgoing wire to JC Whitner | B46: =SUMIFS('Transaction Overview'!$D$2:$D$790,'Transaction Overview'!$I$2:$I$790,$A46,'Transaction Overview'!$H$2:$H$790,B$4) -> 0 | C46: =SUMIFS('Transaction Overview'!$D$2:$D$790,'Transaction Overview'!$I$2:$I$790,$A46,'Transaction Overview'!$H$2:$H$790,C$4) -> 0 | D46: =SUMIFS('Transaction Overview'!$D$2:$D$790,'Transaction Overview'!$I$2:$I$790,$A46,'Transaction Overview'!$H$2:$H$790,D$4) -> 0 | E46: =SUMIFS('Transaction Overview'!$D$2:$D$790,'Transaction Overview'!$I$2:$I$790,$A46,'Transaction Overview'!$H$2:$H$790,E$4) -> 0 | F46: =SUMIFS('Transaction Overview'!$D$2:$D$790,'Transaction Overview'!$I$2:$I$790,$A46,'Transaction Overview'!$H$2:$H$790,F$4) -> 0 | G46: =SUMIFS('Transaction Overview'!$D$2:$D$790,'Transaction Overview'!$I$2:$I$790,$A46,'Transaction Overview'!$H$2:$H$790,G$4) -> 0 | H46: =SUMIFS('Transaction Overview'!$D$2:$D$790,'Transaction Overview'!$I$2:$I$790,$A46,'Transaction Overview'!$H$2:$H$790,H$4) -> 0 | I46: =SUMIFS('Transaction Overview'!$D$2:$D$790,'Transaction Overview'!$I$2:$I$790,$A46,'Transaction Overview'!$H$2:$H$790,I$4) -> -25000 | ... M46: =SUMIFS('Transaction Overview'!$D$2:$D$790,'Transaction Overview'!$I$2:$I$790,$A46,'Transaction Overview'!$H$2:$H$790,M$4) -> -10000 | N46: =SUM(B46:M46) -> -35000
...

Sheet Monthly Detail
A1: Chase 9335 — 2025 Activity
A2: Monthly Detail — Spend by Individual Category | Jan 2025 – Dec 2025
A4: Category | B4: Group | C4: =DATE(2025,1,1) -> 45658 | D4: =DATE(2025,2,1) -> 45689 | E4: =DATE(2025,3,1) -> 45717 | F4: =DATE(2025,4,1) -> 45748 | G4: =DATE(2025,5,1) -> 45778 | H4: =DATE(2025,6,1) -> 45809 | I4: =DATE(2025,7,1) -> 45839 | J4: =DATE(2025,8,1) -> 45870 | K4: =DATE(2025,9,1) -> 45901 | L4: =DATE(2025,10,1) -> 45931 | M4: =DATE(2025,11,1) -> 45962 | N4: =DATE(2025,12,1) -> 45992 | O4: Total
A5: Deal Specific: Austin Iron | B5: Deal-Specific | C5: =SUMIFS('Transaction Overview'!$D$2:$D$790,'Transaction Overview'!$G$2:$G$790,$A5,'Transaction Overview'!$H$2:$H$790,C$4) -> 350 | D5: =SUMIFS('Transaction Overview'!$D$2:$D$790,'Transaction Overview'!$G$2:$G$790,$A5,'Transaction Overview'!$H$2:$H$790,D$4) -> 350 | E5: =SUMIFS('Transaction Overview'!$D$2:$D$790,'Transaction Overview'!$G$2:$G$790,$A5,'Transaction Overview'!$H$2:$H$790,E$4) -> 350 | F5: =SUMIFS('Transaction Overview'!$D$2:$D$790,'Transaction Overview'!$G$2:$G$790,$A5,'Transaction Overview'!$H$2:$H$790,F$4) -> 350 | G5: =SUMIFS('Transaction Overview'!$D$2:$D$790,'Transaction Overview'!$G$2:$G$790,$A5,'Transaction Overview'!$H$2:$H$790,G$4) -> 350 | H5: =SUMIFS('Transaction Overview'!$D$2:$D$790,'Transaction Overview'!$G$2:$G$790,$A5,'Transaction Overview'!$H$2:$H$790,H$4) -> 350 | I5: =SUMIFS('Transaction Overview'!$D$2:$D$790,'Transaction Overview'!$G$2:$G$790,$A5,'Transaction Overview'!$H$2:$H$790,I$4) -> 350 | J5: =SUMIFS('Transaction Overview'!$D$2:$D$790,'Transaction Overview'!$G$2:$G$790,$A5,'Transaction Overview'!$H$2:$H$790,J$4) -> 350 | ... N5: =SUMIFS('Transaction Overview'!$D$2:$D$790,'Transaction Overview'!$G$2:$G$790,$A5,'Transaction Overview'!$H$2:$H$790,N$4) -> 350 | O5: =SUM(C5:N5) -> 4200
A6: Deal Specific: Cloverdale | B6: Deal-Specific | C6: =SUMIFS('Transaction Overview'!$D$2:$D$790,'Transaction Overview'!$G$2:$G$790,$A6,'Transaction Overview'!$H$2:$H$790,C$4) -> 0 | D6: =SUMIFS('Transaction Overview'!$D$2:$D$790,'Transaction Overview'!$G$2:$G$790,$A6,'Transaction Overview'!$H$2:$H$790,D$4) -> 0 | E6: =SUMIFS('Transaction Overview'!$D$2:$D$790,'Transaction Overview'!$G$2:$G$790,$A6,'Transaction Overview'!$H$2:$H$790,E$4) -> 0 | F6: =SUMIFS('Transaction Overview'!$D$2:$D$790,'Transaction Overview'!$G$2:$G$790,$A6,'Transaction Overview'!$H$2:$H$790,F$4) -> 0 | G6: =SUMIFS('Transaction Overview'!$D$2:$D$790,'Transaction Overview'!$G$2:$G$790,$A6,'Transaction Overview'!$H$2:$H$790,G$4) -> 0 | H6: =SUMIFS('Transaction Overview'!$D$2:$D$790,'Transaction Overview'!$G$2:$G$790,$A6,'Transaction Overview'!$H$2:$H$790,H$4) -> 0 | I6: =SUMIFS('Transaction Overview'!$D$2:$D$790,'Transaction Overview'!$G$2:$G$790,$A6,'Transaction Overview'!$H$2:$H$790,I$4) -> 0 | J6: =SUMIFS('Transaction Overview'!$D$2:$D$790,'Transaction Overview'!$G$2:$G$790,$A6,'Transaction Overview'!$H$2:$H$790,J$4) -> 0 | ... N6: =SUMIFS('Transaction Overview'!$D$2:$D$790,'Transaction Overview'!$G$2:$G$790,$A6,'Transaction Overview'!$H$2:$H$790,N$4) -> -155000 | O6: =SUM(C6:N6) -> -155000
A7: Deal Specific: Hibbert | B7: Deal-Specific | C7: =SUMIFS('Transaction Overview'!$D$2:$D$790,'Transaction Overview'!$G$2:$G$790,$A7,'Transaction Overview'!$H$2:$H$790,C$4) -> 0 | D7: =SUMIFS('Transaction Overview'!$D$2:$D$790,'Transaction Overview'!$G$2:$G$790,$A7,'Transaction Overview'!$H$2:$H$790,D$4) -> 0 | E7: =SUMIFS('Transaction Overview'!$D$2:$D$790,'Transaction Overview'!$G$2:$G$790,$A7,'Transaction Overview'!$H$2:$H$790,E$4) -> 0 | F7: =SUMIFS('Transaction Overview'!$D$2:$D$790,'Transaction Overview'!$G$2:$G$790,$A7,'Transaction Overview'!$H$2:$H$790,F$4) -> 0 | G7: =SUMIFS('Transaction Overview'!$D$2:$D$790,'Transaction Overview'!$G$2:$G$790,$A7,'Transaction Overview'!$H$2:$H$790,G$4) -> 0 | H7: =SUMIFS('Transaction Overview'!$D$2:$D$790,'Transaction Overview'!$G$2:$G$790,$A7,'Transaction Overview'!$H$2:$H$790,H$4) -> 0 | I7: =SUMIFS('Transaction Overview'!$D$2:$D$790,'Transaction Overview'!$G$2:$G$790,$A7,'Transaction Overview'!$H$2:$H$790,I$4) -> 0 | J7: =SUMIFS('Transaction Overview'!$D$2:$D$790,'Transaction Overview'!$G$2:$G$790,$A7,'Transaction Overview'!$H$2:$H$790,J$4) -> 0 | ... N7: =SUMIFS('Transaction Overview'!$D$2:$D$790,'Transaction Overview'!$G$2:$G$790,$A7,'Transaction Overview'!$H$2:$H$790,N$4) -> 0 | O7: =SUM(C7:N7) -> -46528.05
A8: Deal Specific: JAL Breese | B8: Deal-Specific | C8: =SUMIFS('Transaction Overview'!$D$2:$D$790,'Transaction Overview'!$G$2:$G$790,$A8,'Transaction Overview'!$H$2:$H$790,C$4) -> 0 | D8: =SUMIFS('Transaction Overview'!$D$2:$D$790,'Transaction Overview'!$G$2:$G$790,$A8,'Transaction Overview'!$H$2:$H$790,D$4) -> 0 | E8: =SUMIFS('Transaction Overview'!$D$2:$D$790,'Transaction Overview'!$G$2:$G$790,$A8,'Transaction Overview'!$H$2:$H$790,E$4) -> 0 | F8: =SUMIFS('Transaction Overview'!$D$2:$D$790,'Transaction Overview'!$G$2:$G$790,$A8,'Transaction Overview'!$H$2:$H$790,F$4) -> -50000 | G8: =SUMIFS('Transaction Overview'!$D$2:$D$790,'Transaction Overview'!$G$2:$G$790,$A8,'Transaction Overview'!$H$2:$H$790,G$4) -> 0 | H8: =SUMIFS('Transaction Overview'!$D$2:$D$790,'Transaction Overview'!$G$2:$G$790,$A8,'Transaction Overview'!$H$2:$H$790,H$4) -> 0 | I8: =SUMIFS('Transaction Overview'!$D$2:$D$790,'Transaction Overview'!$G$2:$G$790,$A8,'Transaction Overview'!$H$2:$H$790,I$4) -> 0 | J8: =SUMIFS('Transaction Overview'!$D$2:$D$790,'Transaction Overview'!$G$2:$G$790,$A8,'Transaction Overview'!$H$2:$H$790,J$4) -> 0 | ... N8: =SUMIFS('Transaction Overview'!$D$2:$D$790,'Transaction Overview'!$G$2:$G$790,$A8,'Transaction Overview'!$H$2:$H$790,N$4) -> 0 | O8: =SUM(C8:N8) -> -50000
A9: Deal Specific: Merit-Lancaster | B9: Deal-Specific | C9: =SUMIFS('Transaction Overview'!$D$2:$D$790,'Transaction Overview'!$G$2:$G$790,$A9,'Transaction Overview'!$H$2:$H$790,C$4) -> 461.52 | D9: =SUMIFS('Transaction Overview'!$D$2:$D$790,'Transaction Overview'!$G$2:$G$790,$A9,'Transaction Overview'!$H$2:$H$790,D$4) -> 461.52 | E9: =SUMIFS('Transaction Overview'!$D$2:$D$790,'Transaction Overview'!$G$2:$G$790,$A9,'Transaction Overview'!$H$2:$H$790,E$4) -> 476.41 | F9: =SUMIFS('Transaction Overview'!$D$2:$D$790,'Transaction Overview'!$G$2:$G$790,$A9,'Transaction Overview'!$H$2:$H$790,F$4) -> 476.41 | G9: =SUMIFS('Transaction Overview'!$D$2:$D$790,'Transaction Overview'!$G$2:$G$790,$A9,'Transaction Overview'!$H$2:$H$790,G$4) -> 476.41 | H9: =SUMIFS('Transaction Overview'!$D$2:$D$790,'Transaction Overview'!$G$2:$G$790,$A9,'Transaction Overview'!$H$2:$H$790,H$4) -> 476.41 | I9: =SUMIFS('Transaction Overview'!$D$2:$D$790,'Transaction Overview'!$G$2:$G$790,$A9,'Transaction Overview'!$H$2:$H$790,I$4) -> 476.41 | J9: =SUMIFS('Transaction Overview'!$D$2:$D$790,'Transaction Overview'!$G$2:$G$790,$A9,'Transaction Overview'!$H$2:$H$790,J$4) -> 476.41 | ... N9: =SUMIFS('Transaction Overview'!$D$2:$D$790,'Transaction Overview'!$G$2:$G$790,$A9,'Transaction Overview'!$H$2:$H$790,N$4) -> 476.41 | O9: =SUM(C9:N9) -> 5687.14
