Workbook

Sheet Category Summary
A1: Chase 1168 — DWG Capital Group 2026 Activity
A2: Category Summary | Jan 2026 – Dec 2026
A4: Entity | B4: DWG Capital Group
A5: Account | B5: Business Checking — Chase 1168
A6: Period | B6: Jan 2026 – Dec 2026
A8: TOTALS
A9: Total Inflows | B9: =SUMIFS('Transaction Overview'!$D$2:$D$517,'Transaction Overview'!$D$2:$D$517,">0") -> 1037026.5
A10: Total Outflows | B10: =SUMIFS('Transaction Overview'!$D$2:$D$517,'Transaction Overview'!$D$2:$D$517,"<0") -> -1064698.9
A11: Net Change | B11: =B9+B10 -> -27672.4
A14: Category | B14: Inflows | C14: Outflows | D14: Net
A15: Deal-Specific
A16: Deal Specific: 260 S Hibbert | B16: =SUMIFS('Transaction Overview'!$D$2:$D$517,'Transaction Overview'!$I$2:$I$517,$A16,'Transaction Overview'!$D$2:$D$517,">0") -> 40000 | C16: =SUMIFS('Transaction Overview'!$D$2:$D$517,'Transaction Overview'!$I$2:$I$517,$A16,'Transaction Overview'!$D$2:$D$517,"<0") -> -600 | D16: =B16+C16 -> 39400
A17: Incoming MOAB Mortgage Coverage | B17: =SUMIFS('Transaction Overview'!$D$2:$D$517,'Transaction Overview'!$I$2:$I$517,$A17,'Transaction Overview'!$D$2:$D$517,">0") -> 42782.05 | C17: =SUMIFS('Transaction Overview'!$D$2:$D$517,'Transaction Overview'!$I$2:$I$517,$A17,'Transaction Overview'!$D$2:$D$517,"<0") -> 0 | D17: =B17+C17 -> 42782.05
A18: Moab E4 Mortgage Payment | B18: =SUMIFS('Transaction Overview'!$D$2:$D$517,'Transaction Overview'!$I$2:$I$517,$A18,'Transaction Overview'!$D$2:$D$517,">0") -> 0 | C18: =SUMIFS('Transaction Overview'!$D$2:$D$517,'Transaction Overview'!$I$2:$I$517,$A18,'Transaction Overview'!$D$2:$D$517,"<0") -> -21303.03 | D18: =B18+C18 -> -21303.03
A19: Moab E7 Mortgage Payment | B19: =SUMIFS('Transaction Overview'!$D$2:$D$517,'Transaction Overview'!$I$2:$I$517,$A19,'Transaction Overview'!$D$2:$D$517,">0") -> 0 | C19: =SUMIFS('Transaction Overview'!$D$2:$D$517,'Transaction Overview'!$I$2:$I$517,$A19,'Transaction Overview'!$D$2:$D$517,"<0") -> -21479.02 | D19: =B19+C19 -> -21479.02
A20: Subtotal — Deal-Specific | B20: =SUMIFS('Transaction Overview'!$D$2:$D$517,'Transaction Overview'!$J$2:$J$517,"Deal-Specific",'Transaction Overview'!$D$2:$D$517,">0") -> 82782.05 | C20: =SUMIFS('Transaction Overview'!$D$2:$D$517,'Transaction Overview'!$J$2:$J$517,"Deal-Specific",'Transaction Overview'!$D$2:$D$517,"<0") -> -43382.05 | D20: =B20+C20 -> 39400
A22: Commissions — Incoming
A23: Incoming Commission: MDC | B23: =SUMIFS('Transaction Overview'!$D$2:$D$517,'Transaction Overview'!$I$2:$I$517,$A23,'Transaction Overview'!$D$2:$D$517,">0") -> 114000 | C23: =SUMIFS('Transaction Overview'!$D$2:$D$517,'Transaction Overview'!$I$2:$I$517,$A23,'Transaction Overview'!$D$2:$D$517,"<0") -> 0 | D23: =B23+C23 -> 114000
A24: Subtotal — Commissions — Incoming | B24: =SUMIFS('Transaction Overview'!$D$2:$D$517,'Transaction Overview'!$J$2:$J$517,"Commissions — Incoming",'Transaction Overview'!$D$2:$D$517,">0") -> 114000 | C24: =SUMIFS('Transaction Overview'!$D$2:$D$517,'Transaction Overview'!$J$2:$J$517,"Commissions — Incoming",'Transaction Overview'!$D$2:$D$517,"<0") -> 0 | D24: =B24+C24 -> 114000
A26: Commissions — Outgoing
A27: Hugh Gerhke - MDC Commission | B27: =SUMIFS('Transaction Overview'!$D$2:$D$517,'Transaction Overview'!$I$2:$I$517,$A27,'Transaction Overview'!$D$2:$D$517,">0") -> 0 | C27: =SUMIFS('Transaction Overview'!$D$2:$D$517,'Transaction Overview'!$I$2:$I$517,$A27,'Transaction Overview'!$D$2:$D$517,"<0") -> -16875 | D27: =B27+C27 -> -16875
A28: Meg Maran - MDC Commission | B28: =SUMIFS('Transaction Overview'!$D$2:$D$517,'Transaction Overview'!$I$2:$I$517,$A28,'Transaction Overview'!$D$2:$D$517,">0") -> 0 | C28: =SUMIFS('Transaction Overview'!$D$2:$D$517,'Transaction Overview'!$I$2:$I$517,$A28,'Transaction Overview'!$D$2:$D$517,"<0") -> -1500 | D28: =B28+C28 -> -1500
A29: Subtotal — Commissions — Outgoing | B29: =SUMIFS('Transaction Overview'!$D$2:$D$517,'Transaction Overview'!$J$2:$J$517,"Commissions — Outgoing",'Transaction Overview'!$D$2:$D$517,">0") -> 0 | C29: =SUMIFS('Transaction Overview'!$D$2:$D$517,'Transaction Overview'!$J$2:$J$517,"Commissions — Outgoing",'Transaction Overview'!$D$2:$D$517,"<0") -> -18375 | D29: =B29+C29 -> -18375
A31: MAG Pass-Through
A32: Due to Andrew – MAG Pass-Through 30% | B32: =SUMIFS('Transaction Overview'!$D$2:$D$517,'Transaction Overview'!$I$2:$I$517,$A32,'Transaction Overview'!$D$2:$D$517,">0") -> 0 | C32: =SUMIFS('Transaction Overview'!$D$2:$D$517,'Transaction Overview'!$I$2:$I$517,$A32,'Transaction Overview'!$D$2:$D$517,"<0") -> -177000 | D32: =B32+C32 -> -177000
A33: Due to Dax – MAG Pass-Through 70% | B33: =SUMIFS('Transaction Overview'!$D$2:$D$517,'Transaction Overview'!$I$2:$I$517,$A33,'Transaction Overview'!$D$2:$D$517,">0") -> 0 | C33: =SUMIFS('Transaction Overview'!$D$2:$D$517,'Transaction Overview'!$I$2:$I$517,$A33,'Transaction Overview'!$D$2:$D$517,"<0") -> -413000 | D33: =B33+C33 -> -413000
A34: MAG Capital Partners Pass-Through Wire – 70/30 Split | B34: =SUMIFS('Transaction Overview'!$D$2:$D$517,'Transaction Overview'!$I$2:$I$517,$A34,'Transaction Overview'!$D$2:$D$517,">0") -> 600000 | C34: =SUMIFS('Transaction Overview'!$D$2:$D$517,'Transaction Overview'!$I$2:$I$517,$A34,'Transaction Overview'!$D$2:$D$517,"<0") -> 0 | D34: =B34+C34 -> 600000
A35: Subtotal — MAG Pass-Through | B35: =SUMIFS('Transaction Overview'!$D$2:$D$517,'Transaction Overview'!$J$2:$J$517,"MAG Pass-Through",'Transaction Overview'!$D$2:$D$517,">0") -> 600000 | C35: =SUMIFS('Transaction Overview'!$D$2:$D$517,'Transaction Overview'!$J$2:$J$517,"MAG Pass-Through",'Transaction Overview'!$D$2:$D$517,"<0") -> -590000 | D35: =B35+C35 -> 10000
A37: Poseidon Asset Group
A38: Poseidon Asset Group (Incoming) | B38: =SUMIFS('Transaction Overview'!$D$2:$D$517,'Transaction Overview'!$I$2:$I$517,$A38,'Transaction Overview'!$D$2:$D$517,">0") -> 238556.41 | C38: =SUMIFS('Transaction Overview'!$D$2:$D$517,'Transaction Overview'!$I$2:$I$517,$A38,'Transaction Overview'!$D$2:$D$517,"<0") -> 0 | D38: =B38+C38 -> 238556.41
A39: Poseidon Asset Group (Outgoing) | B39: =SUMIFS('Transaction Overview'!$D$2:$D$517,'Transaction Overview'!$I$2:$I$517,$A39,'Transaction Overview'!$D$2:$D$517,">0") -> 0 | C39: =SUMIFS('Transaction Overview'!$D$2:$D$517,'Transaction Overview'!$I$2:$I$517,$A39,'Transaction Overview'!$D$2:$D$517,"<0") -> -8556.41 | D39: =B39+C39 -> -8556.41
A40: Subtotal — Poseidon Asset Group | B40: =SUMIFS('Transaction Overview'!$D$2:$D$517,'Transaction Overview'!$J$2:$J$517,"Poseidon Asset Group",'Transaction Overview'!$D$2:$D$517,">0") -> 238556.41 | C40: =SUMIFS('Transaction Overview'!$D$2:$D$517,'Transaction Overview'!$J$2:$J$517,"Poseidon Asset Group",'Transaction Overview'!$D$2:$D$517,"<0") -> -8556.41 | D40: =B40+C40 -> 230000
A42: Intercompany & Savings Transfers
A43: Transfer to DWG Capital Group_Costar | B43: =SUMIFS('Transaction Overview'!$D$2:$D$517,'Transaction Overview'!$I$2:$I$517,$A43,'Transaction Overview'!$D$2:$D$517,">0") -> 0 | C43: =SUMIFS('Transaction Overview'!$D$2:$D$517,'Transaction Overview'!$I$2:$I$517,$A43,'Transaction Overview'!$D$2:$D$517,"<0") -> -12956.18 | D43: =B43+C43 -> -12956.18
A44: Transfer to DWG Savings | B44: =SUMIFS('Transaction Overview'!$D$2:$D$517,'Transaction Overview'!$I$2:$I$517,$A44,'Transaction Overview'!$D$2:$D$517,">0") -> 0 | C44: =SUMIFS('Transaction Overview'!$D$2:$D$517,'Transaction Overview'!$I$2:$I$517,$A44,'Transaction Overview'!$D$2:$D$517,"<0") -> -4742 | D44: =B44+C44 -> -4742
A45: Transfer to DWG Capital Partners | B45: =SUMIFS('Transaction Overview'!$D$2:$D$517,'Transaction Overview'!$I$2:$I$517,$A45,'Transaction Overview'!$D$2:$D$517,">0") -> 0 | C45: =SUMIFS('Transaction Overview'!$D$2:$D$517,'Transaction Overview'!$I$2:$I$517,$A45,'Transaction Overview'!$D$2:$D$517,"<0") -> -5000 | D45: =B45+C45 -> -5000
A46: Transfer to DWG Holdings | B46: =SUMIFS('Transaction Overview'!$D$2:$D$517,'Transaction Overview'!$I$2:$I$517,$A46,'Transaction Overview'!$D$2:$D$517,">0") -> 0 | C46: =SUMIFS('Transaction Overview'!$D$2:$D$517,'Transaction Overview'!$I$2:$I$517,$A46,'Transaction Overview'!$D$2:$D$517,"<0") -> -200 | D46: =B46+C46 -> -200
A47: Transfer to Edgebuilders | B47: =SUMIFS('Transaction Overview'!$D$2:$D$517,'Transaction Overview'!$I$2:$I$517,$A47,'Transaction Overview'!$D$2:$D$517,">0") -> 0 | C47: =SUMIFS('Transaction Overview'!$D$2:$D$517,'Transaction Overview'!$I$2:$I$517,$A47,'Transaction Overview'!$D$2:$D$517,"<0") -> -300 | D47: =B47+C47 -> -300
A48: Transfer to Judd Sol Prop | B48: =SUMIFS('Transaction Overview'!$D$2:$D$517,'Transaction Overview'!$I$2:$I$517,$A48,'Transaction Overview'!$D$2:$D$517,">0") -> 0 | C48: =SUMIFS('Transaction Overview'!$D$2:$D$517,'Transaction Overview'!$I$2:$I$517,$A48,'Transaction Overview'!$D$2:$D$517,"<0") -> -200 | D48: =B48+C48 -> -200
A49: Transfer to MRM | B49: =SUMIFS('Transaction Overview'!$D$2:$D$517,'Transaction Overview'!$I$2:$I$517,$A49,'Transaction Overview'!$D$2:$D$517,">0") -> 0 | C49: =SUMIFS('Transaction Overview'!$D$2:$D$517,'Transaction Overview'!$I$2:$I$517,$A49,'Transaction Overview'!$D$2:$D$517,"<0") -> -600 | D49: =B49+C49 -> -600
...

Sheet Monthly Breakdown
A1: Chase 1168 — DWG Capital Group 2026 Activity
A2: Monthly Breakdown | Jan 2026 – Dec 2026
A4: Category | B4: =DATE(2026,1,1) -> 46023 | C4: =DATE(2026,2,1) -> 46054 | D4: =DATE(2026,3,1) -> 46082 | E4: =DATE(2026,4,1) -> 46113 | F4: =DATE(2026,5,1) -> 46143 | G4: =DATE(2026,6,1) -> 46174 | H4: =DATE(2026,7,1) -> 46204 | I4: =DATE(2026,8,1) -> 46235 | J4: =DATE(2026,9,1) -> 46266 | K4: =DATE(2026,10,1) -> 46296 | L4: =DATE(2026,11,1) -> 46327 | M4: =DATE(2026,12,1) -> 46357 | N4: Total
A5: Deal-Specific
A6: Deal Specific: 260 S Hibbert | B6: =SUMIFS('Transaction Overview'!$D$2:$D$517,'Transaction Overview'!$I$2:$I$517,$A6,'Transaction Overview'!$H$2:$H$517,B$4) -> 0 | C6: =SUMIFS('Transaction Overview'!$D$2:$D$517,'Transaction Overview'!$I$2:$I$517,$A6,'Transaction Overview'!$H$2:$H$517,C$4) -> 20000 | D6: =SUMIFS('Transaction Overview'!$D$2:$D$517,'Transaction Overview'!$I$2:$I$517,$A6,'Transaction Overview'!$H$2:$H$517,D$4) -> 19400 | E6: =SUMIFS('Transaction Overview'!$D$2:$D$517,'Transaction Overview'!$I$2:$I$517,$A6,'Transaction Overview'!$H$2:$H$517,E$4) -> 0 | F6: =SUMIFS('Transaction Overview'!$D$2:$D$517,'Transaction Overview'!$I$2:$I$517,$A6,'Transaction Overview'!$H$2:$H$517,F$4) -> 0 | G6: =SUMIFS('Transaction Overview'!$D$2:$D$517,'Transaction Overview'!$I$2:$I$517,$A6,'Transaction Overview'!$H$2:$H$517,G$4) -> 0 | H6: =SUMIFS('Transaction Overview'!$D$2:$D$517,'Transaction Overview'!$I$2:$I$517,$A6,'Transaction Overview'!$H$2:$H$517,H$4) -> 0 | I6: =SUMIFS('Transaction Overview'!$D$2:$D$517,'Transaction Overview'!$I$2:$I$517,$A6,'Transaction Overview'!$H$2:$H$517,I$4) -> 0 | ... M6: =SUMIFS('Transaction Overview'!$D$2:$D$517,'Transaction Overview'!$I$2:$I$517,$A6,'Transaction Overview'!$H$2:$H$517,M$4) -> 0 | N6: =SUM(B6:M6) -> 39400
A7: Incoming MOAB Mortgage Coverage | B7: =SUMIFS('Transaction Overview'!$D$2:$D$517,'Transaction Overview'!$I$2:$I$517,$A7,'Transaction Overview'!$H$2:$H$517,B$4) -> 0 | C7: =SUMIFS('Transaction Overview'!$D$2:$D$517,'Transaction Overview'!$I$2:$I$517,$A7,'Transaction Overview'!$H$2:$H$517,C$4) -> 8556.41 | D7: =SUMIFS('Transaction Overview'!$D$2:$D$517,'Transaction Overview'!$I$2:$I$517,$A7,'Transaction Overview'!$H$2:$H$517,D$4) -> 8556.41 | E7: =SUMIFS('Transaction Overview'!$D$2:$D$517,'Transaction Overview'!$I$2:$I$517,$A7,'Transaction Overview'!$H$2:$H$517,E$4) -> 8556.41 | F7: =SUMIFS('Transaction Overview'!$D$2:$D$517,'Transaction Overview'!$I$2:$I$517,$A7,'Transaction Overview'!$H$2:$H$517,F$4) -> 8556.41 | G7: =SUMIFS('Transaction Overview'!$D$2:$D$517,'Transaction Overview'!$I$2:$I$517,$A7,'Transaction Overview'!$H$2:$H$517,G$4) -> 8556.41 | H7: =SUMIFS('Transaction Overview'!$D$2:$D$517,'Transaction Overview'!$I$2:$I$517,$A7,'Transaction Overview'!$H$2:$H$517,H$4) -> 0 | I7: =SUMIFS('Transaction Overview'!$D$2:$D$517,'Transaction Overview'!$I$2:$I$517,$A7,'Transaction Overview'!$H$2:$H$517,I$4) -> 0 | ... M7: =SUMIFS('Transaction Overview'!$D$2:$D$517,'Transaction Overview'!$I$2:$I$517,$A7,'Transaction Overview'!$H$2:$H$517,M$4) -> 0 | N7: =SUM(B7:M7) -> 42782.05
A8: Moab E4 Mortgage Payment | B8: =SUMIFS('Transaction Overview'!$D$2:$D$517,'Transaction Overview'!$I$2:$I$517,$A8,'Transaction Overview'!$H$2:$H$517,B$4) -> 0 | C8: =SUMIFS('Transaction Overview'!$D$2:$D$517,'Transaction Overview'!$I$2:$I$517,$A8,'Transaction Overview'!$H$2:$H$517,C$4) -> -4190.21 | D8: =SUMIFS('Transaction Overview'!$D$2:$D$517,'Transaction Overview'!$I$2:$I$517,$A8,'Transaction Overview'!$H$2:$H$517,D$4) -> -4190.21 | E8: =SUMIFS('Transaction Overview'!$D$2:$D$517,'Transaction Overview'!$I$2:$I$517,$A8,'Transaction Overview'!$H$2:$H$517,E$4) -> -4190.21 | F8: =SUMIFS('Transaction Overview'!$D$2:$D$517,'Transaction Overview'!$I$2:$I$517,$A8,'Transaction Overview'!$H$2:$H$517,F$4) -> -4366.2 | G8: =SUMIFS('Transaction Overview'!$D$2:$D$517,'Transaction Overview'!$I$2:$I$517,$A8,'Transaction Overview'!$H$2:$H$517,G$4) -> -4366.2 | H8: =SUMIFS('Transaction Overview'!$D$2:$D$517,'Transaction Overview'!$I$2:$I$517,$A8,'Transaction Overview'!$H$2:$H$517,H$4) -> 0 | I8: =SUMIFS('Transaction Overview'!$D$2:$D$517,'Transaction Overview'!$I$2:$I$517,$A8,'Transaction Overview'!$H$2:$H$517,I$4) -> 0 | ... M8: =SUMIFS('Transaction Overview'!$D$2:$D$517,'Transaction Overview'!$I$2:$I$517,$A8,'Transaction Overview'!$H$2:$H$517,M$4) -> 0 | N8: =SUM(B8:M8) -> -21303.03
A9: Moab E7 Mortgage Payment | B9: =SUMIFS('Transaction Overview'!$D$2:$D$517,'Transaction Overview'!$I$2:$I$517,$A9,'Transaction Overview'!$H$2:$H$517,B$4) -> 0 | C9: =SUMIFS('Transaction Overview'!$D$2:$D$517,'Transaction Overview'!$I$2:$I$517,$A9,'Transaction Overview'!$H$2:$H$517,C$4) -> -4366.2 | D9: =SUMIFS('Transaction Overview'!$D$2:$D$517,'Transaction Overview'!$I$2:$I$517,$A9,'Transaction Overview'!$H$2:$H$517,D$4) -> -4366.2 | E9: =SUMIFS('Transaction Overview'!$D$2:$D$517,'Transaction Overview'!$I$2:$I$517,$A9,'Transaction Overview'!$H$2:$H$517,E$4) -> -4366.2 | F9: =SUMIFS('Transaction Overview'!$D$2:$D$517,'Transaction Overview'!$I$2:$I$517,$A9,'Transaction Overview'!$H$2:$H$517,F$4) -> -4190.21 | G9: =SUMIFS('Transaction Overview'!$D$2:$D$517,'Transaction Overview'!$I$2:$I$517,$A9,'Transaction Overview'!$H$2:$H$517,G$4) -> -4190.21 | H9: =SUMIFS('Transaction Overview'!$D$2:$D$517,'Transaction Overview'!$I$2:$I$517,$A9,'Transaction Overview'!$H$2:$H$517,H$4) -> 0 | I9: =SUMIFS('Transaction Overview'!$D$2:$D$517,'Transaction Overview'!$I$2:$I$517,$A9,'Transaction Overview'!$H$2:$H$517,I$4) -> 0 | ... M9: =SUMIFS('Transaction Overview'!$D$2:$D$517,'Transaction Overview'!$I$2:$I$517,$A9,'Transaction Overview'!$H$2:$H$517,M$4) -> 0 | N9: =SUM(B9:M9) -> -21479.02
A10: Commissions — Incoming
A11: Incoming Commission: MDC | B11: =SUMIFS('Transaction Overview'!$D$2:$D$517,'Transaction Overview'!$I$2:$I$517,$A11,'Transaction Overview'!$H$2:$H$517,B$4) -> 0 | C11: =SUMIFS('Transaction Overview'!$D$2:$D$517,'Transaction Overview'!$I$2:$I$517,$A11,'Transaction Overview'!$H$2:$H$517,C$4) -> 0 | D11: =SUMIFS('Transaction Overview'!$D$2:$D$517,'Transaction Overview'!$I$2:$I$517,$A11,'Transaction Overview'!$H$2:$H$517,D$4) -> 0 | E11: =SUMIFS('Transaction Overview'!$D$2:$D$517,'Transaction Overview'!$I$2:$I$517,$A11,'Transaction Overview'!$H$2:$H$517,E$4) -> 0 | F11: =SUMIFS('Transaction Overview'!$D$2:$D$517,'Transaction Overview'!$I$2:$I$517,$A11,'Transaction Overview'!$H$2:$H$517,F$4) -> 114000 | G11: =SUMIFS('Transaction Overview'!$D$2:$D$517,'Transaction Overview'!$I$2:$I$517,$A11,'Transaction Overview'!$H$2:$H$517,G$4) -> 0 | H11: =SUMIFS('Transaction Overview'!$D$2:$D$517,'Transaction Overview'!$I$2:$I$517,$A11,'Transaction Overview'!$H$2:$H$517,H$4) -> 0 | I11: =SUMIFS('Transaction Overview'!$D$2:$D$517,'Transaction Overview'!$I$2:$I$517,$A11,'Transaction Overview'!$H$2:$H$517,I$4) -> 0 | ... M11: =SUMIFS('Transaction Overview'!$D$2:$D$517,'Transaction Overview'!$I$2:$I$517,$A11,'Transaction Overview'!$H$2:$H$517,M$4) -> 0 | N11: =SUM(B11:M11) -> 114000
A12: Commissions — Outgoing
A13: Hugh Gerhke - MDC Commission | B13: =SUMIFS('Transaction Overview'!$D$2:$D$517,'Transaction Overview'!$I$2:$I$517,$A13,'Transaction Overview'!$H$2:$H$517,B$4) -> 0 | C13: =SUMIFS('Transaction Overview'!$D$2:$D$517,'Transaction Overview'!$I$2:$I$517,$A13,'Transaction Overview'!$H$2:$H$517,C$4) -> 0 | D13: =SUMIFS('Transaction Overview'!$D$2:$D$517,'Transaction Overview'!$I$2:$I$517,$A13,'Transaction Overview'!$H$2:$H$517,D$4) -> 0 | E13: =SUMIFS('Transaction Overview'!$D$2:$D$517,'Transaction Overview'!$I$2:$I$517,$A13,'Transaction Overview'!$H$2:$H$517,E$4) -> 0 | F13: =SUMIFS('Transaction Overview'!$D$2:$D$517,'Transaction Overview'!$I$2:$I$517,$A13,'Transaction Overview'!$H$2:$H$517,F$4) -> -16875 | G13: =SUMIFS('Transaction Overview'!$D$2:$D$517,'Transaction Overview'!$I$2:$I$517,$A13,'Transaction Overview'!$H$2:$H$517,G$4) -> 0 | H13: =SUMIFS('Transaction Overview'!$D$2:$D$517,'Transaction Overview'!$I$2:$I$517,$A13,'Transaction Overview'!$H$2:$H$517,H$4) -> 0 | I13: =SUMIFS('Transaction Overview'!$D$2:$D$517,'Transaction Overview'!$I$2:$I$517,$A13,'Transaction Overview'!$H$2:$H$517,I$4) -> 0 | ... M13: =SUMIFS('Transaction Overview'!$D$2:$D$517,'Transaction Overview'!$I$2:$I$517,$A13,'Transaction Overview'!$H$2:$H$517,M$4) -> 0 | N13: =SUM(B13:M13) -> -16875
A14: Meg Maran - MDC Commission | B14: =SUMIFS('Transaction Overview'!$D$2:$D$517,'Transaction Overview'!$I$2:$I$517,$A14,'Transaction Overview'!$H$2:$H$517,B$4) -> 0 | C14: =SUMIFS('Transaction Overview'!$D$2:$D$517,'Transaction Overview'!$I$2:$I$517,$A14,'Transaction Overview'!$H$2:$H$517,C$4) -> 0 | D14: =SUMIFS('Transaction Overview'!$D$2:$D$517,'Transaction Overview'!$I$2:$I$517,$A14,'Transaction Overview'!$H$2:$H$517,D$4) -> 0 | E14: =SUMIFS('Transaction Overview'!$D$2:$D$517,'Transaction Overview'!$I$2:$I$517,$A14,'Transaction Overview'!$H$2:$H$517,E$4) -> 0 | F14: =SUMIFS('Transaction Overview'!$D$2:$D$517,'Transaction Overview'!$I$2:$I$517,$A14,'Transaction Overview'!$H$2:$H$517,F$4) -> -1500 | G14: =SUMIFS('Transaction Overview'!$D$2:$D$517,'Transaction Overview'!$I$2:$I$517,$A14,'Transaction Overview'!$H$2:$H$517,G$4) -> 0 | H14: =SUMIFS('Transaction Overview'!$D$2:$D$517,'Transaction Overview'!$I$2:$I$517,$A14,'Transaction Overview'!$H$2:$H$517,H$4) -> 0 | I14: =SUMIFS('Transaction Overview'!$D$2:$D$517,'Transaction Overview'!$I$2:$I$517,$A14,'Transaction Overview'!$H$2:$H$517,I$4) -> 0 | ... M14: =SUMIFS('Transaction Overview'!$D$2:$D$517,'Transaction Overview'!$I$2:$I$517,$A14,'Transaction Overview'!$H$2:$H$517,M$4) -> 0 | N14: =SUM(B14:M14) -> -1500
A15: MAG Pass-Through
A16: Due to Andrew – MAG Pass-Through 30% | B16: =SUMIFS('Transaction Overview'!$D$2:$D$517,'Transaction Overview'!$I$2:$I$517,$A16,'Transaction Overview'!$H$2:$H$517,B$4) -> 0 | C16: =SUMIFS('Transaction Overview'!$D$2:$D$517,'Transaction Overview'!$I$2:$I$517,$A16,'Transaction Overview'!$H$2:$H$517,C$4) -> -177000 | D16: =SUMIFS('Transaction Overview'!$D$2:$D$517,'Transaction Overview'!$I$2:$I$517,$A16,'Transaction Overview'!$H$2:$H$517,D$4) -> 0 | E16: =SUMIFS('Transaction Overview'!$D$2:$D$517,'Transaction Overview'!$I$2:$I$517,$A16,'Transaction Overview'!$H$2:$H$517,E$4) -> 0 | F16: =SUMIFS('Transaction Overview'!$D$2:$D$517,'Transaction Overview'!$I$2:$I$517,$A16,'Transaction Overview'!$H$2:$H$517,F$4) -> 0 | G16: =SUMIFS('Transaction Overview'!$D$2:$D$517,'Transaction Overview'!$I$2:$I$517,$A16,'Transaction Overview'!$H$2:$H$517,G$4) -> 0 | H16: =SUMIFS('Transaction Overview'!$D$2:$D$517,'Transaction Overview'!$I$2:$I$517,$A16,'Transaction Overview'!$H$2:$H$517,H$4) -> 0 | I16: =SUMIFS('Transaction Overview'!$D$2:$D$517,'Transaction Overview'!$I$2:$I$517,$A16,'Transaction Overview'!$H$2:$H$517,I$4) -> 0 | ... M16: =SUMIFS('Transaction Overview'!$D$2:$D$517,'Transaction Overview'!$I$2:$I$517,$A16,'Transaction Overview'!$H$2:$H$517,M$4) -> 0 | N16: =SUM(B16:M16) -> -177000
A17: Due to Dax – MAG Pass-Through 70% | B17: =SUMIFS('Transaction Overview'!$D$2:$D$517,'Transaction Overview'!$I$2:$I$517,$A17,'Transaction Overview'!$H$2:$H$517,B$4) -> 0 | C17: =SUMIFS('Transaction Overview'!$D$2:$D$517,'Transaction Overview'!$I$2:$I$517,$A17,'Transaction Overview'!$H$2:$H$517,C$4) -> -413000 | D17: =SUMIFS('Transaction Overview'!$D$2:$D$517,'Transaction Overview'!$I$2:$I$517,$A17,'Transaction Overview'!$H$2:$H$517,D$4) -> 0 | E17: =SUMIFS('Transaction Overview'!$D$2:$D$517,'Transaction Overview'!$I$2:$I$517,$A17,'Transaction Overview'!$H$2:$H$517,E$4) -> 0 | F17: =SUMIFS('Transaction Overview'!$D$2:$D$517,'Transaction Overview'!$I$2:$I$517,$A17,'Transaction Overview'!$H$2:$H$517,F$4) -> 0 | G17: =SUMIFS('Transaction Overview'!$D$2:$D$517,'Transaction Overview'!$I$2:$I$517,$A17,'Transaction Overview'!$H$2:$H$517,G$4) -> 0 | H17: =SUMIFS('Transaction Overview'!$D$2:$D$517,'Transaction Overview'!$I$2:$I$517,$A17,'Transaction Overview'!$H$2:$H$517,H$4) -> 0 | I17: =SUMIFS('Transaction Overview'!$D$2:$D$517,'Transaction Overview'!$I$2:$I$517,$A17,'Transaction Overview'!$H$2:$H$517,I$4) -> 0 | ... M17: =SUMIFS('Transaction Overview'!$D$2:$D$517,'Transaction Overview'!$I$2:$I$517,$A17,'Transaction Overview'!$H$2:$H$517,M$4) -> 0 | N17: =SUM(B17:M17) -> -413000
A18: MAG Capital Partners Pass-Through Wire – 70/30 Split | B18: =SUMIFS('Transaction Overview'!$D$2:$D$517,'Transaction Overview'!$I$2:$I$517,$A18,'Transaction Overview'!$H$2:$H$517,B$4) -> 0 | C18: =SUMIFS('Transaction Overview'!$D$2:$D$517,'Transaction Overview'!$I$2:$I$517,$A18,'Transaction Overview'!$H$2:$H$517,C$4) -> 600000 | D18: =SUMIFS('Transaction Overview'!$D$2:$D$517,'Transaction Overview'!$I$2:$I$517,$A18,'Transaction Overview'!$H$2:$H$517,D$4) -> 0 | E18: =SUMIFS('Transaction Overview'!$D$2:$D$517,'Transaction Overview'!$I$2:$I$517,$A18,'Transaction Overview'!$H$2:$H$517,E$4) -> 0 | F18: =SUMIFS('Transaction Overview'!$D$2:$D$517,'Transaction Overview'!$I$2:$I$517,$A18,'Transaction Overview'!$H$2:$H$517,F$4) -> 0 | G18: =SUMIFS('Transaction Overview'!$D$2:$D$517,'Transaction Overview'!$I$2:$I$517,$A18,'Transaction Overview'!$H$2:$H$517,G$4) -> 0 | H18: =SUMIFS('Transaction Overview'!$D$2:$D$517,'Transaction Overview'!$I$2:$I$517,$A18,'Transaction Overview'!$H$2:$H$517,H$4) -> 0 | I18: =SUMIFS('Transaction Overview'!$D$2:$D$517,'Transaction Overview'!$I$2:$I$517,$A18,'Transaction Overview'!$H$2:$H$517,I$4) -> 0 | ... M18: =SUMIFS('Transaction Overview'!$D$2:$D$517,'Transaction Overview'!$I$2:$I$517,$A18,'Transaction Overview'!$H$2:$H$517,M$4) -> 0 | N18: =SUM(B18:M18) -> 600000
A19: Poseidon Asset Group
A20: Poseidon Asset Group (Incoming) | B20: =SUMIFS('Transaction Overview'!$D$2:$D$517,'Transaction Overview'!$I$2:$I$517,$A20,'Transaction Overview'!$H$2:$H$517,B$4) -> 70000 | C20: =SUMIFS('Transaction Overview'!$D$2:$D$517,'Transaction Overview'!$I$2:$I$517,$A20,'Transaction Overview'!$H$2:$H$517,C$4) -> 48556.41 | D20: =SUMIFS('Transaction Overview'!$D$2:$D$517,'Transaction Overview'!$I$2:$I$517,$A20,'Transaction Overview'!$H$2:$H$517,D$4) -> 55000 | E20: =SUMIFS('Transaction Overview'!$D$2:$D$517,'Transaction Overview'!$I$2:$I$517,$A20,'Transaction Overview'!$H$2:$H$517,E$4) -> 35000 | F20: =SUMIFS('Transaction Overview'!$D$2:$D$517,'Transaction Overview'!$I$2:$I$517,$A20,'Transaction Overview'!$H$2:$H$517,F$4) -> 0 | G20: =SUMIFS('Transaction Overview'!$D$2:$D$517,'Transaction Overview'!$I$2:$I$517,$A20,'Transaction Overview'!$H$2:$H$517,G$4) -> 30000 | H20: =SUMIFS('Transaction Overview'!$D$2:$D$517,'Transaction Overview'!$I$2:$I$517,$A20,'Transaction Overview'!$H$2:$H$517,H$4) -> 0 | I20: =SUMIFS('Transaction Overview'!$D$2:$D$517,'Transaction Overview'!$I$2:$I$517,$A20,'Transaction Overview'!$H$2:$H$517,I$4) -> 0 | ... M20: =SUMIFS('Transaction Overview'!$D$2:$D$517,'Transaction Overview'!$I$2:$I$517,$A20,'Transaction Overview'!$H$2:$H$517,M$4) -> 0 | N20: =SUM(B20:M20) -> 238556.41
A21: Poseidon Asset Group (Outgoing) | B21: =SUMIFS('Transaction Overview'!$D$2:$D$517,'Transaction Overview'!$I$2:$I$517,$A21,'Transaction Overview'!$H$2:$H$517,B$4) -> 0 | C21: =SUMIFS('Transaction Overview'!$D$2:$D$517,'Transaction Overview'!$I$2:$I$517,$A21,'Transaction Overview'!$H$2:$H$517,C$4) -> -8556.41 | D21: =SUMIFS('Transaction Overview'!$D$2:$D$517,'Transaction Overview'!$I$2:$I$517,$A21,'Transaction Overview'!$H$2:$H$517,D$4) -> 0 | E21: =SUMIFS('Transaction Overview'!$D$2:$D$517,'Transaction Overview'!$I$2:$I$517,$A21,'Transaction Overview'!$H$2:$H$517,E$4) -> 0 | F21: =SUMIFS('Transaction Overview'!$D$2:$D$517,'Transaction Overview'!$I$2:$I$517,$A21,'Transaction Overview'!$H$2:$H$517,F$4) -> 0 | G21: =SUMIFS('Transaction Overview'!$D$2:$D$517,'Transaction Overview'!$I$2:$I$517,$A21,'Transaction Overview'!$H$2:$H$517,G$4) -> 0 | H21: =SUMIFS('Transaction Overview'!$D$2:$D$517,'Transaction Overview'!$I$2:$I$517,$A21,'Transaction Overview'!$H$2:$H$517,H$4) -> 0 | I21: =SUMIFS('Transaction Overview'!$D$2:$D$517,'Transaction Overview'!$I$2:$I$517,$A21,'Transaction Overview'!$H$2:$H$517,I$4) -> 0 | ... M21: =SUMIFS('Transaction Overview'!$D$2:$D$517,'Transaction Overview'!$I$2:$I$517,$A21,'Transaction Overview'!$H$2:$H$517,M$4) -> 0 | N21: =SUM(B21:M21) -> -8556.41
A22: Intercompany & Savings Transfers
A23: Transfer to DWG Capital Group_Costar | B23: =SUMIFS('Transaction Overview'!$D$2:$D$517,'Transaction Overview'!$I$2:$I$517,$A23,'Transaction Overview'!$H$2:$H$517,B$4) -> -5000 | C23: =SUMIFS('Transaction Overview'!$D$2:$D$517,'Transaction Overview'!$I$2:$I$517,$A23,'Transaction Overview'!$H$2:$H$517,C$4) -> 0 | D23: =SUMIFS('Transaction Overview'!$D$2:$D$517,'Transaction Overview'!$I$2:$I$517,$A23,'Transaction Overview'!$H$2:$H$517,D$4) -> 0 | E23: =SUMIFS('Transaction Overview'!$D$2:$D$517,'Transaction Overview'!$I$2:$I$517,$A23,'Transaction Overview'!$H$2:$H$517,E$4) -> 0 | F23: =SUMIFS('Transaction Overview'!$D$2:$D$517,'Transaction Overview'!$I$2:$I$517,$A23,'Transaction Overview'!$H$2:$H$517,F$4) -> -7956.18 | G23: =SUMIFS('Transaction Overview'!$D$2:$D$517,'Transaction Overview'!$I$2:$I$517,$A23,'Transaction Overview'!$H$2:$H$517,G$4) -> 0 | H23: =SUMIFS('Transaction Overview'!$D$2:$D$517,'Transaction Overview'!$I$2:$I$517,$A23,'Transaction Overview'!$H$2:$H$517,H$4) -> 0 | I23: =SUMIFS('Transaction Overview'!$D$2:$D$517,'Transaction Overview'!$I$2:$I$517,$A23,'Transaction Overview'!$H$2:$H$517,I$4) -> 0 | ... M23: =SUMIFS('Transaction Overview'!$D$2:$D$517,'Transaction Overview'!$I$2:$I$517,$A23,'Transaction Overview'!$H$2:$H$517,M$4) -> 0 | N23: =SUM(B23:M23) -> -12956.18
A24: Transfer to DWG Savings | B24: =SUMIFS('Transaction Overview'!$D$2:$D$517,'Transaction Overview'!$I$2:$I$517,$A24,'Transaction Overview'!$H$2:$H$517,B$4) -> -1142 | C24: =SUMIFS('Transaction Overview'!$D$2:$D$517,'Transaction Overview'!$I$2:$I$517,$A24,'Transaction Overview'!$H$2:$H$517,C$4) -> 0 | D24: =SUMIFS('Transaction Overview'!$D$2:$D$517,'Transaction Overview'!$I$2:$I$517,$A24,'Transaction Overview'!$H$2:$H$517,D$4) -> -1000 | E24: =SUMIFS('Transaction Overview'!$D$2:$D$517,'Transaction Overview'!$I$2:$I$517,$A24,'Transaction Overview'!$H$2:$H$517,E$4) -> -100 | F24: =SUMIFS('Transaction Overview'!$D$2:$D$517,'Transaction Overview'!$I$2:$I$517,$A24,'Transaction Overview'!$H$2:$H$517,F$4) -> -2500 | G24: =SUMIFS('Transaction Overview'!$D$2:$D$517,'Transaction Overview'!$I$2:$I$517,$A24,'Transaction Overview'!$H$2:$H$517,G$4) -> 0 | H24: =SUMIFS('Transaction Overview'!$D$2:$D$517,'Transaction Overview'!$I$2:$I$517,$A24,'Transaction Overview'!$H$2:$H$517,H$4) -> 0 | I24: =SUMIFS('Transaction Overview'!$D$2:$D$517,'Transaction Overview'!$I$2:$I$517,$A24,'Transaction Overview'!$H$2:$H$517,I$4) -> 0 | ... M24: =SUMIFS('Transaction Overview'!$D$2:$D$517,'Transaction Overview'!$I$2:$I$517,$A24,'Transaction Overview'!$H$2:$H$517,M$4) -> 0 | N24: =SUM(B24:M24) -> -4742
A25: Transfer to DWG Capital Partners | B25: =SUMIFS('Transaction Overview'!$D$2:$D$517,'Transaction Overview'!$I$2:$I$517,$A25,'Transaction Overview'!$H$2:$H$517,B$4) -> 0 | C25: =SUMIFS('Transaction Overview'!$D$2:$D$517,'Transaction Overview'!$I$2:$I$517,$A25,'Transaction Overview'!$H$2:$H$517,C$4) -> 0 | D25: =SUMIFS('Transaction Overview'!$D$2:$D$517,'Transaction Overview'!$I$2:$I$517,$A25,'Transaction Overview'!$H$2:$H$517,D$4) -> 0 | E25: =SUMIFS('Transaction Overview'!$D$2:$D$517,'Transaction Overview'!$I$2:$I$517,$A25,'Transaction Overview'!$H$2:$H$517,E$4) -> 0 | F25: =SUMIFS('Transaction Overview'!$D$2:$D$517,'Transaction Overview'!$I$2:$I$517,$A25,'Transaction Overview'!$H$2:$H$517,F$4) -> -5000 | G25: =SUMIFS('Transaction Overview'!$D$2:$D$517,'Transaction Overview'!$I$2:$I$517,$A25,'Transaction Overview'!$H$2:$H$517,G$4) -> 0 | H25: =SUMIFS('Transaction Overview'!$D$2:$D$517,'Transaction Overview'!$I$2:$I$517,$A25,'Transaction Overview'!$H$2:$H$517,H$4) -> 0 | I25: =SUMIFS('Transaction Overview'!$D$2:$D$517,'Transaction Overview'!$I$2:$I$517,$A25,'Transaction Overview'!$H$2:$H$517,I$4) -> 0 | ... M25: =SUMIFS('Transaction Overview'!$D$2:$D$517,'Transaction Overview'!$I$2:$I$517,$A25,'Transaction Overview'!$H$2:$H$517,M$4) -> 0 | N25: =SUM(B25:M25) -> -5000
A26: Transfer to DWG Holdings | B26: =SUMIFS('Transaction Overview'!$D$2:$D$517,'Transaction Overview'!$I$2:$I$517,$A26,'Transaction Overview'!$H$2:$H$517,B$4) -> 0 | C26: =SUMIFS('Transaction Overview'!$D$2:$D$517,'Transaction Overview'!$I$2:$I$517,$A26,'Transaction Overview'!$H$2:$H$517,C$4) -> 0 | D26: =SUMIFS('Transaction Overview'!$D$2:$D$517,'Transaction Overview'!$I$2:$I$517,$A26,'Transaction Overview'!$H$2:$H$517,D$4) -> 0 | E26: =SUMIFS('Transaction Overview'!$D$2:$D$517,'Transaction Overview'!$I$2:$I$517,$A26,'Transaction Overview'!$H$2:$H$517,E$4) -> 0 | F26: =SUMIFS('Transaction Overview'!$D$2:$D$517,'Transaction Overview'!$I$2:$I$517,$A26,'Transaction Overview'!$H$2:$H$517,F$4) -> 0 | G26: =SUMIFS('Transaction Overview'!$D$2:$D$517,'Transaction Overview'!$I$2:$I$517,$A26,'Transaction Overview'!$H$2:$H$517,G$4) -> -200 | H26: =SUMIFS('Transaction Overview'!$D$2:$D$517,'Transaction Overview'!$I$2:$I$517,$A26,'Transaction Overview'!$H$2:$H$517,H$4) -> 0 | I26: =SUMIFS('Transaction Overview'!$D$2:$D$517,'Transaction Overview'!$I$2:$I$517,$A26,'Transaction Overview'!$H$2:$H$517,I$4) -> 0 | ... M26: =SUMIFS('Transaction Overview'!$D$2:$D$517,'Transaction Overview'!$I$2:$I$517,$A26,'Transaction Overview'!$H$2:$H$517,M$4) -> 0 | N26: =SUM(B26:M26) -> -200
A27: Transfer to Edgebuilders | B27: =SUMIFS('Transaction Overview'!$D$2:$D$517,'Transaction Overview'!$I$2:$I$517,$A27,'Transaction Overview'!$H$2:$H$517,B$4) -> 0 | C27: =SUMIFS('Transaction Overview'!$D$2:$D$517,'Transaction Overview'!$I$2:$I$517,$A27,'Transaction Overview'!$H$2:$H$517,C$4) -> 0 | D27: =SUMIFS('Transaction Overview'!$D$2:$D$517,'Transaction Overview'!$I$2:$I$517,$A27,'Transaction Overview'!$H$2:$H$517,D$4) -> 0 | E27: =SUMIFS('Transaction Overview'!$D$2:$D$517,'Transaction Overview'!$I$2:$I$517,$A27,'Transaction Overview'!$H$2:$H$517,E$4) -> 0 | F27: =SUMIFS('Transaction Overview'!$D$2:$D$517,'Transaction Overview'!$I$2:$I$517,$A27,'Transaction Overview'!$H$2:$H$517,F$4) -> 0 | G27: =SUMIFS('Transaction Overview'!$D$2:$D$517,'Transaction Overview'!$I$2:$I$517,$A27,'Transaction Overview'!$H$2:$H$517,G$4) -> -300 | H27: =SUMIFS('Transaction Overview'!$D$2:$D$517,'Transaction Overview'!$I$2:$I$517,$A27,'Transaction Overview'!$H$2:$H$517,H$4) -> 0 | I27: =SUMIFS('Transaction Overview'!$D$2:$D$517,'Transaction Overview'!$I$2:$I$517,$A27,'Transaction Overview'!$H$2:$H$517,I$4) -> 0 | ... M27: =SUMIFS('Transaction Overview'!$D$2:$D$517,'Transaction Overview'!$I$2:$I$517,$A27,'Transaction Overview'!$H$2:$H$517,M$4) -> 0 | N27: =SUM(B27:M27) -> -300
A28: Transfer to Judd Sol Prop | B28: =SUMIFS('Transaction Overview'!$D$2:$D$517,'Transaction Overview'!$I$2:$I$517,$A28,'Transaction Overview'!$H$2:$H$517,B$4) -> 0 | C28: =SUMIFS('Transaction Overview'!$D$2:$D$517,'Transaction Overview'!$I$2:$I$517,$A28,'Transaction Overview'!$H$2:$H$517,C$4) -> 0 | D28: =SUMIFS('Transaction Overview'!$D$2:$D$517,'Transaction Overview'!$I$2:$I$517,$A28,'Transaction Overview'!$H$2:$H$517,D$4) -> -200 | E28: =SUMIFS('Transaction Overview'!$D$2:$D$517,'Transaction Overview'!$I$2:$I$517,$A28,'Transaction Overview'!$H$2:$H$517,E$4) -> 0 | F28: =SUMIFS('Transaction Overview'!$D$2:$D$517,'Transaction Overview'!$I$2:$I$517,$A28,'Transaction Overview'!$H$2:$H$517,F$4) -> 0 | G28: =SUMIFS('Transaction Overview'!$D$2:$D$517,'Transaction Overview'!$I$2:$I$517,$A28,'Transaction Overview'!$H$2:$H$517,G$4) -> 0 | H28: =SUMIFS('Transaction Overview'!$D$2:$D$517,'Transaction Overview'!$I$2:$I$517,$A28,'Transaction Overview'!$H$2:$H$517,H$4) -> 0 | I28: =SUMIFS('Transaction Overview'!$D$2:$D$517,'Transaction Overview'!$I$2:$I$517,$A28,'Transaction Overview'!$H$2:$H$517,I$4) -> 0 | ... M28: =SUMIFS('Transaction Overview'!$D$2:$D$517,'Transaction Overview'!$I$2:$I$517,$A28,'Transaction Overview'!$H$2:$H$517,M$4) -> 0 | N28: =SUM(B28:M28) -> -200
A29: Transfer to MRM | B29: =SUMIFS('Transaction Overview'!$D$2:$D$517,'Transaction Overview'!$I$2:$I$517,$A29,'Transaction Overview'!$H$2:$H$517,B$4) -> 0 | C29: =SUMIFS('Transaction Overview'!$D$2:$D$517,'Transaction Overview'!$I$2:$I$517,$A29,'Transaction Overview'!$H$2:$H$517,C$4) -> 0 | D29: =SUMIFS('Transaction Overview'!$D$2:$D$517,'Transaction Overview'!$I$2:$I$517,$A29,'Transaction Overview'!$H$2:$H$517,D$4) -> 0 | E29: =SUMIFS('Transaction Overview'!$D$2:$D$517,'Transaction Overview'!$I$2:$I$517,$A29,'Transaction Overview'!$H$2:$H$517,E$4) -> 0 | F29: =SUMIFS('Transaction Overview'!$D$2:$D$517,'Transaction Overview'!$I$2:$I$517,$A29,'Transaction Overview'!$H$2:$H$517,F$4) -> 0 | G29: =SUMIFS('Transaction Overview'!$D$2:$D$517,'Transaction Overview'!$I$2:$I$517,$A29,'Transaction Overview'!$H$2:$H$517,G$4) -> -600 | H29: =SUMIFS('Transaction Overview'!$D$2:$D$517,'Transaction Overview'!$I$2:$I$517,$A29,'Transaction Overview'!$H$2:$H$517,H$4) -> 0 | I29: =SUMIFS('Transaction Overview'!$D$2:$D$517,'Transaction Overview'!$I$2:$I$517,$A29,'Transaction Overview'!$H$2:$H$517,I$4) -> 0 | ... M29: =SUMIFS('Transaction Overview'!$D$2:$D$517,'Transaction Overview'!$I$2:$I$517,$A29,'Transaction Overview'!$H$2:$H$517,M$4) -> 0 | N29: =SUM(B29:M29) -> -600
A30: Transfer to SPF | B30: =SUMIFS('Transaction Overview'!$D$2:$D$517,'Transaction Overview'!$I$2:$I$517,$A30,'Transaction Overview'!$H$2:$H$517,B$4) -> -200 | C30: =SUMIFS('Transaction Overview'!$D$2:$D$517,'Transaction Overview'!$I$2:$I$517,$A30,'Transaction Overview'!$H$2:$H$517,C$4) -> 0 | D30: =SUMIFS('Transaction Overview'!$D$2:$D$517,'Transaction Overview'!$I$2:$I$517,$A30,'Transaction Overview'!$H$2:$H$517,D$4) -> 0 | E30: =SUMIFS('Transaction Overview'!$D$2:$D$517,'Transaction Overview'!$I$2:$I$517,$A30,'Transaction Overview'!$H$2:$H$517,E$4) -> 0 | F30: =SUMIFS('Transaction Overview'!$D$2:$D$517,'Transaction Overview'!$I$2:$I$517,$A30,'Transaction Overview'!$H$2:$H$517,F$4) -> 0 | G30: =SUMIFS('Transaction Overview'!$D$2:$D$517,'Transaction Overview'!$I$2:$I$517,$A30,'Transaction Overview'!$H$2:$H$517,G$4) -> 0 | H30: =SUMIFS('Transaction Overview'!$D$2:$D$517,'Transaction Overview'!$I$2:$I$517,$A30,'Transaction Overview'!$H$2:$H$517,H$4) -> 0 | I30: =SUMIFS('Transaction Overview'!$D$2:$D$517,'Transaction Overview'!$I$2:$I$517,$A30,'Transaction Overview'!$H$2:$H$517,I$4) -> 0 | ... M30: =SUMIFS('Transaction Overview'!$D$2:$D$517,'Transaction Overview'!$I$2:$I$517,$A30,'Transaction Overview'!$H$2:$H$517,M$4) -> 0 | N30: =SUM(B30:M30) -> -200
A31: Transfer to TGAIF Fund | B31: =SUMIFS('Transaction Overview'!$D$2:$D$517,'Transaction Overview'!$I$2:$I$517,$A31,'Transaction Overview'!$H$2:$H$517,B$4) -> 0 | C31: =SUMIFS('Transaction Overview'!$D$2:$D$517,'Transaction Overview'!$I$2:$I$517,$A31,'Transaction Overview'!$H$2:$H$517,C$4) -> 0 | D31: =SUMIFS('Transaction Overview'!$D$2:$D$517,'Transaction Overview'!$I$2:$I$517,$A31,'Transaction Overview'!$H$2:$H$517,D$4) -> 0 | E31: =SUMIFS('Transaction Overview'!$D$2:$D$517,'Transaction Overview'!$I$2:$I$517,$A31,'Transaction Overview'!$H$2:$H$517,E$4) -> 0 | F31: =SUMIFS('Transaction Overview'!$D$2:$D$517,'Transaction Overview'!$I$2:$I$517,$A31,'Transaction Overview'!$H$2:$H$517,F$4) -> -300 | G31: =SUMIFS('Transaction Overview'!$D$2:$D$517,'Transaction Overview'!$I$2:$I$517,$A31,'Transaction Overview'!$H$2:$H$517,G$4) -> 0 | H31: =SUMIFS('Transaction Overview'!$D$2:$D$517,'Transaction Overview'!$I$2:$I$517,$A31,'Transaction Overview'!$H$2:$H$517,H$4) -> 0 | I31: =SUMIFS('Transaction Overview'!$D$2:$D$517,'Transaction Overview'!$I$2:$I$517,$A31,'Transaction Overview'!$H$2:$H$517,I$4) -> 0 | ... M31: =SUMIFS('Transaction Overview'!$D$2:$D$517,'Transaction Overview'!$I$2:$I$517,$A31,'Transaction Overview'!$H$2:$H$517,M$4) -> 0 | N31: =SUM(B31:M31) -> -300
A32: Transfer to Theut Glass | B32: =SUMIFS('Transaction Overview'!$D$2:$D$517,'Transaction Overview'!$I$2:$I$517,$A32,'Transaction Overview'!$H$2:$H$517,B$4) -> -300 | C32: =SUMIFS('Transaction Overview'!$D$2:$D$517,'Transaction Overview'!$I$2:$I$517,$A32,'Transaction Overview'!$H$2:$H$517,C$4) -> 0 | D32: =SUMIFS('Transaction Overview'!$D$2:$D$517,'Transaction Overview'!$I$2:$I$517,$A32,'Transaction Overview'!$H$2:$H$517,D$4) -> 0 | E32: =SUMIFS('Transaction Overview'!$D$2:$D$517,'Transaction Overview'!$I$2:$I$517,$A32,'Transaction Overview'!$H$2:$H$517,E$4) -> -400 | F32: =SUMIFS('Transaction Overview'!$D$2:$D$517,'Transaction Overview'!$I$2:$I$517,$A32,'Transaction Overview'!$H$2:$H$517,F$4) -> 0 | G32: =SUMIFS('Transaction Overview'!$D$2:$D$517,'Transaction Overview'!$I$2:$I$517,$A32,'Transaction Overview'!$H$2:$H$517,G$4) -> 0 | H32: =SUMIFS('Transaction Overview'!$D$2:$D$517,'Transaction Overview'!$I$2:$I$517,$A32,'Transaction Overview'!$H$2:$H$517,H$4) -> 0 | I32: =SUMIFS('Transaction Overview'!$D$2:$D$517,'Transaction Overview'!$I$2:$I$517,$A32,'Transaction Overview'!$H$2:$H$517,I$4) -> 0 | ... M32: =SUMIFS('Transaction Overview'!$D$2:$D$517,'Transaction Overview'!$I$2:$I$517,$A32,'Transaction Overview'!$H$2:$H$517,M$4) -> 0 | N32: =SUM(B32:M32) -> -700
A33: Payroll & Contractors
A34: Andres Alarcon Payroll | B34: =SUMIFS('Transaction Overview'!$D$2:$D$517,'Transaction Overview'!$I$2:$I$517,$A34,'Transaction Overview'!$H$2:$H$517,B$4) -> -1510 | C34: =SUMIFS('Transaction Overview'!$D$2:$D$517,'Transaction Overview'!$I$2:$I$517,$A34,'Transaction Overview'!$H$2:$H$517,C$4) -> -1510 | D34: =SUMIFS('Transaction Overview'!$D$2:$D$517,'Transaction Overview'!$I$2:$I$517,$A34,'Transaction Overview'!$H$2:$H$517,D$4) -> -1510 | E34: =SUMIFS('Transaction Overview'!$D$2:$D$517,'Transaction Overview'!$I$2:$I$517,$A34,'Transaction Overview'!$H$2:$H$517,E$4) -> -1510 | F34: =SUMIFS('Transaction Overview'!$D$2:$D$517,'Transaction Overview'!$I$2:$I$517,$A34,'Transaction Overview'!$H$2:$H$517,F$4) -> -1510 | G34: =SUMIFS('Transaction Overview'!$D$2:$D$517,'Transaction Overview'!$I$2:$I$517,$A34,'Transaction Overview'!$H$2:$H$517,G$4) -> -755 | H34: =SUMIFS('Transaction Overview'!$D$2:$D$517,'Transaction Overview'!$I$2:$I$517,$A34,'Transaction Overview'!$H$2:$H$517,H$4) -> 0 | I34: =SUMIFS('Transaction Overview'!$D$2:$D$517,'Transaction Overview'!$I$2:$I$517,$A34,'Transaction Overview'!$H$2:$H$517,I$4) -> 0 | ... M34: =SUMIFS('Transaction Overview'!$D$2:$D$517,'Transaction Overview'!$I$2:$I$517,$A34,'Transaction Overview'!$H$2:$H$517,M$4) -> 0 | N34: =SUM(B34:M34) -> -8305
A35: Chase Hall - Payroll | B35: =SUMIFS('Transaction Overview'!$D$2:$D$517,'Transaction Overview'!$I$2:$I$517,$A35,'Transaction Overview'!$H$2:$H$517,B$4) -> 0 | C35: =SUMIFS('Transaction Overview'!$D$2:$D$517,'Transaction Overview'!$I$2:$I$517,$A35,'Transaction Overview'!$H$2:$H$517,C$4) -> -3500 | D35: =SUMIFS('Transaction Overview'!$D$2:$D$517,'Transaction Overview'!$I$2:$I$517,$A35,'Transaction Overview'!$H$2:$H$517,D$4) -> -3500 | E35: =SUMIFS('Transaction Overview'!$D$2:$D$517,'Transaction Overview'!$I$2:$I$517,$A35,'Transaction Overview'!$H$2:$H$517,E$4) -> -10500 | F35: =SUMIFS('Transaction Overview'!$D$2:$D$517,'Transaction Overview'!$I$2:$I$517,$A35,'Transaction Overview'!$H$2:$H$517,F$4) -> -7000 | G35: =SUMIFS('Transaction Overview'!$D$2:$D$517,'Transaction Overview'!$I$2:$I$517,$A35,'Transaction Overview'!$H$2:$H$517,G$4) -> -3500 | H35: =SUMIFS('Transaction Overview'!$D$2:$D$517,'Transaction Overview'!$I$2:$I$517,$A35,'Transaction Overview'!$H$2:$H$517,H$4) -> 0 | I35: =SUMIFS('Transaction Overview'!$D$2:$D$517,'Transaction Overview'!$I$2:$I$517,$A35,'Transaction Overview'!$H$2:$H$517,I$4) -> 0 | ... M35: =SUMIFS('Transaction Overview'!$D$2:$D$517,'Transaction Overview'!$I$2:$I$517,$A35,'Transaction Overview'!$H$2:$H$517,M$4) -> 0 | N35: =SUM(B35:M35) -> -28000
A36: DWG HR | B36: =SUMIFS('Transaction Overview'!$D$2:$D$517,'Transaction Overview'!$I$2:$I$517,$A36,'Transaction Overview'!$H$2:$H$517,B$4) -> -937.28 | C36: =SUMIFS('Transaction Overview'!$D$2:$D$517,'Transaction Overview'!$I$2:$I$517,$A36,'Transaction Overview'!$H$2:$H$517,C$4) -> -23.34 | D36: =SUMIFS('Transaction Overview'!$D$2:$D$517,'Transaction Overview'!$I$2:$I$517,$A36,'Transaction Overview'!$H$2:$H$517,D$4) -> -125.69 | E36: =SUMIFS('Transaction Overview'!$D$2:$D$517,'Transaction Overview'!$I$2:$I$517,$A36,'Transaction Overview'!$H$2:$H$517,E$4) -> 0 | F36: =SUMIFS('Transaction Overview'!$D$2:$D$517,'Transaction Overview'!$I$2:$I$517,$A36,'Transaction Overview'!$H$2:$H$517,F$4) -> 0 | G36: =SUMIFS('Transaction Overview'!$D$2:$D$517,'Transaction Overview'!$I$2:$I$517,$A36,'Transaction Overview'!$H$2:$H$517,G$4) -> 0 | H36: =SUMIFS('Transaction Overview'!$D$2:$D$517,'Transaction Overview'!$I$2:$I$517,$A36,'Transaction Overview'!$H$2:$H$517,H$4) -> 0 | I36: =SUMIFS('Transaction Overview'!$D$2:$D$517,'Transaction Overview'!$I$2:$I$517,$A36,'Transaction Overview'!$H$2:$H$517,I$4) -> 0 | ... M36: =SUMIFS('Transaction Overview'!$D$2:$D$517,'Transaction Overview'!$I$2:$I$517,$A36,'Transaction Overview'!$H$2:$H$517,M$4) -> 0 | N36: =SUM(B36:M36) -> -1086.31
A37: Mike Paytonjian - Payroll | B37: =SUMIFS('Transaction Overview'!$D$2:$D$517,'Transaction Overview'!$I$2:$I$517,$A37,'Transaction Overview'!$H$2:$H$517,B$4) -> -7000 | C37: =SUMIFS('Transaction Overview'!$D$2:$D$517,'Transaction Overview'!$I$2:$I$517,$A37,'Transaction Overview'!$H$2:$H$517,C$4) -> -7000 | D37: =SUMIFS('Transaction Overview'!$D$2:$D$517,'Transaction Overview'!$I$2:$I$517,$A37,'Transaction Overview'!$H$2:$H$517,D$4) -> -8750 | E37: =SUMIFS('Transaction Overview'!$D$2:$D$517,'Transaction Overview'!$I$2:$I$517,$A37,'Transaction Overview'!$H$2:$H$517,E$4) -> -7000 | F37: =SUMIFS('Transaction Overview'!$D$2:$D$517,'Transaction Overview'!$I$2:$I$517,$A37,'Transaction Overview'!$H$2:$H$517,F$4) -> -7500 | G37: =SUMIFS('Transaction Overview'!$D$2:$D$517,'Transaction Overview'!$I$2:$I$517,$A37,'Transaction Overview'!$H$2:$H$517,G$4) -> -6000 | H37: =SUMIFS('Transaction Overview'!$D$2:$D$517,'Transaction Overview'!$I$2:$I$517,$A37,'Transaction Overview'!$H$2:$H$517,H$4) -> 0 | I37: =SUMIFS('Transaction Overview'!$D$2:$D$517,'Transaction Overview'!$I$2:$I$517,$A37,'Transaction Overview'!$H$2:$H$517,I$4) -> 0 | ... M37: =SUMIFS('Transaction Overview'!$D$2:$D$517,'Transaction Overview'!$I$2:$I$517,$A37,'Transaction Overview'!$H$2:$H$517,M$4) -> 0 | N37: =SUM(B37:M37) -> -43250
A38: Ruth Alcancia - Forward Bridge Payment | B38: =SUMIFS('Transaction Overview'!$D$2:$D$517,'Transaction Overview'!$I$2:$I$517,$A38,'Transaction Overview'!$H$2:$H$517,B$4) -> -425 | C38: =SUMIFS('Transaction Overview'!$D$2:$D$517,'Transaction Overview'!$I$2:$I$517,$A38,'Transaction Overview'!$H$2:$H$517,C$4) -> -600 | D38: =SUMIFS('Transaction Overview'!$D$2:$D$517,'Transaction Overview'!$I$2:$I$517,$A38,'Transaction Overview'!$H$2:$H$517,D$4) -> -990.4 | E38: =SUMIFS('Transaction Overview'!$D$2:$D$517,'Transaction Overview'!$I$2:$I$517,$A38,'Transaction Overview'!$H$2:$H$517,E$4) -> -791.99 | F38: =SUMIFS('Transaction Overview'!$D$2:$D$517,'Transaction Overview'!$I$2:$I$517,$A38,'Transaction Overview'!$H$2:$H$517,F$4) -> -1049.99 | G38: =SUMIFS('Transaction Overview'!$D$2:$D$517,'Transaction Overview'!$I$2:$I$517,$A38,'Transaction Overview'!$H$2:$H$517,G$4) -> -189.32 | H38: =SUMIFS('Transaction Overview'!$D$2:$D$517,'Transaction Overview'!$I$2:$I$517,$A38,'Transaction Overview'!$H$2:$H$517,H$4) -> 0 | I38: =SUMIFS('Transaction Overview'!$D$2:$D$517,'Transaction Overview'!$I$2:$I$517,$A38,'Transaction Overview'!$H$2:$H$517,I$4) -> 0 | ... M38: =SUMIFS('Transaction Overview'!$D$2:$D$517,'Transaction Overview'!$I$2:$I$517,$A38,'Transaction Overview'!$H$2:$H$517,M$4) -> 0 | N38: =SUM(B38:M38) -> -4046.7
A39: Upwork - Sergei M. | B39: =SUMIFS('Transaction Overview'!$D$2:$D$517,'Transaction Overview'!$I$2:$I$517,$A39,'Transaction Overview'!$H$2:$H$517,B$4) -> -971.25 | C39: =SUMIFS('Transaction Overview'!$D$2:$D$517,'Transaction Overview'!$I$2:$I$517,$A39,'Transaction Overview'!$H$2:$H$517,C$4) -> -656.25 | D39: =SUMIFS('Transaction Overview'!$D$2:$D$517,'Transaction Overview'!$I$2:$I$517,$A39,'Transaction Overview'!$H$2:$H$517,D$4) -> 0 | E39: =SUMIFS('Transaction Overview'!$D$2:$D$517,'Transaction Overview'!$I$2:$I$517,$A39,'Transaction Overview'!$H$2:$H$517,E$4) -> 0 | F39: =SUMIFS('Transaction Overview'!$D$2:$D$517,'Transaction Overview'!$I$2:$I$517,$A39,'Transaction Overview'!$H$2:$H$517,F$4) -> 0 | G39: =SUMIFS('Transaction Overview'!$D$2:$D$517,'Transaction Overview'!$I$2:$I$517,$A39,'Transaction Overview'!$H$2:$H$517,G$4) -> 0 | H39: =SUMIFS('Transaction Overview'!$D$2:$D$517,'Transaction Overview'!$I$2:$I$517,$A39,'Transaction Overview'!$H$2:$H$517,H$4) -> 0 | I39: =SUMIFS('Transaction Overview'!$D$2:$D$517,'Transaction Overview'!$I$2:$I$517,$A39,'Transaction Overview'!$H$2:$H$517,I$4) -> 0 | ... M39: =SUMIFS('Transaction Overview'!$D$2:$D$517,'Transaction Overview'!$I$2:$I$517,$A39,'Transaction Overview'!$H$2:$H$517,M$4) -> 0 | N39: =SUM(B39:M39) -> -1627.5
A40: P2P Payments (Zelle/Venmo/PayPal)
A41: PayPal | B41: =SUMIFS('Transaction Overview'!$D$2:$D$517,'Transaction Overview'!$I$2:$I$517,$A41,'Transaction Overview'!$H$2:$H$517,B$4) -> 0 | C41: =SUMIFS('Transaction Overview'!$D$2:$D$517,'Transaction Overview'!$I$2:$I$517,$A41,'Transaction Overview'!$H$2:$H$517,C$4) -> 0 | D41: =SUMIFS('Transaction Overview'!$D$2:$D$517,'Transaction Overview'!$I$2:$I$517,$A41,'Transaction Overview'!$H$2:$H$517,D$4) -> -37.08 | E41: =SUMIFS('Transaction Overview'!$D$2:$D$517,'Transaction Overview'!$I$2:$I$517,$A41,'Transaction Overview'!$H$2:$H$517,E$4) -> -36.94 | F41: =SUMIFS('Transaction Overview'!$D$2:$D$517,'Transaction Overview'!$I$2:$I$517,$A41,'Transaction Overview'!$H$2:$H$517,F$4) -> 0 | G41: =SUMIFS('Transaction Overview'!$D$2:$D$517,'Transaction Overview'!$I$2:$I$517,$A41,'Transaction Overview'!$H$2:$H$517,G$4) -> 0 | H41: =SUMIFS('Transaction Overview'!$D$2:$D$517,'Transaction Overview'!$I$2:$I$517,$A41,'Transaction Overview'!$H$2:$H$517,H$4) -> 0 | I41: =SUMIFS('Transaction Overview'!$D$2:$D$517,'Transaction Overview'!$I$2:$I$517,$A41,'Transaction Overview'!$H$2:$H$517,I$4) -> 0 | ... M41: =SUMIFS('Transaction Overview'!$D$2:$D$517,'Transaction Overview'!$I$2:$I$517,$A41,'Transaction Overview'!$H$2:$H$517,M$4) -> 0 | N41: =SUM(B41:M41) -> -74.02
...

Sheet Transfer In
A1: Chase 1168 — DWG Capital Group 2026 Activity
A2: Intercompany Transfers — In | Jan 2026 – Dec 2026
A4: SUMMARY
A5: Total | C5: =SUMIFS('Transaction Overview'!$D$2:$D$517,'Transaction Overview'!$J$2:$J$517,"Intercompany & Savings Transfers",'Transaction Overview'!$D$2:$D$517,">0") -> 0
A6: # Transactions | C6: =COUNTIFS('Transaction Overview'!$J$2:$J$517,"Intercompany & Savings Transfers",'Transaction Overview'!$D$2:$D$517,">0") -> 0

Sheet Transfer Out
A1: Chase 1168 — DWG Capital Group 2026 Activity
A2: Intercompany Transfers — Out | Jan 2026 – Dec 2026
A4: SUMMARY
A5: Total | C5: =SUMIFS('Transaction Overview'!$D$2:$D$517,'Transaction Overview'!$J$2:$J$517,"Intercompany & Savings Transfers",'Transaction Overview'!$D$2:$D$517,"<0") -> -25198.18
A6: # Transactions | C6: =COUNTIFS('Transaction Overview'!$J$2:$J$517,"Intercompany & Savings Transfers",'Transaction Overview'!$D$2:$D$517,"<0") -> 20

Sheet Wire In
A1: Chase 1168 — DWG Capital Group 2026 Activity
A2: Wire Transfers — In | Jan 2026 – Dec 2026
A4: SUMMARY
A5: Total | C5: =SUMIFS('Transaction Overview'!$D$2:$D$517,'Transaction Overview'!$J$2:$J$517,"Intercompany & Savings Transfers",'Transaction Overview'!$D$2:$D$517,">0") -> 0
A6: # Transactions | C6: =COUNTIFS('Transaction Overview'!$J$2:$J$517,"Intercompany & Savings Transfers",'Transaction Overview'!$D$2:$D$517,">0") -> 0

Sheet Wire Out
A1: Chase 1168 — DWG Capital Group 2026 Activity
A2: Wire Transfers — Out | Jan 2026 – Dec 2026
A4: SUMMARY
A5: Total | C5: =SUMIFS('Transaction Overview'!$D$2:$D$517,'Transaction Overview'!$J$2:$J$517,"Intercompany & Savings Transfers",'Transaction Overview'!$D$2:$D$517,"<0") -> -25198.18
A6: # Transactions | C6: =COUNTIFS('Transaction Overview'!$J$2:$J$517,"Intercompany & Savings Transfers",'Transaction Overview'!$D$2:$D$517,"<0") -> 20

Sheet Commission
A1: Chase 1168 — DWG Capital Group 2026 Activity
A2: Commissions Statement | Jan 2026 – Dec 2026
A4: SUMMARY
A5: Total | C5: =SUMIFS('Transaction Overview'!$D$2:$D$517,'Transaction Overview'!$J$2:$J$517,"Commissions — Incoming",'Transaction Overview'!$D$2:$D$517,">0") -> 114000
A6: # Transactions | C6: =COUNTIFS('Transaction Overview'!$J$2:$J$517,"Commissions — Incoming",'Transaction Overview'!$D$2:$D$517,">0") -> 1

Sheet Transaction Overview
A1: Details | B1: Posting Date | C1: Description | D1: Amount | E1: Type | F1: Balance | G1: Category | H1: Month | I1: Combined Category | J1: Group
A2: =Chase1168_2026!A2 -> DEBIT | B2: =Chase1168_2026!B2 -> 46188 | C2: =Chase1168_2026!C2 -> ORIG CO NAME:VENMO CO ENTRY DESCR:PAYMENT SEC:WEB IND ID:1051023030786 ORIG ID:3264681992 | D2: =Chase1168_2026!D2 -> -15 | E2: =Chase1168_2026!E2 -> ACH_DEBIT | F2: =Chase1168_2026!F2 | G2: =Chase1168_2026!G2 -> Venmo | H2: =IF($B2="","",DATE(YEAR($B2),MONTH($B2),1)) -> 46174 | I2: =IF($G2="","Uncategorized — Review",IFERROR(INDEX(Mapping!$B:$B,MATCH($G2,Mapping!$A:$A,0)),"Uncategorized — Review")) -> Venmo | J2: =IF($G2="","Uncategorized — Review",IFERROR(INDEX(Mapping!$C:$C,MATCH($G2,Mapping!$A:$A,0)),"Uncategorized — Review")) -> P2P Payments (Zelle/Venmo/PayPal)
A3: =Chase1168_2026!A3 -> DEBIT | B3: =Chase1168_2026!B3 -> 46188 | C3: =Chase1168_2026!C3 -> ONLINE TRANSFER TO CHK ...1117 TRANSACTION#: 29633194527 06/15 | D3: =Chase1168_2026!D3 -> -1000 | E3: =Chase1168_2026!E3 -> ACCT_XFER | F3: =Chase1168_2026!F3 | G3: =Chase1168_2026!G3 -> Transfer to Angela Dunning | H3: =IF($B3="","",DATE(YEAR($B3),MONTH($B3),1)) -> 46174 | I3: =IF($G3="","Uncategorized — Review",IFERROR(INDEX(Mapping!$B:$B,MATCH($G3,Mapping!$A:$A,0)),"Uncategorized — Review")) -> Transfer to Angela Dunning | J3: =IF($G3="","Uncategorized — Review",IFERROR(INDEX(Mapping!$C:$C,MATCH($G3,Mapping!$A:$A,0)),"Uncategorized — Review")) -> Owner / Family Distributions
A4: =Chase1168_2026!A4 -> DEBIT | B4: =Chase1168_2026!B4 -> 46188 | C4: =Chase1168_2026!C4 -> Online ACH payment to Mike | D4: =Chase1168_2026!D4 -> -2000 | E4: =Chase1168_2026!E4 -> BASIC_PAYROLL | F4: =Chase1168_2026!F4 | G4: =Chase1168_2026!G4 -> Mike Paytonjian - Payroll | H4: =IF($B4="","",DATE(YEAR($B4),MONTH($B4),1)) -> 46174 | I4: =IF($G4="","Uncategorized — Review",IFERROR(INDEX(Mapping!$B:$B,MATCH($G4,Mapping!$A:$A,0)),"Uncategorized — Review")) -> Mike Paytonjian - Payroll | J4: =IF($G4="","Uncategorized — Review",IFERROR(INDEX(Mapping!$C:$C,MATCH($G4,Mapping!$A:$A,0)),"Uncategorized — Review")) -> Payroll & Contractors
A5: =Chase1168_2026!A5 -> DEBIT | B5: =Chase1168_2026!B5 -> 46188 | C5: =Chase1168_2026!C5 -> ORIG CO NAME:VENMO CO ENTRY DESCR:PAYMENT SEC:WEB IND ID:1050998946316 ORIG ID:3264681992 | D5: =Chase1168_2026!D5 -> -150 | E5: =Chase1168_2026!E5 -> ACH_DEBIT | F5: =Chase1168_2026!F5 | G5: =Chase1168_2026!G5 -> Venmo | H5: =IF($B5="","",DATE(YEAR($B5),MONTH($B5),1)) -> 46174 | I5: =IF($G5="","Uncategorized — Review",IFERROR(INDEX(Mapping!$B:$B,MATCH($G5,Mapping!$A:$A,0)),"Uncategorized — Review")) -> Venmo | J5: =IF($G5="","Uncategorized — Review",IFERROR(INDEX(Mapping!$C:$C,MATCH($G5,Mapping!$A:$A,0)),"Uncategorized — Review")) -> P2P Payments (Zelle/Venmo/PayPal)
A6: =Chase1168_2026!A6 -> DEBIT | B6: =Chase1168_2026!B6 -> 46188 | C6: =Chase1168_2026!C6 -> ORIG CO NAME:VENMO CO ENTRY DESCR:PAYMENT SEC:WEB IND ID:1050990087863 ORIG ID:3264681992 | D6: =Chase1168_2026!D6 -> -200 | E6: =Chase1168_2026!E6 -> ACH_DEBIT | F6: =Chase1168_2026!F6 | G6: =Chase1168_2026!G6 -> Venmo | H6: =IF($B6="","",DATE(YEAR($B6),MONTH($B6),1)) -> 46174 | I6: =IF($G6="","Uncategorized — Review",IFERROR(INDEX(Mapping!$B:$B,MATCH($G6,Mapping!$A:$A,0)),"Uncategorized — Review")) -> Venmo | J6: =IF($G6="","Uncategorized — Review",IFERROR(INDEX(Mapping!$C:$C,MATCH($G6,Mapping!$A:$A,0)),"Uncategorized — Review")) -> P2P Payments (Zelle/Venmo/PayPal)
A7: =Chase1168_2026!A7 -> DEBIT | B7: =Chase1168_2026!B7 -> 46188 | C7: =Chase1168_2026!C7 -> ONLINE TRANSFER TO CHK ...1117 TRANSACTION#: 29624118889 06/15 | D7: =Chase1168_2026!D7 -> -500 | E7: =Chase1168_2026!E7 -> ACCT_XFER | F7: =Chase1168_2026!F7 | G7: =Chase1168_2026!G7 -> Transfer to Angela Dunning | H7: =IF($B7="","",DATE(YEAR($B7),MONTH($B7),1)) -> 46174 | I7: =IF($G7="","Uncategorized — Review",IFERROR(INDEX(Mapping!$B:$B,MATCH($G7,Mapping!$A:$A,0)),"Uncategorized — Review")) -> Transfer to Angela Dunning | J7: =IF($G7="","Uncategorized — Review",IFERROR(INDEX(Mapping!$C:$C,MATCH($G7,Mapping!$A:$A,0)),"Uncategorized — Review")) -> Owner / Family Distributions
A8: =Chase1168_2026!A8 -> DEBIT | B8: =Chase1168_2026!B8 -> 46188 | C8: =Chase1168_2026!C8 -> ONLINE TRANSFER TO CHK ...6975 TRANSACTION#: 29624118165 06/15 | D8: =Chase1168_2026!D8 -> -200 | E8: =Chase1168_2026!E8 -> ACCT_XFER | F8: =Chase1168_2026!F8 | G8: =Chase1168_2026!G8 -> Transfer to Angela Dunning | H8: =IF($B8="","",DATE(YEAR($B8),MONTH($B8),1)) -> 46174 | I8: =IF($G8="","Uncategorized — Review",IFERROR(INDEX(Mapping!$B:$B,MATCH($G8,Mapping!$A:$A,0)),"Uncategorized — Review")) -> Transfer to Angela Dunning | J8: =IF($G8="","Uncategorized — Review",IFERROR(INDEX(Mapping!$C:$C,MATCH($G8,Mapping!$A:$A,0)),"Uncategorized — Review")) -> Owner / Family Distributions
A9: =Chase1168_2026!A9 -> DEBIT | B9: =Chase1168_2026!B9 -> 46188 | C9: =Chase1168_2026!C9 -> ZELLE PAYMENT TO JEFFREY SEIDER JPM99CKSLP03 | D9: =Chase1168_2026!D9 -> -200 | E9: =Chase1168_2026!E9 -> CHASE_TO_PARTNERFI | F9: =Chase1168_2026!F9 | G9: =Chase1168_2026!G9 -> Zelle - Jeff Seider | H9: =IF($B9="","",DATE(YEAR($B9),MONTH($B9),1)) -> 46174 | I9: =IF($G9="","Uncategorized — Review",IFERROR(INDEX(Mapping!$B:$B,MATCH($G9,Mapping!$A:$A,0)),"Uncategorized — Review")) -> Zelle - Jeff Seider | J9: =IF($G9="","Uncategorized — Review",IFERROR(INDEX(Mapping!$C:$C,MATCH($G9,Mapping!$A:$A,0)),"Uncategorized — Review")) -> P2P Payments (Zelle/Venmo/PayPal)
A10: =Chase1168_2026!A10 -> DEBIT | B10: =Chase1168_2026!B10 -> 46188 | C10: =Chase1168_2026!C10 -> ONLINE TRANSFER TO CHK ...1117 TRANSACTION#: 29617096887 06/15 | D10: =Chase1168_2026!D10 -> -3000 | E10: =Chase1168_2026!E10 -> ACCT_XFER | F10: =Chase1168_2026!F10 | G10: =Chase1168_2026!G10 -> Transfer to Angela Dunning | H10: =IF($B10="","",DATE(YEAR($B10),MONTH($B10),1)) -> 46174 | I10: =IF($G10="","Uncategorized — Review",IFERROR(INDEX(Mapping!$B:$B,MATCH($G10,Mapping!$A:$A,0)),"Uncategorized — Review")) -> Transfer to Angela Dunning | J10: =IF($G10="","Uncategorized — Review",IFERROR(INDEX(Mapping!$C:$C,MATCH($G10,Mapping!$A:$A,0)),"Uncategorized — Review")) -> Owner / Family Distributions
A11: =Chase1168_2026!A11 -> DEBIT | B11: =Chase1168_2026!B11 -> 46188 | C11: =Chase1168_2026!C11 -> POS DEBIT GODADDY#4111542544 480-5058855 AZ 9052 | D11: =Chase1168_2026!D11 -> -45.96 | E11: =Chase1168_2026!E11 -> MISC_DEBIT | F11: =Chase1168_2026!F11 | G11: =Chase1168_2026!G11 -> Go Daddy | H11: =IF($B11="","",DATE(YEAR($B11),MONTH($B11),1)) -> 46174 | I11: =IF($G11="","Uncategorized — Review",IFERROR(INDEX(Mapping!$B:$B,MATCH($G11,Mapping!$A:$A,0)),"Uncategorized — Review")) -> Go Daddy | J11: =IF($G11="","Uncategorized — Review",IFERROR(INDEX(Mapping!$C:$C,MATCH($G11,Mapping!$A:$A,0)),"Uncategorized — Review")) -> DWG Operating
A12: =Chase1168_2026!A12 -> DEBIT | B12: =Chase1168_2026!B12 -> 46185 | C12: =Chase1168_2026!C12 -> GODADDY#4110236617 480-5058855 AZ 06/11 | D12: =Chase1168_2026!D12 -> -60.73 | E12: =Chase1168_2026!E12 -> DEBIT_CARD | F12: =Chase1168_2026!F12 -> 24009.79 | G12: =Chase1168_2026!G12 -> Go Daddy | H12: =IF($B12="","",DATE(YEAR($B12),MONTH($B12),1)) -> 46174 | I12: =IF($G12="","Uncategorized — Review",IFERROR(INDEX(Mapping!$B:$B,MATCH($G12,Mapping!$A:$A,0)),"Uncategorized — Review")) -> Go Daddy | J12: =IF($G12="","Uncategorized — Review",IFERROR(INDEX(Mapping!$C:$C,MATCH($G12,Mapping!$A:$A,0)),"Uncategorized — Review")) -> DWG Operating
A13: =Chase1168_2026!A13 -> DEBIT | B13: =Chase1168_2026!B13 -> 46184 | C13: =Chase1168_2026!C13 -> Zelle payment to Jeffrey Seider JPM99ckg6uwz | D13: =Chase1168_2026!D13 -> -200 | E13: =Chase1168_2026!E13 -> CHASE_TO_PARTNERFI | F13: =Chase1168_2026!F13 -> 24070.52 | G13: =Chase1168_2026!G13 -> Zelle - Jeff Seider | H13: =IF($B13="","",DATE(YEAR($B13),MONTH($B13),1)) -> 46174 | I13: =IF($G13="","Uncategorized — Review",IFERROR(INDEX(Mapping!$B:$B,MATCH($G13,Mapping!$A:$A,0)),"Uncategorized — Review")) -> Zelle - Jeff Seider | J13: =IF($G13="","Uncategorized — Review",IFERROR(INDEX(Mapping!$C:$C,MATCH($G13,Mapping!$A:$A,0)),"Uncategorized — Review")) -> P2P Payments (Zelle/Venmo/PayPal)
... A517: =Chase1168_2026!A517 -> DEBIT | B517: =Chase1168_2026!B517 -> 46024 | C517: =Chase1168_2026!C517 -> ORIG CO NAME:BLUESHIELDCA ORIG ID:7529219311 DESC DATE:251231 CO ENTRY DESCR:BILL PAY SEC:CCD TRACE#:031101115700064 EED:260102 IND ID:15728029331 IND NAME:ANGELA DUNNING TRN: 0025700064TC | D517: =Chase1168_2026!D517 -> -974.85 | E517: =Chase1168_2026!E517 -> ACH_DEBIT | F517: =Chase1168_2026!F517 -> 29231.38 | G517: =Chase1168_2026!G517 -> Personal - Health Insurance | H517: =IF($B517="","",DATE(YEAR($B517),MONTH($B517),1)) -> 46023 | I517: =IF($G517="","Uncategorized — Review",IFERROR(INDEX(Mapping!$B:$B,MATCH($G517,Mapping!$A:$A,0)),"Uncategorized — Review")) -> Personal - Health (incl. Ins.) | J517: =IF($G517="","Uncategorized — Review",IFERROR(INDEX(Mapping!$C:$C,MATCH($G517,Mapping!$A:$A,0)),"Uncategorized — Review")) -> Personal — Owner

Sheet Mapping
A1: Raw Category | B1: Combined Category | C1: Group
A2: ??? | B2: ??? | C2: Uncategorized — Review
A3: AI Subscriptions | B3: AI Subscriptions | C3: DWG Operating
A4: ATM/Cash | B4: ATM/Cash | C4: Uncategorized — Review
A5: Andres Alarcon Payroll | B5: Andres Alarcon Payroll | C5: Payroll & Contractors
A6: Bank Fees | B6: Bank Fees | C6: DWG Operating
A7: Bill Payment | B7: Bill Payment | C7: DWG Operating
A8: Chase Hall - Payroll | B8: Chase Hall - Payroll | C8: Payroll & Contractors
A9: DWG Capital Group - Taxes | B9: Taxes | C9: Taxes
A10: DWG HR | B10: DWG HR | C10: Payroll & Contractors
A11: DWG Marketing | B11: DWG Marketing | C11: DWG Operating
A12: DWGCP Business Development | B12: DWGCP Business Development | C12: DWG Operating
... A74: Zelle/P2P | B74: Zelle/P2P | C74: P2P Payments (Zelle/Venmo/PayPal)

Sheet Chase1168_2026
A1: Details | B1: Posting Date | C1: Description | D1: Amount | E1: Type | F1: Balance | G1: Category
A2: DEBIT | B2: 46188 | C2: ORIG CO NAME:VENMO CO ENTRY DESCR:PAYMENT SEC:WEB IND ID:1051023030786 ORIG ID:3264681992 | D2: -15 | E2: ACH_DEBIT | G2: Venmo
A3: DEBIT | B3: 46188 | C3: ONLINE TRANSFER TO CHK ...1117 TRANSACTION#: 29633194527 06/15 | D3: -1000 | E3: ACCT_XFER | G3: Transfer to Angela Dunning
