Workbook

Sheet Category Summary
A1: Chase 9335 — 2026 Activity
A2: Category Summary | Jan 2026 – Jun 2026
A4: Entity | B4: Poseidon Asset Group
A5: Account | B5: Personal Checking — Chase 9335
A6: Period | B6: Jan 2026 – Jun 2026
A8: TOTALS
A9: Total Inflows | B9: =SUMIFS('Transaction Overview'!$D$2:$D$467,'Transaction Overview'!$D$2:$D$467,">0") -> 680055.66
A10: Total Outflows | B10: =SUMIFS('Transaction Overview'!$D$2:$D$467,'Transaction Overview'!$D$2:$D$467,"<0") -> -901960.84
A11: Net Change | B11: =B9+B10 -> -221905.18
A13: FLOW BY CATEGORY
A14: Category | B14: Inflows | C14: Outflows | D14: Net
A15: Deal-Specific
A16: Bridge Coverage (JC Whitner) | B16: =SUMIFS('Transaction Overview'!$D$2:$D$467,'Transaction Overview'!$G$2:$G$467,$A16,'Transaction Overview'!$D$2:$D$467,">0") -> 0 | C16: =SUMIFS('Transaction Overview'!$D$2:$D$467,'Transaction Overview'!$G$2:$G$467,$A16,'Transaction Overview'!$D$2:$D$467,"<0") -> -10000 | D16: =B16+C16 -> -10000
A17: Deal Specific: Austin Iron | B17: =SUMIFS('Transaction Overview'!$D$2:$D$467,'Transaction Overview'!$G$2:$G$467,$A17,'Transaction Overview'!$D$2:$D$467,">0") -> 2100 | C17: =SUMIFS('Transaction Overview'!$D$2:$D$467,'Transaction Overview'!$G$2:$G$467,$A17,'Transaction Overview'!$D$2:$D$467,"<0") -> 0 | D17: =B17+C17 -> 2100
A18: Deal Specific: MRM | B18: =SUMIFS('Transaction Overview'!$D$2:$D$467,'Transaction Overview'!$G$2:$G$467,$A18,'Transaction Overview'!$D$2:$D$467,">0") -> 725.61 | C18: =SUMIFS('Transaction Overview'!$D$2:$D$467,'Transaction Overview'!$G$2:$G$467,$A18,'Transaction Overview'!$D$2:$D$467,"<0") -> 0 | D18: =B18+C18 -> 725.61
A19: Deal Specific: Merit-Lancaster | B19: =SUMIFS('Transaction Overview'!$D$2:$D$467,'Transaction Overview'!$G$2:$G$467,$A19,'Transaction Overview'!$D$2:$D$467,">0") -> 2917.98 | C19: =SUMIFS('Transaction Overview'!$D$2:$D$467,'Transaction Overview'!$G$2:$G$467,$A19,'Transaction Overview'!$D$2:$D$467,"<0") -> 0 | D19: =B19+C19 -> 2917.98
A20: Deal Specific: Rabourn Road | B20: =SUMIFS('Transaction Overview'!$D$2:$D$467,'Transaction Overview'!$G$2:$G$467,$A20,'Transaction Overview'!$D$2:$D$467,">0") -> 1399.98 | C20: =SUMIFS('Transaction Overview'!$D$2:$D$467,'Transaction Overview'!$G$2:$G$467,$A20,'Transaction Overview'!$D$2:$D$467,"<0") -> 0 | D20: =B20+C20 -> 1399.98
A21: Deal Specific: T&T Machine | B21: =SUMIFS('Transaction Overview'!$D$2:$D$467,'Transaction Overview'!$G$2:$G$467,$A21,'Transaction Overview'!$D$2:$D$467,">0") -> 1091.42 | C21: =SUMIFS('Transaction Overview'!$D$2:$D$467,'Transaction Overview'!$G$2:$G$467,$A21,'Transaction Overview'!$D$2:$D$467,"<0") -> 0 | D21: =B21+C21 -> 1091.42
A22: Subtotal — Deal-Specific | B22: =SUMIFS('Transaction Overview'!$D$2:$D$467,'Transaction Overview'!$J$2:$J$467,"Deal-Specific",'Transaction Overview'!$D$2:$D$467,">0") -> 8234.99 | C22: =SUMIFS('Transaction Overview'!$D$2:$D$467,'Transaction Overview'!$J$2:$J$467,"Deal-Specific",'Transaction Overview'!$D$2:$D$467,"<0") -> -10000 | D22: =B22+C22 -> -1765.01
A24: Commissions — Incoming
A25: Incoming Commission: Rembrandt | B25: =SUMIFS('Transaction Overview'!$D$2:$D$467,'Transaction Overview'!$G$2:$G$467,$A25,'Transaction Overview'!$D$2:$D$467,">0") -> 168266 | C25: =SUMIFS('Transaction Overview'!$D$2:$D$467,'Transaction Overview'!$G$2:$G$467,$A25,'Transaction Overview'!$D$2:$D$467,"<0") -> 0 | D25: =B25+C25 -> 168266
A26: Incoming Commission: SPF | B26: =SUMIFS('Transaction Overview'!$D$2:$D$467,'Transaction Overview'!$G$2:$G$467,$A26,'Transaction Overview'!$D$2:$D$467,">0") -> 266889.44 | C26: =SUMIFS('Transaction Overview'!$D$2:$D$467,'Transaction Overview'!$G$2:$G$467,$A26,'Transaction Overview'!$D$2:$D$467,"<0") -> 0 | D26: =B26+C26 -> 266889.44
A27: Subtotal — Commissions — Incoming | B27: =SUMIFS('Transaction Overview'!$D$2:$D$467,'Transaction Overview'!$J$2:$J$467,"Commissions — Incoming",'Transaction Overview'!$D$2:$D$467,">0") -> 435155.44 | C27: =SUMIFS('Transaction Overview'!$D$2:$D$467,'Transaction Overview'!$J$2:$J$467,"Commissions — Incoming",'Transaction Overview'!$D$2:$D$467,"<0") -> 0 | D27: =B27+C27 -> 435155.44
A29: Commissions — Outgoing
A30: Kevin Wong Commission (SPF) | B30: =SUMIFS('Transaction Overview'!$D$2:$D$467,'Transaction Overview'!$G$2:$G$467,$A30,'Transaction Overview'!$D$2:$D$467,">0") -> 0 | C30: =SUMIFS('Transaction Overview'!$D$2:$D$467,'Transaction Overview'!$G$2:$G$467,$A30,'Transaction Overview'!$D$2:$D$467,"<0") -> -16087.5 | D30: =B30+C30 -> -16087.5
A31: Kevin Wong Commission (Steve Klar) | B31: =SUMIFS('Transaction Overview'!$D$2:$D$467,'Transaction Overview'!$G$2:$G$467,$A31,'Transaction Overview'!$D$2:$D$467,">0") -> 0 | C31: =SUMIFS('Transaction Overview'!$D$2:$D$467,'Transaction Overview'!$G$2:$G$467,$A31,'Transaction Overview'!$D$2:$D$467,"<0") -> -6000 | D31: =B31+C31 -> -6000
A32: Meg Maran - MDC Commission | B32: =SUMIFS('Transaction Overview'!$D$2:$D$467,'Transaction Overview'!$G$2:$G$467,$A32,'Transaction Overview'!$D$2:$D$467,">0") -> 0 | C32: =SUMIFS('Transaction Overview'!$D$2:$D$467,'Transaction Overview'!$G$2:$G$467,$A32,'Transaction Overview'!$D$2:$D$467,"<0") -> -1500 | D32: =B32+C32 -> -1500
A33: Subtotal — Commissions — Outgoing | B33: =SUMIFS('Transaction Overview'!$D$2:$D$467,'Transaction Overview'!$J$2:$J$467,"Commissions — Outgoing",'Transaction Overview'!$D$2:$D$467,">0") -> 0 | C33: =SUMIFS('Transaction Overview'!$D$2:$D$467,'Transaction Overview'!$J$2:$J$467,"Commissions — Outgoing",'Transaction Overview'!$D$2:$D$467,"<0") -> -23587.5 | D33: =B33+C33 -> -23587.5
A35: MAG Pass-Through
A36: MAG - Admeer Advisory Reimbursement | B36: =SUMIFS('Transaction Overview'!$D$2:$D$467,'Transaction Overview'!$G$2:$G$467,$A36,'Transaction Overview'!$D$2:$D$467,">0") -> 5000 | C36: =SUMIFS('Transaction Overview'!$D$2:$D$467,'Transaction Overview'!$G$2:$G$467,$A36,'Transaction Overview'!$D$2:$D$467,"<0") -> 0 | D36: =B36+C36 -> 5000
A37: MAG - Admeer Advisory Transfer | B37: =SUMIFS('Transaction Overview'!$D$2:$D$467,'Transaction Overview'!$G$2:$G$467,$A37,'Transaction Overview'!$D$2:$D$467,">0") -> 0 | C37: =SUMIFS('Transaction Overview'!$D$2:$D$467,'Transaction Overview'!$G$2:$G$467,$A37,'Transaction Overview'!$D$2:$D$467,"<0") -> -10000 | D37: =B37+C37 -> -10000
A38: MAG Marketing Reimbursement | B38: =SUMIFS('Transaction Overview'!$D$2:$D$467,'Transaction Overview'!$G$2:$G$467,$A38,'Transaction Overview'!$D$2:$D$467,">0") -> 15000 | C38: =SUMIFS('Transaction Overview'!$D$2:$D$467,'Transaction Overview'!$G$2:$G$467,$A38,'Transaction Overview'!$D$2:$D$467,"<0") -> 0 | D38: =B38+C38 -> 15000
A39: Subtotal — MAG Pass-Through | B39: =SUMIFS('Transaction Overview'!$D$2:$D$467,'Transaction Overview'!$J$2:$J$467,"MAG Pass-Through",'Transaction Overview'!$D$2:$D$467,">0") -> 20000 | C39: =SUMIFS('Transaction Overview'!$D$2:$D$467,'Transaction Overview'!$J$2:$J$467,"MAG Pass-Through",'Transaction Overview'!$D$2:$D$467,"<0") -> -10000 | D39: =B39+C39 -> 10000
A41: Wire Transfers — Incoming
A42: Incoming wire from JC Whitner | B42: =SUMIFS('Transaction Overview'!$D$2:$D$467,'Transaction Overview'!$G$2:$G$467,$A42,'Transaction Overview'!$D$2:$D$467,">0") -> 20000 | C42: =SUMIFS('Transaction Overview'!$D$2:$D$467,'Transaction Overview'!$G$2:$G$467,$A42,'Transaction Overview'!$D$2:$D$467,"<0") -> 0 | D42: =B42+C42 -> 20000
A43: Incoming wire from Moab (Leftover Funds) | B43: =SUMIFS('Transaction Overview'!$D$2:$D$467,'Transaction Overview'!$G$2:$G$467,$A43,'Transaction Overview'!$D$2:$D$467,">0") -> 58370.85 | C43: =SUMIFS('Transaction Overview'!$D$2:$D$467,'Transaction Overview'!$G$2:$G$467,$A43,'Transaction Overview'!$D$2:$D$467,"<0") -> 0 | D43: =B43+C43 -> 58370.85
A44: Incoming wire from Steve Klar | B44: =SUMIFS('Transaction Overview'!$D$2:$D$467,'Transaction Overview'!$G$2:$G$467,$A44,'Transaction Overview'!$D$2:$D$467,">0") -> 16000 | C44: =SUMIFS('Transaction Overview'!$D$2:$D$467,'Transaction Overview'!$G$2:$G$467,$A44,'Transaction Overview'!$D$2:$D$467,"<0") -> 0 | D44: =B44+C44 -> 16000
A45: Subtotal — Wire Transfers — Incoming | B45: =SUMIFS('Transaction Overview'!$D$2:$D$467,'Transaction Overview'!$J$2:$J$467,"Wire Transfers — Incoming",'Transaction Overview'!$D$2:$D$467,">0") -> 94370.85 | C45: =SUMIFS('Transaction Overview'!$D$2:$D$467,'Transaction Overview'!$J$2:$J$467,"Wire Transfers — Incoming",'Transaction Overview'!$D$2:$D$467,"<0") -> 0 | D45: =B45+C45 -> 94370.85
A47: Wire Transfers — Outgoing
A48: Wire to Gi Capital Group (+ Moab Funds) | B48: =SUMIFS('Transaction Overview'!$D$2:$D$467,'Transaction Overview'!$G$2:$G$467,$A48,'Transaction Overview'!$D$2:$D$467,">0") -> 0 | C48: =SUMIFS('Transaction Overview'!$D$2:$D$467,'Transaction Overview'!$G$2:$G$467,$A48,'Transaction Overview'!$D$2:$D$467,"<0") -> -56670.85 | D48: =B48+C48 -> -56670.85
...

Sheet Monthly Breakdown
A1: Chase 9335 — 2026 Activity
A2: Monthly Breakdown | Net by Category | Jan 2026 – Jun 2026
A4: Category | B4: =DATE(2026,1,1) -> 46023 | C4: =DATE(2026,2,1) -> 46054 | D4: =DATE(2026,3,1) -> 46082 | E4: =DATE(2026,4,1) -> 46113 | F4: =DATE(2026,5,1) -> 46143 | G4: =DATE(2026,6,1) -> 46174 | H4: Total
A5: Deal-Specific
A6: Bridge Coverage (JC Whitner) | B6: =SUMIFS('Transaction Overview'!$D$2:$D$467,'Transaction Overview'!$I$2:$I$467,$A6,'Transaction Overview'!$H$2:$H$467,B$4) -> -10000 | C6: =SUMIFS('Transaction Overview'!$D$2:$D$467,'Transaction Overview'!$I$2:$I$467,$A6,'Transaction Overview'!$H$2:$H$467,C$4) -> 0 | D6: =SUMIFS('Transaction Overview'!$D$2:$D$467,'Transaction Overview'!$I$2:$I$467,$A6,'Transaction Overview'!$H$2:$H$467,D$4) -> 0 | E6: =SUMIFS('Transaction Overview'!$D$2:$D$467,'Transaction Overview'!$I$2:$I$467,$A6,'Transaction Overview'!$H$2:$H$467,E$4) -> 0 | F6: =SUMIFS('Transaction Overview'!$D$2:$D$467,'Transaction Overview'!$I$2:$I$467,$A6,'Transaction Overview'!$H$2:$H$467,F$4) -> 0 | G6: =SUMIFS('Transaction Overview'!$D$2:$D$467,'Transaction Overview'!$I$2:$I$467,$A6,'Transaction Overview'!$H$2:$H$467,G$4) -> 0 | H6: =SUM(B6:G6) -> -10000
A7: Deal Specific: Austin Iron | B7: =SUMIFS('Transaction Overview'!$D$2:$D$467,'Transaction Overview'!$I$2:$I$467,$A7,'Transaction Overview'!$H$2:$H$467,B$4) -> 350 | C7: =SUMIFS('Transaction Overview'!$D$2:$D$467,'Transaction Overview'!$I$2:$I$467,$A7,'Transaction Overview'!$H$2:$H$467,C$4) -> 350 | D7: =SUMIFS('Transaction Overview'!$D$2:$D$467,'Transaction Overview'!$I$2:$I$467,$A7,'Transaction Overview'!$H$2:$H$467,D$4) -> 350 | E7: =SUMIFS('Transaction Overview'!$D$2:$D$467,'Transaction Overview'!$I$2:$I$467,$A7,'Transaction Overview'!$H$2:$H$467,E$4) -> 350 | F7: =SUMIFS('Transaction Overview'!$D$2:$D$467,'Transaction Overview'!$I$2:$I$467,$A7,'Transaction Overview'!$H$2:$H$467,F$4) -> 350 | G7: =SUMIFS('Transaction Overview'!$D$2:$D$467,'Transaction Overview'!$I$2:$I$467,$A7,'Transaction Overview'!$H$2:$H$467,G$4) -> 350 | H7: =SUM(B7:G7) -> 2100
A8: Deal Specific: MRM | B8: =SUMIFS('Transaction Overview'!$D$2:$D$467,'Transaction Overview'!$I$2:$I$467,$A8,'Transaction Overview'!$H$2:$H$467,B$4) -> 241.87 | C8: =SUMIFS('Transaction Overview'!$D$2:$D$467,'Transaction Overview'!$I$2:$I$467,$A8,'Transaction Overview'!$H$2:$H$467,C$4) -> 241.87 | D8: =SUMIFS('Transaction Overview'!$D$2:$D$467,'Transaction Overview'!$I$2:$I$467,$A8,'Transaction Overview'!$H$2:$H$467,D$4) -> 241.87 | E8: =SUMIFS('Transaction Overview'!$D$2:$D$467,'Transaction Overview'!$I$2:$I$467,$A8,'Transaction Overview'!$H$2:$H$467,E$4) -> 0 | F8: =SUMIFS('Transaction Overview'!$D$2:$D$467,'Transaction Overview'!$I$2:$I$467,$A8,'Transaction Overview'!$H$2:$H$467,F$4) -> 0 | G8: =SUMIFS('Transaction Overview'!$D$2:$D$467,'Transaction Overview'!$I$2:$I$467,$A8,'Transaction Overview'!$H$2:$H$467,G$4) -> 0 | H8: =SUM(B8:G8) -> 725.61
A9: Deal Specific: Merit-Lancaster | B9: =SUMIFS('Transaction Overview'!$D$2:$D$467,'Transaction Overview'!$I$2:$I$467,$A9,'Transaction Overview'!$H$2:$H$467,B$4) -> 476.41 | C9: =SUMIFS('Transaction Overview'!$D$2:$D$467,'Transaction Overview'!$I$2:$I$467,$A9,'Transaction Overview'!$H$2:$H$467,C$4) -> 476.41 | D9: =SUMIFS('Transaction Overview'!$D$2:$D$467,'Transaction Overview'!$I$2:$I$467,$A9,'Transaction Overview'!$H$2:$H$467,D$4) -> 491.29 | E9: =SUMIFS('Transaction Overview'!$D$2:$D$467,'Transaction Overview'!$I$2:$I$467,$A9,'Transaction Overview'!$H$2:$H$467,E$4) -> 491.29 | F9: =SUMIFS('Transaction Overview'!$D$2:$D$467,'Transaction Overview'!$I$2:$I$467,$A9,'Transaction Overview'!$H$2:$H$467,F$4) -> 491.29 | G9: =SUMIFS('Transaction Overview'!$D$2:$D$467,'Transaction Overview'!$I$2:$I$467,$A9,'Transaction Overview'!$H$2:$H$467,G$4) -> 491.29 | H9: =SUM(B9:G9) -> 2917.98
A10: Deal Specific: Rabourn Road | B10: =SUMIFS('Transaction Overview'!$D$2:$D$467,'Transaction Overview'!$I$2:$I$467,$A10,'Transaction Overview'!$H$2:$H$467,B$4) -> 233.33 | C10: =SUMIFS('Transaction Overview'!$D$2:$D$467,'Transaction Overview'!$I$2:$I$467,$A10,'Transaction Overview'!$H$2:$H$467,C$4) -> 233.33 | D10: =SUMIFS('Transaction Overview'!$D$2:$D$467,'Transaction Overview'!$I$2:$I$467,$A10,'Transaction Overview'!$H$2:$H$467,D$4) -> 233.33 | E10: =SUMIFS('Transaction Overview'!$D$2:$D$467,'Transaction Overview'!$I$2:$I$467,$A10,'Transaction Overview'!$H$2:$H$467,E$4) -> 233.33 | F10: =SUMIFS('Transaction Overview'!$D$2:$D$467,'Transaction Overview'!$I$2:$I$467,$A10,'Transaction Overview'!$H$2:$H$467,F$4) -> 233.33 | G10: =SUMIFS('Transaction Overview'!$D$2:$D$467,'Transaction Overview'!$I$2:$I$467,$A10,'Transaction Overview'!$H$2:$H$467,G$4) -> 233.33 | H10: =SUM(B10:G10) -> 1399.98
A11: Deal Specific: T&T Machine | B11: =SUMIFS('Transaction Overview'!$D$2:$D$467,'Transaction Overview'!$I$2:$I$467,$A11,'Transaction Overview'!$H$2:$H$467,B$4) -> 356.38 | C11: =SUMIFS('Transaction Overview'!$D$2:$D$467,'Transaction Overview'!$I$2:$I$467,$A11,'Transaction Overview'!$H$2:$H$467,C$4) -> 367.52 | D11: =SUMIFS('Transaction Overview'!$D$2:$D$467,'Transaction Overview'!$I$2:$I$467,$A11,'Transaction Overview'!$H$2:$H$467,D$4) -> 367.52 | E11: =SUMIFS('Transaction Overview'!$D$2:$D$467,'Transaction Overview'!$I$2:$I$467,$A11,'Transaction Overview'!$H$2:$H$467,E$4) -> 0 | F11: =SUMIFS('Transaction Overview'!$D$2:$D$467,'Transaction Overview'!$I$2:$I$467,$A11,'Transaction Overview'!$H$2:$H$467,F$4) -> 0 | G11: =SUMIFS('Transaction Overview'!$D$2:$D$467,'Transaction Overview'!$I$2:$I$467,$A11,'Transaction Overview'!$H$2:$H$467,G$4) -> 0 | H11: =SUM(B11:G11) -> 1091.42
A12: Subtotal — Deal-Specific | B12: =SUM(B6:B11) -> -8342.01 | C12: =SUM(C6:C11) -> 1669.13 | D12: =SUM(D6:D11) -> 1684.01 | E12: =SUM(E6:E11) -> 1074.62 | F12: =SUM(F6:F11) -> 1074.62 | G12: =SUM(G6:G11) -> 1074.62 | H12: =SUM(H6:H11) -> -1765.01
A14: Commissions — Incoming
A15: Incoming Commission: Rembrandt | B15: =SUMIFS('Transaction Overview'!$D$2:$D$467,'Transaction Overview'!$I$2:$I$467,$A15,'Transaction Overview'!$H$2:$H$467,B$4) -> 0 | C15: =SUMIFS('Transaction Overview'!$D$2:$D$467,'Transaction Overview'!$I$2:$I$467,$A15,'Transaction Overview'!$H$2:$H$467,C$4) -> 168266 | D15: =SUMIFS('Transaction Overview'!$D$2:$D$467,'Transaction Overview'!$I$2:$I$467,$A15,'Transaction Overview'!$H$2:$H$467,D$4) -> 0 | E15: =SUMIFS('Transaction Overview'!$D$2:$D$467,'Transaction Overview'!$I$2:$I$467,$A15,'Transaction Overview'!$H$2:$H$467,E$4) -> 0 | F15: =SUMIFS('Transaction Overview'!$D$2:$D$467,'Transaction Overview'!$I$2:$I$467,$A15,'Transaction Overview'!$H$2:$H$467,F$4) -> 0 | G15: =SUMIFS('Transaction Overview'!$D$2:$D$467,'Transaction Overview'!$I$2:$I$467,$A15,'Transaction Overview'!$H$2:$H$467,G$4) -> 0 | H15: =SUM(B15:G15) -> 168266
A16: Incoming Commission: SPF | B16: =SUMIFS('Transaction Overview'!$D$2:$D$467,'Transaction Overview'!$I$2:$I$467,$A16,'Transaction Overview'!$H$2:$H$467,B$4) -> 0 | C16: =SUMIFS('Transaction Overview'!$D$2:$D$467,'Transaction Overview'!$I$2:$I$467,$A16,'Transaction Overview'!$H$2:$H$467,C$4) -> 0 | D16: =SUMIFS('Transaction Overview'!$D$2:$D$467,'Transaction Overview'!$I$2:$I$467,$A16,'Transaction Overview'!$H$2:$H$467,D$4) -> 0 | E16: =SUMIFS('Transaction Overview'!$D$2:$D$467,'Transaction Overview'!$I$2:$I$467,$A16,'Transaction Overview'!$H$2:$H$467,E$4) -> 266889.44 | F16: =SUMIFS('Transaction Overview'!$D$2:$D$467,'Transaction Overview'!$I$2:$I$467,$A16,'Transaction Overview'!$H$2:$H$467,F$4) -> 0 | G16: =SUMIFS('Transaction Overview'!$D$2:$D$467,'Transaction Overview'!$I$2:$I$467,$A16,'Transaction Overview'!$H$2:$H$467,G$4) -> 0 | H16: =SUM(B16:G16) -> 266889.44
A17: Subtotal — Commissions — Incoming | B17: =SUM(B15:B16) -> 0 | C17: =SUM(C15:C16) -> 168266 | D17: =SUM(D15:D16) -> 0 | E17: =SUM(E15:E16) -> 266889.44 | F17: =SUM(F15:F16) -> 0 | G17: =SUM(G15:G16) -> 0 | H17: =SUM(H15:H16) -> 435155.44
A19: Commissions — Outgoing
A20: Kevin Wong Commission (SPF) | B20: =SUMIFS('Transaction Overview'!$D$2:$D$467,'Transaction Overview'!$I$2:$I$467,$A20,'Transaction Overview'!$H$2:$H$467,B$4) -> 0 | C20: =SUMIFS('Transaction Overview'!$D$2:$D$467,'Transaction Overview'!$I$2:$I$467,$A20,'Transaction Overview'!$H$2:$H$467,C$4) -> 0 | D20: =SUMIFS('Transaction Overview'!$D$2:$D$467,'Transaction Overview'!$I$2:$I$467,$A20,'Transaction Overview'!$H$2:$H$467,D$4) -> 0 | E20: =SUMIFS('Transaction Overview'!$D$2:$D$467,'Transaction Overview'!$I$2:$I$467,$A20,'Transaction Overview'!$H$2:$H$467,E$4) -> -16087.5 | F20: =SUMIFS('Transaction Overview'!$D$2:$D$467,'Transaction Overview'!$I$2:$I$467,$A20,'Transaction Overview'!$H$2:$H$467,F$4) -> 0 | G20: =SUMIFS('Transaction Overview'!$D$2:$D$467,'Transaction Overview'!$I$2:$I$467,$A20,'Transaction Overview'!$H$2:$H$467,G$4) -> 0 | H20: =SUM(B20:G20) -> -16087.5
A21: Kevin Wong Commission (Steve Klar) | B21: =SUMIFS('Transaction Overview'!$D$2:$D$467,'Transaction Overview'!$I$2:$I$467,$A21,'Transaction Overview'!$H$2:$H$467,B$4) -> -6000 | C21: =SUMIFS('Transaction Overview'!$D$2:$D$467,'Transaction Overview'!$I$2:$I$467,$A21,'Transaction Overview'!$H$2:$H$467,C$4) -> 0 | D21: =SUMIFS('Transaction Overview'!$D$2:$D$467,'Transaction Overview'!$I$2:$I$467,$A21,'Transaction Overview'!$H$2:$H$467,D$4) -> 0 | E21: =SUMIFS('Transaction Overview'!$D$2:$D$467,'Transaction Overview'!$I$2:$I$467,$A21,'Transaction Overview'!$H$2:$H$467,E$4) -> 0 | F21: =SUMIFS('Transaction Overview'!$D$2:$D$467,'Transaction Overview'!$I$2:$I$467,$A21,'Transaction Overview'!$H$2:$H$467,F$4) -> 0 | G21: =SUMIFS('Transaction Overview'!$D$2:$D$467,'Transaction Overview'!$I$2:$I$467,$A21,'Transaction Overview'!$H$2:$H$467,G$4) -> 0 | H21: =SUM(B21:G21) -> -6000
A22: Meg Maran - MDC Commission | B22: =SUMIFS('Transaction Overview'!$D$2:$D$467,'Transaction Overview'!$I$2:$I$467,$A22,'Transaction Overview'!$H$2:$H$467,B$4) -> 0 | C22: =SUMIFS('Transaction Overview'!$D$2:$D$467,'Transaction Overview'!$I$2:$I$467,$A22,'Transaction Overview'!$H$2:$H$467,C$4) -> 0 | D22: =SUMIFS('Transaction Overview'!$D$2:$D$467,'Transaction Overview'!$I$2:$I$467,$A22,'Transaction Overview'!$H$2:$H$467,D$4) -> 0 | E22: =SUMIFS('Transaction Overview'!$D$2:$D$467,'Transaction Overview'!$I$2:$I$467,$A22,'Transaction Overview'!$H$2:$H$467,E$4) -> -1500 | F22: =SUMIFS('Transaction Overview'!$D$2:$D$467,'Transaction Overview'!$I$2:$I$467,$A22,'Transaction Overview'!$H$2:$H$467,F$4) -> 0 | G22: =SUMIFS('Transaction Overview'!$D$2:$D$467,'Transaction Overview'!$I$2:$I$467,$A22,'Transaction Overview'!$H$2:$H$467,G$4) -> 0 | H22: =SUM(B22:G22) -> -1500
A23: Subtotal — Commissions — Outgoing | B23: =SUM(B20:B22) -> -6000 | C23: =SUM(C20:C22) -> 0 | D23: =SUM(D20:D22) -> 0 | E23: =SUM(E20:E22) -> -17587.5 | F23: =SUM(F20:F22) -> 0 | G23: =SUM(G20:G22) -> 0 | H23: =SUM(H20:H22) -> -23587.5
A25: MAG Pass-Through
A26: MAG - Admeer Advisory Reimbursement | B26: =SUMIFS('Transaction Overview'!$D$2:$D$467,'Transaction Overview'!$I$2:$I$467,$A26,'Transaction Overview'!$H$2:$H$467,B$4) -> 0 | C26: =SUMIFS('Transaction Overview'!$D$2:$D$467,'Transaction Overview'!$I$2:$I$467,$A26,'Transaction Overview'!$H$2:$H$467,C$4) -> 5000 | D26: =SUMIFS('Transaction Overview'!$D$2:$D$467,'Transaction Overview'!$I$2:$I$467,$A26,'Transaction Overview'!$H$2:$H$467,D$4) -> 0 | E26: =SUMIFS('Transaction Overview'!$D$2:$D$467,'Transaction Overview'!$I$2:$I$467,$A26,'Transaction Overview'!$H$2:$H$467,E$4) -> 0 | F26: =SUMIFS('Transaction Overview'!$D$2:$D$467,'Transaction Overview'!$I$2:$I$467,$A26,'Transaction Overview'!$H$2:$H$467,F$4) -> 0 | G26: =SUMIFS('Transaction Overview'!$D$2:$D$467,'Transaction Overview'!$I$2:$I$467,$A26,'Transaction Overview'!$H$2:$H$467,G$4) -> 0 | H26: =SUM(B26:G26) -> 5000
A27: MAG - Admeer Advisory Transfer | B27: =SUMIFS('Transaction Overview'!$D$2:$D$467,'Transaction Overview'!$I$2:$I$467,$A27,'Transaction Overview'!$H$2:$H$467,B$4) -> 0 | C27: =SUMIFS('Transaction Overview'!$D$2:$D$467,'Transaction Overview'!$I$2:$I$467,$A27,'Transaction Overview'!$H$2:$H$467,C$4) -> -5000 | D27: =SUMIFS('Transaction Overview'!$D$2:$D$467,'Transaction Overview'!$I$2:$I$467,$A27,'Transaction Overview'!$H$2:$H$467,D$4) -> 0 | E27: =SUMIFS('Transaction Overview'!$D$2:$D$467,'Transaction Overview'!$I$2:$I$467,$A27,'Transaction Overview'!$H$2:$H$467,E$4) -> -5000 | F27: =SUMIFS('Transaction Overview'!$D$2:$D$467,'Transaction Overview'!$I$2:$I$467,$A27,'Transaction Overview'!$H$2:$H$467,F$4) -> 0 | G27: =SUMIFS('Transaction Overview'!$D$2:$D$467,'Transaction Overview'!$I$2:$I$467,$A27,'Transaction Overview'!$H$2:$H$467,G$4) -> 0 | H27: =SUM(B27:G27) -> -10000
A28: MAG Marketing Reimbursement | B28: =SUMIFS('Transaction Overview'!$D$2:$D$467,'Transaction Overview'!$I$2:$I$467,$A28,'Transaction Overview'!$H$2:$H$467,B$4) -> 0 | C28: =SUMIFS('Transaction Overview'!$D$2:$D$467,'Transaction Overview'!$I$2:$I$467,$A28,'Transaction Overview'!$H$2:$H$467,C$4) -> 0 | D28: =SUMIFS('Transaction Overview'!$D$2:$D$467,'Transaction Overview'!$I$2:$I$467,$A28,'Transaction Overview'!$H$2:$H$467,D$4) -> 0 | E28: =SUMIFS('Transaction Overview'!$D$2:$D$467,'Transaction Overview'!$I$2:$I$467,$A28,'Transaction Overview'!$H$2:$H$467,E$4) -> 15000 | F28: =SUMIFS('Transaction Overview'!$D$2:$D$467,'Transaction Overview'!$I$2:$I$467,$A28,'Transaction Overview'!$H$2:$H$467,F$4) -> 0 | G28: =SUMIFS('Transaction Overview'!$D$2:$D$467,'Transaction Overview'!$I$2:$I$467,$A28,'Transaction Overview'!$H$2:$H$467,G$4) -> 0 | H28: =SUM(B28:G28) -> 15000
A29: Subtotal — MAG Pass-Through | B29: =SUM(B26:B28) -> 0 | C29: =SUM(C26:C28) -> 0 | D29: =SUM(D26:D28) -> 0 | E29: =SUM(E26:E28) -> 10000 | F29: =SUM(F26:F28) -> 0 | G29: =SUM(G26:G28) -> 0 | H29: =SUM(H26:H28) -> 10000
A31: Wire Transfers — Incoming
A32: Incoming wire from JC Whitner | B32: =SUMIFS('Transaction Overview'!$D$2:$D$467,'Transaction Overview'!$I$2:$I$467,$A32,'Transaction Overview'!$H$2:$H$467,B$4) -> 0 | C32: =SUMIFS('Transaction Overview'!$D$2:$D$467,'Transaction Overview'!$I$2:$I$467,$A32,'Transaction Overview'!$H$2:$H$467,C$4) -> 20000 | D32: =SUMIFS('Transaction Overview'!$D$2:$D$467,'Transaction Overview'!$I$2:$I$467,$A32,'Transaction Overview'!$H$2:$H$467,D$4) -> 0 | E32: =SUMIFS('Transaction Overview'!$D$2:$D$467,'Transaction Overview'!$I$2:$I$467,$A32,'Transaction Overview'!$H$2:$H$467,E$4) -> 0 | F32: =SUMIFS('Transaction Overview'!$D$2:$D$467,'Transaction Overview'!$I$2:$I$467,$A32,'Transaction Overview'!$H$2:$H$467,F$4) -> 0 | G32: =SUMIFS('Transaction Overview'!$D$2:$D$467,'Transaction Overview'!$I$2:$I$467,$A32,'Transaction Overview'!$H$2:$H$467,G$4) -> 0 | H32: =SUM(B32:G32) -> 20000
A33: Incoming wire from Moab (Leftover Funds) | B33: =SUMIFS('Transaction Overview'!$D$2:$D$467,'Transaction Overview'!$I$2:$I$467,$A33,'Transaction Overview'!$H$2:$H$467,B$4) -> 0 | C33: =SUMIFS('Transaction Overview'!$D$2:$D$467,'Transaction Overview'!$I$2:$I$467,$A33,'Transaction Overview'!$H$2:$H$467,C$4) -> 58370.85 | D33: =SUMIFS('Transaction Overview'!$D$2:$D$467,'Transaction Overview'!$I$2:$I$467,$A33,'Transaction Overview'!$H$2:$H$467,D$4) -> 0 | E33: =SUMIFS('Transaction Overview'!$D$2:$D$467,'Transaction Overview'!$I$2:$I$467,$A33,'Transaction Overview'!$H$2:$H$467,E$4) -> 0 | F33: =SUMIFS('Transaction Overview'!$D$2:$D$467,'Transaction Overview'!$I$2:$I$467,$A33,'Transaction Overview'!$H$2:$H$467,F$4) -> 0 | G33: =SUMIFS('Transaction Overview'!$D$2:$D$467,'Transaction Overview'!$I$2:$I$467,$A33,'Transaction Overview'!$H$2:$H$467,G$4) -> 0 | H33: =SUM(B33:G33) -> 58370.85
A34: Incoming wire from Steve Klar | B34: =SUMIFS('Transaction Overview'!$D$2:$D$467,'Transaction Overview'!$I$2:$I$467,$A34,'Transaction Overview'!$H$2:$H$467,B$4) -> 16000 | C34: =SUMIFS('Transaction Overview'!$D$2:$D$467,'Transaction Overview'!$I$2:$I$467,$A34,'Transaction Overview'!$H$2:$H$467,C$4) -> 0 | D34: =SUMIFS('Transaction Overview'!$D$2:$D$467,'Transaction Overview'!$I$2:$I$467,$A34,'Transaction Overview'!$H$2:$H$467,D$4) -> 0 | E34: =SUMIFS('Transaction Overview'!$D$2:$D$467,'Transaction Overview'!$I$2:$I$467,$A34,'Transaction Overview'!$H$2:$H$467,E$4) -> 0 | F34: =SUMIFS('Transaction Overview'!$D$2:$D$467,'Transaction Overview'!$I$2:$I$467,$A34,'Transaction Overview'!$H$2:$H$467,F$4) -> 0 | G34: =SUMIFS('Transaction Overview'!$D$2:$D$467,'Transaction Overview'!$I$2:$I$467,$A34,'Transaction Overview'!$H$2:$H$467,G$4) -> 0 | H34: =SUM(B34:G34) -> 16000
A35: Subtotal — Wire Transfers — Incoming | B35: =SUM(B32:B34) -> 16000 | C35: =SUM(C32:C34) -> 78370.85 | D35: =SUM(D32:D34) -> 0 | E35: =SUM(E32:E34) -> 0 | F35: =SUM(F32:F34) -> 0 | G35: =SUM(G32:G34) -> 0 | H35: =SUM(H32:H34) -> 94370.85
A37: Wire Transfers — Outgoing
A38: Wire to Gi Capital Group (+ Moab Funds) | B38: =SUMIFS('Transaction Overview'!$D$2:$D$467,'Transaction Overview'!$I$2:$I$467,$A38,'Transaction Overview'!$H$2:$H$467,B$4) -> 0 | C38: =SUMIFS('Transaction Overview'!$D$2:$D$467,'Transaction Overview'!$I$2:$I$467,$A38,'Transaction Overview'!$H$2:$H$467,C$4) -> -56670.85 | D38: =SUMIFS('Transaction Overview'!$D$2:$D$467,'Transaction Overview'!$I$2:$I$467,$A38,'Transaction Overview'!$H$2:$H$467,D$4) -> 0 | E38: =SUMIFS('Transaction Overview'!$D$2:$D$467,'Transaction Overview'!$I$2:$I$467,$A38,'Transaction Overview'!$H$2:$H$467,E$4) -> 0 | F38: =SUMIFS('Transaction Overview'!$D$2:$D$467,'Transaction Overview'!$I$2:$I$467,$A38,'Transaction Overview'!$H$2:$H$467,F$4) -> 0 | G38: =SUMIFS('Transaction Overview'!$D$2:$D$467,'Transaction Overview'!$I$2:$I$467,$A38,'Transaction Overview'!$H$2:$H$467,G$4) -> 0 | H38: =SUM(B38:G38) -> -56670.85
A39: Wire to Jon Brandon | B39: =SUMIFS('Transaction Overview'!$D$2:$D$467,'Transaction Overview'!$I$2:$I$467,$A39,'Transaction Overview'!$H$2:$H$467,B$4) -> 0 | C39: =SUMIFS('Transaction Overview'!$D$2:$D$467,'Transaction Overview'!$I$2:$I$467,$A39,'Transaction Overview'!$H$2:$H$467,C$4) -> -10000 | D39: =SUMIFS('Transaction Overview'!$D$2:$D$467,'Transaction Overview'!$I$2:$I$467,$A39,'Transaction Overview'!$H$2:$H$467,D$4) -> 0 | E39: =SUMIFS('Transaction Overview'!$D$2:$D$467,'Transaction Overview'!$I$2:$I$467,$A39,'Transaction Overview'!$H$2:$H$467,E$4) -> 0 | F39: =SUMIFS('Transaction Overview'!$D$2:$D$467,'Transaction Overview'!$I$2:$I$467,$A39,'Transaction Overview'!$H$2:$H$467,F$4) -> 0 | G39: =SUMIFS('Transaction Overview'!$D$2:$D$467,'Transaction Overview'!$I$2:$I$467,$A39,'Transaction Overview'!$H$2:$H$467,G$4) -> 0 | H39: =SUM(B39:G39) -> -10000
A40: Wire to Ryan Bodmer | B40: =SUMIFS('Transaction Overview'!$D$2:$D$467,'Transaction Overview'!$I$2:$I$467,$A40,'Transaction Overview'!$H$2:$H$467,B$4) -> 0 | C40: =SUMIFS('Transaction Overview'!$D$2:$D$467,'Transaction Overview'!$I$2:$I$467,$A40,'Transaction Overview'!$H$2:$H$467,C$4) -> -10000 | D40: =SUMIFS('Transaction Overview'!$D$2:$D$467,'Transaction Overview'!$I$2:$I$467,$A40,'Transaction Overview'!$H$2:$H$467,D$4) -> 0 | E40: =SUMIFS('Transaction Overview'!$D$2:$D$467,'Transaction Overview'!$I$2:$I$467,$A40,'Transaction Overview'!$H$2:$H$467,E$4) -> 0 | F40: =SUMIFS('Transaction Overview'!$D$2:$D$467,'Transaction Overview'!$I$2:$I$467,$A40,'Transaction Overview'!$H$2:$H$467,F$4) -> 0 | G40: =SUMIFS('Transaction Overview'!$D$2:$D$467,'Transaction Overview'!$I$2:$I$467,$A40,'Transaction Overview'!$H$2:$H$467,G$4) -> 0 | H40: =SUM(B40:G40) -> -10000
A41: Subtotal — Wire Transfers — Outgoing | B41: =SUM(B38:B40) -> 0 | C41: =SUM(C38:C40) -> -76670.85 | D41: =SUM(D38:D40) -> 0 | E41: =SUM(E38:E40) -> 0 | F41: =SUM(F38:F40) -> 0 | G41: =SUM(G38:G40) -> 0 | H41: =SUM(H38:H40) -> -76670.85
A43: Intercompany & Savings Transfers
A44: Transfer From DWG Capital Group | B44: =SUMIFS('Transaction Overview'!$D$2:$D$467,'Transaction Overview'!$I$2:$I$467,$A44,'Transaction Overview'!$H$2:$H$467,B$4) -> 0 | C44: =SUMIFS('Transaction Overview'!$D$2:$D$467,'Transaction Overview'!$I$2:$I$467,$A44,'Transaction Overview'!$H$2:$H$467,C$4) -> 8556.41 | D44: =SUMIFS('Transaction Overview'!$D$2:$D$467,'Transaction Overview'!$I$2:$I$467,$A44,'Transaction Overview'!$H$2:$H$467,D$4) -> 0 | E44: =SUMIFS('Transaction Overview'!$D$2:$D$467,'Transaction Overview'!$I$2:$I$467,$A44,'Transaction Overview'!$H$2:$H$467,E$4) -> 0 | F44: =SUMIFS('Transaction Overview'!$D$2:$D$467,'Transaction Overview'!$I$2:$I$467,$A44,'Transaction Overview'!$H$2:$H$467,F$4) -> 0 | G44: =SUMIFS('Transaction Overview'!$D$2:$D$467,'Transaction Overview'!$I$2:$I$467,$A44,'Transaction Overview'!$H$2:$H$467,G$4) -> 0 | H44: =SUM(B44:G44) -> 8556.41
A45: Transfer From Poseidon | B45: =SUMIFS('Transaction Overview'!$D$2:$D$467,'Transaction Overview'!$I$2:$I$467,$A45,'Transaction Overview'!$H$2:$H$467,B$4) -> 2000 | C45: =SUMIFS('Transaction Overview'!$D$2:$D$467,'Transaction Overview'!$I$2:$I$467,$A45,'Transaction Overview'!$H$2:$H$467,C$4) -> 0 | D45: =SUMIFS('Transaction Overview'!$D$2:$D$467,'Transaction Overview'!$I$2:$I$467,$A45,'Transaction Overview'!$H$2:$H$467,D$4) -> 0 | E45: =SUMIFS('Transaction Overview'!$D$2:$D$467,'Transaction Overview'!$I$2:$I$467,$A45,'Transaction Overview'!$H$2:$H$467,E$4) -> 0 | F45: =SUMIFS('Transaction Overview'!$D$2:$D$467,'Transaction Overview'!$I$2:$I$467,$A45,'Transaction Overview'!$H$2:$H$467,F$4) -> 0 | G45: =SUMIFS('Transaction Overview'!$D$2:$D$467,'Transaction Overview'!$I$2:$I$467,$A45,'Transaction Overview'!$H$2:$H$467,G$4) -> 0 | H45: =SUM(B45:G45) -> 2000
A46: Transfer From SPF | B46: =SUMIFS('Transaction Overview'!$D$2:$D$467,'Transaction Overview'!$I$2:$I$467,$A46,'Transaction Overview'!$H$2:$H$467,B$4) -> 0 | C46: =SUMIFS('Transaction Overview'!$D$2:$D$467,'Transaction Overview'!$I$2:$I$467,$A46,'Transaction Overview'!$H$2:$H$467,C$4) -> 0 | D46: =SUMIFS('Transaction Overview'!$D$2:$D$467,'Transaction Overview'!$I$2:$I$467,$A46,'Transaction Overview'!$H$2:$H$467,D$4) -> 0 | E46: =SUMIFS('Transaction Overview'!$D$2:$D$467,'Transaction Overview'!$I$2:$I$467,$A46,'Transaction Overview'!$H$2:$H$467,E$4) -> 11450 | F46: =SUMIFS('Transaction Overview'!$D$2:$D$467,'Transaction Overview'!$I$2:$I$467,$A46,'Transaction Overview'!$H$2:$H$467,F$4) -> 0 | G46: =SUMIFS('Transaction Overview'!$D$2:$D$467,'Transaction Overview'!$I$2:$I$467,$A46,'Transaction Overview'!$H$2:$H$467,G$4) -> 0 | H46: =SUM(B46:G46) -> 11450
A47: Transfer From Stryten | B47: =SUMIFS('Transaction Overview'!$D$2:$D$467,'Transaction Overview'!$I$2:$I$467,$A47,'Transaction Overview'!$H$2:$H$467,B$4) -> 0 | C47: =SUMIFS('Transaction Overview'!$D$2:$D$467,'Transaction Overview'!$I$2:$I$467,$A47,'Transaction Overview'!$H$2:$H$467,C$4) -> 50000 | D47: =SUMIFS('Transaction Overview'!$D$2:$D$467,'Transaction Overview'!$I$2:$I$467,$A47,'Transaction Overview'!$H$2:$H$467,D$4) -> 50000 | E47: =SUMIFS('Transaction Overview'!$D$2:$D$467,'Transaction Overview'!$I$2:$I$467,$A47,'Transaction Overview'!$H$2:$H$467,E$4) -> 0 | F47: =SUMIFS('Transaction Overview'!$D$2:$D$467,'Transaction Overview'!$I$2:$I$467,$A47,'Transaction Overview'!$H$2:$H$467,F$4) -> 0 | G47: =SUMIFS('Transaction Overview'!$D$2:$D$467,'Transaction Overview'!$I$2:$I$467,$A47,'Transaction Overview'!$H$2:$H$467,G$4) -> 0 | H47: =SUM(B47:G47) -> 100000
...

Sheet Monthly Detail
A1: Chase 9335 — 2026 Activity
A2: Monthly Detail — Spend by Individual Category | Jan 2026 – Jun 2026
A4: Category | B4: Group | C4: =DATE(2026,1,1) -> 46023 | D4: =DATE(2026,2,1) -> 46054 | E4: =DATE(2026,3,1) -> 46082 | F4: =DATE(2026,4,1) -> 46113 | G4: =DATE(2026,5,1) -> 46143 | H4: =DATE(2026,6,1) -> 46174 | I4: Total
A5: Bridge Coverage (JC Whitner) | B5: Deal-Specific | C5: =SUMIFS('Transaction Overview'!$D$2:$D$467,'Transaction Overview'!$G$2:$G$467,$A5,'Transaction Overview'!$H$2:$H$467,C$4) -> -10000 | D5: =SUMIFS('Transaction Overview'!$D$2:$D$467,'Transaction Overview'!$G$2:$G$467,$A5,'Transaction Overview'!$H$2:$H$467,D$4) -> 0 | E5: =SUMIFS('Transaction Overview'!$D$2:$D$467,'Transaction Overview'!$G$2:$G$467,$A5,'Transaction Overview'!$H$2:$H$467,E$4) -> 0 | F5: =SUMIFS('Transaction Overview'!$D$2:$D$467,'Transaction Overview'!$G$2:$G$467,$A5,'Transaction Overview'!$H$2:$H$467,F$4) -> 0 | G5: =SUMIFS('Transaction Overview'!$D$2:$D$467,'Transaction Overview'!$G$2:$G$467,$A5,'Transaction Overview'!$H$2:$H$467,G$4) -> 0 | H5: =SUMIFS('Transaction Overview'!$D$2:$D$467,'Transaction Overview'!$G$2:$G$467,$A5,'Transaction Overview'!$H$2:$H$467,H$4) -> 0 | I5: =SUM(C5:H5) -> -10000
A6: Deal Specific: Austin Iron | B6: Deal-Specific | C6: =SUMIFS('Transaction Overview'!$D$2:$D$467,'Transaction Overview'!$G$2:$G$467,$A6,'Transaction Overview'!$H$2:$H$467,C$4) -> 350 | D6: =SUMIFS('Transaction Overview'!$D$2:$D$467,'Transaction Overview'!$G$2:$G$467,$A6,'Transaction Overview'!$H$2:$H$467,D$4) -> 350 | E6: =SUMIFS('Transaction Overview'!$D$2:$D$467,'Transaction Overview'!$G$2:$G$467,$A6,'Transaction Overview'!$H$2:$H$467,E$4) -> 350 | F6: =SUMIFS('Transaction Overview'!$D$2:$D$467,'Transaction Overview'!$G$2:$G$467,$A6,'Transaction Overview'!$H$2:$H$467,F$4) -> 350 | G6: =SUMIFS('Transaction Overview'!$D$2:$D$467,'Transaction Overview'!$G$2:$G$467,$A6,'Transaction Overview'!$H$2:$H$467,G$4) -> 350 | H6: =SUMIFS('Transaction Overview'!$D$2:$D$467,'Transaction Overview'!$G$2:$G$467,$A6,'Transaction Overview'!$H$2:$H$467,H$4) -> 350 | I6: =SUM(C6:H6) -> 2100
A7: Deal Specific: MRM | B7: Deal-Specific | C7: =SUMIFS('Transaction Overview'!$D$2:$D$467,'Transaction Overview'!$G$2:$G$467,$A7,'Transaction Overview'!$H$2:$H$467,C$4) -> 241.87 | D7: =SUMIFS('Transaction Overview'!$D$2:$D$467,'Transaction Overview'!$G$2:$G$467,$A7,'Transaction Overview'!$H$2:$H$467,D$4) -> 241.87 | E7: =SUMIFS('Transaction Overview'!$D$2:$D$467,'Transaction Overview'!$G$2:$G$467,$A7,'Transaction Overview'!$H$2:$H$467,E$4) -> 241.87 | F7: =SUMIFS('Transaction Overview'!$D$2:$D$467,'Transaction Overview'!$G$2:$G$467,$A7,'Transaction Overview'!$H$2:$H$467,F$4) -> 0 | G7: =SUMIFS('Transaction Overview'!$D$2:$D$467,'Transaction Overview'!$G$2:$G$467,$A7,'Transaction Overview'!$H$2:$H$467,G$4) -> 0 | H7: =SUMIFS('Transaction Overview'!$D$2:$D$467,'Transaction Overview'!$G$2:$G$467,$A7,'Transaction Overview'!$H$2:$H$467,H$4) -> 0 | I7: =SUM(C7:H7) -> 725.61
A8: Deal Specific: Merit-Lancaster | B8: Deal-Specific | C8: =SUMIFS('Transaction Overview'!$D$2:$D$467,'Transaction Overview'!$G$2:$G$467,$A8,'Transaction Overview'!$H$2:$H$467,C$4) -> 476.41 | D8: =SUMIFS('Transaction Overview'!$D$2:$D$467,'Transaction Overview'!$G$2:$G$467,$A8,'Transaction Overview'!$H$2:$H$467,D$4) -> 476.41 | E8: =SUMIFS('Transaction Overview'!$D$2:$D$467,'Transaction Overview'!$G$2:$G$467,$A8,'Transaction Overview'!$H$2:$H$467,E$4) -> 491.29 | F8: =SUMIFS('Transaction Overview'!$D$2:$D$467,'Transaction Overview'!$G$2:$G$467,$A8,'Transaction Overview'!$H$2:$H$467,F$4) -> 491.29 | G8: =SUMIFS('Transaction Overview'!$D$2:$D$467,'Transaction Overview'!$G$2:$G$467,$A8,'Transaction Overview'!$H$2:$H$467,G$4) -> 491.29 | H8: =SUMIFS('Transaction Overview'!$D$2:$D$467,'Transaction Overview'!$G$2:$G$467,$A8,'Transaction Overview'!$H$2:$H$467,H$4) -> 491.29 | I8: =SUM(C8:H8) -> 2917.98
A9: Deal Specific: Rabourn Road | B9: Deal-Specific | C9: =SUMIFS('Transaction Overview'!$D$2:$D$467,'Transaction Overview'!$G$2:$G$467,$A9,'Transaction Overview'!$H$2:$H$467,C$4) -> 233.33 | D9: =SUMIFS('Transaction Overview'!$D$2:$D$467,'Transaction Overview'!$G$2:$G$467,$A9,'Transaction Overview'!$H$2:$H$467,D$4) -> 233.33 | E9: =SUMIFS('Transaction Overview'!$D$2:$D$467,'Transaction Overview'!$G$2:$G$467,$A9,'Transaction Overview'!$H$2:$H$467,E$4) -> 233.33 | F9: =SUMIFS('Transaction Overview'!$D$2:$D$467,'Transaction Overview'!$G$2:$G$467,$A9,'Transaction Overview'!$H$2:$H$467,F$4) -> 233.33 | G9: =SUMIFS('Transaction Overview'!$D$2:$D$467,'Transaction Overview'!$G$2:$G$467,$A9,'Transaction Overview'!$H$2:$H$467,G$4) -> 233.33 | H9: =SUMIFS('Transaction Overview'!$D$2:$D$467,'Transaction Overview'!$G$2:$G$467,$A9,'Transaction Overview'!$H$2:$H$467,H$4) -> 233.33 | I9: =SUM(C9:H9) -> 1399.98
A10: Deal Specific: T&T Machine | B10: Deal-Specific | C10: =SUMIFS('Transaction Overview'!$D$2:$D$467,'Transaction Overview'!$G$2:$G$467,$A10,'Transaction Overview'!$H$2:$H$467,C$4) -> 356.38 | D10: =SUMIFS('Transaction Overview'!$D$2:$D$467,'Transaction Overview'!$G$2:$G$467,$A10,'Transaction Overview'!$H$2:$H$467,D$4) -> 367.52 | E10: =SUMIFS('Transaction Overview'!$D$2:$D$467,'Transaction Overview'!$G$2:$G$467,$A10,'Transaction Overview'!$H$2:$H$467,E$4) -> 367.52 | F10: =SUMIFS('Transaction Overview'!$D$2:$D$467,'Transaction Overview'!$G$2:$G$467,$A10,'Transaction Overview'!$H$2:$H$467,F$4) -> 0 | G10: =SUMIFS('Transaction Overview'!$D$2:$D$467,'Transaction Overview'!$G$2:$G$467,$A10,'Transaction Overview'!$H$2:$H$467,G$4) -> 0 | H10: =SUMIFS('Transaction Overview'!$D$2:$D$467,'Transaction Overview'!$G$2:$G$467,$A10,'Transaction Overview'!$H$2:$H$467,H$4) -> 0 | I10: =SUM(C10:H10) -> 1091.42
A11: Incoming Commission: Rembrandt | B11: Commissions — Incoming | C11: =SUMIFS('Transaction Overview'!$D$2:$D$467,'Transaction Overview'!$G$2:$G$467,$A11,'Transaction Overview'!$H$2:$H$467,C$4) -> 0 | D11: =SUMIFS('Transaction Overview'!$D$2:$D$467,'Transaction Overview'!$G$2:$G$467,$A11,'Transaction Overview'!$H$2:$H$467,D$4) -> 168266 | E11: =SUMIFS('Transaction Overview'!$D$2:$D$467,'Transaction Overview'!$G$2:$G$467,$A11,'Transaction Overview'!$H$2:$H$467,E$4) -> 0 | F11: =SUMIFS('Transaction Overview'!$D$2:$D$467,'Transaction Overview'!$G$2:$G$467,$A11,'Transaction Overview'!$H$2:$H$467,F$4) -> 0 | G11: =SUMIFS('Transaction Overview'!$D$2:$D$467,'Transaction Overview'!$G$2:$G$467,$A11,'Transaction Overview'!$H$2:$H$467,G$4) -> 0 | H11: =SUMIFS('Transaction Overview'!$D$2:$D$467,'Transaction Overview'!$G$2:$G$467,$A11,'Transaction Overview'!$H$2:$H$467,H$4) -> 0 | I11: =SUM(C11:H11) -> 168266
A12: Incoming Commission: SPF | B12: Commissions — Incoming | C12: =SUMIFS('Transaction Overview'!$D$2:$D$467,'Transaction Overview'!$G$2:$G$467,$A12,'Transaction Overview'!$H$2:$H$467,C$4) -> 0 | D12: =SUMIFS('Transaction Overview'!$D$2:$D$467,'Transaction Overview'!$G$2:$G$467,$A12,'Transaction Overview'!$H$2:$H$467,D$4) -> 0 | E12: =SUMIFS('Transaction Overview'!$D$2:$D$467,'Transaction Overview'!$G$2:$G$467,$A12,'Transaction Overview'!$H$2:$H$467,E$4) -> 0 | F12: =SUMIFS('Transaction Overview'!$D$2:$D$467,'Transaction Overview'!$G$2:$G$467,$A12,'Transaction Overview'!$H$2:$H$467,F$4) -> 266889.44 | G12: =SUMIFS('Transaction Overview'!$D$2:$D$467,'Transaction Overview'!$G$2:$G$467,$A12,'Transaction Overview'!$H$2:$H$467,G$4) -> 0 | H12: =SUMIFS('Transaction Overview'!$D$2:$D$467,'Transaction Overview'!$G$2:$G$467,$A12,'Transaction Overview'!$H$2:$H$467,H$4) -> 0 | I12: =SUM(C12:H12) -> 266889.44
A13: Kevin Wong Commission (SPF) | B13: Commissions — Outgoing | C13: =SUMIFS('Transaction Overview'!$D$2:$D$467,'Transaction Overview'!$G$2:$G$467,$A13,'Transaction Overview'!$H$2:$H$467,C$4) -> 0 | D13: =SUMIFS('Transaction Overview'!$D$2:$D$467,'Transaction Overview'!$G$2:$G$467,$A13,'Transaction Overview'!$H$2:$H$467,D$4) -> 0 | E13: =SUMIFS('Transaction Overview'!$D$2:$D$467,'Transaction Overview'!$G$2:$G$467,$A13,'Transaction Overview'!$H$2:$H$467,E$4) -> 0 | F13: =SUMIFS('Transaction Overview'!$D$2:$D$467,'Transaction Overview'!$G$2:$G$467,$A13,'Transaction Overview'!$H$2:$H$467,F$4) -> -16087.5 | G13: =SUMIFS('Transaction Overview'!$D$2:$D$467,'Transaction Overview'!$G$2:$G$467,$A13,'Transaction Overview'!$H$2:$H$467,G$4) -> 0 | H13: =SUMIFS('Transaction Overview'!$D$2:$D$467,'Transaction Overview'!$G$2:$G$467,$A13,'Transaction Overview'!$H$2:$H$467,H$4) -> 0 | I13: =SUM(C13:H13) -> -16087.5
A14: Kevin Wong Commission (Steve Klar) | B14: Commissions — Outgoing | C14: =SUMIFS('Transaction Overview'!$D$2:$D$467,'Transaction Overview'!$G$2:$G$467,$A14,'Transaction Overview'!$H$2:$H$467,C$4) -> -6000 | D14: =SUMIFS('Transaction Overview'!$D$2:$D$467,'Transaction Overview'!$G$2:$G$467,$A14,'Transaction Overview'!$H$2:$H$467,D$4) -> 0 | E14: =SUMIFS('Transaction Overview'!$D$2:$D$467,'Transaction Overview'!$G$2:$G$467,$A14,'Transaction Overview'!$H$2:$H$467,E$4) -> 0 | F14: =SUMIFS('Transaction Overview'!$D$2:$D$467,'Transaction Overview'!$G$2:$G$467,$A14,'Transaction Overview'!$H$2:$H$467,F$4) -> 0 | G14: =SUMIFS('Transaction Overview'!$D$2:$D$467,'Transaction Overview'!$G$2:$G$467,$A14,'Transaction Overview'!$H$2:$H$467,G$4) -> 0 | H14: =SUMIFS('Transaction Overview'!$D$2:$D$467,'Transaction Overview'!$G$2:$G$467,$A14,'Transaction Overview'!$H$2:$H$467,H$4) -> 0 | I14: =SUM(C14:H14) -> -6000
A15: Meg Maran - MDC Commission | B15: Commissions — Outgoing | C15: =SUMIFS('Transaction Overview'!$D$2:$D$467,'Transaction Overview'!$G$2:$G$467,$A15,'Transaction Overview'!$H$2:$H$467,C$4) -> 0 | D15: =SUMIFS('Transaction Overview'!$D$2:$D$467,'Transaction Overview'!$G$2:$G$467,$A15,'Transaction Overview'!$H$2:$H$467,D$4) -> 0 | E15: =SUMIFS('Transaction Overview'!$D$2:$D$467,'Transaction Overview'!$G$2:$G$467,$A15,'Transaction Overview'!$H$2:$H$467,E$4) -> 0 | F15: =SUMIFS('Transaction Overview'!$D$2:$D$467,'Transaction Overview'!$G$2:$G$467,$A15,'Transaction Overview'!$H$2:$H$467,F$4) -> -1500 | G15: =SUMIFS('Transaction Overview'!$D$2:$D$467,'Transaction Overview'!$G$2:$G$467,$A15,'Transaction Overview'!$H$2:$H$467,G$4) -> 0 | H15: =SUMIFS('Transaction Overview'!$D$2:$D$467,'Transaction Overview'!$G$2:$G$467,$A15,'Transaction Overview'!$H$2:$H$467,H$4) -> 0 | I15: =SUM(C15:H15) -> -1500
A16: MAG - Admeer Advisory Reimbursement | B16: MAG Pass-Through | C16: =SUMIFS('Transaction Overview'!$D$2:$D$467,'Transaction Overview'!$G$2:$G$467,$A16,'Transaction Overview'!$H$2:$H$467,C$4) -> 0 | D16: =SUMIFS('Transaction Overview'!$D$2:$D$467,'Transaction Overview'!$G$2:$G$467,$A16,'Transaction Overview'!$H$2:$H$467,D$4) -> 5000 | E16: =SUMIFS('Transaction Overview'!$D$2:$D$467,'Transaction Overview'!$G$2:$G$467,$A16,'Transaction Overview'!$H$2:$H$467,E$4) -> 0 | F16: =SUMIFS('Transaction Overview'!$D$2:$D$467,'Transaction Overview'!$G$2:$G$467,$A16,'Transaction Overview'!$H$2:$H$467,F$4) -> 0 | G16: =SUMIFS('Transaction Overview'!$D$2:$D$467,'Transaction Overview'!$G$2:$G$467,$A16,'Transaction Overview'!$H$2:$H$467,G$4) -> 0 | H16: =SUMIFS('Transaction Overview'!$D$2:$D$467,'Transaction Overview'!$G$2:$G$467,$A16,'Transaction Overview'!$H$2:$H$467,H$4) -> 0 | I16: =SUM(C16:H16) -> 5000
... A61: TBD | B61: Uncategorized — Review | C61: =SUMIFS('Transaction Overview'!$D$2:$D$467,'Transaction Overview'!$G$2:$G$467,$A61,'Transaction Overview'!$H$2:$H$467,C$4) -> 0 | D61: =SUMIFS('Transaction Overview'!$D$2:$D$467,'Transaction Overview'!$G$2:$G$467,$A61,'Transaction Overview'!$H$2:$H$467,D$4) -> 0 | E61: =SUMIFS('Transaction Overview'!$D$2:$D$467,'Transaction Overview'!$G$2:$G$467,$A61,'Transaction Overview'!$H$2:$H$467,E$4) -> 0 | F61: =SUMIFS('Transaction Overview'!$D$2:$D$467,'Transaction Overview'!$G$2:$G$467,$A61,'Transaction Overview'!$H$2:$H$467,F$4) -> 0 | G61: =SUMIFS('Transaction Overview'!$D$2:$D$467,'Transaction Overview'!$G$2:$G$467,$A61,'Transaction Overview'!$H$2:$H$467,G$4) -> 0 | H61: =SUMIFS('Transaction Overview'!$D$2:$D$467,'Transaction Overview'!$G$2:$G$467,$A61,'Transaction Overview'!$H$2:$H$467,H$4) -> 0 | I61: =SUM(C61:H61) -> 0

Sheet Transfer In
A1: Chase 9335 — 2026 Activity — Transfer In
A2: Statement | Jan 2026 – Jun 2026
A4: SUMMARY
A5: Total | C5: =SUMIFS('Transaction Overview'!$D$2:$D$467,'Transaction Overview'!$E$2:$E$467,"ACCT_XFER",'Transaction Overview'!$D$2:$D$467,">0")+SUMIFS('Transaction Overview'!$D$2:$D$467,'Transaction Overview'!$E$2:$E$467,"CHASE_TO_PARTNERFI",'Transaction Overview'!$D$2:$D$467,">0")+SUMIFS('Transaction Overview'!$D$2:$D$467,'Transaction Overview'!$E$2:$E$467,"QUICKPAY_DEBIT",'Transaction Overview'!$D$2:$D$467,">0") -> 122006.41
A6: # Transactions | C6: =COUNTIFS('Transaction Overview'!$E$2:$E$467,"ACCT_XFER",'Transaction Overview'!$D$2:$D$467,">0")+COUNTIFS('Transaction Overview'!$E$2:$E$467,"CHASE_TO_PARTNERFI",'Transaction Overview'!$D$2:$D$467,">0")+COUNTIFS('Transaction Overview'!$E$2:$E$467,"QUICKPAY_DEBIT",'Transaction Overview'!$D$2:$D$467,">0") -> 5
A8: BY COUNTERPARTY
A9: Counterparty | B9: # Txns | C9: Amount
A10: Transfer From DWG Capital Group | B10: =COUNTIFS('Transaction Overview'!$G$2:$G$467,$A10,'Transaction Overview'!$D$2:$D$467,">0") -> 1 | C10: =SUMIFS('Transaction Overview'!$D$2:$D$467,'Transaction Overview'!$G$2:$G$467,$A10,'Transaction Overview'!$D$2:$D$467,">0") -> 8556.41
A11: Transfer From Poseidon | B11: =COUNTIFS('Transaction Overview'!$G$2:$G$467,$A11,'Transaction Overview'!$D$2:$D$467,">0") -> 1 | C11: =SUMIFS('Transaction Overview'!$D$2:$D$467,'Transaction Overview'!$G$2:$G$467,$A11,'Transaction Overview'!$D$2:$D$467,">0") -> 2000
A12: Transfer From SPF | B12: =COUNTIFS('Transaction Overview'!$G$2:$G$467,$A12,'Transaction Overview'!$D$2:$D$467,">0") -> 1 | C12: =SUMIFS('Transaction Overview'!$D$2:$D$467,'Transaction Overview'!$G$2:$G$467,$A12,'Transaction Overview'!$D$2:$D$467,">0") -> 11450
A13: Transfer From Stryten | B13: =COUNTIFS('Transaction Overview'!$G$2:$G$467,$A13,'Transaction Overview'!$D$2:$D$467,">0") -> 2 | C13: =SUMIFS('Transaction Overview'!$D$2:$D$467,'Transaction Overview'!$G$2:$G$467,$A13,'Transaction Overview'!$D$2:$D$467,">0") -> 100000
A14: Subtotal | B14: =SUM(B10:B13) -> 5 | C14: =SUM(C10:C13) -> 122006.41
A16: DETAIL
A17: Date | B17: Counterparty | C17: Amount
A18: {=_xlfn._xlws.FILTER('Transaction Overview'!$B$2:$B$467,((('Transaction Overview'!$E$2:$E$467="ACCT_XFER")+('Transaction Overview'!$E$2:$E$467="CHASE_TO_PARTNERFI")+('Transaction Overview'!$E$2:$E$467="QUICKPAY_DEBIT"))*('Transaction Overview'!$D$2:$D$467>0)))} -> 46136 | B18: {=_xlfn._xlws.FILTER('Transaction Overview'!$G$2:$G$467,((('Transaction Overview'!$E$2:$E$467="ACCT_XFER")+('Transaction Overview'!$E$2:$E$467="CHASE_TO_PARTNERFI")+('Transaction Overview'!$E$2:$E$467="QUICKPAY_DEBIT"))*('Transaction Overview'!$D$2:$D$467>0)))} -> Transfer From SPF | C18: {=_xlfn._xlws.FILTER('Transaction Overview'!$D$2:$D$467,((('Transaction Overview'!$E$2:$E$467="ACCT_XFER")+('Transaction Overview'!$E$2:$E$467="CHASE_TO_PARTNERFI")+('Transaction Overview'!$E$2:$E$467="QUICKPAY_DEBIT"))*('Transaction Overview'!$D$2:$D$467>0)))} -> 11450
A19: 46111 | B19: Transfer From Stryten | C19: 50000
A20: 46056 | B20: Transfer From DWG Capital Group | C20: 8556.41
A21: 46055 | B21: Transfer From Stryten | C21: 50000
A22: 46035 | B22: Transfer From Poseidon | C22: 2000

Sheet Transfer Out
A1: Chase 9335 — 2026 Activity — Transfer Out
A2: Statement | Jan 2026 – Jun 2026
A4: SUMMARY
A5: Total | C5: =SUMIFS('Transaction Overview'!$D$2:$D$467,'Transaction Overview'!$E$2:$E$467,"ACCT_XFER",'Transaction Overview'!$D$2:$D$467,"<0")+SUMIFS('Transaction Overview'!$D$2:$D$467,'Transaction Overview'!$E$2:$E$467,"CHASE_TO_PARTNERFI",'Transaction Overview'!$D$2:$D$467,"<0")+SUMIFS('Transaction Overview'!$D$2:$D$467,'Transaction Overview'!$E$2:$E$467,"QUICKPAY_DEBIT",'Transaction Overview'!$D$2:$D$467,"<0") -> -541618.41
A6: # Transactions | C6: =COUNTIFS('Transaction Overview'!$E$2:$E$467,"ACCT_XFER",'Transaction Overview'!$D$2:$D$467,"<0")+COUNTIFS('Transaction Overview'!$E$2:$E$467,"CHASE_TO_PARTNERFI",'Transaction Overview'!$D$2:$D$467,"<0")+COUNTIFS('Transaction Overview'!$E$2:$E$467,"QUICKPAY_DEBIT",'Transaction Overview'!$D$2:$D$467,"<0") -> 51
A8: BY COUNTERPARTY
A9: Counterparty | B9: # Txns | C9: Amount
A10: Transfer to Angela Dunning | B10: =COUNTIFS('Transaction Overview'!$G$2:$G$467,$A10,'Transaction Overview'!$D$2:$D$467,"<0") -> 3 | C10: =SUMIFS('Transaction Overview'!$D$2:$D$467,'Transaction Overview'!$G$2:$G$467,$A10,'Transaction Overview'!$D$2:$D$467,"<0") -> -31000
A11: Transfer to Buckeye | B11: =COUNTIFS('Transaction Overview'!$G$2:$G$467,$A11,'Transaction Overview'!$D$2:$D$467,"<0") -> 1 | C11: =SUMIFS('Transaction Overview'!$D$2:$D$467,'Transaction Overview'!$G$2:$G$467,$A11,'Transaction Overview'!$D$2:$D$467,"<0") -> -20000
A12: Transfer to DWG Capital Group | B12: =COUNTIFS('Transaction Overview'!$G$2:$G$467,$A12,'Transaction Overview'!$D$2:$D$467,"<0") -> 17 | C12: =SUMIFS('Transaction Overview'!$D$2:$D$467,'Transaction Overview'!$G$2:$G$467,$A12,'Transaction Overview'!$D$2:$D$467,"<0") -> -298556.41
A13: Transfer to DWG Capital Group_Costar | B13: =COUNTIFS('Transaction Overview'!$G$2:$G$467,$A13,'Transaction Overview'!$D$2:$D$467,"<0") -> 1 | C13: =SUMIFS('Transaction Overview'!$D$2:$D$467,'Transaction Overview'!$G$2:$G$467,$A13,'Transaction Overview'!$D$2:$D$467,"<0") -> -15000
A14: Transfer to DWG Capital Partners | B14: =COUNTIFS('Transaction Overview'!$G$2:$G$467,$A14,'Transaction Overview'!$D$2:$D$467,"<0") -> 5 | C14: =SUMIFS('Transaction Overview'!$D$2:$D$467,'Transaction Overview'!$G$2:$G$467,$A14,'Transaction Overview'!$D$2:$D$467,"<0") -> -77000
A15: Transfer to Edgebuilders | B15: =COUNTIFS('Transaction Overview'!$G$2:$G$467,$A15,'Transaction Overview'!$D$2:$D$467,"<0") -> 2 | C15: =SUMIFS('Transaction Overview'!$D$2:$D$467,'Transaction Overview'!$G$2:$G$467,$A15,'Transaction Overview'!$D$2:$D$467,"<0") -> -35200
A16: Transfer to JAL Southbend | B16: =COUNTIFS('Transaction Overview'!$G$2:$G$467,$A16,'Transaction Overview'!$D$2:$D$467,"<0") -> 1 | C16: =SUMIFS('Transaction Overview'!$D$2:$D$467,'Transaction Overview'!$G$2:$G$467,$A16,'Transaction Overview'!$D$2:$D$467,"<0") -> -13000
A17: Transfer to Judd Sol Prop | B17: =COUNTIFS('Transaction Overview'!$G$2:$G$467,$A17,'Transaction Overview'!$D$2:$D$467,"<0") -> 2 | C17: =SUMIFS('Transaction Overview'!$D$2:$D$467,'Transaction Overview'!$G$2:$G$467,$A17,'Transaction Overview'!$D$2:$D$467,"<0") -> -200
A18: Transfer to TX Personal Joint | B18: =COUNTIFS('Transaction Overview'!$G$2:$G$467,$A18,'Transaction Overview'!$D$2:$D$467,"<0") -> 2 | C18: =SUMIFS('Transaction Overview'!$D$2:$D$467,'Transaction Overview'!$G$2:$G$467,$A18,'Transaction Overview'!$D$2:$D$467,"<0") -> -40000
A19: Meg Maran - MDC Commission | B19: =COUNTIFS('Transaction Overview'!$G$2:$G$467,$A19,'Transaction Overview'!$D$2:$D$467,"<0") -> 1 | C19: =SUMIFS('Transaction Overview'!$D$2:$D$467,'Transaction Overview'!$G$2:$G$467,$A19,'Transaction Overview'!$D$2:$D$467,"<0") -> -1500
A20: Office/Miscellaneous Reimbursement - Mike P. | B20: =COUNTIFS('Transaction Overview'!$G$2:$G$467,$A20,'Transaction Overview'!$D$2:$D$467,"<0") -> 13 | C20: =SUMIFS('Transaction Overview'!$D$2:$D$467,'Transaction Overview'!$G$2:$G$467,$A20,'Transaction Overview'!$D$2:$D$467,"<0") -> -6637
A21: Zelle - Chase Hall | B21: =COUNTIFS('Transaction Overview'!$G$2:$G$467,$A21,'Transaction Overview'!$D$2:$D$467,"<0") -> 1 | C21: =SUMIFS('Transaction Overview'!$D$2:$D$467,'Transaction Overview'!$G$2:$G$467,$A21,'Transaction Overview'!$D$2:$D$467,"<0") -> -325
... A23: Zelle - Scott Brech | B23: =COUNTIFS('Transaction Overview'!$G$2:$G$467,$A23,'Transaction Overview'!$D$2:$D$467,"<0") -> 1 | C23: =SUMIFS('Transaction Overview'!$D$2:$D$467,'Transaction Overview'!$G$2:$G$467,$A23,'Transaction Overview'!$D$2:$D$467,"<0") -> -700
A24: Subtotal | B24: =SUM(B10:B23) -> 51 | C24: =SUM(C10:C23) -> -541618.41
A26: DETAIL
A27: Date | B27: Counterparty | C27: Amount
A28: {=_xlfn._xlws.FILTER('Transaction Overview'!$B$2:$B$467,((('Transaction Overview'!$E$2:$E$467="ACCT_XFER")+('Transaction Overview'!$E$2:$E$467="CHASE_TO_PARTNERFI")+('Transaction Overview'!$E$2:$E$467="QUICKPAY_DEBIT"))*('Transaction Overview'!$D$2:$D$467<0)))} -> 46177 | B28: {=_xlfn._xlws.FILTER('Transaction Overview'!$G$2:$G$467,((('Transaction Overview'!$E$2:$E$467="ACCT_XFER")+('Transaction Overview'!$E$2:$E$467="CHASE_TO_PARTNERFI")+('Transaction Overview'!$E$2:$E$467="QUICKPAY_DEBIT"))*('Transaction Overview'!$D$2:$D$467<0)))} -> Transfer to Angela Dunning | C28: {=_xlfn._xlws.FILTER('Transaction Overview'!$D$2:$D$467,((('Transaction Overview'!$E$2:$E$467="ACCT_XFER")+('Transaction Overview'!$E$2:$E$467="CHASE_TO_PARTNERFI")+('Transaction Overview'!$E$2:$E$467="QUICKPAY_DEBIT"))*('Transaction Overview'!$D$2:$D$467<0)))} -> -1000
A29: 46175 | B29: Transfer to DWG Capital Group | C29: -30000
A30: 46175 | B30: Zelle - Francisco Bautista | C30: -2500
A31: 46160 | B31: Office/Miscellaneous Reimbursement - Mike P. | C31: -25
A32: 46157 | B32: Transfer to DWG Capital Partners | C32: -20000
A33: 46157 | B33: Transfer to Buckeye | C33: -20000
A34: 46153 | B34: Office/Miscellaneous Reimbursement - Mike P. | C34: -140
A35: 46142 | B35: Transfer to DWG Capital Partners | C35: -10000
A36: 46141 | B36: Transfer to DWG Capital Group | C36: -10000
A37: 46141 | B37: Transfer to DWG Capital Group | C37: -30000
A38: 46140 | B38: Office/Miscellaneous Reimbursement - Mike P. | C38: -5000
A39: 46139 | B39: Meg Maran - MDC Commission | C39: -1500
A40: 46135 | B40: Transfer to DWG Capital Group | C40: -15000
... A78: 46030 | B78: Transfer to Edgebuilders | C78: -35000

Sheet Commission
A1: Chase 9335 — 2026 Activity
A2: Commissions Statement | Jan 2026 – Jun 2026
A4: SUMMARY
A5: Commissions Earned (net) | C5: =SUMIFS('Transaction Overview'!$D$2:$D$467,'Transaction Overview'!$J$2:$J$467,"Commissions — Incoming") -> 435155.44
A6: Commissions Paid Out | C6: =SUMIFS('Transaction Overview'!$D$2:$D$467,'Transaction Overview'!$J$2:$J$467,"Commissions — Outgoing") -> -23587.5
A7: Net Commission Kept | C7: =C5+C6 -> 411567.94
A9: BY DEAL — INCOMING
A10: Category | B10: # Txns | C10: Amount
A11: Incoming Commission: Rembrandt | B11: =COUNTIFS('Transaction Overview'!$G$2:$G$467,$A11) -> 1 | C11: =SUMIFS('Transaction Overview'!$D$2:$D$467,'Transaction Overview'!$G$2:$G$467,$A11) -> 168266
A12: Incoming Commission: SPF | B12: =COUNTIFS('Transaction Overview'!$G$2:$G$467,$A12) -> 3 | C12: =SUMIFS('Transaction Overview'!$D$2:$D$467,'Transaction Overview'!$G$2:$G$467,$A12) -> 266889.44
A13: Subtotal — Incoming | B13: =SUM(B11:B12) -> 4 | C13: =SUM(C11:C12) -> 435155.44
A15: BY DEAL — OUTGOING
A16: Category | B16: # Txns | C16: Amount
A17: Kevin Wong Commission (SPF) | B17: =COUNTIFS('Transaction Overview'!$G$2:$G$467,$A17) -> 1 | C17: =SUMIFS('Transaction Overview'!$D$2:$D$467,'Transaction Overview'!$G$2:$G$467,$A17) -> -16087.5
A18: Kevin Wong Commission (Steve Klar) | B18: =COUNTIFS('Transaction Overview'!$G$2:$G$467,$A18) -> 1 | C18: =SUMIFS('Transaction Overview'!$D$2:$D$467,'Transaction Overview'!$G$2:$G$467,$A18) -> -6000
A19: Meg Maran - MDC Commission | B19: =COUNTIFS('Transaction Overview'!$G$2:$G$467,$A19) -> 1 | C19: =SUMIFS('Transaction Overview'!$D$2:$D$467,'Transaction Overview'!$G$2:$G$467,$A19) -> -1500
A20: Subtotal — Outgoing | B20: =SUM(B17:B19) -> 3 | C20: =SUM(C17:C19) -> -23587.5

Sheet Wire In
A1: Chase 9335 — 2026 Activity — Wire In
A2: Statement | Jan 2026 – Jun 2026
A4: SUMMARY
A5: Total | C5: =SUMIFS('Transaction Overview'!$D$2:$D$467,'Transaction Overview'!$E$2:$E$467,"WIRE_INCOMING") -> 529526.29
A6: # Transactions | C6: =COUNTIFS('Transaction Overview'!$E$2:$E$467,"WIRE_INCOMING") -> 7
A8: BY COUNTERPARTY
A9: Counterparty | B9: # Txns | C9: Amount
A10: Incoming Commission: Rembrandt | B10: =COUNTIFS('Transaction Overview'!$G$2:$G$467,$A10,'Transaction Overview'!$E$2:$E$467,"WIRE_INCOMING") -> 1 | C10: =SUMIFS('Transaction Overview'!$D$2:$D$467,'Transaction Overview'!$G$2:$G$467,$A10,'Transaction Overview'!$E$2:$E$467,"WIRE_INCOMING") -> 168266
A11: Incoming Commission: SPF | B11: =COUNTIFS('Transaction Overview'!$G$2:$G$467,$A11,'Transaction Overview'!$E$2:$E$467,"WIRE_INCOMING") -> 3 | C11: =SUMIFS('Transaction Overview'!$D$2:$D$467,'Transaction Overview'!$G$2:$G$467,$A11,'Transaction Overview'!$E$2:$E$467,"WIRE_INCOMING") -> 266889.44
A12: Incoming wire from JC Whitner | B12: =COUNTIFS('Transaction Overview'!$G$2:$G$467,$A12,'Transaction Overview'!$E$2:$E$467,"WIRE_INCOMING") -> 1 | C12: =SUMIFS('Transaction Overview'!$D$2:$D$467,'Transaction Overview'!$G$2:$G$467,$A12,'Transaction Overview'!$E$2:$E$467,"WIRE_INCOMING") -> 20000
A13: Incoming wire from Moab (Leftover Funds) | B13: =COUNTIFS('Transaction Overview'!$G$2:$G$467,$A13,'Transaction Overview'!$E$2:$E$467,"WIRE_INCOMING") -> 1 | C13: =SUMIFS('Transaction Overview'!$D$2:$D$467,'Transaction Overview'!$G$2:$G$467,$A13,'Transaction Overview'!$E$2:$E$467,"WIRE_INCOMING") -> 58370.85
A14: Incoming wire from Steve Klar | B14: =COUNTIFS('Transaction Overview'!$G$2:$G$467,$A14,'Transaction Overview'!$E$2:$E$467,"WIRE_INCOMING") -> 1 | C14: =SUMIFS('Transaction Overview'!$D$2:$D$467,'Transaction Overview'!$G$2:$G$467,$A14,'Transaction Overview'!$E$2:$E$467,"WIRE_INCOMING") -> 16000
A15: Subtotal | B15: =SUM(B10:B14) -> 7 | C15: =SUM(C10:C14) -> 529526.29
A17: DETAIL
A18: Date | B18: Counterparty | C18: Amount
A19: {=_xlfn._xlws.FILTER('Transaction Overview'!$B$2:$B$467,('Transaction Overview'!$E$2:$E$467="WIRE_INCOMING"))} -> 46135 | B19: {=_xlfn._xlws.FILTER('Transaction Overview'!$G$2:$G$467,('Transaction Overview'!$E$2:$E$467="WIRE_INCOMING"))} -> Incoming Commission: SPF | C19: {=_xlfn._xlws.FILTER('Transaction Overview'!$D$2:$D$467,('Transaction Overview'!$E$2:$E$467="WIRE_INCOMING"))} -> 23139.44
A20: 46135 | B20: Incoming Commission: SPF | C20: 48750
A21: 46135 | B21: Incoming Commission: SPF | C21: 195000
A22: 46072 | B22: Incoming Commission: Rembrandt | C22: 168266
A23: 46056 | B23: Incoming wire from Moab (Leftover Funds) | C23: 58370.85
A24: 46055 | B24: Incoming wire from JC Whitner | C24: 20000
A25: 46029 | B25: Incoming wire from Steve Klar | C25: 16000

Sheet Wire Out
A1: Chase 9335 — 2026 Activity — Wire Out
A2: Statement | Jan 2026 – Jun 2026
A4: SUMMARY
A5: Total | C5: =SUMIFS('Transaction Overview'!$D$2:$D$467,'Transaction Overview'!$E$2:$E$467,"WIRE_OUTGOING") -> -108758.35
A6: # Transactions | C6: =COUNTIFS('Transaction Overview'!$E$2:$E$467,"WIRE_OUTGOING") -> 7
A8: BY COUNTERPARTY
A9: Counterparty | B9: # Txns | C9: Amount
A10: Bridge Coverage (JC Whitner) | B10: =COUNTIFS('Transaction Overview'!$G$2:$G$467,$A10,'Transaction Overview'!$E$2:$E$467,"WIRE_OUTGOING") -> 1 | C10: =SUMIFS('Transaction Overview'!$D$2:$D$467,'Transaction Overview'!$G$2:$G$467,$A10,'Transaction Overview'!$E$2:$E$467,"WIRE_OUTGOING") -> -10000
A11: Kevin Wong Commission (SPF) | B11: =COUNTIFS('Transaction Overview'!$G$2:$G$467,$A11,'Transaction Overview'!$E$2:$E$467,"WIRE_OUTGOING") -> 1 | C11: =SUMIFS('Transaction Overview'!$D$2:$D$467,'Transaction Overview'!$G$2:$G$467,$A11,'Transaction Overview'!$E$2:$E$467,"WIRE_OUTGOING") -> -16087.5
A12: Kevin Wong Commission (Steve Klar) | B12: =COUNTIFS('Transaction Overview'!$G$2:$G$467,$A12,'Transaction Overview'!$E$2:$E$467,"WIRE_OUTGOING") -> 1 | C12: =SUMIFS('Transaction Overview'!$D$2:$D$467,'Transaction Overview'!$G$2:$G$467,$A12,'Transaction Overview'!$E$2:$E$467,"WIRE_OUTGOING") -> -6000
A13: MAG - Admeer Advisory Transfer | B13: =COUNTIFS('Transaction Overview'!$G$2:$G$467,$A13,'Transaction Overview'!$E$2:$E$467,"WIRE_OUTGOING") -> 2 | C13: =SUMIFS('Transaction Overview'!$D$2:$D$467,'Transaction Overview'!$G$2:$G$467,$A13,'Transaction Overview'!$E$2:$E$467,"WIRE_OUTGOING") -> -10000
A14: Wire to Gi Capital Group (+ Moab Funds) | B14: =COUNTIFS('Transaction Overview'!$G$2:$G$467,$A14,'Transaction Overview'!$E$2:$E$467,"WIRE_OUTGOING") -> 1 | C14: =SUMIFS('Transaction Overview'!$D$2:$D$467,'Transaction Overview'!$G$2:$G$467,$A14,'Transaction Overview'!$E$2:$E$467,"WIRE_OUTGOING") -> -56670.85
