Workbook

Sheet Transaction Summary
A1: Chase Personal Banking — Angela
A2: Statement Summary | Jan 2, 2025 – Dec 31, 2025
A4: Account | B4: Angela — Chase 1117
A5: Statement Period | B5: Jan 2025 – Dec 2025
A7: TOTALS
A8: Charges (Outflows) | B8: =SUMIF(Angela_2025_Chase1117_Activity_!$D$2:$D$2300,"<0") -> -336303.63
A9: Credits & Payments (Inflows) | B9: =SUMIF(Angela_2025_Chase1117_Activity_!$D$2:$D$2300,">0") -> 335062.41
A10: Net Balance | B10: =B8+B9 -> -1241.22
A12: ACTIVITY — INFLOWS vs OUTFLOWS
A13: Flow | B13: # Txns | C13: Amount
A14: Inflows (Credits) | B14: =COUNTIF(Angela_2025_Chase1117_Activity_!$D$2:$D$2300,">0") -> 173 | C14: =B9 -> 335062.41
A15: Outflows (Charges) | B15: =COUNTIF(Angela_2025_Chase1117_Activity_!$D$2:$D$2300,"<0") -> 2126 | C15: =B8 -> -336303.63
A16: Net | B16: =B14+B15 -> 2299 | C16: =C14+C15 -> -1241.22
A18: SPEND BY CATEGORY
A19: Category | B19: Amount | C19: % of Charges
A20: Transfers
A21: Transfer from DWG Capital Group | B21: =SUMIF(Angela_2025_Chase1117_Activity_!$G$2:$G$2300,$A21,Angela_2025_Chase1117_Activity_!$D$2:$D$2300) -> 306000 | C21: =B21/$B$8 -> -0.90989205
A22: Transfer to Ava | B22: =SUMIF(Angela_2025_Chase1117_Activity_!$G$2:$G$2300,$A22,Angela_2025_Chase1117_Activity_!$D$2:$D$2300) -> -12500 | C22: =B22/$B$8 -> 0.037168793
A23: Transfer from Poseidon Asset Group | B23: =SUMIF(Angela_2025_Chase1117_Activity_!$G$2:$G$2300,$A23,Angela_2025_Chase1117_Activity_!$D$2:$D$2300) -> 1000 | C23: =B23/$B$8 -> -0.0029735034
A24: Transfer to DWG Capital Group_Savings | B24: =SUMIF(Angela_2025_Chase1117_Activity_!$G$2:$G$2300,$A24,Angela_2025_Chase1117_Activity_!$D$2:$D$2300) -> -300 | C24: =B24/$B$8 -> 0.00089205103
A25: Subtotal — Transfers | B25: =SUM(B21:B24) -> 294200 | C25: =SUM(C21:C24) -> -0.87480471
A26: Zelle
A27: Zelle from Mary Margaret Trahan | B27: =SUMIF(Angela_2025_Chase1117_Activity_!$G$2:$G$2300,$A27,Angela_2025_Chase1117_Activity_!$D$2:$D$2300) -> 375 | C27: =B27/$B$8 -> -0.0011150638
A28: Zelle from Rose Li | B28: =SUMIF(Angela_2025_Chase1117_Activity_!$G$2:$G$2300,$A28,Angela_2025_Chase1117_Activity_!$D$2:$D$2300) -> 1350 | C28: =B28/$B$8 -> -0.0040142296
A29: Zelle from Joe Saunders | B29: =SUMIF(Angela_2025_Chase1117_Activity_!$G$2:$G$2300,$A29,Angela_2025_Chase1117_Activity_!$D$2:$D$2300) -> 3950 | C29: =B29/$B$8 -> -0.011745339
A30: Zelle to Joe Saunders | B30: =SUMIF(Angela_2025_Chase1117_Activity_!$G$2:$G$2300,$A30,Angela_2025_Chase1117_Activity_!$D$2:$D$2300) -> -500 | C30: =B30/$B$8 -> 0.0014867517
A31: Zelle from Tanya Miller | B31: =SUMIF(Angela_2025_Chase1117_Activity_!$G$2:$G$2300,$A31,Angela_2025_Chase1117_Activity_!$D$2:$D$2300) -> 200 | C31: =B31/$B$8 -> -0.00059470069
A32: Zelle to Britt Magadini | B32: =SUMIF(Angela_2025_Chase1117_Activity_!$G$2:$G$2300,$A32,Angela_2025_Chase1117_Activity_!$D$2:$D$2300) -> -1100 | C32: =B32/$B$8 -> 0.0032708538
A33: Zelle from Eunice G Chang | B33: =SUMIF(Angela_2025_Chase1117_Activity_!$G$2:$G$2300,$A33,Angela_2025_Chase1117_Activity_!$D$2:$D$2300) -> 350 | C33: =B33/$B$8 -> -0.0010407262
A34: Zelle from G-Eunice LLC | B34: =SUMIF(Angela_2025_Chase1117_Activity_!$G$2:$G$2300,$A34,Angela_2025_Chase1117_Activity_!$D$2:$D$2300) -> 175 | C34: =B34/$B$8 -> -0.0005203631
A35: Zelle to Shaffa | B35: =SUMIF(Angela_2025_Chase1117_Activity_!$G$2:$G$2300,$A35,Angela_2025_Chase1117_Activity_!$D$2:$D$2300) -> -500 | C35: =B35/$B$8 -> 0.0014867517
A36: Zelle to Aaron Frankel | B36: =SUMIF(Angela_2025_Chase1117_Activity_!$G$2:$G$2300,$A36,Angela_2025_Chase1117_Activity_!$D$2:$D$2300) -> -2350 | C36: =B36/$B$8 -> 0.0069877331
A37: Zelle to Denise Quezada | B37: =SUMIF(Angela_2025_Chase1117_Activity_!$G$2:$G$2300,$A37,Angela_2025_Chase1117_Activity_!$D$2:$D$2300) -> -1225 | C37: =B37/$B$8 -> 0.0036425417
A38: Zelle to Jeff Seider | B38: =SUMIF(Angela_2025_Chase1117_Activity_!$G$2:$G$2300,$A38,Angela_2025_Chase1117_Activity_!$D$2:$D$2300) -> -300 | C38: =B38/$B$8 -> 0.00089205103
... A43: Zelle to Angela Dunning | B43: =SUMIF(Angela_2025_Chase1117_Activity_!$G$2:$G$2300,$A43,Angela_2025_Chase1117_Activity_!$D$2:$D$2300) -> -500 | C43: =B43/$B$8 -> 0.0014867517
A44: Subtotal — Zelle | B44: =SUM(B27:B43) -> 1415 | C44: =SUM(C27:C43) -> -0.0042075074
A45: PayPal ACH
A46: PayPal ACH - John Dunning | B46: =SUMIF(Angela_2025_Chase1117_Activity_!$G$2:$G$2300,$A46,Angela_2025_Chase1117_Activity_!$D$2:$D$2300) -> -844.45 | C46: =B46/$B$8 -> 0.002510975
A47: Subtotal — PayPal ACH | B47: =SUM(B46:B46) -> -844.45 | C47: =SUM(C46:C46) -> 0.002510975
A48: Personal Travel
...

Sheet Transfers
A1: Chase Personal Banking — Angela
A2: Transfers | Jan 2, 2025 – Dec 31, 2025
A4: Category | B4: Amount | C4: # Txns
A5: Transfers (Own Accounts)
A6: Transfer from DWG Capital Group | B6: =SUMIF(Angela_2025_Chase1117_Activity_!$G$2:$G$2300,$A6,Angela_2025_Chase1117_Activity_!$D$2:$D$2300) -> 306000 | C6: =COUNTIF(Angela_2025_Chase1117_Activity_!$G$2:$G$2300,$A6) -> 103
A7: Transfer to Ava | B7: =SUMIF(Angela_2025_Chase1117_Activity_!$G$2:$G$2300,$A7,Angela_2025_Chase1117_Activity_!$D$2:$D$2300) -> -12500 | C7: =COUNTIF(Angela_2025_Chase1117_Activity_!$G$2:$G$2300,$A7) -> 15
A8: Transfer from Poseidon Asset Group | B8: =SUMIF(Angela_2025_Chase1117_Activity_!$G$2:$G$2300,$A8,Angela_2025_Chase1117_Activity_!$D$2:$D$2300) -> 1000 | C8: =COUNTIF(Angela_2025_Chase1117_Activity_!$G$2:$G$2300,$A8) -> 1
A9: Transfer to DWG Capital Group_Savings | B9: =SUMIF(Angela_2025_Chase1117_Activity_!$G$2:$G$2300,$A9,Angela_2025_Chase1117_Activity_!$D$2:$D$2300) -> -300 | C9: =COUNTIF(Angela_2025_Chase1117_Activity_!$G$2:$G$2300,$A9) -> 1
A10: Subtotal — Transfers (Own Accounts) | B10: =SUM(B6:B9) -> 294200 | C10: =SUM(C6:C9) -> 120
A11: Zelle (Person-to-Person)
A12: Zelle from Mary Margaret Trahan | B12: =SUMIF(Angela_2025_Chase1117_Activity_!$G$2:$G$2300,$A12,Angela_2025_Chase1117_Activity_!$D$2:$D$2300) -> 375 | C12: =COUNTIF(Angela_2025_Chase1117_Activity_!$G$2:$G$2300,$A12) -> 4
A13: Zelle from Rose Li | B13: =SUMIF(Angela_2025_Chase1117_Activity_!$G$2:$G$2300,$A13,Angela_2025_Chase1117_Activity_!$D$2:$D$2300) -> 1350 | C13: =COUNTIF(Angela_2025_Chase1117_Activity_!$G$2:$G$2300,$A13) -> 4
A14: Zelle from Joe Saunders | B14: =SUMIF(Angela_2025_Chase1117_Activity_!$G$2:$G$2300,$A14,Angela_2025_Chase1117_Activity_!$D$2:$D$2300) -> 3950 | C14: =COUNTIF(Angela_2025_Chase1117_Activity_!$G$2:$G$2300,$A14) -> 11
A15: Zelle to Joe Saunders | B15: =SUMIF(Angela_2025_Chase1117_Activity_!$G$2:$G$2300,$A15,Angela_2025_Chase1117_Activity_!$D$2:$D$2300) -> -500 | C15: =COUNTIF(Angela_2025_Chase1117_Activity_!$G$2:$G$2300,$A15) -> 1
A16: Zelle from Tanya Miller | B16: =SUMIF(Angela_2025_Chase1117_Activity_!$G$2:$G$2300,$A16,Angela_2025_Chase1117_Activity_!$D$2:$D$2300) -> 200 | C16: =COUNTIF(Angela_2025_Chase1117_Activity_!$G$2:$G$2300,$A16) -> 2
A17: Zelle to Britt Magadini | B17: =SUMIF(Angela_2025_Chase1117_Activity_!$G$2:$G$2300,$A17,Angela_2025_Chase1117_Activity_!$D$2:$D$2300) -> -1100 | C17: =COUNTIF(Angela_2025_Chase1117_Activity_!$G$2:$G$2300,$A17) -> 3
A18: Zelle from Eunice G Chang | B18: =SUMIF(Angela_2025_Chase1117_Activity_!$G$2:$G$2300,$A18,Angela_2025_Chase1117_Activity_!$D$2:$D$2300) -> 350 | C18: =COUNTIF(Angela_2025_Chase1117_Activity_!$G$2:$G$2300,$A18) -> 2
A19: Zelle from G-Eunice LLC | B19: =SUMIF(Angela_2025_Chase1117_Activity_!$G$2:$G$2300,$A19,Angela_2025_Chase1117_Activity_!$D$2:$D$2300) -> 175 | C19: =COUNTIF(Angela_2025_Chase1117_Activity_!$G$2:$G$2300,$A19) -> 1
A20: Zelle to Shaffa | B20: =SUMIF(Angela_2025_Chase1117_Activity_!$G$2:$G$2300,$A20,Angela_2025_Chase1117_Activity_!$D$2:$D$2300) -> -500 | C20: =COUNTIF(Angela_2025_Chase1117_Activity_!$G$2:$G$2300,$A20) -> 1
A21: Zelle to Aaron Frankel | B21: =SUMIF(Angela_2025_Chase1117_Activity_!$G$2:$G$2300,$A21,Angela_2025_Chase1117_Activity_!$D$2:$D$2300) -> -2350 | C21: =COUNTIF(Angela_2025_Chase1117_Activity_!$G$2:$G$2300,$A21) -> 8
A22: Zelle to Denise Quezada | B22: =SUMIF(Angela_2025_Chase1117_Activity_!$G$2:$G$2300,$A22,Angela_2025_Chase1117_Activity_!$D$2:$D$2300) -> -1225 | C22: =COUNTIF(Angela_2025_Chase1117_Activity_!$G$2:$G$2300,$A22) -> 2
A23: Zelle to Jeff Seider | B23: =SUMIF(Angela_2025_Chase1117_Activity_!$G$2:$G$2300,$A23,Angela_2025_Chase1117_Activity_!$D$2:$D$2300) -> -300 | C23: =COUNTIF(Angela_2025_Chase1117_Activity_!$G$2:$G$2300,$A23) -> 3
... A28: Zelle to Angela Dunning | B28: =SUMIF(Angela_2025_Chase1117_Activity_!$G$2:$G$2300,$A28,Angela_2025_Chase1117_Activity_!$D$2:$D$2300) -> -500 | C28: =COUNTIF(Angela_2025_Chase1117_Activity_!$G$2:$G$2300,$A28) -> 1
A29: Subtotal — Zelle (Person-to-Person) | B29: =SUM(B12:B28) -> 1415 | C29: =SUM(C12:C28) -> 49
A30: PayPal ACH
A31: PayPal ACH - John Dunning | B31: =SUMIF(Angela_2025_Chase1117_Activity_!$G$2:$G$2300,$A31,Angela_2025_Chase1117_Activity_!$D$2:$D$2300) -> -844.45 | C31: =COUNTIF(Angela_2025_Chase1117_Activity_!$G$2:$G$2300,$A31) -> 3
A32: Subtotal — PayPal ACH | B32: =SUM(B31:B31) -> -844.45 | C32: =SUM(C31:C31) -> 3
A34: TOTAL — ALL TRANSFERS | B34: =B10+B29+B32 -> 294770.55 | C34: =C10+C29+C32 -> 172

Sheet Transaction Details
A1: Chase Personal Banking — Angela
A2: Transaction Detail | Jan 2, 2025 – Dec 31, 2025
A4: Date | B4: Merchant / Description | C4: Category | D4: Amount
A5: =Angela_2025_Chase1117_Activity_!B2 -> 46022 | B5: =Angela_2025_Chase1117_Activity_!C2 -> FOREIGN EXCHANGE RATE ADJUSTMENT FEE 12/30CITY OF V | C5: =Angela_2025_Chase1117_Activity_!G2 -> Personal Travel - Canada | D5: =Angela_2025_Chase1117_Activity_!D2 -> -0.19
A6: =Angela_2025_Chase1117_Activity_!B3 -> 46022 | B6: =Angela_2025_Chase1117_Activity_!C3 -> BLUE SHIELD CALIFORNI 800-393-6130 CA 12/31 | C6: =Angela_2025_Chase1117_Activity_!G3 -> Personal - Health Insurance | D6: =Angela_2025_Chase1117_Activity_!D3 -> -1275.3
A7: =Angela_2025_Chase1117_Activity_!B4 -> 46022 | B7: =Angela_2025_Chase1117_Activity_!C4 -> CITY OF VANCOUVER PARKI VANCOUVER BC 12/30 CA DOLLAR 9.00 X 0.7322222 (EXCHG RTE) | C7: =Angela_2025_Chase1117_Activity_!G4 -> Personal Travel - Canada | D7: =Angela_2025_Chase1117_Activity_!D4 -> -6.59
A8: =Angela_2025_Chase1117_Activity_!B5 -> 46021 | B8: =Angela_2025_Chase1117_Activity_!C5 -> FOREIGN EXCHANGE RATE ADJUSTMENT FEE 12/29BCF - ONL | C8: =Angela_2025_Chase1117_Activity_!G5 -> Personal Travel - Canada | D8: =Angela_2025_Chase1117_Activity_!D5 -> -0.43
A9: =Angela_2025_Chase1117_Activity_!B6 -> 46021 | B9: =Angela_2025_Chase1117_Activity_!C6 -> FOREIGN EXCHANGE RATE ADJUSTMENT FEE 12/29TSESHAHT | C9: =Angela_2025_Chase1117_Activity_!G6 -> Personal Travel - Canada | D9: =Angela_2025_Chase1117_Activity_!D6 -> -1.84
A10: =Angela_2025_Chase1117_Activity_!B7 -> 46021 | B10: =Angela_2025_Chase1117_Activity_!C7 -> PENTESTER.COM PENTESTER.COM FL 12/30 | C10: =Angela_2025_Chase1117_Activity_!G7 -> Personal - Subscription | D10: =Angela_2025_Chase1117_Activity_!D7 -> -19
A11: =Angela_2025_Chase1117_Activity_!B8 -> 46021 | B11: =Angela_2025_Chase1117_Activity_!C8 -> BCF - ONLINE SALES & BO VICTORIA BC 12/29 CA DOLLAR 20.00 X 0.7325000 (EXCHG RTE) | C11: =Angela_2025_Chase1117_Activity_!G8 -> Personal Travel - Canada | D11: =Angela_2025_Chase1117_Activity_!D8 -> -14.65
A12: =Angela_2025_Chase1117_Activity_!B9 -> 46021 | B12: =Angela_2025_Chase1117_Activity_!C9 -> TSESHAHT MARKET LP PORT ALBERNI BC 12/29 CA DOLLAR 83.88 X 0.7331903 (EXCHG RTE) | C12: =Angela_2025_Chase1117_Activity_!G9 -> Personal Travel - Canada | D12: =Angela_2025_Chase1117_Activity_!D9 -> -61.5
A13: =Angela_2025_Chase1117_Activity_!B10 -> 46020 | B13: =Angela_2025_Chase1117_Activity_!C10 -> FOREIGN EXCHANGE RATE ADJUSTMENT FEE 12/26BEACHES G | C13: =Angela_2025_Chase1117_Activity_!G10 -> Personal Travel - Canada | D13: =Angela_2025_Chase1117_Activity_!D10 -> -0.55
A14: =Angela_2025_Chase1117_Activity_!B11 -> 46020 | B14: =Angela_2025_Chase1117_Activity_!C11 -> FOREIGN EXCHANGE RATE ADJUSTMENT FEE 12/28TOFINO PH | C14: =Angela_2025_Chase1117_Activity_!G11 -> Personal Travel - Canada | D14: =Angela_2025_Chase1117_Activity_!D11 -> -1.22
A15: =Angela_2025_Chase1117_Activity_!B12 -> 46020 | B15: =Angela_2025_Chase1117_Activity_!C12 -> FOREIGN EXCHANGE RATE ADJUSTMENT FEE 12/28PHARMASAV | C15: =Angela_2025_Chase1117_Activity_!G12 -> Personal Travel - Canada | D15: =Angela_2025_Chase1117_Activity_!D12 -> -2.08
A16: =Angela_2025_Chase1117_Activity_!B13 -> 46020 | B16: =Angela_2025_Chase1117_Activity_!C13 -> FOREIGN EXCHANGE RATE ADJUSTMENT FEE 161371 12/28TOFINO PH | C16: =Angela_2025_Chase1117_Activity_!G13 -> Personal Travel - Canada | D16: =Angela_2025_Chase1117_Activity_!D13 -> -4.46
... A2303: =Angela_2025_Chase1117_Activity_!B2300 -> 45659 | B2303: =Angela_2025_Chase1117_Activity_!C2300 -> AIR CAN* 01442800 AIRCANADA.COM MB 01/01 CA DOLLAR 150.00 X 0.6975333 (EXCHG RTE) | C2303: =Angela_2025_Chase1117_Activity_!G2300 -> Personal Travel - Canada | D2303: =Angela_2025_Chase1117_Activity_!D2300 -> -104.63

Sheet Monthly Breakdown
A1: Chase Personal Banking — Angela
A2: Monthly Breakdown by Category | Jan 2025 – Dec 2025
A4: Category | B4: =DATE(2025,1,1) -> 45658 | C4: =EDATE(B4,1) -> 45689 | D4: =EDATE(C4,1) -> 45717 | E4: =EDATE(D4,1) -> 45748 | F4: =EDATE(E4,1) -> 45778 | G4: =EDATE(F4,1) -> 45809 | H4: =EDATE(G4,1) -> 45839 | I4: =EDATE(H4,1) -> 45870 | J4: =EDATE(I4,1) -> 45901 | ... M4: =EDATE(L4,1) -> 45992 | N4: Total
A5: Transfer from DWG Capital Group | B5: =SUMIFS(Angela_2025_Chase1117_Activity_!$D$2:$D$2300,Angela_2025_Chase1117_Activity_!$B$2:$B$2300,">="&B$4,Angela_2025_Chase1117_Activity_!$B$2:$B$2300,"<="&EOMONTH(B$4,0),Angela_2025_Chase1117_Activity_!$G$2:$G$2300,$A5) -> 18000 | C5: =SUMIFS(Angela_2025_Chase1117_Activity_!$D$2:$D$2300,Angela_2025_Chase1117_Activity_!$B$2:$B$2300,">="&C$4,Angela_2025_Chase1117_Activity_!$B$2:$B$2300,"<="&EOMONTH(C$4,0),Angela_2025_Chase1117_Activity_!$G$2:$G$2300,$A5) -> 20000 | D5: =SUMIFS(Angela_2025_Chase1117_Activity_!$D$2:$D$2300,Angela_2025_Chase1117_Activity_!$B$2:$B$2300,">="&D$4,Angela_2025_Chase1117_Activity_!$B$2:$B$2300,"<="&EOMONTH(D$4,0),Angela_2025_Chase1117_Activity_!$G$2:$G$2300,$A5) -> 43000 | E5: =SUMIFS(Angela_2025_Chase1117_Activity_!$D$2:$D$2300,Angela_2025_Chase1117_Activity_!$B$2:$B$2300,">="&E$4,Angela_2025_Chase1117_Activity_!$B$2:$B$2300,"<="&EOMONTH(E$4,0),Angela_2025_Chase1117_Activity_!$G$2:$G$2300,$A5) -> 14000 | F5: =SUMIFS(Angela_2025_Chase1117_Activity_!$D$2:$D$2300,Angela_2025_Chase1117_Activity_!$B$2:$B$2300,">="&F$4,Angela_2025_Chase1117_Activity_!$B$2:$B$2300,"<="&EOMONTH(F$4,0),Angela_2025_Chase1117_Activity_!$G$2:$G$2300,$A5) -> 12000 | G5: =SUMIFS(Angela_2025_Chase1117_Activity_!$D$2:$D$2300,Angela_2025_Chase1117_Activity_!$B$2:$B$2300,">="&G$4,Angela_2025_Chase1117_Activity_!$B$2:$B$2300,"<="&EOMONTH(G$4,0),Angela_2025_Chase1117_Activity_!$G$2:$G$2300,$A5) -> 25000 | H5: =SUMIFS(Angela_2025_Chase1117_Activity_!$D$2:$D$2300,Angela_2025_Chase1117_Activity_!$B$2:$B$2300,">="&H$4,Angela_2025_Chase1117_Activity_!$B$2:$B$2300,"<="&EOMONTH(H$4,0),Angela_2025_Chase1117_Activity_!$G$2:$G$2300,$A5) -> 29000 | I5: =SUMIFS(Angela_2025_Chase1117_Activity_!$D$2:$D$2300,Angela_2025_Chase1117_Activity_!$B$2:$B$2300,">="&I$4,Angela_2025_Chase1117_Activity_!$B$2:$B$2300,"<="&EOMONTH(I$4,0),Angela_2025_Chase1117_Activity_!$G$2:$G$2300,$A5) -> 22000 | ... M5: =SUMIFS(Angela_2025_Chase1117_Activity_!$D$2:$D$2300,Angela_2025_Chase1117_Activity_!$B$2:$B$2300,">="&M$4,Angela_2025_Chase1117_Activity_!$B$2:$B$2300,"<="&EOMONTH(M$4,0),Angela_2025_Chase1117_Activity_!$G$2:$G$2300,$A5) -> 31000 | N5: =SUM(B5:M5) -> 306000
A6: Transfer to Ava | B6: =SUMIFS(Angela_2025_Chase1117_Activity_!$D$2:$D$2300,Angela_2025_Chase1117_Activity_!$B$2:$B$2300,">="&B$4,Angela_2025_Chase1117_Activity_!$B$2:$B$2300,"<="&EOMONTH(B$4,0),Angela_2025_Chase1117_Activity_!$G$2:$G$2300,$A6) -> 0 | C6: =SUMIFS(Angela_2025_Chase1117_Activity_!$D$2:$D$2300,Angela_2025_Chase1117_Activity_!$B$2:$B$2300,">="&C$4,Angela_2025_Chase1117_Activity_!$B$2:$B$2300,"<="&EOMONTH(C$4,0),Angela_2025_Chase1117_Activity_!$G$2:$G$2300,$A6) -> -600 | D6: =SUMIFS(Angela_2025_Chase1117_Activity_!$D$2:$D$2300,Angela_2025_Chase1117_Activity_!$B$2:$B$2300,">="&D$4,Angela_2025_Chase1117_Activity_!$B$2:$B$2300,"<="&EOMONTH(D$4,0),Angela_2025_Chase1117_Activity_!$G$2:$G$2300,$A6) -> -1000 | E6: =SUMIFS(Angela_2025_Chase1117_Activity_!$D$2:$D$2300,Angela_2025_Chase1117_Activity_!$B$2:$B$2300,">="&E$4,Angela_2025_Chase1117_Activity_!$B$2:$B$2300,"<="&EOMONTH(E$4,0),Angela_2025_Chase1117_Activity_!$G$2:$G$2300,$A6) -> -2000 | F6: =SUMIFS(Angela_2025_Chase1117_Activity_!$D$2:$D$2300,Angela_2025_Chase1117_Activity_!$B$2:$B$2300,">="&F$4,Angela_2025_Chase1117_Activity_!$B$2:$B$2300,"<="&EOMONTH(F$4,0),Angela_2025_Chase1117_Activity_!$G$2:$G$2300,$A6) -> 0 | G6: =SUMIFS(Angela_2025_Chase1117_Activity_!$D$2:$D$2300,Angela_2025_Chase1117_Activity_!$B$2:$B$2300,">="&G$4,Angela_2025_Chase1117_Activity_!$B$2:$B$2300,"<="&EOMONTH(G$4,0),Angela_2025_Chase1117_Activity_!$G$2:$G$2300,$A6) -> -400 | H6: =SUMIFS(Angela_2025_Chase1117_Activity_!$D$2:$D$2300,Angela_2025_Chase1117_Activity_!$B$2:$B$2300,">="&H$4,Angela_2025_Chase1117_Activity_!$B$2:$B$2300,"<="&EOMONTH(H$4,0),Angela_2025_Chase1117_Activity_!$G$2:$G$2300,$A6) -> 0 | I6: =SUMIFS(Angela_2025_Chase1117_Activity_!$D$2:$D$2300,Angela_2025_Chase1117_Activity_!$B$2:$B$2300,">="&I$4,Angela_2025_Chase1117_Activity_!$B$2:$B$2300,"<="&EOMONTH(I$4,0),Angela_2025_Chase1117_Activity_!$G$2:$G$2300,$A6) -> -500 | ... M6: =SUMIFS(Angela_2025_Chase1117_Activity_!$D$2:$D$2300,Angela_2025_Chase1117_Activity_!$B$2:$B$2300,">="&M$4,Angela_2025_Chase1117_Activity_!$B$2:$B$2300,"<="&EOMONTH(M$4,0),Angela_2025_Chase1117_Activity_!$G$2:$G$2300,$A6) -> -1100 | N6: =SUM(B6:M6) -> -12500
A7: Transfer from Poseidon Asset Group | B7: =SUMIFS(Angela_2025_Chase1117_Activity_!$D$2:$D$2300,Angela_2025_Chase1117_Activity_!$B$2:$B$2300,">="&B$4,Angela_2025_Chase1117_Activity_!$B$2:$B$2300,"<="&EOMONTH(B$4,0),Angela_2025_Chase1117_Activity_!$G$2:$G$2300,$A7) -> 0 | C7: =SUMIFS(Angela_2025_Chase1117_Activity_!$D$2:$D$2300,Angela_2025_Chase1117_Activity_!$B$2:$B$2300,">="&C$4,Angela_2025_Chase1117_Activity_!$B$2:$B$2300,"<="&EOMONTH(C$4,0),Angela_2025_Chase1117_Activity_!$G$2:$G$2300,$A7) -> 0 | D7: =SUMIFS(Angela_2025_Chase1117_Activity_!$D$2:$D$2300,Angela_2025_Chase1117_Activity_!$B$2:$B$2300,">="&D$4,Angela_2025_Chase1117_Activity_!$B$2:$B$2300,"<="&EOMONTH(D$4,0),Angela_2025_Chase1117_Activity_!$G$2:$G$2300,$A7) -> 0 | E7: =SUMIFS(Angela_2025_Chase1117_Activity_!$D$2:$D$2300,Angela_2025_Chase1117_Activity_!$B$2:$B$2300,">="&E$4,Angela_2025_Chase1117_Activity_!$B$2:$B$2300,"<="&EOMONTH(E$4,0),Angela_2025_Chase1117_Activity_!$G$2:$G$2300,$A7) -> 0 | F7: =SUMIFS(Angela_2025_Chase1117_Activity_!$D$2:$D$2300,Angela_2025_Chase1117_Activity_!$B$2:$B$2300,">="&F$4,Angela_2025_Chase1117_Activity_!$B$2:$B$2300,"<="&EOMONTH(F$4,0),Angela_2025_Chase1117_Activity_!$G$2:$G$2300,$A7) -> 1000 | G7: =SUMIFS(Angela_2025_Chase1117_Activity_!$D$2:$D$2300,Angela_2025_Chase1117_Activity_!$B$2:$B$2300,">="&G$4,Angela_2025_Chase1117_Activity_!$B$2:$B$2300,"<="&EOMONTH(G$4,0),Angela_2025_Chase1117_Activity_!$G$2:$G$2300,$A7) -> 0 | H7: =SUMIFS(Angela_2025_Chase1117_Activity_!$D$2:$D$2300,Angela_2025_Chase1117_Activity_!$B$2:$B$2300,">="&H$4,Angela_2025_Chase1117_Activity_!$B$2:$B$2300,"<="&EOMONTH(H$4,0),Angela_2025_Chase1117_Activity_!$G$2:$G$2300,$A7) -> 0 | I7: =SUMIFS(Angela_2025_Chase1117_Activity_!$D$2:$D$2300,Angela_2025_Chase1117_Activity_!$B$2:$B$2300,">="&I$4,Angela_2025_Chase1117_Activity_!$B$2:$B$2300,"<="&EOMONTH(I$4,0),Angela_2025_Chase1117_Activity_!$G$2:$G$2300,$A7) -> 0 | ... M7: =SUMIFS(Angela_2025_Chase1117_Activity_!$D$2:$D$2300,Angela_2025_Chase1117_Activity_!$B$2:$B$2300,">="&M$4,Angela_2025_Chase1117_Activity_!$B$2:$B$2300,"<="&EOMONTH(M$4,0),Angela_2025_Chase1117_Activity_!$G$2:$G$2300,$A7) -> 0 | N7: =SUM(B7:M7) -> 1000
A8: Transfer to DWG Capital Group_Savings | B8: =SUMIFS(Angela_2025_Chase1117_Activity_!$D$2:$D$2300,Angela_2025_Chase1117_Activity_!$B$2:$B$2300,">="&B$4,Angela_2025_Chase1117_Activity_!$B$2:$B$2300,"<="&EOMONTH(B$4,0),Angela_2025_Chase1117_Activity_!$G$2:$G$2300,$A8) -> 0 | C8: =SUMIFS(Angela_2025_Chase1117_Activity_!$D$2:$D$2300,Angela_2025_Chase1117_Activity_!$B$2:$B$2300,">="&C$4,Angela_2025_Chase1117_Activity_!$B$2:$B$2300,"<="&EOMONTH(C$4,0),Angela_2025_Chase1117_Activity_!$G$2:$G$2300,$A8) -> 0 | D8: =SUMIFS(Angela_2025_Chase1117_Activity_!$D$2:$D$2300,Angela_2025_Chase1117_Activity_!$B$2:$B$2300,">="&D$4,Angela_2025_Chase1117_Activity_!$B$2:$B$2300,"<="&EOMONTH(D$4,0),Angela_2025_Chase1117_Activity_!$G$2:$G$2300,$A8) -> 0 | E8: =SUMIFS(Angela_2025_Chase1117_Activity_!$D$2:$D$2300,Angela_2025_Chase1117_Activity_!$B$2:$B$2300,">="&E$4,Angela_2025_Chase1117_Activity_!$B$2:$B$2300,"<="&EOMONTH(E$4,0),Angela_2025_Chase1117_Activity_!$G$2:$G$2300,$A8) -> 0 | F8: =SUMIFS(Angela_2025_Chase1117_Activity_!$D$2:$D$2300,Angela_2025_Chase1117_Activity_!$B$2:$B$2300,">="&F$4,Angela_2025_Chase1117_Activity_!$B$2:$B$2300,"<="&EOMONTH(F$4,0),Angela_2025_Chase1117_Activity_!$G$2:$G$2300,$A8) -> 0 | G8: =SUMIFS(Angela_2025_Chase1117_Activity_!$D$2:$D$2300,Angela_2025_Chase1117_Activity_!$B$2:$B$2300,">="&G$4,Angela_2025_Chase1117_Activity_!$B$2:$B$2300,"<="&EOMONTH(G$4,0),Angela_2025_Chase1117_Activity_!$G$2:$G$2300,$A8) -> 0 | H8: =SUMIFS(Angela_2025_Chase1117_Activity_!$D$2:$D$2300,Angela_2025_Chase1117_Activity_!$B$2:$B$2300,">="&H$4,Angela_2025_Chase1117_Activity_!$B$2:$B$2300,"<="&EOMONTH(H$4,0),Angela_2025_Chase1117_Activity_!$G$2:$G$2300,$A8) -> -300 | I8: =SUMIFS(Angela_2025_Chase1117_Activity_!$D$2:$D$2300,Angela_2025_Chase1117_Activity_!$B$2:$B$2300,">="&I$4,Angela_2025_Chase1117_Activity_!$B$2:$B$2300,"<="&EOMONTH(I$4,0),Angela_2025_Chase1117_Activity_!$G$2:$G$2300,$A8) -> 0 | ... M8: =SUMIFS(Angela_2025_Chase1117_Activity_!$D$2:$D$2300,Angela_2025_Chase1117_Activity_!$B$2:$B$2300,">="&M$4,Angela_2025_Chase1117_Activity_!$B$2:$B$2300,"<="&EOMONTH(M$4,0),Angela_2025_Chase1117_Activity_!$G$2:$G$2300,$A8) -> 0 | N8: =SUM(B8:M8) -> -300
A9: Zelle from Mary Margaret Trahan | B9: =SUMIFS(Angela_2025_Chase1117_Activity_!$D$2:$D$2300,Angela_2025_Chase1117_Activity_!$B$2:$B$2300,">="&B$4,Angela_2025_Chase1117_Activity_!$B$2:$B$2300,"<="&EOMONTH(B$4,0),Angela_2025_Chase1117_Activity_!$G$2:$G$2300,$A9) -> 0 | C9: =SUMIFS(Angela_2025_Chase1117_Activity_!$D$2:$D$2300,Angela_2025_Chase1117_Activity_!$B$2:$B$2300,">="&C$4,Angela_2025_Chase1117_Activity_!$B$2:$B$2300,"<="&EOMONTH(C$4,0),Angela_2025_Chase1117_Activity_!$G$2:$G$2300,$A9) -> 0 | D9: =SUMIFS(Angela_2025_Chase1117_Activity_!$D$2:$D$2300,Angela_2025_Chase1117_Activity_!$B$2:$B$2300,">="&D$4,Angela_2025_Chase1117_Activity_!$B$2:$B$2300,"<="&EOMONTH(D$4,0),Angela_2025_Chase1117_Activity_!$G$2:$G$2300,$A9) -> 0 | E9: =SUMIFS(Angela_2025_Chase1117_Activity_!$D$2:$D$2300,Angela_2025_Chase1117_Activity_!$B$2:$B$2300,">="&E$4,Angela_2025_Chase1117_Activity_!$B$2:$B$2300,"<="&EOMONTH(E$4,0),Angela_2025_Chase1117_Activity_!$G$2:$G$2300,$A9) -> 0 | F9: =SUMIFS(Angela_2025_Chase1117_Activity_!$D$2:$D$2300,Angela_2025_Chase1117_Activity_!$B$2:$B$2300,">="&F$4,Angela_2025_Chase1117_Activity_!$B$2:$B$2300,"<="&EOMONTH(F$4,0),Angela_2025_Chase1117_Activity_!$G$2:$G$2300,$A9) -> 0 | G9: =SUMIFS(Angela_2025_Chase1117_Activity_!$D$2:$D$2300,Angela_2025_Chase1117_Activity_!$B$2:$B$2300,">="&G$4,Angela_2025_Chase1117_Activity_!$B$2:$B$2300,"<="&EOMONTH(G$4,0),Angela_2025_Chase1117_Activity_!$G$2:$G$2300,$A9) -> 0 | H9: =SUMIFS(Angela_2025_Chase1117_Activity_!$D$2:$D$2300,Angela_2025_Chase1117_Activity_!$B$2:$B$2300,">="&H$4,Angela_2025_Chase1117_Activity_!$B$2:$B$2300,"<="&EOMONTH(H$4,0),Angela_2025_Chase1117_Activity_!$G$2:$G$2300,$A9) -> 0 | I9: =SUMIFS(Angela_2025_Chase1117_Activity_!$D$2:$D$2300,Angela_2025_Chase1117_Activity_!$B$2:$B$2300,">="&I$4,Angela_2025_Chase1117_Activity_!$B$2:$B$2300,"<="&EOMONTH(I$4,0),Angela_2025_Chase1117_Activity_!$G$2:$G$2300,$A9) -> 225 | ... M9: =SUMIFS(Angela_2025_Chase1117_Activity_!$D$2:$D$2300,Angela_2025_Chase1117_Activity_!$B$2:$B$2300,">="&M$4,Angela_2025_Chase1117_Activity_!$B$2:$B$2300,"<="&EOMONTH(M$4,0),Angela_2025_Chase1117_Activity_!$G$2:$G$2300,$A9) -> 0 | N9: =SUM(B9:M9) -> 375
A10: Zelle from Rose Li | B10: =SUMIFS(Angela_2025_Chase1117_Activity_!$D$2:$D$2300,Angela_2025_Chase1117_Activity_!$B$2:$B$2300,">="&B$4,Angela_2025_Chase1117_Activity_!$B$2:$B$2300,"<="&EOMONTH(B$4,0),Angela_2025_Chase1117_Activity_!$G$2:$G$2300,$A10) -> 0 | C10: =SUMIFS(Angela_2025_Chase1117_Activity_!$D$2:$D$2300,Angela_2025_Chase1117_Activity_!$B$2:$B$2300,">="&C$4,Angela_2025_Chase1117_Activity_!$B$2:$B$2300,"<="&EOMONTH(C$4,0),Angela_2025_Chase1117_Activity_!$G$2:$G$2300,$A10) -> 450 | D10: =SUMIFS(Angela_2025_Chase1117_Activity_!$D$2:$D$2300,Angela_2025_Chase1117_Activity_!$B$2:$B$2300,">="&D$4,Angela_2025_Chase1117_Activity_!$B$2:$B$2300,"<="&EOMONTH(D$4,0),Angela_2025_Chase1117_Activity_!$G$2:$G$2300,$A10) -> 0 | E10: =SUMIFS(Angela_2025_Chase1117_Activity_!$D$2:$D$2300,Angela_2025_Chase1117_Activity_!$B$2:$B$2300,">="&E$4,Angela_2025_Chase1117_Activity_!$B$2:$B$2300,"<="&EOMONTH(E$4,0),Angela_2025_Chase1117_Activity_!$G$2:$G$2300,$A10) -> 450 | F10: =SUMIFS(Angela_2025_Chase1117_Activity_!$D$2:$D$2300,Angela_2025_Chase1117_Activity_!$B$2:$B$2300,">="&F$4,Angela_2025_Chase1117_Activity_!$B$2:$B$2300,"<="&EOMONTH(F$4,0),Angela_2025_Chase1117_Activity_!$G$2:$G$2300,$A10) -> 0 | G10: =SUMIFS(Angela_2025_Chase1117_Activity_!$D$2:$D$2300,Angela_2025_Chase1117_Activity_!$B$2:$B$2300,">="&G$4,Angela_2025_Chase1117_Activity_!$B$2:$B$2300,"<="&EOMONTH(G$4,0),Angela_2025_Chase1117_Activity_!$G$2:$G$2300,$A10) -> 0 | H10: =SUMIFS(Angela_2025_Chase1117_Activity_!$D$2:$D$2300,Angela_2025_Chase1117_Activity_!$B$2:$B$2300,">="&H$4,Angela_2025_Chase1117_Activity_!$B$2:$B$2300,"<="&EOMONTH(H$4,0),Angela_2025_Chase1117_Activity_!$G$2:$G$2300,$A10) -> 150 | I10: =SUMIFS(Angela_2025_Chase1117_Activity_!$D$2:$D$2300,Angela_2025_Chase1117_Activity_!$B$2:$B$2300,">="&I$4,Angela_2025_Chase1117_Activity_!$B$2:$B$2300,"<="&EOMONTH(I$4,0),Angela_2025_Chase1117_Activity_!$G$2:$G$2300,$A10) -> 0 | ... M10: =SUMIFS(Angela_2025_Chase1117_Activity_!$D$2:$D$2300,Angela_2025_Chase1117_Activity_!$B$2:$B$2300,">="&M$4,Angela_2025_Chase1117_Activity_!$B$2:$B$2300,"<="&EOMONTH(M$4,0),Angela_2025_Chase1117_Activity_!$G$2:$G$2300,$A10) -> 300 | N10: =SUM(B10:M10) -> 1350
A11: Zelle from Joe Saunders | B11: =SUMIFS(Angela_2025_Chase1117_Activity_!$D$2:$D$2300,Angela_2025_Chase1117_Activity_!$B$2:$B$2300,">="&B$4,Angela_2025_Chase1117_Activity_!$B$2:$B$2300,"<="&EOMONTH(B$4,0),Angela_2025_Chase1117_Activity_!$G$2:$G$2300,$A11) -> 0 | C11: =SUMIFS(Angela_2025_Chase1117_Activity_!$D$2:$D$2300,Angela_2025_Chase1117_Activity_!$B$2:$B$2300,">="&C$4,Angela_2025_Chase1117_Activity_!$B$2:$B$2300,"<="&EOMONTH(C$4,0),Angela_2025_Chase1117_Activity_!$G$2:$G$2300,$A11) -> 130 | D11: =SUMIFS(Angela_2025_Chase1117_Activity_!$D$2:$D$2300,Angela_2025_Chase1117_Activity_!$B$2:$B$2300,">="&D$4,Angela_2025_Chase1117_Activity_!$B$2:$B$2300,"<="&EOMONTH(D$4,0),Angela_2025_Chase1117_Activity_!$G$2:$G$2300,$A11) -> 130 | E11: =SUMIFS(Angela_2025_Chase1117_Activity_!$D$2:$D$2300,Angela_2025_Chase1117_Activity_!$B$2:$B$2300,">="&E$4,Angela_2025_Chase1117_Activity_!$B$2:$B$2300,"<="&EOMONTH(E$4,0),Angela_2025_Chase1117_Activity_!$G$2:$G$2300,$A11) -> 0 | F11: =SUMIFS(Angela_2025_Chase1117_Activity_!$D$2:$D$2300,Angela_2025_Chase1117_Activity_!$B$2:$B$2300,">="&F$4,Angela_2025_Chase1117_Activity_!$B$2:$B$2300,"<="&EOMONTH(F$4,0),Angela_2025_Chase1117_Activity_!$G$2:$G$2300,$A11) -> 1130 | G11: =SUMIFS(Angela_2025_Chase1117_Activity_!$D$2:$D$2300,Angela_2025_Chase1117_Activity_!$B$2:$B$2300,">="&G$4,Angela_2025_Chase1117_Activity_!$B$2:$B$2300,"<="&EOMONTH(G$4,0),Angela_2025_Chase1117_Activity_!$G$2:$G$2300,$A11) -> 530 | H11: =SUMIFS(Angela_2025_Chase1117_Activity_!$D$2:$D$2300,Angela_2025_Chase1117_Activity_!$B$2:$B$2300,">="&H$4,Angela_2025_Chase1117_Activity_!$B$2:$B$2300,"<="&EOMONTH(H$4,0),Angela_2025_Chase1117_Activity_!$G$2:$G$2300,$A11) -> 0 | I11: =SUMIFS(Angela_2025_Chase1117_Activity_!$D$2:$D$2300,Angela_2025_Chase1117_Activity_!$B$2:$B$2300,">="&I$4,Angela_2025_Chase1117_Activity_!$B$2:$B$2300,"<="&EOMONTH(I$4,0),Angela_2025_Chase1117_Activity_!$G$2:$G$2300,$A11) -> 530 | ... M11: =SUMIFS(Angela_2025_Chase1117_Activity_!$D$2:$D$2300,Angela_2025_Chase1117_Activity_!$B$2:$B$2300,">="&M$4,Angela_2025_Chase1117_Activity_!$B$2:$B$2300,"<="&EOMONTH(M$4,0),Angela_2025_Chase1117_Activity_!$G$2:$G$2300,$A11) -> 0 | N11: =SUM(B11:M11) -> 3950
A12: Zelle to Joe Saunders | B12: =SUMIFS(Angela_2025_Chase1117_Activity_!$D$2:$D$2300,Angela_2025_Chase1117_Activity_!$B$2:$B$2300,">="&B$4,Angela_2025_Chase1117_Activity_!$B$2:$B$2300,"<="&EOMONTH(B$4,0),Angela_2025_Chase1117_Activity_!$G$2:$G$2300,$A12) -> 0 | C12: =SUMIFS(Angela_2025_Chase1117_Activity_!$D$2:$D$2300,Angela_2025_Chase1117_Activity_!$B$2:$B$2300,">="&C$4,Angela_2025_Chase1117_Activity_!$B$2:$B$2300,"<="&EOMONTH(C$4,0),Angela_2025_Chase1117_Activity_!$G$2:$G$2300,$A12) -> 0 | D12: =SUMIFS(Angela_2025_Chase1117_Activity_!$D$2:$D$2300,Angela_2025_Chase1117_Activity_!$B$2:$B$2300,">="&D$4,Angela_2025_Chase1117_Activity_!$B$2:$B$2300,"<="&EOMONTH(D$4,0),Angela_2025_Chase1117_Activity_!$G$2:$G$2300,$A12) -> 0 | E12: =SUMIFS(Angela_2025_Chase1117_Activity_!$D$2:$D$2300,Angela_2025_Chase1117_Activity_!$B$2:$B$2300,">="&E$4,Angela_2025_Chase1117_Activity_!$B$2:$B$2300,"<="&EOMONTH(E$4,0),Angela_2025_Chase1117_Activity_!$G$2:$G$2300,$A12) -> 0 | F12: =SUMIFS(Angela_2025_Chase1117_Activity_!$D$2:$D$2300,Angela_2025_Chase1117_Activity_!$B$2:$B$2300,">="&F$4,Angela_2025_Chase1117_Activity_!$B$2:$B$2300,"<="&EOMONTH(F$4,0),Angela_2025_Chase1117_Activity_!$G$2:$G$2300,$A12) -> -500 | G12: =SUMIFS(Angela_2025_Chase1117_Activity_!$D$2:$D$2300,Angela_2025_Chase1117_Activity_!$B$2:$B$2300,">="&G$4,Angela_2025_Chase1117_Activity_!$B$2:$B$2300,"<="&EOMONTH(G$4,0),Angela_2025_Chase1117_Activity_!$G$2:$G$2300,$A12) -> 0 | H12: =SUMIFS(Angela_2025_Chase1117_Activity_!$D$2:$D$2300,Angela_2025_Chase1117_Activity_!$B$2:$B$2300,">="&H$4,Angela_2025_Chase1117_Activity_!$B$2:$B$2300,"<="&EOMONTH(H$4,0),Angela_2025_Chase1117_Activity_!$G$2:$G$2300,$A12) -> 0 | I12: =SUMIFS(Angela_2025_Chase1117_Activity_!$D$2:$D$2300,Angela_2025_Chase1117_Activity_!$B$2:$B$2300,">="&I$4,Angela_2025_Chase1117_Activity_!$B$2:$B$2300,"<="&EOMONTH(I$4,0),Angela_2025_Chase1117_Activity_!$G$2:$G$2300,$A12) -> 0 | ... M12: =SUMIFS(Angela_2025_Chase1117_Activity_!$D$2:$D$2300,Angela_2025_Chase1117_Activity_!$B$2:$B$2300,">="&M$4,Angela_2025_Chase1117_Activity_!$B$2:$B$2300,"<="&EOMONTH(M$4,0),Angela_2025_Chase1117_Activity_!$G$2:$G$2300,$A12) -> 0 | N12: =SUM(B12:M12) -> -500
A13: Zelle from Tanya Miller | B13: =SUMIFS(Angela_2025_Chase1117_Activity_!$D$2:$D$2300,Angela_2025_Chase1117_Activity_!$B$2:$B$2300,">="&B$4,Angela_2025_Chase1117_Activity_!$B$2:$B$2300,"<="&EOMONTH(B$4,0),Angela_2025_Chase1117_Activity_!$G$2:$G$2300,$A13) -> 0 | C13: =SUMIFS(Angela_2025_Chase1117_Activity_!$D$2:$D$2300,Angela_2025_Chase1117_Activity_!$B$2:$B$2300,">="&C$4,Angela_2025_Chase1117_Activity_!$B$2:$B$2300,"<="&EOMONTH(C$4,0),Angela_2025_Chase1117_Activity_!$G$2:$G$2300,$A13) -> 0 | D13: =SUMIFS(Angela_2025_Chase1117_Activity_!$D$2:$D$2300,Angela_2025_Chase1117_Activity_!$B$2:$B$2300,">="&D$4,Angela_2025_Chase1117_Activity_!$B$2:$B$2300,"<="&EOMONTH(D$4,0),Angela_2025_Chase1117_Activity_!$G$2:$G$2300,$A13) -> 100 | E13: =SUMIFS(Angela_2025_Chase1117_Activity_!$D$2:$D$2300,Angela_2025_Chase1117_Activity_!$B$2:$B$2300,">="&E$4,Angela_2025_Chase1117_Activity_!$B$2:$B$2300,"<="&EOMONTH(E$4,0),Angela_2025_Chase1117_Activity_!$G$2:$G$2300,$A13) -> 0 | F13: =SUMIFS(Angela_2025_Chase1117_Activity_!$D$2:$D$2300,Angela_2025_Chase1117_Activity_!$B$2:$B$2300,">="&F$4,Angela_2025_Chase1117_Activity_!$B$2:$B$2300,"<="&EOMONTH(F$4,0),Angela_2025_Chase1117_Activity_!$G$2:$G$2300,$A13) -> 0 | G13: =SUMIFS(Angela_2025_Chase1117_Activity_!$D$2:$D$2300,Angela_2025_Chase1117_Activity_!$B$2:$B$2300,">="&G$4,Angela_2025_Chase1117_Activity_!$B$2:$B$2300,"<="&EOMONTH(G$4,0),Angela_2025_Chase1117_Activity_!$G$2:$G$2300,$A13) -> 100 | H13: =SUMIFS(Angela_2025_Chase1117_Activity_!$D$2:$D$2300,Angela_2025_Chase1117_Activity_!$B$2:$B$2300,">="&H$4,Angela_2025_Chase1117_Activity_!$B$2:$B$2300,"<="&EOMONTH(H$4,0),Angela_2025_Chase1117_Activity_!$G$2:$G$2300,$A13) -> 0 | I13: =SUMIFS(Angela_2025_Chase1117_Activity_!$D$2:$D$2300,Angela_2025_Chase1117_Activity_!$B$2:$B$2300,">="&I$4,Angela_2025_Chase1117_Activity_!$B$2:$B$2300,"<="&EOMONTH(I$4,0),Angela_2025_Chase1117_Activity_!$G$2:$G$2300,$A13) -> 0 | ... M13: =SUMIFS(Angela_2025_Chase1117_Activity_!$D$2:$D$2300,Angela_2025_Chase1117_Activity_!$B$2:$B$2300,">="&M$4,Angela_2025_Chase1117_Activity_!$B$2:$B$2300,"<="&EOMONTH(M$4,0),Angela_2025_Chase1117_Activity_!$G$2:$G$2300,$A13) -> 0 | N13: =SUM(B13:M13) -> 200
A14: Zelle to Britt Magadini | B14: =SUMIFS(Angela_2025_Chase1117_Activity_!$D$2:$D$2300,Angela_2025_Chase1117_Activity_!$B$2:$B$2300,">="&B$4,Angela_2025_Chase1117_Activity_!$B$2:$B$2300,"<="&EOMONTH(B$4,0),Angela_2025_Chase1117_Activity_!$G$2:$G$2300,$A14) -> 0 | C14: =SUMIFS(Angela_2025_Chase1117_Activity_!$D$2:$D$2300,Angela_2025_Chase1117_Activity_!$B$2:$B$2300,">="&C$4,Angela_2025_Chase1117_Activity_!$B$2:$B$2300,"<="&EOMONTH(C$4,0),Angela_2025_Chase1117_Activity_!$G$2:$G$2300,$A14) -> 0 | D14: =SUMIFS(Angela_2025_Chase1117_Activity_!$D$2:$D$2300,Angela_2025_Chase1117_Activity_!$B$2:$B$2300,">="&D$4,Angela_2025_Chase1117_Activity_!$B$2:$B$2300,"<="&EOMONTH(D$4,0),Angela_2025_Chase1117_Activity_!$G$2:$G$2300,$A14) -> 0 | E14: =SUMIFS(Angela_2025_Chase1117_Activity_!$D$2:$D$2300,Angela_2025_Chase1117_Activity_!$B$2:$B$2300,">="&E$4,Angela_2025_Chase1117_Activity_!$B$2:$B$2300,"<="&EOMONTH(E$4,0),Angela_2025_Chase1117_Activity_!$G$2:$G$2300,$A14) -> -300 | F14: =SUMIFS(Angela_2025_Chase1117_Activity_!$D$2:$D$2300,Angela_2025_Chase1117_Activity_!$B$2:$B$2300,">="&F$4,Angela_2025_Chase1117_Activity_!$B$2:$B$2300,"<="&EOMONTH(F$4,0),Angela_2025_Chase1117_Activity_!$G$2:$G$2300,$A14) -> 0 | G14: =SUMIFS(Angela_2025_Chase1117_Activity_!$D$2:$D$2300,Angela_2025_Chase1117_Activity_!$B$2:$B$2300,">="&G$4,Angela_2025_Chase1117_Activity_!$B$2:$B$2300,"<="&EOMONTH(G$4,0),Angela_2025_Chase1117_Activity_!$G$2:$G$2300,$A14) -> -500 | H14: =SUMIFS(Angela_2025_Chase1117_Activity_!$D$2:$D$2300,Angela_2025_Chase1117_Activity_!$B$2:$B$2300,">="&H$4,Angela_2025_Chase1117_Activity_!$B$2:$B$2300,"<="&EOMONTH(H$4,0),Angela_2025_Chase1117_Activity_!$G$2:$G$2300,$A14) -> 0 | I14: =SUMIFS(Angela_2025_Chase1117_Activity_!$D$2:$D$2300,Angela_2025_Chase1117_Activity_!$B$2:$B$2300,">="&I$4,Angela_2025_Chase1117_Activity_!$B$2:$B$2300,"<="&EOMONTH(I$4,0),Angela_2025_Chase1117_Activity_!$G$2:$G$2300,$A14) -> -300 | ... M14: =SUMIFS(Angela_2025_Chase1117_Activity_!$D$2:$D$2300,Angela_2025_Chase1117_Activity_!$B$2:$B$2300,">="&M$4,Angela_2025_Chase1117_Activity_!$B$2:$B$2300,"<="&EOMONTH(M$4,0),Angela_2025_Chase1117_Activity_!$G$2:$G$2300,$A14) -> 0 | N14: =SUM(B14:M14) -> -1100
A15: Zelle from Eunice G Chang | B15: =SUMIFS(Angela_2025_Chase1117_Activity_!$D$2:$D$2300,Angela_2025_Chase1117_Activity_!$B$2:$B$2300,">="&B$4,Angela_2025_Chase1117_Activity_!$B$2:$B$2300,"<="&EOMONTH(B$4,0),Angela_2025_Chase1117_Activity_!$G$2:$G$2300,$A15) -> 175 | C15: =SUMIFS(Angela_2025_Chase1117_Activity_!$D$2:$D$2300,Angela_2025_Chase1117_Activity_!$B$2:$B$2300,">="&C$4,Angela_2025_Chase1117_Activity_!$B$2:$B$2300,"<="&EOMONTH(C$4,0),Angela_2025_Chase1117_Activity_!$G$2:$G$2300,$A15) -> 0 | D15: =SUMIFS(Angela_2025_Chase1117_Activity_!$D$2:$D$2300,Angela_2025_Chase1117_Activity_!$B$2:$B$2300,">="&D$4,Angela_2025_Chase1117_Activity_!$B$2:$B$2300,"<="&EOMONTH(D$4,0),Angela_2025_Chase1117_Activity_!$G$2:$G$2300,$A15) -> 0 | E15: =SUMIFS(Angela_2025_Chase1117_Activity_!$D$2:$D$2300,Angela_2025_Chase1117_Activity_!$B$2:$B$2300,">="&E$4,Angela_2025_Chase1117_Activity_!$B$2:$B$2300,"<="&EOMONTH(E$4,0),Angela_2025_Chase1117_Activity_!$G$2:$G$2300,$A15) -> 0 | F15: =SUMIFS(Angela_2025_Chase1117_Activity_!$D$2:$D$2300,Angela_2025_Chase1117_Activity_!$B$2:$B$2300,">="&F$4,Angela_2025_Chase1117_Activity_!$B$2:$B$2300,"<="&EOMONTH(F$4,0),Angela_2025_Chase1117_Activity_!$G$2:$G$2300,$A15) -> 0 | G15: =SUMIFS(Angela_2025_Chase1117_Activity_!$D$2:$D$2300,Angela_2025_Chase1117_Activity_!$B$2:$B$2300,">="&G$4,Angela_2025_Chase1117_Activity_!$B$2:$B$2300,"<="&EOMONTH(G$4,0),Angela_2025_Chase1117_Activity_!$G$2:$G$2300,$A15) -> 0 | H15: =SUMIFS(Angela_2025_Chase1117_Activity_!$D$2:$D$2300,Angela_2025_Chase1117_Activity_!$B$2:$B$2300,">="&H$4,Angela_2025_Chase1117_Activity_!$B$2:$B$2300,"<="&EOMONTH(H$4,0),Angela_2025_Chase1117_Activity_!$G$2:$G$2300,$A15) -> 175 | I15: =SUMIFS(Angela_2025_Chase1117_Activity_!$D$2:$D$2300,Angela_2025_Chase1117_Activity_!$B$2:$B$2300,">="&I$4,Angela_2025_Chase1117_Activity_!$B$2:$B$2300,"<="&EOMONTH(I$4,0),Angela_2025_Chase1117_Activity_!$G$2:$G$2300,$A15) -> 0 | ... M15: =SUMIFS(Angela_2025_Chase1117_Activity_!$D$2:$D$2300,Angela_2025_Chase1117_Activity_!$B$2:$B$2300,">="&M$4,Angela_2025_Chase1117_Activity_!$B$2:$B$2300,"<="&EOMONTH(M$4,0),Angela_2025_Chase1117_Activity_!$G$2:$G$2300,$A15) -> 0 | N15: =SUM(B15:M15) -> 350
A16: Zelle from G-Eunice LLC | B16: =SUMIFS(Angela_2025_Chase1117_Activity_!$D$2:$D$2300,Angela_2025_Chase1117_Activity_!$B$2:$B$2300,">="&B$4,Angela_2025_Chase1117_Activity_!$B$2:$B$2300,"<="&EOMONTH(B$4,0),Angela_2025_Chase1117_Activity_!$G$2:$G$2300,$A16) -> 0 | C16: =SUMIFS(Angela_2025_Chase1117_Activity_!$D$2:$D$2300,Angela_2025_Chase1117_Activity_!$B$2:$B$2300,">="&C$4,Angela_2025_Chase1117_Activity_!$B$2:$B$2300,"<="&EOMONTH(C$4,0),Angela_2025_Chase1117_Activity_!$G$2:$G$2300,$A16) -> 0 | D16: =SUMIFS(Angela_2025_Chase1117_Activity_!$D$2:$D$2300,Angela_2025_Chase1117_Activity_!$B$2:$B$2300,">="&D$4,Angela_2025_Chase1117_Activity_!$B$2:$B$2300,"<="&EOMONTH(D$4,0),Angela_2025_Chase1117_Activity_!$G$2:$G$2300,$A16) -> 0 | E16: =SUMIFS(Angela_2025_Chase1117_Activity_!$D$2:$D$2300,Angela_2025_Chase1117_Activity_!$B$2:$B$2300,">="&E$4,Angela_2025_Chase1117_Activity_!$B$2:$B$2300,"<="&EOMONTH(E$4,0),Angela_2025_Chase1117_Activity_!$G$2:$G$2300,$A16) -> 0 | F16: =SUMIFS(Angela_2025_Chase1117_Activity_!$D$2:$D$2300,Angela_2025_Chase1117_Activity_!$B$2:$B$2300,">="&F$4,Angela_2025_Chase1117_Activity_!$B$2:$B$2300,"<="&EOMONTH(F$4,0),Angela_2025_Chase1117_Activity_!$G$2:$G$2300,$A16) -> 175 | G16: =SUMIFS(Angela_2025_Chase1117_Activity_!$D$2:$D$2300,Angela_2025_Chase1117_Activity_!$B$2:$B$2300,">="&G$4,Angela_2025_Chase1117_Activity_!$B$2:$B$2300,"<="&EOMONTH(G$4,0),Angela_2025_Chase1117_Activity_!$G$2:$G$2300,$A16) -> 0 | H16: =SUMIFS(Angela_2025_Chase1117_Activity_!$D$2:$D$2300,Angela_2025_Chase1117_Activity_!$B$2:$B$2300,">="&H$4,Angela_2025_Chase1117_Activity_!$B$2:$B$2300,"<="&EOMONTH(H$4,0),Angela_2025_Chase1117_Activity_!$G$2:$G$2300,$A16) -> 0 | I16: =SUMIFS(Angela_2025_Chase1117_Activity_!$D$2:$D$2300,Angela_2025_Chase1117_Activity_!$B$2:$B$2300,">="&I$4,Angela_2025_Chase1117_Activity_!$B$2:$B$2300,"<="&EOMONTH(I$4,0),Angela_2025_Chase1117_Activity_!$G$2:$G$2300,$A16) -> 0 | ... M16: =SUMIFS(Angela_2025_Chase1117_Activity_!$D$2:$D$2300,Angela_2025_Chase1117_Activity_!$B$2:$B$2300,">="&M$4,Angela_2025_Chase1117_Activity_!$B$2:$B$2300,"<="&EOMONTH(M$4,0),Angela_2025_Chase1117_Activity_!$G$2:$G$2300,$A16) -> 0 | N16: =SUM(B16:M16) -> 175
... A55: Donation | B55: =SUMIFS(Angela_2025_Chase1117_Activity_!$D$2:$D$2300,Angela_2025_Chase1117_Activity_!$B$2:$B$2300,">="&B$4,Angela_2025_Chase1117_Activity_!$B$2:$B$2300,"<="&EOMONTH(B$4,0),Angela_2025_Chase1117_Activity_!$G$2:$G$2300,$A55) -> 0 | C55: =SUMIFS(Angela_2025_Chase1117_Activity_!$D$2:$D$2300,Angela_2025_Chase1117_Activity_!$B$2:$B$2300,">="&C$4,Angela_2025_Chase1117_Activity_!$B$2:$B$2300,"<="&EOMONTH(C$4,0),Angela_2025_Chase1117_Activity_!$G$2:$G$2300,$A55) -> 0 | D55: =SUMIFS(Angela_2025_Chase1117_Activity_!$D$2:$D$2300,Angela_2025_Chase1117_Activity_!$B$2:$B$2300,">="&D$4,Angela_2025_Chase1117_Activity_!$B$2:$B$2300,"<="&EOMONTH(D$4,0),Angela_2025_Chase1117_Activity_!$G$2:$G$2300,$A55) -> -375 | E55: =SUMIFS(Angela_2025_Chase1117_Activity_!$D$2:$D$2300,Angela_2025_Chase1117_Activity_!$B$2:$B$2300,">="&E$4,Angela_2025_Chase1117_Activity_!$B$2:$B$2300,"<="&EOMONTH(E$4,0),Angela_2025_Chase1117_Activity_!$G$2:$G$2300,$A55) -> 0 | F55: =SUMIFS(Angela_2025_Chase1117_Activity_!$D$2:$D$2300,Angela_2025_Chase1117_Activity_!$B$2:$B$2300,">="&F$4,Angela_2025_Chase1117_Activity_!$B$2:$B$2300,"<="&EOMONTH(F$4,0),Angela_2025_Chase1117_Activity_!$G$2:$G$2300,$A55) -> 0 | G55: =SUMIFS(Angela_2025_Chase1117_Activity_!$D$2:$D$2300,Angela_2025_Chase1117_Activity_!$B$2:$B$2300,">="&G$4,Angela_2025_Chase1117_Activity_!$B$2:$B$2300,"<="&EOMONTH(G$4,0),Angela_2025_Chase1117_Activity_!$G$2:$G$2300,$A55) -> -150 | H55: =SUMIFS(Angela_2025_Chase1117_Activity_!$D$2:$D$2300,Angela_2025_Chase1117_Activity_!$B$2:$B$2300,">="&H$4,Angela_2025_Chase1117_Activity_!$B$2:$B$2300,"<="&EOMONTH(H$4,0),Angela_2025_Chase1117_Activity_!$G$2:$G$2300,$A55) -> -1037 | I55: =SUMIFS(Angela_2025_Chase1117_Activity_!$D$2:$D$2300,Angela_2025_Chase1117_Activity_!$B$2:$B$2300,">="&I$4,Angela_2025_Chase1117_Activity_!$B$2:$B$2300,"<="&EOMONTH(I$4,0),Angela_2025_Chase1117_Activity_!$G$2:$G$2300,$A55) -> -595 | ... M55: =SUMIFS(Angela_2025_Chase1117_Activity_!$D$2:$D$2300,Angela_2025_Chase1117_Activity_!$B$2:$B$2300,">="&M$4,Angela_2025_Chase1117_Activity_!$B$2:$B$2300,"<="&EOMONTH(M$4,0),Angela_2025_Chase1117_Activity_!$G$2:$G$2300,$A55) -> -18.33 | N55: =SUM(B55:M55) -> -2375.33
A56: TOTAL — ALL CATEGORIES | B56: =SUM(B5:B55) -> -1422.22 | C56: =SUM(C5:C55) -> 1057.22 | D56: =SUM(D5:D55) -> 9924.93 | E56: =SUM(E5:E55) -> -6642.32 | F56: =SUM(F5:F55) -> -3233.66 | G56: =SUM(G5:G55) -> 1436 | H56: =SUM(H5:H55) -> 4747.19 | I56: =SUM(I5:I55) -> -4908.19 | ... N56: =SUM(N5:N55) -> -1241.22

Sheet Category Rules
A1: Keyword | B1: Category
A2: DOORDASH | B2: Uber Eats
A3: AMAZON | B3: Amazon
A4: PRIME VIDEO | B4: Amazon
A5: POSHMARK | B5: Poshmark
A6: GRANDVIEW | B6: Personal - Clothing
A7: AMERICAN AI | B7: Personal Travel
A8: UNITED | B8: Personal Travel
A9: EXPEDIA | B9: Personal Travel
A10: SEVENTH | B10: Personal Travel
A11: SOUTHWEST | B11: Personal Travel
A12: FRONTIER AI | B12: Frontier
... A358: CHK ...0709 | B358: Transfer to DWG Capital Group_Savings

Sheet Angela_2025_Chase1117_Activity_
A1: Details | B1: Posting Date | C1: Description | D1: Amount | E1: Type | F1: Balance | G1: Categories
A2: DEBIT | B2: 46022 | C2: FOREIGN EXCHANGE RATE ADJUSTMENT FEE 12/30CITY OF V | D2: -0.19 | E2: FEE_TRANSACTION | F2: 1549.7 | G2: {=IF(AND(ISNUMBER(SEARCH("UBER",C2)),ISNUMBER(SEARCH("EATS",C2))),"Uber Eats",IF(LEFT(C2,6)="CHECK ","Checks Paid",IF(OR(E2="BILLPAY",ISNUMBER(SEARCH("FRANCHISE TAX",C2)),ISNUMBER(SEARCH("NEXTLINK",C2))),"Personal - House Bills",IF(AND(ISNUMBER(SEARCH("PAYMENT FROM",C2)),ISNUMBER(SEARCH("JOE SAUNDERS",C2))),"Zelle from Joe Saunders",IF(AND(ISNUMBER(SEARCH("PAYMENT TO",C2)),ISNUMBER(SEARCH("JOE SAUNDERS",C2))),"Zelle to Joe Saunders",IF(OR(ISNUMBER(SEARCH("NEW ORLEANS",C2)),ISNUMBER(SEARCH("KENNER",C2)),ISNUMBER(SEARCH("HENRY HOWARD",C2)),ISNUMBER(SEARCH("MISS CLAUDIA",C2))),"Personal Travel - New Orleans",IF(AND(YEAR(B2)=2025,MONTH(B2)=4,OR(ISNUMBER(SEARCH("EXCHANGE RATE",C2)),ISNUMBER(SEARCH("EXCHG RTE",C2)))),"Personal Travel - Italy",IFERROR(INDEX('Category Rules'!$B$2:$B$358,MATCH(TRUE,ISNUMBER(SEARCH('Category Rules'!$A$2:$A$358,C2)),0)),""))))))))} -> Personal Travel - Canada
A3: DEBIT | B3: 46022 | C3: BLUE SHIELD CALIFORNI 800-393-6130 CA 12/31 | D3: -1275.3 | E3: DEBIT_CARD | F3: 1549.89 | G3: {=IF(AND(ISNUMBER(SEARCH("UBER",C3)),ISNUMBER(SEARCH("EATS",C3))),"Uber Eats",IF(LEFT(C3,6)="CHECK ","Checks Paid",IF(OR(E3="BILLPAY",ISNUMBER(SEARCH("FRANCHISE TAX",C3)),ISNUMBER(SEARCH("NEXTLINK",C3))),"Personal - House Bills",IF(AND(ISNUMBER(SEARCH("PAYMENT FROM",C3)),ISNUMBER(SEARCH("JOE SAUNDERS",C3))),"Zelle from Joe Saunders",IF(AND(ISNUMBER(SEARCH("PAYMENT TO",C3)),ISNUMBER(SEARCH("JOE SAUNDERS",C3))),"Zelle to Joe Saunders",IF(OR(ISNUMBER(SEARCH("NEW ORLEANS",C3)),ISNUMBER(SEARCH("KENNER",C3)),ISNUMBER(SEARCH("HENRY HOWARD",C3)),ISNUMBER(SEARCH("MISS CLAUDIA",C3))),"Personal Travel - New Orleans",IF(AND(YEAR(B3)=2025,MONTH(B3)=4,OR(ISNUMBER(SEARCH("EXCHANGE RATE",C3)),ISNUMBER(SEARCH("EXCHG RTE",C3)))),"Personal Travel - Italy",IFERROR(INDEX('Category Rules'!$B$2:$B$358,MATCH(TRUE,ISNUMBER(SEARCH('Category Rules'!$A$2:$A$358,C3)),0)),""))))))))} -> Personal - Health Insurance
A4: DEBIT | B4: 46022 | C4: CITY OF VANCOUVER PARKI VANCOUVER BC 12/30 CA DOLLAR 9.00 X 0.7322222 (EXCHG RTE) | D4: -6.59 | E4: DEBIT_CARD | F4: 2825.19 | G4: {=IF(AND(ISNUMBER(SEARCH("UBER",C4)),ISNUMBER(SEARCH("EATS",C4))),"Uber Eats",IF(LEFT(C4,6)="CHECK ","Checks Paid",IF(OR(E4="BILLPAY",ISNUMBER(SEARCH("FRANCHISE TAX",C4)),ISNUMBER(SEARCH("NEXTLINK",C4))),"Personal - House Bills",IF(AND(ISNUMBER(SEARCH("PAYMENT FROM",C4)),ISNUMBER(SEARCH("JOE SAUNDERS",C4))),"Zelle from Joe Saunders",IF(AND(ISNUMBER(SEARCH("PAYMENT TO",C4)),ISNUMBER(SEARCH("JOE SAUNDERS",C4))),"Zelle to Joe Saunders",IF(OR(ISNUMBER(SEARCH("NEW ORLEANS",C4)),ISNUMBER(SEARCH("KENNER",C4)),ISNUMBER(SEARCH("HENRY HOWARD",C4)),ISNUMBER(SEARCH("MISS CLAUDIA",C4))),"Personal Travel - New Orleans",IF(AND(YEAR(B4)=2025,MONTH(B4)=4,OR(ISNUMBER(SEARCH("EXCHANGE RATE",C4)),ISNUMBER(SEARCH("EXCHG RTE",C4)))),"Personal Travel - Italy",IFERROR(INDEX('Category Rules'!$B$2:$B$358,MATCH(TRUE,ISNUMBER(SEARCH('Category Rules'!$A$2:$A$358,C4)),0)),""))))))))} -> Personal Travel - Canada
A5: DEBIT | B5: 46021 | C5: FOREIGN EXCHANGE RATE ADJUSTMENT FEE 12/29BCF - ONL | D5: -0.43 | E5: FEE_TRANSACTION | F5: 2831.78 | G5: {=IF(AND(ISNUMBER(SEARCH("UBER",C5)),ISNUMBER(SEARCH("EATS",C5))),"Uber Eats",IF(LEFT(C5,6)="CHECK ","Checks Paid",IF(OR(E5="BILLPAY",ISNUMBER(SEARCH("FRANCHISE TAX",C5)),ISNUMBER(SEARCH("NEXTLINK",C5))),"Personal - House Bills",IF(AND(ISNUMBER(SEARCH("PAYMENT FROM",C5)),ISNUMBER(SEARCH("JOE SAUNDERS",C5))),"Zelle from Joe Saunders",IF(AND(ISNUMBER(SEARCH("PAYMENT TO",C5)),ISNUMBER(SEARCH("JOE SAUNDERS",C5))),"Zelle to Joe Saunders",IF(OR(ISNUMBER(SEARCH("NEW ORLEANS",C5)),ISNUMBER(SEARCH("KENNER",C5)),ISNUMBER(SEARCH("HENRY HOWARD",C5)),ISNUMBER(SEARCH("MISS CLAUDIA",C5))),"Personal Travel - New Orleans",IF(AND(YEAR(B5)=2025,MONTH(B5)=4,OR(ISNUMBER(SEARCH("EXCHANGE RATE",C5)),ISNUMBER(SEARCH("EXCHG RTE",C5)))),"Personal Travel - Italy",IFERROR(INDEX('Category Rules'!$B$2:$B$358,MATCH(TRUE,ISNUMBER(SEARCH('Category Rules'!$A$2:$A$358,C5)),0)),""))))))))} -> Personal Travel - Canada
A6: DEBIT | B6: 46021 | C6: FOREIGN EXCHANGE RATE ADJUSTMENT FEE 12/29TSESHAHT | D6: -1.84 | E6: FEE_TRANSACTION | F6: 2832.21 | G6: {=IF(AND(ISNUMBER(SEARCH("UBER",C6)),ISNUMBER(SEARCH("EATS",C6))),"Uber Eats",IF(LEFT(C6,6)="CHECK ","Checks Paid",IF(OR(E6="BILLPAY",ISNUMBER(SEARCH("FRANCHISE TAX",C6)),ISNUMBER(SEARCH("NEXTLINK",C6))),"Personal - House Bills",IF(AND(ISNUMBER(SEARCH("PAYMENT FROM",C6)),ISNUMBER(SEARCH("JOE SAUNDERS",C6))),"Zelle from Joe Saunders",IF(AND(ISNUMBER(SEARCH("PAYMENT TO",C6)),ISNUMBER(SEARCH("JOE SAUNDERS",C6))),"Zelle to Joe Saunders",IF(OR(ISNUMBER(SEARCH("NEW ORLEANS",C6)),ISNUMBER(SEARCH("KENNER",C6)),ISNUMBER(SEARCH("HENRY HOWARD",C6)),ISNUMBER(SEARCH("MISS CLAUDIA",C6))),"Personal Travel - New Orleans",IF(AND(YEAR(B6)=2025,MONTH(B6)=4,OR(ISNUMBER(SEARCH("EXCHANGE RATE",C6)),ISNUMBER(SEARCH("EXCHG RTE",C6)))),"Personal Travel - Italy",IFERROR(INDEX('Category Rules'!$B$2:$B$358,MATCH(TRUE,ISNUMBER(SEARCH('Category Rules'!$A$2:$A$358,C6)),0)),""))))))))} -> Personal Travel - Canada
A7: DEBIT | B7: 46021 | C7: PENTESTER.COM PENTESTER.COM FL 12/30 | D7: -19 | E7: DEBIT_CARD | F7: 2834.05 | G7: {=IF(AND(ISNUMBER(SEARCH("UBER",C7)),ISNUMBER(SEARCH("EATS",C7))),"Uber Eats",IF(LEFT(C7,6)="CHECK ","Checks Paid",IF(OR(E7="BILLPAY",ISNUMBER(SEARCH("FRANCHISE TAX",C7)),ISNUMBER(SEARCH("NEXTLINK",C7))),"Personal - House Bills",IF(AND(ISNUMBER(SEARCH("PAYMENT FROM",C7)),ISNUMBER(SEARCH("JOE SAUNDERS",C7))),"Zelle from Joe Saunders",IF(AND(ISNUMBER(SEARCH("PAYMENT TO",C7)),ISNUMBER(SEARCH("JOE SAUNDERS",C7))),"Zelle to Joe Saunders",IF(OR(ISNUMBER(SEARCH("NEW ORLEANS",C7)),ISNUMBER(SEARCH("KENNER",C7)),ISNUMBER(SEARCH("HENRY HOWARD",C7)),ISNUMBER(SEARCH("MISS CLAUDIA",C7))),"Personal Travel - New Orleans",IF(AND(YEAR(B7)=2025,MONTH(B7)=4,OR(ISNUMBER(SEARCH("EXCHANGE RATE",C7)),ISNUMBER(SEARCH("EXCHG RTE",C7)))),"Personal Travel - Italy",IFERROR(INDEX('Category Rules'!$B$2:$B$358,MATCH(TRUE,ISNUMBER(SEARCH('Category Rules'!$A$2:$A$358,C7)),0)),""))))))))} -> Personal - Subscription
A8: DEBIT | B8: 46021 | C8: BCF - ONLINE SALES & BO VICTORIA BC 12/29 CA DOLLAR 20.00 X 0.7325000 (EXCHG RTE) | D8: -14.65 | E8: DEBIT_CARD | F8: 2853.05 | G8: {=IF(AND(ISNUMBER(SEARCH("UBER",C8)),ISNUMBER(SEARCH("EATS",C8))),"Uber Eats",IF(LEFT(C8,6)="CHECK ","Checks Paid",IF(OR(E8="BILLPAY",ISNUMBER(SEARCH("FRANCHISE TAX",C8)),ISNUMBER(SEARCH("NEXTLINK",C8))),"Personal - House Bills",IF(AND(ISNUMBER(SEARCH("PAYMENT FROM",C8)),ISNUMBER(SEARCH("JOE SAUNDERS",C8))),"Zelle from Joe Saunders",IF(AND(ISNUMBER(SEARCH("PAYMENT TO",C8)),ISNUMBER(SEARCH("JOE SAUNDERS",C8))),"Zelle to Joe Saunders",IF(OR(ISNUMBER(SEARCH("NEW ORLEANS",C8)),ISNUMBER(SEARCH("KENNER",C8)),ISNUMBER(SEARCH("HENRY HOWARD",C8)),ISNUMBER(SEARCH("MISS CLAUDIA",C8))),"Personal Travel - New Orleans",IF(AND(YEAR(B8)=2025,MONTH(B8)=4,OR(ISNUMBER(SEARCH("EXCHANGE RATE",C8)),ISNUMBER(SEARCH("EXCHG RTE",C8)))),"Personal Travel - Italy",IFERROR(INDEX('Category Rules'!$B$2:$B$358,MATCH(TRUE,ISNUMBER(SEARCH('Category Rules'!$A$2:$A$358,C8)),0)),""))))))))} -> Personal Travel - Canada
A9: DEBIT | B9: 46021 | C9: TSESHAHT MARKET LP PORT ALBERNI BC 12/29 CA DOLLAR 83.88 X 0.7331903 (EXCHG RTE) | D9: -61.5 | E9: DEBIT_CARD | F9: 2867.7 | G9: {=IF(AND(ISNUMBER(SEARCH("UBER",C9)),ISNUMBER(SEARCH("EATS",C9))),"Uber Eats",IF(LEFT(C9,6)="CHECK ","Checks Paid",IF(OR(E9="BILLPAY",ISNUMBER(SEARCH("FRANCHISE TAX",C9)),ISNUMBER(SEARCH("NEXTLINK",C9))),"Personal - House Bills",IF(AND(ISNUMBER(SEARCH("PAYMENT FROM",C9)),ISNUMBER(SEARCH("JOE SAUNDERS",C9))),"Zelle from Joe Saunders",IF(AND(ISNUMBER(SEARCH("PAYMENT TO",C9)),ISNUMBER(SEARCH("JOE SAUNDERS",C9))),"Zelle to Joe Saunders",IF(OR(ISNUMBER(SEARCH("NEW ORLEANS",C9)),ISNUMBER(SEARCH("KENNER",C9)),ISNUMBER(SEARCH("HENRY HOWARD",C9)),ISNUMBER(SEARCH("MISS CLAUDIA",C9))),"Personal Travel - New Orleans",IF(AND(YEAR(B9)=2025,MONTH(B9)=4,OR(ISNUMBER(SEARCH("EXCHANGE RATE",C9)),ISNUMBER(SEARCH("EXCHG RTE",C9)))),"Personal Travel - Italy",IFERROR(INDEX('Category Rules'!$B$2:$B$358,MATCH(TRUE,ISNUMBER(SEARCH('Category Rules'!$A$2:$A$358,C9)),0)),""))))))))} -> Personal Travel - Canada
A10: DEBIT | B10: 46020 | C10: FOREIGN EXCHANGE RATE ADJUSTMENT FEE 12/26BEACHES G | D10: -0.55 | E10: FEE_TRANSACTION | F10: 2929.2 | G10: {=IF(AND(ISNUMBER(SEARCH("UBER",C10)),ISNUMBER(SEARCH("EATS",C10))),"Uber Eats",IF(LEFT(C10,6)="CHECK ","Checks Paid",IF(OR(E10="BILLPAY",ISNUMBER(SEARCH("FRANCHISE TAX",C10)),ISNUMBER(SEARCH("NEXTLINK",C10))),"Personal - House Bills",IF(AND(ISNUMBER(SEARCH("PAYMENT FROM",C10)),ISNUMBER(SEARCH("JOE SAUNDERS",C10))),"Zelle from Joe Saunders",IF(AND(ISNUMBER(SEARCH("PAYMENT TO",C10)),ISNUMBER(SEARCH("JOE SAUNDERS",C10))),"Zelle to Joe Saunders",IF(OR(ISNUMBER(SEARCH("NEW ORLEANS",C10)),ISNUMBER(SEARCH("KENNER",C10)),ISNUMBER(SEARCH("HENRY HOWARD",C10)),ISNUMBER(SEARCH("MISS CLAUDIA",C10))),"Personal Travel - New Orleans",IF(AND(YEAR(B10)=2025,MONTH(B10)=4,OR(ISNUMBER(SEARCH("EXCHANGE RATE",C10)),ISNUMBER(SEARCH("EXCHG RTE",C10)))),"Personal Travel - Italy",IFERROR(INDEX('Category Rules'!$B$2:$B$358,MATCH(TRUE,ISNUMBER(SEARCH('Category Rules'!$A$2:$A$358,C10)),0)),""))))))))} -> Personal Travel - Canada
A11: DEBIT | B11: 46020 | C11: FOREIGN EXCHANGE RATE ADJUSTMENT FEE 12/28TOFINO PH | D11: -1.22 | E11: FEE_TRANSACTION | F11: 2929.75 | G11: {=IF(AND(ISNUMBER(SEARCH("UBER",C11)),ISNUMBER(SEARCH("EATS",C11))),"Uber Eats",IF(LEFT(C11,6)="CHECK ","Checks Paid",IF(OR(E11="BILLPAY",ISNUMBER(SEARCH("FRANCHISE TAX",C11)),ISNUMBER(SEARCH("NEXTLINK",C11))),"Personal - House Bills",IF(AND(ISNUMBER(SEARCH("PAYMENT FROM",C11)),ISNUMBER(SEARCH("JOE SAUNDERS",C11))),"Zelle from Joe Saunders",IF(AND(ISNUMBER(SEARCH("PAYMENT TO",C11)),ISNUMBER(SEARCH("JOE SAUNDERS",C11))),"Zelle to Joe Saunders",IF(OR(ISNUMBER(SEARCH("NEW ORLEANS",C11)),ISNUMBER(SEARCH("KENNER",C11)),ISNUMBER(SEARCH("HENRY HOWARD",C11)),ISNUMBER(SEARCH("MISS CLAUDIA",C11))),"Personal Travel - New Orleans",IF(AND(YEAR(B11)=2025,MONTH(B11)=4,OR(ISNUMBER(SEARCH("EXCHANGE RATE",C11)),ISNUMBER(SEARCH("EXCHG RTE",C11)))),"Personal Travel - Italy",IFERROR(INDEX('Category Rules'!$B$2:$B$358,MATCH(TRUE,ISNUMBER(SEARCH('Category Rules'!$A$2:$A$358,C11)),0)),""))))))))} -> Personal Travel - Canada
A12: DEBIT | B12: 46020 | C12: FOREIGN EXCHANGE RATE ADJUSTMENT FEE 12/28PHARMASAV | D12: -2.08 | E12: FEE_TRANSACTION | F12: 2930.97 | G12: {=IF(AND(ISNUMBER(SEARCH("UBER",C12)),ISNUMBER(SEARCH("EATS",C12))),"Uber Eats",IF(LEFT(C12,6)="CHECK ","Checks Paid",IF(OR(E12="BILLPAY",ISNUMBER(SEARCH("FRANCHISE TAX",C12)),ISNUMBER(SEARCH("NEXTLINK",C12))),"Personal - House Bills",IF(AND(ISNUMBER(SEARCH("PAYMENT FROM",C12)),ISNUMBER(SEARCH("JOE SAUNDERS",C12))),"Zelle from Joe Saunders",IF(AND(ISNUMBER(SEARCH("PAYMENT TO",C12)),ISNUMBER(SEARCH("JOE SAUNDERS",C12))),"Zelle to Joe Saunders",IF(OR(ISNUMBER(SEARCH("NEW ORLEANS",C12)),ISNUMBER(SEARCH("KENNER",C12)),ISNUMBER(SEARCH("HENRY HOWARD",C12)),ISNUMBER(SEARCH("MISS CLAUDIA",C12))),"Personal Travel - New Orleans",IF(AND(YEAR(B12)=2025,MONTH(B12)=4,OR(ISNUMBER(SEARCH("EXCHANGE RATE",C12)),ISNUMBER(SEARCH("EXCHG RTE",C12)))),"Personal Travel - Italy",IFERROR(INDEX('Category Rules'!$B$2:$B$358,MATCH(TRUE,ISNUMBER(SEARCH('Category Rules'!$A$2:$A$358,C12)),0)),""))))))))} -> Personal Travel - Canada
A13: DEBIT | B13: 46020 | C13: FOREIGN EXCHANGE RATE ADJUSTMENT FEE 161371 12/28TOFINO PH | D13: -4.46 | E13: FEE_TRANSACTION | F13: 2933.05 | G13: {=IF(AND(ISNUMBER(SEARCH("UBER",C13)),ISNUMBER(SEARCH("EATS",C13))),"Uber Eats",IF(LEFT(C13,6)="CHECK ","Checks Paid",IF(OR(E13="BILLPAY",ISNUMBER(SEARCH("FRANCHISE TAX",C13)),ISNUMBER(SEARCH("NEXTLINK",C13))),"Personal - House Bills",IF(AND(ISNUMBER(SEARCH("PAYMENT FROM",C13)),ISNUMBER(SEARCH("JOE SAUNDERS",C13))),"Zelle from Joe Saunders",IF(AND(ISNUMBER(SEARCH("PAYMENT TO",C13)),ISNUMBER(SEARCH("JOE SAUNDERS",C13))),"Zelle to Joe Saunders",IF(OR(ISNUMBER(SEARCH("NEW ORLEANS",C13)),ISNUMBER(SEARCH("KENNER",C13)),ISNUMBER(SEARCH("HENRY HOWARD",C13)),ISNUMBER(SEARCH("MISS CLAUDIA",C13))),"Personal Travel - New Orleans",IF(AND(YEAR(B13)=2025,MONTH(B13)=4,OR(ISNUMBER(SEARCH("EXCHANGE RATE",C13)),ISNUMBER(SEARCH("EXCHG RTE",C13)))),"Personal Travel - Italy",IFERROR(INDEX('Category Rules'!$B$2:$B$358,MATCH(TRUE,ISNUMBER(SEARCH('Category Rules'!$A$2:$A$358,C13)),0)),""))))))))} -> Personal Travel - Canada
... A2300: DEBIT | B2300: 45659 | C2300: AIR CAN* 01442800 AIRCANADA.COM MB 01/01 CA DOLLAR 150.00 X 0.6975333 (EXCHG RTE) | D2300: -104.63 | E2300: DEBIT_CARD | F2300: 2686.29 | G2300: {=IF(AND(ISNUMBER(SEARCH("UBER",C2300)),ISNUMBER(SEARCH("EATS",C2300))),"Uber Eats",IF(LEFT(C2300,6)="CHECK ","Checks Paid",IF(OR(E2300="BILLPAY",ISNUMBER(SEARCH("FRANCHISE TAX",C2300)),ISNUMBER(SEARCH("NEXTLINK",C2300))),"Personal - House Bills",IF(AND(ISNUMBER(SEARCH("PAYMENT FROM",C2300)),ISNUMBER(SEARCH("JOE SAUNDERS",C2300))),"Zelle from Joe Saunders",IF(AND(ISNUMBER(SEARCH("PAYMENT TO",C2300)),ISNUMBER(SEARCH("JOE SAUNDERS",C2300))),"Zelle to Joe Saunders",IF(OR(ISNUMBER(SEARCH("NEW ORLEANS",C2300)),ISNUMBER(SEARCH("KENNER",C2300)),ISNUMBER(SEARCH("HENRY HOWARD",C2300)),ISNUMBER(SEARCH("MISS CLAUDIA",C2300))),"Personal Travel - New Orleans",IF(AND(YEAR(B2300)=2025,MONTH(B2300)=4,OR(ISNUMBER(SEARCH("EXCHANGE RATE",C2300)),ISNUMBER(SEARCH("EXCHG RTE",C2300)))),"Personal Travel - Italy",IFERROR(INDEX('Category Rules'!$B$2:$B$358,MATCH(TRUE,ISNUMBER(SEARCH('Category Rules'!$A$2:$A$358,C2300)),0)),""))))))))} -> Personal Travel - Canada
