Workbook

Sheet Transaction Summary
A1: Chase Personal Banking — Angela
A2: Statement Summary | Jan 2, 2026 – Jul 8, 2026
A4: Account | B4: Angela — Chase 1117
A5: Statement Period | B5: Jan 2026 – Jul 2026
A7: TOTALS
A8: Charges (Outflows) | B8: =SUMIF(Angela_2026_Chase1117_Activity_!$D$2:$D$1368,"<0") -> -225740.02
A9: Credits & Payments (Inflows) | B9: =SUMIF(Angela_2026_Chase1117_Activity_!$D$2:$D$1368,">0") -> 225286.54
A10: Net Balance | B10: =B8+B9 -> -453.48
A12: ACTIVITY — INFLOWS vs OUTFLOWS
A13: Flow | B13: # Txns | C13: Amount
A14: Inflows (Credits) | B14: =COUNTIF(Angela_2026_Chase1117_Activity_!$D$2:$D$1368,">0") -> 100 | C14: =B9 -> 225286.54
A15: Outflows (Charges) | B15: =COUNTIF(Angela_2026_Chase1117_Activity_!$D$2:$D$1368,"<0") -> 1267 | C15: =B8 -> -225740.02
A16: Net | B16: =B14+B15 -> 1367 | C16: =C14+C15 -> -453.48
A18: SPEND BY CATEGORY
A19: Category | B19: Amount | C19: % of Charges
A20: Transfers
A21: Transfer from DWG Capital Group | B21: =SUMIF(Angela_2026_Chase1117_Activity_!$G$2:$G$1368,$A21,Angela_2026_Chase1117_Activity_!$D$2:$D$1368) -> 181500 | C21: =B21/$B$8 -> -0.80402226
A22: Transfer to Ava | B22: =SUMIF(Angela_2026_Chase1117_Activity_!$G$2:$G$1368,$A22,Angela_2026_Chase1117_Activity_!$D$2:$D$1368) -> -8750 | C22: =B22/$B$8 -> 0.038761403
A23: Transfer from Poseidon Asset Group | B23: =SUMIF(Angela_2026_Chase1117_Activity_!$G$2:$G$1368,$A23,Angela_2026_Chase1117_Activity_!$D$2:$D$1368) -> 31000 | C23: =B23/$B$8 -> -0.13732612
A24: Subtotal — Transfers | B24: =SUM(B21:B23) -> 203750 | C24: =SUM(C21:C23) -> -0.90258697
A25: Zelle
A26: Zelle from Mary Margaret Trahan | B26: =SUMIF(Angela_2026_Chase1117_Activity_!$G$2:$G$1368,$A26,Angela_2026_Chase1117_Activity_!$D$2:$D$1368) -> 350 | C26: =B26/$B$8 -> -0.0015504561
A27: Zelle from Rose Li | B27: =SUMIF(Angela_2026_Chase1117_Activity_!$G$2:$G$1368,$A27,Angela_2026_Chase1117_Activity_!$D$2:$D$1368) -> 1350 | C27: =B27/$B$8 -> -0.0059803308
A28: Zelle from Joe Saunders | B28: =SUMIF(Angela_2026_Chase1117_Activity_!$G$2:$G$1368,$A28,Angela_2026_Chase1117_Activity_!$D$2:$D$1368) -> 2000 | C28: =B28/$B$8 -> -0.0088597494
A29: Zelle to Joe Saunders | B29: =SUMIF(Angela_2026_Chase1117_Activity_!$G$2:$G$1368,$A29,Angela_2026_Chase1117_Activity_!$D$2:$D$1368) -> -1000 | C29: =B29/$B$8 -> 0.0044298747
A30: Zelle from Tanya Miller | B30: =SUMIF(Angela_2026_Chase1117_Activity_!$G$2:$G$1368,$A30,Angela_2026_Chase1117_Activity_!$D$2:$D$1368) -> 800 | C30: =B30/$B$8 -> -0.0035438997
A31: Zelle to Britt Magadini | B31: =SUMIF(Angela_2026_Chase1117_Activity_!$G$2:$G$1368,$A31,Angela_2026_Chase1117_Activity_!$D$2:$D$1368) -> -1100 | C31: =B31/$B$8 -> 0.0048728622
A32: Zelle from Eunice G Chang | B32: =SUMIF(Angela_2026_Chase1117_Activity_!$G$2:$G$1368,$A32,Angela_2026_Chase1117_Activity_!$D$2:$D$1368) -> 175 | C32: =B32/$B$8 -> -0.00077522807
A33: Zelle from G-Eunice LLC | B33: =SUMIF(Angela_2026_Chase1117_Activity_!$G$2:$G$1368,$A33,Angela_2026_Chase1117_Activity_!$D$2:$D$1368) -> 175 | C33: =B33/$B$8 -> -0.00077522807
A34: Zelle-Leelee | B34: =SUMIF(Angela_2026_Chase1117_Activity_!$G$2:$G$1368,$A34,Angela_2026_Chase1117_Activity_!$D$2:$D$1368) -> -1300 | C34: =B34/$B$8 -> 0.0057588371
A35: Zelle to Natalie Cordova | B35: =SUMIF(Angela_2026_Chase1117_Activity_!$G$2:$G$1368,$A35,Angela_2026_Chase1117_Activity_!$D$2:$D$1368) -> -300 | C35: =B35/$B$8 -> 0.0013289624
A36: Zelle to Shaffa | B36: =SUMIF(Angela_2026_Chase1117_Activity_!$G$2:$G$1368,$A36,Angela_2026_Chase1117_Activity_!$D$2:$D$1368) -> -300 | C36: =B36/$B$8 -> 0.0013289624
A37: Subtotal — Zelle | B37: =SUM(B26:B36) -> 850 | C37: =SUM(C26:C36) -> -0.0037653935
A38: PayPal ACH
A39: PayPal ACH - RAYSTARLIGH | B39: =SUMIF(Angela_2026_Chase1117_Activity_!$G$2:$G$1368,$A39,Angela_2026_Chase1117_Activity_!$D$2:$D$1368) -> -212.86 | C39: =B39/$B$8 -> 0.00094294313
A40: PayPal ACH - OTHERSIDEMI | B40: =SUMIF(Angela_2026_Chase1117_Activity_!$G$2:$G$1368,$A40,Angela_2026_Chase1117_Activity_!$D$2:$D$1368) -> -9.95 | C40: =B40/$B$8 -> 4.4077253e-05
A41: PayPal ACH - PSYCHICMARY | B41: =SUMIF(Angela_2026_Chase1117_Activity_!$G$2:$G$1368,$A41,Angela_2026_Chase1117_Activity_!$D$2:$D$1368) -> -125 | C41: =B41/$B$8 -> 0.00055373434
A42: Subtotal — PayPal ACH | B42: =SUM(B39:B41) -> -347.81 | C42: =SUM(C39:C41) -> 0.0015407547
A43: Personal Travel
A44: Personal Travel | B44: =SUMIF(Angela_2026_Chase1117_Activity_!$G$2:$G$1368,$A44,Angela_2026_Chase1117_Activity_!$D$2:$D$1368) -> -41752.33 | C44: =B44/$B$8 -> 0.18495759
...

Sheet Transfers
A1: Chase Personal Banking — Angela
A2: Transfers | Jan 2, 2026 – Jul 8, 2026
A4: Category | B4: Amount | C4: # Txns
A5: Transfers (Own Accounts)
A6: Transfer from DWG Capital Group | B6: =SUMIF(Angela_2026_Chase1117_Activity_!$G$2:$G$1368,$A6,Angela_2026_Chase1117_Activity_!$D$2:$D$1368) -> 181500 | C6: =COUNTIF(Angela_2026_Chase1117_Activity_!$G$2:$G$1368,$A6) -> 51
A7: Transfer to Ava | B7: =SUMIF(Angela_2026_Chase1117_Activity_!$G$2:$G$1368,$A7,Angela_2026_Chase1117_Activity_!$D$2:$D$1368) -> -8750 | C7: =COUNTIF(Angela_2026_Chase1117_Activity_!$G$2:$G$1368,$A7) -> 13
A8: Transfer from Poseidon Asset Group | B8: =SUMIF(Angela_2026_Chase1117_Activity_!$G$2:$G$1368,$A8,Angela_2026_Chase1117_Activity_!$D$2:$D$1368) -> 31000 | C8: =COUNTIF(Angela_2026_Chase1117_Activity_!$G$2:$G$1368,$A8) -> 3
A9: Subtotal — Transfers (Own Accounts) | B9: =SUM(B6:B8) -> 203750 | C9: =SUM(C6:C8) -> 67
A10: Zelle (Person-to-Person)
A11: Zelle from Mary Margaret Trahan | B11: =SUMIF(Angela_2026_Chase1117_Activity_!$G$2:$G$1368,$A11,Angela_2026_Chase1117_Activity_!$D$2:$D$1368) -> 350 | C11: =COUNTIF(Angela_2026_Chase1117_Activity_!$G$2:$G$1368,$A11) -> 6
A12: Zelle from Rose Li | B12: =SUMIF(Angela_2026_Chase1117_Activity_!$G$2:$G$1368,$A12,Angela_2026_Chase1117_Activity_!$D$2:$D$1368) -> 1350 | C12: =COUNTIF(Angela_2026_Chase1117_Activity_!$G$2:$G$1368,$A12) -> 3
A13: Zelle from Joe Saunders | B13: =SUMIF(Angela_2026_Chase1117_Activity_!$G$2:$G$1368,$A13,Angela_2026_Chase1117_Activity_!$D$2:$D$1368) -> 2000 | C13: =COUNTIF(Angela_2026_Chase1117_Activity_!$G$2:$G$1368,$A13) -> 4
A14: Zelle to Joe Saunders | B14: =SUMIF(Angela_2026_Chase1117_Activity_!$G$2:$G$1368,$A14,Angela_2026_Chase1117_Activity_!$D$2:$D$1368) -> -1000 | C14: =COUNTIF(Angela_2026_Chase1117_Activity_!$G$2:$G$1368,$A14) -> 1
A15: Zelle from Tanya Miller | B15: =SUMIF(Angela_2026_Chase1117_Activity_!$G$2:$G$1368,$A15,Angela_2026_Chase1117_Activity_!$D$2:$D$1368) -> 800 | C15: =COUNTIF(Angela_2026_Chase1117_Activity_!$G$2:$G$1368,$A15) -> 8
A16: Zelle to Britt Magadini | B16: =SUMIF(Angela_2026_Chase1117_Activity_!$G$2:$G$1368,$A16,Angela_2026_Chase1117_Activity_!$D$2:$D$1368) -> -1100 | C16: =COUNTIF(Angela_2026_Chase1117_Activity_!$G$2:$G$1368,$A16) -> 3
A17: Zelle from Eunice G Chang | B17: =SUMIF(Angela_2026_Chase1117_Activity_!$G$2:$G$1368,$A17,Angela_2026_Chase1117_Activity_!$D$2:$D$1368) -> 175 | C17: =COUNTIF(Angela_2026_Chase1117_Activity_!$G$2:$G$1368,$A17) -> 1
A18: Zelle from G-Eunice LLC | B18: =SUMIF(Angela_2026_Chase1117_Activity_!$G$2:$G$1368,$A18,Angela_2026_Chase1117_Activity_!$D$2:$D$1368) -> 175 | C18: =COUNTIF(Angela_2026_Chase1117_Activity_!$G$2:$G$1368,$A18) -> 1
A19: Zelle-Leelee | B19: =SUMIF(Angela_2026_Chase1117_Activity_!$G$2:$G$1368,$A19,Angela_2026_Chase1117_Activity_!$D$2:$D$1368) -> -1300 | C19: =COUNTIF(Angela_2026_Chase1117_Activity_!$G$2:$G$1368,$A19) -> 2
A20: Zelle to Natalie Cordova | B20: =SUMIF(Angela_2026_Chase1117_Activity_!$G$2:$G$1368,$A20,Angela_2026_Chase1117_Activity_!$D$2:$D$1368) -> -300 | C20: =COUNTIF(Angela_2026_Chase1117_Activity_!$G$2:$G$1368,$A20) -> 1
A21: Zelle to Shaffa | B21: =SUMIF(Angela_2026_Chase1117_Activity_!$G$2:$G$1368,$A21,Angela_2026_Chase1117_Activity_!$D$2:$D$1368) -> -300 | C21: =COUNTIF(Angela_2026_Chase1117_Activity_!$G$2:$G$1368,$A21) -> 1
A22: Subtotal — Zelle (Person-to-Person) | B22: =SUM(B11:B21) -> 850 | C22: =SUM(C11:C21) -> 31
A23: PayPal ACH
A24: PayPal ACH - RAYSTARLIGH | B24: =SUMIF(Angela_2026_Chase1117_Activity_!$G$2:$G$1368,$A24,Angela_2026_Chase1117_Activity_!$D$2:$D$1368) -> -212.86 | C24: =COUNTIF(Angela_2026_Chase1117_Activity_!$G$2:$G$1368,$A24) -> 2
A25: PayPal ACH - OTHERSIDEMI | B25: =SUMIF(Angela_2026_Chase1117_Activity_!$G$2:$G$1368,$A25,Angela_2026_Chase1117_Activity_!$D$2:$D$1368) -> -9.95 | C25: =COUNTIF(Angela_2026_Chase1117_Activity_!$G$2:$G$1368,$A25) -> 1
A26: PayPal ACH - PSYCHICMARY | B26: =SUMIF(Angela_2026_Chase1117_Activity_!$G$2:$G$1368,$A26,Angela_2026_Chase1117_Activity_!$D$2:$D$1368) -> -125 | C26: =COUNTIF(Angela_2026_Chase1117_Activity_!$G$2:$G$1368,$A26) -> 1
A27: Subtotal — PayPal ACH | B27: =SUM(B24:B26) -> -347.81 | C27: =SUM(C24:C26) -> 4
A29: TOTAL — ALL TRANSFERS | B29: =B9+B22+B27 -> 204252.19 | C29: =C9+C22+C27 -> 102

Sheet Transaction Details
A1: Chase Personal Banking — Angela
A2: Transaction Detail | Jan 2, 2026 – Jul 8, 2026
A4: Date | B4: Merchant / Description | C4: Category | D4: Amount
A5: =Angela_2026_Chase1117_Activity_!B2 -> 46211 | B5: =Angela_2026_Chase1117_Activity_!C2 -> POS DEBIT UBER * EATS PENDING SAN FRANCISC CA | C5: =Angela_2026_Chase1117_Activity_!G2 -> Uber Eats | D5: =Angela_2026_Chase1117_Activity_!D2 -> -20.54
A6: =Angela_2026_Chase1117_Activity_!B3 -> 46211 | B6: =Angela_2026_Chase1117_Activity_!C3 -> POS DEBIT 6DAYWEIGHT* 6DAYWEIGHT +18187829038 CA 0089 | C6: =Angela_2026_Chase1117_Activity_!G3 -> Personal - Health | D6: =Angela_2026_Chase1117_Activity_!D3 -> -395
A7: =Angela_2026_Chase1117_Activity_!B4 -> 46211 | B7: =Angela_2026_Chase1117_Activity_!C4 -> POS DEBIT Prime Video Channels amzn.com/bil WA 0360 | C7: =Angela_2026_Chase1117_Activity_!G4 -> Amazon | D7: =Angela_2026_Chase1117_Activity_!D4 -> -15.99
A8: =Angela_2026_Chase1117_Activity_!B5 -> 46211 | B8: =Angela_2026_Chase1117_Activity_!C5 -> POS DEBIT Amazon Tips Amzn.com/bil WA 0360 | C8: =Angela_2026_Chase1117_Activity_!G5 -> Amazon | D8: =Angela_2026_Chase1117_Activity_!D5 -> -15
A9: =Angela_2026_Chase1117_Activity_!B6 -> 46210 | B9: =Angela_2026_Chase1117_Activity_!C6 -> UBER * EATS PENDIN SAN FRANCISCO CA148376 07/07 | C9: =Angela_2026_Chase1117_Activity_!G6 -> Uber Eats | D9: =Angela_2026_Chase1117_Activity_!D6 -> -27.55
A10: =Angela_2026_Chase1117_Activity_!B7 -> 46210 | B10: =Angela_2026_Chase1117_Activity_!C7 -> WITHDRAWAL 07/07 | C10: =Angela_2026_Chase1117_Activity_!G7 -> Withdrawal | D10: =Angela_2026_Chase1117_Activity_!D7 -> -5000
A11: =Angela_2026_Chase1117_Activity_!B8 -> 46210 | B11: =Angela_2026_Chase1117_Activity_!C8 -> AMAZON RETA* XR6945C WWW.AMAZON.CO WA 07/07 | C11: =Angela_2026_Chase1117_Activity_!G8 -> Amazon | D11: =Angela_2026_Chase1117_Activity_!D8 -> -25.62
A12: =Angela_2026_Chase1117_Activity_!B9 -> 46210 | B12: =Angela_2026_Chase1117_Activity_!C9 -> SP VALASTA LLC VALASTA.NET SC 07/06 | C12: =Angela_2026_Chase1117_Activity_!G9 -> Personal - Health | D12: =Angela_2026_Chase1117_Activity_!D9 -> -430.03
A13: =Angela_2026_Chase1117_Activity_!B10 -> 46210 | B13: =Angela_2026_Chase1117_Activity_!C10 -> GRANDVIEW CLEANERS LOS ANGELES CA 07/06 | C13: =Angela_2026_Chase1117_Activity_!G10 -> Personal - Clothing | D13: =Angela_2026_Chase1117_Activity_!D10 -> -133
A14: =Angela_2026_Chase1117_Activity_!B11 -> 46210 | B14: =Angela_2026_Chase1117_Activity_!C11 -> Amazon Tips*SA10C2A4 Amzn.com/bill WA 07/06 | C14: =Angela_2026_Chase1117_Activity_!G11 -> Amazon | D14: =Angela_2026_Chase1117_Activity_!D11 -> -30
A15: =Angela_2026_Chase1117_Activity_!B12 -> 46210 | B15: =Angela_2026_Chase1117_Activity_!C12 -> AMAZON RETA* WC81L6V WWW.AMAZON.CO WA 07/06 | C15: =Angela_2026_Chase1117_Activity_!G12 -> Amazon | D15: =Angela_2026_Chase1117_Activity_!D12 -> -11.75
A16: =Angela_2026_Chase1117_Activity_!B13 -> 46210 | B16: =Angela_2026_Chase1117_Activity_!C13 -> AMAZON RETA* TR3I78I WWW.AMAZON.CO WA 07/07 | C16: =Angela_2026_Chase1117_Activity_!G13 -> Amazon | D16: =Angela_2026_Chase1117_Activity_!D13 -> -7.75
... A1371: =Angela_2026_Chase1117_Activity_!B1368 -> 46024 | B1371: =Angela_2026_Chase1117_Activity_!C1368 -> Online Transfer from CHK ...1168 transaction#: 27551465996 | C1371: =Angela_2026_Chase1117_Activity_!G1368 -> Transfer from DWG Capital Group | D1371: =Angela_2026_Chase1117_Activity_!D1368 -> 5000

Sheet Monthly Breakdown
A1: Chase Personal Banking — Angela
A2: Monthly Breakdown by Category | Jan 2026 – Jul 2026
A4: Category | B4: =DATE(2026,1,1) -> 46023 | C4: =EDATE(B4,1) -> 46054 | D4: =EDATE(C4,1) -> 46082 | E4: =EDATE(D4,1) -> 46113 | F4: =EDATE(E4,1) -> 46143 | G4: =EDATE(F4,1) -> 46174 | H4: =EDATE(G4,1) -> 46204 | I4: Total
A5: Transfer from DWG Capital Group | B5: =SUMIFS(Angela_2026_Chase1117_Activity_!$D$2:$D$1368,Angela_2026_Chase1117_Activity_!$B$2:$B$1368,">="&B$4,Angela_2026_Chase1117_Activity_!$B$2:$B$1368,"<="&EOMONTH(B$4,0),Angela_2026_Chase1117_Activity_!$G$2:$G$1368,$A5) -> 32000 | C5: =SUMIFS(Angela_2026_Chase1117_Activity_!$D$2:$D$1368,Angela_2026_Chase1117_Activity_!$B$2:$B$1368,">="&C$4,Angela_2026_Chase1117_Activity_!$B$2:$B$1368,"<="&EOMONTH(C$4,0),Angela_2026_Chase1117_Activity_!$G$2:$G$1368,$A5) -> 22000 | D5: =SUMIFS(Angela_2026_Chase1117_Activity_!$D$2:$D$1368,Angela_2026_Chase1117_Activity_!$B$2:$B$1368,">="&D$4,Angela_2026_Chase1117_Activity_!$B$2:$B$1368,"<="&EOMONTH(D$4,0),Angela_2026_Chase1117_Activity_!$G$2:$G$1368,$A5) -> 41000 | E5: =SUMIFS(Angela_2026_Chase1117_Activity_!$D$2:$D$1368,Angela_2026_Chase1117_Activity_!$B$2:$B$1368,">="&E$4,Angela_2026_Chase1117_Activity_!$B$2:$B$1368,"<="&EOMONTH(E$4,0),Angela_2026_Chase1117_Activity_!$G$2:$G$1368,$A5) -> 20000 | F5: =SUMIFS(Angela_2026_Chase1117_Activity_!$D$2:$D$1368,Angela_2026_Chase1117_Activity_!$B$2:$B$1368,">="&F$4,Angela_2026_Chase1117_Activity_!$B$2:$B$1368,"<="&EOMONTH(F$4,0),Angela_2026_Chase1117_Activity_!$G$2:$G$1368,$A5) -> 28000 | G5: =SUMIFS(Angela_2026_Chase1117_Activity_!$D$2:$D$1368,Angela_2026_Chase1117_Activity_!$B$2:$B$1368,">="&G$4,Angela_2026_Chase1117_Activity_!$B$2:$B$1368,"<="&EOMONTH(G$4,0),Angela_2026_Chase1117_Activity_!$G$2:$G$1368,$A5) -> 33500 | H5: =SUMIFS(Angela_2026_Chase1117_Activity_!$D$2:$D$1368,Angela_2026_Chase1117_Activity_!$B$2:$B$1368,">="&H$4,Angela_2026_Chase1117_Activity_!$B$2:$B$1368,"<="&EOMONTH(H$4,0),Angela_2026_Chase1117_Activity_!$G$2:$G$1368,$A5) -> 5000 | I5: =SUM(B5:H5) -> 181500
A6: Transfer to Ava | B6: =SUMIFS(Angela_2026_Chase1117_Activity_!$D$2:$D$1368,Angela_2026_Chase1117_Activity_!$B$2:$B$1368,">="&B$4,Angela_2026_Chase1117_Activity_!$B$2:$B$1368,"<="&EOMONTH(B$4,0),Angela_2026_Chase1117_Activity_!$G$2:$G$1368,$A6) -> -500 | C6: =SUMIFS(Angela_2026_Chase1117_Activity_!$D$2:$D$1368,Angela_2026_Chase1117_Activity_!$B$2:$B$1368,">="&C$4,Angela_2026_Chase1117_Activity_!$B$2:$B$1368,"<="&EOMONTH(C$4,0),Angela_2026_Chase1117_Activity_!$G$2:$G$1368,$A6) -> -350 | D6: =SUMIFS(Angela_2026_Chase1117_Activity_!$D$2:$D$1368,Angela_2026_Chase1117_Activity_!$B$2:$B$1368,">="&D$4,Angela_2026_Chase1117_Activity_!$B$2:$B$1368,"<="&EOMONTH(D$4,0),Angela_2026_Chase1117_Activity_!$G$2:$G$1368,$A6) -> -3600 | E6: =SUMIFS(Angela_2026_Chase1117_Activity_!$D$2:$D$1368,Angela_2026_Chase1117_Activity_!$B$2:$B$1368,">="&E$4,Angela_2026_Chase1117_Activity_!$B$2:$B$1368,"<="&EOMONTH(E$4,0),Angela_2026_Chase1117_Activity_!$G$2:$G$1368,$A6) -> -2500 | F6: =SUMIFS(Angela_2026_Chase1117_Activity_!$D$2:$D$1368,Angela_2026_Chase1117_Activity_!$B$2:$B$1368,">="&F$4,Angela_2026_Chase1117_Activity_!$B$2:$B$1368,"<="&EOMONTH(F$4,0),Angela_2026_Chase1117_Activity_!$G$2:$G$1368,$A6) -> -600 | G6: =SUMIFS(Angela_2026_Chase1117_Activity_!$D$2:$D$1368,Angela_2026_Chase1117_Activity_!$B$2:$B$1368,">="&G$4,Angela_2026_Chase1117_Activity_!$B$2:$B$1368,"<="&EOMONTH(G$4,0),Angela_2026_Chase1117_Activity_!$G$2:$G$1368,$A6) -> -1200 | H6: =SUMIFS(Angela_2026_Chase1117_Activity_!$D$2:$D$1368,Angela_2026_Chase1117_Activity_!$B$2:$B$1368,">="&H$4,Angela_2026_Chase1117_Activity_!$B$2:$B$1368,"<="&EOMONTH(H$4,0),Angela_2026_Chase1117_Activity_!$G$2:$G$1368,$A6) -> 0 | I6: =SUM(B6:H6) -> -8750
A7: Transfer from Poseidon Asset Group | B7: =SUMIFS(Angela_2026_Chase1117_Activity_!$D$2:$D$1368,Angela_2026_Chase1117_Activity_!$B$2:$B$1368,">="&B$4,Angela_2026_Chase1117_Activity_!$B$2:$B$1368,"<="&EOMONTH(B$4,0),Angela_2026_Chase1117_Activity_!$G$2:$G$1368,$A7) -> 0 | C7: =SUMIFS(Angela_2026_Chase1117_Activity_!$D$2:$D$1368,Angela_2026_Chase1117_Activity_!$B$2:$B$1368,">="&C$4,Angela_2026_Chase1117_Activity_!$B$2:$B$1368,"<="&EOMONTH(C$4,0),Angela_2026_Chase1117_Activity_!$G$2:$G$1368,$A7) -> 30000 | D7: =SUMIFS(Angela_2026_Chase1117_Activity_!$D$2:$D$1368,Angela_2026_Chase1117_Activity_!$B$2:$B$1368,">="&D$4,Angela_2026_Chase1117_Activity_!$B$2:$B$1368,"<="&EOMONTH(D$4,0),Angela_2026_Chase1117_Activity_!$G$2:$G$1368,$A7) -> 0 | E7: =SUMIFS(Angela_2026_Chase1117_Activity_!$D$2:$D$1368,Angela_2026_Chase1117_Activity_!$B$2:$B$1368,">="&E$4,Angela_2026_Chase1117_Activity_!$B$2:$B$1368,"<="&EOMONTH(E$4,0),Angela_2026_Chase1117_Activity_!$G$2:$G$1368,$A7) -> 0 | F7: =SUMIFS(Angela_2026_Chase1117_Activity_!$D$2:$D$1368,Angela_2026_Chase1117_Activity_!$B$2:$B$1368,">="&F$4,Angela_2026_Chase1117_Activity_!$B$2:$B$1368,"<="&EOMONTH(F$4,0),Angela_2026_Chase1117_Activity_!$G$2:$G$1368,$A7) -> 0 | G7: =SUMIFS(Angela_2026_Chase1117_Activity_!$D$2:$D$1368,Angela_2026_Chase1117_Activity_!$B$2:$B$1368,">="&G$4,Angela_2026_Chase1117_Activity_!$B$2:$B$1368,"<="&EOMONTH(G$4,0),Angela_2026_Chase1117_Activity_!$G$2:$G$1368,$A7) -> 1000 | H7: =SUMIFS(Angela_2026_Chase1117_Activity_!$D$2:$D$1368,Angela_2026_Chase1117_Activity_!$B$2:$B$1368,">="&H$4,Angela_2026_Chase1117_Activity_!$B$2:$B$1368,"<="&EOMONTH(H$4,0),Angela_2026_Chase1117_Activity_!$G$2:$G$1368,$A7) -> 0 | I7: =SUM(B7:H7) -> 31000
A8: Zelle from Mary Margaret Trahan | B8: =SUMIFS(Angela_2026_Chase1117_Activity_!$D$2:$D$1368,Angela_2026_Chase1117_Activity_!$B$2:$B$1368,">="&B$4,Angela_2026_Chase1117_Activity_!$B$2:$B$1368,"<="&EOMONTH(B$4,0),Angela_2026_Chase1117_Activity_!$G$2:$G$1368,$A8) -> 0 | C8: =SUMIFS(Angela_2026_Chase1117_Activity_!$D$2:$D$1368,Angela_2026_Chase1117_Activity_!$B$2:$B$1368,">="&C$4,Angela_2026_Chase1117_Activity_!$B$2:$B$1368,"<="&EOMONTH(C$4,0),Angela_2026_Chase1117_Activity_!$G$2:$G$1368,$A8) -> 150 | D8: =SUMIFS(Angela_2026_Chase1117_Activity_!$D$2:$D$1368,Angela_2026_Chase1117_Activity_!$B$2:$B$1368,">="&D$4,Angela_2026_Chase1117_Activity_!$B$2:$B$1368,"<="&EOMONTH(D$4,0),Angela_2026_Chase1117_Activity_!$G$2:$G$1368,$A8) -> 0 | E8: =SUMIFS(Angela_2026_Chase1117_Activity_!$D$2:$D$1368,Angela_2026_Chase1117_Activity_!$B$2:$B$1368,">="&E$4,Angela_2026_Chase1117_Activity_!$B$2:$B$1368,"<="&EOMONTH(E$4,0),Angela_2026_Chase1117_Activity_!$G$2:$G$1368,$A8) -> 0 | F8: =SUMIFS(Angela_2026_Chase1117_Activity_!$D$2:$D$1368,Angela_2026_Chase1117_Activity_!$B$2:$B$1368,">="&F$4,Angela_2026_Chase1117_Activity_!$B$2:$B$1368,"<="&EOMONTH(F$4,0),Angela_2026_Chase1117_Activity_!$G$2:$G$1368,$A8) -> 75 | G8: =SUMIFS(Angela_2026_Chase1117_Activity_!$D$2:$D$1368,Angela_2026_Chase1117_Activity_!$B$2:$B$1368,">="&G$4,Angela_2026_Chase1117_Activity_!$B$2:$B$1368,"<="&EOMONTH(G$4,0),Angela_2026_Chase1117_Activity_!$G$2:$G$1368,$A8) -> 100 | H8: =SUMIFS(Angela_2026_Chase1117_Activity_!$D$2:$D$1368,Angela_2026_Chase1117_Activity_!$B$2:$B$1368,">="&H$4,Angela_2026_Chase1117_Activity_!$B$2:$B$1368,"<="&EOMONTH(H$4,0),Angela_2026_Chase1117_Activity_!$G$2:$G$1368,$A8) -> 25 | I8: =SUM(B8:H8) -> 350
A9: Zelle from Rose Li | B9: =SUMIFS(Angela_2026_Chase1117_Activity_!$D$2:$D$1368,Angela_2026_Chase1117_Activity_!$B$2:$B$1368,">="&B$4,Angela_2026_Chase1117_Activity_!$B$2:$B$1368,"<="&EOMONTH(B$4,0),Angela_2026_Chase1117_Activity_!$G$2:$G$1368,$A9) -> 0 | C9: =SUMIFS(Angela_2026_Chase1117_Activity_!$D$2:$D$1368,Angela_2026_Chase1117_Activity_!$B$2:$B$1368,">="&C$4,Angela_2026_Chase1117_Activity_!$B$2:$B$1368,"<="&EOMONTH(C$4,0),Angela_2026_Chase1117_Activity_!$G$2:$G$1368,$A9) -> 0 | D9: =SUMIFS(Angela_2026_Chase1117_Activity_!$D$2:$D$1368,Angela_2026_Chase1117_Activity_!$B$2:$B$1368,">="&D$4,Angela_2026_Chase1117_Activity_!$B$2:$B$1368,"<="&EOMONTH(D$4,0),Angela_2026_Chase1117_Activity_!$G$2:$G$1368,$A9) -> 450 | E9: =SUMIFS(Angela_2026_Chase1117_Activity_!$D$2:$D$1368,Angela_2026_Chase1117_Activity_!$B$2:$B$1368,">="&E$4,Angela_2026_Chase1117_Activity_!$B$2:$B$1368,"<="&EOMONTH(E$4,0),Angela_2026_Chase1117_Activity_!$G$2:$G$1368,$A9) -> 0 | F9: =SUMIFS(Angela_2026_Chase1117_Activity_!$D$2:$D$1368,Angela_2026_Chase1117_Activity_!$B$2:$B$1368,">="&F$4,Angela_2026_Chase1117_Activity_!$B$2:$B$1368,"<="&EOMONTH(F$4,0),Angela_2026_Chase1117_Activity_!$G$2:$G$1368,$A9) -> 0 | G9: =SUMIFS(Angela_2026_Chase1117_Activity_!$D$2:$D$1368,Angela_2026_Chase1117_Activity_!$B$2:$B$1368,">="&G$4,Angela_2026_Chase1117_Activity_!$B$2:$B$1368,"<="&EOMONTH(G$4,0),Angela_2026_Chase1117_Activity_!$G$2:$G$1368,$A9) -> 450 | H9: =SUMIFS(Angela_2026_Chase1117_Activity_!$D$2:$D$1368,Angela_2026_Chase1117_Activity_!$B$2:$B$1368,">="&H$4,Angela_2026_Chase1117_Activity_!$B$2:$B$1368,"<="&EOMONTH(H$4,0),Angela_2026_Chase1117_Activity_!$G$2:$G$1368,$A9) -> 450 | I9: =SUM(B9:H9) -> 1350
A10: Zelle from Joe Saunders | B10: =SUMIFS(Angela_2026_Chase1117_Activity_!$D$2:$D$1368,Angela_2026_Chase1117_Activity_!$B$2:$B$1368,">="&B$4,Angela_2026_Chase1117_Activity_!$B$2:$B$1368,"<="&EOMONTH(B$4,0),Angela_2026_Chase1117_Activity_!$G$2:$G$1368,$A10) -> 0 | C10: =SUMIFS(Angela_2026_Chase1117_Activity_!$D$2:$D$1368,Angela_2026_Chase1117_Activity_!$B$2:$B$1368,">="&C$4,Angela_2026_Chase1117_Activity_!$B$2:$B$1368,"<="&EOMONTH(C$4,0),Angela_2026_Chase1117_Activity_!$G$2:$G$1368,$A10) -> 0 | D10: =SUMIFS(Angela_2026_Chase1117_Activity_!$D$2:$D$1368,Angela_2026_Chase1117_Activity_!$B$2:$B$1368,">="&D$4,Angela_2026_Chase1117_Activity_!$B$2:$B$1368,"<="&EOMONTH(D$4,0),Angela_2026_Chase1117_Activity_!$G$2:$G$1368,$A10) -> 0 | E10: =SUMIFS(Angela_2026_Chase1117_Activity_!$D$2:$D$1368,Angela_2026_Chase1117_Activity_!$B$2:$B$1368,">="&E$4,Angela_2026_Chase1117_Activity_!$B$2:$B$1368,"<="&EOMONTH(E$4,0),Angela_2026_Chase1117_Activity_!$G$2:$G$1368,$A10) -> 500 | F10: =SUMIFS(Angela_2026_Chase1117_Activity_!$D$2:$D$1368,Angela_2026_Chase1117_Activity_!$B$2:$B$1368,">="&F$4,Angela_2026_Chase1117_Activity_!$B$2:$B$1368,"<="&EOMONTH(F$4,0),Angela_2026_Chase1117_Activity_!$G$2:$G$1368,$A10) -> 500 | G10: =SUMIFS(Angela_2026_Chase1117_Activity_!$D$2:$D$1368,Angela_2026_Chase1117_Activity_!$B$2:$B$1368,">="&G$4,Angela_2026_Chase1117_Activity_!$B$2:$B$1368,"<="&EOMONTH(G$4,0),Angela_2026_Chase1117_Activity_!$G$2:$G$1368,$A10) -> 1000 | H10: =SUMIFS(Angela_2026_Chase1117_Activity_!$D$2:$D$1368,Angela_2026_Chase1117_Activity_!$B$2:$B$1368,">="&H$4,Angela_2026_Chase1117_Activity_!$B$2:$B$1368,"<="&EOMONTH(H$4,0),Angela_2026_Chase1117_Activity_!$G$2:$G$1368,$A10) -> 0 | I10: =SUM(B10:H10) -> 2000
A11: Zelle to Joe Saunders | B11: =SUMIFS(Angela_2026_Chase1117_Activity_!$D$2:$D$1368,Angela_2026_Chase1117_Activity_!$B$2:$B$1368,">="&B$4,Angela_2026_Chase1117_Activity_!$B$2:$B$1368,"<="&EOMONTH(B$4,0),Angela_2026_Chase1117_Activity_!$G$2:$G$1368,$A11) -> 0 | C11: =SUMIFS(Angela_2026_Chase1117_Activity_!$D$2:$D$1368,Angela_2026_Chase1117_Activity_!$B$2:$B$1368,">="&C$4,Angela_2026_Chase1117_Activity_!$B$2:$B$1368,"<="&EOMONTH(C$4,0),Angela_2026_Chase1117_Activity_!$G$2:$G$1368,$A11) -> 0 | D11: =SUMIFS(Angela_2026_Chase1117_Activity_!$D$2:$D$1368,Angela_2026_Chase1117_Activity_!$B$2:$B$1368,">="&D$4,Angela_2026_Chase1117_Activity_!$B$2:$B$1368,"<="&EOMONTH(D$4,0),Angela_2026_Chase1117_Activity_!$G$2:$G$1368,$A11) -> 0 | E11: =SUMIFS(Angela_2026_Chase1117_Activity_!$D$2:$D$1368,Angela_2026_Chase1117_Activity_!$B$2:$B$1368,">="&E$4,Angela_2026_Chase1117_Activity_!$B$2:$B$1368,"<="&EOMONTH(E$4,0),Angela_2026_Chase1117_Activity_!$G$2:$G$1368,$A11) -> 0 | F11: =SUMIFS(Angela_2026_Chase1117_Activity_!$D$2:$D$1368,Angela_2026_Chase1117_Activity_!$B$2:$B$1368,">="&F$4,Angela_2026_Chase1117_Activity_!$B$2:$B$1368,"<="&EOMONTH(F$4,0),Angela_2026_Chase1117_Activity_!$G$2:$G$1368,$A11) -> 0 | G11: =SUMIFS(Angela_2026_Chase1117_Activity_!$D$2:$D$1368,Angela_2026_Chase1117_Activity_!$B$2:$B$1368,">="&G$4,Angela_2026_Chase1117_Activity_!$B$2:$B$1368,"<="&EOMONTH(G$4,0),Angela_2026_Chase1117_Activity_!$G$2:$G$1368,$A11) -> -1000 | H11: =SUMIFS(Angela_2026_Chase1117_Activity_!$D$2:$D$1368,Angela_2026_Chase1117_Activity_!$B$2:$B$1368,">="&H$4,Angela_2026_Chase1117_Activity_!$B$2:$B$1368,"<="&EOMONTH(H$4,0),Angela_2026_Chase1117_Activity_!$G$2:$G$1368,$A11) -> 0 | I11: =SUM(B11:H11) -> -1000
A12: Zelle from Tanya Miller | B12: =SUMIFS(Angela_2026_Chase1117_Activity_!$D$2:$D$1368,Angela_2026_Chase1117_Activity_!$B$2:$B$1368,">="&B$4,Angela_2026_Chase1117_Activity_!$B$2:$B$1368,"<="&EOMONTH(B$4,0),Angela_2026_Chase1117_Activity_!$G$2:$G$1368,$A12) -> 0 | C12: =SUMIFS(Angela_2026_Chase1117_Activity_!$D$2:$D$1368,Angela_2026_Chase1117_Activity_!$B$2:$B$1368,">="&C$4,Angela_2026_Chase1117_Activity_!$B$2:$B$1368,"<="&EOMONTH(C$4,0),Angela_2026_Chase1117_Activity_!$G$2:$G$1368,$A12) -> 200 | D12: =SUMIFS(Angela_2026_Chase1117_Activity_!$D$2:$D$1368,Angela_2026_Chase1117_Activity_!$B$2:$B$1368,">="&D$4,Angela_2026_Chase1117_Activity_!$B$2:$B$1368,"<="&EOMONTH(D$4,0),Angela_2026_Chase1117_Activity_!$G$2:$G$1368,$A12) -> 200 | E12: =SUMIFS(Angela_2026_Chase1117_Activity_!$D$2:$D$1368,Angela_2026_Chase1117_Activity_!$B$2:$B$1368,">="&E$4,Angela_2026_Chase1117_Activity_!$B$2:$B$1368,"<="&EOMONTH(E$4,0),Angela_2026_Chase1117_Activity_!$G$2:$G$1368,$A12) -> 100 | F12: =SUMIFS(Angela_2026_Chase1117_Activity_!$D$2:$D$1368,Angela_2026_Chase1117_Activity_!$B$2:$B$1368,">="&F$4,Angela_2026_Chase1117_Activity_!$B$2:$B$1368,"<="&EOMONTH(F$4,0),Angela_2026_Chase1117_Activity_!$G$2:$G$1368,$A12) -> 100 | G12: =SUMIFS(Angela_2026_Chase1117_Activity_!$D$2:$D$1368,Angela_2026_Chase1117_Activity_!$B$2:$B$1368,">="&G$4,Angela_2026_Chase1117_Activity_!$B$2:$B$1368,"<="&EOMONTH(G$4,0),Angela_2026_Chase1117_Activity_!$G$2:$G$1368,$A12) -> 200 | H12: =SUMIFS(Angela_2026_Chase1117_Activity_!$D$2:$D$1368,Angela_2026_Chase1117_Activity_!$B$2:$B$1368,">="&H$4,Angela_2026_Chase1117_Activity_!$B$2:$B$1368,"<="&EOMONTH(H$4,0),Angela_2026_Chase1117_Activity_!$G$2:$G$1368,$A12) -> 0 | I12: =SUM(B12:H12) -> 800
A13: Zelle to Britt Magadini | B13: =SUMIFS(Angela_2026_Chase1117_Activity_!$D$2:$D$1368,Angela_2026_Chase1117_Activity_!$B$2:$B$1368,">="&B$4,Angela_2026_Chase1117_Activity_!$B$2:$B$1368,"<="&EOMONTH(B$4,0),Angela_2026_Chase1117_Activity_!$G$2:$G$1368,$A13) -> 0 | C13: =SUMIFS(Angela_2026_Chase1117_Activity_!$D$2:$D$1368,Angela_2026_Chase1117_Activity_!$B$2:$B$1368,">="&C$4,Angela_2026_Chase1117_Activity_!$B$2:$B$1368,"<="&EOMONTH(C$4,0),Angela_2026_Chase1117_Activity_!$G$2:$G$1368,$A13) -> -500 | D13: =SUMIFS(Angela_2026_Chase1117_Activity_!$D$2:$D$1368,Angela_2026_Chase1117_Activity_!$B$2:$B$1368,">="&D$4,Angela_2026_Chase1117_Activity_!$B$2:$B$1368,"<="&EOMONTH(D$4,0),Angela_2026_Chase1117_Activity_!$G$2:$G$1368,$A13) -> 0 | E13: =SUMIFS(Angela_2026_Chase1117_Activity_!$D$2:$D$1368,Angela_2026_Chase1117_Activity_!$B$2:$B$1368,">="&E$4,Angela_2026_Chase1117_Activity_!$B$2:$B$1368,"<="&EOMONTH(E$4,0),Angela_2026_Chase1117_Activity_!$G$2:$G$1368,$A13) -> -300 | F13: =SUMIFS(Angela_2026_Chase1117_Activity_!$D$2:$D$1368,Angela_2026_Chase1117_Activity_!$B$2:$B$1368,">="&F$4,Angela_2026_Chase1117_Activity_!$B$2:$B$1368,"<="&EOMONTH(F$4,0),Angela_2026_Chase1117_Activity_!$G$2:$G$1368,$A13) -> 0 | G13: =SUMIFS(Angela_2026_Chase1117_Activity_!$D$2:$D$1368,Angela_2026_Chase1117_Activity_!$B$2:$B$1368,">="&G$4,Angela_2026_Chase1117_Activity_!$B$2:$B$1368,"<="&EOMONTH(G$4,0),Angela_2026_Chase1117_Activity_!$G$2:$G$1368,$A13) -> -300 | H13: =SUMIFS(Angela_2026_Chase1117_Activity_!$D$2:$D$1368,Angela_2026_Chase1117_Activity_!$B$2:$B$1368,">="&H$4,Angela_2026_Chase1117_Activity_!$B$2:$B$1368,"<="&EOMONTH(H$4,0),Angela_2026_Chase1117_Activity_!$G$2:$G$1368,$A13) -> 0 | I13: =SUM(B13:H13) -> -1100
A14: Zelle from Eunice G Chang | B14: =SUMIFS(Angela_2026_Chase1117_Activity_!$D$2:$D$1368,Angela_2026_Chase1117_Activity_!$B$2:$B$1368,">="&B$4,Angela_2026_Chase1117_Activity_!$B$2:$B$1368,"<="&EOMONTH(B$4,0),Angela_2026_Chase1117_Activity_!$G$2:$G$1368,$A14) -> 0 | C14: =SUMIFS(Angela_2026_Chase1117_Activity_!$D$2:$D$1368,Angela_2026_Chase1117_Activity_!$B$2:$B$1368,">="&C$4,Angela_2026_Chase1117_Activity_!$B$2:$B$1368,"<="&EOMONTH(C$4,0),Angela_2026_Chase1117_Activity_!$G$2:$G$1368,$A14) -> 0 | D14: =SUMIFS(Angela_2026_Chase1117_Activity_!$D$2:$D$1368,Angela_2026_Chase1117_Activity_!$B$2:$B$1368,">="&D$4,Angela_2026_Chase1117_Activity_!$B$2:$B$1368,"<="&EOMONTH(D$4,0),Angela_2026_Chase1117_Activity_!$G$2:$G$1368,$A14) -> 0 | E14: =SUMIFS(Angela_2026_Chase1117_Activity_!$D$2:$D$1368,Angela_2026_Chase1117_Activity_!$B$2:$B$1368,">="&E$4,Angela_2026_Chase1117_Activity_!$B$2:$B$1368,"<="&EOMONTH(E$4,0),Angela_2026_Chase1117_Activity_!$G$2:$G$1368,$A14) -> 0 | F14: =SUMIFS(Angela_2026_Chase1117_Activity_!$D$2:$D$1368,Angela_2026_Chase1117_Activity_!$B$2:$B$1368,">="&F$4,Angela_2026_Chase1117_Activity_!$B$2:$B$1368,"<="&EOMONTH(F$4,0),Angela_2026_Chase1117_Activity_!$G$2:$G$1368,$A14) -> 175 | G14: =SUMIFS(Angela_2026_Chase1117_Activity_!$D$2:$D$1368,Angela_2026_Chase1117_Activity_!$B$2:$B$1368,">="&G$4,Angela_2026_Chase1117_Activity_!$B$2:$B$1368,"<="&EOMONTH(G$4,0),Angela_2026_Chase1117_Activity_!$G$2:$G$1368,$A14) -> 0 | H14: =SUMIFS(Angela_2026_Chase1117_Activity_!$D$2:$D$1368,Angela_2026_Chase1117_Activity_!$B$2:$B$1368,">="&H$4,Angela_2026_Chase1117_Activity_!$B$2:$B$1368,"<="&EOMONTH(H$4,0),Angela_2026_Chase1117_Activity_!$G$2:$G$1368,$A14) -> 0 | I14: =SUM(B14:H14) -> 175
A15: Zelle from G-Eunice LLC | B15: =SUMIFS(Angela_2026_Chase1117_Activity_!$D$2:$D$1368,Angela_2026_Chase1117_Activity_!$B$2:$B$1368,">="&B$4,Angela_2026_Chase1117_Activity_!$B$2:$B$1368,"<="&EOMONTH(B$4,0),Angela_2026_Chase1117_Activity_!$G$2:$G$1368,$A15) -> 0 | C15: =SUMIFS(Angela_2026_Chase1117_Activity_!$D$2:$D$1368,Angela_2026_Chase1117_Activity_!$B$2:$B$1368,">="&C$4,Angela_2026_Chase1117_Activity_!$B$2:$B$1368,"<="&EOMONTH(C$4,0),Angela_2026_Chase1117_Activity_!$G$2:$G$1368,$A15) -> 175 | D15: =SUMIFS(Angela_2026_Chase1117_Activity_!$D$2:$D$1368,Angela_2026_Chase1117_Activity_!$B$2:$B$1368,">="&D$4,Angela_2026_Chase1117_Activity_!$B$2:$B$1368,"<="&EOMONTH(D$4,0),Angela_2026_Chase1117_Activity_!$G$2:$G$1368,$A15) -> 0 | E15: =SUMIFS(Angela_2026_Chase1117_Activity_!$D$2:$D$1368,Angela_2026_Chase1117_Activity_!$B$2:$B$1368,">="&E$4,Angela_2026_Chase1117_Activity_!$B$2:$B$1368,"<="&EOMONTH(E$4,0),Angela_2026_Chase1117_Activity_!$G$2:$G$1368,$A15) -> 0 | F15: =SUMIFS(Angela_2026_Chase1117_Activity_!$D$2:$D$1368,Angela_2026_Chase1117_Activity_!$B$2:$B$1368,">="&F$4,Angela_2026_Chase1117_Activity_!$B$2:$B$1368,"<="&EOMONTH(F$4,0),Angela_2026_Chase1117_Activity_!$G$2:$G$1368,$A15) -> 0 | G15: =SUMIFS(Angela_2026_Chase1117_Activity_!$D$2:$D$1368,Angela_2026_Chase1117_Activity_!$B$2:$B$1368,">="&G$4,Angela_2026_Chase1117_Activity_!$B$2:$B$1368,"<="&EOMONTH(G$4,0),Angela_2026_Chase1117_Activity_!$G$2:$G$1368,$A15) -> 0 | H15: =SUMIFS(Angela_2026_Chase1117_Activity_!$D$2:$D$1368,Angela_2026_Chase1117_Activity_!$B$2:$B$1368,">="&H$4,Angela_2026_Chase1117_Activity_!$B$2:$B$1368,"<="&EOMONTH(H$4,0),Angela_2026_Chase1117_Activity_!$G$2:$G$1368,$A15) -> 0 | I15: =SUM(B15:H15) -> 175
A16: Zelle-Leelee | B16: =SUMIFS(Angela_2026_Chase1117_Activity_!$D$2:$D$1368,Angela_2026_Chase1117_Activity_!$B$2:$B$1368,">="&B$4,Angela_2026_Chase1117_Activity_!$B$2:$B$1368,"<="&EOMONTH(B$4,0),Angela_2026_Chase1117_Activity_!$G$2:$G$1368,$A16) -> -700 | C16: =SUMIFS(Angela_2026_Chase1117_Activity_!$D$2:$D$1368,Angela_2026_Chase1117_Activity_!$B$2:$B$1368,">="&C$4,Angela_2026_Chase1117_Activity_!$B$2:$B$1368,"<="&EOMONTH(C$4,0),Angela_2026_Chase1117_Activity_!$G$2:$G$1368,$A16) -> 0 | D16: =SUMIFS(Angela_2026_Chase1117_Activity_!$D$2:$D$1368,Angela_2026_Chase1117_Activity_!$B$2:$B$1368,">="&D$4,Angela_2026_Chase1117_Activity_!$B$2:$B$1368,"<="&EOMONTH(D$4,0),Angela_2026_Chase1117_Activity_!$G$2:$G$1368,$A16) -> 0 | E16: =SUMIFS(Angela_2026_Chase1117_Activity_!$D$2:$D$1368,Angela_2026_Chase1117_Activity_!$B$2:$B$1368,">="&E$4,Angela_2026_Chase1117_Activity_!$B$2:$B$1368,"<="&EOMONTH(E$4,0),Angela_2026_Chase1117_Activity_!$G$2:$G$1368,$A16) -> 0 | F16: =SUMIFS(Angela_2026_Chase1117_Activity_!$D$2:$D$1368,Angela_2026_Chase1117_Activity_!$B$2:$B$1368,">="&F$4,Angela_2026_Chase1117_Activity_!$B$2:$B$1368,"<="&EOMONTH(F$4,0),Angela_2026_Chase1117_Activity_!$G$2:$G$1368,$A16) -> -600 | G16: =SUMIFS(Angela_2026_Chase1117_Activity_!$D$2:$D$1368,Angela_2026_Chase1117_Activity_!$B$2:$B$1368,">="&G$4,Angela_2026_Chase1117_Activity_!$B$2:$B$1368,"<="&EOMONTH(G$4,0),Angela_2026_Chase1117_Activity_!$G$2:$G$1368,$A16) -> 0 | H16: =SUMIFS(Angela_2026_Chase1117_Activity_!$D$2:$D$1368,Angela_2026_Chase1117_Activity_!$B$2:$B$1368,">="&H$4,Angela_2026_Chase1117_Activity_!$B$2:$B$1368,"<="&EOMONTH(H$4,0),Angela_2026_Chase1117_Activity_!$G$2:$G$1368,$A16) -> 0 | I16: =SUM(B16:H16) -> -1300
... A52: Donation | B52: =SUMIFS(Angela_2026_Chase1117_Activity_!$D$2:$D$1368,Angela_2026_Chase1117_Activity_!$B$2:$B$1368,">="&B$4,Angela_2026_Chase1117_Activity_!$B$2:$B$1368,"<="&EOMONTH(B$4,0),Angela_2026_Chase1117_Activity_!$G$2:$G$1368,$A52) -> 0 | C52: =SUMIFS(Angela_2026_Chase1117_Activity_!$D$2:$D$1368,Angela_2026_Chase1117_Activity_!$B$2:$B$1368,">="&C$4,Angela_2026_Chase1117_Activity_!$B$2:$B$1368,"<="&EOMONTH(C$4,0),Angela_2026_Chase1117_Activity_!$G$2:$G$1368,$A52) -> -310 | D52: =SUMIFS(Angela_2026_Chase1117_Activity_!$D$2:$D$1368,Angela_2026_Chase1117_Activity_!$B$2:$B$1368,">="&D$4,Angela_2026_Chase1117_Activity_!$B$2:$B$1368,"<="&EOMONTH(D$4,0),Angela_2026_Chase1117_Activity_!$G$2:$G$1368,$A52) -> 100 | E52: =SUMIFS(Angela_2026_Chase1117_Activity_!$D$2:$D$1368,Angela_2026_Chase1117_Activity_!$B$2:$B$1368,">="&E$4,Angela_2026_Chase1117_Activity_!$B$2:$B$1368,"<="&EOMONTH(E$4,0),Angela_2026_Chase1117_Activity_!$G$2:$G$1368,$A52) -> 0 | F52: =SUMIFS(Angela_2026_Chase1117_Activity_!$D$2:$D$1368,Angela_2026_Chase1117_Activity_!$B$2:$B$1368,">="&F$4,Angela_2026_Chase1117_Activity_!$B$2:$B$1368,"<="&EOMONTH(F$4,0),Angela_2026_Chase1117_Activity_!$G$2:$G$1368,$A52) -> -295 | G52: =SUMIFS(Angela_2026_Chase1117_Activity_!$D$2:$D$1368,Angela_2026_Chase1117_Activity_!$B$2:$B$1368,">="&G$4,Angela_2026_Chase1117_Activity_!$B$2:$B$1368,"<="&EOMONTH(G$4,0),Angela_2026_Chase1117_Activity_!$G$2:$G$1368,$A52) -> -180 | H52: =SUMIFS(Angela_2026_Chase1117_Activity_!$D$2:$D$1368,Angela_2026_Chase1117_Activity_!$B$2:$B$1368,">="&H$4,Angela_2026_Chase1117_Activity_!$B$2:$B$1368,"<="&EOMONTH(H$4,0),Angela_2026_Chase1117_Activity_!$G$2:$G$1368,$A52) -> 0 | I52: =SUM(B52:H52) -> -685
A53: TOTAL — ALL CATEGORIES | B53: =SUM(B5:B52) -> 3776.99 | C53: =SUM(C5:C52) -> 4538.18 | D53: =SUM(D5:D52) -> 631.4 | E53: =SUM(E5:E52) -> -8763.51 | F53: =SUM(F5:F52) -> -1282.76 | G53: =SUM(G5:G52) -> 5118.09 | H53: =SUM(H5:H52) -> -4471.87 | I53: =SUM(I5:I52) -> -453.48

Sheet Category Rules
A1: Keyword | B1: Category
A2: DOORDASH | B2: Uber Eats
A3: AMAZON | B3: Amazon
A4: PRIME VIDEO | B4: Amazon
A5: POSHMARK | B5: Poshmark
A6: GRANDVIEW | B6: Personal - Clothing
A7: AMERICAN AI | B7: Personal Travel
A8: UNITED | B8: Personal Travel
A9: EXPEDIA | B9: Personal Travel
A10: SEVENTH | B10: Personal Travel
A11: SOUTHWEST | B11: Personal Travel
A12: FRONTIER AI | B12: Frontier
... A194: RAINBOW ACRES | B194: Personal - Misc

Sheet Angela_2026_Chase1117_Activity_
A1: Details | B1: Posting Date | C1: Description | D1: Amount | E1: Type | F1: Balance | G1: Category
A2: DEBIT | B2: 46211 | C2: POS DEBIT UBER * EATS PENDING SAN FRANCISC CA | D2: -20.54 | E2: MISC_DEBIT | G2: {=IF(AND(ISNUMBER(SEARCH("UBER",C2)),ISNUMBER(SEARCH("EATS",C2))),"Uber Eats",IF(LEFT(C2,6)="CHECK ","Checks Paid",IF(OR(E2="BILLPAY",ISNUMBER(SEARCH("FRANCHISE TAX",C2)),ISNUMBER(SEARCH("NEXTLINK",C2))),"Personal - House Bills",IF(AND(ISNUMBER(SEARCH("PAYMENT FROM",C2)),ISNUMBER(SEARCH("JOE SAUNDERS",C2))),"Zelle from Joe Saunders",IF(AND(ISNUMBER(SEARCH("PAYMENT TO",C2)),ISNUMBER(SEARCH("JOE SAUNDERS",C2))),"Zelle to Joe Saunders",IF(OR(ISNUMBER(SEARCH("NEW ORLEANS",C2)),ISNUMBER(SEARCH("KENNER",C2)),ISNUMBER(SEARCH("HENRY HOWARD",C2)),ISNUMBER(SEARCH("MISS CLAUDIA",C2))),"Personal Travel - New Orleans",IFERROR(INDEX('Category Rules'!$B$2:$B$194,MATCH(TRUE,ISNUMBER(SEARCH('Category Rules'!$A$2:$A$194,C2)),0)),"")))))))} -> Uber Eats
A3: DEBIT | B3: 46211 | C3: POS DEBIT 6DAYWEIGHT* 6DAYWEIGHT +18187829038 CA 0089 | D3: -395 | E3: MISC_DEBIT | G3: {=IF(AND(ISNUMBER(SEARCH("UBER",C3)),ISNUMBER(SEARCH("EATS",C3))),"Uber Eats",IF(LEFT(C3,6)="CHECK ","Checks Paid",IF(OR(E3="BILLPAY",ISNUMBER(SEARCH("FRANCHISE TAX",C3)),ISNUMBER(SEARCH("NEXTLINK",C3))),"Personal - House Bills",IF(AND(ISNUMBER(SEARCH("PAYMENT FROM",C3)),ISNUMBER(SEARCH("JOE SAUNDERS",C3))),"Zelle from Joe Saunders",IF(AND(ISNUMBER(SEARCH("PAYMENT TO",C3)),ISNUMBER(SEARCH("JOE SAUNDERS",C3))),"Zelle to Joe Saunders",IF(OR(ISNUMBER(SEARCH("NEW ORLEANS",C3)),ISNUMBER(SEARCH("KENNER",C3)),ISNUMBER(SEARCH("HENRY HOWARD",C3)),ISNUMBER(SEARCH("MISS CLAUDIA",C3))),"Personal Travel - New Orleans",IFERROR(INDEX('Category Rules'!$B$2:$B$194,MATCH(TRUE,ISNUMBER(SEARCH('Category Rules'!$A$2:$A$194,C3)),0)),"")))))))} -> Personal - Health
A4: DEBIT | B4: 46211 | C4: POS DEBIT Prime Video Channels amzn.com/bil WA 0360 | D4: -15.99 | E4: MISC_DEBIT | G4: {=IF(AND(ISNUMBER(SEARCH("UBER",C4)),ISNUMBER(SEARCH("EATS",C4))),"Uber Eats",IF(LEFT(C4,6)="CHECK ","Checks Paid",IF(OR(E4="BILLPAY",ISNUMBER(SEARCH("FRANCHISE TAX",C4)),ISNUMBER(SEARCH("NEXTLINK",C4))),"Personal - House Bills",IF(AND(ISNUMBER(SEARCH("PAYMENT FROM",C4)),ISNUMBER(SEARCH("JOE SAUNDERS",C4))),"Zelle from Joe Saunders",IF(AND(ISNUMBER(SEARCH("PAYMENT TO",C4)),ISNUMBER(SEARCH("JOE SAUNDERS",C4))),"Zelle to Joe Saunders",IF(OR(ISNUMBER(SEARCH("NEW ORLEANS",C4)),ISNUMBER(SEARCH("KENNER",C4)),ISNUMBER(SEARCH("HENRY HOWARD",C4)),ISNUMBER(SEARCH("MISS CLAUDIA",C4))),"Personal Travel - New Orleans",IFERROR(INDEX('Category Rules'!$B$2:$B$194,MATCH(TRUE,ISNUMBER(SEARCH('Category Rules'!$A$2:$A$194,C4)),0)),"")))))))} -> Amazon
A5: DEBIT | B5: 46211 | C5: POS DEBIT Amazon Tips Amzn.com/bil WA 0360 | D5: -15 | E5: MISC_DEBIT | G5: {=IF(AND(ISNUMBER(SEARCH("UBER",C5)),ISNUMBER(SEARCH("EATS",C5))),"Uber Eats",IF(LEFT(C5,6)="CHECK ","Checks Paid",IF(OR(E5="BILLPAY",ISNUMBER(SEARCH("FRANCHISE TAX",C5)),ISNUMBER(SEARCH("NEXTLINK",C5))),"Personal - House Bills",IF(AND(ISNUMBER(SEARCH("PAYMENT FROM",C5)),ISNUMBER(SEARCH("JOE SAUNDERS",C5))),"Zelle from Joe Saunders",IF(AND(ISNUMBER(SEARCH("PAYMENT TO",C5)),ISNUMBER(SEARCH("JOE SAUNDERS",C5))),"Zelle to Joe Saunders",IF(OR(ISNUMBER(SEARCH("NEW ORLEANS",C5)),ISNUMBER(SEARCH("KENNER",C5)),ISNUMBER(SEARCH("HENRY HOWARD",C5)),ISNUMBER(SEARCH("MISS CLAUDIA",C5))),"Personal Travel - New Orleans",IFERROR(INDEX('Category Rules'!$B$2:$B$194,MATCH(TRUE,ISNUMBER(SEARCH('Category Rules'!$A$2:$A$194,C5)),0)),"")))))))} -> Amazon
A6: DEBIT | B6: 46210 | C6: UBER * EATS PENDIN SAN FRANCISCO CA148376 07/07 | D6: -27.55 | E6: DEBIT_CARD | F6: 1542.75 | G6: {=IF(AND(ISNUMBER(SEARCH("UBER",C6)),ISNUMBER(SEARCH("EATS",C6))),"Uber Eats",IF(LEFT(C6,6)="CHECK ","Checks Paid",IF(OR(E6="BILLPAY",ISNUMBER(SEARCH("FRANCHISE TAX",C6)),ISNUMBER(SEARCH("NEXTLINK",C6))),"Personal - House Bills",IF(AND(ISNUMBER(SEARCH("PAYMENT FROM",C6)),ISNUMBER(SEARCH("JOE SAUNDERS",C6))),"Zelle from Joe Saunders",IF(AND(ISNUMBER(SEARCH("PAYMENT TO",C6)),ISNUMBER(SEARCH("JOE SAUNDERS",C6))),"Zelle to Joe Saunders",IF(OR(ISNUMBER(SEARCH("NEW ORLEANS",C6)),ISNUMBER(SEARCH("KENNER",C6)),ISNUMBER(SEARCH("HENRY HOWARD",C6)),ISNUMBER(SEARCH("MISS CLAUDIA",C6))),"Personal Travel - New Orleans",IFERROR(INDEX('Category Rules'!$B$2:$B$194,MATCH(TRUE,ISNUMBER(SEARCH('Category Rules'!$A$2:$A$194,C6)),0)),"")))))))} -> Uber Eats
A7: DEBIT | B7: 46210 | C7: WITHDRAWAL 07/07 | D7: -5000 | E7: MISC_DEBIT | F7: 1570.3 | G7: {=IF(AND(ISNUMBER(SEARCH("UBER",C7)),ISNUMBER(SEARCH("EATS",C7))),"Uber Eats",IF(LEFT(C7,6)="CHECK ","Checks Paid",IF(OR(E7="BILLPAY",ISNUMBER(SEARCH("FRANCHISE TAX",C7)),ISNUMBER(SEARCH("NEXTLINK",C7))),"Personal - House Bills",IF(AND(ISNUMBER(SEARCH("PAYMENT FROM",C7)),ISNUMBER(SEARCH("JOE SAUNDERS",C7))),"Zelle from Joe Saunders",IF(AND(ISNUMBER(SEARCH("PAYMENT TO",C7)),ISNUMBER(SEARCH("JOE SAUNDERS",C7))),"Zelle to Joe Saunders",IF(OR(ISNUMBER(SEARCH("NEW ORLEANS",C7)),ISNUMBER(SEARCH("KENNER",C7)),ISNUMBER(SEARCH("HENRY HOWARD",C7)),ISNUMBER(SEARCH("MISS CLAUDIA",C7))),"Personal Travel - New Orleans",IFERROR(INDEX('Category Rules'!$B$2:$B$194,MATCH(TRUE,ISNUMBER(SEARCH('Category Rules'!$A$2:$A$194,C7)),0)),"")))))))} -> Withdrawal
A8: DEBIT | B8: 46210 | C8: AMAZON RETA* XR6945C WWW.AMAZON.CO WA 07/07 | D8: -25.62 | E8: DEBIT_CARD | F8: 6570.3 | G8: {=IF(AND(ISNUMBER(SEARCH("UBER",C8)),ISNUMBER(SEARCH("EATS",C8))),"Uber Eats",IF(LEFT(C8,6)="CHECK ","Checks Paid",IF(OR(E8="BILLPAY",ISNUMBER(SEARCH("FRANCHISE TAX",C8)),ISNUMBER(SEARCH("NEXTLINK",C8))),"Personal - House Bills",IF(AND(ISNUMBER(SEARCH("PAYMENT FROM",C8)),ISNUMBER(SEARCH("JOE SAUNDERS",C8))),"Zelle from Joe Saunders",IF(AND(ISNUMBER(SEARCH("PAYMENT TO",C8)),ISNUMBER(SEARCH("JOE SAUNDERS",C8))),"Zelle to Joe Saunders",IF(OR(ISNUMBER(SEARCH("NEW ORLEANS",C8)),ISNUMBER(SEARCH("KENNER",C8)),ISNUMBER(SEARCH("HENRY HOWARD",C8)),ISNUMBER(SEARCH("MISS CLAUDIA",C8))),"Personal Travel - New Orleans",IFERROR(INDEX('Category Rules'!$B$2:$B$194,MATCH(TRUE,ISNUMBER(SEARCH('Category Rules'!$A$2:$A$194,C8)),0)),"")))))))} -> Amazon
A9: DEBIT | B9: 46210 | C9: SP VALASTA LLC VALASTA.NET SC 07/06 | D9: -430.03 | E9: DEBIT_CARD | F9: 6595.92 | G9: {=IF(AND(ISNUMBER(SEARCH("UBER",C9)),ISNUMBER(SEARCH("EATS",C9))),"Uber Eats",IF(LEFT(C9,6)="CHECK ","Checks Paid",IF(OR(E9="BILLPAY",ISNUMBER(SEARCH("FRANCHISE TAX",C9)),ISNUMBER(SEARCH("NEXTLINK",C9))),"Personal - House Bills",IF(AND(ISNUMBER(SEARCH("PAYMENT FROM",C9)),ISNUMBER(SEARCH("JOE SAUNDERS",C9))),"Zelle from Joe Saunders",IF(AND(ISNUMBER(SEARCH("PAYMENT TO",C9)),ISNUMBER(SEARCH("JOE SAUNDERS",C9))),"Zelle to Joe Saunders",IF(OR(ISNUMBER(SEARCH("NEW ORLEANS",C9)),ISNUMBER(SEARCH("KENNER",C9)),ISNUMBER(SEARCH("HENRY HOWARD",C9)),ISNUMBER(SEARCH("MISS CLAUDIA",C9))),"Personal Travel - New Orleans",IFERROR(INDEX('Category Rules'!$B$2:$B$194,MATCH(TRUE,ISNUMBER(SEARCH('Category Rules'!$A$2:$A$194,C9)),0)),"")))))))} -> Personal - Health
A10: DEBIT | B10: 46210 | C10: GRANDVIEW CLEANERS LOS ANGELES CA 07/06 | D10: -133 | E10: DEBIT_CARD | F10: 7025.95 | G10: {=IF(AND(ISNUMBER(SEARCH("UBER",C10)),ISNUMBER(SEARCH("EATS",C10))),"Uber Eats",IF(LEFT(C10,6)="CHECK ","Checks Paid",IF(OR(E10="BILLPAY",ISNUMBER(SEARCH("FRANCHISE TAX",C10)),ISNUMBER(SEARCH("NEXTLINK",C10))),"Personal - House Bills",IF(AND(ISNUMBER(SEARCH("PAYMENT FROM",C10)),ISNUMBER(SEARCH("JOE SAUNDERS",C10))),"Zelle from Joe Saunders",IF(AND(ISNUMBER(SEARCH("PAYMENT TO",C10)),ISNUMBER(SEARCH("JOE SAUNDERS",C10))),"Zelle to Joe Saunders",IF(OR(ISNUMBER(SEARCH("NEW ORLEANS",C10)),ISNUMBER(SEARCH("KENNER",C10)),ISNUMBER(SEARCH("HENRY HOWARD",C10)),ISNUMBER(SEARCH("MISS CLAUDIA",C10))),"Personal Travel - New Orleans",IFERROR(INDEX('Category Rules'!$B$2:$B$194,MATCH(TRUE,ISNUMBER(SEARCH('Category Rules'!$A$2:$A$194,C10)),0)),"")))))))} -> Personal - Clothing
A11: DEBIT | B11: 46210 | C11: Amazon Tips*SA10C2A4 Amzn.com/bill WA 07/06 | D11: -30 | E11: DEBIT_CARD | F11: 7158.95 | G11: {=IF(AND(ISNUMBER(SEARCH("UBER",C11)),ISNUMBER(SEARCH("EATS",C11))),"Uber Eats",IF(LEFT(C11,6)="CHECK ","Checks Paid",IF(OR(E11="BILLPAY",ISNUMBER(SEARCH("FRANCHISE TAX",C11)),ISNUMBER(SEARCH("NEXTLINK",C11))),"Personal - House Bills",IF(AND(ISNUMBER(SEARCH("PAYMENT FROM",C11)),ISNUMBER(SEARCH("JOE SAUNDERS",C11))),"Zelle from Joe Saunders",IF(AND(ISNUMBER(SEARCH("PAYMENT TO",C11)),ISNUMBER(SEARCH("JOE SAUNDERS",C11))),"Zelle to Joe Saunders",IF(OR(ISNUMBER(SEARCH("NEW ORLEANS",C11)),ISNUMBER(SEARCH("KENNER",C11)),ISNUMBER(SEARCH("HENRY HOWARD",C11)),ISNUMBER(SEARCH("MISS CLAUDIA",C11))),"Personal Travel - New Orleans",IFERROR(INDEX('Category Rules'!$B$2:$B$194,MATCH(TRUE,ISNUMBER(SEARCH('Category Rules'!$A$2:$A$194,C11)),0)),"")))))))} -> Amazon
A12: DEBIT | B12: 46210 | C12: AMAZON RETA* WC81L6V WWW.AMAZON.CO WA 07/06 | D12: -11.75 | E12: DEBIT_CARD | F12: 7188.95 | G12: {=IF(AND(ISNUMBER(SEARCH("UBER",C12)),ISNUMBER(SEARCH("EATS",C12))),"Uber Eats",IF(LEFT(C12,6)="CHECK ","Checks Paid",IF(OR(E12="BILLPAY",ISNUMBER(SEARCH("FRANCHISE TAX",C12)),ISNUMBER(SEARCH("NEXTLINK",C12))),"Personal - House Bills",IF(AND(ISNUMBER(SEARCH("PAYMENT FROM",C12)),ISNUMBER(SEARCH("JOE SAUNDERS",C12))),"Zelle from Joe Saunders",IF(AND(ISNUMBER(SEARCH("PAYMENT TO",C12)),ISNUMBER(SEARCH("JOE SAUNDERS",C12))),"Zelle to Joe Saunders",IF(OR(ISNUMBER(SEARCH("NEW ORLEANS",C12)),ISNUMBER(SEARCH("KENNER",C12)),ISNUMBER(SEARCH("HENRY HOWARD",C12)),ISNUMBER(SEARCH("MISS CLAUDIA",C12))),"Personal Travel - New Orleans",IFERROR(INDEX('Category Rules'!$B$2:$B$194,MATCH(TRUE,ISNUMBER(SEARCH('Category Rules'!$A$2:$A$194,C12)),0)),"")))))))} -> Amazon
A13: DEBIT | B13: 46210 | C13: AMAZON RETA* TR3I78I WWW.AMAZON.CO WA 07/07 | D13: -7.75 | E13: DEBIT_CARD | F13: 7200.7 | G13: {=IF(AND(ISNUMBER(SEARCH("UBER",C13)),ISNUMBER(SEARCH("EATS",C13))),"Uber Eats",IF(LEFT(C13,6)="CHECK ","Checks Paid",IF(OR(E13="BILLPAY",ISNUMBER(SEARCH("FRANCHISE TAX",C13)),ISNUMBER(SEARCH("NEXTLINK",C13))),"Personal - House Bills",IF(AND(ISNUMBER(SEARCH("PAYMENT FROM",C13)),ISNUMBER(SEARCH("JOE SAUNDERS",C13))),"Zelle from Joe Saunders",IF(AND(ISNUMBER(SEARCH("PAYMENT TO",C13)),ISNUMBER(SEARCH("JOE SAUNDERS",C13))),"Zelle to Joe Saunders",IF(OR(ISNUMBER(SEARCH("NEW ORLEANS",C13)),ISNUMBER(SEARCH("KENNER",C13)),ISNUMBER(SEARCH("HENRY HOWARD",C13)),ISNUMBER(SEARCH("MISS CLAUDIA",C13))),"Personal Travel - New Orleans",IFERROR(INDEX('Category Rules'!$B$2:$B$194,MATCH(TRUE,ISNUMBER(SEARCH('Category Rules'!$A$2:$A$194,C13)),0)),"")))))))} -> Amazon
A14: DEBIT | B14: 46210 | C14: AMAZON RETA* 7S20V2V WWW.AMAZON.CO WA 07/07 | D14: -2.98 | E14: DEBIT_CARD | F14: 7208.45 | G14: {=IF(AND(ISNUMBER(SEARCH("UBER",C14)),ISNUMBER(SEARCH("EATS",C14))),"Uber Eats",IF(LEFT(C14,6)="CHECK ","Checks Paid",IF(OR(E14="BILLPAY",ISNUMBER(SEARCH("FRANCHISE TAX",C14)),ISNUMBER(SEARCH("NEXTLINK",C14))),"Personal - House Bills",IF(AND(ISNUMBER(SEARCH("PAYMENT FROM",C14)),ISNUMBER(SEARCH("JOE SAUNDERS",C14))),"Zelle from Joe Saunders",IF(AND(ISNUMBER(SEARCH("PAYMENT TO",C14)),ISNUMBER(SEARCH("JOE SAUNDERS",C14))),"Zelle to Joe Saunders",IF(OR(ISNUMBER(SEARCH("NEW ORLEANS",C14)),ISNUMBER(SEARCH("KENNER",C14)),ISNUMBER(SEARCH("HENRY HOWARD",C14)),ISNUMBER(SEARCH("MISS CLAUDIA",C14))),"Personal Travel - New Orleans",IFERROR(INDEX('Category Rules'!$B$2:$B$194,MATCH(TRUE,ISNUMBER(SEARCH('Category Rules'!$A$2:$A$194,C14)),0)),"")))))))} -> Amazon
A15: DEBIT | B15: 46210 | C15: Amazon.com*J13TY12U3 Amzn.com/bill WA 07/06 | D15: -77.09 | E15: DEBIT_CARD | F15: 7211.43 | G15: {=IF(AND(ISNUMBER(SEARCH("UBER",C15)),ISNUMBER(SEARCH("EATS",C15))),"Uber Eats",IF(LEFT(C15,6)="CHECK ","Checks Paid",IF(OR(E15="BILLPAY",ISNUMBER(SEARCH("FRANCHISE TAX",C15)),ISNUMBER(SEARCH("NEXTLINK",C15))),"Personal - House Bills",IF(AND(ISNUMBER(SEARCH("PAYMENT FROM",C15)),ISNUMBER(SEARCH("JOE SAUNDERS",C15))),"Zelle from Joe Saunders",IF(AND(ISNUMBER(SEARCH("PAYMENT TO",C15)),ISNUMBER(SEARCH("JOE SAUNDERS",C15))),"Zelle to Joe Saunders",IF(OR(ISNUMBER(SEARCH("NEW ORLEANS",C15)),ISNUMBER(SEARCH("KENNER",C15)),ISNUMBER(SEARCH("HENRY HOWARD",C15)),ISNUMBER(SEARCH("MISS CLAUDIA",C15))),"Personal Travel - New Orleans",IFERROR(INDEX('Category Rules'!$B$2:$B$194,MATCH(TRUE,ISNUMBER(SEARCH('Category Rules'!$A$2:$A$194,C15)),0)),"")))))))} -> Amazon
A16: DEBIT | B16: 46210 | C16: AMAZON RETA* TN0B08X WWW.AMAZON.CO WA 07/06 | D16: -42.47 | E16: DEBIT_CARD | F16: 7288.52 | G16: {=IF(AND(ISNUMBER(SEARCH("UBER",C16)),ISNUMBER(SEARCH("EATS",C16))),"Uber Eats",IF(LEFT(C16,6)="CHECK ","Checks Paid",IF(OR(E16="BILLPAY",ISNUMBER(SEARCH("FRANCHISE TAX",C16)),ISNUMBER(SEARCH("NEXTLINK",C16))),"Personal - House Bills",IF(AND(ISNUMBER(SEARCH("PAYMENT FROM",C16)),ISNUMBER(SEARCH("JOE SAUNDERS",C16))),"Zelle from Joe Saunders",IF(AND(ISNUMBER(SEARCH("PAYMENT TO",C16)),ISNUMBER(SEARCH("JOE SAUNDERS",C16))),"Zelle to Joe Saunders",IF(OR(ISNUMBER(SEARCH("NEW ORLEANS",C16)),ISNUMBER(SEARCH("KENNER",C16)),ISNUMBER(SEARCH("HENRY HOWARD",C16)),ISNUMBER(SEARCH("MISS CLAUDIA",C16))),"Personal Travel - New Orleans",IFERROR(INDEX('Category Rules'!$B$2:$B$194,MATCH(TRUE,ISNUMBER(SEARCH('Category Rules'!$A$2:$A$194,C16)),0)),"")))))))} -> Amazon
A17: DSLIP | B17: 46210 | C17: DEPOSIT ID NUMBER 891007 | D17: 120 | E17: DEPOSIT | F17: 7330.99 | G17: {=IF(AND(ISNUMBER(SEARCH("UBER",C17)),ISNUMBER(SEARCH("EATS",C17))),"Uber Eats",IF(LEFT(C17,6)="CHECK ","Checks Paid",IF(OR(E17="BILLPAY",ISNUMBER(SEARCH("FRANCHISE TAX",C17)),ISNUMBER(SEARCH("NEXTLINK",C17))),"Personal - House Bills",IF(AND(ISNUMBER(SEARCH("PAYMENT FROM",C17)),ISNUMBER(SEARCH("JOE SAUNDERS",C17))),"Zelle from Joe Saunders",IF(AND(ISNUMBER(SEARCH("PAYMENT TO",C17)),ISNUMBER(SEARCH("JOE SAUNDERS",C17))),"Zelle to Joe Saunders",IF(OR(ISNUMBER(SEARCH("NEW ORLEANS",C17)),ISNUMBER(SEARCH("KENNER",C17)),ISNUMBER(SEARCH("HENRY HOWARD",C17)),ISNUMBER(SEARCH("MISS CLAUDIA",C17))),"Personal Travel - New Orleans",IFERROR(INDEX('Category Rules'!$B$2:$B$194,MATCH(TRUE,ISNUMBER(SEARCH('Category Rules'!$A$2:$A$194,C17)),0)),"")))))))} -> Deposit
... A1094: DEBIT | B1094: 46064 | C1094: Amazon Tips*9Z40N0UM Amzn.com/bill WA 02/10 | D1094: -15 | E1094: DEBIT_CARD | F1094: 2555.56 | G1094: {=IF(AND(ISNUMBER(SEARCH("UBER",C1094)),ISNUMBER(SEARCH("EATS",C1094))),"Uber Eats",IF(LEFT(C1094,6)="CHECK ","Checks Paid",IF(OR(E1094="BILLPAY",ISNUMBER(SEARCH("FRANCHISE TAX",C1094)),ISNUMBER(SEARCH("NEXTLINK",C1094))),"Personal - House Bills",IF(AND(ISNUMBER(SEARCH("PAYMENT FROM",C1094)),ISNUMBER(SEARCH("JOE SAUNDERS",C1094))),"Zelle from Joe Saunders",IF(AND(ISNUMBER(SEARCH("PAYMENT TO",C1094)),ISNUMBER(SEARCH("JOE SAUNDERS",C1094))),"Zelle to Joe Saunders",IF(OR(ISNUMBER(SEARCH("NEW ORLEANS",C1094)),ISNUMBER(SEARCH("KENNER",C1094)),ISNUMBER(SEARCH("HENRY HOWARD",C1094)),ISNUMBER(SEARCH("MISS CLAUDIA",C1094))),"Personal Travel - New Orleans",IFERROR(INDEX('Category Rules'!$B$2:$B$194,MATCH(TRUE,ISNUMBER(SEARCH('Category Rules'!$A$2:$A$194,C1094)),0)),"")))))))} -> Amazon
A1095: DEBIT | B1095: 46063 | C1095: CNP* VOGUE - DIGITAL CONDENAST.COM NY 02/10 | D1095: -24.99 | E1095: DEBIT_CARD | F1095: 2570.56 | G1095: Personal - Shopping
A1096: DEBIT | B1096: 46063 | C1096: Online Transfer to CHK ...6975 transaction#: 28016408490 02/10 | D1096: -250 | E1096: ACCT_XFER | F1096: 2595.55 | G1096: {=IF(AND(ISNUMBER(SEARCH("UBER",C1096)),ISNUMBER(SEARCH("EATS",C1096))),"Uber Eats",IF(LEFT(C1096,6)="CHECK ","Checks Paid",IF(OR(E1096="BILLPAY",ISNUMBER(SEARCH("FRANCHISE TAX",C1096)),ISNUMBER(SEARCH("NEXTLINK",C1096))),"Personal - House Bills",IF(AND(ISNUMBER(SEARCH("PAYMENT FROM",C1096)),ISNUMBER(SEARCH("JOE SAUNDERS",C1096))),"Zelle from Joe Saunders",IF(AND(ISNUMBER(SEARCH("PAYMENT TO",C1096)),ISNUMBER(SEARCH("JOE SAUNDERS",C1096))),"Zelle to Joe Saunders",IF(OR(ISNUMBER(SEARCH("NEW ORLEANS",C1096)),ISNUMBER(SEARCH("KENNER",C1096)),ISNUMBER(SEARCH("HENRY HOWARD",C1096)),ISNUMBER(SEARCH("MISS CLAUDIA",C1096))),"Personal Travel - New Orleans",IFERROR(INDEX('Category Rules'!$B$2:$B$194,MATCH(TRUE,ISNUMBER(SEARCH('Category Rules'!$A$2:$A$194,C1096)),0)),"")))))))} -> Transfer to Ava
A1097: DEBIT | B1097: 46063 | C1097: AMAZON MARK* 8Y4Q08G AMAZON.COM/MA WA 02/10 | D1097: -69.08 | E1097: DEBIT_CARD | F1097: 2845.55 | G1097: {=IF(AND(ISNUMBER(SEARCH("UBER",C1097)),ISNUMBER(SEARCH("EATS",C1097))),"Uber Eats",IF(LEFT(C1097,6)="CHECK ","Checks Paid",IF(OR(E1097="BILLPAY",ISNUMBER(SEARCH("FRANCHISE TAX",C1097)),ISNUMBER(SEARCH("NEXTLINK",C1097))),"Personal - House Bills",IF(AND(ISNUMBER(SEARCH("PAYMENT FROM",C1097)),ISNUMBER(SEARCH("JOE SAUNDERS",C1097))),"Zelle from Joe Saunders",IF(AND(ISNUMBER(SEARCH("PAYMENT TO",C1097)),ISNUMBER(SEARCH("JOE SAUNDERS",C1097))),"Zelle to Joe Saunders",IF(OR(ISNUMBER(SEARCH("NEW ORLEANS",C1097)),ISNUMBER(SEARCH("KENNER",C1097)),ISNUMBER(SEARCH("HENRY HOWARD",C1097)),ISNUMBER(SEARCH("MISS CLAUDIA",C1097))),"Personal Travel - New Orleans",IFERROR(INDEX('Category Rules'!$B$2:$B$194,MATCH(TRUE,ISNUMBER(SEARCH('Category Rules'!$A$2:$A$194,C1097)),0)),"")))))))} -> Amazon
A1098: DEBIT | B1098: 46063 | C1098: Amazon.com*XC33A0EY3 Amzn.com/bill WA 02/09 | D1098: -31.46 | E1098: DEBIT_CARD | F1098: 2914.63 | G1098: {=IF(AND(ISNUMBER(SEARCH("UBER",C1098)),ISNUMBER(SEARCH("EATS",C1098))),"Uber Eats",IF(LEFT(C1098,6)="CHECK ","Checks Paid",IF(OR(E1098="BILLPAY",ISNUMBER(SEARCH("FRANCHISE TAX",C1098)),ISNUMBER(SEARCH("NEXTLINK",C1098))),"Personal - House Bills",IF(AND(ISNUMBER(SEARCH("PAYMENT FROM",C1098)),ISNUMBER(SEARCH("JOE SAUNDERS",C1098))),"Zelle from Joe Saunders",IF(AND(ISNUMBER(SEARCH("PAYMENT TO",C1098)),ISNUMBER(SEARCH("JOE SAUNDERS",C1098))),"Zelle to Joe Saunders",IF(OR(ISNUMBER(SEARCH("NEW ORLEANS",C1098)),ISNUMBER(SEARCH("KENNER",C1098)),ISNUMBER(SEARCH("HENRY HOWARD",C1098)),ISNUMBER(SEARCH("MISS CLAUDIA",C1098))),"Personal Travel - New Orleans",IFERROR(INDEX('Category Rules'!$B$2:$B$194,MATCH(TRUE,ISNUMBER(SEARCH('Category Rules'!$A$2:$A$194,C1098)),0)),"")))))))} -> Amazon
A1099: DEBIT | B1099: 46063 | C1099: Amazon.com*LA0TR9IZ3 Amzn.com/bill WA 02/09 | D1099: -104.95 | E1099: DEBIT_CARD | F1099: 2946.09 | G1099: {=IF(AND(ISNUMBER(SEARCH("UBER",C1099)),ISNUMBER(SEARCH("EATS",C1099))),"Uber Eats",IF(LEFT(C1099,6)="CHECK ","Checks Paid",IF(OR(E1099="BILLPAY",ISNUMBER(SEARCH("FRANCHISE TAX",C1099)),ISNUMBER(SEARCH("NEXTLINK",C1099))),"Personal - House Bills",IF(AND(ISNUMBER(SEARCH("PAYMENT FROM",C1099)),ISNUMBER(SEARCH("JOE SAUNDERS",C1099))),"Zelle from Joe Saunders",IF(AND(ISNUMBER(SEARCH("PAYMENT TO",C1099)),ISNUMBER(SEARCH("JOE SAUNDERS",C1099))),"Zelle to Joe Saunders",IF(OR(ISNUMBER(SEARCH("NEW ORLEANS",C1099)),ISNUMBER(SEARCH("KENNER",C1099)),ISNUMBER(SEARCH("HENRY HOWARD",C1099)),ISNUMBER(SEARCH("MISS CLAUDIA",C1099))),"Personal Travel - New Orleans",IFERROR(INDEX('Category Rules'!$B$2:$B$194,MATCH(TRUE,ISNUMBER(SEARCH('Category Rules'!$A$2:$A$194,C1099)),0)),"")))))))} -> Amazon
A1100: DEBIT | B1100: 46063 | C1100: NTTA AUTOCHARGE 972-818-6882 TX 02/09 | D1100: -40 | E1100: DEBIT_CARD | F1100: 3051.04 | G1100: {=IF(AND(ISNUMBER(SEARCH("UBER",C1100)),ISNUMBER(SEARCH("EATS",C1100))),"Uber Eats",IF(LEFT(C1100,6)="CHECK ","Checks Paid",IF(OR(E1100="BILLPAY",ISNUMBER(SEARCH("FRANCHISE TAX",C1100)),ISNUMBER(SEARCH("NEXTLINK",C1100))),"Personal - House Bills",IF(AND(ISNUMBER(SEARCH("PAYMENT FROM",C1100)),ISNUMBER(SEARCH("JOE SAUNDERS",C1100))),"Zelle from Joe Saunders",IF(AND(ISNUMBER(SEARCH("PAYMENT TO",C1100)),ISNUMBER(SEARCH("JOE SAUNDERS",C1100))),"Zelle to Joe Saunders",IF(OR(ISNUMBER(SEARCH("NEW ORLEANS",C1100)),ISNUMBER(SEARCH("KENNER",C1100)),ISNUMBER(SEARCH("HENRY HOWARD",C1100)),ISNUMBER(SEARCH("MISS CLAUDIA",C1100))),"Personal Travel - New Orleans",IFERROR(INDEX('Category Rules'!$B$2:$B$194,MATCH(TRUE,ISNUMBER(SEARCH('Category Rules'!$A$2:$A$194,C1100)),0)),"")))))))} -> Personal - Car
A1101: DEBIT | B1101: 46063 | C1101: AMAZON MARK* UW3I221 AMAZON.COM/MA WA 02/10 | D1101: -140.82 | E1101: DEBIT_CARD | F1101: 3091.04 | G1101: {=IF(AND(ISNUMBER(SEARCH("UBER",C1101)),ISNUMBER(SEARCH("EATS",C1101))),"Uber Eats",IF(LEFT(C1101,6)="CHECK ","Checks Paid",IF(OR(E1101="BILLPAY",ISNUMBER(SEARCH("FRANCHISE TAX",C1101)),ISNUMBER(SEARCH("NEXTLINK",C1101))),"Personal - House Bills",IF(AND(ISNUMBER(SEARCH("PAYMENT FROM",C1101)),ISNUMBER(SEARCH("JOE SAUNDERS",C1101))),"Zelle from Joe Saunders",IF(AND(ISNUMBER(SEARCH("PAYMENT TO",C1101)),ISNUMBER(SEARCH("JOE SAUNDERS",C1101))),"Zelle to Joe Saunders",IF(OR(ISNUMBER(SEARCH("NEW ORLEANS",C1101)),ISNUMBER(SEARCH("KENNER",C1101)),ISNUMBER(SEARCH("HENRY HOWARD",C1101)),ISNUMBER(SEARCH("MISS CLAUDIA",C1101))),"Personal Travel - New Orleans",IFERROR(INDEX('Category Rules'!$B$2:$B$194,MATCH(TRUE,ISNUMBER(SEARCH('Category Rules'!$A$2:$A$194,C1101)),0)),"")))))))} -> Amazon
A1102: DEBIT | B1102: 46063 | C1102: AMAZON MKTPL*IG30P45 Amzn.com/bill WA 02/09 | D1102: -112.45 | E1102: DEBIT_CARD | F1102: 3231.86 | G1102: {=IF(AND(ISNUMBER(SEARCH("UBER",C1102)),ISNUMBER(SEARCH("EATS",C1102))),"Uber Eats",IF(LEFT(C1102,6)="CHECK ","Checks Paid",IF(OR(E1102="BILLPAY",ISNUMBER(SEARCH("FRANCHISE TAX",C1102)),ISNUMBER(SEARCH("NEXTLINK",C1102))),"Personal - House Bills",IF(AND(ISNUMBER(SEARCH("PAYMENT FROM",C1102)),ISNUMBER(SEARCH("JOE SAUNDERS",C1102))),"Zelle from Joe Saunders",IF(AND(ISNUMBER(SEARCH("PAYMENT TO",C1102)),ISNUMBER(SEARCH("JOE SAUNDERS",C1102))),"Zelle to Joe Saunders",IF(OR(ISNUMBER(SEARCH("NEW ORLEANS",C1102)),ISNUMBER(SEARCH("KENNER",C1102)),ISNUMBER(SEARCH("HENRY HOWARD",C1102)),ISNUMBER(SEARCH("MISS CLAUDIA",C1102))),"Personal Travel - New Orleans",IFERROR(INDEX('Category Rules'!$B$2:$B$194,MATCH(TRUE,ISNUMBER(SEARCH('Category Rules'!$A$2:$A$194,C1102)),0)),"")))))))} -> Amazon
A1103: CREDIT | B1103: 46063 | C1103: Zelle payment from G-EUNICE LLC 28023181510 | D1103: 175 | E1103: QUICKPAY_CREDIT | F1103: 3344.31 | G1103: {=IF(AND(ISNUMBER(SEARCH("UBER",C1103)),ISNUMBER(SEARCH("EATS",C1103))),"Uber Eats",IF(LEFT(C1103,6)="CHECK ","Checks Paid",IF(OR(E1103="BILLPAY",ISNUMBER(SEARCH("FRANCHISE TAX",C1103)),ISNUMBER(SEARCH("NEXTLINK",C1103))),"Personal - House Bills",IF(AND(ISNUMBER(SEARCH("PAYMENT FROM",C1103)),ISNUMBER(SEARCH("JOE SAUNDERS",C1103))),"Zelle from Joe Saunders",IF(AND(ISNUMBER(SEARCH("PAYMENT TO",C1103)),ISNUMBER(SEARCH("JOE SAUNDERS",C1103))),"Zelle to Joe Saunders",IF(OR(ISNUMBER(SEARCH("NEW ORLEANS",C1103)),ISNUMBER(SEARCH("KENNER",C1103)),ISNUMBER(SEARCH("HENRY HOWARD",C1103)),ISNUMBER(SEARCH("MISS CLAUDIA",C1103))),"Personal Travel - New Orleans",IFERROR(INDEX('Category Rules'!$B$2:$B$194,MATCH(TRUE,ISNUMBER(SEARCH('Category Rules'!$A$2:$A$194,C1103)),0)),"")))))))} -> Zelle from G-Eunice LLC
A1104: DEBIT | B1104: 46062 | C1104: ZARA USA INC. ESTADOS UNIDO NY 026837 02/09 | D1104: -826.35 | E1104: DEBIT_CARD | F1104: 3169.31 | G1104: {=IF(AND(ISNUMBER(SEARCH("UBER",C1104)),ISNUMBER(SEARCH("EATS",C1104))),"Uber Eats",IF(LEFT(C1104,6)="CHECK ","Checks Paid",IF(OR(E1104="BILLPAY",ISNUMBER(SEARCH("FRANCHISE TAX",C1104)),ISNUMBER(SEARCH("NEXTLINK",C1104))),"Personal - House Bills",IF(AND(ISNUMBER(SEARCH("PAYMENT FROM",C1104)),ISNUMBER(SEARCH("JOE SAUNDERS",C1104))),"Zelle from Joe Saunders",IF(AND(ISNUMBER(SEARCH("PAYMENT TO",C1104)),ISNUMBER(SEARCH("JOE SAUNDERS",C1104))),"Zelle to Joe Saunders",IF(OR(ISNUMBER(SEARCH("NEW ORLEANS",C1104)),ISNUMBER(SEARCH("KENNER",C1104)),ISNUMBER(SEARCH("HENRY HOWARD",C1104)),ISNUMBER(SEARCH("MISS CLAUDIA",C1104))),"Personal Travel - New Orleans",IFERROR(INDEX('Category Rules'!$B$2:$B$194,MATCH(TRUE,ISNUMBER(SEARCH('Category Rules'!$A$2:$A$194,C1104)),0)),"")))))))} -> Personal - Shopping
