Workbook

Sheet Transaction Summary 2025
A1: FAMILY AMEX
A2: Amex Platinum | Statement Summary · 2025
A4: Account Holder | B4: John Dunning
A5: Account | B5: XXXX-XXXXXX-43006
A6: Statement Period | B6: January 2025 - December 2025
A8: TOTALS
A9: Charges | B9: =SUMIF('Transaction Details 2025'!$E$8:$E$331,">0") -> 35067.32
A10: Credits & Payments | B10: =SUMIF('Transaction Details 2025'!$E$8:$E$331,"<0") -> -35902.93
A11: Net Balance | B11: =B9+B10 -> -835.61
A13: SPEND BY CATEGORY
A14: Category | B14: Amount | C14: % of Charges
A15: John — Business
A16: DWG-RE Platform (Redirected) | B16: =SUMIFS('Transaction Details 2025'!$E$8:$E$331,'Transaction Details 2025'!$J$8:$J$331,A16) -> 16316.48 | C16: =IFERROR(B16/$B$9,0) -> 0.46529019
A17: DWG-RE Platform (Canceled) | B17: =SUMIFS('Transaction Details 2025'!$E$8:$E$331,'Transaction Details 2025'!$J$8:$J$331,A17) -> 48 | C17: =IFERROR(B17/$B$9,0) -> 0.0013687958
A18: Sponsor Cloud | B18: =SUMIFS('Transaction Details 2025'!$E$8:$E$331,'Transaction Details 2025'!$J$8:$J$331,A18) -> 339.31 | C18: =IFERROR(B18/$B$9,0) -> 0.0096759604
A19: Business Services-Other Services | B19: =SUMIFS('Transaction Details 2025'!$E$8:$E$331,'Transaction Details 2025'!$J$8:$J$331,A19) -> -300 | C19: =IFERROR(B19/$B$9,0) -> -0.0085549737
A20: Business Services-Professional Services | B20: =SUMIFS('Transaction Details 2025'!$E$8:$E$331,'Transaction Details 2025'!$J$8:$J$331,A20) -> 119 | C20: =IFERROR(B20/$B$9,0) -> 0.0033934729
A21: Renewal Fee | B21: =SUMIFS('Transaction Details 2025'!$E$8:$E$331,'Transaction Details 2025'!$J$8:$J$331,A21) -> 695 | C21: =IFERROR(B21/$B$9,0) -> 0.019819022
A22: Subtotal — John Business | B22: =SUM(B16:B21) -> 17217.79 | C22: =IFERROR(B22/$B$9,0) -> 0.49099247
A23: John — Travel
A24: Travel | B24: =SUMIFS('Transaction Details 2025'!$E$8:$E$331,'Transaction Details 2025'!$J$8:$J$331,A24) -> 50.31 | C24: =IFERROR(B24/$B$9,0) -> 0.0014346691
A25: Travel-Airline | B25: =SUMIFS('Transaction Details 2025'!$E$8:$E$331,'Transaction Details 2025'!$J$8:$J$331,A25) -> 1143.96 | C25: =IFERROR(B25/$B$9,0) -> 0.032621826
A26: Subtotal — John Travel | B26: =SUM(B24:B25) -> 1194.27 | C26: =IFERROR(B26/$B$9,0) -> 0.034056495
A27: John — Personal / Other
A28: Family | B28: =SUMIFS('Transaction Details 2025'!$E$8:$E$331,'Transaction Details 2025'!$J$8:$J$331,A28) -> 302.87 | C28: =IFERROR(B28/$B$9,0) -> 0.0086368163
A29: Personal - Health | B29: =SUMIFS('Transaction Details 2025'!$E$8:$E$331,'Transaction Details 2025'!$J$8:$J$331,A29) -> 280.44 | C29: =IFERROR(B29/$B$9,0) -> 0.0079971894
A30: Personal - Car | B30: =SUMIFS('Transaction Details 2025'!$E$8:$E$331,'Transaction Details 2025'!$J$8:$J$331,A30) -> 62.8 | C30: =IFERROR(B30/$B$9,0) -> 0.0017908412
A31: Personal | B31: =SUMIFS('Transaction Details 2025'!$E$8:$E$331,'Transaction Details 2025'!$J$8:$J$331,A31) -> 591.26 | C31: =IFERROR(B31/$B$9,0) -> 0.016860712
A32: Other-Miscellaneous | B32: =SUMIFS('Transaction Details 2025'!$E$8:$E$331,'Transaction Details 2025'!$J$8:$J$331,A32) -> -368.31 | C32: =IFERROR(B32/$B$9,0) -> -0.010502941
A33: Fees & Adjustments-Fees & Adjustments | B33: =SUMIFS('Transaction Details 2025'!$E$8:$E$331,'Transaction Details 2025'!$J$8:$J$331,A33) -> 2509.78 | C33: =IFERROR(B33/$B$9,0) -> 0.07157034
A34: Subtotal — John Personal / Other | B34: =SUM(B28:B33) -> 3378.84 | C34: =IFERROR(B34/$B$9,0) -> 0.096352958
A35: Other Card Members
A36: Ava Perez | B36: =SUMIFS('Transaction Details 2025'!$E$8:$E$331,'Transaction Details 2025'!$J$8:$J$331,A36) -> 10690.63 | C36: =IFERROR(B36/$B$9,0) -> 0.30486019
A37: Angela L Dunning | B37: =SUMIFS('Transaction Details 2025'!$E$8:$E$331,'Transaction Details 2025'!$J$8:$J$331,A37) -> 447.99 | C37: =IFERROR(B37/$B$9,0) -> 0.012775142
A38: Subtotal — Card Members | B38: =SUM(B36:B37) -> 11138.62 | C38: =IFERROR(B38/$B$9,0) -> 0.31763534
A39: Credits & Payments
A40: Online AMEX Payment | B40: =SUMIFS('Transaction Details 2025'!$E$8:$E$331,'Transaction Details 2025'!$J$8:$J$331,A40) -> -33765.13 | C40: =IFERROR(B40/$B$9,0) -> -0.962866
A41: Subtotal — Credits & Payments | B41: =SUM(B40:B40) -> -33765.13 | C41: =IFERROR(B41/$B$9,0) -> -0.962866
A42: GRAND TOTAL | B42: =B22+B26+B34+B38+B41 -> -835.61 | C42: =IFERROR(B42/$B$9,0) -> -0.023828739
A44: SPEND BY MONTH
...

Sheet Monthly Breakdown 2025
A1: FAMILY AMEX
A2: Amex Platinum | Monthly Breakdown · 2025
A4: Category | B4: =DATE(2025,1,1) -> 45658 | C4: =EDATE(B4,1) -> 45689 | D4: =EDATE(C4,1) -> 45717 | E4: =EDATE(D4,1) -> 45748 | F4: =EDATE(E4,1) -> 45778 | G4: =EDATE(F4,1) -> 45809 | H4: =EDATE(G4,1) -> 45839 | I4: =EDATE(H4,1) -> 45870 | J4: =EDATE(I4,1) -> 45901 | ... M4: =EDATE(L4,1) -> 45992 | N4: Total
A5: DWG-RE Platform (Redirected) | B5: =SUMIFS('Transaction Details 2025'!$E$8:$E$331,'Transaction Details 2025'!$J$8:$J$331,$A5,'Transaction Details 2025'!$I$8:$I$331,B$4) -> 362.92 | C5: =SUMIFS('Transaction Details 2025'!$E$8:$E$331,'Transaction Details 2025'!$J$8:$J$331,$A5,'Transaction Details 2025'!$I$8:$I$331,C$4) -> 365.92 | D5: =SUMIFS('Transaction Details 2025'!$E$8:$E$331,'Transaction Details 2025'!$J$8:$J$331,$A5,'Transaction Details 2025'!$I$8:$I$331,D$4) -> 365.92 | E5: =SUMIFS('Transaction Details 2025'!$E$8:$E$331,'Transaction Details 2025'!$J$8:$J$331,$A5,'Transaction Details 2025'!$I$8:$I$331,E$4) -> 1129.91 | F5: =SUMIFS('Transaction Details 2025'!$E$8:$E$331,'Transaction Details 2025'!$J$8:$J$331,$A5,'Transaction Details 2025'!$I$8:$I$331,F$4) -> 11489.92 | G5: =SUMIFS('Transaction Details 2025'!$E$8:$E$331,'Transaction Details 2025'!$J$8:$J$331,$A5,'Transaction Details 2025'!$I$8:$I$331,G$4) -> 365.92 | H5: =SUMIFS('Transaction Details 2025'!$E$8:$E$331,'Transaction Details 2025'!$J$8:$J$331,$A5,'Transaction Details 2025'!$I$8:$I$331,H$4) -> 365.92 | I5: =SUMIFS('Transaction Details 2025'!$E$8:$E$331,'Transaction Details 2025'!$J$8:$J$331,$A5,'Transaction Details 2025'!$I$8:$I$331,I$4) -> 365.92 | ... M5: =SUMIFS('Transaction Details 2025'!$E$8:$E$331,'Transaction Details 2025'!$J$8:$J$331,$A5,'Transaction Details 2025'!$I$8:$I$331,M$4) -> 386.37 | N5: =SUM(B5:M5) -> 16316.48
A6: DWG-RE Platform (Canceled) | B6: =SUMIFS('Transaction Details 2025'!$E$8:$E$331,'Transaction Details 2025'!$J$8:$J$331,$A6,'Transaction Details 2025'!$I$8:$I$331,B$4) -> 0 | C6: =SUMIFS('Transaction Details 2025'!$E$8:$E$331,'Transaction Details 2025'!$J$8:$J$331,$A6,'Transaction Details 2025'!$I$8:$I$331,C$4) -> 0 | D6: =SUMIFS('Transaction Details 2025'!$E$8:$E$331,'Transaction Details 2025'!$J$8:$J$331,$A6,'Transaction Details 2025'!$I$8:$I$331,D$4) -> 0 | E6: =SUMIFS('Transaction Details 2025'!$E$8:$E$331,'Transaction Details 2025'!$J$8:$J$331,$A6,'Transaction Details 2025'!$I$8:$I$331,E$4) -> 0 | F6: =SUMIFS('Transaction Details 2025'!$E$8:$E$331,'Transaction Details 2025'!$J$8:$J$331,$A6,'Transaction Details 2025'!$I$8:$I$331,F$4) -> 0 | G6: =SUMIFS('Transaction Details 2025'!$E$8:$E$331,'Transaction Details 2025'!$J$8:$J$331,$A6,'Transaction Details 2025'!$I$8:$I$331,G$4) -> 0 | H6: =SUMIFS('Transaction Details 2025'!$E$8:$E$331,'Transaction Details 2025'!$J$8:$J$331,$A6,'Transaction Details 2025'!$I$8:$I$331,H$4) -> 0 | I6: =SUMIFS('Transaction Details 2025'!$E$8:$E$331,'Transaction Details 2025'!$J$8:$J$331,$A6,'Transaction Details 2025'!$I$8:$I$331,I$4) -> 0 | ... M6: =SUMIFS('Transaction Details 2025'!$E$8:$E$331,'Transaction Details 2025'!$J$8:$J$331,$A6,'Transaction Details 2025'!$I$8:$I$331,M$4) -> 48 | N6: =SUM(B6:M6) -> 48
A7: Sponsor Cloud | B7: =SUMIFS('Transaction Details 2025'!$E$8:$E$331,'Transaction Details 2025'!$J$8:$J$331,$A7,'Transaction Details 2025'!$I$8:$I$331,B$4) -> 0 | C7: =SUMIFS('Transaction Details 2025'!$E$8:$E$331,'Transaction Details 2025'!$J$8:$J$331,$A7,'Transaction Details 2025'!$I$8:$I$331,C$4) -> 2.94 | D7: =SUMIFS('Transaction Details 2025'!$E$8:$E$331,'Transaction Details 2025'!$J$8:$J$331,$A7,'Transaction Details 2025'!$I$8:$I$331,D$4) -> 152.11 | E7: =SUMIFS('Transaction Details 2025'!$E$8:$E$331,'Transaction Details 2025'!$J$8:$J$331,$A7,'Transaction Details 2025'!$I$8:$I$331,E$4) -> 184.26 | F7: =SUMIFS('Transaction Details 2025'!$E$8:$E$331,'Transaction Details 2025'!$J$8:$J$331,$A7,'Transaction Details 2025'!$I$8:$I$331,F$4) -> 0 | G7: =SUMIFS('Transaction Details 2025'!$E$8:$E$331,'Transaction Details 2025'!$J$8:$J$331,$A7,'Transaction Details 2025'!$I$8:$I$331,G$4) -> 0 | H7: =SUMIFS('Transaction Details 2025'!$E$8:$E$331,'Transaction Details 2025'!$J$8:$J$331,$A7,'Transaction Details 2025'!$I$8:$I$331,H$4) -> 0 | I7: =SUMIFS('Transaction Details 2025'!$E$8:$E$331,'Transaction Details 2025'!$J$8:$J$331,$A7,'Transaction Details 2025'!$I$8:$I$331,I$4) -> 0 | ... M7: =SUMIFS('Transaction Details 2025'!$E$8:$E$331,'Transaction Details 2025'!$J$8:$J$331,$A7,'Transaction Details 2025'!$I$8:$I$331,M$4) -> 0 | N7: =SUM(B7:M7) -> 339.31
A8: Business Services-Other Services | B8: =SUMIFS('Transaction Details 2025'!$E$8:$E$331,'Transaction Details 2025'!$J$8:$J$331,$A8,'Transaction Details 2025'!$I$8:$I$331,B$4) -> -300 | C8: =SUMIFS('Transaction Details 2025'!$E$8:$E$331,'Transaction Details 2025'!$J$8:$J$331,$A8,'Transaction Details 2025'!$I$8:$I$331,C$4) -> 0 | D8: =SUMIFS('Transaction Details 2025'!$E$8:$E$331,'Transaction Details 2025'!$J$8:$J$331,$A8,'Transaction Details 2025'!$I$8:$I$331,D$4) -> 0 | E8: =SUMIFS('Transaction Details 2025'!$E$8:$E$331,'Transaction Details 2025'!$J$8:$J$331,$A8,'Transaction Details 2025'!$I$8:$I$331,E$4) -> 0 | F8: =SUMIFS('Transaction Details 2025'!$E$8:$E$331,'Transaction Details 2025'!$J$8:$J$331,$A8,'Transaction Details 2025'!$I$8:$I$331,F$4) -> 0 | G8: =SUMIFS('Transaction Details 2025'!$E$8:$E$331,'Transaction Details 2025'!$J$8:$J$331,$A8,'Transaction Details 2025'!$I$8:$I$331,G$4) -> 0 | H8: =SUMIFS('Transaction Details 2025'!$E$8:$E$331,'Transaction Details 2025'!$J$8:$J$331,$A8,'Transaction Details 2025'!$I$8:$I$331,H$4) -> 0 | I8: =SUMIFS('Transaction Details 2025'!$E$8:$E$331,'Transaction Details 2025'!$J$8:$J$331,$A8,'Transaction Details 2025'!$I$8:$I$331,I$4) -> 0 | ... M8: =SUMIFS('Transaction Details 2025'!$E$8:$E$331,'Transaction Details 2025'!$J$8:$J$331,$A8,'Transaction Details 2025'!$I$8:$I$331,M$4) -> 0 | N8: =SUM(B8:M8) -> -300
A9: Business Services-Professional Services | B9: =SUMIFS('Transaction Details 2025'!$E$8:$E$331,'Transaction Details 2025'!$J$8:$J$331,$A9,'Transaction Details 2025'!$I$8:$I$331,B$4) -> 119 | C9: =SUMIFS('Transaction Details 2025'!$E$8:$E$331,'Transaction Details 2025'!$J$8:$J$331,$A9,'Transaction Details 2025'!$I$8:$I$331,C$4) -> 0 | D9: =SUMIFS('Transaction Details 2025'!$E$8:$E$331,'Transaction Details 2025'!$J$8:$J$331,$A9,'Transaction Details 2025'!$I$8:$I$331,D$4) -> 0 | E9: =SUMIFS('Transaction Details 2025'!$E$8:$E$331,'Transaction Details 2025'!$J$8:$J$331,$A9,'Transaction Details 2025'!$I$8:$I$331,E$4) -> 0 | F9: =SUMIFS('Transaction Details 2025'!$E$8:$E$331,'Transaction Details 2025'!$J$8:$J$331,$A9,'Transaction Details 2025'!$I$8:$I$331,F$4) -> 0 | G9: =SUMIFS('Transaction Details 2025'!$E$8:$E$331,'Transaction Details 2025'!$J$8:$J$331,$A9,'Transaction Details 2025'!$I$8:$I$331,G$4) -> 0 | H9: =SUMIFS('Transaction Details 2025'!$E$8:$E$331,'Transaction Details 2025'!$J$8:$J$331,$A9,'Transaction Details 2025'!$I$8:$I$331,H$4) -> 0 | I9: =SUMIFS('Transaction Details 2025'!$E$8:$E$331,'Transaction Details 2025'!$J$8:$J$331,$A9,'Transaction Details 2025'!$I$8:$I$331,I$4) -> 0 | ... M9: =SUMIFS('Transaction Details 2025'!$E$8:$E$331,'Transaction Details 2025'!$J$8:$J$331,$A9,'Transaction Details 2025'!$I$8:$I$331,M$4) -> 0 | N9: =SUM(B9:M9) -> 119
A10: Renewal Fee | B10: =SUMIFS('Transaction Details 2025'!$E$8:$E$331,'Transaction Details 2025'!$J$8:$J$331,$A10,'Transaction Details 2025'!$I$8:$I$331,B$4) -> 0 | C10: =SUMIFS('Transaction Details 2025'!$E$8:$E$331,'Transaction Details 2025'!$J$8:$J$331,$A10,'Transaction Details 2025'!$I$8:$I$331,C$4) -> 0 | D10: =SUMIFS('Transaction Details 2025'!$E$8:$E$331,'Transaction Details 2025'!$J$8:$J$331,$A10,'Transaction Details 2025'!$I$8:$I$331,D$4) -> 0 | E10: =SUMIFS('Transaction Details 2025'!$E$8:$E$331,'Transaction Details 2025'!$J$8:$J$331,$A10,'Transaction Details 2025'!$I$8:$I$331,E$4) -> 0 | F10: =SUMIFS('Transaction Details 2025'!$E$8:$E$331,'Transaction Details 2025'!$J$8:$J$331,$A10,'Transaction Details 2025'!$I$8:$I$331,F$4) -> 0 | G10: =SUMIFS('Transaction Details 2025'!$E$8:$E$331,'Transaction Details 2025'!$J$8:$J$331,$A10,'Transaction Details 2025'!$I$8:$I$331,G$4) -> 0 | H10: =SUMIFS('Transaction Details 2025'!$E$8:$E$331,'Transaction Details 2025'!$J$8:$J$331,$A10,'Transaction Details 2025'!$I$8:$I$331,H$4) -> 0 | I10: =SUMIFS('Transaction Details 2025'!$E$8:$E$331,'Transaction Details 2025'!$J$8:$J$331,$A10,'Transaction Details 2025'!$I$8:$I$331,I$4) -> 0 | ... M10: =SUMIFS('Transaction Details 2025'!$E$8:$E$331,'Transaction Details 2025'!$J$8:$J$331,$A10,'Transaction Details 2025'!$I$8:$I$331,M$4) -> 695 | N10: =SUM(B10:M10) -> 695
A11: Travel | B11: =SUMIFS('Transaction Details 2025'!$E$8:$E$331,'Transaction Details 2025'!$J$8:$J$331,$A11,'Transaction Details 2025'!$I$8:$I$331,B$4) -> 0 | C11: =SUMIFS('Transaction Details 2025'!$E$8:$E$331,'Transaction Details 2025'!$J$8:$J$331,$A11,'Transaction Details 2025'!$I$8:$I$331,C$4) -> 0 | D11: =SUMIFS('Transaction Details 2025'!$E$8:$E$331,'Transaction Details 2025'!$J$8:$J$331,$A11,'Transaction Details 2025'!$I$8:$I$331,D$4) -> 50.31 | E11: =SUMIFS('Transaction Details 2025'!$E$8:$E$331,'Transaction Details 2025'!$J$8:$J$331,$A11,'Transaction Details 2025'!$I$8:$I$331,E$4) -> 0 | F11: =SUMIFS('Transaction Details 2025'!$E$8:$E$331,'Transaction Details 2025'!$J$8:$J$331,$A11,'Transaction Details 2025'!$I$8:$I$331,F$4) -> 0 | G11: =SUMIFS('Transaction Details 2025'!$E$8:$E$331,'Transaction Details 2025'!$J$8:$J$331,$A11,'Transaction Details 2025'!$I$8:$I$331,G$4) -> 0 | H11: =SUMIFS('Transaction Details 2025'!$E$8:$E$331,'Transaction Details 2025'!$J$8:$J$331,$A11,'Transaction Details 2025'!$I$8:$I$331,H$4) -> 0 | I11: =SUMIFS('Transaction Details 2025'!$E$8:$E$331,'Transaction Details 2025'!$J$8:$J$331,$A11,'Transaction Details 2025'!$I$8:$I$331,I$4) -> 0 | ... M11: =SUMIFS('Transaction Details 2025'!$E$8:$E$331,'Transaction Details 2025'!$J$8:$J$331,$A11,'Transaction Details 2025'!$I$8:$I$331,M$4) -> 0 | N11: =SUM(B11:M11) -> 50.31
A12: Travel-Airline | B12: =SUMIFS('Transaction Details 2025'!$E$8:$E$331,'Transaction Details 2025'!$J$8:$J$331,$A12,'Transaction Details 2025'!$I$8:$I$331,B$4) -> 438.48 | C12: =SUMIFS('Transaction Details 2025'!$E$8:$E$331,'Transaction Details 2025'!$J$8:$J$331,$A12,'Transaction Details 2025'!$I$8:$I$331,C$4) -> 705.48 | D12: =SUMIFS('Transaction Details 2025'!$E$8:$E$331,'Transaction Details 2025'!$J$8:$J$331,$A12,'Transaction Details 2025'!$I$8:$I$331,D$4) -> 0 | E12: =SUMIFS('Transaction Details 2025'!$E$8:$E$331,'Transaction Details 2025'!$J$8:$J$331,$A12,'Transaction Details 2025'!$I$8:$I$331,E$4) -> 0 | F12: =SUMIFS('Transaction Details 2025'!$E$8:$E$331,'Transaction Details 2025'!$J$8:$J$331,$A12,'Transaction Details 2025'!$I$8:$I$331,F$4) -> 0 | G12: =SUMIFS('Transaction Details 2025'!$E$8:$E$331,'Transaction Details 2025'!$J$8:$J$331,$A12,'Transaction Details 2025'!$I$8:$I$331,G$4) -> 0 | H12: =SUMIFS('Transaction Details 2025'!$E$8:$E$331,'Transaction Details 2025'!$J$8:$J$331,$A12,'Transaction Details 2025'!$I$8:$I$331,H$4) -> 0 | I12: =SUMIFS('Transaction Details 2025'!$E$8:$E$331,'Transaction Details 2025'!$J$8:$J$331,$A12,'Transaction Details 2025'!$I$8:$I$331,I$4) -> 0 | ... M12: =SUMIFS('Transaction Details 2025'!$E$8:$E$331,'Transaction Details 2025'!$J$8:$J$331,$A12,'Transaction Details 2025'!$I$8:$I$331,M$4) -> 0 | N12: =SUM(B12:M12) -> 1143.96
A13: Family | B13: =SUMIFS('Transaction Details 2025'!$E$8:$E$331,'Transaction Details 2025'!$J$8:$J$331,$A13,'Transaction Details 2025'!$I$8:$I$331,B$4) -> 22.99 | C13: =SUMIFS('Transaction Details 2025'!$E$8:$E$331,'Transaction Details 2025'!$J$8:$J$331,$A13,'Transaction Details 2025'!$I$8:$I$331,C$4) -> 22.99 | D13: =SUMIFS('Transaction Details 2025'!$E$8:$E$331,'Transaction Details 2025'!$J$8:$J$331,$A13,'Transaction Details 2025'!$I$8:$I$331,D$4) -> 24.99 | E13: =SUMIFS('Transaction Details 2025'!$E$8:$E$331,'Transaction Details 2025'!$J$8:$J$331,$A13,'Transaction Details 2025'!$I$8:$I$331,E$4) -> 31.98 | F13: =SUMIFS('Transaction Details 2025'!$E$8:$E$331,'Transaction Details 2025'!$J$8:$J$331,$A13,'Transaction Details 2025'!$I$8:$I$331,F$4) -> 24.99 | G13: =SUMIFS('Transaction Details 2025'!$E$8:$E$331,'Transaction Details 2025'!$J$8:$J$331,$A13,'Transaction Details 2025'!$I$8:$I$331,G$4) -> 24.99 | H13: =SUMIFS('Transaction Details 2025'!$E$8:$E$331,'Transaction Details 2025'!$J$8:$J$331,$A13,'Transaction Details 2025'!$I$8:$I$331,H$4) -> 24.99 | I13: =SUMIFS('Transaction Details 2025'!$E$8:$E$331,'Transaction Details 2025'!$J$8:$J$331,$A13,'Transaction Details 2025'!$I$8:$I$331,I$4) -> 24.99 | ... M13: =SUMIFS('Transaction Details 2025'!$E$8:$E$331,'Transaction Details 2025'!$J$8:$J$331,$A13,'Transaction Details 2025'!$I$8:$I$331,M$4) -> 24.99 | N13: =SUM(B13:M13) -> 302.87
A14: Personal - Health | B14: =SUMIFS('Transaction Details 2025'!$E$8:$E$331,'Transaction Details 2025'!$J$8:$J$331,$A14,'Transaction Details 2025'!$I$8:$I$331,B$4) -> 28.5 | C14: =SUMIFS('Transaction Details 2025'!$E$8:$E$331,'Transaction Details 2025'!$J$8:$J$331,$A14,'Transaction Details 2025'!$I$8:$I$331,C$4) -> 0 | D14: =SUMIFS('Transaction Details 2025'!$E$8:$E$331,'Transaction Details 2025'!$J$8:$J$331,$A14,'Transaction Details 2025'!$I$8:$I$331,D$4) -> 0 | E14: =SUMIFS('Transaction Details 2025'!$E$8:$E$331,'Transaction Details 2025'!$J$8:$J$331,$A14,'Transaction Details 2025'!$I$8:$I$331,E$4) -> 0 | F14: =SUMIFS('Transaction Details 2025'!$E$8:$E$331,'Transaction Details 2025'!$J$8:$J$331,$A14,'Transaction Details 2025'!$I$8:$I$331,F$4) -> 0 | G14: =SUMIFS('Transaction Details 2025'!$E$8:$E$331,'Transaction Details 2025'!$J$8:$J$331,$A14,'Transaction Details 2025'!$I$8:$I$331,G$4) -> 0 | H14: =SUMIFS('Transaction Details 2025'!$E$8:$E$331,'Transaction Details 2025'!$J$8:$J$331,$A14,'Transaction Details 2025'!$I$8:$I$331,H$4) -> 0 | I14: =SUMIFS('Transaction Details 2025'!$E$8:$E$331,'Transaction Details 2025'!$J$8:$J$331,$A14,'Transaction Details 2025'!$I$8:$I$331,I$4) -> 0 | ... M14: =SUMIFS('Transaction Details 2025'!$E$8:$E$331,'Transaction Details 2025'!$J$8:$J$331,$A14,'Transaction Details 2025'!$I$8:$I$331,M$4) -> 0 | N14: =SUM(B14:M14) -> 280.44
A15: Personal - Car | B15: =SUMIFS('Transaction Details 2025'!$E$8:$E$331,'Transaction Details 2025'!$J$8:$J$331,$A15,'Transaction Details 2025'!$I$8:$I$331,B$4) -> 62.8 | C15: =SUMIFS('Transaction Details 2025'!$E$8:$E$331,'Transaction Details 2025'!$J$8:$J$331,$A15,'Transaction Details 2025'!$I$8:$I$331,C$4) -> 0 | D15: =SUMIFS('Transaction Details 2025'!$E$8:$E$331,'Transaction Details 2025'!$J$8:$J$331,$A15,'Transaction Details 2025'!$I$8:$I$331,D$4) -> 0 | E15: =SUMIFS('Transaction Details 2025'!$E$8:$E$331,'Transaction Details 2025'!$J$8:$J$331,$A15,'Transaction Details 2025'!$I$8:$I$331,E$4) -> 0 | F15: =SUMIFS('Transaction Details 2025'!$E$8:$E$331,'Transaction Details 2025'!$J$8:$J$331,$A15,'Transaction Details 2025'!$I$8:$I$331,F$4) -> 0 | G15: =SUMIFS('Transaction Details 2025'!$E$8:$E$331,'Transaction Details 2025'!$J$8:$J$331,$A15,'Transaction Details 2025'!$I$8:$I$331,G$4) -> 0 | H15: =SUMIFS('Transaction Details 2025'!$E$8:$E$331,'Transaction Details 2025'!$J$8:$J$331,$A15,'Transaction Details 2025'!$I$8:$I$331,H$4) -> 0 | I15: =SUMIFS('Transaction Details 2025'!$E$8:$E$331,'Transaction Details 2025'!$J$8:$J$331,$A15,'Transaction Details 2025'!$I$8:$I$331,I$4) -> 0 | ... M15: =SUMIFS('Transaction Details 2025'!$E$8:$E$331,'Transaction Details 2025'!$J$8:$J$331,$A15,'Transaction Details 2025'!$I$8:$I$331,M$4) -> 0 | N15: =SUM(B15:M15) -> 62.8
A16: Personal | B16: =SUMIFS('Transaction Details 2025'!$E$8:$E$331,'Transaction Details 2025'!$J$8:$J$331,$A16,'Transaction Details 2025'!$I$8:$I$331,B$4) -> 591.26 | C16: =SUMIFS('Transaction Details 2025'!$E$8:$E$331,'Transaction Details 2025'!$J$8:$J$331,$A16,'Transaction Details 2025'!$I$8:$I$331,C$4) -> 0 | D16: =SUMIFS('Transaction Details 2025'!$E$8:$E$331,'Transaction Details 2025'!$J$8:$J$331,$A16,'Transaction Details 2025'!$I$8:$I$331,D$4) -> 0 | E16: =SUMIFS('Transaction Details 2025'!$E$8:$E$331,'Transaction Details 2025'!$J$8:$J$331,$A16,'Transaction Details 2025'!$I$8:$I$331,E$4) -> 0 | F16: =SUMIFS('Transaction Details 2025'!$E$8:$E$331,'Transaction Details 2025'!$J$8:$J$331,$A16,'Transaction Details 2025'!$I$8:$I$331,F$4) -> 0 | G16: =SUMIFS('Transaction Details 2025'!$E$8:$E$331,'Transaction Details 2025'!$J$8:$J$331,$A16,'Transaction Details 2025'!$I$8:$I$331,G$4) -> 0 | H16: =SUMIFS('Transaction Details 2025'!$E$8:$E$331,'Transaction Details 2025'!$J$8:$J$331,$A16,'Transaction Details 2025'!$I$8:$I$331,H$4) -> 0 | I16: =SUMIFS('Transaction Details 2025'!$E$8:$E$331,'Transaction Details 2025'!$J$8:$J$331,$A16,'Transaction Details 2025'!$I$8:$I$331,I$4) -> 0 | ... M16: =SUMIFS('Transaction Details 2025'!$E$8:$E$331,'Transaction Details 2025'!$J$8:$J$331,$A16,'Transaction Details 2025'!$I$8:$I$331,M$4) -> 0 | N16: =SUM(B16:M16) -> 591.26
... A22: Online AMEX Payment | B22: =SUMIFS('Transaction Details 2025'!$E$8:$E$331,'Transaction Details 2025'!$J$8:$J$331,$A22,'Transaction Details 2025'!$I$8:$I$331,B$4) -> -4930.5 | C22: =SUMIFS('Transaction Details 2025'!$E$8:$E$331,'Transaction Details 2025'!$J$8:$J$331,$A22,'Transaction Details 2025'!$I$8:$I$331,C$4) -> -1853.08 | D22: =SUMIFS('Transaction Details 2025'!$E$8:$E$331,'Transaction Details 2025'!$J$8:$J$331,$A22,'Transaction Details 2025'!$I$8:$I$331,D$4) -> -1982.28 | E22: =SUMIFS('Transaction Details 2025'!$E$8:$E$331,'Transaction Details 2025'!$J$8:$J$331,$A22,'Transaction Details 2025'!$I$8:$I$331,E$4) -> -2222.92 | F22: =SUMIFS('Transaction Details 2025'!$E$8:$E$331,'Transaction Details 2025'!$J$8:$J$331,$A22,'Transaction Details 2025'!$I$8:$I$331,F$4) -> -1542.61 | G22: =SUMIFS('Transaction Details 2025'!$E$8:$E$331,'Transaction Details 2025'!$J$8:$J$331,$A22,'Transaction Details 2025'!$I$8:$I$331,G$4) -> -12616.91 | H22: =SUMIFS('Transaction Details 2025'!$E$8:$E$331,'Transaction Details 2025'!$J$8:$J$331,$A22,'Transaction Details 2025'!$I$8:$I$331,H$4) -> -1373.57 | I22: =SUMIFS('Transaction Details 2025'!$E$8:$E$331,'Transaction Details 2025'!$J$8:$J$331,$A22,'Transaction Details 2025'!$I$8:$I$331,I$4) -> -1935.03 | ... M22: =SUMIFS('Transaction Details 2025'!$E$8:$E$331,'Transaction Details 2025'!$J$8:$J$331,$A22,'Transaction Details 2025'!$I$8:$I$331,M$4) -> -1625.86 | N22: =SUM(B22:M22) -> -33765.13
A24: Total Charges | B24: =SUMIFS('Transaction Details 2025'!$E$8:$E$331,'Transaction Details 2025'!$I$8:$I$331,B$4,'Transaction Details 2025'!$E$8:$E$331,">0") -> 5242.75 | C24: =SUMIFS('Transaction Details 2025'!$E$8:$E$331,'Transaction Details 2025'!$I$8:$I$331,C$4,'Transaction Details 2025'!$E$8:$E$331,">0") -> 2796.12 | D24: =SUMIFS('Transaction Details 2025'!$E$8:$E$331,'Transaction Details 2025'!$I$8:$I$331,D$4,'Transaction Details 2025'!$E$8:$E$331,">0") -> 2046.88 | E24: =SUMIFS('Transaction Details 2025'!$E$8:$E$331,'Transaction Details 2025'!$I$8:$I$331,E$4,'Transaction Details 2025'!$E$8:$E$331,">0") -> 2110.8 | F24: =SUMIFS('Transaction Details 2025'!$E$8:$E$331,'Transaction Details 2025'!$I$8:$I$331,F$4,'Transaction Details 2025'!$E$8:$E$331,">0") -> 12482.35 | G24: =SUMIFS('Transaction Details 2025'!$E$8:$E$331,'Transaction Details 2025'!$I$8:$I$331,G$4,'Transaction Details 2025'!$E$8:$E$331,">0") -> 1737.73 | H24: =SUMIFS('Transaction Details 2025'!$E$8:$E$331,'Transaction Details 2025'!$I$8:$I$331,H$4,'Transaction Details 2025'!$E$8:$E$331,">0") -> 1632.17 | I24: =SUMIFS('Transaction Details 2025'!$E$8:$E$331,'Transaction Details 2025'!$I$8:$I$331,I$4,'Transaction Details 2025'!$E$8:$E$331,">0") -> 1493.06 | ... M24: =SUMIFS('Transaction Details 2025'!$E$8:$E$331,'Transaction Details 2025'!$I$8:$I$331,M$4,'Transaction Details 2025'!$E$8:$E$331,">0") -> 1737.42 | N24: =SUM(B24:M24) -> 35067.32
A25: Total Credits & Payments | B25: =SUMIFS('Transaction Details 2025'!$E$8:$E$331,'Transaction Details 2025'!$I$8:$I$331,B$4,'Transaction Details 2025'!$E$8:$E$331,"<0") -> -5429.5 | C25: =SUMIFS('Transaction Details 2025'!$E$8:$E$331,'Transaction Details 2025'!$I$8:$I$331,C$4,'Transaction Details 2025'!$E$8:$E$331,"<0") -> -3171.33 | D25: =SUMIFS('Transaction Details 2025'!$E$8:$E$331,'Transaction Details 2025'!$I$8:$I$331,D$4,'Transaction Details 2025'!$E$8:$E$331,"<0") -> -2132.01 | E25: =SUMIFS('Transaction Details 2025'!$E$8:$E$331,'Transaction Details 2025'!$I$8:$I$331,E$4,'Transaction Details 2025'!$E$8:$E$331,"<0") -> -2241.85 | F25: =SUMIFS('Transaction Details 2025'!$E$8:$E$331,'Transaction Details 2025'!$I$8:$I$331,F$4,'Transaction Details 2025'!$E$8:$E$331,"<0") -> -1542.61 | G25: =SUMIFS('Transaction Details 2025'!$E$8:$E$331,'Transaction Details 2025'!$I$8:$I$331,G$4,'Transaction Details 2025'!$E$8:$E$331,"<0") -> -12616.91 | H25: =SUMIFS('Transaction Details 2025'!$E$8:$E$331,'Transaction Details 2025'!$I$8:$I$331,H$4,'Transaction Details 2025'!$E$8:$E$331,"<0") -> -1373.57 | I25: =SUMIFS('Transaction Details 2025'!$E$8:$E$331,'Transaction Details 2025'!$I$8:$I$331,I$4,'Transaction Details 2025'!$E$8:$E$331,"<0") -> -2055.22 | ... M25: =SUMIFS('Transaction Details 2025'!$E$8:$E$331,'Transaction Details 2025'!$I$8:$I$331,M$4,'Transaction Details 2025'!$E$8:$E$331,"<0") -> -1625.86 | N25: =SUM(B25:M25) -> -35902.93
A26: Net | B26: =B24+B25 -> -186.75 | C26: =C24+C25 -> -375.21 | D26: =D24+D25 -> -85.13 | E26: =E24+E25 -> -131.05 | F26: =F24+F25 -> 10939.74 | G26: =G24+G25 -> -10879.18 | H26: =H24+H25 -> 258.6 | I26: =I24+I25 -> -562.16 | ... M26: =M24+M25 -> 111.56 | N26: =SUM(B26:M26) -> -835.61
A28: =IF(ROUND(N26-'Transaction Summary 2025'!B11,2)=0,"✓ Net ties to Transaction Summary 2025","⚠ mismatch") -> ✓ Net ties to Transaction Summary 2025

Sheet Transaction Details 2025
A1: FAMILY AMEX | B1: Platinum Card® / Jan 01, 2025 to Dec 31, 2025
A2: Prepared for
A3: JOHN DUNNING
A4: Account Number
A5: XXXX-XXXXXX-43006
A7: Date | B7: Description | C7: Card Member | D7: Account # | E7: Amount | F7: Extended Details | G7: Appears On Your Statement As | H7: Category | I7: Month | J7: Category (clean)
A8: 12/30/2025 | B8: PAYPAL *CANVA 416131887 DE | C8: AVA PEREZ | D8: -46025 | E8: 15 | F8: 10199647970 416131887 PAYPAL *CANVA 416131887 DE Description : OEM SOFTWARE Price : 0.00 416131887 | G8: PAYPAL *CANVA 416131887 DE | H8: Merchandise & Supplies-Computer Supplies | I8: =DATE(RIGHT(A8,4)+0,LEFT(A8,2)+0,1) -> 45992 | J8: =IF(C8="JOHN DUNNING",IF(TRIM(H8)="",IF(ISNUMBER(SEARCH("PAYMENT",B8)),"Online AMEX Payment","(Uncategorized)"),TRIM(H8)),C8) -> AVA PEREZ
A9: 12/22/2025 | B9: PAYPAL *RESUME IO RE767110326 NL | C9: AVA PEREZ | D9: -46025 | E9: 26.86 | F9: 10199031816 767110326 19.95 UNITED KINGDOM POUND STERLING CONVE PAYPAL *RESUME IO RESUME. 767110326 NL Description : HIRING SERVICES Price : 0.00 767110326Foreign Spend Amount: 19.95 UNITED KINGDOM POUND STERLING Commission Amount: Currency Exchange Rate: null | G9: PAYPAL *RESUME IO RE767110326 NL | H9: Business Services-Employment Agencies | I9: =DATE(RIGHT(A9,4)+0,LEFT(A9,2)+0,1) -> 45992 | J9: =IF(C9="JOHN DUNNING",IF(TRIM(H9)="",IF(ISNUMBER(SEARCH("PAYMENT",B9)),"Online AMEX Payment","(Uncategorized)"),TRIM(H9)),C9) -> AVA PEREZ
A10: 12/21/2025 | B10: PAYPAL *PDFNET 4029357733 CA | C10: AVA PEREZ | D10: -46025 | E10: 1.95 | F10: 10198961903 4029357733 PAYPAL *PDFNET 4029357733 CA Description : DIGITAL APPLICATION Price : 0.00 4029357733 | G10: PAYPAL *PDFNET 4029357733 CA | H10: Merchandise & Supplies-Internet Purchase | I10: =DATE(RIGHT(A10,4)+0,LEFT(A10,2)+0,1) -> 45992 | J10: =IF(C10="JOHN DUNNING",IF(TRIM(H10)="",IF(ISNUMBER(SEARCH("PAYMENT",B10)),"Online AMEX Payment","(Uncategorized)"),TRIM(H10)),C10) -> AVA PEREZ
A11: 12/19/2025 | B11: ADOBE SYSTEMS Adobe SAN JOSE CA | C11: JOHN DUNNING | D11: -43006 | E11: 69.99 | F11: 538929008 www.adobe.com ADOBE SYSTEMS Adobe Systems SAN JOSE CA Description : DEFAULT Price : 0.6999 www.adobe.com | G11: ADOBE SYSTEMS Adobe SAN JOSE CA | H11: DWG-RE Platform (Redirected) | I11: =DATE(RIGHT(A11,4)+0,LEFT(A11,2)+0,1) -> 45992 | J11: =IF(C11="JOHN DUNNING",IF(TRIM(H11)="",IF(ISNUMBER(SEARCH("PAYMENT",B11)),"Online AMEX Payment","(Uncategorized)"),TRIM(H11)),C11) -> DWG-RE Platform (Redirected)
A12: 12/19/2025 | B12: MICROSOFT*MICROSOFT MSBILL.INFO WA | C12: JOHN DUNNING | D12: -43006 | E12: 12.99 | F12: Z72YHGRFAFM MSBILL.INFO MICROSOFT*MICROSOFT 365 F MSBILL.INFO WA MSBILL.INFO | G12: MICROSOFT*MICROSOFT MSBILL.INFO WA | H12: DWG-RE Platform (Redirected) | I12: =DATE(RIGHT(A12,4)+0,LEFT(A12,2)+0,1) -> 45992 | J12: =IF(C12="JOHN DUNNING",IF(TRIM(H12)="",IF(ISNUMBER(SEARCH("PAYMENT",B12)),"Online AMEX Payment","(Uncategorized)"),TRIM(H12)),C12) -> DWG-RE Platform (Redirected)
A13: 12/18/2025 | B13: ONLINE PAYMENT - THANK YOU | C13: JOHN DUNNING | D13: -43006 | E13: -1625.86 | F13: ONLINE PAYMENT - THANK YOU | G13: ONLINE PAYMENT - THANK YOU | H13: Online AMEX Payment | I13: =DATE(RIGHT(A13,4)+0,LEFT(A13,2)+0,1) -> 45992 | J13: =IF(C13="JOHN DUNNING",IF(TRIM(H13)="",IF(ISNUMBER(SEARCH("PAYMENT",B13)),"Online AMEX Payment","(Uncategorized)"),TRIM(H13)),C13) -> Online AMEX Payment
A14: 12/16/2025 | B14: LASTPASS.COM BOSTON MA | C14: JOHN DUNNING | D14: -43006 | E14: 48 | F14: 40466747QJ6 SAAS LASTPASS.COM BOSTON MA SAAS | G14: LASTPASS.COM BOSTON MA | H14: DWG-RE Platform (Canceled) | I14: =DATE(RIGHT(A14,4)+0,LEFT(A14,2)+0,1) -> 45992 | J14: =IF(C14="JOHN DUNNING",IF(TRIM(H14)="",IF(ISNUMBER(SEARCH("PAYMENT",B14)),"Online AMEX Payment","(Uncategorized)"),TRIM(H14)),C14) -> DWG-RE Platform (Canceled)
A15: 12/16/2025 | B15: NETFLIX.COM 866-579-7172 CA | C15: JOHN DUNNING | D15: -43006 | E15: 24.99 | F15: 57053627809 NETFLIX.COM NETFLIX.COM 866-579-7172 CA NETFLIX.COM | G15: NETFLIX.COM 866-579-7172 CA | H15: Family | I15: =DATE(RIGHT(A15,4)+0,LEFT(A15,2)+0,1) -> 45992 | J15: =IF(C15="JOHN DUNNING",IF(TRIM(H15)="",IF(ISNUMBER(SEARCH("PAYMENT",B15)),"Online AMEX Payment","(Uncategorized)"),TRIM(H15)),C15) -> Family
A16: 12/11/2025 | B16: PAYPAL *APPLE.COM/BI8002752273 CA | C16: AVA PEREZ | D16: -46025 | E16: 19.99 | F16: 10198043274 8002752273 PAYPAL *APPLE.COM/BILL 8002752273 CA Description : MUSIC Price : 0.00 8002752273 | G16: PAYPAL *APPLE.COM/BI8002752273 CA | H16: Merchandise & Supplies-Music & Video | I16: =DATE(RIGHT(A16,4)+0,LEFT(A16,2)+0,1) -> 45992 | J16: =IF(C16="JOHN DUNNING",IF(TRIM(H16)="",IF(ISNUMBER(SEARCH("PAYMENT",B16)),"Online AMEX Payment","(Uncategorized)"),TRIM(H16)),C16) -> AVA PEREZ
A17: 12/11/2025 | B17: PAYPAL *SOUNDLY 93294327 NO | C17: AVA PEREZ | D17: -46025 | E17: 14.99 | F17: 10198006277 93294327 PAYPAL *SOUNDLY 93294327 NO Description : DIGITAL APPLICATION Price : 0.00 93294327 | G17: PAYPAL *SOUNDLY 93294327 NO | H17: Business Services-Internet Services | I17: =DATE(RIGHT(A17,4)+0,LEFT(A17,2)+0,1) -> 45992 | J17: =IF(C17="JOHN DUNNING",IF(TRIM(H17)="",IF(ISNUMBER(SEARCH("PAYMENT",B17)),"Online AMEX Payment","(Uncategorized)"),TRIM(H17)),C17) -> AVA PEREZ
A18: 12/10/2025 | B18: PAYPAL *SPOTIFY*P3D42033189708 NY | C18: AVA PEREZ | D18: -46025 | E18: 11.99 | F18: 10197958977 2033189708 PAYPAL *SPOTIFY*P3D4B816E 2033189708 NY Description : GENERAL Price : 0.00 2033189708 | G18: PAYPAL *SPOTIFY*P3D42033189708 NY | H18: Communications-Other Telecom | I18: =DATE(RIGHT(A18,4)+0,LEFT(A18,2)+0,1) -> 45992 | J18: =IF(C18="JOHN DUNNING",IF(TRIM(H18)="",IF(ISNUMBER(SEARCH("PAYMENT",B18)),"Online AMEX Payment","(Uncategorized)"),TRIM(H18)),C18) -> AVA PEREZ
A19: 12/08/2025 | B19: PAYPAL *ETSY INC 4029357733 NY | C19: AVA PEREZ | D19: -46025 | E19: 131.7 | F19: 10197746553 4029357733 PAYPAL *ETSY INC 4029357733 NY Description : MISC. GENERAL MERCH Price : 0.00 4029357733 | G19: PAYPAL *ETSY INC 4029357733 NY | H19: Merchandise & Supplies-General Retail | I19: =DATE(RIGHT(A19,4)+0,LEFT(A19,2)+0,1) -> 45992 | J19: =IF(C19="JOHN DUNNING",IF(TRIM(H19)="",IF(ISNUMBER(SEARCH("PAYMENT",B19)),"Online AMEX Payment","(Uncategorized)"),TRIM(H19)),C19) -> AVA PEREZ
... A135: 07/19/2025 | B135: PAYPAL *ETSY INC 4029357733 NY | C135: AVA PEREZ | D135: -46025 | E135: 45.68 | F135: 10185688675 4029357733 PAYPAL *ETSY INC 4029357733 NY Description : MISC. GENERAL MERCH Price : 0.00 4029357733 | G135: PAYPAL *ETSY INC 4029357733 NY | H135: Merchandise & Supplies-General Retail | I135: =DATE(RIGHT(A135,4)+0,LEFT(A135,2)+0,1) -> 45839 | J135: =IF(C135="JOHN DUNNING",IF(TRIM(H135)="",IF(ISNUMBER(SEARCH("PAYMENT",B135)),"Online AMEX Payment","(Uncategorized)"),TRIM(H135)),C135) -> AVA PEREZ
A136: 07/17/2025 | B136: ONLINE PAYMENT - THANK YOU | C136: JOHN DUNNING | D136: -43006 | E136: -1373.57 | F136: ONLINE PAYMENT - THANK YOU | G136: ONLINE PAYMENT - THANK YOU | I136: =DATE(RIGHT(A136,4)+0,LEFT(A136,2)+0,1) -> 45839 | J136: =IF(C136="JOHN DUNNING",IF(TRIM(H136)="",IF(ISNUMBER(SEARCH("PAYMENT",B136)),"Online AMEX Payment","(Uncategorized)"),TRIM(H136)),C136) -> Online AMEX Payment
A137: 07/16/2025 | B137: NETFLIX.COM 866-579-7172 CA | C137: JOHN DUNNING | D137: -43006 | E137: 24.99 | F137: 50121674982 CABLE & PAY TV NETFLIX.COM 866-579-7172 CA CABLE & PAY TV | G137: NETFLIX.COM 866-579-7172 CA | H137: Family | I137: =DATE(RIGHT(A137,4)+0,LEFT(A137,2)+0,1) -> 45839 | J137: =IF(C137="JOHN DUNNING",IF(TRIM(H137)="",IF(ISNUMBER(SEARCH("PAYMENT",B137)),"Online AMEX Payment","(Uncategorized)"),TRIM(H137)),C137) -> Family
A138: 07/15/2025 | B138: PAYPAL *ETSY INC 4029357733 NY | C138: AVA PEREZ | D138: -46025 | E138: 15.33 | F138: 10185361380 4029357733 PAYPAL *ETSY INC 4029357733 NY Description : MISC. GENERAL MERCH Price : 0.00 4029357733 | G138: PAYPAL *ETSY INC 4029357733 NY | H138: Merchandise & Supplies-General Retail | I138: =DATE(RIGHT(A138,4)+0,LEFT(A138,2)+0,1) -> 45839 | J138: =IF(C138="JOHN DUNNING",IF(TRIM(H138)="",IF(ISNUMBER(SEARCH("PAYMENT",B138)),"Online AMEX Payment","(Uncategorized)"),TRIM(H138)),C138) -> AVA PEREZ
A139: 07/13/2025 | B139: PAYPAL *BLACKMOONCO 8182632784 CA | C139: AVA PEREZ | D139: -46025 | E139: 88.51 | F139: 10185171014 8182632784 PAYPAL *BLACKMOONCO 8182632784 CA Description : COSMETIC STORES Price : 0.00 8182632784 | G139: PAYPAL *BLACKMOONCO 8182632784 CA | H139: Merchandise & Supplies-Department Stores | I139: =DATE(RIGHT(A139,4)+0,LEFT(A139,2)+0,1) -> 45839 | J139: =IF(C139="JOHN DUNNING",IF(TRIM(H139)="",IF(ISNUMBER(SEARCH("PAYMENT",B139)),"Online AMEX Payment","(Uncategorized)"),TRIM(H139)),C139) -> AVA PEREZ
A140: 07/13/2025 | B140: PAYPAL *EBAY 800-4564029357733 CA | C140: AVA PEREZ | D140: -46025 | E140: 41.05 | F140: 10185175818 4029357733 PAYPAL *EBAY 800-456-3229 4029357733 CA Description : VARIETY STORE Price : 0.00 4029357733 | G140: PAYPAL *EBAY 800-4564029357733 CA | H140: Merchandise & Supplies-General Retail | I140: =DATE(RIGHT(A140,4)+0,LEFT(A140,2)+0,1) -> 45839 | J140: =IF(C140="JOHN DUNNING",IF(TRIM(H140)="",IF(ISNUMBER(SEARCH("PAYMENT",B140)),"Online AMEX Payment","(Uncategorized)"),TRIM(H140)),C140) -> AVA PEREZ
A141: 07/13/2025 | B141: PAYPAL *ETSY INC 4029357733 NY | C141: AVA PEREZ | D141: -46025 | E141: 27.9 | F141: 10185130567 4029357733 PAYPAL *ETSY INC 4029357733 NY Description : MISC. GENERAL MERCH Price : 0.00 4029357733 | G141: PAYPAL *ETSY INC 4029357733 NY | H141: Merchandise & Supplies-General Retail | I141: =DATE(RIGHT(A141,4)+0,LEFT(A141,2)+0,1) -> 45839 | J141: =IF(C141="JOHN DUNNING",IF(TRIM(H141)="",IF(ISNUMBER(SEARCH("PAYMENT",B141)),"Online AMEX Payment","(Uncategorized)"),TRIM(H141)),C141) -> AVA PEREZ
A142: 07/13/2025 | B142: PAYPAL *POSHMARK 6502624771 CA | C142: AVA PEREZ | D142: -46025 | E142: 30.1 | F142: 10185169366 6502624771 PAYPAL *POSHMARK 6502624771 CA Description : USED AND SECONDHAND Price : 0.00 6502624771 | G142: PAYPAL *POSHMARK 6502624771 CA | H142: Merchandise & Supplies-General Retail | I142: =DATE(RIGHT(A142,4)+0,LEFT(A142,2)+0,1) -> 45839 | J142: =IF(C142="JOHN DUNNING",IF(TRIM(H142)="",IF(ISNUMBER(SEARCH("PAYMENT",B142)),"Online AMEX Payment","(Uncategorized)"),TRIM(H142)),C142) -> AVA PEREZ
A143: 07/12/2025 | B143: GRAMMARLY.COM (888)3SAN FRANCISCO CA | C143: ANGELA L DUNNING | D143: -46017 | E143: 60 | F143: H6RGDBQ3 89825994 94104 GRAMMARLY.COM (888)318-6146 SAN FRANCISCO CA 89825994 94104 | G143: GRAMMARLY.COM (888)3SAN FRANCISCO CA | H143: Merchandise & Supplies-Internet Purchase | I143: =DATE(RIGHT(A143,4)+0,LEFT(A143,2)+0,1) -> 45839 | J143: =IF(C143="JOHN DUNNING",IF(TRIM(H143)="",IF(ISNUMBER(SEARCH("PAYMENT",B143)),"Online AMEX Payment","(Uncategorized)"),TRIM(H143)),C143) -> ANGELA L DUNNING
A144: 07/12/2025 | B144: PAYPAL *EBAY 800-4564029357733 CA | C144: AVA PEREZ | D144: -46025 | E144: 35.56 | F144: 10185064346 4029357733 PAYPAL *EBAY 800-456-3229 4029357733 CA Description : VARIETY STORE Price : 0.00 4029357733 | G144: PAYPAL *EBAY 800-4564029357733 CA | H144: Merchandise & Supplies-General Retail | I144: =DATE(RIGHT(A144,4)+0,LEFT(A144,2)+0,1) -> 45839 | J144: =IF(C144="JOHN DUNNING",IF(TRIM(H144)="",IF(ISNUMBER(SEARCH("PAYMENT",B144)),"Online AMEX Payment","(Uncategorized)"),TRIM(H144)),C144) -> AVA PEREZ
A145: 07/12/2025 | B145: PAYPAL *EBAY 800-4564029357733 CA | C145: AVA PEREZ | D145: -46025 | E145: 40.11 | F145: 10185127784 4029357733 PAYPAL *EBAY 800-456-3229 4029357733 CA Description : VARIETY STORE Price : 0.00 4029357733 | G145: PAYPAL *EBAY 800-4564029357733 CA | H145: Merchandise & Supplies-General Retail | I145: =DATE(RIGHT(A145,4)+0,LEFT(A145,2)+0,1) -> 45839 | J145: =IF(C145="JOHN DUNNING",IF(TRIM(H145)="",IF(ISNUMBER(SEARCH("PAYMENT",B145)),"Online AMEX Payment","(Uncategorized)"),TRIM(H145)),C145) -> AVA PEREZ
A146: 07/11/2025 | B146: PAYPAL *APPLE.COM/BI8002752273 CA | C146: AVA PEREZ | D146: -46025 | E146: 19.99 | F146: 10185020027 8002752273 PAYPAL *APPLE.COM/BILL 8002752273 CA Description : MUSIC Price : 0.00 8002752273 | G146: PAYPAL *APPLE.COM/BI8002752273 CA | H146: Merchandise & Supplies-Music & Video | I146: =DATE(RIGHT(A146,4)+0,LEFT(A146,2)+0,1) -> 45839 | J146: =IF(C146="JOHN DUNNING",IF(TRIM(H146)="",IF(ISNUMBER(SEARCH("PAYMENT",B146)),"Online AMEX Payment","(Uncategorized)"),TRIM(H146)),C146) -> AVA PEREZ
A147: 07/11/2025 | B147: PAYPAL *SOUNDLY 93294327 NO | C147: AVA PEREZ | D147: -46025 | E147: 14.99 | F147: 10184992038 93294327 PAYPAL *SOUNDLY 93294327 NO Description : DIGITAL APPLICATION Price : 0.00 93294327 | G147: PAYPAL *SOUNDLY 93294327 NO | H147: Business Services-Internet Services | I147: =DATE(RIGHT(A147,4)+0,LEFT(A147,2)+0,1) -> 45839 | J147: =IF(C147="JOHN DUNNING",IF(TRIM(H147)="",IF(ISNUMBER(SEARCH("PAYMENT",B147)),"Online AMEX Payment","(Uncategorized)"),TRIM(H147)),C147) -> AVA PEREZ
A148: 07/10/2025 | B148: PAYPAL *SPOTIFY*P3872033189708 NY | C148: AVA PEREZ | D148: -46025 | E148: 11.99 | F148: 10184952003 2033189708 PAYPAL *SPOTIFY*P38782D27 2033189708 NY Description : GENERAL Price : 0.00 2033189708 | G148: PAYPAL *SPOTIFY*P3872033189708 NY | H148: Communications-Other Telecom | I148: =DATE(RIGHT(A148,4)+0,LEFT(A148,2)+0,1) -> 45839 | J148: =IF(C148="JOHN DUNNING",IF(TRIM(H148)="",IF(ISNUMBER(SEARCH("PAYMENT",B148)),"Online AMEX Payment","(Uncategorized)"),TRIM(H148)),C148) -> AVA PEREZ
... A191: 05/27/2025 | B191: LIGHTBOX PARENT SHELTON CT | C191: JOHN DUNNING | D191: -43006 | E191: 11124 | F191: 49684083 855-337-5126 LIGHTBOX PARENT SHELTON CT Description : BUSINESS SERVICES Price : 0.00 855-337-5126 | G191: LIGHTBOX PARENT SHELTON CT | H191: DWG-RE Platform (Redirected) | I191: =DATE(RIGHT(A191,4)+0,LEFT(A191,2)+0,1) -> 45778 | J191: =IF(C191="JOHN DUNNING",IF(TRIM(H191)="",IF(ISNUMBER(SEARCH("PAYMENT",B191)),"Online AMEX Payment","(Uncategorized)"),TRIM(H191)),C191) -> DWG-RE Platform (Redirected)
A192: 05/26/2025 | B192: CUSTOMER SERVICE PAYMENT - THANK YOU | C192: JOHN DUNNING | D192: -43006 | E192: -1542.61 | F192: CUSTOMER SERVICE PAYMENT - THANK YOU | G192: CUSTOMER SERVICE PAYMENT - THANK YOU | I192: =DATE(RIGHT(A192,4)+0,LEFT(A192,2)+0,1) -> 45778 | J192: =IF(C192="JOHN DUNNING",IF(TRIM(H192)="",IF(ISNUMBER(SEARCH("PAYMENT",B192)),"Online AMEX Payment","(Uncategorized)"),TRIM(H192)),C192) -> Online AMEX Payment
A193: 05/20/2025 | B193: PAYPAL *APPLE.COM/BI8002752273 CA | C193: AVA PEREZ | D193: -46025 | E193: 2.99 | F193: 10180688282 8002752273 PAYPAL *APPLE.COM/BILL 8002752273 CA Description : MUSIC Price : 0.00 8002752273 | G193: PAYPAL *APPLE.COM/BI8002752273 CA | H193: Merchandise & Supplies-Music & Video | I193: =DATE(RIGHT(A193,4)+0,LEFT(A193,2)+0,1) -> 45778 | J193: =IF(C193="JOHN DUNNING",IF(TRIM(H193)="",IF(ISNUMBER(SEARCH("PAYMENT",B193)),"Online AMEX Payment","(Uncategorized)"),TRIM(H193)),C193) -> AVA PEREZ
A194: 05/19/2025 | B194: ADOBE SYSTEMS Adobe SAN JOSE CA | C194: JOHN DUNNING | D194: -43006 | E194: 59.99 | F194: 585723726 www.adobe.com ADOBE SYSTEMS Adobe Systems SAN JOSE CA Description : 0 Price : 0.5999 www.adobe.com | G194: ADOBE SYSTEMS Adobe SAN JOSE CA | H194: DWG-RE Platform (Redirected) | I194: =DATE(RIGHT(A194,4)+0,LEFT(A194,2)+0,1) -> 45778 | J194: =IF(C194="JOHN DUNNING",IF(TRIM(H194)="",IF(ISNUMBER(SEARCH("PAYMENT",B194)),"Online AMEX Payment","(Uncategorized)"),TRIM(H194)),C194) -> DWG-RE Platform (Redirected)
A195: 05/19/2025 | B195: MICROSOFT MSBILL.INFO | C195: JOHN DUNNING | D195: -43006 | E195: 12.99 | F195: Z72G47RMZ0TZ72G47RMZ0TL 98052 MICROSOFT MSBILL.INFO Z72G47RMZ0TL 98052 | G195: MICROSOFT MSBILL.INFO | H195: DWG-RE Platform (Redirected) | I195: =DATE(RIGHT(A195,4)+0,LEFT(A195,2)+0,1) -> 45778 | J195: =IF(C195="JOHN DUNNING",IF(TRIM(H195)="",IF(ISNUMBER(SEARCH("PAYMENT",B195)),"Online AMEX Payment","(Uncategorized)"),TRIM(H195)),C195) -> DWG-RE Platform (Redirected)
A196: 05/19/2025 | B196: PAYPAL *ETSY INC 4029357733 NY | C196: AVA PEREZ | D196: -46025 | E196: 142.68 | F196: 10180660397 4029357733 PAYPAL *ETSY INC 4029357733 NY Description : MISC. GENERAL MERCH Price : 0.00 4029357733 | G196: PAYPAL *ETSY INC 4029357733 NY | H196: Merchandise & Supplies-General Retail | I196: =DATE(RIGHT(A196,4)+0,LEFT(A196,2)+0,1) -> 45778 | J196: =IF(C196="JOHN DUNNING",IF(TRIM(H196)="",IF(ISNUMBER(SEARCH("PAYMENT",B196)),"Online AMEX Payment","(Uncategorized)"),TRIM(H196)),C196) -> AVA PEREZ
A197: 05/18/2025 | B197: PAYPAL *ETSY INC 4029357733 NY | C197: AVA PEREZ | D197: -46025 | E197: 67.77 | F197: 10180573566 4029357733 PAYPAL *ETSY INC 4029357733 NY Description : MISC. GENERAL MERCH Price : 0.00 4029357733 | G197: PAYPAL *ETSY INC 4029357733 NY | H197: Merchandise & Supplies-General Retail | I197: =DATE(RIGHT(A197,4)+0,LEFT(A197,2)+0,1) -> 45778 | J197: =IF(C197="JOHN DUNNING",IF(TRIM(H197)="",IF(ISNUMBER(SEARCH("PAYMENT",B197)),"Online AMEX Payment","(Uncategorized)"),TRIM(H197)),C197) -> AVA PEREZ
A198: 05/16/2025 | B198: NETFLIX.COM 866-579-7172 CA | C198: JOHN DUNNING | D198: -43006 | E198: 24.99 | F198: 47357647053 CABLE & PAY TV NETFLIX.COM 866-579-7172 CA CABLE & PAY TV | G198: NETFLIX.COM 866-579-7172 CA | H198: Family | I198: =DATE(RIGHT(A198,4)+0,LEFT(A198,2)+0,1) -> 45778 | J198: =IF(C198="JOHN DUNNING",IF(TRIM(H198)="",IF(ISNUMBER(SEARCH("PAYMENT",B198)),"Online AMEX Payment","(Uncategorized)"),TRIM(H198)),C198) -> Family
...

Sheet Transaction Summary 2026
A1: FAMILY AMEX
A2: Amex Platinum | Statement Summary
A4: Account Holder | B4: John Dunning
A5: Account | B5: XXXX-XXXXXX-43006
A6: Statement Period | B6: January 2026 - June 2026
A8: TOTALS
A9: Charges | B9: =SUMIF('Transaction Details 2026'!$E$8:$E$170,">0") -> 10241.82
A10: Credits & Payments | B10: =SUMIF('Transaction Details 2026'!$E$8:$E$170,"<0") -> -7569.81
A11: Net Balance | B11: =B9+B10 -> 2672.01
A13: SPEND BY CATEGORY
A14: Category | B14: Amount | C14: % of Charges
A15: John — Business
A16: DWG-RE Platform (Redirected) | B16: =SUMIFS('Transaction Details 2026'!$E$8:$E$170,'Transaction Details 2026'!$J$8:$J$170,A16) -> 2860.29 | C16: =IFERROR(B16/$B$9,0) -> 0.27927556
A17: Sponsor Cloud | B17: =SUMIFS('Transaction Details 2026'!$E$8:$E$170,'Transaction Details 2026'!$J$8:$J$170,A17) -> 512.87 | C17: =IFERROR(B17/$B$9,0) -> 0.050076061
A18: Subtotal — John Business | B18: =SUM(B16:B17) -> 3373.16 | C18: =IFERROR(B18/$B$9,0) -> 0.32935162
A19: John — Personal / Other
A20: Family | B20: =SUMIFS('Transaction Details 2026'!$E$8:$E$170,'Transaction Details 2026'!$J$8:$J$170,A20) -> 126.95 | C20: =IFERROR(B20/$B$9,0) -> 0.012395258
A21: Personal - Health | B21: =SUMIFS('Transaction Details 2026'!$E$8:$E$170,'Transaction Details 2026'!$J$8:$J$170,A21) -> 827 | C21: =IFERROR(B21/$B$9,0) -> 0.080747367
A22: (Uncategorized) | B22: =SUMIFS('Transaction Details 2026'!$E$8:$E$170,'Transaction Details 2026'!$J$8:$J$170,A22) -> 54 | C22: =IFERROR(B22/$B$9,0) -> 0.0052725004
A23: Subtotal — John Personal | B23: =SUM(B20:B22) -> 1007.95 | C23: =IFERROR(B23/$B$9,0) -> 0.098415125
A24: Other Card Members
A25: Ava Perez | B25: =SUMIFS('Transaction Details 2026'!$E$8:$E$170,'Transaction Details 2026'!$J$8:$J$170,A25) -> 3694.8 | C25: =IFERROR(B25/$B$9,0) -> 0.36075619
A26: Joe Saunders | B26: =SUMIFS('Transaction Details 2026'!$E$8:$E$170,'Transaction Details 2026'!$J$8:$J$170,A26) -> 1976.47 | C26: =IFERROR(B26/$B$9,0) -> 0.19298035
A27: Angela L Dunning | B27: =SUMIFS('Transaction Details 2026'!$E$8:$E$170,'Transaction Details 2026'!$J$8:$J$170,A27) -> 120 | C27: =IFERROR(B27/$B$9,0) -> 0.011716668
A28: Subtotal — Card Members | B28: =SUM(B25:B27) -> 5791.27 | C28: =IFERROR(B28/$B$9,0) -> 0.56545321
A29: Credits & Payments
A30: Online AMEX Payment | B30: =SUMIFS('Transaction Details 2026'!$E$8:$E$170,'Transaction Details 2026'!$J$8:$J$170,A30) -> -7500.37 | C30: =IFERROR(B30/$B$9,0) -> -0.73232785
A31: Subtotal — Credits & Payments | B31: =SUM(B30:B30) -> -7500.37 | C31: =IFERROR(B31/$B$9,0) -> -0.73232785
A32: GRAND TOTAL | B32: =B18+B23+B28+B31 -> 2672.01 | C32: =IFERROR(B32/$B$9,0) -> 0.26089211
A34: SPEND BY MONTH
A35: Month | B35: Charges | C35: Credits | D35: Net
A36: =DATE(2026,1,1) -> 46023 | B36: =SUMIFS('Transaction Details 2026'!$E$8:$E$170,'Transaction Details 2026'!$I$8:$I$170,$A36,'Transaction Details 2026'!$E$8:$E$170,">0") -> 1418.07 | C36: =SUMIFS('Transaction Details 2026'!$E$8:$E$170,'Transaction Details 2026'!$I$8:$I$170,$A36,'Transaction Details 2026'!$E$8:$E$170,"<0") -> -321.79 | D36: =B36+C36 -> 1096.28
A37: =EDATE(A36,1) -> 46054 | B37: =SUMIFS('Transaction Details 2026'!$E$8:$E$170,'Transaction Details 2026'!$I$8:$I$170,$A37,'Transaction Details 2026'!$E$8:$E$170,">0") -> 898.94 | C37: =SUMIFS('Transaction Details 2026'!$E$8:$E$170,'Transaction Details 2026'!$I$8:$I$170,$A37,'Transaction Details 2026'!$E$8:$E$170,"<0") -> -2012.65 | D37: =B37+C37 -> -1113.71 | E37: Net
A38: =EDATE(A37,1) -> 46082 | B38: =SUMIFS('Transaction Details 2026'!$E$8:$E$170,'Transaction Details 2026'!$I$8:$I$170,$A38,'Transaction Details 2026'!$E$8:$E$170,">0") -> 1940.34 | C38: =SUMIFS('Transaction Details 2026'!$E$8:$E$170,'Transaction Details 2026'!$I$8:$I$170,$A38,'Transaction Details 2026'!$E$8:$E$170,"<0") -> -1775.69 | D38: =B38+C38 -> 164.65 | E38: =C38+D38 -> -1611.04
A39: =EDATE(A38,1) -> 46113 | B39: =SUMIFS('Transaction Details 2026'!$E$8:$E$170,'Transaction Details 2026'!$I$8:$I$170,$A39,'Transaction Details 2026'!$E$8:$E$170,">0") -> 3142.58 | C39: =SUMIFS('Transaction Details 2026'!$E$8:$E$170,'Transaction Details 2026'!$I$8:$I$170,$A39,'Transaction Details 2026'!$E$8:$E$170,"<0") -> -443.1 | D39: =B39+C39 -> 2699.48
A40: =EDATE(A39,1) -> 46143 | B40: =SUMIFS('Transaction Details 2026'!$E$8:$E$170,'Transaction Details 2026'!$I$8:$I$170,$A40,'Transaction Details 2026'!$E$8:$E$170,">0") -> 2248.19 | C40: =SUMIFS('Transaction Details 2026'!$E$8:$E$170,'Transaction Details 2026'!$I$8:$I$170,$A40,'Transaction Details 2026'!$E$8:$E$170,"<0") -> -3016.58 | D40: =B40+C40 -> -768.39
A41: =EDATE(A40,1) -> 46174 | B41: =SUMIFS('Transaction Details 2026'!$E$8:$E$170,'Transaction Details 2026'!$I$8:$I$170,$A41,'Transaction Details 2026'!$E$8:$E$170,">0") -> 593.7 | C41: =SUMIFS('Transaction Details 2026'!$E$8:$E$170,'Transaction Details 2026'!$I$8:$I$170,$A41,'Transaction Details 2026'!$E$8:$E$170,"<0") -> 0 | D41: =B41+C41 -> 593.7
A42: Total | B42: =SUM(B36:B41) -> 10241.82 | C42: =SUM(C36:C41) -> -7569.81 | D42: =SUM(D36:D41) -> 2672.01 | F42: =AVERAGE(B36:B41) -> 1706.97
B43: =EDATE(B42,1) -> 10272
A44: SPEND BY CARD MEMBER | B44: Total | C44: =SUM(C38:C43) -> -12805.18 | D44: =SUM(D38:D43) -> 5361.45 | E44: =SUM(E38:E43) -> -1611.04
...

Sheet Monthly Breakdown 2026
A1: FAMILY AMEX
A2: Amex Platinum | Monthly Breakdown
A4: Category | B4: =DATE(2026,1,1) -> 46023 | C4: =EDATE(B4,1) -> 46054 | D4: =EDATE(C4,1) -> 46082 | E4: =EDATE(D4,1) -> 46113 | F4: =EDATE(E4,1) -> 46143 | G4: =EDATE(F4,1) -> 46174 | H4: Total
A5: DWG-RE Platform (Redirected) | B5: =SUMIFS('Transaction Details 2026'!$E$8:$E$170,'Transaction Details 2026'!$J$8:$J$170,$A5,'Transaction Details 2026'!$I$8:$I$170,B$4) -> 373.38 | C5: =SUMIFS('Transaction Details 2026'!$E$8:$E$170,'Transaction Details 2026'!$J$8:$J$170,$A5,'Transaction Details 2026'!$I$8:$I$170,C$4) -> 373.38 | D5: =SUMIFS('Transaction Details 2026'!$E$8:$E$170,'Transaction Details 2026'!$J$8:$J$170,$A5,'Transaction Details 2026'!$I$8:$I$170,D$4) -> 373.38 | E5: =SUMIFS('Transaction Details 2026'!$E$8:$E$170,'Transaction Details 2026'!$J$8:$J$170,$A5,'Transaction Details 2026'!$I$8:$I$170,E$4) -> 1147.37 | F5: =SUMIFS('Transaction Details 2026'!$E$8:$E$170,'Transaction Details 2026'!$J$8:$J$170,$A5,'Transaction Details 2026'!$I$8:$I$170,F$4) -> 373.38 | G5: =SUMIFS('Transaction Details 2026'!$E$8:$E$170,'Transaction Details 2026'!$J$8:$J$170,$A5,'Transaction Details 2026'!$I$8:$I$170,G$4) -> 219.4 | H5: =SUM(B5:G5) -> 2860.29
A6: Sponsor Cloud | B6: =SUMIFS('Transaction Details 2026'!$E$8:$E$170,'Transaction Details 2026'!$J$8:$J$170,$A6,'Transaction Details 2026'!$I$8:$I$170,B$4) -> 0 | C6: =SUMIFS('Transaction Details 2026'!$E$8:$E$170,'Transaction Details 2026'!$J$8:$J$170,$A6,'Transaction Details 2026'!$I$8:$I$170,C$4) -> 0 | D6: =SUMIFS('Transaction Details 2026'!$E$8:$E$170,'Transaction Details 2026'!$J$8:$J$170,$A6,'Transaction Details 2026'!$I$8:$I$170,D$4) -> 0 | E6: =SUMIFS('Transaction Details 2026'!$E$8:$E$170,'Transaction Details 2026'!$J$8:$J$170,$A6,'Transaction Details 2026'!$I$8:$I$170,E$4) -> 423.49 | F6: =SUMIFS('Transaction Details 2026'!$E$8:$E$170,'Transaction Details 2026'!$J$8:$J$170,$A6,'Transaction Details 2026'!$I$8:$I$170,F$4) -> 89.38 | G6: =SUMIFS('Transaction Details 2026'!$E$8:$E$170,'Transaction Details 2026'!$J$8:$J$170,$A6,'Transaction Details 2026'!$I$8:$I$170,G$4) -> 0 | H6: =SUM(B6:G6) -> 512.87
A7: Family | B7: =SUMIFS('Transaction Details 2026'!$E$8:$E$170,'Transaction Details 2026'!$J$8:$J$170,$A7,'Transaction Details 2026'!$I$8:$I$170,B$4) -> 24.99 | C7: =SUMIFS('Transaction Details 2026'!$E$8:$E$170,'Transaction Details 2026'!$J$8:$J$170,$A7,'Transaction Details 2026'!$I$8:$I$170,C$4) -> 24.99 | D7: =SUMIFS('Transaction Details 2026'!$E$8:$E$170,'Transaction Details 2026'!$J$8:$J$170,$A7,'Transaction Details 2026'!$I$8:$I$170,D$4) -> 24.99 | E7: =SUMIFS('Transaction Details 2026'!$E$8:$E$170,'Transaction Details 2026'!$J$8:$J$170,$A7,'Transaction Details 2026'!$I$8:$I$170,E$4) -> 24.99 | F7: =SUMIFS('Transaction Details 2026'!$E$8:$E$170,'Transaction Details 2026'!$J$8:$J$170,$A7,'Transaction Details 2026'!$I$8:$I$170,F$4) -> 26.99 | G7: =SUMIFS('Transaction Details 2026'!$E$8:$E$170,'Transaction Details 2026'!$J$8:$J$170,$A7,'Transaction Details 2026'!$I$8:$I$170,G$4) -> 0 | H7: =SUM(B7:G7) -> 126.95
A8: Personal - Health | B8: =SUMIFS('Transaction Details 2026'!$E$8:$E$170,'Transaction Details 2026'!$J$8:$J$170,$A8,'Transaction Details 2026'!$I$8:$I$170,B$4) -> 0 | C8: =SUMIFS('Transaction Details 2026'!$E$8:$E$170,'Transaction Details 2026'!$J$8:$J$170,$A8,'Transaction Details 2026'!$I$8:$I$170,C$4) -> 0 | D8: =SUMIFS('Transaction Details 2026'!$E$8:$E$170,'Transaction Details 2026'!$J$8:$J$170,$A8,'Transaction Details 2026'!$I$8:$I$170,D$4) -> 230 | E8: =SUMIFS('Transaction Details 2026'!$E$8:$E$170,'Transaction Details 2026'!$J$8:$J$170,$A8,'Transaction Details 2026'!$I$8:$I$170,E$4) -> 199 | F8: =SUMIFS('Transaction Details 2026'!$E$8:$E$170,'Transaction Details 2026'!$J$8:$J$170,$A8,'Transaction Details 2026'!$I$8:$I$170,F$4) -> 398 | G8: =SUMIFS('Transaction Details 2026'!$E$8:$E$170,'Transaction Details 2026'!$J$8:$J$170,$A8,'Transaction Details 2026'!$I$8:$I$170,G$4) -> 0 | H8: =SUM(B8:G8) -> 827
A9: (Uncategorized) | B9: =SUMIFS('Transaction Details 2026'!$E$8:$E$170,'Transaction Details 2026'!$J$8:$J$170,$A9,'Transaction Details 2026'!$I$8:$I$170,B$4) -> 0 | C9: =SUMIFS('Transaction Details 2026'!$E$8:$E$170,'Transaction Details 2026'!$J$8:$J$170,$A9,'Transaction Details 2026'!$I$8:$I$170,C$4) -> 0 | D9: =SUMIFS('Transaction Details 2026'!$E$8:$E$170,'Transaction Details 2026'!$J$8:$J$170,$A9,'Transaction Details 2026'!$I$8:$I$170,D$4) -> 0 | E9: =SUMIFS('Transaction Details 2026'!$E$8:$E$170,'Transaction Details 2026'!$J$8:$J$170,$A9,'Transaction Details 2026'!$I$8:$I$170,E$4) -> 0 | F9: =SUMIFS('Transaction Details 2026'!$E$8:$E$170,'Transaction Details 2026'!$J$8:$J$170,$A9,'Transaction Details 2026'!$I$8:$I$170,F$4) -> 0 | G9: =SUMIFS('Transaction Details 2026'!$E$8:$E$170,'Transaction Details 2026'!$J$8:$J$170,$A9,'Transaction Details 2026'!$I$8:$I$170,G$4) -> 54 | H9: =SUM(B9:G9) -> 54
A10: Ava Perez | B10: =SUMIFS('Transaction Details 2026'!$E$8:$E$170,'Transaction Details 2026'!$J$8:$J$170,$A10,'Transaction Details 2026'!$I$8:$I$170,B$4) -> 959.7 | C10: =SUMIFS('Transaction Details 2026'!$E$8:$E$170,'Transaction Details 2026'!$J$8:$J$170,$A10,'Transaction Details 2026'!$I$8:$I$170,C$4) -> 500.57 | D10: =SUMIFS('Transaction Details 2026'!$E$8:$E$170,'Transaction Details 2026'!$J$8:$J$170,$A10,'Transaction Details 2026'!$I$8:$I$170,D$4) -> 1067.3 | E10: =SUMIFS('Transaction Details 2026'!$E$8:$E$170,'Transaction Details 2026'!$J$8:$J$170,$A10,'Transaction Details 2026'!$I$8:$I$170,E$4) -> 564.46 | F10: =SUMIFS('Transaction Details 2026'!$E$8:$E$170,'Transaction Details 2026'!$J$8:$J$170,$A10,'Transaction Details 2026'!$I$8:$I$170,F$4) -> 482.64 | G10: =SUMIFS('Transaction Details 2026'!$E$8:$E$170,'Transaction Details 2026'!$J$8:$J$170,$A10,'Transaction Details 2026'!$I$8:$I$170,G$4) -> 120.13 | H10: =SUM(B10:G10) -> 3694.8
A11: Joe Saunders | B11: =SUMIFS('Transaction Details 2026'!$E$8:$E$170,'Transaction Details 2026'!$J$8:$J$170,$A11,'Transaction Details 2026'!$I$8:$I$170,B$4) -> 0 | C11: =SUMIFS('Transaction Details 2026'!$E$8:$E$170,'Transaction Details 2026'!$J$8:$J$170,$A11,'Transaction Details 2026'!$I$8:$I$170,C$4) -> 0 | D11: =SUMIFS('Transaction Details 2026'!$E$8:$E$170,'Transaction Details 2026'!$J$8:$J$170,$A11,'Transaction Details 2026'!$I$8:$I$170,D$4) -> 244.67 | E11: =SUMIFS('Transaction Details 2026'!$E$8:$E$170,'Transaction Details 2026'!$J$8:$J$170,$A11,'Transaction Details 2026'!$I$8:$I$170,E$4) -> 709.39 | F11: =SUMIFS('Transaction Details 2026'!$E$8:$E$170,'Transaction Details 2026'!$J$8:$J$170,$A11,'Transaction Details 2026'!$I$8:$I$170,F$4) -> 822.24 | G11: =SUMIFS('Transaction Details 2026'!$E$8:$E$170,'Transaction Details 2026'!$J$8:$J$170,$A11,'Transaction Details 2026'!$I$8:$I$170,G$4) -> 200.17 | H11: =SUM(B11:G11) -> 1976.47
A12: Angela L Dunning | B12: =SUMIFS('Transaction Details 2026'!$E$8:$E$170,'Transaction Details 2026'!$J$8:$J$170,$A12,'Transaction Details 2026'!$I$8:$I$170,B$4) -> 60 | C12: =SUMIFS('Transaction Details 2026'!$E$8:$E$170,'Transaction Details 2026'!$J$8:$J$170,$A12,'Transaction Details 2026'!$I$8:$I$170,C$4) -> 0 | D12: =SUMIFS('Transaction Details 2026'!$E$8:$E$170,'Transaction Details 2026'!$J$8:$J$170,$A12,'Transaction Details 2026'!$I$8:$I$170,D$4) -> 0 | E12: =SUMIFS('Transaction Details 2026'!$E$8:$E$170,'Transaction Details 2026'!$J$8:$J$170,$A12,'Transaction Details 2026'!$I$8:$I$170,E$4) -> 60 | F12: =SUMIFS('Transaction Details 2026'!$E$8:$E$170,'Transaction Details 2026'!$J$8:$J$170,$A12,'Transaction Details 2026'!$I$8:$I$170,F$4) -> 0 | G12: =SUMIFS('Transaction Details 2026'!$E$8:$E$170,'Transaction Details 2026'!$J$8:$J$170,$A12,'Transaction Details 2026'!$I$8:$I$170,G$4) -> 0 | H12: =SUM(B12:G12) -> 120
A13: Online AMEX Payment | B13: =SUMIFS('Transaction Details 2026'!$E$8:$E$170,'Transaction Details 2026'!$J$8:$J$170,$A13,'Transaction Details 2026'!$I$8:$I$170,B$4) -> -321.79 | C13: =SUMIFS('Transaction Details 2026'!$E$8:$E$170,'Transaction Details 2026'!$J$8:$J$170,$A13,'Transaction Details 2026'!$I$8:$I$170,C$4) -> -2012.65 | D13: =SUMIFS('Transaction Details 2026'!$E$8:$E$170,'Transaction Details 2026'!$J$8:$J$170,$A13,'Transaction Details 2026'!$I$8:$I$170,D$4) -> -1775.69 | E13: =SUMIFS('Transaction Details 2026'!$E$8:$E$170,'Transaction Details 2026'!$J$8:$J$170,$A13,'Transaction Details 2026'!$I$8:$I$170,E$4) -> -429.22 | F13: =SUMIFS('Transaction Details 2026'!$E$8:$E$170,'Transaction Details 2026'!$J$8:$J$170,$A13,'Transaction Details 2026'!$I$8:$I$170,F$4) -> -2961.02 | G13: =SUMIFS('Transaction Details 2026'!$E$8:$E$170,'Transaction Details 2026'!$J$8:$J$170,$A13,'Transaction Details 2026'!$I$8:$I$170,G$4) -> 0 | H13: =SUM(B13:G13) -> -7500.37
A15: Total Charges | B15: =SUMIFS('Transaction Details 2026'!$E$8:$E$170,'Transaction Details 2026'!$I$8:$I$170,B$4,'Transaction Details 2026'!$E$8:$E$170,">0") -> 1418.07 | C15: =SUMIFS('Transaction Details 2026'!$E$8:$E$170,'Transaction Details 2026'!$I$8:$I$170,C$4,'Transaction Details 2026'!$E$8:$E$170,">0") -> 898.94 | D15: =SUMIFS('Transaction Details 2026'!$E$8:$E$170,'Transaction Details 2026'!$I$8:$I$170,D$4,'Transaction Details 2026'!$E$8:$E$170,">0") -> 1940.34 | E15: =SUMIFS('Transaction Details 2026'!$E$8:$E$170,'Transaction Details 2026'!$I$8:$I$170,E$4,'Transaction Details 2026'!$E$8:$E$170,">0") -> 3142.58 | F15: =SUMIFS('Transaction Details 2026'!$E$8:$E$170,'Transaction Details 2026'!$I$8:$I$170,F$4,'Transaction Details 2026'!$E$8:$E$170,">0") -> 2248.19 | G15: =SUMIFS('Transaction Details 2026'!$E$8:$E$170,'Transaction Details 2026'!$I$8:$I$170,G$4,'Transaction Details 2026'!$E$8:$E$170,">0") -> 593.7 | H15: =SUM(B15:G15) -> 10241.82
A16: Total Credits & Payments | B16: =SUMIFS('Transaction Details 2026'!$E$8:$E$170,'Transaction Details 2026'!$I$8:$I$170,B$4,'Transaction Details 2026'!$E$8:$E$170,"<0") -> -321.79 | C16: =SUMIFS('Transaction Details 2026'!$E$8:$E$170,'Transaction Details 2026'!$I$8:$I$170,C$4,'Transaction Details 2026'!$E$8:$E$170,"<0") -> -2012.65 | D16: =SUMIFS('Transaction Details 2026'!$E$8:$E$170,'Transaction Details 2026'!$I$8:$I$170,D$4,'Transaction Details 2026'!$E$8:$E$170,"<0") -> -1775.69 | E16: =SUMIFS('Transaction Details 2026'!$E$8:$E$170,'Transaction Details 2026'!$I$8:$I$170,E$4,'Transaction Details 2026'!$E$8:$E$170,"<0") -> -443.1 | F16: =SUMIFS('Transaction Details 2026'!$E$8:$E$170,'Transaction Details 2026'!$I$8:$I$170,F$4,'Transaction Details 2026'!$E$8:$E$170,"<0") -> -3016.58 | G16: =SUMIFS('Transaction Details 2026'!$E$8:$E$170,'Transaction Details 2026'!$I$8:$I$170,G$4,'Transaction Details 2026'!$E$8:$E$170,"<0") -> 0 | H16: =SUM(B16:G16) -> -7569.81
A17: Net | B17: =B15+B16 -> 1096.28 | C17: =C15+C16 -> -1113.71 | D17: =D15+D16 -> 164.65 | E17: =E15+E16 -> 2699.48 | F17: =F15+F16 -> -768.39 | G17: =G15+G16 -> 593.7 | H17: =SUM(B17:G17) -> 2672.01
A19: =IF(ROUND(H17-'Transaction Summary 2026'!B11,2)=0,"✓ Net ties to Transaction Summary","⚠ mismatch") -> ✓ Net ties to Transaction Summary

Sheet Transaction Details 2026
A1: FAMILY AMEX | B1: Platinum Card® / Jan 01, 2026 to Jun 11, 2026
A2: Prepared for
A3: JOHN DUNNING
A4: Account Number
A5: XXXX-XXXXXX-43006
