Workbook

Sheet Transaction Summary
A1: POSEIDON PARTNERS
A2: Amex Business Platinum | Statement Summary
A4: Account Holder | B4: John Dunning
A5: Account | B5: XXXX-XXXXXX-02000
A6: Statement Period (Detail) | B6: January 2026 - February 2026
A8: TOTALS
A9: Charges | B9: =SUMIF('Transaction Details'!$E$8:$E$261,">0") -> 44873.29
A10: Credits & Payments | B10: =SUMIF('Transaction Details'!$E$8:$E$261,"<0") -> -56616.5
A11: Net Balance | B11: =B9+B10 -> -11743.21
A13: SPEND BY CATEGORY
A14: Category | B14: Amount | C14: % of Charges
A15: DWG / Business
A16: Team Travel | B16: =SUMIFS('Transaction Details'!$E$8:$E$261,'Transaction Details'!$J$8:$J$261,A16) -> 6456.4 | C16: =IFERROR(B16/$B$9,0) -> 0.14388069
A17: Team Lunch | B17: =SUMIFS('Transaction Details'!$E$8:$E$261,'Transaction Details'!$J$8:$J$261,A17) -> 1133.84 | C17: =IFERROR(B17/$B$9,0) -> 0.025267592
A18: DWG Conference | B18: =SUMIFS('Transaction Details'!$E$8:$E$261,'Transaction Details'!$J$8:$J$261,A18) -> 1370 | C18: =IFERROR(B18/$B$9,0) -> 0.030530411
A19: DWG Meeting | B19: =SUMIFS('Transaction Details'!$E$8:$E$261,'Transaction Details'!$J$8:$J$261,A19) -> 259.08 | C19: =IFERROR(B19/$B$9,0) -> 0.0057735905
A20: DWG Swag | B20: =SUMIFS('Transaction Details'!$E$8:$E$261,'Transaction Details'!$J$8:$J$261,A20) -> 671.44 | C20: =IFERROR(B20/$B$9,0) -> 0.014963021
A21: DWG Listing Platform | B21: =SUMIFS('Transaction Details'!$E$8:$E$261,'Transaction Details'!$J$8:$J$261,A21) -> 252 | C21: =IFERROR(B21/$B$9,0) -> 0.0056158129
A22: DWG-RE Listing Platform | B22: =SUMIFS('Transaction Details'!$E$8:$E$261,'Transaction Details'!$J$8:$J$261,A22) -> 260 | C22: =IFERROR(B22/$B$9,0) -> 0.0057940927
A23: DWG-RE Marketing | B23: =SUMIFS('Transaction Details'!$E$8:$E$261,'Transaction Details'!$J$8:$J$261,A23) -> 2123.37 | C23: =IFERROR(B23/$B$9,0) -> 0.04731924
A24: DWGCP Conference | B24: =SUMIFS('Transaction Details'!$E$8:$E$261,'Transaction Details'!$J$8:$J$261,A24) -> 4500 | C24: =IFERROR(B24/$B$9,0) -> 0.10028237
A25: DWGCP Lawsuit | B25: =SUMIFS('Transaction Details'!$E$8:$E$261,'Transaction Details'!$J$8:$J$261,A25) -> 100 | C25: =IFERROR(B25/$B$9,0) -> 0.0022284972
A26: DWGCP Marketing | B26: =SUMIFS('Transaction Details'!$E$8:$E$261,'Transaction Details'!$J$8:$J$261,A26) -> 151.33 | C26: =IFERROR(B26/$B$9,0) -> 0.0033723848
A27: DWGCP Supplies (Prints) | B27: =SUMIFS('Transaction Details'!$E$8:$E$261,'Transaction Details'!$J$8:$J$261,A27) -> 195 | C27: =IFERROR(B27/$B$9,0) -> 0.0043455695
... A32: Jeff Farjado - Case | B32: =SUMIFS('Transaction Details'!$E$8:$E$261,'Transaction Details'!$J$8:$J$261,A32) -> 1600 | C32: =IFERROR(B32/$B$9,0) -> 0.035655955
A33: Subtotal — DWG | B33: =SUM(B16:B32) -> 29238.94 | C33: =IFERROR(B33/$B$9,0) -> 0.65158895
A34: Software, Subscriptions & Comms
A35: Software & Subscriptions | B35: =SUMIFS('Transaction Details'!$E$8:$E$261,'Transaction Details'!$J$8:$J$261,A35) -> 2046.17 | C35: =IFERROR(B35/$B$9,0) -> 0.045598841
A36: AI Subscription | B36: =SUMIFS('Transaction Details'!$E$8:$E$261,'Transaction Details'!$J$8:$J$261,A36) -> 126.28 | C36: =IFERROR(B36/$B$9,0) -> 0.0028141462
A37: Go Daddy | B37: =SUMIFS('Transaction Details'!$E$8:$E$261,'Transaction Details'!$J$8:$J$261,A37) -> 1054.84 | C37: =IFERROR(B37/$B$9,0) -> 0.02350708
A38: Personal - Word Press | B38: =SUMIFS('Transaction Details'!$E$8:$E$261,'Transaction Details'!$J$8:$J$261,A38) -> 319.8 | C38: =IFERROR(B38/$B$9,0) -> 0.007126734
A39: CLEAR ME (2026) | B39: =SUMIFS('Transaction Details'!$E$8:$E$261,'Transaction Details'!$J$8:$J$261,A39) -> 334 | C39: =IFERROR(B39/$B$9,0) -> 0.0074431806
A40: Subtotal — Software | B40: =SUM(B35:B39) -> 3881.09 | C40: =IFERROR(B40/$B$9,0) -> 0.086489981
A41: Personal / Living
A42: Personal - Food | B42: =SUMIFS('Transaction Details'!$E$8:$E$261,'Transaction Details'!$J$8:$J$261,A42) -> 3076.13 | C42: =IFERROR(B42/$B$9,0) -> 0.06855147
A43: Personal - Health | B43: =SUMIFS('Transaction Details'!$E$8:$E$261,'Transaction Details'!$J$8:$J$261,A43) -> 3689.94 | C43: =IFERROR(B43/$B$9,0) -> 0.082230209
A44: Personal - Car | B44: =SUMIFS('Transaction Details'!$E$8:$E$261,'Transaction Details'!$J$8:$J$261,A44) -> 365.47 | C44: =IFERROR(B44/$B$9,0) -> 0.0081444886
A45: Personal - Clothing | B45: =SUMIFS('Transaction Details'!$E$8:$E$261,'Transaction Details'!$J$8:$J$261,A45) -> 439.04 | C45: =IFERROR(B45/$B$9,0) -> 0.009783994
A46: Personal - Family | B46: =SUMIFS('Transaction Details'!$E$8:$E$261,'Transaction Details'!$J$8:$J$261,A46) -> 2516.12 | C46: =IFERROR(B46/$B$9,0) -> 0.056071663
A47: Personal - Entertainment | B47: =SUMIFS('Transaction Details'!$E$8:$E$261,'Transaction Details'!$J$8:$J$261,A47) -> 102.36 | C47: =IFERROR(B47/$B$9,0) -> 0.0022810897
...

Sheet Monthly Breakdown
A1: POSEIDON PARTNERS
A2: Amex Business Platinum | Monthly Breakdown
A4: Category | B4: =DATE(2026,1,1) -> 46023 | C4: =DATE(2026,2,1) -> 46054 | D4: Total
A5: Team Travel | B5: =SUMIFS('Transaction Details'!$E$8:$E$261,'Transaction Details'!$J$8:$J$261,$A5,'Transaction Details'!$I$8:$I$261,B$4) -> 3324.67 | C5: =SUMIFS('Transaction Details'!$E$8:$E$261,'Transaction Details'!$J$8:$J$261,$A5,'Transaction Details'!$I$8:$I$261,C$4) -> 3131.73 | D5: =SUM(B5:C5) -> 6456.4
A6: Team Lunch | B6: =SUMIFS('Transaction Details'!$E$8:$E$261,'Transaction Details'!$J$8:$J$261,$A6,'Transaction Details'!$I$8:$I$261,B$4) -> 214.33 | C6: =SUMIFS('Transaction Details'!$E$8:$E$261,'Transaction Details'!$J$8:$J$261,$A6,'Transaction Details'!$I$8:$I$261,C$4) -> 919.51 | D6: =SUM(B6:C6) -> 1133.84
A7: DWG Conference | B7: =SUMIFS('Transaction Details'!$E$8:$E$261,'Transaction Details'!$J$8:$J$261,$A7,'Transaction Details'!$I$8:$I$261,B$4) -> 0 | C7: =SUMIFS('Transaction Details'!$E$8:$E$261,'Transaction Details'!$J$8:$J$261,$A7,'Transaction Details'!$I$8:$I$261,C$4) -> 1370 | D7: =SUM(B7:C7) -> 1370
A8: DWG Meeting | B8: =SUMIFS('Transaction Details'!$E$8:$E$261,'Transaction Details'!$J$8:$J$261,$A8,'Transaction Details'!$I$8:$I$261,B$4) -> 259.08 | C8: =SUMIFS('Transaction Details'!$E$8:$E$261,'Transaction Details'!$J$8:$J$261,$A8,'Transaction Details'!$I$8:$I$261,C$4) -> 0 | D8: =SUM(B8:C8) -> 259.08
A9: DWG Swag | B9: =SUMIFS('Transaction Details'!$E$8:$E$261,'Transaction Details'!$J$8:$J$261,$A9,'Transaction Details'!$I$8:$I$261,B$4) -> 671.44 | C9: =SUMIFS('Transaction Details'!$E$8:$E$261,'Transaction Details'!$J$8:$J$261,$A9,'Transaction Details'!$I$8:$I$261,C$4) -> 0 | D9: =SUM(B9:C9) -> 671.44
A10: DWG Listing Platform | B10: =SUMIFS('Transaction Details'!$E$8:$E$261,'Transaction Details'!$J$8:$J$261,$A10,'Transaction Details'!$I$8:$I$261,B$4) -> 0 | C10: =SUMIFS('Transaction Details'!$E$8:$E$261,'Transaction Details'!$J$8:$J$261,$A10,'Transaction Details'!$I$8:$I$261,C$4) -> 252 | D10: =SUM(B10:C10) -> 252
A11: DWG-RE Listing Platform | B11: =SUMIFS('Transaction Details'!$E$8:$E$261,'Transaction Details'!$J$8:$J$261,$A11,'Transaction Details'!$I$8:$I$261,B$4) -> 0 | C11: =SUMIFS('Transaction Details'!$E$8:$E$261,'Transaction Details'!$J$8:$J$261,$A11,'Transaction Details'!$I$8:$I$261,C$4) -> 260 | D11: =SUM(B11:C11) -> 260
A12: DWG-RE Marketing | B12: =SUMIFS('Transaction Details'!$E$8:$E$261,'Transaction Details'!$J$8:$J$261,$A12,'Transaction Details'!$I$8:$I$261,B$4) -> 455 | C12: =SUMIFS('Transaction Details'!$E$8:$E$261,'Transaction Details'!$J$8:$J$261,$A12,'Transaction Details'!$I$8:$I$261,C$4) -> 1668.37 | D12: =SUM(B12:C12) -> 2123.37
A13: DWGCP Conference | B13: =SUMIFS('Transaction Details'!$E$8:$E$261,'Transaction Details'!$J$8:$J$261,$A13,'Transaction Details'!$I$8:$I$261,B$4) -> 4500 | C13: =SUMIFS('Transaction Details'!$E$8:$E$261,'Transaction Details'!$J$8:$J$261,$A13,'Transaction Details'!$I$8:$I$261,C$4) -> 0 | D13: =SUM(B13:C13) -> 4500
A14: DWGCP Lawsuit | B14: =SUMIFS('Transaction Details'!$E$8:$E$261,'Transaction Details'!$J$8:$J$261,$A14,'Transaction Details'!$I$8:$I$261,B$4) -> 0 | C14: =SUMIFS('Transaction Details'!$E$8:$E$261,'Transaction Details'!$J$8:$J$261,$A14,'Transaction Details'!$I$8:$I$261,C$4) -> 100 | D14: =SUM(B14:C14) -> 100
A15: DWGCP Marketing | B15: =SUMIFS('Transaction Details'!$E$8:$E$261,'Transaction Details'!$J$8:$J$261,$A15,'Transaction Details'!$I$8:$I$261,B$4) -> 151.33 | C15: =SUMIFS('Transaction Details'!$E$8:$E$261,'Transaction Details'!$J$8:$J$261,$A15,'Transaction Details'!$I$8:$I$261,C$4) -> 0 | D15: =SUM(B15:C15) -> 151.33
A16: DWGCP Supplies (Prints) | B16: =SUMIFS('Transaction Details'!$E$8:$E$261,'Transaction Details'!$J$8:$J$261,$A16,'Transaction Details'!$I$8:$I$261,B$4) -> 0 | C16: =SUMIFS('Transaction Details'!$E$8:$E$261,'Transaction Details'!$J$8:$J$261,$A16,'Transaction Details'!$I$8:$I$261,C$4) -> 195 | D16: =SUM(B16:C16) -> 195
... A43: Points for Amex Trvl | B43: =SUMIFS('Transaction Details'!$E$8:$E$261,'Transaction Details'!$J$8:$J$261,$A43,'Transaction Details'!$I$8:$I$261,B$4) -> 0 | C43: =SUMIFS('Transaction Details'!$E$8:$E$261,'Transaction Details'!$J$8:$J$261,$A43,'Transaction Details'!$I$8:$I$261,C$4) -> -150 | D43: =SUM(B43:C43) -> -150
A45: Total Charges | B45: =SUMIFS('Transaction Details'!$E$8:$E$261,'Transaction Details'!$I$8:$I$261,B$4,'Transaction Details'!$E$8:$E$261,">0") -> 18696.85 | C45: =SUMIFS('Transaction Details'!$E$8:$E$261,'Transaction Details'!$I$8:$I$261,C$4,'Transaction Details'!$E$8:$E$261,">0") -> 26176.44 | D45: =SUM(B45:C45) -> 44873.29
A46: Total Credits & Payments | B46: =SUMIFS('Transaction Details'!$E$8:$E$261,'Transaction Details'!$I$8:$I$261,B$4,'Transaction Details'!$E$8:$E$261,"<0") -> -15091.61 | C46: =SUMIFS('Transaction Details'!$E$8:$E$261,'Transaction Details'!$I$8:$I$261,C$4,'Transaction Details'!$E$8:$E$261,"<0") -> -41524.89 | D46: =SUM(B46:C46) -> -56616.5
A47: Net | B47: =B45+B46 -> 3605.24 | C47: =C45+C46 -> -15348.45 | D47: =D45+D46 -> -11743.21
A49: =IF(ROUND(D47-'Transaction Summary'!B11,2)=0,"✓ Net ties to Transaction Summary","⚠ mismatch") -> ✓ Net ties to Transaction Summary

Sheet Transaction Details
A1: Transaction Details | B1: Business Platinum Card® / Dec 01, 2025 to Feb 28, 2026
A2: Prepared for
A3: JOHN DUNNING
A4: Account Number
A5: XXXX-XXXXXX-02000
A7: Date | B7: Description | C7: Card Member | D7: Account # | E7: Amount | F7: Extended Details | G7: Appears On Your Statement As | H7: Category | I7: Month | J7: Category (clean)
A8: 46081 | B8: CASABLANCA RESTAURANVENICE CA | C8: JOHN DUNNING | D8: -2000 | E8: 95.7 | F8: 31099536060 RESTAURANT CASABLANCA RESTAURANT 00-08045339838 VENICE CA RESTAURANT | G8: CASABLANCA RESTAURANVENICE CA | H8: Personal - Food | I8: =DATE(YEAR(A8),MONTH(A8),1) -> 46054 | J8: =IF(TRIM(H8)="","(Uncategorized)",TRIM(H8)) -> Personal - Food
A9: 46081 | B9: GELSON'S MARKET #29 SANTA MONICA CA | C9: JOHN DUNNING | D9: -2000 | E9: 126.6 | F9: 000069766 3105816450 GELSON'S MARKET #29 000000000098932 SANTA MONICA CA 3105816450 | G9: GELSON'S MARKET #29 SANTA MONICA CA | H9: Personal - Food | I9: =DATE(YEAR(A9),MONTH(A9),1) -> 46054 | J9: =IF(TRIM(H9)="","(Uncategorized)",TRIM(H9)) -> Personal - Food
A10: 46081 | B10: SPONSORCLOUD (SYNPROSALT LAKE CITY UT | C10: JOHN DUNNING | D10: -2000 | E10: 182.98 | F10: CH_3T5XQRB7 +13854834872 SPONSORCLOUD (SYNPRO) SALT LAKE CITY UT +13854834872 | G10: SPONSORCLOUD (SYNPROSALT LAKE CITY UT | H10: Sponsor Cloud - DWGCP | I10: =DATE(YEAR(A10),MONTH(A10),1) -> 46054 | J10: =IF(TRIM(H10)="","(Uncategorized)",TRIM(H10)) -> Sponsor Cloud - DWGCP
A11: 46080 | B11: ALANA'S COFFEE ROASTLos Angeles CA | C11: JOHN DUNNING | D11: -2000 | E11: 47.1 | F11: jZKHQjjVA0y squareup.com/receipts ALANA'S COFFEE ROASTERS Los Angeles CA squareup.com/receipts | G11: ALANA'S COFFEE ROASTLos Angeles CA | H11: Personal - Food | I11: =DATE(YEAR(A11),MONTH(A11),1) -> 46054 | J11: =IF(TRIM(H11)="","(Uncategorized)",TRIM(H11)) -> Personal - Food
A12: 46080 | B12: DNH*GODADDY#40268371Tempe AZ | C12: JOHN DUNNING | D12: -2000 | E12: 17.98 | F12: 4026837181 4805058855 Hosting - Web - Economy - Linux cPanel - PHP Extended Support Level 1 - Renewal - DNH*GODADDY#4026837181 Tempe AZ Hosting - Web - Economy - Linux cPanel - PHP Extended Support Level 1 - Renewal - 4805058855 | G12: DNH*GODADDY#40268371Tempe AZ | H12: Go Daddy | I12: =DATE(YEAR(A12),MONTH(A12),1) -> 46054 | J12: =IF(TRIM(H12)="","(Uncategorized)",TRIM(H12)) -> Go Daddy
A13: 46080 | B13: SPLICE.COM NEW YORK NY | C13: JOHN DUNNING | D13: -2000 | E13: 39.99 | F13: CH_3T5S9YCF 3235775423 SPLICE.COM NEW YORK NY 3235775423 | G13: SPLICE.COM NEW YORK NY | H13: Software & Subscriptions | I13: =DATE(YEAR(A13),MONTH(A13),1) -> 46054 | J13: =IF(TRIM(H13)="","(Uncategorized)",TRIM(H13)) -> Software & Subscriptions
A14: 46079 | B14: ALANA'S COFFEE ROASTLos Angeles CA | C14: JOHN DUNNING | D14: -2000 | E14: 19.84 | F14: 9iqGR6Vq5eW squareup.com/receipts ALANA'S COFFEE ROASTERS Los Angeles CA squareup.com/receipts | G14: ALANA'S COFFEE ROASTLos Angeles CA | H14: Personal - Food | I14: =DATE(YEAR(A14),MONTH(A14),1) -> 46054 | J14: =IF(TRIM(H14)="","(Uncategorized)",TRIM(H14)) -> Personal - Food
A15: 46079 | B15: NAIOP, INC.*NAIOP, IHERNDON VA | C15: JOHN DUNNING | D15: -2000 | E15: 1370 | F15: HERNDON NAIOP, INC.*NAIOP, INC. NAIOP, INC. HERNDON VA HERNDON | G15: NAIOP, INC.*NAIOP, IHERNDON VA | H15: DWG Conference | I15: =DATE(YEAR(A15),MONTH(A15),1) -> 46054 | J15: =IF(TRIM(H15)="","(Uncategorized)",TRIM(H15)) -> DWG Conference
A16: 46079 | B16: ONLINE PAYMENT - THANK YOU | C16: JOHN DUNNING | D16: -2000 | E16: -40222.68 | F16: ONLINE PAYMENT - THANK YOU | G16: ONLINE PAYMENT - THANK YOU | H16: Online AMEX Payment | I16: =DATE(YEAR(A16),MONTH(A16),1) -> 46054 | J16: =IF(TRIM(H16)="","(Uncategorized)",TRIM(H16)) -> Online AMEX Payment
A17: 46078 | B17: ALANA'S COFFEE ROASTLos Angeles CA | C17: JOHN DUNNING | D17: -2000 | E17: 19.55 | F17: 7PDFunpsqir squareup.com/receipts ALANA'S COFFEE ROASTERS Los Angeles CA squareup.com/receipts | G17: ALANA'S COFFEE ROASTLos Angeles CA | H17: Personal - Food | I17: =DATE(YEAR(A17),MONTH(A17),1) -> 46054 | J17: =IF(TRIM(H17)="","(Uncategorized)",TRIM(H17)) -> Personal - Food
A18: 46078 | B18: CASABLANCA RESTAURANVENICE CA | C18: JOHN DUNNING | D18: -2000 | E18: 67.85 | F18: 31099536057 RESTAURANT CASABLANCA RESTAURANT 00-08045339838 VENICE CA RESTAURANT | G18: CASABLANCA RESTAURANVENICE CA | H18: Personal - Food | I18: =DATE(YEAR(A18),MONTH(A18),1) -> 46054 | J18: =IF(TRIM(H18)="","(Uncategorized)",TRIM(H18)) -> Personal - Food
A19: 46078 | B19: DNH*GODADDY#40251923Tempe AZ | C19: JOHN DUNNING | D19: -2000 | E19: 16.98 | F19: 4025192380 4805058855 Email Plus - Renewal - monthly Email - Archiving - Renewal DNH*GODADDY#4025192380 Tempe AZ Email Plus - Renewal - monthly Email - Archiving - Renewal 4805058855 | G19: DNH*GODADDY#40251923Tempe AZ | H19: Go Daddy | I19: =DATE(YEAR(A19),MONTH(A19),1) -> 46054 | J19: =IF(TRIM(H19)="","(Uncategorized)",TRIM(H19)) -> Go Daddy
... A261: 46023 | B261: LOOM SUBSCRIPTION AUSTIN TX | C261: JOHN DUNNING | D261: -2000 | E261: 20 | F261: CH_3SKMF5D0 +16780000000 LOOM SUBSCRIPTION AUSTIN TX +16780000000 | G261: LOOM SUBSCRIPTION AUSTIN TX | H261: Software & Subscriptions | I261: =DATE(YEAR(A261),MONTH(A261),1) -> 46023 | J261: =IF(TRIM(H261)="","(Uncategorized)",TRIM(H261)) -> Software & Subscriptions
