Workbook

Sheet Transaction Summary
A1: DWG CAPITAL PARTNERS
A2: Amex Business Platinum | Statement Summary
A4: Account Holder | B4: John Dunning
A5: Account | B5: XXXX-XXXXXX-01004
A6: Statement Period | B6: May 29, 2026 – Jun 30, 2026
A8: TOTALS
A9: Charges | B9: =SUMIF('Transaction Details'!C8:C106,">0") -> 13714.41
A10: Credits & Payments | B10: =SUMIF('Transaction Details'!C8:C106,"<0") -> -16950.79
A11: Net Balance | B11: =B9+B10 -> -3236.38
A13: SPEND BY CATEGORY
A14: Category | B14: Amount | C14: % of Charges
A15: Team Travel
A16: DWG Team Travel (Atlanta, GA) | B16: =SUMIFS('Transaction Details'!$C$8:$C$106,'Transaction Details'!$F$8:$F$106,A16) -> 5128.54 | C16: =IFERROR(B16/$B$9,0) -> 0.37395265
A17: Less: Amex Travel Pay with Points (miles) | B17: =SUMIFS('Transaction Details'!$C$8:$C$106,'Transaction Details'!$F$8:$F$106,"AMEX TRAVEL PAY WITH POINTS CREDIT") -> -560 | C17: =IFERROR(B17/$B$9,0) -> -0.040832963
A18: Less: Platinum Hotel Credit | B18: =SUMIFS('Transaction Details'!$C$8:$C$106,'Transaction Details'!$F$8:$F$106,"Platinum Hotel Credit") -> -300 | C18: =IFERROR(B18/$B$9,0) -> -0.021874802
A19: Less: Southwest Airlines refund | B19: =SUMIFS('Transaction Details'!$C$8:$C$106,'Transaction Details'!$F$8:$F$106,"Refund") -> -29 | C19: =IFERROR(B19/$B$9,0) -> -0.0021145642
A20: DWG Team Travel (Atlanta, GA) — net | B20: =B16+B17+B18+B19 -> 4239.54 | C20: =IFERROR(B20/$B$9,0) -> 0.30913032
A21: DWG Team Travel (Austin, TX) | B21: =SUMIFS('Transaction Details'!$C$8:$C$106,'Transaction Details'!$F$8:$F$106,A21) -> 619.77 | C21: =IFERROR(B21/$B$9,0) -> 0.045191153
A22: DWG Team Travel (Roanoke, VA) | B22: =SUMIFS('Transaction Details'!$C$8:$C$106,'Transaction Details'!$F$8:$F$106,A22) -> 1262.87 | C22: =IFERROR(B22/$B$9,0) -> 0.092083436
A23: DWG Team Travel (MISC) | B23: =SUMIFS('Transaction Details'!$C$8:$C$106,'Transaction Details'!$F$8:$F$106,A23) -> 31.91 | C23: =IFERROR(B23/$B$9,0) -> 0.0023267497
A24: DWG Team Travel | B24: =SUMIFS('Transaction Details'!$C$8:$C$106,'Transaction Details'!$F$8:$F$106,A24) -> 147.66 | C24: =IFERROR(B24/$B$9,0) -> 0.010766777
A25: Subtotal — Team Travel (net of credits) | B25: =B20+B21+B22+B23+B24 -> 6301.75 | C25: =IFERROR(B25/$B$9,0) -> 0.45949844
A26: Operating & Subscriptions
A27: DWG Operational Subscription | B27: =SUMIFS('Transaction Details'!$C$8:$C$106,'Transaction Details'!$F$8:$F$106,A27) -> 1136.86 | C27: =IFERROR(B27/$B$9,0) -> 0.08289529
A28: AI Subscriptions | B28: =SUMIFS('Transaction Details'!$C$8:$C$106,'Transaction Details'!$F$8:$F$106,A28) -> 357.48 | C28: =IFERROR(B28/$B$9,0) -> 0.026066014
A29: Amazon | B29: =SUMIFS('Transaction Details'!$C$8:$C$106,'Transaction Details'!$F$8:$F$106,A29) -> 361.69 | C29: =IFERROR(B29/$B$9,0) -> 0.02637299
A30: Employee MISC | B30: =SUMIFS('Transaction Details'!$C$8:$C$106,'Transaction Details'!$F$8:$F$106,A30) -> 461.79 | C30: =IFERROR(B30/$B$9,0) -> 0.033671882
A31: Subtotal — Operating & Subscriptions | B31: =SUM(B27:B30) -> 2317.82 | C31: =IFERROR(B31/$B$9,0) -> 0.16900618
A32: Deal Specific
A33: Deal Specific - Austin Iron | B33: =SUMIFS('Transaction Details'!$C$8:$C$106,'Transaction Details'!$F$8:$F$106,A33) -> 0 | C33: =IFERROR(B33/$B$9,0) -> 0
A34: Deal Specific - MRM/CMG | B34: =SUMIFS('Transaction Details'!$C$8:$C$106,'Transaction Details'!$F$8:$F$106,A34) -> 405.21 | C34: =IFERROR(B34/$B$9,0) -> 0.029546295
A35: Deal Specific - JAL Southbend | B35: =SUMIFS('Transaction Details'!$C$8:$C$106,'Transaction Details'!$F$8:$F$106,A35) -> 2500 | C35: =IFERROR(B35/$B$9,0) -> 0.18229001
A36: Subtotal — Deal Specific | B36: =SUM(B33:B35) -> 2905.21 | C36: =IFERROR(B36/$B$9,0) -> 0.21183631
A37: Review
A38: TBD Review | B38: =SUMIFS('Transaction Details'!$C$8:$C$106,'Transaction Details'!$F$8:$F$106,A38) -> 45.15 | C38: =IFERROR(B38/$B$9,0) -> 0.0032921577
A39: Subtotal — Review | B39: =SUM(B38:B38) -> 45.15 | C39: =IFERROR(B39/$B$9,0) -> 0.0032921577
A40: Payments
A41: Online AMEX Pmt | B41: =SUMIFS('Transaction Details'!$C$8:$C$106,'Transaction Details'!$F$8:$F$106,A41) -> -14806.31 | C41: =IFERROR(B41/$B$9,0) -> -1.079617
A42: Subtotal — Payments | B42: =SUM(B41:B41) -> -14806.31 | C42: =IFERROR(B42/$B$9,0) -> -1.079617
A43: GRAND TOTAL (nets to Net Balance) | B43: =B25+B31+B36+B39+B42 -> -3236.38 | C43: =IFERROR(B43/$B$9,0) -> -0.2359839
...

Sheet Transaction Details
A1: Transaction Details
A2: Prepared for
A3: JOHN DUNNING
A4: Account Number
A5: XXXX-XXXXXX-01004
A7: Date | B7: Description | C7: Amount | D7: Extended Details | E7: Appears On Your Statement As | F7: Category
A8: 06/30/2026 | B8: AMAZON MARKEPLACE NA PA | C8: 130.8 | D8: XAY4NYV44KC MERCHANDISE AMAZON MARKETPLACE NA PA AMZN.COM/BILL WA MERCHANDISE | E8: AMAZON MARKETPLACE NAMZN.COM/BILL WA | F8: Amazon
A9: 06/29/2026 | B9: EAI*TRAVIS CO TAX OFAUSTIN TX | C9: 1255.48 | D9: 20191520102 19566626172 EAI*TRAVIS CO TAX OFFICE TRAVIS COUNTY AUSTIN TX 19566626172 | E9: EAI*TRAVIS CO TAX OFAUSTIN TX | F9: Deal Specific - Austin Iron
A10: 06/29/2026 | B10: ONLINE PAYMENT - THANK YOU | C10: -1255.48 | D10: ONLINE PAYMENT - THANK YOU | E10: ONLINE PAYMENT - THANK YOU | F10: Deal Specific - Austin Iron
A11: 06/24/2026 | B11: AMAZON MARKEPLACE NA PA | C11: 76.48 | D11: 4WCQCBJVZHA MERCHANDISE AMAZON MARKETPLACE NA PA AMZN.COM/BILL WA MERCHANDISE | E11: AMAZON MARKETPLACE NAMZN.COM/BILL WA | F11: Amazon
A12: 06/24/2026 | B12: SP NOVAPETAL NYC NEW YORK NY | C12: 240.98 | D12: CH_3TM3REJ1 2122160900 SP NOVAPETAL NYC NEW YORK NY 2122160900 | E12: SP NOVAPETAL NYC NEW YORK NY | F12: Employee MISC
A13: 06/23/2026 | B13: ANTHROPIC SAN FRANCISCO CA | C13: 10.6 | D13: CH_3TLAPEAC +14152360599 ANTHROPIC SAN FRANCISCO CA +14152360599 | E13: ANTHROPIC SAN FRANCISCO CA | F13: AI Subscriptions
A14: 06/23/2026 | B14: ANTHROPIC SAN FRANCISCO CA | C14: 10.62 | D14: CH_3TLZMUAC +14152360599 ANTHROPIC SAN FRANCISCO CA +14152360599 | E14: ANTHROPIC SAN FRANCISCO CA | F14: AI Subscriptions
A15: 06/23/2026 | B15: ANTHROPIC SAN FRANCISCO CA | C15: 11.35 | D15: CH_3TLA5BAC +14152360599 ANTHROPIC SAN FRANCISCO CA +14152360599 | E15: ANTHROPIC SAN FRANCISCO CA | F15: AI Subscriptions
A16: 06/23/2026 | B16: ANTHROPIC SAN FRANCISCO CA | C16: 12.16 | D16: CH_3TLAF0AC +14152360599 ANTHROPIC SAN FRANCISCO CA +14152360599 | E16: ANTHROPIC SAN FRANCISCO CA | F16: AI Subscriptions
A17: 06/23/2026 | B17: ANTHROPIC* CLAUDE SUSAN FRANCISCO CA | C17: 105.4 | D17: CH_3TLXWPAC +14152360599 ANTHROPIC* CLAUDE SUB SAN FRANCISCO CA +14152360599 | E17: ANTHROPIC* CLAUDE SUSAN FRANCISCO CA | F17: AI Subscriptions
A18: 06/23/2026 | B18: MICROSOFT MSBILL.INFO | C18: 0.99 | D18: Z73WSUU8LSRZ73WSUU8LSR9 98052 MICROSOFT MSBILL.INFO Z73WSUU8LSR9 98052 | E18: MICROSOFT MSBILL.INFO | F18: DWG Operational Subscription
A19: 06/22/2026 | B19: AMAZON.COM AMZN.COM/BILL WA | C19: 23.13 | D19: 5PRKG7WMDK1 BOOK STORES AMAZON.COM AMZN.COM/BILL WA BOOK STORES | E19: AMAZON.COM AMZN.COM/BILL WA | F19: Amazon
... A106: 05/31/2026 | B106: TASKER ON TASKRABBITSAN FRANCISCO CA | C106: 220.81 | D106: CH_3TDGGPC5 +18443408275 TASKER ON TASKRABBIT SAN FRANCISCO CA +18443408275 | E106: TASKER ON TASKRABBITSAN FRANCISCO CA | F106: Employee MISC
