Workbook

Sheet Transaction Summary
A1: DWG CAPITAL GROUP
A2: Amex Business Platinum | Statement Summary
A4: Account Holder | B4: John Dunning
A5: Account | B5: XXXX-XXXXXX-81005
A6: Statement Period | B6: Feb 21, 2026 – Jun 11, 2026
A8: TOTALS
A9: Charges | B9: =SUMIFS('Transaction Details'!$D:$D,'Transaction Details'!$D:$D,">0") -> 26987.05
A10: Credits & Payments | B10: =SUMIFS('Transaction Details'!$D:$D,'Transaction Details'!$D:$D,"<0") -> -22620
A11: Net Balance | B11: =B9+B10 -> 4367.05
A13: SPEND BY CATEGORY
A14: Category | B14: Amount | C14: % of Charges
A15: DWG Operating
A16: DWG Listing Platform | B16: =SUMIFS('Transaction Details'!$D:$D,'Transaction Details'!$C:$C,A16) -> 12682.68 | C16: =IFERROR(B16/$B$9,0) -> 0.46995429
A17: DWG E&O Insurance | B17: =SUMIFS('Transaction Details'!$D:$D,'Transaction Details'!$C:$C,A17) -> 3161.52 | C17: =IFERROR(B17/$B$9,0) -> 0.11714952
A18: DWG-RE Professional Training | B18: =SUMIFS('Transaction Details'!$D:$D,'Transaction Details'!$C:$C,A18) -> 249 | C18: =IFERROR(B18/$B$9,0) -> 0.0092266476
A19: Employee Bonus | B19: =SUMIFS('Transaction Details'!$D:$D,'Transaction Details'!$C:$C,A19) -> 4251.77 | C19: =IFERROR(B19/$B$9,0) -> 0.15754853
A20: Membership Fee | B20: =SUMIFS('Transaction Details'!$D:$D,'Transaction Details'!$C:$C,A20) -> 895 | C20: =IFERROR(B20/$B$9,0) -> 0.033164055
A21: Subtotal — Operating | B21: =SUM(B16:B20) -> 21239.97 | C21: =IFERROR(B21/$B$9,0) -> 0.78704304
A22: Technology & Software
A23: Software & Subscriptions | B23: =SUMIFS('Transaction Details'!$D:$D,'Transaction Details'!$C:$C,A23) -> 409.74 | C23: =IFERROR(B23/$B$9,0) -> 0.015182838
A24: Subtotal — Technology | B24: =SUM(B23:B23) -> 409.74 | C24: =IFERROR(B24/$B$9,0) -> 0.015182838
A25: Team Travel & Meals
A26: Team Travel | B26: =SUMIFS('Transaction Details'!$D:$D,'Transaction Details'!$C:$C,A26) -> 1005.61 | C26: =IFERROR(B26/$B$9,0) -> 0.037262687
A27: Team Lunch | B27: =SUMIFS('Transaction Details'!$D:$D,'Transaction Details'!$C:$C,A27) -> 523.61 | C27: =IFERROR(B27/$B$9,0) -> 0.019402269
A28: Team Outing | B28: =SUMIFS('Transaction Details'!$D:$D,'Transaction Details'!$C:$C,A28) -> 470.31 | C28: =IFERROR(B28/$B$9,0) -> 0.017427248
A29: Subtotal — Travel & Meals | B29: =SUM(B26:B28) -> 1999.53 | C29: =IFERROR(B29/$B$9,0) -> 0.074092203
A30: One-Time / Capital
A31: Bridge Loan (JC Whitner) | B31: =SUMIFS('Transaction Details'!$D:$D,'Transaction Details'!$C:$C,A31) -> 2000 | C31: =IFERROR(B31/$B$9,0) -> 0.074109619
A32: Subtotal — Capital | B32: =SUM(B31:B31) -> 2000 | C32: =IFERROR(B32/$B$9,0) -> 0.074109619
A33: Personal — Reimburse to Company
A34: Personal | B34: =SUMIFS('Transaction Details'!$D:$D,'Transaction Details'!$C:$C,A34) -> 1227.31 | C34: =IFERROR(B34/$B$9,0) -> 0.045477738
A35: Subtotal — Personal | B35: =SUM(B34:B34) -> 1227.31 | C35: =IFERROR(B35/$B$9,0) -> 0.045477738
A36: Credits, Refunds & Payments
A37: Online AMEX Payment | B37: =SUMIFS('Transaction Details'!$D:$D,'Transaction Details'!$C:$C,A37) -> -22509.5 | C37: =IFERROR(B37/$B$9,0) -> -0.83408524
A38: Subtotal — Credits/Payments | B38: =SUM(B37:B37) -> -22509.5 | C38: =IFERROR(B38/$B$9,0) -> -0.83408524
A39: GRAND TOTAL | B39: =B21+B24+B29+B32+B35+B38 -> 4367.05 | C39: =B39/$B$9 -> 0.16182021
A41: SPEND BY MONTH
A42: Month | B42: Charges | C42: Credits | D42: Net
A43: =DATE(2026,3,1) -> 46082 | B43: =SUMIFS('Transaction Details'!$D:$D,'Transaction Details'!$A:$A,">="&DATE(2026,3,1),'Transaction Details'!$A:$A,"<"&DATE(2026,4,1),'Transaction Details'!$D:$D,">0") -> 1035 | C43: =SUMIFS('Transaction Details'!$D:$D,'Transaction Details'!$A:$A,">="&DATE(2026,3,1),'Transaction Details'!$A:$A,"<"&DATE(2026,4,1),'Transaction Details'!$D:$D,"<0") -> 0 | D43: =B43+C43 -> 1035
A44: =DATE(2026,4,1) -> 46113 | B44: =SUMIFS('Transaction Details'!$D:$D,'Transaction Details'!$A:$A,">="&DATE(2026,4,1),'Transaction Details'!$A:$A,"<"&DATE(2026,5,1),'Transaction Details'!$D:$D,">0") -> 423.32 | C44: =SUMIFS('Transaction Details'!$D:$D,'Transaction Details'!$A:$A,">="&DATE(2026,4,1),'Transaction Details'!$A:$A,"<"&DATE(2026,5,1),'Transaction Details'!$D:$D,"<0") -> -1295 | D44: =B44+C44 -> -871.68
...

Sheet Monthly Breakdown
A1: DWG CAPITAL GROUP
A2: Amex Business Platinum | Monthly Breakdown
A4: Period | B4: Feb 21, 2026 – Jun 11, 2026
A6: 46082
A7: Category | B7: Amount | C7: % of Month Charges
A8: DWG Listing Platform | B8: =SUMIFS('Transaction Details'!$D:$D,'Transaction Details'!$C:$C,$A8,'Transaction Details'!$A:$A,">="&DATE(2026,3,1),'Transaction Details'!$A:$A,"<"&DATE(2026,4,1)) -> 0 | C8: =IFERROR(B8/$B$20,0) -> 0
A9: DWG E&O Insurance | B9: =SUMIFS('Transaction Details'!$D:$D,'Transaction Details'!$C:$C,$A9,'Transaction Details'!$A:$A,">="&DATE(2026,3,1),'Transaction Details'!$A:$A,"<"&DATE(2026,4,1)) -> 0 | C9: =IFERROR(B9/$B$20,0) -> 0
A10: DWG-RE Professional Training | B10: =SUMIFS('Transaction Details'!$D:$D,'Transaction Details'!$C:$C,$A10,'Transaction Details'!$A:$A,">="&DATE(2026,3,1),'Transaction Details'!$A:$A,"<"&DATE(2026,4,1)) -> 0 | C10: =IFERROR(B10/$B$20,0) -> 0
A11: Employee Bonus | B11: =SUMIFS('Transaction Details'!$D:$D,'Transaction Details'!$C:$C,$A11,'Transaction Details'!$A:$A,">="&DATE(2026,3,1),'Transaction Details'!$A:$A,"<"&DATE(2026,4,1)) -> 0 | C11: =IFERROR(B11/$B$20,0) -> 0
A12: Membership Fee | B12: =SUMIFS('Transaction Details'!$D:$D,'Transaction Details'!$C:$C,$A12,'Transaction Details'!$A:$A,">="&DATE(2026,3,1),'Transaction Details'!$A:$A,"<"&DATE(2026,4,1)) -> 895 | C12: =IFERROR(B12/$B$20,0) -> 0.8647343
A13: Software & Subscriptions | B13: =SUMIFS('Transaction Details'!$D:$D,'Transaction Details'!$C:$C,$A13,'Transaction Details'!$A:$A,">="&DATE(2026,3,1),'Transaction Details'!$A:$A,"<"&DATE(2026,4,1)) -> 0 | C13: =IFERROR(B13/$B$20,0) -> 0
A14: Team Travel | B14: =SUMIFS('Transaction Details'!$D:$D,'Transaction Details'!$C:$C,$A14,'Transaction Details'!$A:$A,">="&DATE(2026,3,1),'Transaction Details'!$A:$A,"<"&DATE(2026,4,1)) -> 0 | C14: =IFERROR(B14/$B$20,0) -> 0
A15: Team Lunch | B15: =SUMIFS('Transaction Details'!$D:$D,'Transaction Details'!$C:$C,$A15,'Transaction Details'!$A:$A,">="&DATE(2026,3,1),'Transaction Details'!$A:$A,"<"&DATE(2026,4,1)) -> 140 | C15: =IFERROR(B15/$B$20,0) -> 0.1352657
A16: Team Outing | B16: =SUMIFS('Transaction Details'!$D:$D,'Transaction Details'!$C:$C,$A16,'Transaction Details'!$A:$A,">="&DATE(2026,3,1),'Transaction Details'!$A:$A,"<"&DATE(2026,4,1)) -> 0 | C16: =IFERROR(B16/$B$20,0) -> 0
A17: Bridge Loan (JC Whitner) | B17: =SUMIFS('Transaction Details'!$D:$D,'Transaction Details'!$C:$C,$A17,'Transaction Details'!$A:$A,">="&DATE(2026,3,1),'Transaction Details'!$A:$A,"<"&DATE(2026,4,1)) -> 0 | C17: =IFERROR(B17/$B$20,0) -> 0
A18: Personal | B18: =SUMIFS('Transaction Details'!$D:$D,'Transaction Details'!$C:$C,$A18,'Transaction Details'!$A:$A,">="&DATE(2026,3,1),'Transaction Details'!$A:$A,"<"&DATE(2026,4,1)) -> 0 | C18: =IFERROR(B18/$B$20,0) -> 0
A19: Online AMEX Payment | B19: =SUMIFS('Transaction Details'!$D:$D,'Transaction Details'!$C:$C,$A19,'Transaction Details'!$A:$A,">="&DATE(2026,3,1),'Transaction Details'!$A:$A,"<"&DATE(2026,4,1)) -> 0 | C19: =IFERROR(B19/$B$20,0) -> 0
A20: Total Charges | B20: =SUMIFS('Transaction Details'!$D:$D,'Transaction Details'!$A:$A,">="&DATE(2026,3,1),'Transaction Details'!$A:$A,"<"&DATE(2026,4,1),'Transaction Details'!$D:$D,">0") -> 1035
A21: Credits & Payments | B21: =SUMIFS('Transaction Details'!$D:$D,'Transaction Details'!$A:$A,">="&DATE(2026,3,1),'Transaction Details'!$A:$A,"<"&DATE(2026,4,1),'Transaction Details'!$D:$D,"<0") -> 0
A22: Net | B22: =B20+B21 -> 1035
A24: 46113
A25: Category | B25: Amount | C25: % of Month Charges
A26: DWG Listing Platform | B26: =SUMIFS('Transaction Details'!$D:$D,'Transaction Details'!$C:$C,$A26,'Transaction Details'!$A:$A,">="&DATE(2026,4,1),'Transaction Details'!$A:$A,"<"&DATE(2026,5,1)) -> 260 | C26: =IFERROR(B26/$B$38,0) -> 0.61419257
A27: DWG E&O Insurance | B27: =SUMIFS('Transaction Details'!$D:$D,'Transaction Details'!$C:$C,$A27,'Transaction Details'!$A:$A,">="&DATE(2026,4,1),'Transaction Details'!$A:$A,"<"&DATE(2026,5,1)) -> 0 | C27: =IFERROR(B27/$B$38,0) -> 0
A28: DWG-RE Professional Training | B28: =SUMIFS('Transaction Details'!$D:$D,'Transaction Details'!$C:$C,$A28,'Transaction Details'!$A:$A,">="&DATE(2026,4,1),'Transaction Details'!$A:$A,"<"&DATE(2026,5,1)) -> 0 | C28: =IFERROR(B28/$B$38,0) -> 0
A29: Employee Bonus | B29: =SUMIFS('Transaction Details'!$D:$D,'Transaction Details'!$C:$C,$A29,'Transaction Details'!$A:$A,">="&DATE(2026,4,1),'Transaction Details'!$A:$A,"<"&DATE(2026,5,1)) -> 0 | C29: =IFERROR(B29/$B$38,0) -> 0
A30: Membership Fee | B30: =SUMIFS('Transaction Details'!$D:$D,'Transaction Details'!$C:$C,$A30,'Transaction Details'!$A:$A,">="&DATE(2026,4,1),'Transaction Details'!$A:$A,"<"&DATE(2026,5,1)) -> 0 | C30: =IFERROR(B30/$B$38,0) -> 0
A31: Software & Subscriptions | B31: =SUMIFS('Transaction Details'!$D:$D,'Transaction Details'!$C:$C,$A31,'Transaction Details'!$A:$A,">="&DATE(2026,4,1),'Transaction Details'!$A:$A,"<"&DATE(2026,5,1)) -> 163.32 | C31: =IFERROR(B31/$B$38,0) -> 0.38580743
A32: Team Travel | B32: =SUMIFS('Transaction Details'!$D:$D,'Transaction Details'!$C:$C,$A32,'Transaction Details'!$A:$A,">="&DATE(2026,4,1),'Transaction Details'!$A:$A,"<"&DATE(2026,5,1)) -> 0 | C32: =IFERROR(B32/$B$38,0) -> 0
A33: Team Lunch | B33: =SUMIFS('Transaction Details'!$D:$D,'Transaction Details'!$C:$C,$A33,'Transaction Details'!$A:$A,">="&DATE(2026,4,1),'Transaction Details'!$A:$A,"<"&DATE(2026,5,1)) -> 0 | C33: =IFERROR(B33/$B$38,0) -> 0
A34: Team Outing | B34: =SUMIFS('Transaction Details'!$D:$D,'Transaction Details'!$C:$C,$A34,'Transaction Details'!$A:$A,">="&DATE(2026,4,1),'Transaction Details'!$A:$A,"<"&DATE(2026,5,1)) -> 0 | C34: =IFERROR(B34/$B$38,0) -> 0
A35: Bridge Loan (JC Whitner) | B35: =SUMIFS('Transaction Details'!$D:$D,'Transaction Details'!$C:$C,$A35,'Transaction Details'!$A:$A,">="&DATE(2026,4,1),'Transaction Details'!$A:$A,"<"&DATE(2026,5,1)) -> 0 | C35: =IFERROR(B35/$B$38,0) -> 0
A36: Personal | B36: =SUMIFS('Transaction Details'!$D:$D,'Transaction Details'!$C:$C,$A36,'Transaction Details'!$A:$A,">="&DATE(2026,4,1),'Transaction Details'!$A:$A,"<"&DATE(2026,5,1)) -> 0 | C36: =IFERROR(B36/$B$38,0) -> 0
A37: Online AMEX Payment | B37: =SUMIFS('Transaction Details'!$D:$D,'Transaction Details'!$C:$C,$A37,'Transaction Details'!$A:$A,">="&DATE(2026,4,1),'Transaction Details'!$A:$A,"<"&DATE(2026,5,1)) -> -1295 | C37: =IFERROR(B37/$B$38,0) -> -3.0591515
A38: Total Charges | B38: =SUMIFS('Transaction Details'!$D:$D,'Transaction Details'!$A:$A,">="&DATE(2026,4,1),'Transaction Details'!$A:$A,"<"&DATE(2026,5,1),'Transaction Details'!$D:$D,">0") -> 423.32
A39: Credits & Payments | B39: =SUMIFS('Transaction Details'!$D:$D,'Transaction Details'!$A:$A,">="&DATE(2026,4,1),'Transaction Details'!$A:$A,"<"&DATE(2026,5,1),'Transaction Details'!$D:$D,"<0") -> -1295
A40: Net | B40: =B38+B39 -> -871.68
A42: 46143
A43: Category | B43: Amount | C43: % of Month Charges
A44: DWG Listing Platform | B44: =SUMIFS('Transaction Details'!$D:$D,'Transaction Details'!$C:$C,$A44,'Transaction Details'!$A:$A,">="&DATE(2026,5,1),'Transaction Details'!$A:$A,"<"&DATE(2026,6,1)) -> 12162.68 | C44: =IFERROR(B44/$B$56,0) -> 0.55417862
...

Sheet Transaction Details
A1: DWG CAPITAL GROUP
A2: Amex Business Platinum | Transaction Detail
A4: Account Holder | B4: John Dunning
A5: Account | B5: XXXX-XXXXXX-81005
A6: Statement Period | B6: Feb 21, 2026 – Jun 11, 2026
A7: Entity | B7: DWG Capital Group
A9: Date | B9: Merchant | C9: Category | D9: Amount | E9: B/P | F9: Reimb. | G9: Notes | H9: Extended Details | I9: Appears On Statement As
A10: 46183 | B10: ONLINE PAYMENT - THANK YOU | C10: Online AMEX Payment | D10: -4103.05 | H10: ONLINE PAYMENT - THANK YOU | I10: ONLINE PAYMENT - THANK YOU
A11: 46180 | B11: ADOBE Adobe Systems SAN JOSE CA | C11: Software & Subscriptions | D11: 29.99 | E11: B | H11: 577124508 ADOBE.LY/ENUS ADOBE Adobe Systems SAN JOSE CA Description : DEFAULT Price : 0.2999 ADOBE.LY/ENUS | I11: ADOBE Adobe Systems SAN JOSE CA
A12: 46179 | B12: CREXI LOS ANGELES CA | C12: DWG Listing Platform | D12: 260 | E12: B | H12: CH_3TFGUIJL +18882730423 CREXI LOS ANGELES CA +18882730423 | I12: CREXI LOS ANGELES CA
A13: 46179 | B13: Epay3*RealCare InsurSonoma CA | C13: DWG E&O Insurance | D13: 3161.52 | E13: B | H13: CQ9Scz0dEUG https://epay3.com/ Epay3*RealCare Insurance Marke Sonoma CA | I13: Epay3*RealCare InsurSonoma CA
A14: 46178 | B14: SOCIALPILOT LEWES DE | C14: Software & Subscriptions | D14: 50 | E14: B | H14: CH_2TF4IW04 +14154506060 SOCIALPILOT LEWES DE +14154506060 | I14: SOCIALPILOT LEWES DE
A15: 46175 | B15: AMERICAN AIRLINES 800-433-7300 TX | C15: Team Travel | D15: -110.5 | E15: B | H15: 20260601 4806933473 / kristyne PASSENGER TICKET AMERICAN AIRLINES 800-433-7300 TX Carrier : American Airlines Passenger Name : JOSEPH WHITNER Ticket Number : 0012344904230 Departure Day : 05/29 Additional Info : PASSENGER TICKET From : MIAMI INTERNATIONA To : DALLAS/FORT WORTH Class : Y From : DALLAS/FORT WORTH To : SAN JOSE CABO Class : Y From : SAN JOSE CABO To : PHOENIX SKY HARBOR Class : Y From : PHOENIX SKY HARBOR To : MIAMI INTERNATIONA Class : Y | I15: AMERICAN AIRLINES 800-433-7300 TX
A16: 46174 | B16: FIN'S PATIO BAR & GRWEATHERFORD TX | C16: Team Lunch | D16: 80 | E16: B | H16: 73011006153 FINSWEATHERFORD@GMAIL FINSWEATHERFORD@GMAIL.COM FIN'S PATIO BAR & GRILL 92754040660042 WEATHERFORD TX FINSWEATHERFORD@GMAIL.COM | I16: FIN'S PATIO BAR & GRWEATHERFORD TX
A17: 46170 | B17: ONLINE PAYMENT - THANK YOU | C17: Online AMEX Payment | D17: -2500 | H17: ONLINE PAYMENT - THANK YOU | I17: ONLINE PAYMENT - THANK YOU
A18: 46168 | B18: TRAININNG LLC FREMONT CA | C18: DWG-RE Professional Training | D18: 249 | E18: B | H18: CH_3TBLQCHI +15109628903 TRAININNG LLC FREMONT CA +15109628903 | I18: TRAININNG LLC FREMONT CA
A19: 46165 | B19: GRASSHOPPER GROUP, LBOSTON MA | C19: Software & Subscriptions | D19: 46.81 | E19: B | H19: ######LZ5bH 8888959685 / support@ 8888959685 / support@goto GRASSHOPPER GROUP, LLC BOSTON MA 8888959685 / support@goto | I19: GRASSHOPPER GROUP, LBOSTON MA
A20: 46164 | B20: AMERICAN AIRLINES 800-433-7300 TX | C20: Team Travel | D20: 172.22 | E20: B | H20: 20260522 4806933473 / kristyne PASSENGER TICKET AMERICAN AIRLINES 800-433-7300 TX Carrier : American Airlines Passenger Name : WHITNER/JOSEPH Ticket Number : 0012344904230 Departure Day : 05/29 Additional Info : PASSENGER TICKET From : MIAMI INTERNATIONA To : DALLAS/FORT WORTH Class : Y From : DALLAS/FORT WORTH To : SAN JOSE CABO Class : Y From : SAN JOSE CABO To : PHOENIX SKY HARBOR Class : Y From : PHOENIX SKY HARBOR To : MIAMI INTERNATIONA Class : Y | I20: AMERICAN AIRLINES 800-433-7300 TX
A21: 46164 | B21: WORLD MARKET ECOMM 8ALAMEDA CA | C21: Employee Bonus | D21: 489.73 | E21: B | H21: 11080480338 510-808-9164 WORLD MARKET ECOMM 899 ALAMEDA CA Description : BED/BATH/LINEN Price : 0.00 510-808-9164 | I21: WORLD MARKET ECOMM 8ALAMEDA CA
A22: 46162 | B22: QUANTUM LEAP CONSULTSHERIDAN WY | C22: Bridge Loan (JC Whitner) | D22: 2000 | E22: B | H22: ######fC2ej support@optimateai.co support@optimateai.com QUANTUM LEAP CONSULTIN SHERIDAN WY support@optimateai.com | I22: QUANTUM LEAP CONSULTSHERIDAN WY
A23: 46162 | B23: TST* BLUEYS KITCHEN LOS ANGELES CA | C23: Team Travel | D23: 94.05 | E23: B | H23: 21105176141 RESTAURANT TST* BLUEYS KITCHEN MAR V 00098618 LOS ANGELES CA RESTAURANT | I23: TST* BLUEYS KITCHEN LOS ANGELES CA
A24: 46160 | B24: WORLD MARKET ECOMM 8ALAMEDA CA | C24: Employee Bonus | D24: 252.44 | E24: B | H24: 11080480577 510-808-9164 WORLD MARKET ECOMM 899 ALAMEDA CA Description : BED/BATH/LINEN Price : 0.00 510-808-9164 | I24: WORLD MARKET ECOMM 8ALAMEDA CA
A25: 46159 | B25: WORLD MARKET #304 6HAWTHORNE CA | C25: Employee Bonus | D25: 3509.6 | E25: B | H25: 00015082 510-893-7300 WORLD MARKET #304 6304 HAWTHORNE CA Description : ON-BOARD CRUISE SHO Price : 0.00 510-893-7300 | I25: WORLD MARKET #304 6HAWTHORNE CA
A26: 46157 | B26: 800.COM, LLC 800-800-4321 FL | C26: Software & Subscriptions | D26: 69.62 | E26: B | H26: 21105176136 ESTABLISHES 800.COM, LLC 800-800-4321 FL ESTABLISHES | I26: 800.COM, LLC 800-800-4321 FL
A27: 46156 | B27: LEVY @ THE ROXY THEAWest Hollywood CA | C27: Team Outing | D27: 18.56 | E27: B | H27: H9lEqNNZ4jb squareup.com/receipts LEVY @ THE ROXY THEATER West Hollywood CA squareup.com/receipts | I27: LEVY @ THE ROXY THEAWest Hollywood CA
A28: 46156 | B28: LEVY @ THE ROXY THEAWest Hollywood CA | C28: Team Outing | D28: 27.84 | E28: B | H28: x0czWqd4Eyw squareup.com/receipts LEVY @ THE ROXY THEATER West Hollywood CA squareup.com/receipts | I28: LEVY @ THE ROXY THEAWest Hollywood CA
A29: 46155 | B29: AXS.COM*SOUTHERN CALLOS ANGELES CA | C29: Team Outing | D29: 167 | E29: B | H29: 17759953 17759953 76087 AXS.COM*SOUTHERN CAL LOS ANGELES CA 17759953 76087 | I29: AXS.COM*SOUTHERN CALLOS ANGELES CA
A30: 46155 | B30: ONLINE PAYMENT - THANK YOU | C30: Online AMEX Payment | D30: -14494.94 | H30: ONLINE PAYMENT - THANK YOU | I30: ONLINE PAYMENT - THANK YOU
A31: 46155 | B31: ONLINE PAYMENT - THANK YOU | C31: Online AMEX Payment | D31: -116.51 | H31: ONLINE PAYMENT - THANK YOU | I31: ONLINE PAYMENT - THANK YOU
A32: 46155 | B32: RAINBOW BAR & GRILL LOS ANGELES CA | C32: Team Outing | D32: 256.91 | E32: B | H32: 68700010 310-278-4232 RAINBOW BAR & GRILL LOS ANGELES CA Description : FOOD/BEVERAGE Price : 0.00 310-278-4232 | I32: RAINBOW BAR & GRILL LOS ANGELES CA
A33: 46155 | B33: TST* BLUEYS KITCHEN LOS ANGELES CA | C33: Team Lunch | D33: 145.31 | E33: B | H33: 21105176134 RESTAURANT TST* BLUEYS KITCHEN MAR V 00098618 LOS ANGELES CA RESTAURANT | I33: TST* BLUEYS KITCHEN LOS ANGELES CA
A34: 46153 | B34: AIRBNB * HMETZB9K93 SAN FRANCISCO CA | C34: Team Travel | D34: 470.85 | E34: B | H34: JJSQBX5T 4158005959 AIRBNB * HMETZB9K93 SAN FRANCISCO CA 4158005959 | I34: AIRBNB * HMETZB9K93 SAN FRANCISCO CA
A35: 46153 | B35: AMERICAN AIRLINES 800-433-7300 TX | C35: Team Travel | D35: 54.99 | E35: B | H35: 20260511 4806933473 / help@aa. PASSENGER TICKET AMERICAN AIRLINES 800-433-7300 TX Carrier : American Airlines Passenger Name : BISWAS/SOUMI Ticket Number : 0012341816563 Departure Day : 05/14 Additional Info : PASSENGER TICKET From : LOS ANGELES INTERN To : DALLAS/FORT WORTH Class : S | I35: AMERICAN AIRLINES 800-433-7300 TX
A36: 46151 | B36: AIRBNB * INC SAN FRANCISCO CA | C36: Team Travel | D36: 324 | E36: B | H36: D69H34KB 4158005959 AIRBNB * INC SAN FRANCISCO CA 4158005959 | I36: AIRBNB * INC SAN FRANCISCO CA
A37: 46151 | B37: FORT WORTH FLORIST FORT WORTH TX | C37: Personal | D37: 177.31 | E37: P | H37: CH_3TVGF8CK +18172442345 FORT WORTH FLORIST FORT WORTH TX +18172442345 | I37: FORT WORTH FLORIST FORT WORTH TX
A38: 46149 | B38: LIGHTBOX PARENT SHELTON CT | C38: DWG Listing Platform | D38: 11902.68 | E38: B | H38: 96360361 855-337-5126 LIGHTBOX PARENT SHELTON CT Description : BUSINESS SERVICES Price : 0.00 855-337-5126 | I38: LIGHTBOX PARENT SHELTON CT
A39: 46149 | B39: TST* THE BUTCHER'S DVENICE CA | C39: Team Lunch | D39: 158.3 | E39: B | H39: 99999996127 3109813004 TST* THE BUTCHER'S DAUGHT 000037203 VENICE CA Description : RESTAURANTS Price : 1.583 3109813004 | I39: TST* THE BUTCHER'S DVENICE CA
A40: 46148 | B40: CREXI LOS ANGELES CA | C40: DWG Listing Platform | D40: 260 | E40: B | H40: CH_3TU1SDJL +18882730423 CREXI LOS ANGELES CA +18882730423 | I40: CREXI LOS ANGELES CA
A41: 46147 | B41: POWERHOUSE PILATES LOS ANGELES CA | C41: Personal | D41: 1050 | E41: P | H41: CH_3TTRZCCL +18184918387 POWERHOUSE PILATES LOS ANGELES CA +18184918387 | I41: POWERHOUSE PILATES LOS ANGELES CA
A42: 46147 | B42: SOCIALPILOT LEWES DE | C42: Software & Subscriptions | D42: 50 | E42: B | H42: CH_2TTPUW04 +14154506060 SOCIALPILOT LEWES DE +14154506060 | I42: SOCIALPILOT LEWES DE
...
