Workbook

Sheet Transaction Summary
A1: DWG CAPITAL PARTNERS | D1: #VALUE!
A2: Amex Business Platinum | Statement Summary
A4: Account Holder | B4: John Dunning
A5: Account | B5: XXXX-XXXXXX-01004
A6: Statement Period (Past 3 Mon) | B6: February 2026 - May 2026
A8: TOTALS
A9: Charges | B9: ='Transaction Details'!D112 -> 28501.7
A10: Credits & Payments | B10: ='Transaction Details'!D113 -> -18477.34
A11: Net Balance | B11: =B9+B10 -> 10024.36
A13: SPEND BY CATEGORY
A14: Category | B14: Amount | C14: % of Charges
A15: DWGCP / DWG Operating
A16: DWGCP Team Travel | B16: =SUMIFS('Transaction Details'!D:D,'Transaction Details'!C:C,A16) -> 5640.94 | C16: =IFERROR(B16/$B$9,0) -> 0.19791591
A17: Employee Bonus | B17: =SUMIFS('Transaction Details'!D:D,'Transaction Details'!C:C,A17) -> 141.24 | C17: =IFERROR(B17/$B$9,0) -> 0.0049554939
A18: DWGCP Car | B18: =SUMIFS('Transaction Details'!D:D,'Transaction Details'!C:C,A18) -> 2608 | C18: =IFERROR(B18/$B$9,0) -> 0.091503314
A19: DWGCP Professional Training | B19: =SUMIFS('Transaction Details'!D:D,'Transaction Details'!C:C,A19) -> 1484 | C19: =IFERROR(B19/$B$9,0) -> 0.05206707
A20: DWGCP Investor Dinner | B20: =SUMIFS('Transaction Details'!D:D,'Transaction Details'!C:C,A20) -> 1000 | C20: =IFERROR(B20/$B$9,0) -> 0.035085626
A21: DWGCP Investor Meeting | B21: =SUMIFS('Transaction Details'!D:D,'Transaction Details'!C:C,A21) -> 533.23 | C21: =IFERROR(B21/$B$9,0) -> 0.018708709
A22: DWGCP HR | B22: =SUMIFS('Transaction Details'!D:D,'Transaction Details'!C:C,A22) -> 78.49 | C22: =IFERROR(B22/$B$9,0) -> 0.0027538708
A23: DWG Capital Group | B23: =SUMIFS('Transaction Details'!D:D,'Transaction Details'!C:C,A23) -> 1200 | C23: =IFERROR(B23/$B$9,0) -> 0.042102752
A24: JAL Legal Case | B24: =SUMIFS('Transaction Details'!D:D,'Transaction Details'!C:C,A24) -> 109.54 | C24: =IFERROR(B24/$B$9,0) -> 0.0038432795
A25: Notary Services | B25: =SUMIFS('Transaction Details'!D:D,'Transaction Details'!C:C,A25) -> 35 | C25: =IFERROR(B25/$B$9,0) -> 0.0012279969
A26: Annual AMEX Fee | B26: =SUMIFS('Transaction Details'!D:D,'Transaction Details'!C:C,A26) -> 895 | C26: =IFERROR(B26/$B$9,0) -> 0.031401636
A27: Subtotal — Operating | B27: =SUM(B16:B26) -> 13725.44 | C27: =IFERROR(B27/$B$9,0) -> 0.48156566
A28: Technology & Software
A29: Software & Subscriptions | B29: =SUMIFS('Transaction Details'!D:D,'Transaction Details'!C:C,A29) -> 3027.84 | C29: =IFERROR(B29/$B$9,0) -> 0.10623366
A30: Employee Tech Onboarding | B30: =SUMIFS('Transaction Details'!D:D,'Transaction Details'!C:C,A30) -> 1572.28 | C30: =IFERROR(B30/$B$9,0) -> 0.055164429
A31: Recruiting | B31: =SUMIFS('Transaction Details'!D:D,'Transaction Details'!C:C,A31) -> 1841.11 | C31: =IFERROR(B31/$B$9,0) -> 0.064596498
A32: Subtotal — Technology | B32: =SUM(B29:B31) -> 6441.23 | C32: =IFERROR(B32/$B$9,0) -> 0.22599459
A33: Meals & Ground Transport
A34: Team Lunch | B34: =SUMIFS('Transaction Details'!D:D,'Transaction Details'!C:C,A34) -> 719.4 | C34: =IFERROR(B34/$B$9,0) -> 0.0252406
A35: Team Dinner | B35: =SUMIFS('Transaction Details'!D:D,'Transaction Details'!C:C,A35) -> 65.57 | C35: =IFERROR(B35/$B$9,0) -> 0.0023005645
A36: Travel Meal | B36: =SUMIFS('Transaction Details'!D:D,'Transaction Details'!C:C,A36) -> 69.11 | C36: =IFERROR(B36/$B$9,0) -> 0.0024247676
A37: Transportation | B37: =SUMIFS('Transaction Details'!D:D,'Transaction Details'!C:C,A37) -> 163.32 | C37: =IFERROR(B37/$B$9,0) -> 0.0057301845
A38: Subtotal — Meals & Transport | B38: =SUM(B34:B37) -> 1017.4 | C38: =IFERROR(B38/$B$9,0) -> 0.035696116
A39: One-Time / Capital
A40: Auto (One-Time) | B40: =SUMIFS('Transaction Details'!D:D,'Transaction Details'!C:C,A40) -> 6900.58 | C40: =IFERROR(B40/$B$9,0) -> 0.24211117
A41: Subtotal — Capital | B41: =SUM(B40:B40) -> 6900.58 | C41: =IFERROR(B41/$B$9,0) -> 0.24211117
A42: Personal — Reimburse to Company
A43: Personal | B43: =SUMIFS('Transaction Details'!D:D,'Transaction Details'!C:C,A43) -> 217.05 | C43: =IFERROR(B43/$B$9,0) -> 0.0076153352
...

Sheet Monthly Breakdown
A1: DWG CAPITAL PARTNERS | D1: #VALUE!
A2: Amex Business Platinum | Monthly Breakdown
A4: Period | B4: February 2026 - May 2026
A6: 46107
A7: Category | B7: Amount | C7: % of Month Charges
A8: Auto (One-Time) | B8: =SUMIFS('Transaction Details'!D:D,'Transaction Details'!C:C,A8,'Transaction Details'!A:A,">="&DATE(2026,3,1),'Transaction Details'!A:A,"<"&DATE(2026,4,1)) -> 6900.58 | C8: =IFERROR(B8/$B$15,0) -> 0.66670274
A9: DWGCP Team Travel | B9: =SUMIFS('Transaction Details'!D:D,'Transaction Details'!C:C,A9,'Transaction Details'!A:A,">="&DATE(2026,3,1),'Transaction Details'!A:A,"<"&DATE(2026,4,1)) -> 1446.55 | C9: =IFERROR(B9/$B$15,0) -> 0.1397591
A10: Annual AMEX Fee | B10: =SUMIFS('Transaction Details'!D:D,'Transaction Details'!C:C,A10,'Transaction Details'!A:A,">="&DATE(2026,3,1),'Transaction Details'!A:A,"<"&DATE(2026,4,1)) -> 895 | C10: =IFERROR(B10/$B$15,0) -> 0.08647084
A11: Recruiting | B11: =SUMIFS('Transaction Details'!D:D,'Transaction Details'!C:C,A11,'Transaction Details'!A:A,">="&DATE(2026,3,1),'Transaction Details'!A:A,"<"&DATE(2026,4,1)) -> 560 | C11: =IFERROR(B11/$B$15,0) -> 0.05410466
A12: Team Lunch | B12: =SUMIFS('Transaction Details'!D:D,'Transaction Details'!C:C,A12,'Transaction Details'!A:A,">="&DATE(2026,3,1),'Transaction Details'!A:A,"<"&DATE(2026,4,1)) -> 265.56 | C12: =IFERROR(B12/$B$15,0) -> 0.025657203
A13: Personal | B13: =SUMIFS('Transaction Details'!D:D,'Transaction Details'!C:C,A13,'Transaction Details'!A:A,">="&DATE(2026,3,1),'Transaction Details'!A:A,"<"&DATE(2026,4,1)) -> 217.05 | C13: =IFERROR(B13/$B$15,0) -> 0.020970386
A14: Team Dinner | B14: =SUMIFS('Transaction Details'!D:D,'Transaction Details'!C:C,A14,'Transaction Details'!A:A,">="&DATE(2026,3,1),'Transaction Details'!A:A,"<"&DATE(2026,4,1)) -> 65.57 | C14: =IFERROR(B14/$B$15,0) -> 0.006335076
A15: Total Charges | B15: =SUMIFS('Transaction Details'!D:D,'Transaction Details'!A:A,">="&DATE(2026,3,1),'Transaction Details'!A:A,"<"&DATE(2026,4,1),'Transaction Details'!D:D,">0") -> 10350.31
A16: Credits & Payments | B16: =SUMIFS('Transaction Details'!D:D,'Transaction Details'!A:A,">="&DATE(2026,3,1),'Transaction Details'!A:A,"<"&DATE(2026,4,1),'Transaction Details'!D:D,"<0") -> -462.4
A17: Net | B17: =B15+B16 -> 9887.91
A19: 46113
A20: Category | B20: Amount | C20: % of Month Charges
A21: DWGCP Car | B21: =SUMIFS('Transaction Details'!D:D,'Transaction Details'!C:C,A21,'Transaction Details'!A:A,">="&DATE(2026,4,1),'Transaction Details'!A:A,"<"&DATE(2026,5,1)) -> 2608 | C21: =IFERROR(B21/$B$31,0) -> 0.23487011
A22: DWGCP Team Travel | B22: =SUMIFS('Transaction Details'!D:D,'Transaction Details'!C:C,A22,'Transaction Details'!A:A,">="&DATE(2026,4,1),'Transaction Details'!A:A,"<"&DATE(2026,5,1)) -> 2260.59 | C22: =IFERROR(B22/$B$31,0) -> 0.20358321
A23: Software & Subscriptions | B23: =SUMIFS('Transaction Details'!D:D,'Transaction Details'!C:C,A23,'Transaction Details'!A:A,">="&DATE(2026,4,1),'Transaction Details'!A:A,"<"&DATE(2026,5,1)) -> 1774.44 | C23: =IFERROR(B23/$B$31,0) -> 0.15980173
A24: Recruiting | B24: =SUMIFS('Transaction Details'!D:D,'Transaction Details'!C:C,A24,'Transaction Details'!A:A,">="&DATE(2026,4,1),'Transaction Details'!A:A,"<"&DATE(2026,5,1)) -> 1281.11 | C24: =IFERROR(B24/$B$31,0) -> 0.11537364
A25: DWGCP Professional Training | B25: =SUMIFS('Transaction Details'!D:D,'Transaction Details'!C:C,A25,'Transaction Details'!A:A,">="&DATE(2026,4,1),'Transaction Details'!A:A,"<"&DATE(2026,5,1)) -> 1235 | C25: =IFERROR(B25/$B$31,0) -> 0.11122108
A26: DWG Capital Group | B26: =SUMIFS('Transaction Details'!D:D,'Transaction Details'!C:C,A26,'Transaction Details'!A:A,">="&DATE(2026,4,1),'Transaction Details'!A:A,"<"&DATE(2026,5,1)) -> 1200 | C26: =IFERROR(B26/$B$31,0) -> 0.10806907
A27: DWGCP Investor Meeting | B27: =SUMIFS('Transaction Details'!D:D,'Transaction Details'!C:C,A27,'Transaction Details'!A:A,">="&DATE(2026,4,1),'Transaction Details'!A:A,"<"&DATE(2026,5,1)) -> 533.23 | C27: =IFERROR(B27/$B$31,0) -> 0.04802139
A28: Transportation | B28: =SUMIFS('Transaction Details'!D:D,'Transaction Details'!C:C,A28,'Transaction Details'!A:A,">="&DATE(2026,4,1),'Transaction Details'!A:A,"<"&DATE(2026,5,1)) -> 98.15 | C28: =IFERROR(B28/$B$31,0) -> 0.0088391491
A29: DWGCP HR | B29: =SUMIFS('Transaction Details'!D:D,'Transaction Details'!C:C,A29,'Transaction Details'!A:A,">="&DATE(2026,4,1),'Transaction Details'!A:A,"<"&DATE(2026,5,1)) -> 78.49 | C29: =IFERROR(B29/$B$31,0) -> 0.0070686176
A30: Notary Services | B30: =SUMIFS('Transaction Details'!D:D,'Transaction Details'!C:C,A30,'Transaction Details'!A:A,">="&DATE(2026,4,1),'Transaction Details'!A:A,"<"&DATE(2026,5,1)) -> 35 | C30: =IFERROR(B30/$B$31,0) -> 0.0031520145
A31: Total Charges | B31: =SUMIFS('Transaction Details'!D:D,'Transaction Details'!A:A,">="&DATE(2026,4,1),'Transaction Details'!A:A,"<"&DATE(2026,5,1),'Transaction Details'!D:D,">0") -> 11104.01
A32: Credits & Payments | B32: =SUMIFS('Transaction Details'!D:D,'Transaction Details'!A:A,">="&DATE(2026,4,1),'Transaction Details'!A:A,"<"&DATE(2026,5,1),'Transaction Details'!D:D,"<0") -> -1591.53
A33: Net | B33: =B31+B32 -> 9512.48
A35: 46143
A36: Category | B36: Amount | C36: % of Month Charges
A37: DWGCP Team Travel | B37: =SUMIFS('Transaction Details'!D:D,'Transaction Details'!C:C,A37,'Transaction Details'!A:A,">="&DATE(2026,5,1),'Transaction Details'!A:A,"<"&DATE(2026,6,1)) -> 1933.8 | C37: =IFERROR(B37/$B$48,0) -> 0.27439985
A38: Employee Tech Onboarding | B38: =SUMIFS('Transaction Details'!D:D,'Transaction Details'!C:C,A38,'Transaction Details'!A:A,">="&DATE(2026,5,1),'Transaction Details'!A:A,"<"&DATE(2026,6,1)) -> 1572.28 | C38: =IFERROR(B38/$B$48,0) -> 0.22310135
A39: Software & Subscriptions | B39: =SUMIFS('Transaction Details'!D:D,'Transaction Details'!C:C,A39,'Transaction Details'!A:A,">="&DATE(2026,5,1),'Transaction Details'!A:A,"<"&DATE(2026,6,1)) -> 1253.4 | C39: =IFERROR(B39/$B$48,0) -> 0.17785333
A40: DWGCP Investor Dinner | B40: =SUMIFS('Transaction Details'!D:D,'Transaction Details'!C:C,A40,'Transaction Details'!A:A,">="&DATE(2026,5,1),'Transaction Details'!A:A,"<"&DATE(2026,6,1)) -> 1000 | C40: =IFERROR(B40/$B$48,0) -> 0.1418967
A41: Team Lunch | B41: =SUMIFS('Transaction Details'!D:D,'Transaction Details'!C:C,A41,'Transaction Details'!A:A,">="&DATE(2026,5,1),'Transaction Details'!A:A,"<"&DATE(2026,6,1)) -> 453.84 | C41: =IFERROR(B41/$B$48,0) -> 0.064398401
A42: DWGCP Professional Training | B42: =SUMIFS('Transaction Details'!D:D,'Transaction Details'!C:C,A42,'Transaction Details'!A:A,">="&DATE(2026,5,1),'Transaction Details'!A:A,"<"&DATE(2026,6,1)) -> 249 | C42: =IFERROR(B42/$B$48,0) -> 0.03533228
A43: Personal Health | B43: =SUMIFS('Transaction Details'!D:D,'Transaction Details'!C:C,A43,'Transaction Details'!A:A,">="&DATE(2026,5,1),'Transaction Details'!A:A,"<"&DATE(2026,6,1)) -> 200 | C43: =IFERROR(B43/$B$48,0) -> 0.028379341
A44: Employee Bonus | B44: =SUMIFS('Transaction Details'!D:D,'Transaction Details'!C:C,A44,'Transaction Details'!A:A,">="&DATE(2026,5,1),'Transaction Details'!A:A,"<"&DATE(2026,6,1)) -> 141.24 | C44: =IFERROR(B44/$B$48,0) -> 0.020041491
...

Sheet Transaction Details
A1: DWG CAPITAL PARTNERS
A2: Amex Business Platinum | Transaction Detail
A4: Account Holder | B4: John Dunning
A5: Account | B5: XXXX-XXXXXX-01004
A6: Statement Period | B6: Feb 21, 2026 – May 29, 2026
A7: Entity | B7: DWG Capital Partners
A9: Date | B9: Merchant | C9: Category | D9: Amount | E9: B/P | F9: Reimb. | G9: Notes
A10: 46170 | B10: INTUIT QUICKBOOKS | C10: Software & Subscriptions | D10: 4.25 | E10: B
A11: 46169 | B11: ANTHROPIC | C11: Software & Subscriptions | D11: 11.51 | E11: B
A12: 46169 | B12: BESTBUYCOM | C12: Employee Tech Onboarding | D12: 108.24 | E12: B
A13: 46169 | B13: BESTBUYCOM | C13: Employee Tech Onboarding | D13: 1464.04 | E13: B
A14: 46168 | B14: ANTHROPIC | C14: Software & Subscriptions | D14: 10.62 | E14: B
A15: 46168 | B15: ANTHROPIC | C15: Software & Subscriptions | D15: 10.67 | E15: B
A16: 46168 | B16: DELBAR OLD MILTON LLC | C16: DWGCP Investor Dinner | D16: 1000 | E16: B | G16: Alpharetta GA
A17: 46168 | B17: TRAININNG LLC | C17: DWGCP Professional Training | D17: 249 | E17: B | G17: Training
A18: 46167 | B18: UBER EATS | C18: Team Lunch | D18: 35.42 | E18: P?
A19: 46166 | B19: UBER | C19: Transportation | D19: 28.2 | E19: B
A20: 46165 | B20: AMERICAN AIRLINES | C20: DWGCP Team Travel | D20: 49.46 | E20: B | G20: Dunning seat upgrade
A21: 46165 | B21: CLAUDE.AI SUBSCRIPTION | C21: Software & Subscriptions | D21: 105.4 | E21: B
A22: 46164 | B22: LUGG | C22: Employee Bonus | D22: 141.24 | E22: B | G22: Helping move
A23: 46162 | B23: CAMPAIGNER SVC | C23: Software & Subscriptions | D23: 584 | E23: B | G23: Email marketing
A24: 46161 | B24: ANTHROPIC | C24: Software & Subscriptions | D24: 10.98 | E24: B
A25: 46161 | B25: UBER | C25: Transportation | D25: 5.76 | E25: B
A26: 46158 | B26: ANTHROPIC | C26: Software & Subscriptions | D26: 11.06 | E26: B
A27: 46158 | B27: ANTHROPIC | C27: Software & Subscriptions | D27: 11.68 | E27: B
A28: 46158 | B28: NIMBUS HEALTH FIRST | C28: Personal Health | D28: 200 | E28: P? | G28: Marked w/ receipt; verify
A29: 46156 | B29: ANTHROPIC | C29: Software & Subscriptions | D29: 12.13 | E29: B
A30: 46156 | B30: TST* BLUEYS KITCHEN | C30: Team Lunch | D30: 99.44 | E30: P?
A31: 46155 | B31: ANTHROPIC | C31: Software & Subscriptions | D31: 11.66 | E31: B
A32: 46155 | B32: ANTHROPIC | C32: Software & Subscriptions | D32: 12.19 | E32: B
A33: 46155 | B33: ANTHROPIC | C33: Software & Subscriptions | D33: 12.21 | E33: B
A34: 46155 | B34: ANTHROPIC | C34: Software & Subscriptions | D34: 13.5 | E34: B
A35: 46155 | B35: ANTHROPIC | C35: Software & Subscriptions | D35: 15.8 | E35: B
A36: 46155 | B36: ONLINE PAYMENT - THANK YOU | C36: Payment | D36: -15821.6 | G36: Payment received
A37: 46154 | B37: ANTHROPIC | C37: Software & Subscriptions | D37: 11.46 | E37: B
A38: 46154 | B38: ANTHROPIC | C38: Software & Subscriptions | D38: 11.53 | E38: B
A39: 46154 | B39: ANTHROPIC | C39: Software & Subscriptions | D39: 11.94 | E39: B
A40: 46154 | B40: ANTHROPIC | C40: Software & Subscriptions | D40: 13.46 | E40: B
A41: 46154 | B41: CAMDEN & MERIDEW PC | C41: JAL Legal Case | D41: 109.54 | E41: B | G41: Legal services
A42: 46153 | B42: ANTHROPIC | C42: Software & Subscriptions | D42: 10.75 | E42: B
...
