Workbook

Sheet Transaction Summary
A1: POSEIDON PARTNERS
A2: Amex Business Platinum | Statement Summary
A4: Account Holder | B4: John Dunning
A5: Account | B5: XXXX-XXXXXX-02000
A6: Statement Period (Detail) | B6: March 2026 - June 2026
A8: TOTALS
A9: Charges | B9: =SUMIF('Transaction Details'!$E$8:$E$312,">0") -> 55260.92
A10: Credits & Payments | B10: =SUMIF('Transaction Details'!$E$8:$E$312,"<0") -> -47495.04
A11: Net Balance | B11: =B9+B10 -> 7765.88
A13: SPEND BY CATEGORY
A14: Category | B14: Amount | C14: % of Charges
A15: DWG / Business
A16: Team Travel | B16: =SUMIFS('Transaction Details'!$E$8:$E$312,'Transaction Details'!$J$8:$J$312,A16) -> 2568.87 | C16: =IFERROR(B16/$B$9,0) -> 0.046486197
A17: DWG Business Development | B17: =SUMIFS('Transaction Details'!$E$8:$E$312,'Transaction Details'!$J$8:$J$312,A17) -> 809.53 | C17: =IFERROR(B17/$B$9,0) -> 0.014649231
A18: DWG Listing Platform | B18: =SUMIFS('Transaction Details'!$E$8:$E$312,'Transaction Details'!$J$8:$J$312,A18) -> 1505 | C18: =IFERROR(B18/$B$9,0) -> 0.027234436
A19: Insurance | B19: =SUMIFS('Transaction Details'!$E$8:$E$312,'Transaction Details'!$J$8:$J$312,A19) -> 25.5 | C19: =IFERROR(B19/$B$9,0) -> 0.00046144726
A20: Realtor Association | B20: =SUMIFS('Transaction Details'!$E$8:$E$312,'Transaction Details'!$J$8:$J$312,A20) -> 1031 | C20: =IFERROR(B20/$B$9,0) -> 0.018656946
A21: Subtotal — DWG / Business | B21: =SUM(B16:B20) -> 5939.9 | C21: =IFERROR(B21/$B$9,0) -> 0.10748826
A22: Software, Subscriptions & Comms
A23: Software & Subscriptions | B23: =SUMIFS('Transaction Details'!$E$8:$E$312,'Transaction Details'!$J$8:$J$312,A23) -> 1346.54 | C23: =IFERROR(B23/$B$9,0) -> 0.024366949
A24: AI Subscription | B24: =SUMIFS('Transaction Details'!$E$8:$E$312,'Transaction Details'!$J$8:$J$312,A24) -> 41.28 | C24: =IFERROR(B24/$B$9,0) -> 0.00074700168
A25: Linkedin | B25: =SUMIFS('Transaction Details'!$E$8:$E$312,'Transaction Details'!$J$8:$J$312,A25) -> 636.57 | C25: =IFERROR(B25/$B$9,0) -> 0.011519352
A26: AT&T | B26: =SUMIFS('Transaction Details'!$E$8:$E$312,'Transaction Details'!$J$8:$J$312,A26) -> 746.01 | C26: =IFERROR(B26/$B$9,0) -> 0.013499775
A27: Subtotal — Software & Comms | B27: =SUM(B23:B26) -> 2770.4 | C27: =IFERROR(B27/$B$9,0) -> 0.050133078
A28: Travel
A29: Judd & Angela - Portugal | B29: =SUMIFS('Transaction Details'!$E$8:$E$312,'Transaction Details'!$J$8:$J$312,A29) -> 26514.68 | C29: =IFERROR(B29/$B$9,0) -> 0.47980888
A30: Personal - Travel | B30: =SUMIFS('Transaction Details'!$E$8:$E$312,'Transaction Details'!$J$8:$J$312,A30) -> 50 | C30: =IFERROR(B30/$B$9,0) -> 0.00090479854
A31: Subtotal — Travel | B31: =SUM(B29:B30) -> 26564.68 | C31: =IFERROR(B31/$B$9,0) -> 0.48071368
A32: Personal / Living
A33: Personal - Food | B33: =SUMIFS('Transaction Details'!$E$8:$E$312,'Transaction Details'!$J$8:$J$312,A33) -> 6710.17 | C33: =IFERROR(B33/$B$9,0) -> 0.12142704
A34: Personal - Health | B34: =SUMIFS('Transaction Details'!$E$8:$E$312,'Transaction Details'!$J$8:$J$312,A34) -> 4769.86 | C34: =IFERROR(B34/$B$9,0) -> 0.086315248
A35: Personal - House | B35: =SUMIFS('Transaction Details'!$E$8:$E$312,'Transaction Details'!$J$8:$J$312,A35) -> 2292.62 | C35: =IFERROR(B35/$B$9,0) -> 0.041487185
A36: Personal - Car | B36: =SUMIFS('Transaction Details'!$E$8:$E$312,'Transaction Details'!$J$8:$J$312,A36) -> 591.38 | C36: =IFERROR(B36/$B$9,0) -> 0.010701595
A37: Personal - Clothing | B37: =SUMIFS('Transaction Details'!$E$8:$E$312,'Transaction Details'!$J$8:$J$312,A37) -> 1141.3 | C37: =IFERROR(B37/$B$9,0) -> 0.020652932
A38: Personal - Family | B38: =SUMIFS('Transaction Details'!$E$8:$E$312,'Transaction Details'!$J$8:$J$312,A38) -> 750.26 | C38: =IFERROR(B38/$B$9,0) -> 0.013576683
A39: Personal - Entertainment | B39: =SUMIFS('Transaction Details'!$E$8:$E$312,'Transaction Details'!$J$8:$J$312,A39) -> 699.21 | C39: =IFERROR(B39/$B$9,0) -> 0.012652884
A40: Personal | B40: =SUMIFS('Transaction Details'!$E$8:$E$312,'Transaction Details'!$J$8:$J$312,A40) -> 189 | C40: =IFERROR(B40/$B$9,0) -> 0.0034201385
A41: Personal - ? | B41: =SUMIFS('Transaction Details'!$E$8:$E$312,'Transaction Details'!$J$8:$J$312,A41) -> 160.35 | C41: =IFERROR(B41/$B$9,0) -> 0.0029016889
A42: Amazon | B42: =SUMIFS('Transaction Details'!$E$8:$E$312,'Transaction Details'!$J$8:$J$312,A42) -> 685.26 | C42: =IFERROR(B42/$B$9,0) -> 0.012400445
A43: Shipping | B43: =SUMIFS('Transaction Details'!$E$8:$E$312,'Transaction Details'!$J$8:$J$312,A43) -> 12.75 | C43: =IFERROR(B43/$B$9,0) -> 0.00023072363
...

Sheet Monthly Breakdown
A1: POSEIDON PARTNERS
A2: Amex Business Platinum | Monthly Breakdown
A4: Category | B4: =DATE(2026,3,1) -> 46082 | C4: =DATE(2026,4,1) -> 46113 | D4: =DATE(2026,5,1) -> 46143 | E4: =DATE(2026,6,1) -> 46174 | F4: Total
A5: Team Travel | B5: =SUMIFS('Transaction Details'!$E$8:$E$312,'Transaction Details'!$J$8:$J$312,$A5,'Transaction Details'!$I$8:$I$312,B$4) -> 1927.42 | C5: =SUMIFS('Transaction Details'!$E$8:$E$312,'Transaction Details'!$J$8:$J$312,$A5,'Transaction Details'!$I$8:$I$312,C$4) -> 0 | D5: =SUMIFS('Transaction Details'!$E$8:$E$312,'Transaction Details'!$J$8:$J$312,$A5,'Transaction Details'!$I$8:$I$312,D$4) -> 463.4 | E5: =SUMIFS('Transaction Details'!$E$8:$E$312,'Transaction Details'!$J$8:$J$312,$A5,'Transaction Details'!$I$8:$I$312,E$4) -> 178.05 | F5: =SUM(B5:E5) -> 2568.87
A6: DWG Business Development | B6: =SUMIFS('Transaction Details'!$E$8:$E$312,'Transaction Details'!$J$8:$J$312,$A6,'Transaction Details'!$I$8:$I$312,B$4) -> 774.53 | C6: =SUMIFS('Transaction Details'!$E$8:$E$312,'Transaction Details'!$J$8:$J$312,$A6,'Transaction Details'!$I$8:$I$312,C$4) -> 35 | D6: =SUMIFS('Transaction Details'!$E$8:$E$312,'Transaction Details'!$J$8:$J$312,$A6,'Transaction Details'!$I$8:$I$312,D$4) -> 0 | E6: =SUMIFS('Transaction Details'!$E$8:$E$312,'Transaction Details'!$J$8:$J$312,$A6,'Transaction Details'!$I$8:$I$312,E$4) -> 0 | F6: =SUM(B6:E6) -> 809.53
A7: DWG Listing Platform | B7: =SUMIFS('Transaction Details'!$E$8:$E$312,'Transaction Details'!$J$8:$J$312,$A7,'Transaction Details'!$I$8:$I$312,B$4) -> 1505 | C7: =SUMIFS('Transaction Details'!$E$8:$E$312,'Transaction Details'!$J$8:$J$312,$A7,'Transaction Details'!$I$8:$I$312,C$4) -> 0 | D7: =SUMIFS('Transaction Details'!$E$8:$E$312,'Transaction Details'!$J$8:$J$312,$A7,'Transaction Details'!$I$8:$I$312,D$4) -> 0 | E7: =SUMIFS('Transaction Details'!$E$8:$E$312,'Transaction Details'!$J$8:$J$312,$A7,'Transaction Details'!$I$8:$I$312,E$4) -> 0 | F7: =SUM(B7:E7) -> 1505
A8: Realtor Association | B8: =SUMIFS('Transaction Details'!$E$8:$E$312,'Transaction Details'!$J$8:$J$312,$A8,'Transaction Details'!$I$8:$I$312,B$4) -> 1031 | C8: =SUMIFS('Transaction Details'!$E$8:$E$312,'Transaction Details'!$J$8:$J$312,$A8,'Transaction Details'!$I$8:$I$312,C$4) -> 0 | D8: =SUMIFS('Transaction Details'!$E$8:$E$312,'Transaction Details'!$J$8:$J$312,$A8,'Transaction Details'!$I$8:$I$312,D$4) -> 0 | E8: =SUMIFS('Transaction Details'!$E$8:$E$312,'Transaction Details'!$J$8:$J$312,$A8,'Transaction Details'!$I$8:$I$312,E$4) -> 0 | F8: =SUM(B8:E8) -> 1031
A9: Insurance | B9: =SUMIFS('Transaction Details'!$E$8:$E$312,'Transaction Details'!$J$8:$J$312,$A9,'Transaction Details'!$I$8:$I$312,B$4) -> 25.5 | C9: =SUMIFS('Transaction Details'!$E$8:$E$312,'Transaction Details'!$J$8:$J$312,$A9,'Transaction Details'!$I$8:$I$312,C$4) -> 0 | D9: =SUMIFS('Transaction Details'!$E$8:$E$312,'Transaction Details'!$J$8:$J$312,$A9,'Transaction Details'!$I$8:$I$312,D$4) -> 0 | E9: =SUMIFS('Transaction Details'!$E$8:$E$312,'Transaction Details'!$J$8:$J$312,$A9,'Transaction Details'!$I$8:$I$312,E$4) -> 0 | F9: =SUM(B9:E9) -> 25.5
A10: Software & Subscriptions | B10: =SUMIFS('Transaction Details'!$E$8:$E$312,'Transaction Details'!$J$8:$J$312,$A10,'Transaction Details'!$I$8:$I$312,B$4) -> 1346.54 | C10: =SUMIFS('Transaction Details'!$E$8:$E$312,'Transaction Details'!$J$8:$J$312,$A10,'Transaction Details'!$I$8:$I$312,C$4) -> 0 | D10: =SUMIFS('Transaction Details'!$E$8:$E$312,'Transaction Details'!$J$8:$J$312,$A10,'Transaction Details'!$I$8:$I$312,D$4) -> 0 | E10: =SUMIFS('Transaction Details'!$E$8:$E$312,'Transaction Details'!$J$8:$J$312,$A10,'Transaction Details'!$I$8:$I$312,E$4) -> 0 | F10: =SUM(B10:E10) -> 1346.54
A11: AI Subscription | B11: =SUMIFS('Transaction Details'!$E$8:$E$312,'Transaction Details'!$J$8:$J$312,$A11,'Transaction Details'!$I$8:$I$312,B$4) -> 41.28 | C11: =SUMIFS('Transaction Details'!$E$8:$E$312,'Transaction Details'!$J$8:$J$312,$A11,'Transaction Details'!$I$8:$I$312,C$4) -> 0 | D11: =SUMIFS('Transaction Details'!$E$8:$E$312,'Transaction Details'!$J$8:$J$312,$A11,'Transaction Details'!$I$8:$I$312,D$4) -> 0 | E11: =SUMIFS('Transaction Details'!$E$8:$E$312,'Transaction Details'!$J$8:$J$312,$A11,'Transaction Details'!$I$8:$I$312,E$4) -> 0 | F11: =SUM(B11:E11) -> 41.28
A12: Linkedin | B12: =SUMIFS('Transaction Details'!$E$8:$E$312,'Transaction Details'!$J$8:$J$312,$A12,'Transaction Details'!$I$8:$I$312,B$4) -> 636.57 | C12: =SUMIFS('Transaction Details'!$E$8:$E$312,'Transaction Details'!$J$8:$J$312,$A12,'Transaction Details'!$I$8:$I$312,C$4) -> 0 | D12: =SUMIFS('Transaction Details'!$E$8:$E$312,'Transaction Details'!$J$8:$J$312,$A12,'Transaction Details'!$I$8:$I$312,D$4) -> 0 | E12: =SUMIFS('Transaction Details'!$E$8:$E$312,'Transaction Details'!$J$8:$J$312,$A12,'Transaction Details'!$I$8:$I$312,E$4) -> 0 | F12: =SUM(B12:E12) -> 636.57
A13: AT&T | B13: =SUMIFS('Transaction Details'!$E$8:$E$312,'Transaction Details'!$J$8:$J$312,$A13,'Transaction Details'!$I$8:$I$312,B$4) -> 992.74 | C13: =SUMIFS('Transaction Details'!$E$8:$E$312,'Transaction Details'!$J$8:$J$312,$A13,'Transaction Details'!$I$8:$I$312,C$4) -> -246.73 | D13: =SUMIFS('Transaction Details'!$E$8:$E$312,'Transaction Details'!$J$8:$J$312,$A13,'Transaction Details'!$I$8:$I$312,D$4) -> 0 | E13: =SUMIFS('Transaction Details'!$E$8:$E$312,'Transaction Details'!$J$8:$J$312,$A13,'Transaction Details'!$I$8:$I$312,E$4) -> 0 | F13: =SUM(B13:E13) -> 746.01
A14: Judd & Angela - Portugal | B14: =SUMIFS('Transaction Details'!$E$8:$E$312,'Transaction Details'!$J$8:$J$312,$A14,'Transaction Details'!$I$8:$I$312,B$4) -> 969.65 | C14: =SUMIFS('Transaction Details'!$E$8:$E$312,'Transaction Details'!$J$8:$J$312,$A14,'Transaction Details'!$I$8:$I$312,C$4) -> 25343.05 | D14: =SUMIFS('Transaction Details'!$E$8:$E$312,'Transaction Details'!$J$8:$J$312,$A14,'Transaction Details'!$I$8:$I$312,D$4) -> 201.98 | E14: =SUMIFS('Transaction Details'!$E$8:$E$312,'Transaction Details'!$J$8:$J$312,$A14,'Transaction Details'!$I$8:$I$312,E$4) -> 0 | F14: =SUM(B14:E14) -> 26514.68
A15: Personal - Travel | B15: =SUMIFS('Transaction Details'!$E$8:$E$312,'Transaction Details'!$J$8:$J$312,$A15,'Transaction Details'!$I$8:$I$312,B$4) -> 0 | C15: =SUMIFS('Transaction Details'!$E$8:$E$312,'Transaction Details'!$J$8:$J$312,$A15,'Transaction Details'!$I$8:$I$312,C$4) -> 0 | D15: =SUMIFS('Transaction Details'!$E$8:$E$312,'Transaction Details'!$J$8:$J$312,$A15,'Transaction Details'!$I$8:$I$312,D$4) -> 50 | E15: =SUMIFS('Transaction Details'!$E$8:$E$312,'Transaction Details'!$J$8:$J$312,$A15,'Transaction Details'!$I$8:$I$312,E$4) -> 0 | F15: =SUM(B15:E15) -> 50
A16: Personal - Food | B16: =SUMIFS('Transaction Details'!$E$8:$E$312,'Transaction Details'!$J$8:$J$312,$A16,'Transaction Details'!$I$8:$I$312,B$4) -> 2247.27 | C16: =SUMIFS('Transaction Details'!$E$8:$E$312,'Transaction Details'!$J$8:$J$312,$A16,'Transaction Details'!$I$8:$I$312,C$4) -> 1207.32 | D16: =SUMIFS('Transaction Details'!$E$8:$E$312,'Transaction Details'!$J$8:$J$312,$A16,'Transaction Details'!$I$8:$I$312,D$4) -> 2445.17 | E16: =SUMIFS('Transaction Details'!$E$8:$E$312,'Transaction Details'!$J$8:$J$312,$A16,'Transaction Details'!$I$8:$I$312,E$4) -> 810.41 | F16: =SUM(B16:E16) -> 6710.17
... A32: Amex Online Flight Statement Credit | B32: =SUMIFS('Transaction Details'!$E$8:$E$312,'Transaction Details'!$J$8:$J$312,$A32,'Transaction Details'!$I$8:$I$312,B$4) -> -151.2 | C32: =SUMIFS('Transaction Details'!$E$8:$E$312,'Transaction Details'!$J$8:$J$312,$A32,'Transaction Details'!$I$8:$I$312,C$4) -> 0 | D32: =SUMIFS('Transaction Details'!$E$8:$E$312,'Transaction Details'!$J$8:$J$312,$A32,'Transaction Details'!$I$8:$I$312,D$4) -> 0 | E32: =SUMIFS('Transaction Details'!$E$8:$E$312,'Transaction Details'!$J$8:$J$312,$A32,'Transaction Details'!$I$8:$I$312,E$4) -> 0 | F32: =SUM(B32:E32) -> -151.2
A34: Total Charges | B34: =SUMIFS('Transaction Details'!$E$8:$E$312,'Transaction Details'!$I$8:$I$312,B$4,'Transaction Details'!$E$8:$E$312,">0") -> 16220.84 | C34: =SUMIFS('Transaction Details'!$E$8:$E$312,'Transaction Details'!$I$8:$I$312,C$4,'Transaction Details'!$E$8:$E$312,">0") -> 28524.66 | D34: =SUMIFS('Transaction Details'!$E$8:$E$312,'Transaction Details'!$I$8:$I$312,D$4,'Transaction Details'!$E$8:$E$312,">0") -> 8440.97 | E34: =SUMIFS('Transaction Details'!$E$8:$E$312,'Transaction Details'!$I$8:$I$312,E$4,'Transaction Details'!$E$8:$E$312,">0") -> 2074.45 | F34: =SUM(B34:E34) -> 55260.92
A35: Total Credits & Payments | B35: =SUMIFS('Transaction Details'!$E$8:$E$312,'Transaction Details'!$I$8:$I$312,B$4,'Transaction Details'!$E$8:$E$312,"<0") -> -17080.19 | C35: =SUMIFS('Transaction Details'!$E$8:$E$312,'Transaction Details'!$I$8:$I$312,C$4,'Transaction Details'!$E$8:$E$312,"<0") -> -2832.96 | D35: =SUMIFS('Transaction Details'!$E$8:$E$312,'Transaction Details'!$I$8:$I$312,D$4,'Transaction Details'!$E$8:$E$312,"<0") -> -27581.89 | E35: =SUMIFS('Transaction Details'!$E$8:$E$312,'Transaction Details'!$I$8:$I$312,E$4,'Transaction Details'!$E$8:$E$312,"<0") -> 0 | F35: =SUM(B35:E35) -> -47495.04
A36: Net | B36: =B34+B35 -> -859.35 | C36: =C34+C35 -> 25691.7 | D36: =D34+D35 -> -19140.92 | E36: =E34+E35 -> 2074.45 | F36: =SUM(B36:E36) -> 7765.88
A38: =IF(ROUND(F36-'Transaction Summary'!B11,2)=0,"✓ Net ties to Transaction Summary","⚠ mismatch") -> ✓ Net ties to Transaction Summary

Sheet Transaction Details
A1: Transaction Details | C1: Business Platinum Card® / Jan 01, 2026 to Jun 11, 2026
A2: Prepared for
A3: JOHN DUNNING
A4: Account Number
A5: XXXX-XXXXXX-02000
A7: Date | B7: Description | C7: Card Member | D7: Account # | E7: Amount | F7: Extended Details | G7: Appears On Your Statement As | H7: Category | I7: Month | J7: Category (clean)
A8: 06/10/2026 | B8: AMAZON.COM AMZN.COM/BILL WA | C8: JOHN DUNNING | D8: -02000 | E8: 35.8 | F8: 49EUX7L0ZK1 BOOK STORES AMAZON.COM AMZN.COM/BILL WA BOOK STORES | G8: AMAZON.COM AMZN.COM/BILL WA | H8: Amazon | I8: =DATE(RIGHT(A8,4)+0,LEFT(A8,2)+0,1) -> 46174 | J8: =IF(TRIM(H8)="","(Uncategorized)",TRIM(H8)) -> Amazon
A9: 06/10/2026 | B9: AMAZON.COM AMZN.COM/BILL WA | C9: JOHN DUNNING | D9: -02000 | E9: 89.09 | F9: 5PQYRAAK7EI BOOK STORES AMAZON.COM AMZN.COM/BILL WA BOOK STORES | G9: AMAZON.COM AMZN.COM/BILL WA | H9: Amazon | I9: =DATE(RIGHT(A9,4)+0,LEFT(A9,2)+0,1) -> 46174 | J9: =IF(TRIM(H9)="","(Uncategorized)",TRIM(H9)) -> Amazon
A10: 06/10/2026 | B10: PRIME VIDEO *421V62J888-802-3080 WA | C10: JOHN DUNNING | D10: -02000 | E10: 6.39 | F10: 1QQLEKSJV1W DIGITAL PRIME VIDEO *421V62JU3 888-802-3080 WA DIGITAL | G10: PRIME VIDEO *421V62J888-802-3080 WA | H10: Amazon | I10: =DATE(RIGHT(A10,4)+0,LEFT(A10,2)+0,1) -> 46174 | J10: =IF(TRIM(H10)="","(Uncategorized)",TRIM(H10)) -> Amazon
A11: 06/09/2026 | B11: AMAZON DIGITAL SVCS AMZN.COM/BILL WA | C11: JOHN DUNNING | D11: -02000 | E11: 7.46 | F11: 3M4J82I4YYO DIGITAL AMAZON DIGITAL SVCS AMZN.COM/BILL WA DIGITAL | G11: AMAZON DIGITAL SVCS AMZN.COM/BILL WA | H11: Amazon | I11: =DATE(RIGHT(A11,4)+0,LEFT(A11,2)+0,1) -> 46174 | J11: =IF(TRIM(H11)="","(Uncategorized)",TRIM(H11)) -> Amazon
A12: 06/09/2026 | B12: COWBOY EXPRESS WEATHWEATHERFORD TX | C12: JOHN DUNNING | D12: -02000 | E12: 21 | F12: 73011006160 MARCOSCH@DDTGROUP.ORG COWBOY EXPRESS WEATHERFOR 689200001413 WEATHERFORD TX MARCOSCH@DDTGROUP.ORG | G12: COWBOY EXPRESS WEATHWEATHERFORD TX | H12: Personal - Car | I12: =DATE(RIGHT(A12,4)+0,LEFT(A12,2)+0,1) -> 46174 | J12: =IF(TRIM(H12)="","(Uncategorized)",TRIM(H12)) -> Personal - Car
A13: 06/09/2026 | B13: PURE MASSAGE WEATHERFORD TX | C13: JOHN DUNNING | D13: -02000 | E13: 135 | F13: X3kB9W8gvQF squareup.com/receipts PURE MASSAGE WEATHERFORD TX squareup.com/receipts | G13: PURE MASSAGE WEATHERFORD TX | H13: Personal - Health | I13: =DATE(RIGHT(A13,4)+0,LEFT(A13,2)+0,1) -> 46174 | J13: =IF(TRIM(H13)="","(Uncategorized)",TRIM(H13)) -> Personal - Health
A14: 06/09/2026 | B14: STARBUCKS STORE 8480WEATHERFORD TX | C14: JOHN DUNNING | D14: -02000 | E14: 8.58 | F14: 63211FA4524 FAST FOOD RESTAURANT STARBUCKS STORE 8480 WEATHERFORD TX FAST FOOD RESTAURANT | G14: STARBUCKS STORE 8480WEATHERFORD TX | H14: Personal - Food | I14: =DATE(RIGHT(A14,4)+0,LEFT(A14,2)+0,1) -> 46174 | J14: =IF(TRIM(H14)="","(Uncategorized)",TRIM(H14)) -> Personal - Food
A15: 06/09/2026 | B15: VIOLET VAPOR - 2 WEATHERFORD TX | C15: JOHN DUNNING | D15: -02000 | E15: 43.14 | F15: 13610007 817-341-6571 VIOLET VAPOR - 2 WEATHERFORD TX Description : TOBACCO/ACC Price : 0.00 817-341-6571 | G15: VIOLET VAPOR - 2 WEATHERFORD TX | H15: Personal | I15: =DATE(RIGHT(A15,4)+0,LEFT(A15,2)+0,1) -> 46174 | J15: =IF(TRIM(H15)="","(Uncategorized)",TRIM(H15)) -> Personal
A16: 06/08/2026 | B16: HARBOR FREIGHT TOOLSWEATHERFORD TX | C16: JOHN DUNNING | D16: -02000 | E16: 82.16 | F16: 00279051613 818-836-5000 HARBOR FREIGHT TOOLS 698 698 WEATHERFORD TX Description : HARDWARE/TOOLS Price : 0.00 818-836-5000 | G16: HARBOR FREIGHT TOOLSWEATHERFORD TX | H16: Personal - House | I16: =DATE(RIGHT(A16,4)+0,LEFT(A16,2)+0,1) -> 46174 | J16: =IF(TRIM(H16)="","(Uncategorized)",TRIM(H16)) -> Personal - House
A17: 06/08/2026 | B17: PRESS CAFE - FORT WOFORT WORTH TX | C17: JOHN DUNNING | D17: -02000 | E17: 205 | F17: 42461854 20113 76109 RESTAURANT PRESS CAFE - FORT WORTH FORT WORTH TX RESTAURANT 20113 76109 | G17: PRESS CAFE - FORT WOFORT WORTH TX | H17: Personal - Food | I17: =DATE(RIGHT(A17,4)+0,LEFT(A17,2)+0,1) -> 46174 | J17: =IF(TRIM(H17)="","(Uncategorized)",TRIM(H17)) -> Personal - Food
A18: 06/08/2026 | B18: THE HOME DEPOT WEATHERFORD TX | C18: JOHN DUNNING | D18: -02000 | E18: 327.9 | F18: 06080651522 800-654-0688 THE HOME DEPOT WEATHERFORD TX 800-654-0688 | G18: THE HOME DEPOT WEATHERFORD TX | H18: Personal - House | I18: =DATE(RIGHT(A18,4)+0,LEFT(A18,2)+0,1) -> 46174 | J18: =IF(TRIM(H18)="","(Uncategorized)",TRIM(H18)) -> Personal - House
A19: 06/07/2026 | B19: AMAZON MARKEPLACE NA PA | C19: JOHN DUNNING | D19: -02000 | E19: 120.71 | F19: 1OA2LGVFP9K MERCHANDISE AMAZON MARKETPLACE NA PA AMZN.COM/BILL WA MERCHANDISE | G19: AMAZON MARKETPLACE NAMZN.COM/BILL WA | H19: Amazon | I19: =DATE(RIGHT(A19,4)+0,LEFT(A19,2)+0,1) -> 46174 | J19: =IF(TRIM(H19)="","(Uncategorized)",TRIM(H19)) -> Amazon
... A312: 03/01/2026 | B312: SP AVIATOR NATION VENICE CA | C312: JOHN DUNNING | D312: -02000 | E312: 82.32 | F312: CH_3T6L4AIA +13103969100 SP AVIATOR NATION VENICE CA +13103969100 | G312: SP AVIATOR NATION VENICE CA | H312: Personal - Clothing | I312: =DATE(RIGHT(A312,4)+0,LEFT(A312,2)+0,1) -> 46082 | J312: =IF(TRIM(H312)="","(Uncategorized)",TRIM(H312)) -> Personal - Clothing
A314: Totals | D314: Charges | E314: =SUMIF(E8:E312,">0") -> 55260.92
D315: Credits & Payments | E315: =SUMIF(E8:E312,"<0") -> -47495.04
D316: Net Balance | E316: =E314+E315 -> 7765.88
